{"type":"trade","received_at_ms":1788331869982,"data":{"e":"trade","E":1788331870120,"s":"BTCUSDT","t":6646634036,"p":"77582.84000000","q":"0.00200000","T":1788331870119,"m":false,"M":true}}
{"type":"trade","received_at_ms":1788331869982,"data":{"e":"trade","E":1788331870120,"s":"BTCUSDT","t":6646634037,"p":"77582.84000000","q":"0.00200000","T":1788331870120,"m":false,"M":true}}
{"type":"trade","received_at_ms":1788331869982,"data":{"e":"trade","E":1788331870120,"s":"BTCUSDT","t":6646634038,"p":"77582.84000000","q":"0.00200000","T":1788331870120,"m":false,"M":true}}
{"type":"trade","received_at_ms":1788331869982,"data":{"e":"trade","E":1788331870120,"s":"BTCUSDT","t":6646634039,"p":"77582.84000000","q":"0.01289000","T":1788331870120,"m":false,"M":true}}
{"type":"trade","received_at_ms":1788331869989,"data":{"e":"trade","E":1788331870121,"s":"BTCUSDT","t":6646634040,"p":"77582.84000000","q":"0.15156000","T":1788331870120,"m":false,"M":true}}
{"type":"trade","received_at_ms":1788331869989,"data":{"e":"trade","E":1788331870121,"s":"BTCUSDT","t":6646634041,"p":"77582.84000000","q":"0.00007000","T":1788331870120,"m":false,"M":true}}
{"type":"trade","received_at_ms":1788331869989,"data":{"e":"trade","E":1788331870121,"s":"BTCUSDT","t":6646634042,"p":"77582.84000000","q":"0.00007000","T":1788331870120,"m":false,"M":true}}
{"type":"trade","received_at_ms":1788331869989,"data":{"e":"trade","E":1788331870121,"s":"BTCUSDT","t":6646634043,"p":"77582.84000000","q":"0.00007000","T":1788331870120,"m":false,"M":true}}
{"type":"trade","received_at_ms":1788331869989,"data":{"e":"trade","E":1788331870121,"s":"BTCUSDT","t":6646634044,"p":"77582.84000000","q":"0.00007000","T":1788331870120,"m":false,"M":true}}
{"type":"trade","received_at_ms":1788331869989,"data":{"e":"trade","E":1788331870121,"s":"BTCUSDT","t":6646634045,"p":"77582.84000000","q":"0.00007000","T":1788331870120,"m":false,"M":true}}
{"type":"trade","received_at_ms":1788331869989,"data":{"e":"trade","E":1788331870121,"s":"BTCUSDT","t":6646634046,"p":"77582.84000000","q":"0.00007000","T":1788331870120,"m":false,"M":true}}
{"type":"trade","received_at_ms":1788331869990,"data":{"e":"trade","E":1788331870121,"s":"BTCUSDT","t":6646634047,"p":"77582.84000000","q":"0.00064000","T":1788331870120,"m":false,"M":true}}
{"type":"trade","received_at_ms":1788331869990,"data":{"e":"trade","E":1788331870121,"s":"BTCUSDT","t":6646634048,"p":"77582.84000000","q":"0.00007000","T":1788331870120,"m":false,"M":true}}
{"type":"trade","received_at_ms":1788331869990,"data":{"e":"trade","E":1788331870121,"s":"BTCUSDT","t":6646634049,"p":"77582.84000000","q":"0.00065000","T":1788331870120,"m":false,"M":true}}
{"type":"trade","received_at_ms":1788331869990,"data":{"e":"trade","E":1788331870121,"s":"BTCUSDT","t":6646634050,"p":"77582.84000000","q":"0.00007000","T":1788331870120,"m":false,"M":true}}
{"type":"trade","received_at_ms":1788331869990,"data":{"e":"trade","E":1788331870121,"s":"BTCUSDT","t":6646634051,"p":"77582.84000000","q":"0.00007000","T":1788331870120,"m":false,"M":true}}
{"type":"trade","received_at_ms":1788331869990,"data":{"e":"trade","E":1788331870121,"s":"BTCUSDT","t":6646634052,"p":"77582.84000000","q":"0.00007000","T":1788331870120,"m":false,"M":true}}
{"type":"trade","received_at_ms":1788331869990,"data":{"e":"trade","E":1788331870121,"s":"BTCUSDT","t":6646634053,"p":"77582.84000000","q":"0.00007000","T":1788331870120,"m":false,"M":true}}
{"type":"trade","received_at_ms":1788331869990,"data":{"e":"trade","E":1788331870121,"s":"BTCUSDT","t":6646634054,"p":"77582.84000000","q":"0.00008000","T":1788331870120,"m":false,"M":true}}
{"type":"trade","received_at_ms":1788331869990,"data":{"e":"trade","E":1788331870121,"s":"BTCUSDT","t":6646634055,"p":"77582.84000000","q":"0.00007000","T":1788331870120,"m":false,"M":true}}
{"type":"trade","received_at_ms":1788331869990,"data":{"e":"trade","E":1788331870121,"s":"BTCUSDT","t":6646634056,"p":"77582.84000000","q":"0.00007000","T":1788331870120,"m":false,"M":true}}
{"type":"trade","received_at_ms":1788331869990,"data":{"e":"trade","E":1788331870121,"s":"BTCUSDT","t":6646634057,"p":"77582.84000000","q":"0.03223000","T":1788331870120,"m":false,"M":true}}
{"type":"trade","received_at_ms":1788331869990,"data":{"e":"trade","E":1788331870121,"s":"BTCUSDT","t":6646634058,"p":"77582.84000000","q":"0.00007000","T":1788331870120,"m":false,"M":true}}
{"type":"trade","received_at_ms":1788331869990,"data":{"e":"trade","E":1788331870121,"s":"BTCUSDT","t":6646634059,"p":"77582.84000000","q":"0.00995000","T":1788331870120,"m":false,"M":true}}
{"type":"trade","received_at_ms":1788331869990,"data":{"e":"trade","E":1788331870121,"s":"BTCUSDT","t":6646634060,"p":"77582.84000000","q":"0.00007000","T":1788331870120,"m":false,"M":true}}
{"type":"trade","received_at_ms":1788331869990,"data":{"e":"trade","E":1788331870121,"s":"BTCUSDT","t":6646634061,"p":"77582.84000000","q":"0.00007000","T":1788331870120,"m":false,"M":true}}
{"type":"trade","received_at_ms":1788331869990,"data":{"e":"trade","E":1788331870121,"s":"BTCUSDT","t":6646634062,"p":"77582.84000000","q":"0.00007000","T":1788331870120,"m":false,"M":true}}
{"type":"trade","received_at_ms":1788331869990,"data":{"e":"trade","E":1788331870121,"s":"BTCUSDT","t":6646634063,"p":"77582.84000000","q":"0.00007000","T":1788331870120,"m":false,"M":true}}
{"type":"trade","received_at_ms":1788331869990,"data":{"e":"trade","E":1788331870121,"s":"BTCUSDT","t":6646634064,"p":"77582.84000000","q":"0.00036000","T":1788331870120,"m":false,"M":true}}
{"type":"trade","received_at_ms":1788331869990,"data":{"e":"trade","E":1788331870121,"s":"BTCUSDT","t":6646634065,"p":"77582.84000000","q":"0.00007000","T":1788331870120,"m":false,"M":true}}
{"type":"trade","received_at_ms":1788331869990,"data":{"e":"trade","E":1788331870121,"s":"BTCUSDT","t":6646634066,"p":"77582.84000000","q":"0.00013000","T":1788331870120,"m":false,"M":true}}
{"type":"trade","received_at_ms":1788331869990,"data":{"e":"trade","E":1788331870121,"s":"BTCUSDT","t":6646634067,"p":"77582.84000000","q":"0.00010000","T":1788331870120,"m":false,"M":true}}
{"type":"trade","received_at_ms":1788331869990,"data":{"e":"trade","E":1788331870121,"s":"BTCUSDT","t":6646634068,"p":"77582.84000000","q":"0.00007000","T":1788331870120,"m":false,"M":true}}
{"type":"trade","received_at_ms":1788331869990,"data":{"e":"trade","E":1788331870121,"s":"BTCUSDT","t":6646634069,"p":"77582.84000000","q":"0.00318000","T":1788331870120,"m":false,"M":true}}
{"type":"trade","received_at_ms":1788331869990,"data":{"e":"trade","E":1788331870121,"s":"BTCUSDT","t":6646634070,"p":"77582.84000000","q":"0.00007000","T":1788331870120,"m":false,"M":true}}
{"type":"trade","received_at_ms":1788331869990,"data":{"e":"trade","E":1788331870121,"s":"BTCUSDT","t":6646634071,"p":"77582.84000000","q":"0.00047000","T":1788331870120,"m":false,"M":true}}
{"type":"trade","received_at_ms":1788331869990,"data":{"e":"trade","E":1788331870121,"s":"BTCUSDT","t":6646634072,"p":"77582.84000000","q":"0.00015000","T":1788331870120,"m":false,"M":true}}
{"type":"trade","received_at_ms":1788331869990,"data":{"e":"trade","E":1788331870121,"s":"BTCUSDT","t":6646634073,"p":"77582.84000000","q":"0.00844000","T":1788331870120,"m":false,"M":true}}
{"type":"trade","received_at_ms":1788331869990,"data":{"e":"trade","E":1788331870121,"s":"BTCUSDT","t":6646634074,"p":"77582.84000000","q":"0.00007000","T":1788331870120,"m":false,"M":true}}
{"type":"trade","received_at_ms":1788331869990,"data":{"e":"trade","E":1788331870121,"s":"BTCUSDT","t":6646634075,"p":"77582.84000000","q":"0.00007000","T":1788331870120,"m":false,"M":true}}
{"type":"trade","received_at_ms":1788331869990,"data":{"e":"trade","E":1788331870121,"s":"BTCUSDT","t":6646634076,"p":"77582.84000000","q":"0.00007000","T":1788331870120,"m":false,"M":true}}
{"type":"trade","received_at_ms":1788331869990,"data":{"e":"trade","E":1788331870121,"s":"BTCUSDT","t":6646634077,"p":"77582.84000000","q":"0.00007000","T":1788331870120,"m":false,"M":true}}
{"type":"trade","received_at_ms":1788331869990,"data":{"e":"trade","E":1788331870121,"s":"BTCUSDT","t":6646634078,"p":"77582.84000000","q":"0.00007000","T":1788331870120,"m":false,"M":true}}
{"type":"trade","received_at_ms":1788331869991,"data":{"e":"trade","E":1788331870121,"s":"BTCUSDT","t":6646634079,"p":"77582.84000000","q":"0.00007000","T":1788331870120,"m":false,"M":true}}
{"type":"trade","received_at_ms":1788331869991,"data":{"e":"trade","E":1788331870121,"s":"BTCUSDT","t":6646634080,"p":"77582.84000000","q":"0.00007000","T":1788331870120,"m":false,"M":true}}
{"type":"trade","received_at_ms":1788331869991,"data":{"e":"trade","E":1788331870121,"s":"BTCUSDT","t":6646634081,"p":"77582.84000000","q":"0.00007000","T":1788331870120,"m":false,"M":true}}
{"type":"trade","received_at_ms":1788331869991,"data":{"e":"trade","E":1788331870121,"s":"BTCUSDT","t":6646634082,"p":"77582.84000000","q":"0.00007000","T":1788331870120,"m":false,"M":true}}
{"type":"trade","received_at_ms":1788331869991,"data":{"e":"trade","E":1788331870121,"s":"BTCUSDT","t":6646634083,"p":"77582.84000000","q":"0.00007000","T":1788331870120,"m":false,"M":true}}
{"type":"trade","received_at_ms":1788331869991,"data":{"e":"trade","E":1788331870121,"s":"BTCUSDT","t":6646634084,"p":"77582.84000000","q":"0.00007000","T":1788331870120,"m":false,"M":true}}
{"type":"trade","received_at_ms":1788331869991,"data":{"e":"trade","E":1788331870121,"s":"BTCUSDT","t":6646634085,"p":"77582.84000000","q":"0.00007000","T":1788331870120,"m":false,"M":true}}
{"type":"trade","received_at_ms":1788331869991,"data":{"e":"trade","E":1788331870121,"s":"BTCUSDT","t":6646634086,"p":"77582.84000000","q":"0.00007000","T":1788331870120,"m":false,"M":true}}
{"type":"trade","received_at_ms":1788331869991,"data":{"e":"trade","E":1788331870121,"s":"BTCUSDT","t":6646634087,"p":"77582.85000000","q":"0.00007000","T":1788331870120,"m":false,"M":true}}
{"type":"trade","received_at_ms":1788331869991,"data":{"e":"trade","E":1788331870121,"s":"BTCUSDT","t":6646634088,"p":"77582.85000000","q":"0.00007000","T":1788331870120,"m":false,"M":true}}
{"type":"trade","received_at_ms":1788331869991,"data":{"e":"trade","E":1788331870121,"s":"BTCUSDT","t":6646634089,"p":"77582.85000000","q":"0.00007000","T":1788331870120,"m":false,"M":true}}
{"type":"trade","received_at_ms":1788331869991,"data":{"e":"trade","E":1788331870121,"s":"BTCUSDT","t":6646634090,"p":"77582.85000000","q":"0.00007000","T":1788331870120,"m":false,"M":true}}
{"type":"trade","received_at_ms":1788331869991,"data":{"e":"trade","E":1788331870121,"s":"BTCUSDT","t":6646634091,"p":"77582.85000000","q":"0.00007000","T":1788331870120,"m":false,"M":true}}
{"type":"trade","received_at_ms":1788331869991,"data":{"e":"trade","E":1788331870121,"s":"BTCUSDT","t":6646634092,"p":"77582.85000000","q":"0.00007000","T":1788331870120,"m":false,"M":true}}
{"type":"trade","received_at_ms":1788331869991,"data":{"e":"trade","E":1788331870121,"s":"BTCUSDT","t":6646634093,"p":"77582.85000000","q":"0.00007000","T":1788331870120,"m":false,"M":true}}
{"type":"trade","received_at_ms":1788331869991,"data":{"e":"trade","E":1788331870121,"s":"BTCUSDT","t":6646634094,"p":"77582.85000000","q":"0.00007000","T":1788331870120,"m":false,"M":true}}
{"type":"trade","received_at_ms":1788331869991,"data":{"e":"trade","E":1788331870121,"s":"BTCUSDT","t":6646634095,"p":"77582.85000000","q":"0.00013000","T":1788331870120,"m":false,"M":true}}
{"type":"trade","received_at_ms":1788331869991,"data":{"e":"trade","E":1788331870121,"s":"BTCUSDT","t":6646634096,"p":"77582.85000000","q":"0.00007000","T":1788331870120,"m":false,"M":true}}
{"type":"trade","received_at_ms":1788331869991,"data":{"e":"trade","E":1788331870121,"s":"BTCUSDT","t":6646634097,"p":"77582.86000000","q":"0.00013000","T":1788331870120,"m":false,"M":true}}
{"type":"trade","received_at_ms":1788331869991,"data":{"e":"trade","E":1788331870121,"s":"BTCUSDT","t":6646634098,"p":"77583.49000000","q":"0.00007000","T":1788331870120,"m":false,"M":true}}
{"type":"trade","received_at_ms":1788331869991,"data":{"e":"trade","E":1788331870121,"s":"BTCUSDT","t":6646634099,"p":"77583.49000000","q":"0.00007000","T":1788331870120,"m":false,"M":true}}
{"type":"trade","received_at_ms":1788331869991,"data":{"e":"trade","E":1788331870121,"s":"BTCUSDT","t":6646634100,"p":"77583.49000000","q":"0.00007000","T":1788331870120,"m":false,"M":true}}
{"type":"trade","received_at_ms":1788331869991,"data":{"e":"trade","E":1788331870121,"s":"BTCUSDT","t":6646634101,"p":"77583.50000000","q":"0.01320000","T":1788331870120,"m":false,"M":true}}
{"type":"trade","received_at_ms":1788331869991,"data":{"e":"trade","E":1788331870121,"s":"BTCUSDT","t":6646634102,"p":"77583.50000000","q":"0.00007000","T":1788331870120,"m":false,"M":true}}
{"type":"trade","received_at_ms":1788331869991,"data":{"e":"trade","E":1788331870121,"s":"BTCUSDT","t":6646634103,"p":"77583.50000000","q":"0.00007000","T":1788331870120,"m":false,"M":true}}
{"type":"trade","received_at_ms":1788331869991,"data":{"e":"trade","E":1788331870121,"s":"BTCUSDT","t":6646634104,"p":"77583.51000000","q":"0.00007000","T":1788331870120,"m":false,"M":true}}
{"type":"trade","received_at_ms":1788331869991,"data":{"e":"trade","E":1788331870121,"s":"BTCUSDT","t":6646634105,"p":"77583.51000000","q":"0.00007000","T":1788331870120,"m":false,"M":true}}
{"type":"trade","received_at_ms":1788331869991,"data":{"e":"trade","E":1788331870121,"s":"BTCUSDT","t":6646634106,"p":"77583.85000000","q":"0.00007000","T":1788331870121,"m":false,"M":true}}
{"type":"trade","received_at_ms":1788331869991,"data":{"e":"trade","E":1788331870121,"s":"BTCUSDT","t":6646634107,"p":"77583.85000000","q":"0.00007000","T":1788331870121,"m":false,"M":true}}
{"type":"trade","received_at_ms":1788331869991,"data":{"e":"trade","E":1788331870121,"s":"BTCUSDT","t":6646634108,"p":"77583.85000000","q":"0.00007000","T":1788331870121,"m":false,"M":true}}
{"type":"trade","received_at_ms":1788331869991,"data":{"e":"trade","E":1788331870121,"s":"BTCUSDT","t":6646634109,"p":"77583.86000000","q":"0.00179000","T":1788331870121,"m":false,"M":true}}
{"type":"trade","received_at_ms":1788331869991,"data":{"e":"trade","E":1788331870121,"s":"BTCUSDT","t":6646634110,"p":"77583.86000000","q":"0.00200000","T":1788331870121,"m":false,"M":true}}
{"type":"trade","received_at_ms":1788331869993,"data":{"e":"trade","E":1788331870122,"s":"BTCUSDT","t":6646634111,"p":"77583.86000000","q":"0.00200000","T":1788331870121,"m":false,"M":true}}
{"type":"trade","received_at_ms":1788331869993,"data":{"e":"trade","E":1788331870123,"s":"BTCUSDT","t":6646634112,"p":"77583.86000000","q":"0.00200000","T":1788331870123,"m":false,"M":true}}
{"type":"trade","received_at_ms":1788331869993,"data":{"e":"trade","E":1788331870124,"s":"BTCUSDT","t":6646634113,"p":"77583.86000000","q":"0.00207000","T":1788331870123,"m":false,"M":true}}
{"type":"trade","received_at_ms":1788331869993,"data":{"e":"trade","E":1788331870124,"s":"BTCUSDT","t":6646634114,"p":"77583.86000000","q":"0.01914000","T":1788331870123,"m":false,"M":true}}
{"type":"trade","received_at_ms":1788331869993,"data":{"e":"trade","E":1788331870124,"s":"BTCUSDT","t":6646634115,"p":"77583.86000000","q":"0.00007000","T":1788331870123,"m":false,"M":true}}
{"type":"trade","received_at_ms":1788331869993,"data":{"e":"trade","E":1788331870124,"s":"BTCUSDT","t":6646634116,"p":"77583.86000000","q":"0.00007000","T":1788331870123,"m":false,"M":true}}
{"type":"trade","received_at_ms":1788331869993,"data":{"e":"trade","E":1788331870124,"s":"BTCUSDT","t":6646634117,"p":"77583.86000000","q":"0.00007000","T":1788331870123,"m":false,"M":true}}
{"type":"trade","received_at_ms":1788331869993,"data":{"e":"trade","E":1788331870124,"s":"BTCUSDT","t":6646634118,"p":"77583.86000000","q":"0.00007000","T":1788331870123,"m":false,"M":true}}
{"type":"trade","received_at_ms":1788331869993,"data":{"e":"trade","E":1788331870124,"s":"BTCUSDT","t":6646634119,"p":"77583.86000000","q":"0.00007000","T":1788331870123,"m":false,"M":true}}
{"type":"trade","received_at_ms":1788331869993,"data":{"e":"trade","E":1788331870124,"s":"BTCUSDT","t":6646634120,"p":"77583.86000000","q":"0.00007000","T":1788331870123,"m":false,"M":true}}
{"type":"trade","received_at_ms":1788331869993,"data":{"e":"trade","E":1788331870124,"s":"BTCUSDT","t":6646634121,"p":"77583.86000000","q":"0.00007000","T":1788331870123,"m":false,"M":true}}
{"type":"trade","received_at_ms":1788331869993,"data":{"e":"trade","E":1788331870124,"s":"BTCUSDT","t":6646634122,"p":"77583.86000000","q":"0.00007000","T":1788331870123,"m":false,"M":true}}
{"type":"trade","received_at_ms":1788331869993,"data":{"e":"trade","E":1788331870124,"s":"BTCUSDT","t":6646634123,"p":"77583.86000000","q":"0.00007000","T":1788331870123,"m":false,"M":true}}
{"type":"trade","received_at_ms":1788331869993,"data":{"e":"trade","E":1788331870124,"s":"BTCUSDT","t":6646634124,"p":"77583.86000000","q":"0.00007000","T":1788331870123,"m":false,"M":true}}
{"type":"trade","received_at_ms":1788331869993,"data":{"e":"trade","E":1788331870124,"s":"BTCUSDT","t":6646634125,"p":"77583.86000000","q":"0.00007000","T":1788331870123,"m":false,"M":true}}
{"type":"trade","received_at_ms":1788331869993,"data":{"e":"trade","E":1788331870124,"s":"BTCUSDT","t":6646634126,"p":"77583.86000000","q":"0.00007000","T":1788331870123,"m":false,"M":true}}
{"type":"trade","received_at_ms":1788331869993,"data":{"e":"trade","E":1788331870124,"s":"BTCUSDT","t":6646634127,"p":"77583.86000000","q":"0.00007000","T":1788331870123,"m":false,"M":true}}
{"type":"trade","received_at_ms":1788331869993,"data":{"e":"trade","E":1788331870124,"s":"BTCUSDT","t":6646634128,"p":"77583.86000000","q":"0.00007000","T":1788331870123,"m":false,"M":true}}
{"type":"trade","received_at_ms":1788331869993,"data":{"e":"trade","E":1788331870124,"s":"BTCUSDT","t":6646634129,"p":"77583.86000000","q":"0.00007000","T":1788331870123,"m":false,"M":true}}
{"type":"trade","received_at_ms":1788331869993,"data":{"e":"trade","E":1788331870124,"s":"BTCUSDT","t":6646634130,"p":"77583.86000000","q":"0.00007000","T":1788331870123,"m":false,"M":true}}
{"type":"trade","received_at_ms":1788331869993,"data":{"e":"trade","E":1788331870124,"s":"BTCUSDT","t":6646634131,"p":"77584.08000000","q":"0.00007000","T":1788331870123,"m":false,"M":true}}
{"type":"trade","received_at_ms":1788331869993,"data":{"e":"trade","E":1788331870124,"s":"BTCUSDT","t":6646634132,"p":"77584.08000000","q":"0.00007000","T":1788331870123,"m":false,"M":true}}
{"type":"trade","received_at_ms":1788331869993,"data":{"e":"trade","E":1788331870124,"s":"BTCUSDT","t":6646634133,"p":"77584.08000000","q":"0.00007000","T":1788331870123,"m":false,"M":true}}
{"type":"trade","received_at_ms":1788331869993,"data":{"e":"trade","E":1788331870124,"s":"BTCUSDT","t":6646634134,"p":"77584.09000000","q":"0.01658000","T":1788331870123,"m":false,"M":true}}
{"type":"trade","received_at_ms":1788331869993,"data":{"e":"trade","E":1788331870124,"s":"BTCUSDT","t":6646634135,"p":"77584.09000000","q":"0.00007000","T":1788331870123,"m":false,"M":true}}
{"type":"trade","received_at_ms":1788331869993,"data":{"e":"trade","E":1788331870124,"s":"BTCUSDT","t":6646634136,"p":"77584.09000000","q":"0.00007000","T":1788331870123,"m":false,"M":true}}
{"type":"trade","received_at_ms":1788331869993,"data":{"e":"trade","E":1788331870124,"s":"BTCUSDT","t":6646634137,"p":"77584.09000000","q":"0.00007000","T":1788331870123,"m":false,"M":true}}
{"type":"trade","received_at_ms":1788331869993,"data":{"e":"trade","E":1788331870124,"s":"BTCUSDT","t":6646634138,"p":"77584.09000000","q":"0.00007000","T":1788331870123,"m":false,"M":true}}
{"type":"trade","received_at_ms":1788331869994,"data":{"e":"trade","E":1788331870124,"s":"BTCUSDT","t":6646634139,"p":"77584.09000000","q":"0.00007000","T":1788331870123,"m":false,"M":true}}
{"type":"trade","received_at_ms":1788331869994,"data":{"e":"trade","E":1788331870124,"s":"BTCUSDT","t":6646634140,"p":"77584.09000000","q":"0.00007000","T":1788331870123,"m":false,"M":true}}
{"type":"trade","received_at_ms":1788331869994,"data":{"e":"trade","E":1788331870124,"s":"BTCUSDT","t":6646634141,"p":"77584.15000000","q":"0.00007000","T":1788331870123,"m":false,"M":true}}
{"type":"trade","received_at_ms":1788331869994,"data":{"e":"trade","E":1788331870124,"s":"BTCUSDT","t":6646634142,"p":"77584.15000000","q":"0.00007000","T":1788331870123,"m":false,"M":true}}
{"type":"trade","received_at_ms":1788331869994,"data":{"e":"trade","E":1788331870124,"s":"BTCUSDT","t":6646634143,"p":"77584.15000000","q":"0.00007000","T":1788331870123,"m":false,"M":true}}
{"type":"trade","received_at_ms":1788331869994,"data":{"e":"trade","E":1788331870128,"s":"BTCUSDT","t":6646634144,"p":"77584.16000000","q":"0.00007000","T":1788331870127,"m":false,"M":true}}
{"type":"trade","received_at_ms":1788331869994,"data":{"e":"trade","E":1788331870128,"s":"BTCUSDT","t":6646634145,"p":"77584.16000000","q":"0.00007000","T":1788331870127,"m":false,"M":true}}
{"type":"trade","received_at_ms":1788331869994,"data":{"e":"trade","E":1788331870128,"s":"BTCUSDT","t":6646634146,"p":"77584.16000000","q":"0.00007000","T":1788331870127,"m":false,"M":true}}
{"type":"trade","received_at_ms":1788331869994,"data":{"e":"trade","E":1788331870128,"s":"BTCUSDT","t":6646634147,"p":"77584.16000000","q":"0.00007000","T":1788331870127,"m":false,"M":true}}
{"type":"trade","received_at_ms":1788331869994,"data":{"e":"trade","E":1788331870128,"s":"BTCUSDT","t":6646634148,"p":"77584.16000000","q":"0.00007000","T":1788331870127,"m":false,"M":true}}
{"type":"trade","received_at_ms":1788331869994,"data":{"e":"trade","E":1788331870128,"s":"BTCUSDT","t":6646634149,"p":"77584.16000000","q":"0.00007000","T":1788331870127,"m":false,"M":true}}
{"type":"trade","received_at_ms":1788331869994,"data":{"e":"trade","E":1788331870128,"s":"BTCUSDT","t":6646634150,"p":"77584.16000000","q":"0.00007000","T":1788331870127,"m":false,"M":true}}
{"type":"trade","received_at_ms":1788331869994,"data":{"e":"trade","E":1788331870128,"s":"BTCUSDT","t":6646634151,"p":"77584.16000000","q":"0.00007000","T":1788331870127,"m":false,"M":true}}
{"type":"trade","received_at_ms":1788331869994,"data":{"e":"trade","E":1788331870128,"s":"BTCUSDT","t":6646634152,"p":"77584.16000000","q":"0.00007000","T":1788331870127,"m":false,"M":true}}
{"type":"trade","received_at_ms":1788331869994,"data":{"e":"trade","E":1788331870128,"s":"BTCUSDT","t":6646634153,"p":"77584.16000000","q":"0.00007000","T":1788331870127,"m":false,"M":true}}
{"type":"trade","received_at_ms":1788331869994,"data":{"e":"trade","E":1788331870128,"s":"BTCUSDT","t":6646634154,"p":"77584.16000000","q":"0.00007000","T":1788331870127,"m":false,"M":true}}
{"type":"trade","received_at_ms":1788331869994,"data":{"e":"trade","E":1788331870128,"s":"BTCUSDT","t":6646634155,"p":"77584.16000000","q":"0.00007000","T":1788331870127,"m":false,"M":true}}
{"type":"trade","received_at_ms":1788331869994,"data":{"e":"trade","E":1788331870128,"s":"BTCUSDT","t":6646634156,"p":"77584.17000000","q":"0.00007000","T":1788331870127,"m":false,"M":true}}
{"type":"trade","received_at_ms":1788331869994,"data":{"e":"trade","E":1788331870128,"s":"BTCUSDT","t":6646634157,"p":"77584.62000000","q":"0.00007000","T":1788331870127,"m":false,"M":true}}
{"type":"trade","received_at_ms":1788331869994,"data":{"e":"trade","E":1788331870128,"s":"BTCUSDT","t":6646634158,"p":"77584.62000000","q":"0.00007000","T":1788331870127,"m":false,"M":true}}
{"type":"trade","received_at_ms":1788331869994,"data":{"e":"trade","E":1788331870128,"s":"BTCUSDT","t":6646634159,"p":"77584.88000000","q":"0.00007000","T":1788331870127,"m":false,"M":true}}
{"type":"trade","received_at_ms":1788331869994,"data":{"e":"trade","E":1788331870128,"s":"BTCUSDT","t":6646634160,"p":"77584.88000000","q":"0.00007000","T":1788331870127,"m":false,"M":true}}
{"type":"trade","received_at_ms":1788331869994,"data":{"e":"trade","E":1788331870128,"s":"BTCUSDT","t":6646634161,"p":"77584.88000000","q":"0.00007000","T":1788331870127,"m":false,"M":true}}
{"type":"trade","received_at_ms":1788331869994,"data":{"e":"trade","E":1788331870128,"s":"BTCUSDT","t":6646634162,"p":"77584.88000000","q":"0.00007000","T":1788331870127,"m":false,"M":true}}
{"type":"trade","received_at_ms":1788331869995,"data":{"e":"trade","E":1788331870130,"s":"BTCUSDT","t":6646634163,"p":"77585.33000000","q":"0.01990000","T":1788331870129,"m":false,"M":true}}
{"type":"trade","received_at_ms":1788331869995,"data":{"e":"trade","E":1788331870130,"s":"BTCUSDT","t":6646634164,"p":"77585.33000000","q":"0.00007000","T":1788331870129,"m":false,"M":true}}
{"type":"trade","received_at_ms":1788331869995,"data":{"e":"trade","E":1788331870130,"s":"BTCUSDT","t":6646634165,"p":"77585.33000000","q":"0.00007000","T":1788331870129,"m":false,"M":true}}
{"type":"trade","received_at_ms":1788331869995,"data":{"e":"trade","E":1788331870130,"s":"BTCUSDT","t":6646634166,"p":"77585.33000000","q":"0.00007000","T":1788331870129,"m":false,"M":true}}
{"type":"trade","received_at_ms":1788331869995,"data":{"e":"trade","E":1788331870130,"s":"BTCUSDT","t":6646634167,"p":"77585.54000000","q":"0.00007000","T":1788331870129,"m":false,"M":true}}
{"type":"trade","received_at_ms":1788331869995,"data":{"e":"trade","E":1788331870130,"s":"BTCUSDT","t":6646634168,"p":"77585.54000000","q":"0.00007000","T":1788331870129,"m":false,"M":true}}
{"type":"trade","received_at_ms":1788331869995,"data":{"e":"trade","E":1788331870130,"s":"BTCUSDT","t":6646634169,"p":"77585.54000000","q":"0.00007000","T":1788331870129,"m":false,"M":true}}
{"type":"trade","received_at_ms":1788331869995,"data":{"e":"trade","E":1788331870130,"s":"BTCUSDT","t":6646634170,"p":"77585.55000000","q":"0.00007000","T":1788331870129,"m":false,"M":true}}
{"type":"trade","received_at_ms":1788331869995,"data":{"e":"trade","E":1788331870130,"s":"BTCUSDT","t":6646634171,"p":"77585.55000000","q":"0.00007000","T":1788331870129,"m":false,"M":true}}
{"type":"trade","received_at_ms":1788331869995,"data":{"e":"trade","E":1788331870130,"s":"BTCUSDT","t":6646634172,"p":"77585.55000000","q":"0.00007000","T":1788331870129,"m":false,"M":true}}
{"type":"trade","received_at_ms":1788331869995,"data":{"e":"trade","E":1788331870130,"s":"BTCUSDT","t":6646634173,"p":"77585.55000000","q":"0.00007000","T":1788331870129,"m":false,"M":true}}
{"type":"trade","received_at_ms":1788331869995,"data":{"e":"trade","E":1788331870130,"s":"BTCUSDT","t":6646634174,"p":"77585.56000000","q":"0.00007000","T":1788331870129,"m":false,"M":true}}
{"type":"trade","received_at_ms":1788331869995,"data":{"e":"trade","E":1788331870130,"s":"BTCUSDT","t":6646634175,"p":"77585.56000000","q":"0.00007000","T":1788331870129,"m":false,"M":true}}
{"type":"trade","received_at_ms":1788331869995,"data":{"e":"trade","E":1788331870130,"s":"BTCUSDT","t":6646634176,"p":"77585.56000000","q":"0.00007000","T":1788331870129,"m":false,"M":true}}
{"type":"trade","received_at_ms":1788331869995,"data":{"e":"trade","E":1788331870130,"s":"BTCUSDT","t":6646634177,"p":"77585.57000000","q":"0.00007000","T":1788331870129,"m":false,"M":true}}
{"type":"trade","received_at_ms":1788331869995,"data":{"e":"trade","E":1788331870130,"s":"BTCUSDT","t":6646634178,"p":"77585.57000000","q":"0.00007000","T":1788331870129,"m":false,"M":true}}
{"type":"trade","received_at_ms":1788331869995,"data":{"e":"trade","E":1788331870130,"s":"BTCUSDT","t":6646634179,"p":"77585.57000000","q":"0.00005000","T":1788331870129,"m":false,"M":true}}
{"type":"trade","received_at_ms":1788331869995,"data":{"e":"trade","E":1788331870130,"s":"BTCUSDT","t":6646634180,"p":"77585.57000000","q":"0.00002000","T":1788331870130,"m":false,"M":true}}
{"type":"trade","received_at_ms":1788331869995,"data":{"e":"trade","E":1788331870130,"s":"BTCUSDT","t":6646634181,"p":"77585.57000000","q":"0.00007000","T":1788331870130,"m":false,"M":true}}
{"type":"trade","received_at_ms":1788331869995,"data":{"e":"trade","E":1788331870130,"s":"BTCUSDT","t":6646634182,"p":"77585.57000000","q":"0.00007000","T":1788331870130,"m":false,"M":true}}
{"type":"trade","received_at_ms":1788331869995,"data":{"e":"trade","E":1788331870130,"s":"BTCUSDT","t":6646634183,"p":"77585.57000000","q":"0.00007000","T":1788331870130,"m":false,"M":true}}
{"type":"trade","received_at_ms":1788331869995,"data":{"e":"trade","E":1788331870130,"s":"BTCUSDT","t":6646634184,"p":"77585.81000000","q":"0.00007000","T":1788331870130,"m":false,"M":true}}
{"type":"trade","received_at_ms":1788331869995,"data":{"e":"trade","E":1788331870130,"s":"BTCUSDT","t":6646634185,"p":"77586.43000000","q":"0.00007000","T":1788331870130,"m":false,"M":true}}
{"type":"trade","received_at_ms":1788331869995,"data":{"e":"trade","E":1788331870130,"s":"BTCUSDT","t":6646634186,"p":"77586.43000000","q":"0.00007000","T":1788331870130,"m":false,"M":true}}
{"type":"trade","received_at_ms":1788331869995,"data":{"e":"trade","E":1788331870130,"s":"BTCUSDT","t":6646634187,"p":"77586.48000000","q":"0.00007000","T":1788331870130,"m":false,"M":true}}
{"type":"trade","received_at_ms":1788331869996,"data":{"e":"trade","E":1788331870130,"s":"BTCUSDT","t":6646634188,"p":"77586.56000000","q":"0.00007000","T":1788331870130,"m":false,"M":true}}
{"type":"trade","received_at_ms":1788331869996,"data":{"e":"trade","E":1788331870130,"s":"BTCUSDT","t":6646634189,"p":"77586.56000000","q":"0.00007000","T":1788331870130,"m":false,"M":true}}
{"type":"trade","received_at_ms":1788331869996,"data":{"e":"trade","E":1788331870130,"s":"BTCUSDT","t":6646634190,"p":"77586.56000000","q":"0.00007000","T":1788331870130,"m":false,"M":true}}
{"type":"trade","received_at_ms":1788331869996,"data":{"e":"trade","E":1788331870130,"s":"BTCUSDT","t":6646634191,"p":"77586.57000000","q":"0.01990000","T":1788331870130,"m":false,"M":true}}
{"type":"trade","received_at_ms":1788331869996,"data":{"e":"trade","E":1788331870130,"s":"BTCUSDT","t":6646634192,"p":"77586.57000000","q":"0.00007000","T":1788331870130,"m":false,"M":true}}
{"type":"trade","received_at_ms":1788331869996,"data":{"e":"trade","E":1788331870130,"s":"BTCUSDT","t":6646634193,"p":"77586.57000000","q":"0.00007000","T":1788331870130,"m":false,"M":true}}
{"type":"trade","received_at_ms":1788331869996,"data":{"e":"trade","E":1788331870130,"s":"BTCUSDT","t":6646634194,"p":"77587.02000000","q":"0.00007000","T":1788331870130,"m":false,"M":true}}
{"type":"trade","received_at_ms":1788331869996,"data":{"e":"trade","E":1788331870130,"s":"BTCUSDT","t":6646634195,"p":"77587.03000000","q":"0.00007000","T":1788331870130,"m":false,"M":true}}
{"type":"trade","received_at_ms":1788331869996,"data":{"e":"trade","E":1788331870130,"s":"BTCUSDT","t":6646634196,"p":"77587.03000000","q":"0.00007000","T":1788331870130,"m":false,"M":true}}
{"type":"trade","received_at_ms":1788331869996,"data":{"e":"trade","E":1788331870130,"s":"BTCUSDT","t":6646634197,"p":"77587.03000000","q":"0.00003000","T":1788331870130,"m":false,"M":true}}
{"type":"trade","received_at_ms":1788331869997,"data":{"e":"trade","E":1788331870132,"s":"BTCUSDT","t":6646634198,"p":"77587.03000000","q":"0.00004000","T":1788331870131,"m":false,"M":true}}
{"type":"trade","received_at_ms":1788331869997,"data":{"e":"trade","E":1788331870132,"s":"BTCUSDT","t":6646634199,"p":"77587.03000000","q":"0.00007000","T":1788331870131,"m":false,"M":true}}
{"type":"trade","received_at_ms":1788331869997,"data":{"e":"trade","E":1788331870132,"s":"BTCUSDT","t":6646634200,"p":"77587.03000000","q":"0.00007000","T":1788331870131,"m":false,"M":true}}
{"type":"trade","received_at_ms":1788331869997,"data":{"e":"trade","E":1788331870132,"s":"BTCUSDT","t":6646634201,"p":"77587.03000000","q":"0.00007000","T":1788331870131,"m":false,"M":true}}
{"type":"trade","received_at_ms":1788331869997,"data":{"e":"trade","E":1788331870132,"s":"BTCUSDT","t":6646634202,"p":"77587.03000000","q":"0.00007000","T":1788331870131,"m":false,"M":true}}
{"type":"trade","received_at_ms":1788331869997,"data":{"e":"trade","E":1788331870132,"s":"BTCUSDT","t":6646634203,"p":"77587.03000000","q":"0.00007000","T":1788331870131,"m":false,"M":true}}
{"type":"trade","received_at_ms":1788331869997,"data":{"e":"trade","E":1788331870132,"s":"BTCUSDT","t":6646634204,"p":"77587.03000000","q":"0.00007000","T":1788331870131,"m":false,"M":true}}
{"type":"trade","received_at_ms":1788331869997,"data":{"e":"trade","E":1788331870132,"s":"BTCUSDT","t":6646634205,"p":"77587.08000000","q":"0.01280000","T":1788331870131,"m":false,"M":true}}
{"type":"trade","received_at_ms":1788331869997,"data":{"e":"trade","E":1788331870132,"s":"BTCUSDT","t":6646634206,"p":"77587.10000000","q":"0.00007000","T":1788331870131,"m":false,"M":true}}
{"type":"trade","received_at_ms":1788331869997,"data":{"e":"trade","E":1788331870132,"s":"BTCUSDT","t":6646634207,"p":"77587.10000000","q":"0.00007000","T":1788331870131,"m":false,"M":true}}
{"type":"trade","received_at_ms":1788331869997,"data":{"e":"trade","E":1788331870132,"s":"BTCUSDT","t":6646634208,"p":"77587.73000000","q":"0.00322000","T":1788331870131,"m":false,"M":true}}
{"type":"trade","received_at_ms":1788331869997,"data":{"e":"trade","E":1788331870132,"s":"BTCUSDT","t":6646634209,"p":"77588.18000000","q":"0.00241000","T":1788331870131,"m":false,"M":true}}
{"type":"trade","received_at_ms":1788331869997,"data":{"e":"trade","E":1788331870132,"s":"BTCUSDT","t":6646634210,"p":"77588.22000000","q":"0.00197000","T":1788331870131,"m":false,"M":true}}
{"type":"trade","received_at_ms":1788331869997,"data":{"e":"trade","E":1788331870132,"s":"BTCUSDT","t":6646634211,"p":"77588.22000000","q":"0.01008000","T":1788331870131,"m":false,"M":true}}
{"type":"trade","received_at_ms":1788331869997,"data":{"e":"trade","E":1788331870132,"s":"BTCUSDT","t":6646634212,"p":"77588.24000000","q":"0.00290000","T":1788331870131,"m":false,"M":true}}
{"type":"trade","received_at_ms":1788331869997,"data":{"e":"trade","E":1788331870132,"s":"BTCUSDT","t":6646634213,"p":"77588.24000000","q":"0.00043000","T":1788331870131,"m":false,"M":true}}
{"type":"trade","received_at_ms":1788331869997,"data":{"e":"trade","E":1788331870132,"s":"BTCUSDT","t":6646634214,"p":"77588.28000000","q":"0.00007000","T":1788331870131,"m":false,"M":true}}
{"type":"trade","received_at_ms":1788331869997,"data":{"e":"trade","E":1788331870132,"s":"BTCUSDT","t":6646634215,"p":"77588.29000000","q":"0.00007000","T":1788331870131,"m":false,"M":true}}
{"type":"trade","received_at_ms":1788331869997,"data":{"e":"trade","E":1788331870132,"s":"BTCUSDT","t":6646634216,"p":"77588.29000000","q":"0.00007000","T":1788331870131,"m":false,"M":true}}
{"type":"trade","received_at_ms":1788331869997,"data":{"e":"trade","E":1788331870132,"s":"BTCUSDT","t":6646634217,"p":"77588.32000000","q":"0.00211000","T":1788331870131,"m":false,"M":true}}
{"type":"trade","received_at_ms":1788331869997,"data":{"e":"trade","E":1788331870132,"s":"BTCUSDT","t":6646634218,"p":"77588.50000000","q":"0.00007000","T":1788331870131,"m":false,"M":true}}
{"type":"trade","received_at_ms":1788331869997,"data":{"e":"trade","E":1788331870132,"s":"BTCUSDT","t":6646634219,"p":"77588.50000000","q":"0.00007000","T":1788331870131,"m":false,"M":true}}
{"type":"trade","received_at_ms":1788331869997,"data":{"e":"trade","E":1788331870132,"s":"BTCUSDT","t":6646634220,"p":"77588.50000000","q":"0.00007000","T":1788331870131,"m":false,"M":true}}
{"type":"trade","received_at_ms":1788331869997,"data":{"e":"trade","E":1788331870132,"s":"BTCUSDT","t":6646634221,"p":"77588.50000000","q":"0.00007000","T":1788331870131,"m":false,"M":true}}
{"type":"trade","received_at_ms":1788331869997,"data":{"e":"trade","E":1788331870132,"s":"BTCUSDT","t":6646634222,"p":"77588.50000000","q":"0.00007000","T":1788331870131,"m":false,"M":true}}
{"type":"trade","received_at_ms":1788331869997,"data":{"e":"trade","E":1788331870132,"s":"BTCUSDT","t":6646634223,"p":"77588.50000000","q":"0.00007000","T":1788331870131,"m":false,"M":true}}
{"type":"trade","received_at_ms":1788331869997,"data":{"e":"trade","E":1788331870132,"s":"BTCUSDT","t":6646634224,"p":"77588.54000000","q":"0.00007000","T":1788331870131,"m":false,"M":true}}
{"type":"trade","received_at_ms":1788331869997,"data":{"e":"trade","E":1788331870132,"s":"BTCUSDT","t":6646634225,"p":"77588.54000000","q":"0.00007000","T":1788331870131,"m":false,"M":true}}
{"type":"trade","received_at_ms":1788331869997,"data":{"e":"trade","E":1788331870132,"s":"BTCUSDT","t":6646634226,"p":"77588.91000000","q":"0.00007000","T":1788331870131,"m":false,"M":true}}
{"type":"trade","received_at_ms":1788331869997,"data":{"e":"trade","E":1788331870132,"s":"BTCUSDT","t":6646634227,"p":"77588.91000000","q":"0.00007000","T":1788331870131,"m":false,"M":true}}
{"type":"trade","received_at_ms":1788331869997,"data":{"e":"trade","E":1788331870132,"s":"BTCUSDT","t":6646634228,"p":"77588.91000000","q":"0.00007000","T":1788331870131,"m":false,"M":true}}
{"type":"trade","received_at_ms":1788331869997,"data":{"e":"trade","E":1788331870132,"s":"BTCUSDT","t":6646634229,"p":"77588.91000000","q":"0.00007000","T":1788331870131,"m":false,"M":true}}
{"type":"trade","received_at_ms":1788331869997,"data":{"e":"trade","E":1788331870132,"s":"BTCUSDT","t":6646634230,"p":"77588.91000000","q":"0.00007000","T":1788331870131,"m":false,"M":true}}
{"type":"trade","received_at_ms":1788331869997,"data":{"e":"trade","E":1788331870132,"s":"BTCUSDT","t":6646634231,"p":"77589.33000000","q":"0.00007000","T":1788331870131,"m":false,"M":true}}
{"type":"trade","received_at_ms":1788331869997,"data":{"e":"trade","E":1788331870132,"s":"BTCUSDT","t":6646634232,"p":"77589.34000000","q":"0.00007000","T":1788331870131,"m":false,"M":true}}
{"type":"trade","received_at_ms":1788331869997,"data":{"e":"trade","E":1788331870132,"s":"BTCUSDT","t":6646634233,"p":"77589.34000000","q":"0.00007000","T":1788331870131,"m":false,"M":true}}
{"type":"trade","received_at_ms":1788331869997,"data":{"e":"trade","E":1788331870132,"s":"BTCUSDT","t":6646634234,"p":"77589.40000000","q":"0.00007000","T":1788331870131,"m":false,"M":true}}
{"type":"trade","received_at_ms":1788331869997,"data":{"e":"trade","E":1788331870132,"s":"BTCUSDT","t":6646634235,"p":"77589.40000000","q":"0.00007000","T":1788331870131,"m":false,"M":true}}
{"type":"trade","received_at_ms":1788331869997,"data":{"e":"trade","E":1788331870132,"s":"BTCUSDT","t":6646634236,"p":"77589.67000000","q":"0.00013000","T":1788331870131,"m":false,"M":true}}
{"type":"trade","received_at_ms":1788331869997,"data":{"e":"trade","E":1788331870132,"s":"BTCUSDT","t":6646634237,"p":"77590.01000000","q":"0.00007000","T":1788331870131,"m":false,"M":true}}
{"type":"trade","received_at_ms":1788331869997,"data":{"e":"trade","E":1788331870132,"s":"BTCUSDT","t":6646634238,"p":"77590.01000000","q":"0.00007000","T":1788331870131,"m":false,"M":true}}
{"type":"trade","received_at_ms":1788331869997,"data":{"e":"trade","E":1788331870132,"s":"BTCUSDT","t":6646634239,"p":"77590.30000000","q":"0.00374000","T":1788331870131,"m":false,"M":true}}
{"type":"trade","received_at_ms":1788331869997,"data":{"e":"trade","E":1788331870133,"s":"BTCUSDT","t":6646634240,"p":"77590.30000000","q":"0.00026000","T":1788331870132,"m":false,"M":true}}
{"type":"trade","received_at_ms":1788331869997,"data":{"e":"trade","E":1788331870133,"s":"BTCUSDT","t":6646634241,"p":"77590.30000000","q":"0.02074000","T":1788331870132,"m":false,"M":true}}
{"type":"trade","received_at_ms":1788331869997,"data":{"e":"trade","E":1788331870134,"s":"BTCUSDT","t":6646634242,"p":"77590.30000000","q":"0.02100000","T":1788331870133,"m":false,"M":true}}
{"type":"trade","received_at_ms":1788331869997,"data":{"e":"trade","E":1788331870135,"s":"BTCUSDT","t":6646634243,"p":"77590.30000000","q":"0.02100000","T":1788331870134,"m":false,"M":true}}
{"type":"trade","received_at_ms":1788331869998,"data":{"e":"trade","E":1788331870139,"s":"BTCUSDT","t":6646634244,"p":"77590.30000000","q":"0.02100000","T":1788331870139,"m":false,"M":true}}
{"type":"depth","received_at_ms":1788331870076,"data":{"e":"depthUpdate","E":1788331870215,"s":"BTCUSDT","U":99555820328,"u":99555822129,"b":[["77590.29000000","6.52894000"],["77590.28000000","0.00034000"],["77590.27000000","0.00013000"],["77590.02000000","0.00014000"],["77590.01000000","0.03233000"],["77590.00000000","0.00021000"],["77589.91000000","0.00000000"],["77589.73000000","0.00000000"],["77589.40000000","0.00000000"],["77589.39000000","0.00021000"],["77589.34000000","0.00000000"],["77589.33000000","0.00021000"],["77589.32000000","0.00014000"],["77588.99000000","0.00000000"],["77588.91000000","0.00000000"],["77588.90000000","0.00000000"],["77588.80000000","0.00000000"],["77588.53000000","0.00000000"],["77588.50000000","0.00000000"],["77588.49000000","0.00021000"],["77588.29000000","0.00000000"],["77588.28000000","0.00028000"],["77588.26000000","0.00014000"],["77588.25000000","0.00014000"],["77588.24000000","2.67468000"],["77588.23000000","1.93226000"],["77588.22000000","0.00000000"],["77588.21000000","0.37779000"],["77588.19000000","0.00000000"],["77588.18000000","0.00124000"],["77587.72000000","0.00000000"],["77587.12000000","0.00000000"],["77587.11000000","0.00754000"],["77587.10000000","0.00021000"],["77587.09000000","2.23247000"],["77587.03000000","0.00007000"],["77587.02000000","1.93247000"],["77586.91000000","0.04000000"],["77586.59000000","0.00000000"],["77586.57000000","0.07775000"],["77586.56000000","0.00007000"],["77586.48000000","0.00014000"],["77586.47000000","0.00000000"],["77586.42000000","0.00400000"],["77586.38000000","0.00000000"],["77586.12000000","0.00000000"],["77585.68000000","0.00000000"],["77585.57000000","0.00000000"],["77585.56000000","1.31478000"],["77585.54000000","0.00007000"],["77585.33000000","0.07507000"],["77585.32000000","0.43506000"],["77585.31000000","0.00000000"],["77584.87000000","2.28004000"],["77584.61000000","0.00000000"],["77584.48000000","0.00408000"],["77584.16000000","0.00000000"],["77584.15000000","1.60576000"],["77584.14000000","0.00000000"],["77584.08000000","0.60102000"],["77584.07000000","0.00007000"],["77583.86000000","0.07500000"],["77583.85000000","0.75076000"],["77583.84000000","0.16884000"],["77583.80000000","0.05014000"],["77583.79000000","0.00000000"],["77583.50000000","0.00000000"],["77583.49000000","0.00000000"],["77583.48000000","0.00000000"],["77583.46000000","0.08000000"],["77582.85000000","0.00000000"],["77582.84000000","0.07712000"],["77582.83000000","0.36554000"],["77582.82000000","0.00000000"],["77582.81000000","0.07775000"],["77582.80000000","0.00000000"],["77582.78000000","0.02000000"],["77582.76000000","0.00000000"],["77582.75000000","0.00000000"],["77582.55000000","0.00000000"],["77582.53000000","0.00008000"],["77582.40000000","0.01200000"],["77582.39000000","0.00000000"],["77581.98000000","0.00000000"],["77581.97000000","0.00000000"],["77581.42000000","0.00000000"],["77581.21000000","0.00000000"],["77581.17000000","0.00000000"],["77581.16000000","0.01499000"],["77581.15000000","1.44429000"],["77581.14000000","0.03239000"],["77581.13000000","0.04244000"],["77580.86000000","0.00000000"],["77580.74000000","0.00151000"],["77580.61000000","0.00007000"],["77580.56000000","0.00007000"],["77580.14000000","0.00000000"],["77580.01000000","0.00000000"],["77580.00000000","0.03012000"],["77579.86000000","0.00000000"],["77579.69000000","0.07775000"],["77579.66000000","0.00000000"],["77579.54000000","0.00007000"],["77579.26000000","0.00000000"],["77579.15000000","0.00000000"],["77578.86000000","0.00000000"],["77578.38000000","0.00000000"],["77578.36000000","0.00000000"],["77578.06000000","0.00000000"],["77578.04000000","0.00000000"],["77578.01000000","0.00000000"],["77578.00000000","0.03000000"],["77577.65000000","0.00007000"],["77577.62000000","0.00000000"],["77577.29000000","0.00000000"],["77577.28000000","0.00000000"],["77576.76000000","0.00000000"],["77576.56000000","0.62859000"],["77576.38000000","0.00000000"],["77576.08000000","0.00000000"],["77575.86000000","0.00322000"],["77575.80000000","0.00000000"],["77575.58000000","0.00000000"],["77575.34000000","0.00000000"],["77575.33000000","0.00000000"],["77575.14000000","0.00000000"],["77574.98000000","0.00000000"],["77574.48000000","0.00008000"],["77573.47000000","0.00000000"],["77572.35000000","0.00000000"],["77572.25000000","0.00000000"],["77572.01000000","0.14061000"],["77571.76000000","0.10429000"],["77571.51000000","0.00000000"],["77571.21000000","0.00000000"],["77571.20000000","0.00000000"],["77571.01000000","0.00007000"],["77570.73000000","0.00000000"],["77570.60000000","0.00008000"],["77570.24000000","0.00000000"],["77570.19000000","0.00000000"],["77569.82000000","0.10429000"],["77569.80000000","0.07775000"],["77567.76000000","0.00000000"],["77567.42000000","0.00060000"],["77567.28000000","0.00000000"],["77567.16000000","0.00190000"],["77567.01000000","0.00008000"],["77565.92000000","0.00000000"],["77565.71000000","0.00000000"],["77565.54000000","0.00200000"],["77564.17000000","0.00257000"],["77564.11000000","0.00000000"],["77563.67000000","0.00000000"],["77563.55000000","0.00000000"],["77562.84000000","0.00022000"],["77562.18000000","0.00000000"],["77562.04000000","0.00000000"],["77561.83000000","0.00000000"],["77560.19000000","0.64495000"],["77560.00000000","1.96233000"],["77559.19000000","0.00000000"],["77558.96000000","0.00008000"],["77558.66000000","0.00000000"],["77558.61000000","0.34828000"],["77558.17000000","0.00000000"],["77557.96000000","0.00000000"],["77557.61000000","0.00000000"],["77556.43000000","0.00000000"],["77556.27000000","0.00000000"],["77555.85000000","0.00000000"],["77555.38000000","0.00000000"],["77555.08000000","0.00008000"],["77554.29000000","0.00000000"],["77554.08000000","0.00000000"],["77553.71000000","0.00000000"],["77553.44000000","0.00015000"],["77553.13000000","0.79586000"],["77552.31000000","0.00000000"],["77551.21000000","0.00008000"],["77551.03000000","0.00000000"],["77551.02000000","0.00000000"],["77550.64000000","0.00000000"],["77550.57000000","0.00000000"],["77550.41000000","0.00000000"],["77550.20000000","0.00000000"],["77549.24000000","0.49513000"],["77549.10000000","1.27719000"],["77547.08000000","0.00000000"],["77546.53000000","0.00000000"],["77546.32000000","0.00007000"],["77545.53000000","0.00000000"],["77545.44000000","0.00000000"],["77545.00000000","0.01000000"],["77544.00000000","0.03000000"],["77542.44000000","0.00000000"],["77541.07000000","0.00000000"],["77539.94000000","0.79600000"],["77526.75000000","0.79613000"],["77525.14000000","0.00321000"],["77525.13000000","0.00000000"],["77521.57000000","0.38975000"],["77520.41000000","0.00000000"],["77518.84000000","0.00321000"],["77518.83000000","0.00000000"],["77518.29000000","0.70976000"],["77517.13000000","0.00000000"],["77516.01000000","0.00321000"],["77515.50000000","0.00000000"],["77512.41000000","0.00008000"],["77512.02000000","0.00000000"],["77512.01000000","0.00000000"],["77511.93000000","0.00000000"],["77511.66000000","0.00000000"],["77503.65000000","0.00000000"],["77499.61000000","0.00000000"],["77497.93000000","0.00000000"],["77447.78000000","0.00128000"],["77440.27000000","0.00000000"],["77434.82000000","0.00008000"],["77434.41000000","0.00128000"],["77433.93000000","0.00000000"],["77426.07000000","0.00000000"],["77378.58000000","0.00000000"],["77357.23000000","0.00008000"],["77348.49000000","0.00000000"],["77279.64000000","0.00008000"],["77270.91000000","0.00000000"],["77202.05000000","0.00008000"],["77193.32000000","0.00000000"],["77124.46000000","0.00008000"],["77115.74000000","0.00000000"],["77077.39000000","0.00250000"],["77046.87000000","0.00008000"],["77038.16000000","0.00000000"],["76969.28000000","0.00008000"],["76960.58000000","0.00000000"],["76960.36000000","0.00128000"],["76819.27000000","0.00000000"],["76818.70000000","0.00069000"],["76419.08000000","0.00000000"],["75557.06000000","0.00000000"],["69824.55000000","0.00000000"],["69824.53000000","0.00000000"],["69824.00000000","0.00000000"],["62066.27000000","0.00000000"]],"a":[["77582.84000000","0.00000000"],["77582.85000000","0.00000000"],["77582.86000000","0.00000000"],["77583.49000000","0.00000000"],["77583.50000000","0.00000000"],["77583.51000000","0.00000000"],["77583.85000000","0.00000000"],["77583.86000000","0.00000000"],["77584.08000000","0.00000000"],["77584.09000000","0.00000000"],["77584.15000000","0.00000000"],["77584.16000000","0.00000000"],["77584.17000000","0.00000000"],["77584.62000000","0.00000000"],["77584.88000000","0.00000000"],["77585.32000000","0.00000000"],["77585.33000000","0.00000000"],["77585.54000000","0.00000000"],["77585.55000000","0.00000000"],["77585.56000000","0.00000000"],["77585.57000000","0.00000000"],["77585.81000000","0.00000000"],["77586.13000000","0.00000000"],["77586.39000000","0.00000000"],["77586.43000000","0.00000000"],["77586.48000000","0.00000000"],["77586.56000000","0.00000000"],["77586.57000000","0.00000000"],["77586.96000000","0.00000000"],["77587.02000000","0.00000000"],["77587.03000000","0.00000000"],["77587.08000000","0.00000000"],["77587.10000000","0.00000000"],["77587.13000000","0.00000000"],["77587.73000000","0.00000000"],["77588.18000000","0.00000000"],["77588.20000000","0.00000000"],["77588.22000000","0.00000000"],["77588.24000000","0.00000000"],["77588.28000000","0.00000000"],["77588.29000000","0.00000000"],["77588.32000000","0.00000000"],["77588.50000000","0.00000000"],["77588.54000000","0.00000000"],["77588.91000000","0.00000000"],["77588.93000000","0.00000000"],["77589.00000000","0.00000000"],["77589.33000000","0.00000000"],["77589.34000000","0.00000000"],["77589.40000000","0.00000000"],["77589.67000000","0.00000000"],["77590.01000000","0.00000000"],["77590.30000000","0.45137000"],["77590.31000000","0.00063000"],["77590.42000000","0.00007000"],["77590.47000000","0.00000000"],["77590.50000000","0.00000000"],["77590.79000000","0.00014000"],["77590.80000000","0.01466000"],["77590.83000000","0.00000000"],["77590.84000000","0.00021000"],["77591.29000000","0.00014000"],["77591.30000000","0.01278000"],["77591.38000000","0.00000000"],["77591.61000000","0.00000000"],["77591.77000000","0.00000000"],["77591.78000000","0.00007000"],["77591.80000000","0.00000000"],["77591.81000000","0.00014000"],["77591.82000000","0.13325000"],["77591.88000000","0.00000000"],["77591.94000000","0.00000000"],["77592.03000000","0.00014000"],["77592.04000000","0.01466000"],["77592.24000000","0.00008000"],["77592.30000000","0.00000000"],["77592.31000000","0.00007000"],["77592.84000000","0.00000000"],["77593.07000000","0.00000000"],["77593.10000000","0.00000000"],["77593.13000000","0.00000000"],["77593.26000000","0.00322000"],["77593.27000000","0.00014000"],["77593.28000000","0.10444000"],["77593.80000000","0.00007000"],["77593.81000000","0.00000000"],["77594.00000000","0.00000000"],["77594.11000000","0.00007000"],["77594.12000000","0.00007000"],["77594.25000000","0.00007000"],["77594.26000000","0.02906000"],["77594.30000000","0.00000000"],["77594.31000000","0.00007000"],["77594.34000000","0.00000000"],["77594.36000000","0.00007000"],["77594.37000000","0.00000000"],["77594.41000000","0.00007000"],["77594.50000000","0.00000000"],["77594.59000000","0.00000000"],["77594.68000000","0.00000000"],["77594.76000000","0.00000000"],["77594.77000000","0.11602000"],["77594.79000000","0.00000000"],["77595.05000000","0.00000000"],["77595.35000000","0.00000000"],["77595.49000000","0.00000000"],["77595.50000000","0.12887000"],["77595.55000000","0.00000000"],["77595.56000000","0.02607000"],["77595.62000000","0.00000000"],["77595.63000000","0.00208000"],["77595.65000000","0.08219000"],["77595.99000000","0.00000000"],["77596.10000000","0.00000000"],["77596.11000000","0.00000000"],["77596.16000000","0.00000000"],["77596.17000000","0.00000000"],["77596.18000000","0.11602000"],["77596.19000000","0.00000000"],["77596.20000000","0.00000000"],["77596.25000000","0.00000000"],["77596.33000000","0.00000000"],["77596.66000000","0.46167000"],["77596.80000000","0.00330000"],["77596.82000000","0.00000000"],["77596.89000000","0.00000000"],["77596.93000000","0.00000000"],["77597.01000000","0.01000000"],["77597.02000000","0.00000000"],["77597.82000000","0.00000000"],["77597.88000000","0.00000000"],["77598.06000000","0.00408000"],["77598.16000000","0.00000000"],["77598.29000000","0.00644000"],["77598.30000000","0.00014000"],["77598.51000000","0.00000000"],["77598.52000000","0.00000000"],["77598.81000000","0.00000000"],["77599.01000000","0.02000000"],["77599.12000000","0.00000000"],["77599.44000000","0.00000000"],["77600.17000000","0.00000000"],["77600.21000000","0.00000000"],["77600.22000000","0.15610000"],["77600.23000000","0.00000000"],["77600.46000000","0.00000000"],["77600.69000000","0.00000000"],["77600.70000000","0.11602000"],["77600.81000000","0.12000000"],["77600.82000000","0.00000000"],["77600.84000000","0.00000000"],["77601.06000000","0.00048000"],["77601.24000000","0.00007000"],["77601.68000000","0.00000000"],["77601.87000000","0.00190000"],["77602.05000000","0.00007000"],["77602.22000000","0.11602000"],["77602.86000000","0.11602000"],["77602.87000000","0.00644000"],["77602.88000000","0.00000000"],["77603.05000000","0.00000000"],["77603.07000000","0.00000000"],["77603.16000000","0.00000000"],["77603.80000000","0.00200000"],["77604.51000000","0.11602000"],["77604.52000000","0.04000000"],["77604.57000000","0.26958000"],["77604.72000000","0.00000000"],["77604.86000000","0.12885000"],["77605.03000000","0.00000000"],["77605.10000000","0.00000000"],["77605.11000000","0.00000000"],["77605.38000000","0.00000000"],["77605.51000000","0.00000000"],["77605.82000000","0.00008000"],["77606.69000000","0.11602000"],["77606.82000000","0.00000000"],["77606.88000000","0.38673000"],["77607.35000000","0.00000000"],["77607.78000000","0.11602000"],["77607.79000000","1.77508000"],["77607.80000000","3.59875000"],["77607.81000000","0.00000000"],["77607.82000000","0.00000000"],["77607.85000000","0.00000000"],["77608.08000000","0.00128000"],["77608.45000000","0.00000000"],["77608.57000000","0.00000000"],["77608.58000000","0.00000000"],["77608.60000000","0.00000000"],["77609.29000000","0.00000000"],["77609.30000000","0.00000000"],["77609.31000000","0.00000000"],["77609.67000000","0.00000000"],["77609.70000000","0.00008000"],["77609.99000000","0.00000000"],["77610.92000000","0.28137000"],["77610.93000000","0.00000000"],["77612.33000000","0.00000000"],["77612.47000000","0.00000000"],["77612.74000000","0.00038000"],["77613.58000000","0.00408000"],["77613.78000000","0.00000000"],["77613.88000000","0.00000000"],["77614.37000000","0.64472000"],["77614.38000000","0.00000000"],["77614.78000000","0.25788000"],["77614.79000000","0.00000000"],["77616.21000000","0.00000000"],["77616.35000000","0.00000000"],["77616.43000000","0.00000000"],["77616.65000000","0.00124000"],["77617.10000000","0.00000000"],["77617.46000000","0.00408000"],["77617.55000000","0.34778000"],["77617.68000000","1.20987000"],["77617.70000000","0.00000000"],["77618.05000000","0.00000000"],["77618.68000000","0.00000000"],["77618.82000000","0.00000000"],["77619.01000000","0.00000000"],["77619.16000000","0.00000000"],["77619.21000000","0.00000000"],["77619.46000000","0.00012000"],["77619.51000000","0.24126000"],["77619.79000000","0.00060000"],["77620.08000000","0.00000000"],["77620.09000000","0.00000000"],["77620.23000000","0.00000000"],["77620.66000000","0.00000000"],["77620.79000000","0.00000000"],["77621.20000000","0.04765000"],["77621.34000000","0.00408000"],["77621.69000000","0.00000000"],["77621.94000000","0.00014000"],["77622.00000000","0.04344000"],["77622.47000000","0.00000000"],["77622.66000000","0.00000000"],["77622.88000000","0.05513000"],["77623.00000000","0.00000000"],["77624.11000000","0.00000000"],["77624.52000000","0.64441000"],["77625.06000000","0.00000000"],["77625.22000000","0.00408000"],["77625.32000000","0.34798000"],["77625.88000000","0.00014000"],["77629.10000000","0.00008000"],["77629.82000000","0.00007000"],["77630.00000000","0.04000000"],["77633.76000000","0.00644000"],["77639.99000000","0.00000000"],["77640.26000000","0.00000000"],["77640.70000000","0.00000000"],["77641.06000000","0.00000000"],["77642.04000000","0.00000000"],["77643.32000000","0.00000000"],["77643.77000000","0.00322000"],["77645.01000000","0.00018000"],["77649.64000000","0.00321000"],["77650.83000000","0.43884000"],["77650.84000000","0.00000000"],["77652.32000000","1.27549000"],["77657.11000000","0.01712000"],["77657.34000000","0.00544000"],["77658.88000000","0.00000000"],["77667.44000000","0.09309000"],["77667.89000000","0.00008000"],["77674.42000000","0.00007000"],["77683.47000000","0.16877000"],["77684.93000000","0.00000000"],["77687.03000000","0.99415000"],["77687.04000000","0.00000000"],["77689.63000000","0.00000000"],["77717.36000000","0.00000000"],["77719.74000000","0.00000000"],["77720.69000000","0.00000000"],["77721.73000000","0.00128000"],["77726.97000000","0.00128000"],["77728.34000000","1.54468000"],["77729.38000000","0.52657000"],["77729.39000000","0.00000000"],["77729.49000000","0.00000000"],["77729.69000000","0.00000000"],["77791.42000000","0.00000000"],["77800.03000000","0.02019000"],["77816.69000000","0.00007000"],["77820.56000000","0.00007000"],["77896.59000000","0.00250000"],["77969.21000000","0.00000000"],["77972.88000000","0.00007000"],["77978.25000000","0.00264000"],["78046.79000000","0.00000000"],["78055.84000000","0.00008000"],["78124.37000000","0.00000000"],["78133.43000000","0.00008000"],["78201.95000000","0.00000000"],["78211.02000000","0.00008000"],["78746.59000000","0.00000000"],["81001.06000000","0.00000000"]]}}
{"type":"trade","received_at_ms":1788331870084,"data":{"e":"trade","E":1788331870224,"s":"BTCUSDT","t":6646634245,"p":"77590.30000000","q":"0.03223000","T":1788331870223,"m":false,"M":true}}
{"type":"depth","received_at_ms":1788331870173,"data":{"e":"depthUpdate","E":1788331870314,"s":"BTCUSDT","U":99555822130,"u":99555822342,"b":[["77590.29000000","6.74786000"],["77590.28000000","0.00934000"],["77590.26000000","0.00014000"],["77590.25000000","0.05007000"],["77590.21000000","0.00014000"],["77590.20000000","0.05000000"],["77590.01000000","0.03254000"],["77590.00000000","0.00335000"],["77589.39000000","0.00000000"],["77589.33000000","0.00000000"],["77589.32000000","0.00000000"],["77589.05000000","0.00014000"],["77589.04000000","0.01361000"],["77588.49000000","0.00007000"],["77588.28000000","0.00014000"],["77588.26000000","0.00000000"],["77588.25000000","0.00614000"],["77588.24000000","2.67468000"],["77588.23000000","1.93240000"],["77588.22000000","0.00000000"],["77588.21000000","0.37800000"],["77587.80000000","0.01633000"],["77587.79000000","0.00400000"],["77587.37000000","0.00007000"],["77587.11000000","0.00768000"],["77587.10000000","0.00007000"],["77587.02000000","1.93247000"],["77586.56000000","0.01640000"],["77585.32000000","0.43848000"],["77583.85000000","0.70076000"],["77583.80000000","0.00014000"],["77582.83000000","0.34554000"],["77582.40000000","0.00000000"],["77581.16000000","0.01299000"],["77576.00000000","0.03265000"],["77565.54000000","0.00000000"],["77562.68000000","0.00200000"],["77561.44000000","0.25000000"],["77551.00000000","0.01000000"],["77545.00000000","0.00000000"],["77366.36000000","0.00000000"],["69831.27000000","0.00032000"],["62072.00000000","0.14757000"],["62066.00000000","0.00300000"]],"a":[["77590.30000000","0.47920000"],["77590.31000000","0.00049000"],["77590.60000000","0.00000000"],["77590.79000000","0.00000000"],["77590.80000000","0.00021000"],["77590.84000000","0.00007000"],["77591.30000000","0.01299000"],["77591.78000000","0.00021000"],["77591.79000000","0.11600000"],["77591.82000000","0.13339000"],["77592.03000000","0.00000000"],["77592.04000000","0.00021000"],["77593.27000000","0.00021000"],["77593.28000000","0.10458000"],["77594.26000000","0.02920000"],["77594.36000000","0.00014000"],["77594.77000000","0.11616000"],["77595.50000000","0.12901000"],["77595.56000000","0.02607000"],["77595.63000000","0.00000000"],["77595.65000000","0.00000000"],["77596.18000000","0.11609000"],["77596.38000000","0.03007000"],["77597.50000000","0.00202000"],["77598.06000000","0.00441000"],["77598.36000000","0.00000000"],["77598.66000000","0.00000000"],["77598.98000000","0.00000000"],["77599.04000000","0.00400000"],["77599.29000000","0.00000000"],["77599.30000000","0.00000000"],["77600.32000000","0.00048000"],["77600.82000000","0.00400000"],["77601.68000000","0.00000000"],["77602.04000000","0.00257000"],["77604.50000000","0.00800000"],["77604.57000000","0.26958000"],["77605.82000000","0.00041000"],["77606.12000000","0.00000000"],["77607.78000000","0.00000000"],["77607.80000000","3.25097000"],["77613.58000000","0.00441000"],["77619.34000000","0.00000000"],["77619.88000000","0.00000000"],["77620.97000000","0.09754000"],["77621.34000000","0.00441000"],["77622.88000000","0.00000000"],["77623.52000000","0.00000000"],["77623.53000000","0.25000000"],["77625.89000000","0.00000000"],["77648.02000000","0.03867000"],["77729.38000000","0.00000000"],["77820.56000000","0.00000000"]]}}
{"type":"trade","received_at_ms":1788331870255,"data":{"e":"trade","E":1788331870394,"s":"BTCUSDT","t":6646634246,"p":"77590.29000000","q":"0.00100000","T":1788331870394,"m":true,"M":true}}
{"type":"depth","received_at_ms":1788331870273,"data":{"e":"depthUpdate","E":1788331870414,"s":"BTCUSDT","U":99555822343,"u":99555822510,"b":[["77590.29000000","6.74510000"],["77590.28000000","0.01113000"],["77590.25000000","0.05021000"],["77590.20000000","0.05014000"],["77590.01000000","0.03254000"],["77589.66000000","0.00000000"],["77589.04000000","0.01375000"],["77589.03000000","0.00400000"],["77588.25000000","0.01014000"],["77588.21000000","0.37786000"],["77587.80000000","0.01640000"],["77587.61000000","0.01301000"],["77587.11000000","0.00754000"],["77587.09000000","2.23233000"],["77587.02000000","1.93233000"],["77585.59000000","0.00027000"],["77584.15000000","0.30346000"],["77584.00000000","0.00007000"],["77583.84000000","0.00007000"],["77583.80000000","0.00007000"],["77582.83000000","0.34526000"],["77582.53000000","0.16878000"],["77581.16000000","0.00000000"],["77574.77000000","0.16870000"],["77573.09000000","0.00000000"],["77394.10000000","0.00000000"],["77386.34000000","0.00000000"],["69831.27000000","0.00064000"],["69831.26000000","0.00009000"],["62072.23000000","0.00000000"]],"a":[["77590.30000000","0.60038000"],["77590.31000000","0.00063000"],["77590.80000000","0.00007000"],["77591.29000000","0.00000000"],["77591.30000000","0.00021000"],["77591.58000000","0.00729000"],["77591.79000000","0.11614000"],["77591.82000000","0.13346000"],["77592.04000000","0.00007000"],["77592.83000000","0.01223000"],["77593.04000000","0.01277000"],["77593.28000000","0.10465000"],["77594.07000000","0.01469000"],["77594.25000000","0.00014000"],["77594.76000000","0.00007000"],["77594.77000000","0.11623000"],["77595.31000000","0.01459000"],["77595.56000000","0.02621000"],["77601.23000000","0.00200000"],["77603.80000000","0.00000000"],["77604.49000000","0.00400000"],["77622.77000000","0.79515000"],["78144.00000000","0.00080000"]]}}
{"type":"depth","received_at_ms":1788331870373,"data":{"e":"depthUpdate","E":1788331870514,"s":"BTCUSDT","U":99555822511,"u":99555822560,"b":[["77590.29000000","6.75510000"],["77590.28000000","0.01113000"],["77584.08000000","0.83838000"],["77582.83000000","0.33526000"],["77576.27000000","0.02000000"],["77568.98000000","0.00012000"],["77559.42000000","0.00000000"],["69831.27000000","0.00080000"],["62072.24000000","0.00063000"],["62072.00000000","0.14957000"]],"a":[["77590.30000000","0.60038000"],["77591.30000000","0.00007000"],["77591.58000000","0.00743000"],["77591.82000000","0.13346000"],["77592.83000000","0.01237000"],["77593.04000000","0.01291000"],["77593.28000000","0.10465000"],["77594.07000000","0.01483000"],["77594.77000000","0.11609000"],["77595.50000000","0.12887000"],["77595.56000000","0.02607000"],["77606.67000000","0.00007000"],["77607.78000000","0.34778000"],["77619.51000000","0.47395000"],["77634.39000000","0.00000000"],["77643.77000000","0.00000000"],["77643.78000000","0.17282000"],["77647.12000000","0.00322000"],["78754.16000000","0.00030000"]]}}
{"type":"depth","received_at_ms":1788331870474,"data":{"e":"depthUpdate","E":1788331870614,"s":"BTCUSDT","U":99555822561,"u":99555822776,"b":[["77590.29000000","1.66813000"],["77590.28000000","0.01106000"],["77590.26000000","0.00000000"],["77590.25000000","0.00021000"],["77590.21000000","0.00000000"],["77590.20000000","0.00014000"],["77590.02000000","0.00000000"],["77590.01000000","0.00028000"],["77590.00000000","0.00000000"],["77589.03000000","0.00000000"],["77588.26000000","0.00000000"],["77588.25000000","0.00028000"],["77588.24000000","0.67715000"],["77588.23000000","0.00014000"],["77588.22000000","0.00014000"],["77588.21000000","0.12979000"],["77587.81000000","0.00000000"],["77587.79000000","0.00000000"],["77587.31000000","0.00000000"],["77587.11000000","0.00007000"],["77587.09000000","0.00007000"],["77587.02000000","0.00007000"],["77586.58000000","0.00007000"],["77586.47000000","0.00000000"],["77585.59000000","0.00000000"],["77585.34000000","0.00083000"],["77585.33000000","0.00007000"],["77585.32000000","0.30021000"],["77584.87000000","0.34778000"],["77584.79000000","0.00000000"],["77584.55000000","0.00000000"],["77584.53000000","0.00000000"],["77584.49000000","0.00094000"],["77583.85000000","0.41269000"],["77583.63000000","0.00000000"],["77583.60000000","0.00000000"],["77583.49000000","0.00000000"],["77583.40000000","0.00000000"],["77582.84000000","0.07500000"],["77582.61000000","0.00400000"],["77581.97000000","0.00644000"],["77581.96000000","0.00000000"],["77581.31000000","0.00000000"],["77579.70000000","0.71666000"],["77578.67000000","0.00644000"],["77577.76000000","1.93233000"],["77576.57000000","0.01000000"],["77576.00000000","0.03007000"],["77574.88000000","0.00400000"],["77574.41000000","0.00000000"],["77571.16000000","0.00000000"],["77567.17000000","0.00212000"],["77562.68000000","0.00000000"],["77560.19000000","0.00000000"],["77560.03000000","0.00000000"],["77560.00000000","1.96226000"],["77559.67000000","0.00200000"],["77551.02000000","0.00007000"],["77549.24000000","0.14097000"],["77549.10000000","0.00000000"],["77517.98000000","1.27770000"],["77511.94000000","0.00200000"],["77466.52000000","0.00012000"],["77457.38000000","0.00000000"],["77453.91000000","0.00000000"],["69831.27000000","0.00096000"],["62072.24000000","0.00031000"]],"a":[["77590.30000000","2.35415000"],["77590.31000000","0.00049000"],["77590.42000000","0.00014000"],["77591.09000000","0.00014000"],["77591.10000000","0.08219000"],["77591.18000000","0.00208000"],["77591.22000000","0.00007000"],["77591.23000000","0.00027000"],["77591.58000000","0.00750000"],["77591.78000000","0.00007000"],["77591.79000000","0.00014000"],["77591.80000000","0.00014000"],["77591.81000000","0.18169000"],["77592.00000000","0.00008000"],["77592.45000000","0.00400000"],["77594.51000000","0.00527000"],["77594.76000000","0.00000000"],["77596.20000000","0.00000000"],["77596.59000000","0.00257000"],["77596.62000000","0.04000000"],["77596.66000000","0.42699000"],["77596.67000000","0.00000000"],["77596.75000000","0.00331000"],["77597.12000000","0.00000000"],["77598.96000000","0.00000000"],["77599.04000000","0.00000000"],["77600.22000000","0.47237000"],["77600.32000000","0.00000000"],["77600.69000000","0.01200000"],["77600.70000000","0.00000000"],["77600.82000000","0.00000000"],["77602.04000000","0.00000000"],["77602.22000000","0.11615000"],["77602.86000000","0.00000000"],["77603.71000000","1.43086000"],["77604.49000000","0.00000000"],["77604.50000000","0.00000000"],["77604.51000000","0.00000000"],["77604.52000000","0.00000000"],["77606.68000000","0.00000000"],["77606.69000000","0.00000000"],["77625.30000000","1.27593000"],["77625.43000000","0.02559000"],["77629.82000000","0.00000000"],["77650.83000000","0.00000000"],["77652.32000000","0.00000000"],["77695.34000000","0.00000000"],["77697.70000000","0.00000000"],["77702.45000000","0.00000000"]]}}
{"type":"trade","received_at_ms":1788331870565,"data":{"e":"trade","E":1788331870705,"s":"BTCUSDT","t":6646634247,"p":"77590.30000000","q":"0.00064000","T":1788331870705,"m":false,"M":true}}
{"type":"depth","received_at_ms":1788331870573,"data":{"e":"depthUpdate","E":1788331870714,"s":"BTCUSDT","U":99555822777,"u":99555822909,"b":[["77590.29000000","1.66814000"],["77590.28000000","0.01106000"],["77590.25000000","0.00000000"],["77590.20000000","0.00000000"],["77590.01000000","0.00014000"],["77589.04000000","0.01382000"],["77588.25000000","0.00014000"],["77588.24000000","0.67715000"],["77588.23000000","0.00000000"],["77588.21000000","0.12993000"],["77587.80000000","0.01654000"],["77587.61000000","0.01315000"],["77586.92000000","0.00007000"],["77586.91000000","0.04014000"],["77586.57000000","0.07789000"],["77585.32000000","0.00028000"],["77577.77000000","0.00400000"],["77564.60000000","0.00000000"],["77463.06000000","0.00011000"],["69831.27000000","0.00112000"],["69831.26000000","0.00000000"],["69831.25000000","0.00009000"],["62072.23000000","0.00020000"]],"a":[["77590.30000000","2.37525000"],["77590.31000000","0.00070000"],["77590.80000000","0.00000000"],["77591.10000000","0.08233000"],["77591.23000000","0.00000000"],["77591.30000000","0.00000000"],["77591.58000000","0.00750000"],["77591.79000000","0.00000000"],["77591.81000000","0.18183000"],["77593.27000000","0.00007000"],["77593.28000000","0.00021000"],["77593.80000000","0.00338000"],["77594.26000000","0.02913000"],["77594.76000000","0.00007000"],["77596.61000000","0.00000000"],["77598.06000000","0.00434000"],["77600.09000000","0.00200000"],["77600.22000000","1.01216000"],["77600.80000000","0.00400000"],["77601.06000000","0.00000000"],["77601.23000000","0.00000000"],["77601.87000000","0.00000000"],["77602.22000000","0.00000000"],["77603.06000000","1.93226000"],["77603.71000000","1.31471000"],["77605.82000000","0.00034000"],["77613.58000000","0.00434000"],["77621.34000000","0.00434000"],["77704.52000000","0.00012000"],["77706.87000000","0.00019000"]]}}
{"type":"depth","received_at_ms":1788331870674,"data":{"e":"depthUpdate","E":1788331870814,"s":"BTCUSDT","U":99555822910,"u":99555822940,"b":[["77590.29000000","1.57746000"],["77586.48000000","0.00007000"],["77585.58000000","0.00027000"],["77583.85000000","0.00007000"],["77581.21000000","0.00047000"],["77550.00000000","0.03007000"],["69831.27000000","0.00144000"],["62072.23000000","0.00000000"]],"a":[["77590.30000000","2.38036000"],["77593.04000000","0.01291000"],["77593.28000000","0.00007000"],["77593.54000000","0.00007000"],["77594.26000000","0.02927000"],["77594.85000000","0.00257000"],["77596.59000000","0.00000000"],["77620.01000000","0.14824000"],["77623.65000000","0.05307000"],["77711.62000000","0.00032000"]]}}
{"type":"depth","received_at_ms":1788331870774,"data":{"e":"depthUpdate","E":1788331870914,"s":"BTCUSDT","U":99555822941,"u":99555822952,"b":[["77553.85000000","0.07775000"],["77517.07000000","0.00000000"],["77485.91000000","0.00000000"],["76426.43000000","0.00030000"]],"a":[["77590.30000000","2.38029000"],["77590.31000000","0.00063000"],["77592.45000000","0.00000000"],["77604.12000000","0.00000000"],["77643.78000000","0.16870000"],["77643.96000000","0.00012000"],["77673.83000000","0.00000000"]]}}
{"type":"depth","received_at_ms":1788331870874,"data":{"e":"depthUpdate","E":1788331871014,"s":"BTCUSDT","U":99555822953,"u":99555822984,"b":[["77590.29000000","1.76599000"],["77584.49000000","0.00000000"],["77584.01000000","0.00103000"],["77582.83000000","0.31526000"],["77581.22000000","0.00644000"],["77578.67000000","0.00000000"],["77576.56000000","0.00000000"],["77572.94000000","0.62859000"],["69831.27000000","0.00160000"],["62078.00000000","0.00000000"],["62072.24000000","0.00063000"],["62065.00000000","0.00000000"]],"a":[["77590.30000000","2.55234000"],["77590.31000000","0.00076000"],["77590.32000000","0.00013000"],["77594.17000000","0.00644000"],["77595.03000000","0.00644000"],["77598.29000000","0.00000000"],["77602.87000000","0.00000000"],["77605.99000000","0.28425000"],["77609.99000000","0.25789000"],["77610.92000000","0.00000000"],["77610.93000000","0.64474000"],["77614.37000000","0.00000000"],["77614.78000000","0.00000000"],["77623.28000000","0.00408000"],["77625.22000000","0.00008000"]]}}
{"type":"depth","received_at_ms":1788331870973,"data":{"e":"depthUpdate","E":1788331871114,"s":"BTCUSDT","U":99555822985,"u":99555822998,"b":[["77577.71000000","0.00007000"],["75557.06000000","0.00010000"],["69831.27000000","0.00160000"]],"a":[["77594.07000000","0.01483000"],["77594.17000000","0.00658000"],["77594.26000000","0.02913000"],["77611.18000000","0.00412000"],["85349.32000000","0.00383000"]]}}
{"type":"depth","received_at_ms":1788331871079,"data":{"e":"depthUpdate","E":1788331871214,"s":"BTCUSDT","U":99555822999,"u":99555823024,"b":[["77590.25000000","0.00015000"],["77583.35000000","0.00007000"],["77578.65000000","0.12890000"],["77578.61000000","0.00200000"],["77576.57000000","0.00800000"],["77571.01000000","0.00007000"],["77563.13000000","0.12892000"],["77504.98000000","0.00007000"],["77381.66000000","0.00000000"],["77378.67000000","0.00813000"],["76884.58000000","0.00000000"],["69831.27000000","0.00176000"],["62072.24000000","0.00031000"],["62072.00000000","0.14957000"]],"a":[["77591.18000000","0.00000000"],["77591.99000000","0.00007000"],["77594.07000000","0.01490000"],["77595.03000000","0.00000000"],["77596.11000000","0.00644000"],["77596.18000000","0.11602000"],["77596.38000000","0.03000000"],["77596.66000000","0.31097000"],["77602.05000000","0.00007000"],["77605.99000000","0.00000000"],["77606.87000000","0.31227000"],["77613.27000000","0.12884000"],["85349.32000000","0.00000000"]]}}
{"type":"trade","received_at_ms":1788331871164,"data":{"e":"trade","E":1788331871305,"s":"BTCUSDT","t":6646634248,"p":"77590.30000000","q":"0.00011000","T":1788331871304,"m":false,"M":true}}
{"type":"depth","received_at_ms":1788331871173,"data":{"e":"depthUpdate","E":1788331871314,"s":"BTCUSDT","U":99555823025,"u":99555823135,"b":[["77590.29000000","1.03577000"],["77590.25000000","0.00000000"],["77588.21000000","0.00035000"],["77586.56000000","0.01647000"],["77586.42000000","0.00000000"],["77586.41000000","0.08427000"],["77585.34000000","0.00000000"],["77585.32000000","0.00021000"],["77584.88000000","0.00000000"],["77584.16000000","0.00000000"],["77584.07000000","0.00000000"],["77584.01000000","0.00000000"],["77583.86000000","0.00000000"],["77582.85000000","0.00085000"],["77582.83000000","0.31190000"],["77582.61000000","0.00000000"],["77582.54000000","0.00414000"],["77581.97000000","0.00000000"],["77581.76000000","0.00000000"],["77581.57000000","0.00000000"],["77581.23000000","0.00103000"],["77581.22000000","0.00000000"],["77581.04000000","0.00048000"],["77580.61000000","0.00407000"],["77580.31000000","0.00189000"],["77580.23000000","0.00644000"],["77580.22000000","0.00000000"],["77578.67000000","0.00000000"],["77578.61000000","0.00000000"],["77577.77000000","0.00000000"],["77577.66000000","0.00257000"],["77576.87000000","0.00644000"],["77576.57000000","0.00000000"],["77574.49000000","0.01200000"],["77572.95000000","0.00200000"],["77572.94000000","0.00000000"],["77568.92000000","0.62862000"],["77561.93000000","0.00412000"],["77561.57000000","0.00000000"],["77559.88000000","0.00000000"],["77559.67000000","0.00000000"],["77557.61000000","0.00200000"],["77551.50000000","0.00400000"],["77547.08000000","0.00007000"],["77543.95000000","0.34834000"],["77525.14000000","0.00000000"],["77525.03000000","0.00321000"],["77516.64000000","1.27772000"],["77447.78000000","0.00128000"],["69831.27000000","0.00176000"],["69831.25000000","0.00000000"],["69831.00000000","0.00000000"]],"a":[["77590.30000000","2.55445000"],["77590.31000000","0.00090000"],["77591.69000000","0.00400000"],["77592.24000000","0.00408000"],["77592.39000000","0.00257000"],["77594.51000000","0.00127000"],["77594.85000000","0.00000000"],["77596.37000000","0.11615000"],["77596.61000000","0.01600000"],["77598.90000000","0.38677000"],["77600.09000000","0.00000000"],["77600.69000000","0.00000000"],["77600.80000000","0.00000000"],["77603.70000000","0.26625000"],["77604.57000000","0.40821000"],["77606.87000000","0.64474000"],["77608.59000000","0.83767000"],["77610.93000000","0.00000000"],["77623.28000000","0.00008000"],["77625.30000000","0.00000000"],["77625.54000000","0.00000000"],["81001.06000000","0.00010000"]]}}
{"type":"depth","received_at_ms":1788331871273,"data":{"e":"depthUpdate","E":1788331871414,"s":"BTCUSDT","U":99555823136,"u":99555823203,"b":[["77590.29000000","1.03570000"],["77590.28000000","0.01106000"],["77588.24000000","0.67715000"],["77588.22000000","0.00000000"],["77588.21000000","0.00021000"],["77586.92000000","0.00014000"],["77586.56000000","0.01661000"],["77582.85000000","0.00000000"],["77582.67000000","0.00334000"],["77581.24000000","0.00088000"],["77580.70000000","0.00000000"],["77580.66000000","0.00000000"],["77580.61000000","0.00007000"],["77577.77000000","0.00000000"],["77574.49000000","0.00000000"],["77573.96000000","0.00800000"],["77573.77000000","0.00400000"],["77572.95000000","0.00000000"],["77561.00000000","0.00515000"],["77557.61000000","0.00000000"],["77554.17000000","0.00200000"],["69831.27000000","0.00192000"],["62072.23000000","0.00000000"],["62072.00000000","0.14957000"]],"a":[["77590.30000000","2.55431000"],["77590.31000000","0.00069000"],["77590.83000000","0.00644000"],["77591.46000000","0.00339000"],["77592.24000000","0.00747000"],["77592.39000000","0.00000000"],["77592.41000000","0.00257000"],["77594.17000000","0.00014000"],["77595.49000000","0.00200000"],["77595.56000000","0.02600000"],["77596.16000000","1.09823000"],["77596.17000000","1.93226000"],["77596.18000000","0.00000000"],["77596.37000000","0.00000000"],["77596.61000000","0.00000000"],["77596.66000000","0.00008000"],["77598.29000000","0.01600000"],["77606.86000000","0.25790000"],["77609.99000000","0.00000000"]]}}
{"type":"depth","received_at_ms":1788331871373,"data":{"e":"depthUpdate","E":1788331871514,"s":"BTCUSDT","U":99555823204,"u":99555823238,"b":[["77572.94000000","0.00000000"],["77564.40000000","0.50147000"],["77523.14000000","0.00412000"],["77518.29000000","1.41166000"],["69831.27000000","0.00176000"],["62072.24000000","0.00063000"]],"a":[["77590.30000000","2.55859000"],["77590.31000000","0.00083000"],["77590.83000000","0.00658000"],["77591.82000000","0.13353000"],["77594.07000000","0.01469000"],["77594.17000000","0.00000000"],["77595.49000000","0.00000000"],["77596.15000000","1.31471000"],["77607.89000000","0.00200000"],["77614.88000000","0.00000000"],["77621.34000000","0.00034000"],["77651.99000000","0.03781000"],["77728.33000000","0.52672000"],["78754.16000000","0.00030000"]]}}
{"type":"depth","received_at_ms":1788331871474,"data":{"e":"depthUpdate","E":1788331871614,"s":"BTCUSDT","U":99555823239,"u":99555823255,"b":[["77581.23000000","0.00000000"],["77580.81000000","0.00010000"],["77578.93000000","0.00257000"],["77577.66000000","0.00000000"],["77569.35000000","0.00200000"],["77547.08000000","0.00000000"],["69831.27000000","0.00208000"],["62072.24000000","0.00031000"],["62072.00000000","0.14957000"]],"a":[["77592.41000000","0.00000000"],["77594.44000000","0.00257000"],["77600.53000000","0.03210000"]]}}
{"type":"depth","received_at_ms":1788331871573,"data":{"e":"depthUpdate","E":1788331871714,"s":"BTCUSDT","U":99555823256,"u":99555823266,"b":[["77586.41000000","0.08219000"],["77492.12000000","0.00412000"],["77378.67000000","0.00000000"],["77373.13000000","0.00813000"],["69831.27000000","0.00208000"],["62072.00000000","0.14957000"]],"a":[["77590.30000000","2.55866000"],["77590.31000000","0.00090000"],["77591.80000000","0.00214000"]]}}
{"type":"depth","received_at_ms":1788331871673,"data":{"e":"depthUpdate","E":1788331871814,"s":"BTCUSDT","U":99555823267,"u":99555823275,"b":[["77578.93000000","0.00000000"],["77577.90000000","0.00257000"],["77547.08000000","0.00007000"],["69831.27000000","0.00208000"],["62072.23000000","0.00000000"]],"a":[["77593.41000000","0.00257000"],["77594.44000000","0.00000000"]]}}
{"type":"depth","received_at_ms":1788331871773,"data":{"e":"depthUpdate","E":1788331871914,"s":"BTCUSDT","U":99555823276,"u":99555823285,"b":[["77590.29000000","1.03577000"],["77590.28000000","0.01113000"],["77586.58000000","0.00215000"],["76426.43000000","0.00030000"],["69831.27000000","0.00240000"],["63581.14000000","0.01100000"]],"a":[["77681.04000000","0.00412000"]]}}
{"type":"depth","received_at_ms":1788331871874,"data":{"e":"depthUpdate","E":1788331872014,"s":"BTCUSDT","U":99555823286,"u":99555823292,"b":[["77582.54000000","0.00495000"],["77581.24000000","0.00000000"],["69831.27000000","0.00240000"],["62072.24000000","0.00063000"]],"a":[["77596.14000000","0.09622000"],["77604.58000000","0.00000000"],["77681.85000000","1.29787000"],["77684.45000000","2.15391000"]]}}
{"type":"depth","received_at_ms":1788331871973,"data":{"e":"depthUpdate","E":1788331872114,"s":"BTCUSDT","U":99555823293,"u":99555823306,"b":[["77584.15000000","0.30007000"],["77584.05000000","0.00342000"],["77582.67000000","0.00000000"],["77582.50000000","0.00339000"],["77581.14000000","0.01837000"],["77561.00000000","0.70515000"],["77445.42000000","0.00000000"],["69831.27000000","0.00256000"]],"a":[["77590.30000000","2.55995000"],["77596.14000000","0.00000000"],["77603.05000000","0.09622000"],["77679.03000000","0.00000000"]]}}
{"type":"depth","received_at_ms":1788331872076,"data":{"e":"depthUpdate","E":1788331872215,"s":"BTCUSDT","U":99555823307,"u":99555823320,"b":[["77590.29000000","1.04690000"],["77584.48000000","0.00421000"],["77571.01000000","0.00007000"],["76891.98000000","0.00032000"],["62072.24000000","0.00031000"]],"a":[["77590.30000000","2.55988000"],["77590.31000000","0.00083000"],["77591.80000000","0.00014000"],["77592.82000000","0.00200000"],["77596.11000000","0.00657000"],["77602.05000000","0.00007000"],["77686.50000000","0.00025000"],["79000.00000000","46.14957000"]]}}
{"type":"trade","received_at_ms":1788331872164,"data":{"e":"trade","E":1788331872305,"s":"BTCUSDT","t":6646634249,"p":"77590.30000000","q":"0.00257000","T":1788331872305,"m":false,"M":true}}
{"type":"depth","received_at_ms":1788331872176,"data":{"e":"depthUpdate","E":1788331872314,"s":"BTCUSDT","U":99555823321,"u":99555823340,"b":[["77586.91000000","0.00014000"],["77561.93000000","0.00000000"],["77523.14000000","0.00000000"],["77492.12000000","0.00000000"],["77487.99000000","0.04884000"],["69831.27000000","0.00281000"],["69831.00000000","0.00000000"],["62072.00000000","0.14957000"]],"a":[["77590.30000000","2.55731000"],["77611.18000000","0.00000000"],["77649.99000000","0.00000000"],["77681.04000000","0.00000000"]]}}
{"type":"trade","received_at_ms":1788331872176,"data":{"e":"trade","E":1788331872316,"s":"BTCUSDT","t":6646634250,"p":"77590.30000000","q":"0.00382000","T":1788331872316,"m":false,"M":true}}
{"type":"depth","received_at_ms":1788331872273,"data":{"e":"depthUpdate","E":1788331872414,"s":"BTCUSDT","U":99555823341,"u":99555823369,"b":[["77590.29000000","1.04683000"],["77590.28000000","0.01106000"],["77588.21000000","0.00014000"],["77587.61000000","0.01315000"],["77587.11000000","0.00000000"],["77587.09000000","0.00026000"],["77586.92000000","0.00000000"],["77586.91000000","0.00000000"],["77586.58000000","0.00222000"],["77586.42000000","0.00007000"],["77580.81000000","0.00000000"],["69831.27000000","0.00281000"],["62072.23000000","0.00000000"],["62072.00000000","0.14957000"]],"a":[["77590.30000000","2.55287000"],["77592.24000000","0.00761000"]]}}
{"type":"depth","received_at_ms":1788331872373,"data":{"e":"depthUpdate","E":1788331872514,"s":"BTCUSDT","U":99555823370,"u":99555823378,"b":[["69831.27000000","0.00297000"],["62072.24000000","0.00063000"]],"a":[["77590.30000000","2.55287000"],["77620.97000000","0.00000000"],["77621.72000000","0.09428000"],["77676.92000000","0.00412000"],["78754.16000000","0.00030000"]]}}
{"type":"depth","received_at_ms":1788331872473,"data":{"e":"depthUpdate","E":1788331872614,"s":"BTCUSDT","U":99555823379,"u":99555823386,"b":[["77556.38000000","0.00000000"],["77552.55000000","0.09876000"],["69831.27000000","0.00297000"],["62072.24000000","0.00031000"],["62066.00000000","0.00300000"]],"a":[["77590.30000000","2.55280000"]]}}
{"type":"depth","received_at_ms":1788331872572,"data":{"e":"depthUpdate","E":1788331872714,"s":"BTCUSDT","U":99555823387,"u":99555823392,"b":[["77522.91000000","0.00412000"],["69831.27000000","0.00313000"]],"a":[["77602.64000000","0.00128000"],["77608.08000000","0.00000000"]]}}
{"type":"depth","received_at_ms":1788331872673,"data":{"e":"depthUpdate","E":1788331872814,"s":"BTCUSDT","U":99555823393,"u":99555823394,"b":[["62072.23000000","0.00000000"]],"a":[]}}
{"type":"trade","received_at_ms":1788331872744,"data":{"e":"trade","E":1788331872885,"s":"BTCUSDT","t":6646634251,"p":"77590.30000000","q":"0.00064000","T":1788331872884,"m":false,"M":true}}
{"type":"depth","received_at_ms":1788331872772,"data":{"e":"depthUpdate","E":1788331872914,"s":"BTCUSDT","U":99555823395,"u":99555823403,"b":[["76426.43000000","0.00030000"],["69831.27000000","0.00320000"],["69831.26000000","0.00009000"]],"a":[["77590.30000000","2.55223000"],["77645.88000000","0.00412000"]]}}
{"type":"trade","received_at_ms":1788331872836,"data":{"e":"trade","E":1788331872977,"s":"BTCUSDT","t":6646634252,"p":"77590.30000000","q":"0.00100000","T":1788331872977,"m":false,"M":true}}
{"type":"depth","received_at_ms":1788331872873,"data":{"e":"depthUpdate","E":1788331873014,"s":"BTCUSDT","U":99555823404,"u":99555823409,"b":[["69831.27000000","0.00320000"],["62072.24000000","0.00063000"],["62072.00000000","0.14957000"]],"a":[["77590.30000000","2.55123000"]]}}
{"type":"depth","received_at_ms":1788331872973,"data":{"e":"depthUpdate","E":1788331873114,"s":"BTCUSDT","U":99555823410,"u":99555823410,"b":[["69831.27000000","0.00336000"]],"a":[]}}
{"type":"depth","received_at_ms":1788331873073,"data":{"e":"depthUpdate","E":1788331873214,"s":"BTCUSDT","U":99555823411,"u":99555823413,"b":[["69831.27000000","0.00336000"],["62072.24000000","0.00031000"]],"a":[]}}
{"type":"depth","received_at_ms":1788331873173,"data":{"e":"depthUpdate","E":1788331873314,"s":"BTCUSDT","U":99555823414,"u":99555823421,"b":[["77571.01000000","0.00007000"],["69831.27000000","0.00352000"]],"a":[["77590.30000000","2.55656000"],["77602.05000000","0.00007000"]]}}
{"type":"depth","received_at_ms":1788331873273,"data":{"e":"depthUpdate","E":1788331873414,"s":"BTCUSDT","U":99555823422,"u":99555823427,"b":[["69831.27000000","0.00352000"],["69831.00000000","0.00000000"],["62072.23000000","0.00000000"]],"a":[]}}
{"type":"depth","received_at_ms":1788331873373,"data":{"e":"depthUpdate","E":1788331873514,"s":"BTCUSDT","U":99555823428,"u":99555823434,"b":[["69831.27000000","0.00368000"],["65146.32000000","0.00000000"],["62072.24000000","0.00063000"],["62072.00000000","0.14957000"]],"a":[["78754.16000000","0.00030000"]]}}
{"type":"trade","received_at_ms":1788331873473,"data":{"e":"trade","E":1788331873613,"s":"BTCUSDT","t":6646634253,"p":"77590.29000000","q":"0.00205000","T":1788331873613,"m":true,"M":true}}
{"type":"depth","received_at_ms":1788331873473,"data":{"e":"depthUpdate","E":1788331873614,"s":"BTCUSDT","U":99555823435,"u":99555823439,"b":[["77590.29000000","1.04478000"],["69831.27000000","0.00384000"],["62072.24000000","0.00031000"]],"a":[]}}
{"type":"depth","received_at_ms":1788331873573,"data":{"e":"depthUpdate","E":1788331873714,"s":"BTCUSDT","U":99555823440,"u":99555823448,"b":[["77586.41000000","0.08233000"],["69831.27000000","0.00368000"],["69831.26000000","0.00000000"]],"a":[["77590.30000000","2.55642000"],["77607.07000000","0.00412000"],["77620.01000000","0.12841000"],["77623.65000000","0.00000000"]]}}
{"type":"depth","received_at_ms":1788331873673,"data":{"e":"depthUpdate","E":1788331873814,"s":"BTCUSDT","U":99555823449,"u":99555823459,"b":[["71374.65000000","0.00015000"],["69831.27000000","0.00400000"],["65146.32000000","0.01188000"],["62072.23000000","0.00000000"]],"a":[["77590.30000000","2.55656000"],["77611.63000000","0.04684000"],["77621.20000000","0.00000000"],["77716.96000000","0.00000000"]]}}
{"type":"depth","received_at_ms":1788331873772,"data":{"e":"depthUpdate","E":1788331873914,"s":"BTCUSDT","U":99555823460,"u":99555823465,"b":[["76426.43000000","0.00030000"],["69831.27000000","0.00400000"]],"a":[["77590.30000000","2.55642000"]]}}
{"type":"trade","received_at_ms":1788331873867,"data":{"e":"trade","E":1788331874008,"s":"BTCUSDT","t":6646634254,"p":"77590.29000000","q":"0.00100000","T":1788331874007,"m":true,"M":true}}
{"type":"depth","received_at_ms":1788331873873,"data":{"e":"depthUpdate","E":1788331874014,"s":"BTCUSDT","U":99555823466,"u":99555823475,"b":[["77590.29000000","1.04378000"],["77582.54000000","0.00414000"],["77581.22000000","0.00081000"],["69831.27000000","0.00416000"],["69831.26000000","0.00009000"],["62072.24000000","0.00063000"]],"a":[["77590.30000000","2.76041000"]]}}
{"type":"depth","received_at_ms":1788331873974,"data":{"e":"depthUpdate","E":1788331874114,"s":"BTCUSDT","U":99555823476,"u":99555823476,"b":[["77580.81000000","0.00015000"]],"a":[]}}
{"type":"depth","received_at_ms":1788331874072,"data":{"e":"depthUpdate","E":1788331874214,"s":"BTCUSDT","U":99555823477,"u":99555823486,"b":[["77587.09000000","0.00007000"],["77533.13000000","0.25784000"],["77528.80000000","0.00000000"],["69831.27000000","0.00432000"],["62072.24000000","0.00031000"]],"a":[["77590.30000000","2.76034000"],["77620.27000000","0.02011000"],["77623.92000000","0.05470000"]]}}
{"type":"depth","received_at_ms":1788331874173,"data":{"e":"depthUpdate","E":1788331874314,"s":"BTCUSDT","U":99555823487,"u":99555823496,"b":[["77571.01000000","0.00007000"],["77491.89000000","0.00412000"],["69831.27000000","0.00432000"],["62072.00000000","0.14957000"]],"a":[["77602.05000000","0.00007000"]]}}
{"type":"depth","received_at_ms":1788331874272,"data":{"e":"depthUpdate","E":1788331874414,"s":"BTCUSDT","U":99555823497,"u":99555823502,"b":[["71374.65000000","0.00000000"],["69831.27000000","0.00432000"],["69831.00000000","0.00000000"]],"a":[["77590.30000000","2.76209000"]]}}
{"type":"depth","received_at_ms":1788331874374,"data":{"e":"depthUpdate","E":1788331874514,"s":"BTCUSDT","U":99555823503,"u":99555823519,"b":[["77586.96000000","0.00018000"],["77561.70000000","0.00412000"],["77522.91000000","0.00000000"],["77491.89000000","0.00000000"],["69831.27000000","0.00432000"],["62072.24000000","0.00063000"],["62072.23000000","0.00000000"]],"a":[["77590.30000000","2.76224000"],["77590.34000000","0.00875000"],["77607.07000000","0.00000000"],["77645.88000000","0.00000000"],["77676.92000000","0.00000000"],["78754.16000000","0.00030000"]]}}
{"type":"depth","received_at_ms":1788331874473,"data":{"e":"depthUpdate","E":1788331874614,"s":"BTCUSDT","U":99555823520,"u":99555823547,"b":[["69831.27000000","0.00432000"],["62072.24000000","0.00031000"],["62072.00000000","0.14957000"]],"a":[["77590.30000000","2.76238000"],["77590.34000000","0.00889000"],["77591.81000000","0.11798000"],["77593.04000000","0.01277000"],["77594.76000000","0.00000000"],["77594.77000000","0.00007000"],["77595.49000000","0.00007000"]]}}
{"type":"trade","received_at_ms":1788331874487,"data":{"e":"trade","E":1788331874624,"s":"BTCUSDT","t":6646634255,"p":"77590.29000000","q":"0.00285000","T":1788331874623,"m":true,"M":true}}
{"type":"trade","received_at_ms":1788331874491,"data":{"e":"trade","E":1788331874628,"s":"BTCUSDT","t":6646634256,"p":"77590.29000000","q":"0.00269000","T":1788331874627,"m":true,"M":true}}
{"type":"trade","received_at_ms":1788331874562,"data":{"e":"trade","E":1788331874702,"s":"BTCUSDT","t":6646634257,"p":"77590.30000000","q":"0.00011000","T":1788331874702,"m":false,"M":true}}
{"type":"depth","received_at_ms":1788331874575,"data":{"e":"depthUpdate","E":1788331874714,"s":"BTCUSDT","U":99555823548,"u":99555823562,"b":[["77590.29000000","1.03824000"],["77588.38000000","0.00018000"],["77586.96000000","0.00000000"],["69831.26000000","0.00000000"],["69831.25000000","0.00009000"]],"a":[["77590.30000000","2.76227000"],["77596.14000000","0.00000000"],["77603.05000000","0.09622000"],["77676.94000000","0.00412000"],["77681.85000000","0.75095000"],["77684.45000000","0.00000000"],["77687.03000000","1.50999000"],["77687.04000000","2.15391000"]]}}
{"type":"depth","received_at_ms":1788331874674,"data":{"e":"depthUpdate","E":1788331874814,"s":"BTCUSDT","U":99555823563,"u":99555823568,"b":[["69831.27000000","0.00432000"],["62072.23000000","0.00000000"]],"a":[]}}
{"type":"depth","received_at_ms":1788331874785,"data":{"e":"depthUpdate","E":1788331874914,"s":"BTCUSDT","U":99555823569,"u":99555823578,"b":[["76426.43000000","0.00030000"],["69831.27000000","0.00448000"],["62072.00000000","0.14957000"]],"a":[["77590.30000000","2.76213000"],["77607.09000000","0.00412000"]]}}
{"type":"depth","received_at_ms":1788331874873,"data":{"e":"depthUpdate","E":1788331875014,"s":"BTCUSDT","U":99555823579,"u":99555823593,"b":[["77590.29000000","1.03824000"],["77588.38000000","0.00000000"],["77588.24000000","0.45691000"],["77585.32000000","0.00014000"],["77584.87000000","0.00000000"],["77580.81000000","0.00000000"],["77580.32000000","0.00016000"],["69831.27000000","0.00416000"],["62072.24000000","0.00063000"]],"a":[["77596.13000000","0.09622000"],["77596.14000000","0.11615000"],["77602.57000000","0.10419000"],["77603.05000000","0.00000000"],["77604.51000000","0.10419000"]]}}
{"type":"depth","received_at_ms":1788331874973,"data":{"e":"depthUpdate","E":1788331875114,"s":"BTCUSDT","U":99555823594,"u":99555823604,"b":[["77590.29000000","0.80041000"],["77582.84000000","0.00000000"],["77582.78000000","0.00000000"],["77580.81000000","0.02000000"],["77454.56000000","0.00020000"],["69831.27000000","0.00448000"]],"a":[["77591.98000000","0.00644000"],["77594.77000000","0.11622000"],["77596.11000000","0.00013000"],["77645.90000000","0.00412000"],["77726.12000000","0.00020000"]]}}
{"type":"depth","received_at_ms":1788331875073,"data":{"e":"depthUpdate","E":1788331875214,"s":"BTCUSDT","U":99555823605,"u":99555823645,"b":[["77590.29000000","0.80041000"],["77584.48000000","0.00021000"],["77583.66000000","0.00017000"],["77580.23000000","0.00000000"],["77578.67000000","0.00644000"],["77577.90000000","0.00000000"],["77572.94000000","0.00200000"],["77569.35000000","0.00000000"],["77558.61000000","0.00000000"],["77547.62000000","0.00400000"],["77535.23000000","0.34838000"],["69831.27000000","0.00432000"],["62072.24000000","0.00031000"]],"a":[["77590.30000000","2.76213000"],["77590.31000000","0.00076000"],["77591.81000000","0.24587000"],["77591.82000000","0.13360000"],["77591.98000000","0.00658000"],["77592.83000000","0.01223000"],["77593.41000000","0.00000000"],["77594.41000000","0.00000000"],["77594.76000000","0.00007000"],["77596.11000000","0.34791000"],["77604.39000000","0.34807000"],["77608.00000000","0.03265000"],["77625.32000000","0.00000000"],["77684.45000000","2.15391000"],["77687.03000000","0.99415000"],["77687.04000000","0.00000000"]]}}
{"type":"depth","received_at_ms":1788331875173,"data":{"e":"depthUpdate","E":1788331875314,"s":"BTCUSDT","U":99555823646,"u":99555823662,"b":[["77582.54000000","0.00014000"],["77580.74000000","0.00000000"],["77572.94000000","0.00000000"],["77572.15000000","0.00163000"],["77571.01000000","0.00007000"],["77570.01000000","0.00000000"],["77568.99000000","0.00200000"],["77553.44000000","0.00415000"],["77522.93000000","0.00412000"],["69831.27000000","0.00432000"]],"a":[["77590.30000000","2.76850000"],["77590.31000000","0.00069000"],["77590.83000000","0.00014000"],["77602.05000000","0.00007000"]]}}
{"type":"trade","received_at_ms":1788331875186,"data":{"e":"trade","E":1788331875326,"s":"BTCUSDT","t":6646634258,"p":"77590.29000000","q":"0.00382000","T":1788331875326,"m":true,"M":true}}
{"type":"depth","received_at_ms":1788331875273,"data":{"e":"depthUpdate","E":1788331875414,"s":"BTCUSDT","U":99555823663,"u":99555823721,"b":[["77590.29000000","0.50227000"],["77590.28000000","0.01106000"],["77586.58000000","0.00014000"],["77586.42000000","0.00000000"],["77586.41000000","0.00014000"],["77585.57000000","0.00007000"],["77584.15000000","0.00007000"],["77573.96000000","0.00000000"],["77573.26000000","0.00400000"],["77572.94000000","0.00400000"],["77568.92000000","0.00000000"],["77566.79000000","0.62862000"],["77458.70000000","0.00000000"],["69831.27000000","0.00432000"],["69831.25000000","0.00000000"]],"a":[["77590.30000000","3.06786000"],["77590.31000000","0.00027000"],["77590.34000000","0.00889000"],["77590.83000000","0.00000000"],["77592.83000000","0.01237000"],["77595.49000000","0.00000000"]]}}
{"type":"depth","received_at_ms":1788331875373,"data":{"e":"depthUpdate","E":1788331875514,"s":"BTCUSDT","U":99555823722,"u":99555823761,"b":[["77590.29000000","0.50234000"],["77590.28000000","0.01113000"],["77590.01000000","0.00007000"],["77588.25000000","0.00000000"],["77588.24000000","0.00014000"],["77587.81000000","0.00014000"],["77587.62000000","0.00014000"],["77586.56000000","0.01661000"],["77586.41000000","0.00000000"],["77585.82000000","0.11622000"],["77585.57000000","0.50880000"],["77585.56000000","1.31492000"],["77580.32000000","0.00000000"],["77579.68000000","0.00011000"],["69831.27000000","0.00448000"],["69831.00000000","0.00000000"],["62072.24000000","0.00063000"],["62072.23000000","0.00000000"]],"a":[["78754.16000000","0.00030000"]]}}
{"type":"depth","received_at_ms":1788331875473,"data":{"e":"depthUpdate","E":1788331875614,"s":"BTCUSDT","U":99555823762,"u":99555823807,"b":[["77590.29000000","0.69414000"],["77589.04000000","0.01375000"],["77588.24000000","0.00000000"],["77586.56000000","0.01661000"],["77585.82000000","0.11636000"],["77585.57000000","0.50894000"],["77585.56000000","1.31478000"],["77584.49000000","0.00017000"],["77583.66000000","0.00000000"],["69831.27000000","0.00432000"],["62072.24000000","0.00031000"],["62072.00000000","0.14957000"]],"a":[["77590.30000000","3.06484000"],["77590.31000000","0.00069000"],["77596.14000000","0.00000000"]]}}
{"type":"depth","received_at_ms":1788331875573,"data":{"e":"depthUpdate","E":1788331875714,"s":"BTCUSDT","U":99555823808,"u":99555823854,"b":[["77590.29000000","0.69406000"],["77568.00000000","0.03007000"],["77561.70000000","0.00000000"],["77560.00000000","1.96484000"],["77522.93000000","0.00000000"],["77491.91000000","0.00000000"],["77419.97000000","0.00000000"],["69831.27000000","0.00448000"]],"a":[["77590.30000000","3.06172000"],["77590.31000000","0.00076000"],["77591.10000000","0.08240000"],["77591.22000000","0.00656000"],["77607.09000000","0.00000000"],["77645.90000000","0.00000000"],["77676.94000000","0.00000000"]]}}
{"type":"depth","received_at_ms":1788331875675,"data":{"e":"depthUpdate","E":1788331875814,"s":"BTCUSDT","U":99555823855,"u":99555823878,"b":[["77590.29000000","0.69414000"],["77585.34000000","0.00020000"],["77584.49000000","0.00000000"],["77573.26000000","0.00000000"],["77573.11000000","0.00800000"],["77572.94000000","0.00000000"],["69831.27000000","0.00432000"],["62072.23000000","0.00000000"],["59355.87000000","0.00000000"]],"a":[["77590.30000000","3.05918000"],["77591.10000000","0.08240000"],["77591.22000000","0.00670000"],["77592.83000000","0.01223000"],["81444.00000000","0.06594000"]]}}
{"type":"depth","received_at_ms":1788331875773,"data":{"e":"depthUpdate","E":1788331875914,"s":"BTCUSDT","U":99555823879,"u":99555823887,"b":[["77488.02000000","0.00412000"],["76426.43000000","0.00030000"],["69831.27000000","0.00432000"]],"a":[["77590.30000000","3.06018000"],["77706.96000000","0.00000000"]]}}
{"type":"depth","received_at_ms":1788331875873,"data":{"e":"depthUpdate","E":1788331876014,"s":"BTCUSDT","U":99555823888,"u":99555823892,"b":[["62072.24000000","0.00063000"],["62072.00000000","0.14957000"]],"a":[]}}
{"type":"depth","received_at_ms":1788331875974,"data":{"e":"depthUpdate","E":1788331876114,"s":"BTCUSDT","U":99555823893,"u":99555823901,"b":[["77555.38000000","0.00400000"],["77547.62000000","0.00000000"],["75557.06000000","0.00000000"],["69831.27000000","0.00432000"]],"a":[["77621.72000000","0.00000000"],["81001.06000000","0.00000000"],["81444.00000000","0.16906000"]]}}
{"type":"depth","received_at_ms":1788331876074,"data":{"e":"depthUpdate","E":1788331876214,"s":"BTCUSDT","U":99555823902,"u":99555823909,"b":[["77586.18000000","0.00000000"],["77585.34000000","0.00000000"],["69831.27000000","0.00432000"],["62072.24000000","0.00031000"]],"a":[["77682.30000000","0.00087000"],["77745.81000000","0.00000000"]]}}
{"type":"depth","received_at_ms":1788331876173,"data":{"e":"depthUpdate","E":1788331876315,"s":"BTCUSDT","U":99555823910,"u":99555823939,"b":[["77590.29000000","0.69428000"],["77585.57000000","0.50901000"],["77585.15000000","0.09904000"],["77584.69000000","0.00208000"],["77576.57000000","0.00257000"],["69831.27000000","0.00432000"],["62072.00000000","0.14957000"]],"a":[["77590.30000000","3.06086000"],["77590.31000000","0.00069000"],["77590.34000000","0.00896000"],["77591.09000000","0.00000000"],["77591.10000000","0.00021000"],["77591.22000000","0.00021000"],["77591.46000000","0.00988000"],["77592.07000000","0.00383000"],["77594.76000000","0.00014000"],["77595.49000000","0.00007000"]]}}
{"type":"depth","received_at_ms":1788331876275,"data":{"e":"depthUpdate","E":1788331876415,"s":"BTCUSDT","U":99555823940,"u":99555823959,"b":[["77571.01000000","0.00007000"],["69831.27000000","0.00448000"],["62072.00000000","0.14957000"]],"a":[["77590.34000000","0.00896000"],["77591.10000000","0.00007000"],["77591.22000000","0.00007000"],["77591.46000000","0.01002000"],["77592.83000000","0.01237000"],["77602.05000000","0.00007000"]]}}
{"type":"depth","received_at_ms":1788331876375,"data":{"e":"depthUpdate","E":1788331876514,"s":"BTCUSDT","U":99555823960,"u":99555823971,"b":[["69831.27000000","0.00432000"],["62072.24000000","0.00063000"],["62072.23000000","0.00000000"],["62072.00000000","0.14957000"]],"a":[["77701.87000000","0.02019000"],["77710.32000000","0.00000000"],["78754.16000000","0.00030000"]]}}
{"type":"trade","received_at_ms":1788331876442,"data":{"e":"trade","E":1788331876583,"s":"BTCUSDT","t":6646634259,"p":"77590.30000000","q":"0.00100000","T":1788331876582,"m":false,"M":true}}
{"type":"depth","received_at_ms":1788331876474,"data":{"e":"depthUpdate","E":1788331876614,"s":"BTCUSDT","U":99555823972,"u":99555823989,"b":[["69831.27000000","0.00441000"],["69831.00000000","0.00000000"],["62072.24000000","0.00031000"]],"a":[["77590.30000000","3.05989000"],["77598.06000000","0.00437000"],["77605.82000000","0.00037000"],["77613.58000000","0.00437000"],["77621.34000000","0.00037000"],["77622.08000000","0.09792000"]]}}
{"type":"depth","received_at_ms":1788331876575,"data":{"e":"depthUpdate","E":1788331876714,"s":"BTCUSDT","U":99555823990,"u":99555824007,"b":[["77584.75000000","0.00016000"],["77579.68000000","0.00000000"],["77564.40000000","0.00000000"],["77538.01000000","0.00000000"],["69831.27000000","0.00441000"],["62072.00000000","0.14957000"]],"a":[["77591.10000000","0.00000000"],["77591.22000000","0.00000000"],["77591.46000000","0.00353000"],["77591.58000000","0.01460000"],["77645.89000000","0.00412000"],["77681.85000000","1.29812000"]]}}
{"type":"depth","received_at_ms":1788331876673,"data":{"e":"depthUpdate","E":1788331876814,"s":"BTCUSDT","U":99555824008,"u":99555824029,"b":[["77577.42000000","0.00257000"],["77576.57000000","0.00000000"],["69831.27000000","0.00457000"],["62072.23000000","0.00000000"]],"a":[["77590.30000000","3.05975000"],["77590.34000000","0.00896000"],["77591.46000000","0.00339000"],["77591.57000000","0.00014000"],["77592.07000000","0.00126000"],["77592.93000000","0.00257000"],["77593.04000000","0.01291000"],["77595.49000000","0.00000000"]]}}
{"type":"depth","received_at_ms":1788331876775,"data":{"e":"depthUpdate","E":1788331876914,"s":"BTCUSDT","U":99555824030,"u":99555824035,"b":[["77519.05000000","0.00412000"],["76426.43000000","0.00030000"],["75557.06000000","0.00010000"],["69831.27000000","0.00425000"]],"a":[]}}
{"type":"trade","received_at_ms":1788331876835,"data":{"e":"trade","E":1788331876975,"s":"BTCUSDT","t":6646634260,"p":"77590.29000000","q":"0.00257000","T":1788331876975,"m":true,"M":true}}
{"type":"depth","received_at_ms":1788331876873,"data":{"e":"depthUpdate","E":1788331877014,"s":"BTCUSDT","U":99555824036,"u":99555824045,"b":[["77590.29000000","0.69371000"],["69831.27000000","0.00448000"],["69831.26000000","0.00009000"],["62072.24000000","0.00063000"],["62066.00000000","0.00100000"]],"a":[["77590.30000000","3.05982000"]]}}
{"type":"trade","received_at_ms":1788331876886,"data":{"e":"trade","E":1788331877026,"s":"BTCUSDT","t":6646634261,"p":"77590.30000000","q":"0.00037000","T":1788331877026,"m":false,"M":true}}
{"type":"depth","received_at_ms":1788331876973,"data":{"e":"depthUpdate","E":1788331877114,"s":"BTCUSDT","U":99555824046,"u":99555824055,"b":[["77585.82000000","0.11654000"],["77584.75000000","0.00000000"],["77561.96000000","0.49739000"],["77538.69000000","0.99854000"],["69831.27000000","0.00432000"]],"a":[["77590.30000000","3.05945000"],["77607.08000000","0.00412000"],["81001.06000000","0.00010000"]]}}
{"type":"depth","received_at_ms":1788331877073,"data":{"e":"depthUpdate","E":1788331877214,"s":"BTCUSDT","U":99555824056,"u":99555824058,"b":[["69831.27000000","0.00432000"],["62072.24000000","0.00031000"]],"a":[]}}
{"type":"depth","received_at_ms":1788331877174,"data":{"e":"depthUpdate","E":1788331877314,"s":"BTCUSDT","U":99555824059,"u":99555824083,"b":[["77590.29000000","0.86233000"],["77587.31000000","0.11615000"],["77586.62000000","0.00020000"],["77585.83000000","0.00800000"],["77585.82000000","0.11636000"],["77573.77000000","0.00000000"],["77573.11000000","0.00000000"],["77572.94000000","0.00200000"],["77568.99000000","0.00000000"],["69831.27000000","0.00448000"]],"a":[["77590.30000000","2.75966000"],["77594.76000000","0.00000000"],["77594.77000000","0.00007000"],["77595.49000000","0.00007000"],["77596.11000000","0.00013000"],["77596.17000000","0.00000000"]]}}
{"type":"trade","received_at_ms":1788331877237,"data":{"e":"trade","E":1788331877374,"s":"BTCUSDT","t":6646634262,"p":"77590.30000000","q":"0.00037000","T":1788331877374,"m":false,"M":true}}
{"type":"depth","received_at_ms":1788331877276,"data":{"e":"depthUpdate","E":1788331877414,"s":"BTCUSDT","U":99555824084,"u":99555824192,"b":[["77590.29000000","1.07522000"],["77590.28000000","0.01127000"],["77587.61000000","0.01322000"],["77587.32000000","0.00007000"],["77587.31000000","0.11636000"],["77587.16000000","0.10112000"],["77586.62000000","0.00000000"],["77586.58000000","0.00007000"],["77586.56000000","0.01668000"],["77585.83000000","0.00014000"],["77585.82000000","0.11629000"],["77585.59000000","1.22410000"],["77585.58000000","2.28031000"],["77585.57000000","0.00000000"],["77585.15000000","0.00000000"],["77584.69000000","0.00000000"],["77582.81000000","0.37775000"],["77582.55000000","0.00068000"],["77582.53000000","0.46878000"],["77582.50000000","0.30339000"],["77581.22000000","0.00000000"],["77578.40000000","0.00257000"],["77577.77000000","0.00000000"],["77577.42000000","0.00000000"],["77574.78000000","0.00800000"],["77574.49000000","0.00800000"],["77571.01000000","0.00007000"],["77547.08000000","0.00000000"],["77466.15000000","0.00074000"],["69831.27000000","0.00448000"],["69831.26000000","0.00000000"]],"a":[["77590.30000000","2.85196000"],["77590.31000000","0.00069000"],["77591.58000000","0.01467000"],["77591.68000000","0.00644000"],["77591.81000000","0.11807000"],["77591.98000000","0.00014000"],["77592.82000000","0.00000000"],["77592.93000000","0.00000000"],["77593.04000000","0.01298000"],["77593.25000000","0.00644000"],["77593.53000000","0.00200000"],["77593.90000000","0.00257000"],["77596.13000000","0.00000000"],["77596.14000000","0.45216000"],["77596.15000000","0.00000000"],["77596.16000000","0.00000000"],["77602.05000000","0.00007000"],["77603.05000000","0.09622000"],["77681.85000000","0.75095000"],["77684.45000000","0.00000000"],["77687.04000000","2.15391000"]]}}
{"type":"depth","received_at_ms":1788331877372,"data":{"e":"depthUpdate","E":1788331877514,"s":"BTCUSDT","U":99555824193,"u":99555824294,"b":[["77590.29000000","1.07577000"],["77588.80000000","0.11444000"],["77587.31000000","0.11636000"],["77587.16000000","0.00014000"],["77586.56000000","0.01668000"],["77586.48000000","0.00014000"],["77585.83000000","0.01200000"],["77585.82000000","0.11622000"],["77584.82000000","0.00340000"],["77581.04000000","0.00000000"],["77578.40000000","0.00000000"],["77574.78000000","0.00400000"],["77574.49000000","0.00000000"],["77572.94000000","0.00200000"],["77570.73000000","0.00000000"],["77557.83000000","0.00412000"],["77487.99000000","0.00000000"],["69831.27000000","0.00448000"],["62072.24000000","0.00063000"],["62072.23000000","0.00000000"]],"a":[["77590.30000000","2.68326000"],["77590.31000000","0.00069000"],["77590.34000000","0.00889000"],["77591.46000000","0.00000000"],["77591.57000000","0.00000000"],["77591.58000000","0.00757000"],["77591.67000000","0.00014000"],["77591.68000000","0.01275000"],["77591.69000000","0.00000000"],["77591.82000000","0.13353000"],["77591.98000000","0.00000000"],["77593.04000000","0.01298000"],["77593.25000000","0.00000000"],["77593.90000000","0.00000000"],["77595.30000000","0.00644000"],["77596.06000000","0.00257000"],["77597.05000000","0.00000000"],["77598.06000000","0.17307000"],["77598.20000000","0.00400000"],["77598.28000000","0.00000000"],["77598.29000000","0.00400000"],["77608.00000000","0.03007000"],["77720.81000000","0.00000000"],["78754.16000000","0.00030000"]]}}
{"type":"depth","received_at_ms":1788331877473,"data":{"e":"depthUpdate","E":1788331877614,"s":"BTCUSDT","U":99555824295,"u":99555824364,"b":[["77590.29000000","1.07767000"],["77590.28000000","0.01134000"],["77590.14000000","0.00014000"],["77590.13000000","0.09904000"],["77589.69000000","0.00208000"],["77589.04000000","0.01382000"],["77588.81000000","0.00014000"],["77588.80000000","0.11458000"],["77587.62000000","0.00000000"],["77587.32000000","0.00000000"],["77587.31000000","0.11629000"],["77587.16000000","0.00000000"],["77586.58000000","0.00000000"],["77586.56000000","0.01668000"],["77583.43000000","0.00400000"],["77580.31000000","0.00000000"],["77568.00000000","0.03265000"],["77498.72000000","0.05431000"],["77496.20000000","0.03997000"],["77427.41000000","0.00074000"],["69831.27000000","0.00448000"],["62072.24000000","0.00031000"],["62072.00000000","0.14957000"]],"a":[["77590.30000000","2.68319000"],["77590.31000000","0.00069000"],["77593.04000000","0.01291000"],["77593.53000000","0.00000000"],["77594.31000000","0.00407000"],["77594.76000000","0.00200000"],["77596.06000000","0.00000000"],["77596.85000000","0.00257000"],["77729.05000000","0.00971000"]]}}
{"type":"trade","received_at_ms":1788331877475,"data":{"e":"trade","E":1788331877616,"s":"BTCUSDT","t":6646634263,"p":"77590.29000000","q":"0.00100000","T":1788331877616,"m":true,"M":true}}
{"type":"trade","received_at_ms":1788331877505,"data":{"e":"trade","E":1788331877644,"s":"BTCUSDT","t":6646634264,"p":"77590.30000000","q":"0.05054000","T":1788331877643,"m":false,"M":true}}
{"type":"trade","received_at_ms":1788331877505,"data":{"e":"trade","E":1788331877646,"s":"BTCUSDT","t":6646634265,"p":"77590.30000000","q":"0.00352000","T":1788331877646,"m":false,"M":true}}
{"type":"depth","received_at_ms":1788331877573,"data":{"e":"depthUpdate","E":1788331877714,"s":"BTCUSDT","U":99555824365,"u":99555824395,"b":[["77590.29000000","1.51617000"],["77590.28000000","0.01134000"],["77590.13000000","0.09918000"],["77586.56000000","0.01654000"],["77378.67000000","0.00813000"],["77373.13000000","0.00000000"],["69831.27000000","0.00473000"],["69831.00000000","0.00000000"]],"a":[["77590.30000000","2.54968000"],["77594.31000000","0.00007000"],["77595.08000000","0.00400000"],["77687.03000000","1.50999000"]]}}
{"type":"depth","received_at_ms":1788331877673,"data":{"e":"depthUpdate","E":1788331877814,"s":"BTCUSDT","U":99555824396,"u":99555824408,"b":[["77590.29000000","1.51617000"],["77586.56000000","0.01647000"],["77585.83000000","0.00000000"],["77585.60000000","0.00400000"],["77448.10000000","0.00000000"],["69831.27000000","0.00457000"],["65951.75000000","0.06054000"]],"a":[["77590.30000000","2.54868000"]]}}
{"type":"depth","received_at_ms":1788331877775,"data":{"e":"depthUpdate","E":1788331877914,"s":"BTCUSDT","U":99555824409,"u":99555824422,"b":[["77590.29000000","1.68039000"],["77582.54000000","0.00414000"],["77551.50000000","0.00000000"],["77451.71000000","0.02019000"],["76426.43000000","0.00030000"],["69831.27000000","0.00473000"],["62072.23000000","0.00000000"],["62072.00000000","0.14957000"]],"a":[["77590.30000000","2.54876000"],["77714.43000000","0.00085000"]]}}
{"type":"depth","received_at_ms":1788331877873,"data":{"e":"depthUpdate","E":1788331878014,"s":"BTCUSDT","U":99555824423,"u":99555824442,"b":[["77590.29000000","1.68046000"],["77590.28000000","0.01141000"],["77588.81000000","0.00000000"],["77588.80000000","0.00014000"],["77587.32000000","0.00007000"],["77584.06000000","0.00064000"],["77582.84000000","0.00644000"],["77582.83000000","0.30607000"],["77582.55000000","0.00000000"],["77582.54000000","0.30414000"],["77576.87000000","0.00000000"],["69831.27000000","0.00457000"],["62072.24000000","0.00063000"]],"a":[["77595.30000000","0.00000000"],["77596.87000000","0.00644000"],["77606.86000000","0.00000000"],["77608.58000000","0.25790000"]]}}
{"type":"trade","received_at_ms":1788331877966,"data":{"e":"trade","E":1788331878106,"s":"BTCUSDT","t":6646634266,"p":"77590.30000000","q":"0.00137000","T":1788331878106,"m":false,"M":true}}
{"type":"depth","received_at_ms":1788331877974,"data":{"e":"depthUpdate","E":1788331878114,"s":"BTCUSDT","U":99555824443,"u":99555824465,"b":[["77590.29000000","1.68046000"],["77589.04000000","0.01375000"],["77588.80000000","0.00000000"],["77586.56000000","0.01661000"],["77557.83000000","0.00000000"],["77519.05000000","0.00000000"],["77488.02000000","0.00000000"],["69831.27000000","0.00464000"],["69831.26000000","0.00009000"]],"a":[["77590.30000000","2.54739000"],["77607.08000000","0.00000000"],["77645.89000000","0.00000000"],["77676.93000000","0.00412000"],["77753.28000000","0.00085000"]]}}
{"type":"trade","received_at_ms":1788331878005,"data":{"e":"trade","E":1788331878146,"s":"BTCUSDT","t":6646634267,"p":"77590.29000000","q":"0.00386000","T":1788331878145,"m":true,"M":true}}
{"type":"depth","received_at_ms":1788331878072,"data":{"e":"depthUpdate","E":1788331878214,"s":"BTCUSDT","U":99555824466,"u":99555824472,"b":[["77590.29000000","1.67660000"],["69831.27000000","0.00448000"],["62072.24000000","0.00031000"]],"a":[["77590.30000000","2.39158000"]]}}
{"type":"depth","received_at_ms":1788331878174,"data":{"e":"depthUpdate","E":1788331878314,"s":"BTCUSDT","U":99555824473,"u":99555824570,"b":[["77590.29000000","1.73542000"],["77590.28000000","0.01127000"],["77585.88000000","0.00400000"],["77585.34000000","0.00064000"],["77584.06000000","0.00000000"],["77583.43000000","0.00000000"],["77583.14000000","0.03210000"],["77581.21000000","0.00000000"],["77579.94000000","0.00163000"],["77572.15000000","0.00000000"],["69831.27000000","0.00464000"],["62072.00000000","0.14957000"]],"a":[["77590.30000000","2.23416000"],["77591.67000000","0.00000000"],["77591.68000000","0.00014000"],["77593.04000000","0.01298000"],["77593.79000000","0.00644000"],["77594.76000000","0.00000000"],["77595.08000000","0.00000000"],["77595.49000000","0.00214000"],["77595.55000000","0.00007000"],["77596.85000000","0.00257000"],["77596.87000000","0.00000000"],["77596.95000000","0.00400000"],["77597.09000000","0.00000000"],["77597.15000000","0.00000000"],["77597.40000000","0.00000000"],["77598.20000000","0.00000000"],["77598.29000000","0.00000000"],["77598.89000000","0.00644000"],["77599.58000000","0.00000000"],["77599.68000000","0.00800000"],["77599.78000000","0.00000000"],["77600.09000000","0.00000000"],["77600.22000000","0.51449000"],["77600.53000000","0.00000000"],["77603.04000000","0.00400000"],["77603.06000000","0.00000000"],["77603.70000000","0.00000000"],["77605.35000000","0.29740000"],["77606.87000000","0.00000000"],["77607.80000000","3.24697000"],["77607.89000000","0.00000000"],["77608.57000000","0.64475000"],["77609.96000000","0.00200000"],["77611.63000000","0.00000000"],["77614.24000000","0.04589000"],["77687.03000000","0.99415000"],["77687.04000000","0.00000000"],["77689.63000000","2.15391000"]]}}
{"type":"depth","received_at_ms":1788331878273,"data":{"e":"depthUpdate","E":1788331878414,"s":"BTCUSDT","U":99555824571,"u":99555824616,"b":[["77590.29000000","1.73542000"],["77585.34000000","0.00000000"],["77584.49000000","0.00063000"],["77584.48000000","0.00421000"],["77571.01000000","0.00007000"],["77560.00000000","1.96226000"],["77553.44000000","0.00015000"],["69831.27000000","0.00448000"],["62072.00000000","0.14957000"]],"a":[["77590.30000000","2.22735000"],["77590.31000000","0.00062000"],["77591.58000000","0.00750000"],["77591.68000000","0.00000000"],["77593.04000000","0.01298000"],["77593.79000000","0.00658000"],["77596.71000000","0.00400000"],["77596.76000000","0.00000000"],["77596.95000000","0.00000000"],["77598.89000000","0.01044000"],["77599.20000000","0.00189000"],["77599.44000000","0.00000000"],["77599.68000000","0.00400000"],["77602.05000000","0.00007000"],["77620.27000000","0.00000000"],["77623.92000000","0.00000000"],["77625.22000000","0.00408000"]]}}
{"type":"depth","received_at_ms":1788331878374,"data":{"e":"depthUpdate","E":1788331878514,"s":"BTCUSDT","U":99555824617,"u":99555824635,"b":[["77590.29000000","1.73542000"],["77582.91000000","0.00257000"],["77551.02000000","0.00000000"],["69831.27000000","0.00448000"],["62072.24000000","0.00063000"],["62072.23000000","0.00000000"]],"a":[["77590.30000000","2.34708000"],["77590.42000000","0.00007000"],["77596.85000000","0.00000000"],["77597.64000000","0.00257000"],["77599.14000000","0.00048000"],["77607.17000000","0.00412000"],["78754.16000000","0.00000000"]]}}
{"type":"depth","received_at_ms":1788331878474,"data":{"e":"depthUpdate","E":1788331878614,"s":"BTCUSDT","U":99555824636,"u":99555824646,"b":[["77590.29000000","1.74373000"],["69831.27000000","0.00448000"],["62072.24000000","0.00031000"],["62072.00000000","0.14957000"]],"a":[["77590.30000000","2.34764000"],["77599.14000000","0.00000000"],["78754.16000000","0.00030000"]]}}
{"type":"depth","received_at_ms":1788331878574,"data":{"e":"depthUpdate","E":1788331878714,"s":"BTCUSDT","U":99555824647,"u":99555824658,"b":[["77590.29000000","1.73790000"],["77582.91000000","0.00000000"],["77551.02000000","0.00007000"],["69831.27000000","0.00464000"]],"a":[["77590.30000000","2.22696000"],["77590.42000000","0.00014000"],["77689.33000000","0.65982000"]]}}
{"type":"depth","received_at_ms":1788331878672,"data":{"e":"depthUpdate","E":1788331878814,"s":"BTCUSDT","U":99555824659,"u":99555824676,"b":[["77590.29000000","1.73797000"],["77589.54000000","0.00338000"],["77587.31000000","0.11636000"],["77586.98000000","0.04000000"],["77585.66000000","0.00328000"],["77551.02000000","0.00000000"],["77381.66000000","0.00813000"],["77378.67000000","0.00000000"],["69831.27000000","0.00432000"]],"a":[["77590.30000000","2.22744000"],["77590.42000000","0.00007000"],["77701.87000000","0.00000000"]]}}
{"type":"depth","received_at_ms":1788331878774,"data":{"e":"depthUpdate","E":1788331878914,"s":"BTCUSDT","U":99555824677,"u":99555824714,"b":[["77590.29000000","1.73804000"],["77590.28000000","0.01134000"],["77587.31000000","0.11636000"],["77586.98000000","0.04014000"],["77586.56000000","0.01647000"],["77585.88000000","0.00000000"],["77585.23000000","0.00400000"],["77557.93000000","0.00412000"],["76426.43000000","0.00030000"],["69831.27000000","0.00448000"],["62072.23000000","0.00000000"]],"a":[["77590.30000000","2.39606000"],["77591.78000000","0.00585000"],["77620.41000000","0.02009000"],["77624.05000000","0.05323000"],["77709.88000000","0.02019000"]]}}
{"type":"depth","received_at_ms":1788331878873,"data":{"e":"depthUpdate","E":1788331879014,"s":"BTCUSDT","U":99555824715,"u":99555824741,"b":[["77590.29000000","1.73818000"],["69831.27000000","0.00448000"],["62072.24000000","0.00063000"],["62072.00000000","0.14957000"]],"a":[["77590.30000000","2.53962000"],["77590.31000000","0.00069000"],["77591.58000000","0.00750000"],["77591.78000000","0.00599000"],["77593.79000000","0.00644000"],["77656.18000000","0.00000000"],["77661.22000000","0.25783000"]]}}
{"type":"depth","received_at_ms":1788331878975,"data":{"e":"depthUpdate","E":1788331879114,"s":"BTCUSDT","U":99555824742,"u":99555824749,"b":[["77590.29000000","1.73818000"],["77552.55000000","0.00000000"],["69831.27000000","0.00448000"]],"a":[["77590.30000000","2.53954000"]]}}
{"type":"depth","received_at_ms":1788331879072,"data":{"e":"depthUpdate","E":1788331879214,"s":"BTCUSDT","U":99555824750,"u":99555824756,"b":[["77590.29000000","1.73818000"],["69831.27000000","0.00464000"],["62072.24000000","0.00031000"]],"a":[["77590.30000000","2.54428000"]]}}
{"type":"depth","received_at_ms":1788331879174,"data":{"e":"depthUpdate","E":1788331879314,"s":"BTCUSDT","U":99555824757,"u":99555824767,"b":[["77590.29000000","1.73818000"],["77586.98000000","0.00014000"],["69831.27000000","0.00448000"]],"a":[["77590.30000000","2.54972000"],["77645.98000000","0.00412000"]]}}
{"type":"depth","received_at_ms":1788331879273,"data":{"e":"depthUpdate","E":1788331879414,"s":"BTCUSDT","U":99555824768,"u":99555824784,"b":[["77590.29000000","1.74401000"],["77587.31000000","0.11629000"],["77586.98000000","0.00000000"],["77586.56000000","0.01661000"],["77571.01000000","0.00000000"],["77394.36000000","0.02019000"],["77361.26000000","0.00000000"],["69831.27000000","0.00464000"]],"a":[["77590.30000000","2.55066000"],["77602.05000000","0.00000000"]]}}
{"type":"depth","received_at_ms":1788331879373,"data":{"e":"depthUpdate","E":1788331879514,"s":"BTCUSDT","U":99555824785,"u":99555824797,"b":[["77590.29000000","1.74401000"],["77571.01000000","0.00007000"],["77519.15000000","0.00412000"],["71383.07000000","0.00015000"],["69831.27000000","0.00448000"],["62072.24000000","0.00063000"],["62072.23000000","0.00000000"],["62072.00000000","0.15157000"]],"a":[["77602.05000000","0.00007000"]]}}
{"type":"depth","received_at_ms":1788331879473,"data":{"e":"depthUpdate","E":1788331879614,"s":"BTCUSDT","U":99555824798,"u":99555824807,"b":[["77590.29000000","1.74401000"],["77560.50000000","0.09478000"],["69831.27000000","0.00464000"],["62072.24000000","0.00031000"]],"a":[["77590.30000000","2.55368000"],["78754.16000000","0.00030000"]]}}
{"type":"depth","received_at_ms":1788331879574,"data":{"e":"depthUpdate","E":1788331879714,"s":"BTCUSDT","U":99555824808,"u":99555824816,"b":[["77590.29000000","1.74725000"],["77551.02000000","0.00007000"],["69831.27000000","0.00448000"]],"a":[["77590.42000000","0.00014000"]]}}
{"type":"depth","received_at_ms":1788331879673,"data":{"e":"depthUpdate","E":1788331879814,"s":"BTCUSDT","U":99555824817,"u":99555824826,"b":[["77590.29000000","1.74733000"],["77584.49000000","0.00000000"],["77584.06000000","0.00060000"],["77582.85000000","0.00257000"],["77565.19000000","0.04508000"],["77558.68000000","0.00000000"],["77408.91000000","0.00000000"],["69831.27000000","0.00464000"],["69831.00000000","0.00020000"]],"a":[]}}
{"type":"depth","received_at_ms":1788331879774,"data":{"e":"depthUpdate","E":1788331879914,"s":"BTCUSDT","U":99555824827,"u":99555824837,"b":[["77590.29000000","1.74150000"],["77582.85000000","0.00000000"],["77582.84000000","0.00901000"],["69831.27000000","0.00448000"],["69831.00000000","0.00000000"],["62072.23000000","0.00000000"]],"a":[]}}
{"type":"depth","received_at_ms":1788331879874,"data":{"e":"depthUpdate","E":1788331880014,"s":"BTCUSDT","U":99555824838,"u":99555824849,"b":[["77590.29000000","1.74733000"],["77582.84000000","0.00644000"],["77582.83000000","0.30864000"],["76426.43000000","0.00030000"],["71383.07000000","0.00000000"],["69831.27000000","0.00464000"],["62072.24000000","0.00063000"]],"a":[["77590.30000000","2.55559000"],["77599.20000000","0.00000000"]]}}
{"type":"depth","received_at_ms":1788331879973,"data":{"e":"depthUpdate","E":1788331880114,"s":"BTCUSDT","U":99555824850,"u":99555824858,"b":[["77590.29000000","1.74733000"],["77582.83000000","0.30607000"],["77582.82000000","0.00257000"],["77412.59000000","4.38427000"],["69831.27000000","0.00432000"]],"a":[["77590.30000000","2.55555000"]]}}
{"type":"trade","received_at_ms":1788331880062,"data":{"e":"trade","E":1788331880200,"s":"BTCUSDT","t":6646634268,"p":"77590.30000000","q":"0.00100000","T":1788331880200,"m":false,"M":true}}
{"type":"depth","received_at_ms":1788331880074,"data":{"e":"depthUpdate","E":1788331880214,"s":"BTCUSDT","U":99555824859,"u":99555824873,"b":[["77582.82000000","0.30257000"],["77582.50000000","0.00339000"],["77551.74000000","0.02575000"],["77545.45000000","0.00000000"],["69831.27000000","0.00464000"],["69831.26000000","0.00000000"],["62072.24000000","0.00031000"]],"a":[["77590.30000000","2.55477000"],["77625.43000000","0.00000000"],["77629.35000000","0.02481000"]]}}
{"type":"depth","received_at_ms":1788331880172,"data":{"e":"depthUpdate","E":1788331880314,"s":"BTCUSDT","U":99555824874,"u":99555824906,"b":[["77590.29000000","1.74733000"],["77585.60000000","0.00800000"],["77582.55000000","0.00010000"],["77581.79000000","0.00400000"],["69831.27000000","0.00448000"],["62072.00000000","0.15157000"]],"a":[["77590.30000000","2.56163000"],["77590.31000000","0.00076000"],["77592.66000000","0.00400000"],["77597.05000000","0.00400000"],["77791.02000000","0.02019000"],["77800.03000000","0.00000000"]]}}
{"type":"depth","received_at_ms":1788331880273,"data":{"e":"depthUpdate","E":1788331880414,"s":"BTCUSDT","U":99555824907,"u":99555824935,"b":[["77590.29000000","1.59681000"],["77585.82000000","0.11629000"],["77585.61000000","0.00400000"],["77585.23000000","0.00000000"],["77584.32000000","0.00400000"],["77582.55000000","0.00000000"],["77581.80000000","0.00010000"],["69831.27000000","0.00432000"]],"a":[["77590.30000000","2.83151000"],["77597.05000000","0.00000000"],["77598.88000000","0.00800000"]]}}
{"type":"depth","received_at_ms":1788331880375,"data":{"e":"depthUpdate","E":1788331880514,"s":"BTCUSDT","U":99555824936,"u":99555824950,"b":[["77590.29000000","1.59681000"],["77589.54000000","0.00000000"],["77589.15000000","0.00338000"],["77571.01000000","0.00007000"],["69831.27000000","0.00448000"],["62072.24000000","0.00063000"]],"a":[["77590.30000000","2.83299000"],["77602.05000000","0.00007000"]]}}
{"type":"depth","received_at_ms":1788331880474,"data":{"e":"depthUpdate","E":1788331880614,"s":"BTCUSDT","U":99555824951,"u":99555824970,"b":[["77590.29000000","1.59681000"],["77584.06000000","0.00000000"],["77583.47000000","0.00077000"],["69831.27000000","0.00448000"],["62072.24000000","0.00031000"],["62072.23000000","0.00000000"],["62072.00000000","0.15157000"]],"a":[["77590.30000000","2.83363000"],["78754.16000000","0.00030000"]]}}
{"type":"depth","received_at_ms":1788331880573,"data":{"e":"depthUpdate","E":1788331880714,"s":"BTCUSDT","U":99555824971,"u":99555824978,"b":[["77590.29000000","1.59681000"],["69831.27000000","0.00448000"]],"a":[["77590.30000000","2.83363000"]]}}
{"type":"trade","received_at_ms":1788331880627,"data":{"e":"trade","E":1788331880768,"s":"BTCUSDT","t":6646634269,"p":"77590.30000000","q":"0.00090000","T":1788331880768,"m":false,"M":true}}
{"type":"depth","received_at_ms":1788331880673,"data":{"e":"depthUpdate","E":1788331880814,"s":"BTCUSDT","U":99555824979,"u":99555824991,"b":[["77590.29000000","1.59681000"],["77590.28000000","0.01134000"],["69831.27000000","0.00441000"]],"a":[["77590.30000000","2.83273000"]]}}
{"type":"depth","received_at_ms":1788331880777,"data":{"e":"depthUpdate","E":1788331880914,"s":"BTCUSDT","U":99555824992,"u":99555825005,"b":[["77590.29000000","1.59681000"],["77581.79000000","0.00000000"],["77581.09000000","0.00400000"],["77572.94000000","0.00000000"],["77570.73000000","0.00000000"],["69831.27000000","0.00457000"],["62072.23000000","0.00000000"]],"a":[["77590.30000000","2.83273000"]]}}
{"type":"depth","received_at_ms":1788331880874,"data":{"e":"depthUpdate","E":1788331881014,"s":"BTCUSDT","U":99555825006,"u":99555825020,"b":[["77590.29000000","1.59673000"],["77581.80000000","0.00000000"],["77581.16000000","0.00010000"],["77572.94000000","0.00200000"],["76426.43000000","0.00030000"],["69831.27000000","0.00441000"],["69831.00000000","0.00000000"],["62072.24000000","0.00063000"]],"a":[["77590.30000000","2.83273000"]]}}
{"type":"trade","received_at_ms":1788331880910,"data":{"e":"trade","E":1788331881051,"s":"BTCUSDT","t":6646634270,"p":"77590.29000000","q":"0.00250000","T":1788331881051,"m":true,"M":true}}
{"type":"depth","received_at_ms":1788331880973,"data":{"e":"depthUpdate","E":1788331881114,"s":"BTCUSDT","U":99555825021,"u":99555825037,"b":[["77590.29000000","1.59431000"],["77557.93000000","0.00000000"],["77519.15000000","0.00000000"],["77488.12000000","0.00000000"],["69831.27000000","0.00448000"],["69831.26000000","0.00009000"]],"a":[["77590.30000000","2.83273000"],["77607.17000000","0.00000000"],["77645.98000000","0.00000000"],["77676.93000000","0.00000000"]]}}
{"type":"depth","received_at_ms":1788331881073,"data":{"e":"depthUpdate","E":1788331881214,"s":"BTCUSDT","U":99555825038,"u":99555825047,"b":[["77590.29000000","1.59431000"],["69831.27000000","0.00432000"],["62072.24000000","0.00031000"]],"a":[["77590.30000000","2.83445000"]]}}
{"type":"trade","received_at_ms":1788331881089,"data":{"e":"trade","E":1788331881230,"s":"BTCUSDT","t":6646634271,"p":"77590.29000000","q":"0.00100000","T":1788331881230,"m":true,"M":true}}
{"type":"depth","received_at_ms":1788331881176,"data":{"e":"depthUpdate","E":1788331881314,"s":"BTCUSDT","U":99555825048,"u":99555825058,"b":[["77590.29000000","1.59331000"],["69831.27000000","0.00448000"]],"a":[["77590.30000000","2.83445000"],["77646.05000000","0.00412000"]]}}
{"type":"depth","received_at_ms":1788331881273,"data":{"e":"depthUpdate","E":1788331881414,"s":"BTCUSDT","U":99555825059,"u":99555825063,"b":[["77590.29000000","1.59331000"],["69831.27000000","0.00432000"]],"a":[["77590.30000000","2.83445000"]]}}
{"type":"trade","received_at_ms":1788331881344,"data":{"e":"trade","E":1788331881485,"s":"BTCUSDT","t":6646634272,"p":"77590.30000000","q":"0.00257000","T":1788331881485,"m":false,"M":true}}
{"type":"depth","received_at_ms":1788331881376,"data":{"e":"depthUpdate","E":1788331881514,"s":"BTCUSDT","U":99555825064,"u":99555825080,"b":[["77590.29000000","1.59331000"],["77571.01000000","0.00007000"],["69831.27000000","0.00448000"],["69831.26000000","0.00000000"],["62072.24000000","0.00063000"]],"a":[["77590.30000000","2.83188000"],["77602.05000000","0.00007000"]]}}
{"type":"depth","received_at_ms":1788331881473,"data":{"e":"depthUpdate","E":1788331881614,"s":"BTCUSDT","U":99555825081,"u":99555825096,"b":[["77590.29000000","1.59331000"],["69831.27000000","0.00432000"],["62072.24000000","0.00031000"],["62072.23000000","0.00000000"],["62072.00000000","0.15157000"]],"a":[["77590.30000000","2.83188000"],["77620.41000000","0.00000000"],["77624.05000000","0.00000000"],["78754.16000000","0.00030000"]]}}
{"type":"depth","received_at_ms":1788331881574,"data":{"e":"depthUpdate","E":1788331881714,"s":"BTCUSDT","U":99555825097,"u":99555825101,"b":[["77590.29000000","1.59331000"],["69831.27000000","0.00448000"]],"a":[["77590.30000000","2.83188000"]]}}
{"type":"trade","received_at_ms":1788331881659,"data":{"e":"trade","E":1788331881799,"s":"BTCUSDT","t":6646634273,"p":"77590.30000000","q":"0.00014000","T":1788331881798,"m":false,"M":true}}
{"type":"depth","received_at_ms":1788331881674,"data":{"e":"depthUpdate","E":1788331881814,"s":"BTCUSDT","U":99555825102,"u":99555825114,"b":[["77590.29000000","1.59331000"],["69831.27000000","0.00441000"]],"a":[["77590.30000000","2.83174000"]]}}
{"type":"depth","received_at_ms":1788331881775,"data":{"e":"depthUpdate","E":1788331881914,"s":"BTCUSDT","U":99555825115,"u":99555825124,"b":[["77590.29000000","1.59331000"],["75557.06000000","0.00000000"],["69831.27000000","0.00441000"],["62072.23000000","0.00000000"]],"a":[["77622.08000000","0.00000000"],["81001.06000000","0.00000000"]]}}
{"type":"depth","received_at_ms":1788331881873,"data":{"e":"depthUpdate","E":1788331882014,"s":"BTCUSDT","U":99555825125,"u":99555825138,"b":[["77590.29000000","1.59331000"],["76426.43000000","0.00030000"],["69831.27000000","0.00425000"],["62072.24000000","0.00063000"],["62072.00000000","0.15157000"]],"a":[["77687.04000000","2.15391000"],["77689.63000000","0.00000000"]]}}
{"type":"depth","received_at_ms":1788331881974,"data":{"e":"depthUpdate","E":1788331882114,"s":"BTCUSDT","U":99555825139,"u":99555825147,"b":[["69831.27000000","0.00441000"],["69831.00000000","0.00000000"]],"a":[["77620.56000000","0.02006000"],["77624.21000000","0.18270000"],["77687.03000000","1.50999000"],["77689.33000000","0.01935000"]]}}
{"type":"depth","received_at_ms":1788331882074,"data":{"e":"depthUpdate","E":1788331882214,"s":"BTCUSDT","U":99555825148,"u":99555825153,"b":[["77590.29000000","1.59331000"],["69831.27000000","0.00457000"],["62072.24000000","0.00031000"]],"a":[]}}
{"type":"trade","received_at_ms":1788331882078,"data":{"e":"trade","E":1788331882218,"s":"BTCUSDT","t":6646634274,"p":"77590.30000000","q":"0.00258000","T":1788331882218,"m":false,"M":true}}
{"type":"depth","received_at_ms":1788331882172,"data":{"e":"depthUpdate","E":1788331882314,"s":"BTCUSDT","U":99555825154,"u":99555825164,"b":[["77590.29000000","1.59331000"],["69831.27000000","0.00416000"],["69831.26000000","0.00009000"],["62072.00000000","0.15157000"]],"a":[["77590.30000000","2.82916000"],["77607.24000000","0.00412000"]]}}
{"type":"depth","received_at_ms":1788331882272,"data":{"e":"depthUpdate","E":1788331882414,"s":"BTCUSDT","U":99555825165,"u":99555825174,"b":[["77590.29000000","1.59317000"],["76486.08000000","0.00061000"],["69831.27000000","0.00448000"]],"a":[["77590.30000000","2.51705000"],["77622.24000000","0.09879000"]]}}
{"type":"trade","received_at_ms":1788331882355,"data":{"e":"trade","E":1788331882492,"s":"BTCUSDT","t":6646634275,"p":"77590.29000000","q":"0.06444000","T":1788331882492,"m":true,"M":true}}
{"type":"depth","received_at_ms":1788331882372,"data":{"e":"depthUpdate","E":1788331882514,"s":"BTCUSDT","U":99555825175,"u":99555825199,"b":[["77590.29000000","1.63908000"],["77571.01000000","0.00007000"],["77496.20000000","0.00000000"],["69831.27000000","0.00432000"],["69831.26000000","0.00000000"],["62072.24000000","0.00063000"],["62072.00000000","0.15357000"]],"a":[["77590.30000000","2.66616000"],["77602.05000000","0.00007000"],["77677.09000000","0.00412000"],["77687.03000000","0.99415000"],["77687.04000000","0.00000000"],["77689.63000000","2.15391000"],["77729.05000000","0.00000000"]]}}
{"type":"trade","received_at_ms":1788331882461,"data":{"e":"trade","E":1788331882602,"s":"BTCUSDT","t":6646634276,"p":"77590.29000000","q":"0.00139000","T":1788331882602,"m":true,"M":true}}
{"type":"depth","received_at_ms":1788331882472,"data":{"e":"depthUpdate","E":1788331882614,"s":"BTCUSDT","U":99555825200,"u":99555825210,"b":[["77590.29000000","1.63769000"],["77486.08000000","0.04884000"],["69831.27000000","0.00448000"],["62072.24000000","0.00031000"],["62072.23000000","0.00000000"]],"a":[["77718.89000000","0.00971000"],["78754.16000000","0.00030000"]]}}
{"type":"depth","received_at_ms":1788331882574,"data":{"e":"depthUpdate","E":1788331882714,"s":"BTCUSDT","U":99555825211,"u":99555825216,"b":[["77590.29000000","1.63795000"],["77561.87000000","0.00412000"],["69831.27000000","0.00432000"]],"a":[["77590.30000000","2.66624000"]]}}
{"type":"depth","received_at_ms":1788331882675,"data":{"e":"depthUpdate","E":1788331882814,"s":"BTCUSDT","U":99555825217,"u":99555825298,"b":[["77590.29000000","1.69259000"],["77582.55000000","0.00010000"],["77581.16000000","0.00000000"],["77572.94000000","0.00000000"],["77570.61000000","0.00200000"],["75556.88000000","0.00010000"],["69831.27000000","0.00448000"]],"a":[["77590.30000000","2.39856000"],["77590.31000000","0.00076000"],["77592.57000000","0.00000000"],["77592.66000000","0.00000000"],["77592.77000000","0.00400000"],["77592.79000000","0.00000000"],["77592.81000000","0.00000000"],["77595.54000000","0.00000000"],["77595.76000000","0.00400000"],["77595.77000000","0.00000000"],["77595.85000000","0.00000000"],["77595.94000000","0.00000000"],["77596.71000000","0.00000000"],["77597.05000000","0.00000000"],["77598.88000000","0.01200000"],["77598.89000000","0.00644000"]]}}
{"type":"depth","received_at_ms":1788331882773,"data":{"e":"depthUpdate","E":1788331882914,"s":"BTCUSDT","U":99555825299,"u":99555825318,"b":[["77590.29000000","1.71997000"],["77582.55000000","0.00000000"],["77581.16000000","0.00010000"],["77572.94000000","0.00200000"],["77570.61000000","0.00000000"],["69831.27000000","0.00432000"],["62072.23000000","0.00000000"]],"a":[["77590.30000000","2.26898000"]]}}
{"type":"trade","received_at_ms":1788331882785,"data":{"e":"trade","E":1788331882924,"s":"BTCUSDT","t":6646634277,"p":"77590.30000000","q":"0.00258000","T":1788331882924,"m":false,"M":true}}
{"type":"trade","received_at_ms":1788331882785,"data":{"e":"trade","E":1788331882924,"s":"BTCUSDT","t":6646634278,"p":"77590.30000000","q":"0.00307000","T":1788331882924,"m":false,"M":true}}
{"type":"depth","received_at_ms":1788331882873,"data":{"e":"depthUpdate","E":1788331883014,"s":"BTCUSDT","U":99555825319,"u":99555825331,"b":[["77590.29000000","1.71997000"],["77582.55000000","0.00010000"],["77581.16000000","0.00000000"],["76426.43000000","0.00030000"],["69831.27000000","0.00457000"],["62072.24000000","0.00063000"]],"a":[["77590.30000000","2.38186000"],["81001.25000000","0.00010000"]]}}
{"type":"depth","received_at_ms":1788331882974,"data":{"e":"depthUpdate","E":1788331883115,"s":"BTCUSDT","U":99555825332,"u":99555825343,"b":[["77590.29000000","1.72004000"],["77492.06000000","0.00412000"],["69831.27000000","0.00441000"]],"a":[["77590.30000000","2.26333000"],["77599.14000000","0.00000000"]]}}
{"type":"depth","received_at_ms":1788331883073,"data":{"e":"depthUpdate","E":1788331883214,"s":"BTCUSDT","U":99555825344,"u":99555825351,"b":[["77590.29000000","1.72004000"],["69831.27000000","0.00457000"],["62072.24000000","0.00031000"],["62072.00000000","0.15357000"]],"a":[]}}
{"type":"depth","received_at_ms":1788331883172,"data":{"e":"depthUpdate","E":1788331883314,"s":"BTCUSDT","U":99555825352,"u":99555825358,"b":[["77590.29000000","1.71997000"],["69831.27000000","0.00441000"],["69831.00000000","0.00020000"]],"a":[["77590.30000000","2.26338000"]]}}
{"type":"depth","received_at_ms":1788331883273,"data":{"e":"depthUpdate","E":1788331883414,"s":"BTCUSDT","U":99555825359,"u":99555825366,"b":[["77590.29000000","1.71997000"],["69831.27000000","0.00441000"]],"a":[["77590.30000000","2.26336000"]]}}
{"type":"depth","received_at_ms":1788331883373,"data":{"e":"depthUpdate","E":1788331883514,"s":"BTCUSDT","U":99555825367,"u":99555825377,"b":[["77590.29000000","1.71997000"],["77571.01000000","0.00000000"],["77560.00000000","2.31053000"],["77535.23000000","0.00000000"],["69831.27000000","0.00441000"],["69831.00000000","0.00000000"],["62072.24000000","0.00063000"]],"a":[["77590.30000000","2.26146000"],["77599.13000000","0.00188000"],["77602.05000000","0.00000000"]]}}
{"type":"depth","received_at_ms":1788331883472,"data":{"e":"depthUpdate","E":1788331883614,"s":"BTCUSDT","U":99555825378,"u":99555825397,"b":[["77590.29000000","1.71997000"],["77571.01000000","0.00007000"],["69831.27000000","0.00425000"],["62072.24000000","0.00031000"],["62072.23000000","0.00000000"],["62072.00000000","0.15357000"]],"a":[["77590.30000000","2.26335000"],["77599.13000000","0.00000000"],["77602.05000000","0.00007000"],["78754.16000000","0.00030000"]]}}
{"type":"depth","received_at_ms":1788331883573,"data":{"e":"depthUpdate","E":1788331883714,"s":"BTCUSDT","U":99555825398,"u":99555825408,"b":[["77590.29000000","1.71990000"],["77590.14000000","0.00117000"],["77590.01000000","0.00046000"],["69831.27000000","0.00457000"],["62072.00000000","0.15357000"]],"a":[["77590.30000000","2.26146000"],["77599.14000000","0.00190000"]]}}
{"type":"trade","received_at_ms":1788331883625,"data":{"e":"trade","E":1788331883766,"s":"BTCUSDT","t":6646634279,"p":"77590.29000000","q":"0.00257000","T":1788331883765,"m":true,"M":true}}
{"type":"trade","received_at_ms":1788331883665,"data":{"e":"trade","E":1788331883805,"s":"BTCUSDT","t":6646634280,"p":"77590.30000000","q":"0.00100000","T":1788331883804,"m":false,"M":true}}
{"type":"depth","received_at_ms":1788331883673,"data":{"e":"depthUpdate","E":1788331883814,"s":"BTCUSDT","U":99555825409,"u":99555825430,"b":[["77590.29000000","1.71740000"],["77589.15000000","0.00000000"],["77582.55000000","0.00000000"],["77581.16000000","0.00013000"],["77577.12000000","0.33003000"],["77573.51000000","0.00000000"],["69831.27000000","0.00432000"],["69831.26000000","0.00009000"]],"a":[["77590.30000000","2.23980000"],["77599.14000000","0.00000000"],["77689.33000000","0.65982000"]]}}
{"type":"depth","received_at_ms":1788331883774,"data":{"e":"depthUpdate","E":1788331883914,"s":"BTCUSDT","U":99555825431,"u":99555825446,"b":[["77590.29000000","1.71733000"],["77590.28000000","0.01127000"],["77589.08000000","0.00328000"],["77585.60000000","0.00807000"],["77584.46000000","0.04000000"],["77561.87000000","0.00000000"],["77523.08000000","0.00412000"],["77492.06000000","0.00000000"],["69831.27000000","0.00432000"]],"a":[["77590.30000000","2.24172000"],["77607.24000000","0.00000000"],["77646.05000000","0.00000000"],["77677.09000000","0.00000000"]]}}
{"type":"depth","received_at_ms":1788331883873,"data":{"e":"depthUpdate","E":1788331884014,"s":"BTCUSDT","U":99555825447,"u":99555825464,"b":[["77590.29000000","1.71761000"],["77590.28000000","0.01134000"],["76426.43000000","0.00030000"],["69831.27000000","0.00432000"],["62072.24000000","0.00063000"],["62072.23000000","0.00000000"]],"a":[["77590.30000000","2.53288000"]]}}
{"type":"depth","received_at_ms":1788331883974,"data":{"e":"depthUpdate","E":1788331884114,"s":"BTCUSDT","U":99555825465,"u":99555825474,"b":[["77590.29000000","1.71429000"],["77589.08000000","0.00000000"],["77589.05000000","0.00348000"],["69831.27000000","0.00448000"]],"a":[["77646.08000000","0.00412000"],["77687.04000000","2.15391000"],["77689.33000000","0.01935000"],["77689.63000000","0.00000000"]]}}
{"type":"depth","received_at_ms":1788331884073,"data":{"e":"depthUpdate","E":1788331884214,"s":"BTCUSDT","U":99555825475,"u":99555825484,"b":[["77590.29000000","1.71429000"],["77590.28000000","0.01134000"],["69831.27000000","0.00432000"],["62072.24000000","0.00031000"]],"a":[]}}
{"type":"depth","received_at_ms":1788331884173,"data":{"e":"depthUpdate","E":1788331884314,"s":"BTCUSDT","U":99555825485,"u":99555825493,"b":[["77590.29000000","1.71429000"],["77589.05000000","0.00014000"],["69831.27000000","0.00448000"],["62072.00000000","0.15357000"]],"a":[["77677.12000000","0.00412000"]]}}
{"type":"depth","received_at_ms":1788331884275,"data":{"e":"depthUpdate","E":1788331884414,"s":"BTCUSDT","U":99555825494,"u":99555825506,"b":[["77590.29000000","1.71429000"],["77590.28000000","0.01134000"],["77588.62000000","0.00340000"],["69831.27000000","0.00432000"],["62072.00000000","0.15357000"]],"a":[["77590.30000000","2.36418000"]]}}
{"type":"depth","received_at_ms":1788331884373,"data":{"e":"depthUpdate","E":1788331884514,"s":"BTCUSDT","U":99555825507,"u":99555825516,"b":[["77590.29000000","1.71422000"],["77590.28000000","0.01127000"],["77588.62000000","0.00000000"],["77492.09000000","0.00412000"],["69831.27000000","0.00448000"],["62072.24000000","0.00063000"]],"a":[]}}
{"type":"depth","received_at_ms":1788331884474,"data":{"e":"depthUpdate","E":1788331884615,"s":"BTCUSDT","U":99555825517,"u":99555825532,"b":[["77590.29000000","1.71422000"],["77588.22000000","0.00326000"],["77571.01000000","0.00007000"],["69831.27000000","0.00432000"],["69831.00000000","0.00000000"],["62072.24000000","0.00031000"],["62072.23000000","0.00000000"],["62072.00000000","0.15357000"]],"a":[["77602.05000000","0.00007000"],["78754.16000000","0.00030000"]]}}
{"type":"trade","received_at_ms":1788331884530,"data":{"e":"trade","E":1788331884668,"s":"BTCUSDT","t":6646634281,"p":"77590.29000000","q":"0.08985000","T":1788331884668,"m":true,"M":true}}
{"type":"depth","received_at_ms":1788331884572,"data":{"e":"depthUpdate","E":1788331884714,"s":"BTCUSDT","U":99555825533,"u":99555825551,"b":[["77590.29000000","1.33538000"],["77590.28000000","0.01134000"],["77588.22000000","0.00000000"],["77585.66000000","0.00000000"],["77584.32000000","0.00000000"],["77583.69000000","0.00400000"],["69831.27000000","0.00448000"],["69831.26000000","0.00000000"]],"a":[["77590.30000000","2.55354000"]]}}
{"type":"depth","received_at_ms":1788331884673,"data":{"e":"depthUpdate","E":1788331884814,"s":"BTCUSDT","U":99555825552,"u":99555825561,"b":[["77590.29000000","1.33538000"],["77582.82000000","0.30000000"],["77581.03000000","0.00257000"],["69831.27000000","0.00432000"]],"a":[["77596.54000000","0.00257000"],["77597.64000000","0.00000000"],["77687.03000000","1.50999000"]]}}
{"type":"trade","received_at_ms":1788331884693,"data":{"e":"trade","E":1788331884833,"s":"BTCUSDT","t":6646634282,"p":"77590.29000000","q":"0.00100000","T":1788331884832,"m":true,"M":true}}
{"type":"depth","received_at_ms":1788331884773,"data":{"e":"depthUpdate","E":1788331884914,"s":"BTCUSDT","U":99555825562,"u":99555825567,"b":[["77590.29000000","1.33438000"],["69831.27000000","0.00432000"]],"a":[["77607.27000000","0.00412000"]]}}
{"type":"depth","received_at_ms":1788331884874,"data":{"e":"depthUpdate","E":1788331885014,"s":"BTCUSDT","U":99555825568,"u":99555825581,"b":[["77590.29000000","1.33438000"],["77590.28000000","0.01127000"],["76426.43000000","0.00030000"],["69831.27000000","0.00432000"],["62072.24000000","0.00063000"],["62072.23000000","0.00000000"],["62072.00000000","0.15357000"]],"a":[]}}
{"type":"depth","received_at_ms":1788331884972,"data":{"e":"depthUpdate","E":1788331885114,"s":"BTCUSDT","U":99555825582,"u":99555825588,"b":[["77590.29000000","1.33438000"],["71383.07000000","0.00015000"],["69831.27000000","0.00432000"]],"a":[]}}
{"type":"depth","received_at_ms":1788331885074,"data":{"e":"depthUpdate","E":1788331885214,"s":"BTCUSDT","U":99555825589,"u":99555825593,"b":[["77590.29000000","1.33438000"],["69831.27000000","0.00432000"],["62072.24000000","0.00031000"]],"a":[]}}
{"type":"depth","received_at_ms":1788331885173,"data":{"e":"depthUpdate","E":1788331885314,"s":"BTCUSDT","U":99555825594,"u":99555825597,"b":[["77590.29000000","1.33438000"],["69831.27000000","0.00432000"]],"a":[]}}
{"type":"depth","received_at_ms":1788331885273,"data":{"e":"depthUpdate","E":1788331885414,"s":"BTCUSDT","U":99555825598,"u":99555825602,"b":[["77590.29000000","1.33438000"],["69831.27000000","0.00448000"]],"a":[]}}
{"type":"depth","received_at_ms":1788331885374,"data":{"e":"depthUpdate","E":1788331885515,"s":"BTCUSDT","U":99555825603,"u":99555825609,"b":[["77590.29000000","1.33438000"],["69831.27000000","0.00416000"],["62072.24000000","0.00063000"],["62072.00000000","0.15357000"]],"a":[]}}
{"type":"trade","received_at_ms":1788331885384,"data":{"e":"trade","E":1788331885524,"s":"BTCUSDT","t":6646634283,"p":"77590.29000000","q":"0.00012000","T":1788331885524,"m":true,"M":true}}
{"type":"depth","received_at_ms":1788331885472,"data":{"e":"depthUpdate","E":1788331885614,"s":"BTCUSDT","U":99555825610,"u":99555825625,"b":[["77590.29000000","1.33426000"],["77573.29000000","0.00000000"],["77571.01000000","0.00007000"],["77534.48000000","0.00000000"],["77515.08000000","0.00000000"],["71383.07000000","0.00000000"],["69831.27000000","0.00448000"],["69831.26000000","0.00009000"],["62072.24000000","0.00031000"],["62072.23000000","0.00000000"]],"a":[["77596.42000000","0.02400000"],["77602.05000000","0.00007000"],["77615.82000000","0.02400000"],["77635.23000000","0.00000000"],["78754.16000000","0.00030000"]]}}
{"type":"trade","received_at_ms":1788331885483,"data":{"e":"trade","E":1788331885624,"s":"BTCUSDT","t":6646634284,"p":"77590.30000000","q":"0.01542000","T":1788331885624,"m":false,"M":true}}
{"type":"depth","received_at_ms":1788331885573,"data":{"e":"depthUpdate","E":1788331885714,"s":"BTCUSDT","U":99555825626,"u":99555825635,"b":[["77590.29000000","1.33426000"],["77508.74000000","0.00396000"],["77495.59000000","0.00000000"],["69831.27000000","0.00448000"],["69831.00000000","0.00020000"]],"a":[["77590.30000000","2.53812000"]]}}
{"type":"depth","received_at_ms":1788331885673,"data":{"e":"depthUpdate","E":1788331885814,"s":"BTCUSDT","U":99555825636,"u":99555825642,"b":[["77590.29000000","1.38137000"],["69831.27000000","0.00448000"],["69831.00000000","0.00000000"]],"a":[]}}
{"type":"trade","received_at_ms":1788331885700,"data":{"e":"trade","E":1788331885841,"s":"BTCUSDT","t":6646634285,"p":"77590.29000000","q":"0.00078000","T":1788331885840,"m":true,"M":true}}
{"type":"depth","received_at_ms":1788331885773,"data":{"e":"depthUpdate","E":1788331885914,"s":"BTCUSDT","U":99555825643,"u":99555825660,"b":[["77590.29000000","1.38067000"],["77561.90000000","0.00412000"],["77523.08000000","0.00000000"],["77492.09000000","0.00000000"],["69831.27000000","0.00448000"],["69831.26000000","0.00000000"],["69831.25000000","0.00009000"]],"a":[["77590.30000000","2.53912000"],["77607.27000000","0.00000000"],["77646.08000000","0.00000000"],["77677.12000000","0.00000000"],["77687.03000000","0.99415000"],["77687.04000000","0.00000000"],["77689.33000000","0.65982000"],["77689.63000000","2.15391000"]]}}
{"type":"depth","received_at_ms":1788331885875,"data":{"e":"depthUpdate","E":1788331886015,"s":"BTCUSDT","U":99555825661,"u":99555825671,"b":[["77590.29000000","1.38067000"],["76426.43000000","0.00030000"],["69831.27000000","0.00464000"],["62072.24000000","0.00063000"],["62072.23000000","0.00000000"]],"a":[["77597.07000000","0.71649000"]]}}
{"type":"depth","received_at_ms":1788331885973,"data":{"e":"depthUpdate","E":1788331886114,"s":"BTCUSDT","U":99555825672,"u":99555825677,"b":[["77590.29000000","1.38067000"],["69831.27000000","0.00448000"]],"a":[["77677.05000000","0.00412000"]]}}
{"type":"depth","received_at_ms":1788331886075,"data":{"e":"depthUpdate","E":1788331886214,"s":"BTCUSDT","U":99555825678,"u":99555825682,"b":[["77590.29000000","1.38067000"],["69831.27000000","0.00464000"],["62072.24000000","0.00031000"]],"a":[["81000.00000000","101.87777000"]]}}
{"type":"depth","received_at_ms":1788331886174,"data":{"e":"depthUpdate","E":1788331886314,"s":"BTCUSDT","U":99555825683,"u":99555825691,"b":[["77590.29000000","1.38067000"],["69831.27000000","0.00448000"],["62072.00000000","0.15357000"]],"a":[]}}
{"type":"depth","received_at_ms":1788331886273,"data":{"e":"depthUpdate","E":1788331886414,"s":"BTCUSDT","U":99555825692,"u":99555825702,"b":[["77590.29000000","1.38067000"],["69831.27000000","0.00448000"]],"a":[["77590.30000000","2.53662000"],["77687.04000000","2.15391000"],["77689.33000000","0.01935000"],["77689.63000000","0.00000000"]]}}
{"type":"depth","received_at_ms":1788331886373,"data":{"e":"depthUpdate","E":1788331886514,"s":"BTCUSDT","U":99555825703,"u":99555825707,"b":[["77590.29000000","1.38067000"],["77573.25000000","0.00000000"],["77534.44000000","0.00000000"],["77515.04000000","0.00000000"],["62072.24000000","0.00063000"]],"a":[["77596.42000000","0.00000000"],["77607.20000000","0.00412000"],["77615.82000000","0.00000000"],["77635.22000000","0.00000000"]]}}
{"type":"depth","received_at_ms":1788331886472,"data":{"e":"depthUpdate","E":1788331886614,"s":"BTCUSDT","U":99555825708,"u":99555825730,"b":[["77590.29000000","1.38067000"],["77574.97000000","0.02007000"],["77574.93000000","0.02000000"],["77571.01000000","0.00000000"],["77536.16000000","0.02000000"],["77536.12000000","0.02000000"],["69831.27000000","0.00448000"],["62072.24000000","0.00031000"],["62072.23000000","0.00020000"],["62072.00000000","0.15357000"]],"a":[["77601.22000000","0.03000000"],["77601.25000000","0.02400000"],["77602.05000000","0.00000000"],["77620.62000000","0.03000000"],["77620.66000000","0.02400000"],["77640.03000000","0.03000000"],["77640.06000000","0.02400000"],["78754.16000000","0.00030000"]]}}
{"type":"depth","received_at_ms":1788331886573,"data":{"e":"depthUpdate","E":1788331886714,"s":"BTCUSDT","U":99555825731,"u":99555825740,"b":[["77590.29000000","1.38067000"],["77571.01000000","0.00007000"],["77523.04000000","0.00412000"],["69831.27000000","0.00464000"],["62072.23000000","0.00000000"],["62072.00000000","0.15557000"]],"a":[["77602.05000000","0.00007000"]]}}
{"type":"depth","received_at_ms":1788331886673,"data":{"e":"depthUpdate","E":1788331886814,"s":"BTCUSDT","U":99555825741,"u":99555825744,"b":[["77590.29000000","1.38067000"],["69831.27000000","0.00448000"],["62072.00000000","0.15357000"]],"a":[]}}
{"type":"depth","received_at_ms":1788331886773,"data":{"e":"depthUpdate","E":1788331886914,"s":"BTCUSDT","U":99555825745,"u":99555825751,"b":[["77590.29000000","1.38067000"],["69831.27000000","0.00464000"],["69831.00000000","0.00000000"]],"a":[]}}
{"type":"depth","received_at_ms":1788331886875,"data":{"e":"depthUpdate","E":1788331887014,"s":"BTCUSDT","U":99555825752,"u":99555825765,"b":[["77590.29000000","1.38067000"],["77394.36000000","0.00000000"],["77346.11000000","0.02019000"],["76426.43000000","0.00030000"],["69831.27000000","0.00448000"],["62072.24000000","0.00063000"],["62072.23000000","0.00000000"]],"a":[["77687.04000000","0.00000000"],["77689.63000000","2.15391000"]]}}
{"type":"depth","received_at_ms":1788331886973,"data":{"e":"depthUpdate","E":1788331887114,"s":"BTCUSDT","U":99555825766,"u":99555825770,"b":[["69831.27000000","0.00448000"]],"a":[["77590.30000000","2.53974000"],["77591.78000000","0.00021000"],["77646.01000000","0.00412000"]]}}
{"type":"depth","received_at_ms":1788331887073,"data":{"e":"depthUpdate","E":1788331887214,"s":"BTCUSDT","U":99555825771,"u":99555825787,"b":[["77590.29000000","1.38067000"],["69831.27000000","0.00448000"],["62072.24000000","0.00031000"]],"a":[["77590.30000000","2.53967000"],["77590.31000000","0.00069000"],["77591.58000000","0.00750000"],["77591.78000000","0.00007000"],["77593.79000000","0.00658000"],["77594.35000000","0.00200000"],["77595.49000000","0.00014000"]]}}
{"type":"depth","received_at_ms":1788331887173,"data":{"e":"depthUpdate","E":1788331887314,"s":"BTCUSDT","U":99555825788,"u":99555825795,"b":[["77523.04000000","0.00000000"],["77492.02000000","0.00412000"],["69831.27000000","0.00464000"]],"a":[["77607.20000000","0.00000000"],["77646.01000000","0.00000000"],["77677.05000000","0.00000000"]]}}
{"type":"trade","received_at_ms":1788331887209,"data":{"e":"trade","E":1788331887350,"s":"BTCUSDT","t":6646634286,"p":"77590.30000000","q":"0.12329000","T":1788331887350,"m":false,"M":true}}
{"type":"depth","received_at_ms":1788331887273,"data":{"e":"depthUpdate","E":1788331887415,"s":"BTCUSDT","U":99555825796,"u":99555825806,"b":[["77590.29000000","1.37619000"],["69831.27000000","0.00432000"],["69831.25000000","0.00000000"]],"a":[["77590.30000000","2.41638000"],["77687.04000000","2.15391000"],["77689.63000000","0.00000000"]]}}
{"type":"trade","received_at_ms":1788331887282,"data":{"e":"trade","E":1788331887422,"s":"BTCUSDT","t":6646634287,"p":"77590.30000000","q":"0.00100000","T":1788331887422,"m":false,"M":true}}
{"type":"depth","received_at_ms":1788331887373,"data":{"e":"depthUpdate","E":1788331887514,"s":"BTCUSDT","U":99555825807,"u":99555825818,"b":[["77590.29000000","1.57153000"],["77573.21000000","0.00000000"],["77572.94000000","0.00000000"],["77570.73000000","0.00200000"],["77534.40000000","0.00000000"],["77515.00000000","0.00000000"],["69831.27000000","0.00464000"],["62072.24000000","0.00063000"]],"a":[["77590.30000000","2.41538000"],["77596.38000000","0.00000000"],["77615.78000000","0.00000000"],["77635.18000000","0.00000000"]]}}
{"type":"depth","received_at_ms":1788331887473,"data":{"e":"depthUpdate","E":1788331887614,"s":"BTCUSDT","U":99555825819,"u":99555825839,"b":[["77590.29000000","1.57161000"],["77575.07000000","0.02000000"],["77572.94000000","0.00200000"],["77570.73000000","0.00000000"],["77536.25000000","0.02000000"],["77516.75000000","0.02000000"],["77516.71000000","0.02000000"],["75000.00000000","109.04911000"],["69831.27000000","0.00448000"],["62072.24000000","0.00031000"],["62072.00000000","0.15357000"]],"a":[["77601.32000000","0.03000000"],["77620.72000000","0.03000000"],["77640.13000000","0.03000000"],["78754.16000000","0.00030000"]]}}
{"type":"depth","received_at_ms":1788331887574,"data":{"e":"depthUpdate","E":1788331887714,"s":"BTCUSDT","U":99555825840,"u":99555825850,"b":[["77590.29000000","1.57161000"],["77571.01000000","0.00007000"],["69831.27000000","0.00464000"],["62072.23000000","0.00000000"]],"a":[["77602.05000000","0.00007000"],["77646.12000000","0.00412000"]]}}
{"type":"depth","received_at_ms":1788331887673,"data":{"e":"depthUpdate","E":1788331887814,"s":"BTCUSDT","U":99555825851,"u":99555825855,"b":[["77590.29000000","1.57161000"],["75556.88000000","0.00000000"],["69831.27000000","0.00448000"]],"a":[["77590.30000000","2.41438000"],["81001.25000000","0.00000000"]]}}
{"type":"depth","received_at_ms":1788331887773,"data":{"e":"depthUpdate","E":1788331887914,"s":"BTCUSDT","U":99555825856,"u":99555825864,"b":[["77590.29000000","1.57161000"],["77523.15000000","0.00412000"],["69831.27000000","0.00448000"],["69831.00000000","0.00020000"]],"a":[["77687.03000000","1.50999000"]]}}
{"type":"depth","received_at_ms":1788331887872,"data":{"e":"depthUpdate","E":1788331888014,"s":"BTCUSDT","U":99555825865,"u":99555825881,"b":[["77590.29000000","1.57161000"],["76426.43000000","0.00030000"],["69831.27000000","0.00448000"],["69831.00000000","0.00000000"],["62072.24000000","0.00063000"],["62072.23000000","0.00000000"],["62072.00000000","0.15357000"]],"a":[["77687.03000000","0.99415000"],["77687.04000000","0.00000000"],["77689.63000000","2.15391000"]]}}
{"type":"depth","received_at_ms":1788331887973,"data":{"e":"depthUpdate","E":1788331888114,"s":"BTCUSDT","U":99555825882,"u":99555825886,"b":[["77590.29000000","1.57161000"],["69831.27000000","0.00448000"]],"a":[["77677.16000000","0.00412000"]]}}
{"type":"depth","received_at_ms":1788331888073,"data":{"e":"depthUpdate","E":1788331888214,"s":"BTCUSDT","U":99555825887,"u":99555825898,"b":[["77590.29000000","1.57161000"],["69831.27000000","0.00464000"],["62072.24000000","0.00031000"]],"a":[]}}
{"type":"depth","received_at_ms":1788331888178,"data":{"e":"depthUpdate","E":1788331888314,"s":"BTCUSDT","U":99555825899,"u":99555825912,"b":[["77590.29000000","1.57161000"],["77523.15000000","0.00000000"],["77492.02000000","0.00000000"],["69831.27000000","0.00448000"],["62072.00000000","0.15357000"]],"a":[["77607.31000000","0.00412000"],["77646.12000000","0.00000000"],["77677.16000000","0.00000000"]]}}
{"type":"depth","received_at_ms":1788331888272,"data":{"e":"depthUpdate","E":1788331888414,"s":"BTCUSDT","U":99555825913,"u":99555825915,"b":[["77590.29000000","1.57161000"],["69831.27000000","0.00464000"]],"a":[]}}
{"type":"trade","received_at_ms":1788331888316,"data":{"e":"trade","E":1788331888456,"s":"BTCUSDT","t":6646634288,"p":"77590.29000000","q":"0.00100000","T":1788331888456,"m":true,"M":true}}
{"type":"trade","received_at_ms":1788331888365,"data":{"e":"trade","E":1788331888506,"s":"BTCUSDT","t":6646634289,"p":"77590.30000000","q":"0.00257000","T":1788331888506,"m":false,"M":true}}
{"type":"depth","received_at_ms":1788331888377,"data":{"e":"depthUpdate","E":1788331888514,"s":"BTCUSDT","U":99555825916,"u":99555825930,"b":[["77590.29000000","1.57061000"],["77573.95000000","0.00000000"],["77535.14000000","0.00000000"],["77515.74000000","0.00000000"],["69831.27000000","0.00448000"],["69831.26000000","0.00009000"],["62072.24000000","0.00063000"],["62072.00000000","0.15357000"]],"a":[["77590.30000000","2.41181000"],["77594.35000000","0.00000000"],["77595.49000000","0.00214000"],["77595.56000000","0.00000000"],["77614.97000000","0.00000000"],["77634.37000000","0.00000000"],["77677.09000000","0.00412000"]]}}
{"type":"depth","received_at_ms":1788331888474,"data":{"e":"depthUpdate","E":1788331888614,"s":"BTCUSDT","U":99555825931,"u":99555825950,"b":[["77590.29000000","1.57061000"],["77575.94000000","0.02000000"],["77537.13000000","0.02000000"],["77516.85000000","0.02000000"],["69831.27000000","0.00464000"],["62072.24000000","0.00031000"]],"a":[["77595.55000000","0.00000000"],["77596.13000000","0.00007000"],["77600.57000000","0.02600000"],["77619.98000000","0.02600000"],["77626.84000000","0.33003000"],["77629.34000000","0.00000000"],["77639.39000000","0.02600000"],["77687.04000000","2.15391000"],["77689.63000000","0.00000000"],["78754.16000000","0.00030000"]]}}
{"type":"trade","received_at_ms":1788331888532,"data":{"e":"trade","E":1788331888673,"s":"BTCUSDT","t":6646634290,"p":"77590.30000000","q":"0.00038000","T":1788331888672,"m":false,"M":true}}
{"type":"depth","received_at_ms":1788331888573,"data":{"e":"depthUpdate","E":1788331888714,"s":"BTCUSDT","U":99555825951,"u":99555825962,"b":[["77571.01000000","0.00000000"],["69831.27000000","0.00432000"],["62072.23000000","0.00000000"],["62072.00000000","0.15357000"]],"a":[["77590.30000000","2.41143000"],["77602.05000000","0.00000000"]]}}
{"type":"depth","received_at_ms":1788331888674,"data":{"e":"depthUpdate","E":1788331888814,"s":"BTCUSDT","U":99555825963,"u":99555825979,"b":[["77582.84000000","0.00000000"],["77582.55000000","0.00644000"],["77581.17000000","0.00644000"],["77578.67000000","0.00000000"],["77571.01000000","0.00007000"],["77518.85000000","0.00320000"],["77518.84000000","0.00000000"],["77518.40000000","0.00320000"],["77516.01000000","0.00000000"],["77441.49000000","0.00256000"],["77434.41000000","0.00000000"],["77434.40000000","0.00000000"],["75557.06000000","0.00010000"],["69831.27000000","0.00464000"]],"a":[["77592.76000000","0.00644000"],["77593.79000000","0.00014000"],["77596.74000000","0.00644000"],["77598.89000000","0.00000000"],["77602.05000000","0.00007000"],["77614.21000000","0.04695000"],["77614.24000000","0.00000000"],["77721.73000000","0.00000000"],["77724.99000000","0.00128000"],["77726.97000000","0.00000000"],["77727.26000000","0.00128000"]]}}
{"type":"depth","received_at_ms":1788331888774,"data":{"e":"depthUpdate","E":1788331888914,"s":"BTCUSDT","U":99555825980,"u":99555826008,"b":[["77583.69000000","0.00000000"],["77582.95000000","0.00400000"],["77582.55000000","0.30644000"],["77582.53000000","0.16878000"],["69831.27000000","0.00448000"]],"a":[["77590.30000000","2.41143000"],["77590.31000000","0.00076000"],["77592.24000000","0.00768000"],["77592.76000000","0.00658000"],["77593.04000000","0.01291000"],["77593.79000000","0.00000000"],["77593.83000000","0.00400000"],["77594.30000000","0.00200000"],["77595.49000000","0.00014000"],["77595.76000000","0.00000000"],["77687.03000000","1.50999000"]]}}
{"type":"depth","received_at_ms":1788331888873,"data":{"e":"depthUpdate","E":1788331889014,"s":"BTCUSDT","U":99555826009,"u":99555826130,"b":[["77590.29000000","0.81616000"],["77585.82000000","0.11636000"],["77585.61000000","0.00000000"],["77585.60000000","0.00007000"],["77585.59000000","0.61385000"],["77585.58000000","0.34805000"],["77584.82000000","0.00000000"],["77583.47000000","0.00000000"],["77583.14000000","0.00000000"],["77582.96000000","0.00000000"],["77582.95000000","0.00000000"],["77582.55000000","0.30000000"],["77581.95000000","0.00000000"],["77581.17000000","0.00000000"],["77581.16000000","0.00090000"],["77581.13000000","0.04292000"],["77581.12000000","0.00000000"],["77581.09000000","0.00000000"],["77581.04000000","0.00000000"],["77581.03000000","0.00257000"],["77580.71000000","0.00000000"],["77580.62000000","0.00400000"],["77580.49000000","0.00000000"],["77580.44000000","0.00000000"],["77580.43000000","0.00000000"],["77580.13000000","0.00016000"],["77580.12000000","0.00000000"],["77579.66000000","0.00000000"],["77579.48000000","0.00644000"],["77579.47000000","0.00400000"],["77578.68000000","0.00644000"],["77578.67000000","0.00000000"],["77573.59000000","0.00400000"],["77573.35000000","0.00800000"],["77572.94000000","0.00000000"],["77569.35000000","0.00200000"],["76426.43000000","0.00030000"],["69831.27000000","0.00448000"],["69831.00000000","0.00020000"],["62072.24000000","0.00063000"],["62072.23000000","0.00000000"]],"a":[["77590.30000000","2.66573000"],["77590.31000000","0.00076000"],["77590.53000000","0.00400000"],["77591.90000000","0.00400000"],["77592.76000000","0.00014000"],["77592.77000000","0.00000000"],["77592.82000000","0.00200000"],["77593.25000000","0.00644000"],["77593.83000000","0.00000000"],["77594.30000000","0.00000000"],["77596.12000000","0.00407000"],["77596.13000000","0.12022000"],["77596.74000000","0.00000000"],["77599.68000000","0.00000000"],["77600.22000000","1.05952000"],["77603.10000000","1.93226000"],["77623.28000000","0.00408000"],["77625.22000000","0.00008000"],["81001.06000000","0.00010000"]]}}
{"type":"trade","received_at_ms":1788331888894,"data":{"e":"trade","E":1788331889034,"s":"BTCUSDT","t":6646634291,"p":"77590.29000000","q":"0.00619000","T":1788331889034,"m":true,"M":true}}
{"type":"depth","received_at_ms":1788331888974,"data":{"e":"depthUpdate","E":1788331889114,"s":"BTCUSDT","U":99555826131,"u":99555826373,"b":[["77590.29000000","0.33471000"],["77590.28000000","0.01113000"],["77590.14000000","0.00103000"],["77590.13000000","0.00014000"],["77589.69000000","0.00000000"],["77587.62000000","0.00014000"],["77587.32000000","0.10557000"],["77586.57000000","0.00014000"],["77586.56000000","0.01668000"],["77586.48000000","0.00007000"],["77585.99000000","0.09904000"],["77585.82000000","0.11629000"],["77585.59000000","0.11615000"],["77585.58000000","0.00000000"],["77585.56000000","0.00007000"],["77584.08000000","0.16601000"],["77584.05000000","0.00000000"],["77582.84000000","0.11615000"],["77582.83000000","0.00607000"],["77582.82000000","0.00000000"],["77582.81000000","0.07775000"],["77582.55000000","0.00000000"],["77582.54000000","0.00414000"],["77582.50000000","0.00000000"],["77581.35000000","0.11615000"],["77581.32000000","0.00190000"],["77581.16000000","0.00000000"],["77581.15000000","0.12958000"],["77581.03000000","0.00000000"],["77580.81000000","0.00000000"],["77580.62000000","0.00000000"],["77580.17000000","0.00048000"],["77580.13000000","0.00000000"],["77579.95000000","0.00090000"],["77579.86000000","0.11615000"],["77579.71000000","0.11615000"],["77579.70000000","1.17547000"],["77579.49000000","0.00000000"],["77579.48000000","0.00000000"],["77579.47000000","0.00000000"],["77579.30000000","0.00000000"],["77578.96000000","0.00000000"],["77578.89000000","0.00000000"],["77578.72000000","0.00000000"],["77578.68000000","0.00000000"],["77578.23000000","0.00000000"],["77578.22000000","0.00000000"],["77578.01000000","0.00019000"],["77577.81000000","0.00000000"],["77577.77000000","3.24697000"],["77577.76000000","0.00007000"],["77577.65000000","0.00007000"],["77577.64000000","0.00000000"],["77577.49000000","0.00000000"],["77577.19000000","0.00400000"],["77577.13000000","0.00644000"],["77577.05000000","0.00000000"],["77576.28000000","0.00257000"],["77576.01000000","0.00644000"],["77575.05000000","0.02000000"],["77573.35000000","0.00000000"],["77572.94000000","0.01000000"],["77570.44000000","0.00128000"],["77569.35000000","0.00000000"],["77560.00000000","1.96226000"],["77559.53000000","0.00000000"],["77554.17000000","0.00000000"],["77551.86000000","0.00200000"],["77547.08000000","0.00007000"],["77536.63000000","0.34838000"],["77496.20000000","0.03997000"],["77486.08000000","0.00000000"],["69831.27000000","0.00432000"],["69831.26000000","0.00000000"],["69831.25000000","0.00009000"],["69831.00000000","0.00000000"]],"a":[["77590.30000000","2.97146000"],["77590.31000000","0.00027000"],["77590.83000000","0.00000000"],["77591.57000000","0.00200000"],["77591.58000000","0.00757000"],["77591.61000000","0.00328000"],["77591.62000000","0.00027000"],["77591.64000000","0.00014000"],["77591.65000000","0.38681000"],["77591.79000000","0.00257000"],["77591.81000000","1.13973000"],["77591.98000000","0.00000000"],["77592.24000000","0.00761000"],["77592.76000000","0.00000000"],["77592.82000000","0.00000000"],["77593.04000000","0.01298000"],["77593.25000000","0.00014000"],["77593.27000000","0.00007000"],["77593.28000000","0.00007000"],["77594.25000000","0.00000000"],["77594.26000000","0.02920000"],["77594.68000000","0.01200000"],["77594.77000000","0.00007000"],["77594.81000000","0.00000000"],["77595.49000000","0.00000000"],["77596.11000000","0.09635000"],["77596.12000000","3.25097000"],["77596.13000000","0.00400000"],["77596.54000000","0.00000000"],["77597.05000000","0.34778000"],["77598.88000000","0.00000000"],["77599.77000000","0.03210000"],["77600.56000000","0.27083000"],["77603.05000000","0.00000000"],["77603.70000000","0.64477000"],["77604.38000000","0.35773000"],["77604.57000000","0.00000000"],["77605.35000000","0.00000000"],["77608.57000000","0.00000000"],["77616.49000000","0.00000000"],["77621.34000000","0.00437000"],["77623.28000000","0.00008000"],["77718.89000000","0.00000000"],["77729.05000000","0.00971000"],["77776.07000000","0.00000000"]]}}
{"type":"depth","received_at_ms":1788331889072,"data":{"e":"depthUpdate","E":1788331889214,"s":"BTCUSDT","U":99555826374,"u":99555826468,"b":[["77590.29000000","0.33410000"],["77590.28000000","0.01113000"],["77590.13000000","0.00000000"],["77588.21000000","0.00007000"],["77587.61000000","0.01329000"],["77587.33000000","0.00007000"],["77587.32000000","0.10571000"],["77587.31000000","0.11629000"],["77587.10000000","0.00000000"],["77587.03000000","0.00000000"],["77586.57000000","0.00000000"],["77586.56000000","0.01668000"],["77585.99000000","0.09918000"],["77585.67000000","0.00027000"],["77581.76000000","0.00070000"],["77579.87000000","0.00600000"],["77577.24000000","0.00400000"],["77577.19000000","0.00000000"],["77577.08000000","0.00257000"],["77576.28000000","0.00000000"],["77573.59000000","0.00000000"],["77572.94000000","0.00000000"],["77568.92000000","0.00000000"],["69831.27000000","0.00448000"],["62072.24000000","0.00031000"]],"a":[["77590.30000000","2.96675000"],["77591.58000000","0.00757000"],["77591.62000000","0.00000000"],["77591.63000000","0.00014000"],["77591.64000000","1.31485000"],["77591.65000000","0.38695000"],["77591.79000000","0.00000000"],["77591.81000000","1.13959000"],["77592.59000000","0.00257000"],["77593.04000000","0.01291000"],["77593.25000000","0.00000000"],["77608.00000000","0.03265000"]]}}
{"type":"depth","received_at_ms":1788331889172,"data":{"e":"depthUpdate","E":1788331889314,"s":"BTCUSDT","U":99555826469,"u":99555826486,"b":[["77586.57000000","0.00018000"],["77577.34000000","0.00000000"],["77577.24000000","0.00000000"],["77381.66000000","0.00000000"],["77378.67000000","0.00813000"],["69831.27000000","0.00432000"]],"a":[["77591.58000000","0.00757000"],["77591.64000000","1.31499000"],["77593.04000000","0.01277000"]]}}
{"type":"depth","received_at_ms":1788331889273,"data":{"e":"depthUpdate","E":1788331889414,"s":"BTCUSDT","U":99555826487,"u":99555826488,"b":[["69831.27000000","0.00432000"]],"a":[]}}
{"type":"depth","received_at_ms":1788331889374,"data":{"e":"depthUpdate","E":1788331889514,"s":"BTCUSDT","U":99555826489,"u":99555826518,"b":[["77590.29000000","0.52590000"],["77523.08000000","0.00412000"],["69831.27000000","0.00432000"],["62072.24000000","0.00063000"]],"a":[["77590.30000000","2.96738000"],["77590.31000000","0.00062000"],["77591.22000000","0.00007000"],["77594.26000000","0.02913000"],["77594.68000000","0.00000000"],["77596.10000000","0.00400000"],["77596.11000000","0.00013000"],["77601.88000000","0.09622000"]]}}
{"type":"depth","received_at_ms":1788331889472,"data":{"e":"depthUpdate","E":1788331889614,"s":"BTCUSDT","U":99555826519,"u":99555826536,"b":[["77581.36000000","0.00092000"],["77579.95000000","0.00000000"],["77579.68000000","0.00020000"],["77578.01000000","0.00000000"],["77517.72000000","0.02000000"],["69831.27000000","0.00432000"],["62072.24000000","0.00031000"],["62072.00000000","0.15357000"]],"a":[["78754.16000000","0.00030000"]]}}
{"type":"depth","received_at_ms":1788331889576,"data":{"e":"depthUpdate","E":1788331889714,"s":"BTCUSDT","U":99555826537,"u":99555826548,"b":[["77590.29000000","0.52597000"],["77587.32000000","0.15019000"],["77586.56000000","0.01675000"],["77586.00000000","0.07775000"],["77585.86000000","0.00208000"],["69831.27000000","0.00448000"],["62072.23000000","0.00000000"]],"a":[["77590.30000000","2.96738000"],["77646.05000000","0.00412000"]]}}
{"type":"depth","received_at_ms":1788331889673,"data":{"e":"depthUpdate","E":1788331889814,"s":"BTCUSDT","U":99555826549,"u":99555826565,"b":[["77590.29000000","0.52604000"],["77586.56000000","0.01675000"],["77586.00000000","0.07789000"],["77585.99000000","0.09904000"],["77571.01000000","0.00007000"],["69831.27000000","0.00432000"]],"a":[["77590.30000000","2.96738000"],["77602.05000000","0.00007000"]]}}
{"type":"depth","received_at_ms":1788331889774,"data":{"e":"depthUpdate","E":1788331889914,"s":"BTCUSDT","U":99555826566,"u":99555826577,"b":[["77577.08000000","0.00000000"],["77561.90000000","0.00000000"],["77523.08000000","0.00000000"],["77492.06000000","0.00000000"],["69831.27000000","0.00448000"]],"a":[["77592.59000000","0.00000000"],["77607.31000000","0.00000000"],["77646.05000000","0.00000000"],["77677.09000000","0.00000000"]]}}
{"type":"trade","received_at_ms":1788331889834,"data":{"e":"trade","E":1788331889966,"s":"BTCUSDT","t":6646634292,"p":"77590.29000000","q":"0.00007000","T":1788331889965,"m":true,"M":true}}
{"type":"trade","received_at_ms":1788331889834,"data":{"e":"trade","E":1788331889966,"s":"BTCUSDT","t":6646634293,"p":"77590.29000000","q":"0.00002000","T":1788331889965,"m":true,"M":true}}
{"type":"trade","received_at_ms":1788331889834,"data":{"e":"trade","E":1788331889966,"s":"BTCUSDT","t":6646634294,"p":"77590.29000000","q":"0.00062000","T":1788331889965,"m":true,"M":true}}
{"type":"trade","received_at_ms":1788331889834,"data":{"e":"trade","E":1788331889966,"s":"BTCUSDT","t":6646634295,"p":"77590.29000000","q":"0.00013000","T":1788331889965,"m":true,"M":true}}
{"type":"trade","received_at_ms":1788331889834,"data":{"e":"trade","E":1788331889966,"s":"BTCUSDT","t":6646634296,"p":"77590.29000000","q":"0.00007000","T":1788331889965,"m":true,"M":true}}
{"type":"trade","received_at_ms":1788331889834,"data":{"e":"trade","E":1788331889966,"s":"BTCUSDT","t":6646634297,"p":"77590.29000000","q":"0.00065000","T":1788331889965,"m":true,"M":true}}
{"type":"trade","received_at_ms":1788331889834,"data":{"e":"trade","E":1788331889966,"s":"BTCUSDT","t":6646634298,"p":"77590.29000000","q":"0.00007000","T":1788331889965,"m":true,"M":true}}
{"type":"trade","received_at_ms":1788331889834,"data":{"e":"trade","E":1788331889966,"s":"BTCUSDT","t":6646634299,"p":"77590.29000000","q":"0.00008000","T":1788331889965,"m":true,"M":true}}
{"type":"trade","received_at_ms":1788331889834,"data":{"e":"trade","E":1788331889966,"s":"BTCUSDT","t":6646634300,"p":"77590.29000000","q":"0.00007000","T":1788331889965,"m":true,"M":true}}
{"type":"trade","received_at_ms":1788331889834,"data":{"e":"trade","E":1788331889966,"s":"BTCUSDT","t":6646634301,"p":"77590.29000000","q":"0.00007000","T":1788331889965,"m":true,"M":true}}
{"type":"trade","received_at_ms":1788331889834,"data":{"e":"trade","E":1788331889966,"s":"BTCUSDT","t":6646634302,"p":"77590.29000000","q":"0.03324000","T":1788331889965,"m":true,"M":true}}
{"type":"trade","received_at_ms":1788331889834,"data":{"e":"trade","E":1788331889966,"s":"BTCUSDT","t":6646634303,"p":"77590.29000000","q":"0.09562000","T":1788331889965,"m":true,"M":true}}
{"type":"trade","received_at_ms":1788331889834,"data":{"e":"trade","E":1788331889966,"s":"BTCUSDT","t":6646634304,"p":"77590.29000000","q":"0.00007000","T":1788331889965,"m":true,"M":true}}
{"type":"trade","received_at_ms":1788331889834,"data":{"e":"trade","E":1788331889966,"s":"BTCUSDT","t":6646634305,"p":"77590.29000000","q":"0.00048000","T":1788331889965,"m":true,"M":true}}
{"type":"trade","received_at_ms":1788331889834,"data":{"e":"trade","E":1788331889966,"s":"BTCUSDT","t":6646634306,"p":"77590.29000000","q":"0.00200000","T":1788331889965,"m":true,"M":true}}
{"type":"trade","received_at_ms":1788331889834,"data":{"e":"trade","E":1788331889966,"s":"BTCUSDT","t":6646634307,"p":"77590.29000000","q":"0.00200000","T":1788331889965,"m":true,"M":true}}
{"type":"trade","received_at_ms":1788331889834,"data":{"e":"trade","E":1788331889966,"s":"BTCUSDT","t":6646634308,"p":"77590.29000000","q":"0.02000000","T":1788331889965,"m":true,"M":true}}
{"type":"trade","received_at_ms":1788331889834,"data":{"e":"trade","E":1788331889966,"s":"BTCUSDT","t":6646634309,"p":"77590.29000000","q":"0.00007000","T":1788331889965,"m":true,"M":true}}
{"type":"trade","received_at_ms":1788331889834,"data":{"e":"trade","E":1788331889966,"s":"BTCUSDT","t":6646634310,"p":"77590.29000000","q":"0.00007000","T":1788331889965,"m":true,"M":true}}
{"type":"trade","received_at_ms":1788331889834,"data":{"e":"trade","E":1788331889966,"s":"BTCUSDT","t":6646634311,"p":"77590.29000000","q":"0.00200000","T":1788331889965,"m":true,"M":true}}
{"type":"trade","received_at_ms":1788331889835,"data":{"e":"trade","E":1788331889966,"s":"BTCUSDT","t":6646634312,"p":"77590.29000000","q":"0.00007000","T":1788331889965,"m":true,"M":true}}
{"type":"trade","received_at_ms":1788331889835,"data":{"e":"trade","E":1788331889966,"s":"BTCUSDT","t":6646634313,"p":"77590.29000000","q":"0.00007000","T":1788331889965,"m":true,"M":true}}
{"type":"trade","received_at_ms":1788331889835,"data":{"e":"trade","E":1788331889966,"s":"BTCUSDT","t":6646634314,"p":"77590.29000000","q":"0.00007000","T":1788331889965,"m":true,"M":true}}
{"type":"trade","received_at_ms":1788331889835,"data":{"e":"trade","E":1788331889966,"s":"BTCUSDT","t":6646634315,"p":"77590.29000000","q":"0.00007000","T":1788331889965,"m":true,"M":true}}
{"type":"trade","received_at_ms":1788331889835,"data":{"e":"trade","E":1788331889966,"s":"BTCUSDT","t":6646634316,"p":"77590.29000000","q":"0.00007000","T":1788331889965,"m":true,"M":true}}
{"type":"trade","received_at_ms":1788331889835,"data":{"e":"trade","E":1788331889966,"s":"BTCUSDT","t":6646634317,"p":"77590.29000000","q":"0.00007000","T":1788331889965,"m":true,"M":true}}
{"type":"trade","received_at_ms":1788331889835,"data":{"e":"trade","E":1788331889966,"s":"BTCUSDT","t":6646634318,"p":"77590.29000000","q":"0.00007000","T":1788331889965,"m":true,"M":true}}
{"type":"trade","received_at_ms":1788331889835,"data":{"e":"trade","E":1788331889966,"s":"BTCUSDT","t":6646634319,"p":"77590.29000000","q":"0.01000000","T":1788331889965,"m":true,"M":true}}
{"type":"trade","received_at_ms":1788331889835,"data":{"e":"trade","E":1788331889966,"s":"BTCUSDT","t":6646634320,"p":"77590.29000000","q":"0.00007000","T":1788331889965,"m":true,"M":true}}
{"type":"trade","received_at_ms":1788331889835,"data":{"e":"trade","E":1788331889966,"s":"BTCUSDT","t":6646634321,"p":"77590.29000000","q":"0.02000000","T":1788331889965,"m":true,"M":true}}
{"type":"trade","received_at_ms":1788331889835,"data":{"e":"trade","E":1788331889966,"s":"BTCUSDT","t":6646634322,"p":"77590.29000000","q":"0.01113000","T":1788331889965,"m":true,"M":true}}
{"type":"trade","received_at_ms":1788331889835,"data":{"e":"trade","E":1788331889966,"s":"BTCUSDT","t":6646634323,"p":"77590.29000000","q":"0.00200000","T":1788331889965,"m":true,"M":true}}
{"type":"trade","received_at_ms":1788331889835,"data":{"e":"trade","E":1788331889966,"s":"BTCUSDT","t":6646634324,"p":"77590.29000000","q":"0.00007000","T":1788331889965,"m":true,"M":true}}
{"type":"trade","received_at_ms":1788331889835,"data":{"e":"trade","E":1788331889966,"s":"BTCUSDT","t":6646634325,"p":"77590.29000000","q":"0.00248000","T":1788331889965,"m":true,"M":true}}
{"type":"trade","received_at_ms":1788331889835,"data":{"e":"trade","E":1788331889966,"s":"BTCUSDT","t":6646634326,"p":"77590.29000000","q":"0.00026000","T":1788331889965,"m":true,"M":true}}
{"type":"trade","received_at_ms":1788331889835,"data":{"e":"trade","E":1788331889966,"s":"BTCUSDT","t":6646634327,"p":"77590.29000000","q":"0.00007000","T":1788331889965,"m":true,"M":true}}
{"type":"trade","received_at_ms":1788331889835,"data":{"e":"trade","E":1788331889966,"s":"BTCUSDT","t":6646634328,"p":"77590.29000000","q":"0.00007000","T":1788331889965,"m":true,"M":true}}
{"type":"trade","received_at_ms":1788331889835,"data":{"e":"trade","E":1788331889966,"s":"BTCUSDT","t":6646634329,"p":"77590.29000000","q":"0.00583000","T":1788331889965,"m":true,"M":true}}
{"type":"trade","received_at_ms":1788331889835,"data":{"e":"trade","E":1788331889966,"s":"BTCUSDT","t":6646634330,"p":"77590.29000000","q":"0.00007000","T":1788331889965,"m":true,"M":true}}
{"type":"trade","received_at_ms":1788331889835,"data":{"e":"trade","E":1788331889966,"s":"BTCUSDT","t":6646634331,"p":"77590.29000000","q":"0.00007000","T":1788331889965,"m":true,"M":true}}
{"type":"trade","received_at_ms":1788331889835,"data":{"e":"trade","E":1788331889966,"s":"BTCUSDT","t":6646634332,"p":"77590.29000000","q":"0.00007000","T":1788331889965,"m":true,"M":true}}
{"type":"trade","received_at_ms":1788331889835,"data":{"e":"trade","E":1788331889966,"s":"BTCUSDT","t":6646634333,"p":"77590.29000000","q":"0.00007000","T":1788331889965,"m":true,"M":true}}
{"type":"trade","received_at_ms":1788331889835,"data":{"e":"trade","E":1788331889966,"s":"BTCUSDT","t":6646634334,"p":"77590.29000000","q":"0.00007000","T":1788331889965,"m":true,"M":true}}
{"type":"trade","received_at_ms":1788331889835,"data":{"e":"trade","E":1788331889966,"s":"BTCUSDT","t":6646634335,"p":"77590.29000000","q":"0.00007000","T":1788331889965,"m":true,"M":true}}
{"type":"trade","received_at_ms":1788331889835,"data":{"e":"trade","E":1788331889966,"s":"BTCUSDT","t":6646634336,"p":"77590.29000000","q":"0.00008000","T":1788331889965,"m":true,"M":true}}
{"type":"trade","received_at_ms":1788331889835,"data":{"e":"trade","E":1788331889966,"s":"BTCUSDT","t":6646634337,"p":"77590.29000000","q":"0.00007000","T":1788331889965,"m":true,"M":true}}
{"type":"trade","received_at_ms":1788331889835,"data":{"e":"trade","E":1788331889966,"s":"BTCUSDT","t":6646634338,"p":"77590.29000000","q":"0.00007000","T":1788331889965,"m":true,"M":true}}
{"type":"trade","received_at_ms":1788331889835,"data":{"e":"trade","E":1788331889966,"s":"BTCUSDT","t":6646634339,"p":"77590.29000000","q":"0.00007000","T":1788331889965,"m":true,"M":true}}
{"type":"trade","received_at_ms":1788331889835,"data":{"e":"trade","E":1788331889966,"s":"BTCUSDT","t":6646634340,"p":"77590.29000000","q":"0.00007000","T":1788331889965,"m":true,"M":true}}
{"type":"trade","received_at_ms":1788331889835,"data":{"e":"trade","E":1788331889966,"s":"BTCUSDT","t":6646634341,"p":"77590.29000000","q":"0.00007000","T":1788331889965,"m":true,"M":true}}
{"type":"trade","received_at_ms":1788331889835,"data":{"e":"trade","E":1788331889966,"s":"BTCUSDT","t":6646634342,"p":"77590.29000000","q":"0.00007000","T":1788331889965,"m":true,"M":true}}
{"type":"trade","received_at_ms":1788331889835,"data":{"e":"trade","E":1788331889966,"s":"BTCUSDT","t":6646634343,"p":"77590.29000000","q":"0.00007000","T":1788331889965,"m":true,"M":true}}
{"type":"trade","received_at_ms":1788331889835,"data":{"e":"trade","E":1788331889966,"s":"BTCUSDT","t":6646634344,"p":"77590.29000000","q":"0.00007000","T":1788331889965,"m":true,"M":true}}
{"type":"trade","received_at_ms":1788331889836,"data":{"e":"trade","E":1788331889966,"s":"BTCUSDT","t":6646634345,"p":"77590.29000000","q":"0.00007000","T":1788331889965,"m":true,"M":true}}
{"type":"trade","received_at_ms":1788331889836,"data":{"e":"trade","E":1788331889966,"s":"BTCUSDT","t":6646634346,"p":"77590.29000000","q":"0.00007000","T":1788331889965,"m":true,"M":true}}
{"type":"trade","received_at_ms":1788331889836,"data":{"e":"trade","E":1788331889966,"s":"BTCUSDT","t":6646634347,"p":"77590.29000000","q":"0.00007000","T":1788331889965,"m":true,"M":true}}
{"type":"trade","received_at_ms":1788331889836,"data":{"e":"trade","E":1788331889966,"s":"BTCUSDT","t":6646634348,"p":"77590.28000000","q":"0.00007000","T":1788331889965,"m":true,"M":true}}
{"type":"trade","received_at_ms":1788331889836,"data":{"e":"trade","E":1788331889966,"s":"BTCUSDT","t":6646634349,"p":"77590.28000000","q":"0.00007000","T":1788331889965,"m":true,"M":true}}
{"type":"trade","received_at_ms":1788331889836,"data":{"e":"trade","E":1788331889966,"s":"BTCUSDT","t":6646634350,"p":"77590.28000000","q":"0.00013000","T":1788331889965,"m":true,"M":true}}
{"type":"trade","received_at_ms":1788331889836,"data":{"e":"trade","E":1788331889966,"s":"BTCUSDT","t":6646634351,"p":"77590.28000000","q":"0.00816000","T":1788331889965,"m":true,"M":true}}
{"type":"trade","received_at_ms":1788331889836,"data":{"e":"trade","E":1788331889966,"s":"BTCUSDT","t":6646634352,"p":"77590.28000000","q":"0.00200000","T":1788331889965,"m":true,"M":true}}
{"type":"trade","received_at_ms":1788331889836,"data":{"e":"trade","E":1788331889966,"s":"BTCUSDT","t":6646634353,"p":"77590.28000000","q":"0.00007000","T":1788331889965,"m":true,"M":true}}
{"type":"trade","received_at_ms":1788331889836,"data":{"e":"trade","E":1788331889966,"s":"BTCUSDT","t":6646634354,"p":"77590.28000000","q":"0.00007000","T":1788331889965,"m":true,"M":true}}
{"type":"trade","received_at_ms":1788331889836,"data":{"e":"trade","E":1788331889966,"s":"BTCUSDT","t":6646634355,"p":"77590.28000000","q":"0.00007000","T":1788331889965,"m":true,"M":true}}
{"type":"trade","received_at_ms":1788331889836,"data":{"e":"trade","E":1788331889966,"s":"BTCUSDT","t":6646634356,"p":"77590.28000000","q":"0.00007000","T":1788331889965,"m":true,"M":true}}
{"type":"trade","received_at_ms":1788331889836,"data":{"e":"trade","E":1788331889966,"s":"BTCUSDT","t":6646634357,"p":"77590.28000000","q":"0.00007000","T":1788331889965,"m":true,"M":true}}
{"type":"trade","received_at_ms":1788331889836,"data":{"e":"trade","E":1788331889966,"s":"BTCUSDT","t":6646634358,"p":"77590.28000000","q":"0.00007000","T":1788331889965,"m":true,"M":true}}
{"type":"trade","received_at_ms":1788331889836,"data":{"e":"trade","E":1788331889966,"s":"BTCUSDT","t":6646634359,"p":"77590.28000000","q":"0.00007000","T":1788331889965,"m":true,"M":true}}
{"type":"trade","received_at_ms":1788331889836,"data":{"e":"trade","E":1788331889966,"s":"BTCUSDT","t":6646634360,"p":"77590.28000000","q":"0.00007000","T":1788331889965,"m":true,"M":true}}
{"type":"trade","received_at_ms":1788331889836,"data":{"e":"trade","E":1788331889966,"s":"BTCUSDT","t":6646634361,"p":"77590.28000000","q":"0.00007000","T":1788331889965,"m":true,"M":true}}
{"type":"trade","received_at_ms":1788331889836,"data":{"e":"trade","E":1788331889966,"s":"BTCUSDT","t":6646634362,"p":"77590.28000000","q":"0.00007000","T":1788331889965,"m":true,"M":true}}
{"type":"trade","received_at_ms":1788331889836,"data":{"e":"trade","E":1788331889966,"s":"BTCUSDT","t":6646634363,"p":"77590.27000000","q":"0.00013000","T":1788331889965,"m":true,"M":true}}
{"type":"trade","received_at_ms":1788331889836,"data":{"e":"trade","E":1788331889966,"s":"BTCUSDT","t":6646634364,"p":"77590.14000000","q":"0.00103000","T":1788331889965,"m":true,"M":true}}
{"type":"trade","received_at_ms":1788331889836,"data":{"e":"trade","E":1788331889966,"s":"BTCUSDT","t":6646634365,"p":"77590.01000000","q":"0.00007000","T":1788331889965,"m":true,"M":true}}
{"type":"trade","received_at_ms":1788331889836,"data":{"e":"trade","E":1788331889966,"s":"BTCUSDT","t":6646634366,"p":"77590.01000000","q":"0.00039000","T":1788331889965,"m":true,"M":true}}
{"type":"trade","received_at_ms":1788331889836,"data":{"e":"trade","E":1788331889966,"s":"BTCUSDT","t":6646634367,"p":"77590.01000000","q":"0.00007000","T":1788331889965,"m":true,"M":true}}
{"type":"trade","received_at_ms":1788331889836,"data":{"e":"trade","E":1788331889966,"s":"BTCUSDT","t":6646634368,"p":"77589.05000000","q":"0.00007000","T":1788331889965,"m":true,"M":true}}
{"type":"trade","received_at_ms":1788331889836,"data":{"e":"trade","E":1788331889966,"s":"BTCUSDT","t":6646634369,"p":"77589.05000000","q":"0.00007000","T":1788331889965,"m":true,"M":true}}
{"type":"trade","received_at_ms":1788331889836,"data":{"e":"trade","E":1788331889966,"s":"BTCUSDT","t":6646634370,"p":"77589.05000000","q":"0.00007000","T":1788331889965,"m":true,"M":true}}
{"type":"trade","received_at_ms":1788331889836,"data":{"e":"trade","E":1788331889966,"s":"BTCUSDT","t":6646634371,"p":"77589.04000000","q":"0.00697000","T":1788331889965,"m":true,"M":true}}
{"type":"trade","received_at_ms":1788331889836,"data":{"e":"trade","E":1788331889966,"s":"BTCUSDT","t":6646634372,"p":"77589.04000000","q":"0.00664000","T":1788331889965,"m":true,"M":true}}
{"type":"trade","received_at_ms":1788331889836,"data":{"e":"trade","E":1788331889966,"s":"BTCUSDT","t":6646634373,"p":"77589.04000000","q":"0.00007000","T":1788331889965,"m":true,"M":true}}
{"type":"trade","received_at_ms":1788331889836,"data":{"e":"trade","E":1788331889966,"s":"BTCUSDT","t":6646634374,"p":"77589.04000000","q":"0.00007000","T":1788331889965,"m":true,"M":true}}
{"type":"trade","received_at_ms":1788331889836,"data":{"e":"trade","E":1788331889966,"s":"BTCUSDT","t":6646634375,"p":"77588.49000000","q":"0.00007000","T":1788331889965,"m":true,"M":true}}
{"type":"trade","received_at_ms":1788331889836,"data":{"e":"trade","E":1788331889966,"s":"BTCUSDT","t":6646634376,"p":"77588.49000000","q":"0.00007000","T":1788331889965,"m":true,"M":true}}
{"type":"trade","received_at_ms":1788331889836,"data":{"e":"trade","E":1788331889966,"s":"BTCUSDT","t":6646634377,"p":"77588.28000000","q":"0.00007000","T":1788331889965,"m":true,"M":true}}
{"type":"trade","received_at_ms":1788331889836,"data":{"e":"trade","E":1788331889966,"s":"BTCUSDT","t":6646634378,"p":"77588.28000000","q":"0.00007000","T":1788331889965,"m":true,"M":true}}
{"type":"trade","received_at_ms":1788331889836,"data":{"e":"trade","E":1788331889966,"s":"BTCUSDT","t":6646634379,"p":"77588.28000000","q":"0.00007000","T":1788331889965,"m":true,"M":true}}
{"type":"trade","received_at_ms":1788331889836,"data":{"e":"trade","E":1788331889966,"s":"BTCUSDT","t":6646634380,"p":"77588.28000000","q":"0.00007000","T":1788331889965,"m":true,"M":true}}
{"type":"trade","received_at_ms":1788331889836,"data":{"e":"trade","E":1788331889966,"s":"BTCUSDT","t":6646634381,"p":"77588.21000000","q":"0.00007000","T":1788331889965,"m":true,"M":true}}
{"type":"trade","received_at_ms":1788331889836,"data":{"e":"trade","E":1788331889966,"s":"BTCUSDT","t":6646634382,"p":"77588.21000000","q":"0.00007000","T":1788331889965,"m":true,"M":true}}
{"type":"trade","received_at_ms":1788331889836,"data":{"e":"trade","E":1788331889966,"s":"BTCUSDT","t":6646634383,"p":"77587.81000000","q":"0.00007000","T":1788331889965,"m":true,"M":true}}
{"type":"trade","received_at_ms":1788331889836,"data":{"e":"trade","E":1788331889966,"s":"BTCUSDT","t":6646634384,"p":"77587.81000000","q":"0.00007000","T":1788331889965,"m":true,"M":true}}
{"type":"trade","received_at_ms":1788331889836,"data":{"e":"trade","E":1788331889966,"s":"BTCUSDT","t":6646634385,"p":"77587.81000000","q":"0.00007000","T":1788331889965,"m":true,"M":true}}
{"type":"trade","received_at_ms":1788331889836,"data":{"e":"trade","E":1788331889966,"s":"BTCUSDT","t":6646634386,"p":"77587.80000000","q":"0.00245000","T":1788331889965,"m":true,"M":true}}
{"type":"trade","received_at_ms":1788331889836,"data":{"e":"trade","E":1788331889966,"s":"BTCUSDT","t":6646634387,"p":"77587.80000000","q":"0.01388000","T":1788331889965,"m":true,"M":true}}
{"type":"trade","received_at_ms":1788331889836,"data":{"e":"trade","E":1788331889966,"s":"BTCUSDT","t":6646634388,"p":"77587.80000000","q":"0.00007000","T":1788331889965,"m":true,"M":true}}
{"type":"trade","received_at_ms":1788331889836,"data":{"e":"trade","E":1788331889966,"s":"BTCUSDT","t":6646634389,"p":"77587.80000000","q":"0.00007000","T":1788331889965,"m":true,"M":true}}
{"type":"trade","received_at_ms":1788331889836,"data":{"e":"trade","E":1788331889966,"s":"BTCUSDT","t":6646634390,"p":"77587.80000000","q":"0.00007000","T":1788331889965,"m":true,"M":true}}
{"type":"trade","received_at_ms":1788331889837,"data":{"e":"trade","E":1788331889966,"s":"BTCUSDT","t":6646634391,"p":"77587.80000000","q":"0.00007000","T":1788331889965,"m":true,"M":true}}
{"type":"trade","received_at_ms":1788331889837,"data":{"e":"trade","E":1788331889966,"s":"BTCUSDT","t":6646634392,"p":"77587.62000000","q":"0.00007000","T":1788331889965,"m":true,"M":true}}
{"type":"trade","received_at_ms":1788331889837,"data":{"e":"trade","E":1788331889966,"s":"BTCUSDT","t":6646634393,"p":"77587.62000000","q":"0.00007000","T":1788331889965,"m":true,"M":true}}
{"type":"trade","received_at_ms":1788331889837,"data":{"e":"trade","E":1788331889966,"s":"BTCUSDT","t":6646634394,"p":"77587.62000000","q":"0.00007000","T":1788331889965,"m":true,"M":true}}
{"type":"trade","received_at_ms":1788331889837,"data":{"e":"trade","E":1788331889966,"s":"BTCUSDT","t":6646634395,"p":"77587.61000000","q":"0.00563000","T":1788331889965,"m":true,"M":true}}
{"type":"trade","received_at_ms":1788331889842,"data":{"e":"trade","E":1788331889966,"s":"BTCUSDT","t":6646634396,"p":"77587.61000000","q":"0.00738000","T":1788331889966,"m":true,"M":true}}
{"type":"trade","received_at_ms":1788331889842,"data":{"e":"trade","E":1788331889966,"s":"BTCUSDT","t":6646634397,"p":"77587.61000000","q":"0.00007000","T":1788331889966,"m":true,"M":true}}
{"type":"trade","received_at_ms":1788331889842,"data":{"e":"trade","E":1788331889966,"s":"BTCUSDT","t":6646634398,"p":"77587.61000000","q":"0.00007000","T":1788331889966,"m":true,"M":true}}
{"type":"trade","received_at_ms":1788331889842,"data":{"e":"trade","E":1788331889966,"s":"BTCUSDT","t":6646634399,"p":"77587.61000000","q":"0.00007000","T":1788331889966,"m":true,"M":true}}
{"type":"trade","received_at_ms":1788331889842,"data":{"e":"trade","E":1788331889966,"s":"BTCUSDT","t":6646634400,"p":"77587.61000000","q":"0.00007000","T":1788331889966,"m":true,"M":true}}
{"type":"trade","received_at_ms":1788331889842,"data":{"e":"trade","E":1788331889966,"s":"BTCUSDT","t":6646634401,"p":"77587.61000000","q":"0.00007000","T":1788331889966,"m":true,"M":true}}
{"type":"trade","received_at_ms":1788331889842,"data":{"e":"trade","E":1788331889966,"s":"BTCUSDT","t":6646634402,"p":"77587.61000000","q":"0.00007000","T":1788331889966,"m":true,"M":true}}
{"type":"trade","received_at_ms":1788331889842,"data":{"e":"trade","E":1788331889966,"s":"BTCUSDT","t":6646634403,"p":"77587.33000000","q":"0.00007000","T":1788331889966,"m":true,"M":true}}
{"type":"trade","received_at_ms":1788331889842,"data":{"e":"trade","E":1788331889966,"s":"BTCUSDT","t":6646634404,"p":"77587.32000000","q":"0.00007000","T":1788331889966,"m":true,"M":true}}
{"type":"trade","received_at_ms":1788331889842,"data":{"e":"trade","E":1788331889966,"s":"BTCUSDT","t":6646634405,"p":"77587.32000000","q":"0.10550000","T":1788331889966,"m":true,"M":true}}
{"type":"trade","received_at_ms":1788331889842,"data":{"e":"trade","E":1788331889966,"s":"BTCUSDT","t":6646634406,"p":"77587.32000000","q":"0.00007000","T":1788331889966,"m":true,"M":true}}
{"type":"trade","received_at_ms":1788331889842,"data":{"e":"trade","E":1788331889966,"s":"BTCUSDT","t":6646634407,"p":"77587.32000000","q":"0.00007000","T":1788331889966,"m":true,"M":true}}
{"type":"trade","received_at_ms":1788331889842,"data":{"e":"trade","E":1788331889966,"s":"BTCUSDT","t":6646634408,"p":"77587.32000000","q":"0.04448000","T":1788331889966,"m":true,"M":true}}
{"type":"trade","received_at_ms":1788331889842,"data":{"e":"trade","E":1788331889966,"s":"BTCUSDT","t":6646634409,"p":"77587.31000000","q":"0.00007000","T":1788331889966,"m":true,"M":true}}
{"type":"trade","received_at_ms":1788331889842,"data":{"e":"trade","E":1788331889966,"s":"BTCUSDT","t":6646634410,"p":"77587.31000000","q":"0.00007000","T":1788331889966,"m":true,"M":true}}
{"type":"trade","received_at_ms":1788331889842,"data":{"e":"trade","E":1788331889966,"s":"BTCUSDT","t":6646634411,"p":"77587.09000000","q":"0.00007000","T":1788331889966,"m":true,"M":true}}
{"type":"trade","received_at_ms":1788331889842,"data":{"e":"trade","E":1788331889966,"s":"BTCUSDT","t":6646634412,"p":"77587.09000000","q":"0.00007000","T":1788331889966,"m":true,"M":true}}
{"type":"trade","received_at_ms":1788331889842,"data":{"e":"trade","E":1788331889966,"s":"BTCUSDT","t":6646634413,"p":"77587.02000000","q":"0.00007000","T":1788331889966,"m":true,"M":true}}
{"type":"trade","received_at_ms":1788331889842,"data":{"e":"trade","E":1788331889966,"s":"BTCUSDT","t":6646634414,"p":"77587.02000000","q":"0.00007000","T":1788331889966,"m":true,"M":true}}
{"type":"trade","received_at_ms":1788331889842,"data":{"e":"trade","E":1788331889966,"s":"BTCUSDT","t":6646634415,"p":"77587.02000000","q":"0.00007000","T":1788331889966,"m":true,"M":true}}
{"type":"trade","received_at_ms":1788331889842,"data":{"e":"trade","E":1788331889966,"s":"BTCUSDT","t":6646634416,"p":"77587.02000000","q":"0.00007000","T":1788331889966,"m":true,"M":true}}
{"type":"trade","received_at_ms":1788331889842,"data":{"e":"trade","E":1788331889966,"s":"BTCUSDT","t":6646634417,"p":"77587.02000000","q":"0.00007000","T":1788331889966,"m":true,"M":true}}
{"type":"trade","received_at_ms":1788331889842,"data":{"e":"trade","E":1788331889966,"s":"BTCUSDT","t":6646634418,"p":"77586.56000000","q":"0.00007000","T":1788331889966,"m":true,"M":true}}
{"type":"trade","received_at_ms":1788331889842,"data":{"e":"trade","E":1788331889966,"s":"BTCUSDT","t":6646634419,"p":"77586.56000000","q":"0.01633000","T":1788331889966,"m":true,"M":true}}
{"type":"trade","received_at_ms":1788331889842,"data":{"e":"trade","E":1788331889966,"s":"BTCUSDT","t":6646634420,"p":"77586.56000000","q":"0.00007000","T":1788331889966,"m":true,"M":true}}
{"type":"trade","received_at_ms":1788331889842,"data":{"e":"trade","E":1788331889966,"s":"BTCUSDT","t":6646634421,"p":"77586.56000000","q":"0.00007000","T":1788331889966,"m":true,"M":true}}
{"type":"trade","received_at_ms":1788331889842,"data":{"e":"trade","E":1788331889966,"s":"BTCUSDT","t":6646634422,"p":"77586.56000000","q":"0.00007000","T":1788331889966,"m":true,"M":true}}
{"type":"trade","received_at_ms":1788331889842,"data":{"e":"trade","E":1788331889966,"s":"BTCUSDT","t":6646634423,"p":"77586.56000000","q":"0.00007000","T":1788331889966,"m":true,"M":true}}
{"type":"trade","received_at_ms":1788331889842,"data":{"e":"trade","E":1788331889966,"s":"BTCUSDT","t":6646634424,"p":"77586.56000000","q":"0.00007000","T":1788331889966,"m":true,"M":true}}
{"type":"trade","received_at_ms":1788331889842,"data":{"e":"trade","E":1788331889966,"s":"BTCUSDT","t":6646634425,"p":"77586.56000000","q":"0.00007000","T":1788331889966,"m":true,"M":true}}
{"type":"trade","received_at_ms":1788331889842,"data":{"e":"trade","E":1788331889966,"s":"BTCUSDT","t":6646634426,"p":"77586.56000000","q":"0.00007000","T":1788331889966,"m":true,"M":true}}
{"type":"trade","received_at_ms":1788331889842,"data":{"e":"trade","E":1788331889966,"s":"BTCUSDT","t":6646634427,"p":"77586.56000000","q":"0.00007000","T":1788331889966,"m":true,"M":true}}
{"type":"trade","received_at_ms":1788331889842,"data":{"e":"trade","E":1788331889966,"s":"BTCUSDT","t":6646634428,"p":"77586.56000000","q":"0.00007000","T":1788331889966,"m":true,"M":true}}
{"type":"trade","received_at_ms":1788331889842,"data":{"e":"trade","E":1788331889966,"s":"BTCUSDT","t":6646634429,"p":"77586.48000000","q":"0.00007000","T":1788331889966,"m":true,"M":true}}
{"type":"trade","received_at_ms":1788331889842,"data":{"e":"trade","E":1788331889966,"s":"BTCUSDT","t":6646634430,"p":"77586.00000000","q":"0.00007000","T":1788331889966,"m":true,"M":true}}
{"type":"trade","received_at_ms":1788331889842,"data":{"e":"trade","E":1788331889966,"s":"BTCUSDT","t":6646634431,"p":"77586.00000000","q":"0.00007000","T":1788331889966,"m":true,"M":true}}
