{"type":"depth","received_at_ms":1788407400908,"data":{"e":"depthUpdate","E":1788407401114,"s":"BTCUSDT","U":99603311418,"u":99603311426,"b":[["77681.99000000","9.10697000"],["77667.67000000","0.00000000"],["75561.74000000","0.00010000"],["69913.80000000","0.00416000"],["69913.78000000","0.00000000"],["62145.59000000","0.00000000"]],"a":[["77682.00000000","1.76743000"],["77698.76000000","0.00000000"],["77755.34000000","0.02400000"]]}}
{"type":"depth","received_at_ms":1788407401011,"data":{"e":"depthUpdate","E":1788407401214,"s":"BTCUSDT","U":99603311427,"u":99603311439,"b":[["77681.99000000","9.10690000"],["77681.98000000","0.00063000"],["77667.67000000","0.00007000"],["69913.80000000","0.00432000"],["62145.60000000","0.00000000"]],"a":[["77698.76000000","0.00007000"],["77735.19000000","0.00000000"],["77735.32000000","0.00000000"]]}}
{"type":"depth","received_at_ms":1788407401109,"data":{"e":"depthUpdate","E":1788407401314,"s":"BTCUSDT","U":99603311440,"u":99603311450,"b":[["77681.99000000","9.10710000"],["77625.34000000","0.00432000"],["77362.28000000","0.01922000"],["69913.80000000","0.00432000"],["62146.00000000","0.00000000"]],"a":[["77682.00000000","1.76791000"],["77727.20000000","0.00432000"]]}}
{"type":"depth","received_at_ms":1788407401209,"data":{"e":"depthUpdate","E":1788407401414,"s":"BTCUSDT","U":99603311451,"u":99603311456,"b":[["69913.80000000","0.00416000"],["62146.00000000","0.00000000"]],"a":[["77929.95000000","0.01922000"]]}}
{"type":"depth","received_at_ms":1788407401312,"data":{"e":"depthUpdate","E":1788407401514,"s":"BTCUSDT","U":99603311457,"u":99603311463,"b":[["77576.72000000","0.00116000"],["77567.52000000","0.00000000"],["69913.80000000","0.00448000"],["62145.60000000","0.00032000"]],"a":[["77754.61000000","0.02000000"],["81006.07000000","0.00010000"]]}}
{"type":"depth","received_at_ms":1788407401409,"data":{"e":"depthUpdate","E":1788407401614,"s":"BTCUSDT","U":99603311464,"u":99603311476,"b":[["77681.22000000","0.00257000"],["77679.52000000","0.00000000"],["69913.80000000","0.00432000"],["62145.60000000","0.00000000"]],"a":[["77682.00000000","1.76784000"],["77685.26000000","0.00014000"],["77685.84000000","0.17060000"],["77694.28000000","0.00000000"],["77696.75000000","0.00257000"],["77724.96000000","0.00007000"]]}}
{"type":"depth","received_at_ms":1788407401520,"data":{"e":"depthUpdate","E":1788407401714,"s":"BTCUSDT","U":99603311477,"u":99603311501,"b":[["77681.99000000","8.93840000"],["77681.98000000","0.00070000"],["77680.76000000","0.00000000"],["77680.22000000","0.00130000"],["77665.30000000","0.00000000"],["77664.62000000","0.27988000"],["77498.35000000","0.16870000"],["76516.76000000","0.00030000"],["69913.80000000","0.00441000"]],"a":[["77682.00000000","2.16473000"],["77685.06000000","0.32214000"],["77685.26000000","0.00000000"],["77685.29000000","0.00671000"],["77685.84000000","0.17074000"]]}}
{"type":"depth","received_at_ms":1788407401609,"data":{"e":"depthUpdate","E":1788407401814,"s":"BTCUSDT","U":99603311502,"u":99603311526,"b":[["77681.99000000","8.75202000"],["77681.40000000","0.00014000"],["77679.29000000","0.00007000"],["69913.80000000","0.00441000"],["62146.00000000","0.00000000"]],"a":[["77682.00000000","2.35133000"],["77682.01000000","0.00091000"],["77683.43000000","0.00014000"],["77683.44000000","0.17704000"],["77683.45000000","0.00014000"],["77685.06000000","0.32214000"],["77685.29000000","0.00685000"],["77685.84000000","0.17060000"]]}}
{"type":"depth","received_at_ms":1788407401709,"data":{"e":"depthUpdate","E":1788407401914,"s":"BTCUSDT","U":99603311527,"u":99603311552,"b":[["77681.99000000","8.75735000"],["77681.39000000","0.09138000"],["69913.80000000","0.00457000"]],"a":[["77682.00000000","2.35126000"],["77683.44000000","0.17697000"],["77683.45000000","0.00000000"],["77685.29000000","0.00014000"],["77685.84000000","0.17074000"],["77686.78000000","0.00000000"],["77687.26000000","0.00517000"],["77687.62000000","0.00208000"],["77734.58000000","0.00000000"],["78847.23000000","0.00030000"]]}}
{"type":"depth","received_at_ms":1788407401809,"data":{"e":"depthUpdate","E":1788407402014,"s":"BTCUSDT","U":99603311553,"u":99603311576,"b":[["77681.99000000","8.83648000"],["77664.61000000","0.00000000"],["77664.27000000","0.25755000"],["76500.00000000","26.58772000"],["71467.43000000","0.00014000"],["69913.80000000","0.00441000"],["62145.60000000","0.00032000"],["62145.59000000","0.00020000"]],"a":[["77682.00000000","2.16488000"],["77685.06000000","0.32214000"],["77685.29000000","0.00000000"],["77686.00000000","0.03014000"],["77687.26000000","0.00000000"],["77702.34000000","0.25817000"],["77702.81000000","0.00000000"],["77706.46000000","0.25755000"],["77707.49000000","0.00013000"],["77724.96000000","0.00000000"],["77734.87000000","0.00000000"]]}}
{"type":"depth","received_at_ms":1788407401910,"data":{"e":"depthUpdate","E":1788407402114,"s":"BTCUSDT","U":99603311577,"u":99603311586,"b":[["77661.27000000","0.00000000"],["77659.07000000","0.04695000"],["77474.76000000","0.00000000"],["77464.81000000","0.00812000"],["69913.80000000","0.00457000"],["62146.00000000","0.00200000"],["62145.59000000","0.00000000"]],"a":[["77708.55000000","0.04765000"]]}}
{"type":"depth","received_at_ms":1788407402009,"data":{"e":"depthUpdate","E":1788407402214,"s":"BTCUSDT","U":99603311587,"u":99603311601,"b":[["77667.67000000","0.00007000"],["69913.80000000","0.00432000"],["69913.79000000","0.00009000"],["62146.00000000","0.00000000"],["62145.60000000","0.00000000"]],"a":[["77682.00000000","2.16488000"],["77695.20000000","0.00257000"],["77696.75000000","0.00000000"],["77698.76000000","0.00007000"],["77734.98000000","0.00000000"]]}}
{"type":"depth","received_at_ms":1788407402109,"data":{"e":"depthUpdate","E":1788407402314,"s":"BTCUSDT","U":99603311602,"u":99603311621,"b":[["77681.99000000","8.83648000"],["77681.98000000","0.00070000"],["77681.22000000","0.00000000"],["77681.21000000","0.00257000"],["77680.78000000","0.00132000"],["77680.22000000","0.00000000"],["77674.89000000","0.00400000"],["77672.79000000","0.00000000"],["77667.60000000","0.00000000"],["69913.80000000","0.00448000"],["62146.00000000","0.00000000"]],"a":[["77682.00000000","1.99618000"],["77695.75000000","0.00000000"],["77734.76000000","0.00000000"]]}}
{"type":"depth","received_at_ms":1788407402209,"data":{"e":"depthUpdate","E":1788407402414,"s":"BTCUSDT","U":99603311622,"u":99603311638,"b":[["77681.99000000","8.83648000"],["77681.98000000","0.00070000"],["77681.21000000","0.00000000"],["77681.19000000","0.00257000"],["77672.53000000","0.00200000"],["69913.80000000","0.00432000"],["62146.00000000","0.00000000"]],"a":[["77693.34000000","0.00000000"],["77695.13000000","0.00643000"],["77696.17000000","0.00000000"],["77710.00000000","0.73200000"],["77712.00000000","0.03265000"],["77716.99000000","0.00000000"],["77735.17000000","0.00000000"]]}}
{"type":"depth","received_at_ms":1788407402309,"data":{"e":"depthUpdate","E":1788407402515,"s":"BTCUSDT","U":99603311639,"u":99603311648,"b":[["77681.19000000","0.00000000"],["77681.17000000","0.00257000"],["77680.00000000","0.62317000"],["77679.84000000","0.00000000"],["77667.55000000","0.08934000"],["69913.80000000","0.00448000"],["62145.60000000","0.00032000"]],"a":[["77695.70000000","0.26636000"],["77695.99000000","0.00200000"]]}}
{"type":"depth","received_at_ms":1788407402409,"data":{"e":"depthUpdate","E":1788407402614,"s":"BTCUSDT","U":99603311649,"u":99603311677,"b":[["77681.99000000","8.83641000"],["77681.98000000","0.00070000"],["77681.17000000","0.00000000"],["77681.16000000","0.00000000"],["77679.99000000","0.22570000"],["77672.53000000","0.00000000"],["71467.43000000","0.00000000"],["69913.80000000","0.00432000"],["62146.00000000","0.00000000"],["62145.60000000","0.00000000"]],"a":[["77693.34000000","0.00200000"],["77695.99000000","0.00000000"],["77744.11000000","0.85229000"]]}}
{"type":"depth","received_at_ms":1788407402509,"data":{"e":"depthUpdate","E":1788407402715,"s":"BTCUSDT","U":99603311678,"u":99603311689,"b":[["77681.99000000","8.83641000"],["77681.98000000","0.00070000"],["77681.14000000","0.00257000"],["77672.85000000","0.00200000"],["76516.76000000","0.00030000"],["69913.80000000","0.00432000"]],"a":[["77682.00000000","2.01530000"]]}}
{"type":"depth","received_at_ms":1788407402609,"data":{"e":"depthUpdate","E":1788407402814,"s":"BTCUSDT","U":99603311690,"u":99603311695,"b":[["77681.14000000","0.00000000"],["77681.13000000","0.00257000"],["69913.80000000","0.00432000"]],"a":[["77735.78000000","0.00000000"]]}}
{"type":"depth","received_at_ms":1788407402709,"data":{"e":"depthUpdate","E":1788407402914,"s":"BTCUSDT","U":99603311696,"u":99603311714,"b":[["77681.99000000","8.83633000"],["77681.98000000","0.00070000"],["77681.13000000","0.00000000"],["77681.11000000","0.00257000"],["77674.89000000","0.00600000"],["77672.85000000","0.00000000"],["69913.80000000","0.00432000"],["62146.00000000","0.00000000"]],"a":[["78847.23000000","0.00030000"]]}}
{"type":"depth","received_at_ms":1788407402809,"data":{"e":"depthUpdate","E":1788407403014,"s":"BTCUSDT","U":99603311715,"u":99603311733,"b":[["77681.99000000","8.83648000"],["77681.98000000","0.00070000"],["77681.11000000","0.00000000"],["77681.10000000","0.00257000"],["77680.00000000","0.61674000"],["77679.86000000","0.00643000"],["77674.89000000","0.00400000"],["77672.85000000","0.00000000"],["77664.62000000","0.00000000"],["77664.28000000","0.28268000"],["69913.80000000","0.00432000"],["62146.00000000","0.00000000"],["62145.60000000","0.00032000"]],"a":[["77702.34000000","0.00000000"],["77702.81000000","0.29207000"]]}}
{"type":"depth","received_at_ms":1788407402909,"data":{"e":"depthUpdate","E":1788407403114,"s":"BTCUSDT","U":99603311734,"u":99603311749,"b":[["77681.99000000","8.83108000"],["77681.98000000","0.00063000"],["77681.10000000","0.00000000"],["77681.08000000","0.00257000"],["77679.99000000","0.22570000"],["77674.89000000","0.00600000"],["69913.80000000","0.00432000"],["62145.59000000","0.00000000"]],"a":[]}}
{"type":"depth","received_at_ms":1788407403008,"data":{"e":"depthUpdate","E":1788407403214,"s":"BTCUSDT","U":99603311750,"u":99603311759,"b":[["77681.08000000","0.00000000"],["77681.07000000","0.00257000"],["77667.67000000","0.00007000"],["69913.80000000","0.00448000"],["62145.60000000","0.00000000"]],"a":[["77698.76000000","0.00007000"],["77755.84000000","0.02600000"]]}}
{"type":"depth","received_at_ms":1788407403111,"data":{"e":"depthUpdate","E":1788407403314,"s":"BTCUSDT","U":99603311760,"u":99603311775,"b":[["77681.99000000","8.82729000"],["77681.98000000","0.00070000"],["77681.07000000","0.00000000"],["77681.05000000","0.00257000"],["77674.89000000","0.00600000"],["69913.80000000","0.00416000"],["69913.79000000","0.00000000"],["62146.00000000","0.00000000"]],"a":[["77682.00000000","2.01502000"],["77695.20000000","0.00000000"],["77695.90000000","0.00257000"]]}}
{"type":"depth","received_at_ms":1788407403209,"data":{"e":"depthUpdate","E":1788407403414,"s":"BTCUSDT","U":99603311776,"u":99603311781,"b":[["69913.80000000","0.00448000"],["62146.00000000","0.00000000"]],"a":[]}}
{"type":"depth","received_at_ms":1788407403308,"data":{"e":"depthUpdate","E":1788407403514,"s":"BTCUSDT","U":99603311782,"u":99603311788,"b":[["77681.99000000","8.82470000"],["69913.80000000","0.00432000"],["62145.60000000","0.00032000"]],"a":[["77735.77000000","0.00000000"]]}}
{"type":"depth","received_at_ms":1788407403409,"data":{"e":"depthUpdate","E":1788407403614,"s":"BTCUSDT","U":99603311789,"u":99603311801,"b":[["77681.99000000","8.82470000"],["77681.98000000","0.00070000"],["77680.77000000","0.00014000"],["77680.22000000","0.00643000"],["77674.89000000","0.00400000"],["77672.85000000","0.00200000"],["69913.80000000","0.00448000"],["62145.60000000","0.00000000"]],"a":[["77736.68000000","0.00000000"]]}}
{"type":"depth","received_at_ms":1788407403510,"data":{"e":"depthUpdate","E":1788407403714,"s":"BTCUSDT","U":99603311802,"u":99603311831,"b":[["77681.99000000","8.82456000"],["77681.39000000","0.09131000"],["77680.77000000","0.00000000"],["77680.74000000","0.01705000"],["77680.22000000","0.00671000"],["77680.21000000","0.02220000"],["77679.86000000","0.00000000"],["77679.83000000","0.00000000"],["77679.31000000","0.00000000"],["77672.85000000","0.00000000"],["76516.76000000","0.00030000"],["69913.80000000","0.00448000"]],"a":[["77735.30000000","0.00000000"]]}}
{"type":"depth","received_at_ms":1788407403609,"data":{"e":"depthUpdate","E":1788407403814,"s":"BTCUSDT","U":99603311832,"u":99603311841,"b":[["77679.99000000","0.22570000"],["77674.89000000","0.00600000"],["69913.80000000","0.00464000"]],"a":[["77735.28000000","0.00000000"]]}}
{"type":"depth","received_at_ms":1788407403712,"data":{"e":"depthUpdate","E":1788407403914,"s":"BTCUSDT","U":99603311842,"u":99603311846,"b":[["69913.80000000","0.00448000"]],"a":[["78847.23000000","0.00030000"]]}}
{"type":"depth","received_at_ms":1788407403809,"data":{"e":"depthUpdate","E":1788407404014,"s":"BTCUSDT","U":99603311847,"u":99603311849,"b":[["77680.79000000","0.00643000"],["77680.22000000","0.00028000"],["69913.80000000","0.00464000"],["62145.60000000","0.00032000"]],"a":[]}}
{"type":"depth","received_at_ms":1788407403910,"data":{"e":"depthUpdate","E":1788407404114,"s":"BTCUSDT","U":99603311850,"u":99603311878,"b":[["77681.99000000","8.82456000"],["77681.98000000","0.00070000"],["77681.39000000","0.09138000"],["77681.05000000","0.00000000"],["77680.79000000","0.00657000"],["77680.74000000","0.01705000"],["77680.22000000","0.00014000"],["77678.32000000","0.00257000"],["69913.80000000","0.00448000"],["62145.59000000","0.00000000"]],"a":[["77682.00000000","2.01529000"],["77687.62000000","0.00000000"],["77693.85000000","0.00657000"],["77695.90000000","0.00000000"]]}}
{"type":"depth","received_at_ms":1788407404010,"data":{"e":"depthUpdate","E":1788407404214,"s":"BTCUSDT","U":99603311879,"u":99603311888,"b":[["77667.67000000","0.00000000"],["69913.80000000","0.00448000"],["62145.60000000","0.00000000"],["62145.59000000","0.00000000"]],"a":[["77684.43000000","0.00000000"],["77698.76000000","0.00000000"],["77730.54000000","0.00100000"]]}}
{"type":"depth","received_at_ms":1788407404109,"data":{"e":"depthUpdate","E":1788407404314,"s":"BTCUSDT","U":99603311889,"u":99603311897,"b":[["77681.99000000","8.82449000"],["77681.98000000","0.00063000"],["77667.67000000","0.00007000"],["77665.30000000","0.27886000"],["77664.28000000","0.00008000"],["62146.00000000","0.00000000"]],"a":[["77682.00000000","2.01502000"],["77698.76000000","0.00007000"],["77706.46000000","0.00000000"],["77707.49000000","0.25768000"]]}}
{"type":"depth","received_at_ms":1788407404209,"data":{"e":"depthUpdate","E":1788407404414,"s":"BTCUSDT","U":99603311898,"u":99603311902,"b":[["77665.30000000","0.00000000"],["77664.28000000","0.27903000"],["69913.80000000","0.00448000"]],"a":[]}}
{"type":"depth","received_at_ms":1788407404312,"data":{"e":"depthUpdate","E":1788407404514,"s":"BTCUSDT","U":99603311903,"u":99603311911,"b":[["77674.89000000","0.00400000"],["77672.85000000","0.00200000"],["77667.55000000","0.00000000"],["69913.80000000","0.00464000"],["62145.60000000","0.00032000"]],"a":[["77695.70000000","0.00000000"],["77736.29000000","0.12878000"]]}}
{"type":"depth","received_at_ms":1788407404409,"data":{"e":"depthUpdate","E":1788407404614,"s":"BTCUSDT","U":99603311912,"u":99603311928,"b":[["77681.99000000","8.82456000"],["77680.74000000","0.01698000"],["77680.22000000","0.00000000"],["77680.21000000","0.01577000"],["77679.99000000","0.22577000"],["77679.86000000","0.00643000"],["77679.83000000","0.00007000"],["77679.10000000","0.00257000"],["77678.32000000","0.00000000"],["69913.80000000","0.00432000"],["62145.60000000","0.00000000"]],"a":[["77684.89000000","0.00007000"],["77693.34000000","0.00000000"],["77693.85000000","0.00400000"],["77694.63000000","0.00257000"],["77695.99000000","0.00200000"]]}}
{"type":"depth","received_at_ms":1788407404510,"data":{"e":"depthUpdate","E":1788407404714,"s":"BTCUSDT","U":99603311929,"u":99603311938,"b":[["77679.99000000","0.22577000"],["77674.89000000","0.00600000"],["77672.85000000","0.00000000"],["76516.76000000","0.00030000"],["69913.80000000","0.00464000"]],"a":[]}}
{"type":"depth","received_at_ms":1788407404609,"data":{"e":"depthUpdate","E":1788407404814,"s":"BTCUSDT","U":99603311939,"u":99603311947,"b":[["77674.89000000","0.00400000"],["77672.85000000","0.00200000"],["77667.58000000","0.09062000"],["69913.80000000","0.00448000"],["62146.00000000","0.00000000"]],"a":[["77695.73000000","0.26804000"]]}}
{"type":"depth","received_at_ms":1788407404709,"data":{"e":"depthUpdate","E":1788407404914,"s":"BTCUSDT","U":99603311948,"u":99603311962,"b":[["77681.99000000","8.82448000"],["77400.46000000","0.00000000"],["69913.80000000","0.00448000"]],"a":[["77693.34000000","0.00200000"],["77695.99000000","0.00000000"],["77736.05000000","0.00000000"],["77736.29000000","0.00000000"],["77736.37000000","0.12878000"],["77919.39000000","0.00000000"],["78847.23000000","0.00030000"]]}}
{"type":"depth","received_at_ms":1788407404809,"data":{"e":"depthUpdate","E":1788407405014,"s":"BTCUSDT","U":99603311963,"u":99603311972,"b":[["77262.28000000","0.00000000"],["69913.80000000","0.00448000"],["62145.60000000","0.00032000"]],"a":[["77735.91000000","0.02400000"],["77736.17000000","0.00000000"],["77736.30000000","0.12878000"],["77736.37000000","0.00000000"]]}}
{"type":"depth","received_at_ms":1788407404909,"data":{"e":"depthUpdate","E":1788407405114,"s":"BTCUSDT","U":99603311973,"u":99603311980,"b":[["69913.80000000","0.00464000"],["62146.00000000","0.00200000"],["62145.59000000","0.00000000"]],"a":[["77736.30000000","0.00000000"],["77977.46000000","0.00000000"]]}}
{"type":"depth","received_at_ms":1788407405010,"data":{"e":"depthUpdate","E":1788407405214,"s":"BTCUSDT","U":99603311981,"u":99603311995,"b":[["77678.39000000","0.04040000"],["77674.89000000","0.00400000"],["77672.85000000","0.00000000"],["77099.07000000","0.00000000"],["76950.40000000","0.00000000"],["69913.80000000","0.00457000"],["62146.00000000","0.00000000"],["62145.60000000","0.00000000"],["62145.59000000","0.00000000"]],"a":[["77682.00000000","2.01486000"]]}}
{"type":"depth","received_at_ms":1788407405109,"data":{"e":"depthUpdate","E":1788407405314,"s":"BTCUSDT","U":99603311996,"u":99603312005,"b":[["77674.89000000","0.00400000"],["77672.85000000","0.00200000"],["77667.67000000","0.00007000"],["76748.41000000","0.00000000"],["69913.80000000","0.00473000"],["62146.00000000","0.00000000"]],"a":[["77698.76000000","0.00007000"]]}}
{"type":"depth","received_at_ms":1788407405210,"data":{"e":"depthUpdate","E":1788407405415,"s":"BTCUSDT","U":99603312006,"u":99603312013,"b":[["77674.89000000","0.00600000"],["77672.85000000","0.00000000"],["76538.83000000","0.00000000"],["69913.80000000","0.00457000"]],"a":[["77718.65000000","0.00000000"],["85000.00000000","159.98827000"]]}}
{"type":"depth","received_at_ms":1788407405309,"data":{"e":"depthUpdate","E":1788407405514,"s":"BTCUSDT","U":99603312014,"u":99603312029,"b":[["77681.99000000","8.82456000"],["77674.89000000","0.00400000"],["77672.79000000","0.00200000"],["77665.30000000","0.27896000"],["77664.28000000","0.00008000"],["76297.05000000","0.00000000"],["76022.37000000","0.00000000"],["69913.80000000","0.00457000"],["62145.60000000","0.00032000"]],"a":[["77682.00000000","2.02331000"],["77736.26000000","0.00000000"]]}}
{"type":"depth","received_at_ms":1788407405412,"data":{"e":"depthUpdate","E":1788407405614,"s":"BTCUSDT","U":99603312030,"u":99603312044,"b":[["77674.89000000","0.00600000"],["77672.79000000","0.00000000"],["76863.58000000","0.00134000"],["75475.12000000","0.00000000"],["62146.00000000","0.00000000"],["62145.60000000","0.00000000"]],"a":[["77682.00000000","1.87586000"],["77735.69000000","0.00000000"]]}}
{"type":"depth","received_at_ms":1788407405509,"data":{"e":"depthUpdate","E":1788407405714,"s":"BTCUSDT","U":99603312045,"u":99603312050,"b":[["76516.76000000","0.00030000"],["69913.80000000","0.00457000"]],"a":[]}}
{"type":"depth","received_at_ms":1788407405608,"data":{"e":"depthUpdate","E":1788407405814,"s":"BTCUSDT","U":99603312051,"u":99603312057,"b":[["77674.89000000","0.00400000"],["77672.85000000","0.00000000"],["69913.80000000","0.00457000"]],"a":[["77734.99000000","0.00000000"]]}}
{"type":"depth","received_at_ms":1788407405709,"data":{"e":"depthUpdate","E":1788407405914,"s":"BTCUSDT","U":99603312058,"u":99603312064,"b":[["77681.99000000","8.82983000"],["77674.89000000","0.00600000"],["69913.80000000","0.00457000"]],"a":[["77682.00000000","1.87626000"],["78847.23000000","0.00030000"]]}}
{"type":"depth","received_at_ms":1788407405809,"data":{"e":"depthUpdate","E":1788407406014,"s":"BTCUSDT","U":99603312065,"u":99603312083,"b":[["77680.80000000","0.00131000"],["77680.78000000","0.00000000"],["77680.22000000","0.00000000"],["77679.10000000","0.00000000"],["77678.90000000","0.00257000"],["77674.89000000","0.00400000"],["77672.79000000","0.00200000"],["75561.74000000","0.00000000"],["69913.80000000","0.00473000"],["62146.00000000","0.00000000"],["62145.60000000","0.00032000"]],"a":[["77687.52000000","0.00000000"],["77694.42000000","0.00257000"],["77694.63000000","0.00000000"],["81006.07000000","0.00000000"]]}}
{"type":"depth","received_at_ms":1788407405917,"data":{"e":"depthUpdate","E":1788407406114,"s":"BTCUSDT","U":99603312084,"u":99603312095,"b":[["77674.89000000","0.00400000"],["77672.79000000","0.00000000"],["77504.50000000","0.00000000"],["69913.80000000","0.00457000"],["62145.59000000","0.00000000"]],"a":[["77782.64000000","2.60864000"],["77785.19000000","0.00000000"],["77861.33000000","0.00000000"]]}}
{"type":"depth","received_at_ms":1788407406023,"data":{"e":"depthUpdate","E":1788407406214,"s":"BTCUSDT","U":99603312096,"u":99603312151,"b":[["77681.99000000","8.83633000"],["77681.98000000","0.00070000"],["77681.41000000","0.00131000"],["77680.81000000","0.00643000"],["77680.80000000","0.00000000"],["77680.79000000","0.00014000"],["77679.99000000","0.22570000"],["77679.86000000","0.00000000"],["77675.58000000","0.00200000"],["77674.89000000","0.31266000"],["77672.85000000","0.00000000"],["77661.26000000","0.00200000"],["77658.00000000","0.03000000"],["69913.80000000","0.00457000"],["62145.60000000","0.00000000"],["62145.59000000","0.00000000"]],"a":[["77682.00000000","1.84061000"],["77682.01000000","0.00084000"],["77683.43000000","0.00000000"],["77683.44000000","0.00014000"],["77684.89000000","0.00014000"],["77685.05000000","0.00007000"],["77689.40000000","0.00000000"],["77689.49000000","0.00000000"],["77691.06000000","0.00000000"],["77692.20000000","0.00000000"],["77692.38000000","0.00513000"],["77692.48000000","0.00400000"],["77693.16000000","0.00000000"],["77693.35000000","0.34058000"],["77693.36000000","0.00000000"],["77693.70000000","0.00000000"],["77694.60000000","0.00400000"],["77695.13000000","0.00000000"],["77695.72000000","0.00643000"],["77702.81000000","0.00000000"],["77703.54000000","0.30403000"],["77706.47000000","0.00000000"],["77707.48000000","0.64389000"]]}}
{"type":"depth","received_at_ms":1788407406109,"data":{"e":"depthUpdate","E":1788407406314,"s":"BTCUSDT","U":99603312152,"u":99603312218,"b":[["77681.99000000","8.83626000"],["77681.98000000","0.00063000"],["77681.39000000","0.09138000"],["77680.81000000","0.00657000"],["77680.79000000","0.00000000"],["77679.99000000","0.22570000"],["77679.74000000","0.00257000"],["77678.90000000","0.00000000"],["77667.67000000","0.00007000"],["77503.42000000","4.41768000"],["77430.22000000","0.00119000"],["77389.56000000","0.00000000"],["69913.80000000","0.00457000"],["62146.00000000","0.00000000"]],"a":[["77682.00000000","1.84068000"],["77682.01000000","0.00084000"],["77682.23000000","0.00000000"],["77682.24000000","0.00014000"],["77683.44000000","0.00000000"],["77684.88000000","0.00014000"],["77684.89000000","0.12717000"],["77685.06000000","0.32221000"],["77686.22000000","0.00548000"],["77686.99000000","0.00208000"],["77690.94000000","0.00048000"],["77693.34000000","0.00000000"],["77694.42000000","0.00000000"],["77694.60000000","0.00000000"],["77695.05000000","0.10315000"],["77695.11000000","0.00400000"],["77695.27000000","0.00257000"],["77695.53000000","0.10315000"],["77697.26000000","0.10315000"],["77698.40000000","0.00600000"],["77698.76000000","0.00007000"],["77710.00000000","0.03200000"],["77755.40000000","0.12560000"],["77755.41000000","0.00000000"],["77762.76000000","0.25749000"],["77860.40000000","4.38679000"]]}}
{"type":"depth","received_at_ms":1788407406210,"data":{"e":"depthUpdate","E":1788407406414,"s":"BTCUSDT","U":99603312219,"u":99603312246,"b":[["77681.99000000","8.83597000"],["77675.58000000","0.00000000"],["77674.90000000","0.00200000"],["77661.26000000","0.00000000"],["77659.72000000","0.00200000"],["76927.80000000","0.00444000"],["69913.80000000","0.00464000"],["69913.79000000","0.00009000"]],"a":[["77682.00000000","1.84061000"],["77682.24000000","0.00000000"],["77684.77000000","0.03190000"],["77684.89000000","0.12731000"],["77734.57000000","0.00000000"],["77921.28000000","0.00055000"]]}}
{"type":"depth","received_at_ms":1788407406309,"data":{"e":"depthUpdate","E":1788407406514,"s":"BTCUSDT","U":99603312247,"u":99603312289,"b":[["77681.99000000","8.84342000"],["77681.71000000","0.00400000"],["77681.41000000","0.00000000"],["77680.81000000","0.00014000"],["77679.85000000","0.00000000"],["77679.74000000","0.00000000"],["77676.96000000","0.00200000"],["77676.31000000","0.01200000"],["77676.18000000","0.00800000"],["77674.90000000","0.00000000"],["77673.66000000","0.00000000"],["77669.99000000","0.11715000"],["77668.01000000","0.00000000"],["77644.77000000","1.27554000"],["77579.07000000","0.00000000"],["69913.80000000","0.00432000"],["62145.60000000","0.00032000"]],"a":[["77682.00000000","1.09164000"],["77684.22000000","0.11328000"],["77684.89000000","0.00028000"],["77692.38000000","0.00000000"],["77693.14000000","0.00528000"],["77695.11000000","0.00000000"],["77695.27000000","0.00000000"],["77695.72000000","0.00000000"],["77696.18000000","0.00400000"],["77696.89000000","0.00000000"],["77697.70000000","0.00643000"],["77698.40000000","0.00200000"],["77703.54000000","0.00000000"],["77705.99000000","0.46786000"],["77734.65000000","0.12878000"],["77734.82000000","0.00000000"]]}}
{"type":"depth","received_at_ms":1788407406410,"data":{"e":"depthUpdate","E":1788407406614,"s":"BTCUSDT","U":99603312290,"u":99603312358,"b":[["77681.99000000","8.84300000"],["77681.98000000","0.00049000"],["77681.71000000","0.00000000"],["77681.39000000","0.09131000"],["77681.23000000","0.00400000"],["77680.81000000","0.00000000"],["77680.64000000","0.00257000"],["77679.50000000","0.02035000"],["77676.96000000","0.00000000"],["77676.92000000","0.01021000"],["77676.22000000","0.00200000"],["77676.21000000","0.02007000"],["77651.06000000","0.04775000"],["77579.55000000","0.47930000"],["77474.76000000","0.00812000"],["77464.81000000","0.00000000"],["77282.44000000","0.00044000"],["69913.80000000","0.00464000"],["62146.00000000","0.00200000"],["62145.60000000","0.00000000"]],"a":[["77682.00000000","1.09314000"],["77682.01000000","0.00084000"],["77684.00000000","0.03028000"],["77684.21000000","0.00014000"],["77684.22000000","0.11342000"],["77684.77000000","0.03190000"],["77684.88000000","0.00000000"],["77684.89000000","0.00014000"],["77696.17000000","0.00257000"],["77696.18000000","0.00000000"],["77697.22000000","0.00400000"],["77698.40000000","0.01000000"],["77734.65000000","0.00000000"],["77734.79000000","0.00000000"]]}}
{"type":"depth","received_at_ms":1788407406509,"data":{"e":"depthUpdate","E":1788407406714,"s":"BTCUSDT","U":99603312359,"u":99603312376,"b":[["77681.99000000","8.84300000"],["77681.98000000","0.00049000"],["76516.76000000","0.00030000"],["69913.80000000","0.00448000"],["62146.00000000","0.00000000"]],"a":[["77683.82000000","0.00000000"],["77734.56000000","0.00000000"],["77977.46000000","0.00033000"]]}}
{"type":"depth","received_at_ms":1788407406608,"data":{"e":"depthUpdate","E":1788407406814,"s":"BTCUSDT","U":99603312377,"u":99603312382,"b":[["69913.80000000","0.00448000"]],"a":[["77734.68000000","0.00000000"],["77734.80000000","0.00000000"]]}}
{"type":"depth","received_at_ms":1788407406710,"data":{"e":"depthUpdate","E":1788407406914,"s":"BTCUSDT","U":99603312383,"u":99603312396,"b":[["77681.99000000","8.84292000"],["77652.00000000","0.73000000"],["77120.45000000","0.00014000"],["75561.74000000","0.00010000"],["69913.80000000","0.00448000"]],"a":[["77734.40000000","0.00000000"],["77782.64000000","0.00000000"],["77785.19000000","2.60864000"],["78847.23000000","0.00030000"]]}}
{"type":"depth","received_at_ms":1788407406809,"data":{"e":"depthUpdate","E":1788407407014,"s":"BTCUSDT","U":99603312397,"u":99603312409,"b":[["77681.99000000","8.83649000"],["77681.41000000","0.00643000"],["77665.91000000","0.25755000"],["77664.27000000","0.00000000"],["69913.80000000","0.00448000"],["62145.60000000","0.00032000"]],"a":[["77682.00000000","1.09164000"],["77697.70000000","0.00000000"],["77698.86000000","0.00643000"],["77707.49000000","0.00013000"],["77708.54000000","0.25755000"],["77720.00000000","0.73000000"],["77735.12000000","0.12878000"],["81006.07000000","0.00010000"]]}}
{"type":"depth","received_at_ms":1788407406909,"data":{"e":"depthUpdate","E":1788407407114,"s":"BTCUSDT","U":99603312410,"u":99603312513,"b":[["77681.99000000","8.86258000"],["77681.98000000","0.00014000"],["77681.59000000","0.00257000"],["77681.41000000","0.00000000"],["77680.64000000","0.00000000"],["77677.63000000","0.00200000"],["77676.22000000","0.00000000"],["77676.21000000","0.00007000"],["77676.18000000","0.00400000"],["77672.00000000","0.11462000"],["77669.99000000","0.00000000"],["77667.59000000","0.25313000"],["77665.30000000","0.00000000"],["77663.00000000","0.00200000"],["77659.72000000","0.00000000"],["77653.00000000","0.34783000"],["77634.82000000","0.00000000"],["76971.58000000","0.00019000"],["69913.80000000","0.00432000"]],"a":[["77682.00000000","0.16495000"],["77682.01000000","0.00070000"],["77684.21000000","0.00000000"],["77684.22000000","0.00014000"],["77685.05000000","0.00014000"],["77685.84000000","0.00014000"],["77685.99000000","0.00007000"],["77686.05000000","0.00000000"],["77686.36000000","0.00007000"],["77686.99000000","0.00000000"],["77692.48000000","0.00000000"],["77693.14000000","0.00000000"],["77693.38000000","0.30866000"],["77695.34000000","0.02000000"],["77695.73000000","0.00000000"],["77696.17000000","0.00000000"],["77697.12000000","0.00257000"],["77697.22000000","0.00000000"],["77698.12000000","0.00000000"],["77698.40000000","0.00200000"],["77698.43000000","0.00000000"],["77698.54000000","0.02000000"],["77698.86000000","0.00000000"],["77700.20000000","0.00000000"],["77701.18000000","0.02000000"],["77702.34000000","0.00000000"],["77703.52000000","0.00643000"],["77705.99000000","0.00000000"],["77707.48000000","0.00000000"],["77707.69000000","0.39078000"],["77708.53000000","0.00000000"],["77708.54000000","0.00000000"],["77711.17000000","0.90142000"],["77712.68000000","0.60432000"],["77715.29000000","0.00000000"],["77721.15000000","0.00400000"],["77724.96000000","0.00007000"],["77732.49000000","0.34748000"],["77735.12000000","0.00000000"]]}}
{"type":"depth","received_at_ms":1788407407009,"data":{"e":"depthUpdate","E":1788407407214,"s":"BTCUSDT","U":99603312514,"u":99603312575,"b":[["77681.99000000","8.86515000"],["77681.59000000","0.00000000"],["77680.01000000","0.00214000"],["77677.63000000","0.00000000"],["69913.80000000","0.00432000"],["62145.60000000","0.00000000"],["62145.59000000","0.00000000"]],"a":[["77682.00000000","0.16495000"],["77682.01000000","0.00063000"],["77682.27000000","0.00007000"],["77684.00000000","0.03028000"],["77684.22000000","0.00000000"],["77685.06000000","0.32214000"],["77685.84000000","0.00000000"],["77686.00000000","0.03021000"],["77686.33000000","0.10329000"],["77687.17000000","0.00014000"],["77688.00000000","0.03207000"],["77695.19000000","0.00400000"],["77697.12000000","0.00000000"],["77697.14000000","0.00257000"],["77697.25000000","0.00000000"],["77698.40000000","0.00000000"],["77700.84000000","0.01600000"],["77701.18000000","0.00400000"],["77701.33000000","0.00000000"],["77701.79000000","0.00400000"],["77717.25000000","0.00400000"],["77735.67000000","0.12878000"]]}}
{"type":"depth","received_at_ms":1788407407108,"data":{"e":"depthUpdate","E":1788407407314,"s":"BTCUSDT","U":99603312576,"u":99603312599,"b":[["77672.00000000","0.00007000"],["77670.58000000","0.12763000"],["77667.67000000","0.00000000"],["76748.41000000","0.00117000"],["69913.80000000","0.00432000"],["62146.00000000","0.00000000"]],"a":[["77686.33000000","0.10329000"],["77687.17000000","0.00000000"],["77687.47000000","0.00904000"],["77690.58000000","0.00208000"],["77697.13000000","0.00000000"],["77697.14000000","0.00000000"],["77698.76000000","0.00000000"],["77701.18000000","0.00600000"],["77734.93000000","0.00000000"],["77735.67000000","0.00000000"]]}}
{"type":"depth","received_at_ms":1788407407209,"data":{"e":"depthUpdate","E":1788407407414,"s":"BTCUSDT","U":99603312600,"u":99603312616,"b":[["77667.67000000","0.00007000"],["77667.58000000","0.00000000"],["69913.80000000","0.00432000"]],"a":[["77684.59000000","0.00007000"],["77697.25000000","0.01600000"],["77698.76000000","0.00007000"],["77700.84000000","0.00000000"],["77752.32000000","0.00000000"]]}}
{"type":"depth","received_at_ms":1788407407309,"data":{"e":"depthUpdate","E":1788407407514,"s":"BTCUSDT","U":99603312617,"u":99603312620,"b":[["69913.80000000","0.00448000"],["69913.79000000","0.00000000"],["62145.60000000","0.00032000"]],"a":[["77682.00000000","0.16236000"]]}}
{"type":"depth","received_at_ms":1788407407408,"data":{"e":"depthUpdate","E":1788407407614,"s":"BTCUSDT","U":99603312621,"u":99603312633,"b":[["76538.83000000","0.00457000"],["71467.43000000","0.00014000"],["69913.80000000","0.00432000"],["62145.60000000","0.00000000"]],"a":[["77682.00000000","0.15419000"],["77700.37000000","0.00400000"],["77701.79000000","0.00000000"]]}}
{"type":"depth","received_at_ms":1788407407510,"data":{"e":"depthUpdate","E":1788407407714,"s":"BTCUSDT","U":99603312634,"u":99603312647,"b":[["77681.99000000","8.86477000"],["77670.03000000","0.17564000"],["77658.49000000","0.08000000"],["77635.19000000","0.00000000"],["77527.30000000","0.00000000"],["76516.76000000","0.00030000"],["69913.80000000","0.00448000"]],"a":[["77682.00000000","0.15409000"],["77708.05000000","0.00000000"],["77728.19000000","0.00430000"],["77731.36000000","0.00007000"]]}}
{"type":"depth","received_at_ms":1788407407609,"data":{"e":"depthUpdate","E":1788407407814,"s":"BTCUSDT","U":99603312648,"u":99603312653,"b":[["77535.43000000","0.02016000"],["76297.05000000","0.00013000"],["69913.80000000","0.00432000"],["62146.00000000","0.00000000"]],"a":[["77688.62000000","0.14428000"]]}}
{"type":"depth","received_at_ms":1788407407708,"data":{"e":"depthUpdate","E":1788407407914,"s":"BTCUSDT","U":99603312654,"u":99603312661,"b":[["69913.80000000","0.00448000"]],"a":[["77682.00000000","0.15416000"],["77687.82000000","0.13008000"],["77688.62000000","0.00000000"],["78847.23000000","0.00030000"]]}}
{"type":"depth","received_at_ms":1788407407809,"data":{"e":"depthUpdate","E":1788407408014,"s":"BTCUSDT","U":99603312662,"u":99603312677,"b":[["77680.01000000","0.00214000"],["77677.63000000","0.00000000"],["77660.73000000","0.50363000"],["77637.43000000","0.98330000"],["77475.35000000","0.00812000"],["77474.76000000","0.00000000"],["69913.80000000","0.00432000"],["62145.60000000","0.00032000"]],"a":[["77691.93000000","0.00000000"],["77693.78000000","0.00400000"],["77695.19000000","0.00000000"],["77710.73000000","0.50835000"],["77734.04000000","0.99832000"]]}}
{"type":"depth","received_at_ms":1788407407909,"data":{"e":"depthUpdate","E":1788407408114,"s":"BTCUSDT","U":99603312678,"u":99603312698,"b":[["77680.01000000","0.00014000"],["77676.96000000","0.00200000"],["77663.00000000","0.00000000"],["77661.72000000","0.00200000"],["77602.78000000","0.41703000"],["77601.61000000","0.72109000"],["77599.06000000","0.00000000"],["76022.37000000","0.00013000"],["69913.80000000","0.00432000"],["62146.00000000","0.00200000"]],"a":[["77682.00000000","0.15416000"],["77686.94000000","0.14102000"],["77687.82000000","0.00013000"],["77698.61000000","0.00400000"],["77700.37000000","0.00000000"],["77701.17000000","0.00643000"],["77703.52000000","0.00000000"]]}}
{"type":"depth","received_at_ms":1788407408009,"data":{"e":"depthUpdate","E":1788407408214,"s":"BTCUSDT","U":99603312699,"u":99603312722,"b":[["77681.41000000","0.00400000"],["77681.40000000","0.00014000"],["71467.43000000","0.00000000"],["69913.80000000","0.00432000"],["62146.00000000","0.00000000"],["62145.60000000","0.00000000"],["62145.59000000","0.00000000"]],"a":[["77686.33000000","0.10329000"],["77686.94000000","0.14116000"],["77687.47000000","0.00890000"],["77697.24000000","0.00200000"],["77701.18000000","0.00400000"],["77728.89000000","0.70663000"],["78070.41000000","0.00007000"]]}}
{"type":"depth","received_at_ms":1788407408109,"data":{"e":"depthUpdate","E":1788407408314,"s":"BTCUSDT","U":99603312723,"u":99603312754,"b":[["77676.96000000","0.00000000"],["77676.22000000","0.00000000"],["77675.58000000","0.00200000"],["77661.72000000","0.00000000"],["77660.45000000","0.00200000"],["77648.00000000","0.03007000"],["75475.12000000","0.00013000"],["69913.80000000","0.00448000"],["62146.00000000","0.00000000"]],"a":[["77682.00000000","0.16946000"],["77682.01000000","0.00070000"],["77682.27000000","0.00000000"],["77683.63000000","0.10593000"],["77685.73000000","0.00000000"],["77686.94000000","0.00014000"],["77692.95000000","0.00522000"],["77708.54000000","0.25754000"],["77711.17000000","0.64387000"],["77733.83000000","0.00000000"],["77734.19000000","0.02000000"]]}}
{"type":"depth","received_at_ms":1788407408209,"data":{"e":"depthUpdate","E":1788407408414,"s":"BTCUSDT","U":99603312755,"u":99603312794,"b":[["77667.67000000","0.00007000"],["69913.80000000","0.00416000"],["62146.00000000","0.00000000"]],"a":[["77682.00000000","0.16953000"],["77682.01000000","0.00077000"],["77683.44000000","0.00014000"],["77683.45000000","0.10315000"],["77683.62000000","0.00007000"],["77683.63000000","0.10607000"],["77685.05000000","0.00000000"],["77685.99000000","0.00000000"],["77686.33000000","0.10329000"],["77686.94000000","0.00000000"],["77698.40000000","0.10315000"],["77698.76000000","0.00007000"],["77699.46000000","0.10315000"],["77708.53000000","0.64387000"],["77711.17000000","0.00000000"],["77732.91000000","0.00000000"],["77733.80000000","0.12878000"],["77734.19000000","0.02000000"]]}}
{"type":"depth","received_at_ms":1788407408309,"data":{"e":"depthUpdate","E":1788407408514,"s":"BTCUSDT","U":99603312795,"u":99603312823,"b":[["69913.80000000","0.00432000"],["62145.60000000","0.00032000"]],"a":[["77682.00000000","0.16960000"],["77683.45000000","0.10329000"],["77686.32000000","0.11990000"],["77686.33000000","0.10315000"],["77690.58000000","0.00000000"],["77692.95000000","0.00000000"],["77693.18000000","0.00533000"],["77696.48000000","0.00257000"],["77733.11000000","0.12878000"],["77733.33000000","0.00000000"],["77733.36000000","0.02000000"],["77733.44000000","0.00000000"],["77733.80000000","0.00000000"],["77733.81000000","0.00000000"]]}}
{"type":"depth","received_at_ms":1788407408410,"data":{"e":"depthUpdate","E":1788407408614,"s":"BTCUSDT","U":99603312824,"u":99603312845,"b":[["69913.80000000","0.00432000"],["62146.00000000","0.00000000"],["62145.60000000","0.00000000"]],"a":[["77684.59000000","0.00000000"],["77686.22000000","0.00548000"],["77691.93000000","0.00007000"],["77733.11000000","0.00000000"],["77733.51000000","0.00000000"],["77733.67000000","0.00000000"]]}}
{"type":"depth","received_at_ms":1788407408509,"data":{"e":"depthUpdate","E":1788407408714,"s":"BTCUSDT","U":99603312846,"u":99603312854,"b":[["76516.76000000","0.00030000"],["69913.80000000","0.00432000"]],"a":[["77682.00000000","0.16810000"],["77732.68000000","0.00000000"]]}}
{"type":"depth","received_at_ms":1788407408609,"data":{"e":"depthUpdate","E":1788407408815,"s":"BTCUSDT","U":99603312855,"u":99603312869,"b":[["77681.99000000","8.86459000"],["77677.63000000","0.00000000"],["77676.96000000","0.00200000"],["77675.58000000","0.00000000"],["69913.79000000","0.00009000"]],"a":[["77682.00000000","0.15776000"],["77682.01000000","0.00070000"],["77683.62000000","0.00000000"],["77683.63000000","0.00014000"],["77685.05000000","0.00007000"],["77686.32000000","0.00000000"]]}}
{"type":"depth","received_at_ms":1788407408709,"data":{"e":"depthUpdate","E":1788407408914,"s":"BTCUSDT","U":99603312870,"u":99603312893,"b":[["77681.99000000","8.86451000"],["77681.41000000","0.00000000"],["69913.80000000","0.00432000"]],"a":[["77682.00000000","0.15783000"],["77683.45000000","0.10329000"],["77683.63000000","0.00000000"],["77686.22000000","0.00548000"],["77686.32000000","0.11995000"],["77686.33000000","0.10329000"],["78847.23000000","0.00030000"]]}}
{"type":"depth","received_at_ms":1788407408809,"data":{"e":"depthUpdate","E":1788407409014,"s":"BTCUSDT","U":99603312894,"u":99603312907,"b":[["69913.80000000","0.00448000"],["62146.00000000","0.00000000"],["62145.60000000","0.00032000"]],"a":[["77686.22000000","0.00548000"],["77686.32000000","0.12009000"],["77686.33000000","0.10315000"]]}}
{"type":"depth","received_at_ms":1788407408909,"data":{"e":"depthUpdate","E":1788407409114,"s":"BTCUSDT","U":99603312908,"u":99603312916,"b":[["77681.99000000","8.86411000"],["77475.35000000","0.00000000"],["77474.76000000","0.00812000"],["69913.80000000","0.00432000"],["69913.79000000","0.00000000"],["69913.78000000","0.00009000"]],"a":[["77682.00000000","0.15776000"],["77684.59000000","0.00007000"],["77686.32000000","0.00014000"],["77733.83000000","0.00000000"]]}}
{"type":"depth","received_at_ms":1788407409008,"data":{"e":"depthUpdate","E":1788407409214,"s":"BTCUSDT","U":99603312917,"u":99603312932,"b":[["77513.35000000","0.00000000"],["69913.80000000","0.00448000"],["62145.60000000","0.00000000"],["62145.59000000","0.00000000"]],"a":[["77686.22000000","0.00548000"],["77686.32000000","0.00000000"],["77686.33000000","0.10329000"],["78070.41000000","0.00000000"]]}}
{"type":"depth","received_at_ms":1788407409110,"data":{"e":"depthUpdate","E":1788407409314,"s":"BTCUSDT","U":99603312933,"u":99603312943,"b":[["77516.44000000","0.00025000"],["76863.58000000","0.00000000"],["69913.80000000","0.00432000"],["62146.00000000","0.00000000"],["62145.59000000","0.00000000"]],"a":[["77683.82000000","0.00007000"],["77684.77000000","0.14953000"]]}}
{"type":"depth","received_at_ms":1788407409209,"data":{"e":"depthUpdate","E":1788407409414,"s":"BTCUSDT","U":99603312944,"u":99603312952,"b":[["77667.67000000","0.00007000"],["69913.80000000","0.00448000"],["62146.00000000","0.00000000"]],"a":[["77698.76000000","0.00007000"],["77718.67000000","0.09764000"]]}}
{"type":"depth","received_at_ms":1788407409309,"data":{"e":"depthUpdate","E":1788407409514,"s":"BTCUSDT","U":99603312953,"u":99603312958,"b":[["69913.80000000","0.00432000"],["62146.00000000","0.00000000"],["62145.60000000","0.00032000"]],"a":[]}}
{"type":"depth","received_at_ms":1788407409409,"data":{"e":"depthUpdate","E":1788407409614,"s":"BTCUSDT","U":99603312959,"u":99603312964,"b":[["69913.80000000","0.00448000"],["62145.60000000","0.00000000"]],"a":[["77684.59000000","0.00000000"],["77735.02000000","0.12878000"]]}}
{"type":"depth","received_at_ms":1788407409509,"data":{"e":"depthUpdate","E":1788407409714,"s":"BTCUSDT","U":99603312965,"u":99603312973,"b":[["76516.76000000","0.00030000"],["69913.80000000","0.00416000"]],"a":[["77682.00000000","0.15426000"],["77698.61000000","0.00000000"],["77699.46000000","0.00400000"],["77708.54000000","0.00000000"],["77709.79000000","0.25754000"]]}}
{"type":"depth","received_at_ms":1788407409609,"data":{"e":"depthUpdate","E":1788407409814,"s":"BTCUSDT","U":99603312974,"u":99603312984,"b":[["77681.99000000","8.81700000"],["69913.80000000","0.00448000"],["69913.78000000","0.00000000"]],"a":[["77684.77000000","0.03190000"],["77693.18000000","0.00000000"],["77697.24000000","0.00000000"],["77699.46000000","0.00000000"],["77699.99000000","0.00400000"],["77701.00000000","0.00200000"],["77707.49000000","0.00000000"],["77709.99000000","0.00013000"]]}}
{"type":"depth","received_at_ms":1788407409710,"data":{"e":"depthUpdate","E":1788407409914,"s":"BTCUSDT","U":99603312985,"u":99603312996,"b":[["69913.80000000","0.00432000"]],"a":[["77682.00000000","0.15386000"],["77682.27000000","0.00007000"],["77688.29000000","0.00208000"],["77688.60000000","0.12364000"],["77697.24000000","0.00200000"],["77701.00000000","0.00000000"],["78847.23000000","0.00030000"]]}}
{"type":"depth","received_at_ms":1788407409810,"data":{"e":"depthUpdate","E":1788407410014,"s":"BTCUSDT","U":99603312997,"u":99603313003,"b":[["77681.99000000","8.81708000"],["76927.80000000","0.00578000"],["69913.80000000","0.00416000"],["62145.60000000","0.00032000"]],"a":[["77682.00000000","0.15410000"]]}}
{"type":"depth","received_at_ms":1788407409909,"data":{"e":"depthUpdate","E":1788407410114,"s":"BTCUSDT","U":99603313004,"u":99603313004,"b":[["69913.80000000","0.00432000"]],"a":[]}}
{"type":"depth","received_at_ms":1788407410009,"data":{"e":"depthUpdate","E":1788407410214,"s":"BTCUSDT","U":99603313005,"u":99603313011,"b":[["69913.80000000","0.00432000"],["62145.60000000","0.00000000"],["62145.59000000","0.00000000"]],"a":[]}}
{"type":"depth","received_at_ms":1788407410109,"data":{"e":"depthUpdate","E":1788407410314,"s":"BTCUSDT","U":99603313012,"u":99603313025,"b":[["77663.87000000","0.00200000"],["77660.45000000","0.00000000"],["69913.80000000","0.00432000"],["62146.00000000","0.00000000"],["62145.59000000","0.00000000"]],"a":[["77686.33000000","0.23412000"],["77693.78000000","0.00000000"],["77693.85000000","0.00800000"],["77697.24000000","0.00000000"],["77700.84000000","0.00200000"],["77718.67000000","0.00008000"]]}}
{"type":"depth","received_at_ms":1788407410209,"data":{"e":"depthUpdate","E":1788407410414,"s":"BTCUSDT","U":99603313026,"u":99603313035,"b":[["77671.18000000","0.00000000"],["77667.67000000","0.00007000"],["77663.87000000","0.00000000"],["77662.26000000","0.00200000"],["69913.80000000","0.00432000"]],"a":[["77697.24000000","0.00200000"],["77698.76000000","0.00007000"],["77700.84000000","0.00000000"]]}}
{"type":"depth","received_at_ms":1788407410309,"data":{"e":"depthUpdate","E":1788407410514,"s":"BTCUSDT","U":99603313036,"u":99603313046,"b":[["69913.80000000","0.00457000"],["62145.60000000","0.00032000"]],"a":[["77682.00000000","0.15210000"],["77696.48000000","0.00000000"],["77697.23000000","0.00257000"],["77807.03000000","0.00000000"],["77832.73000000","0.00000000"]]}}
{"type":"depth","received_at_ms":1788407410408,"data":{"e":"depthUpdate","E":1788407410614,"s":"BTCUSDT","U":99603313047,"u":99603313054,"b":[["69913.80000000","0.00441000"],["62145.60000000","0.00000000"]],"a":[["77697.23000000","0.00000000"],["77853.54000000","0.00000000"],["77873.28000000","0.02016000"]]}}
{"type":"depth","received_at_ms":1788407410509,"data":{"e":"depthUpdate","E":1788407410714,"s":"BTCUSDT","U":99603313055,"u":99603313067,"b":[["77626.63000000","0.00672000"],["76516.76000000","0.00030000"],["69913.80000000","0.00457000"],["40885.30000000","0.00037000"]],"a":[["77682.00000000","0.15217000"],["77682.01000000","0.00077000"],["77684.84000000","0.00007000"],["77684.85000000","0.11376000"],["77685.05000000","0.00000000"],["77686.33000000","0.10329000"],["77697.24000000","0.00457000"],["77873.28000000","0.00000000"]]}}
{"type":"depth","received_at_ms":1788407410610,"data":{"e":"depthUpdate","E":1788407410815,"s":"BTCUSDT","U":99603313068,"u":99603313091,"b":[["69913.80000000","0.00441000"],["62146.00000000","0.00000000"]],"a":[["77682.00000000","0.15567000"],["77682.01000000","0.00077000"],["77684.04000000","0.00007000"],["77684.05000000","0.12391000"],["77684.77000000","0.03190000"],["77684.84000000","0.00000000"],["77684.85000000","0.00014000"],["77686.33000000","0.10315000"],["77697.24000000","0.00200000"],["77853.54000000","0.02016000"]]}}
{"type":"depth","received_at_ms":1788407410709,"data":{"e":"depthUpdate","E":1788407410914,"s":"BTCUSDT","U":99603313092,"u":99603313111,"b":[["77681.99000000","8.81700000"],["69913.80000000","0.00457000"]],"a":[["77684.00000000","0.03028000"],["77684.05000000","0.12405000"],["77684.77000000","0.03190000"],["77684.85000000","0.00000000"],["78847.23000000","0.00030000"]]}}
{"type":"depth","received_at_ms":1788407410809,"data":{"e":"depthUpdate","E":1788407411014,"s":"BTCUSDT","U":99603313112,"u":99603313117,"b":[["69913.80000000","0.00441000"],["62145.60000000","0.00032000"]],"a":[["77734.17000000","0.00000000"],["77734.59000000","0.12878000"],["77735.02000000","0.00000000"]]}}
{"type":"depth","received_at_ms":1788407410909,"data":{"e":"depthUpdate","E":1788407411114,"s":"BTCUSDT","U":99603313118,"u":99603313129,"b":[["69913.80000000","0.00457000"],["62146.00000000","0.00200000"]],"a":[["77682.27000000","0.00000000"],["77734.05000000","0.00000000"],["77734.24000000","0.02000000"],["77734.59000000","0.00000000"],["77734.62000000","0.00000000"]]}}
{"type":"depth","received_at_ms":1788407411010,"data":{"e":"depthUpdate","E":1788407411215,"s":"BTCUSDT","U":99603313130,"u":99603313148,"b":[["77681.99000000","8.82708000"],["77676.92000000","0.00021000"],["69913.80000000","0.00441000"],["62146.00000000","0.00000000"],["62145.60000000","0.00000000"],["62145.59000000","0.00000000"]],"a":[["77735.12000000","0.12878000"]]}}
{"type":"depth","received_at_ms":1788407411109,"data":{"e":"depthUpdate","E":1788407411314,"s":"BTCUSDT","U":99603313149,"u":99603313157,"b":[["69913.80000000","0.00457000"],["62146.00000000","0.00000000"],["62145.59000000","0.00000000"]],"a":[["77682.00000000","0.15217000"],["77734.54000000","0.00000000"],["77735.12000000","0.00000000"]]}}
{"type":"depth","received_at_ms":1788407411209,"data":{"e":"depthUpdate","E":1788407411415,"s":"BTCUSDT","U":99603313158,"u":99603313161,"b":[["69913.80000000","0.00441000"],["65146.32000000","0.00000000"]],"a":[]}}
{"type":"depth","received_at_ms":1788407411309,"data":{"e":"depthUpdate","E":1788407411514,"s":"BTCUSDT","U":99603313162,"u":99603313169,"b":[["77667.67000000","0.00007000"],["69913.80000000","0.00441000"],["62145.60000000","0.00032000"]],"a":[["77698.76000000","0.00007000"]]}}
{"type":"depth","received_at_ms":1788407411409,"data":{"e":"depthUpdate","E":1788407411614,"s":"BTCUSDT","U":99603313170,"u":99603313176,"b":[["69913.80000000","0.00425000"],["62146.00000000","0.00000000"],["62145.60000000","0.00000000"],["40885.30000000","0.00000000"]],"a":[]}}
{"type":"depth","received_at_ms":1788407411509,"data":{"e":"depthUpdate","E":1788407411715,"s":"BTCUSDT","U":99603313177,"u":99603313183,"b":[["69913.80000000","0.00432000"],["69913.79000000","0.00009000"],["65146.32000000","0.01188000"]],"a":[["77682.00000000","0.15181000"],["77682.27000000","0.00007000"]]}}
{"type":"depth","received_at_ms":1788407411609,"data":{"e":"depthUpdate","E":1788407411814,"s":"BTCUSDT","U":99603313184,"u":99603313188,"b":[["76516.76000000","0.00030000"],["69913.80000000","0.00432000"]],"a":[["77682.00000000","0.15149000"]]}}
{"type":"depth","received_at_ms":1788407411709,"data":{"e":"depthUpdate","E":1788407411914,"s":"BTCUSDT","U":99603313189,"u":99603313195,"b":[["75561.74000000","0.00000000"],["69913.80000000","0.00416000"]],"a":[["77697.09000000","0.00257000"],["78847.23000000","0.00030000"],["81006.07000000","0.00000000"]]}}
{"type":"depth","received_at_ms":1788407411810,"data":{"e":"depthUpdate","E":1788407412015,"s":"BTCUSDT","U":99603313196,"u":99603313206,"b":[["69913.80000000","0.00448000"],["62146.00000000","0.00000000"],["62145.60000000","0.00032000"]],"a":[["77697.08000000","0.00257000"],["77697.09000000","0.00000000"],["77734.14000000","0.00000000"],["77734.17000000","0.00000000"]]}}
{"type":"depth","received_at_ms":1788407411909,"data":{"e":"depthUpdate","E":1788407412114,"s":"BTCUSDT","U":99603313207,"u":99603313213,"b":[["69913.80000000","0.00432000"]],"a":[["77684.05000000","0.00014000"],["77697.07000000","0.00257000"],["77697.08000000","0.00000000"],["77735.29000000","0.12878000"]]}}
{"type":"depth","received_at_ms":1788407412009,"data":{"e":"depthUpdate","E":1788407412214,"s":"BTCUSDT","U":99603313214,"u":99603313231,"b":[["69913.80000000","0.00464000"],["62145.60000000","0.00000000"],["40885.30000000","0.00037000"]],"a":[["77684.00000000","0.03028000"],["77684.04000000","0.00000000"],["77684.05000000","0.00000000"],["77685.05000000","0.00007000"],["77686.33000000","0.10329000"],["77697.06000000","0.00257000"],["77697.07000000","0.00000000"]]}}
{"type":"depth","received_at_ms":1788407412109,"data":{"e":"depthUpdate","E":1788407412314,"s":"BTCUSDT","U":99603313232,"u":99603313247,"b":[["77681.99000000","8.79490000"],["77600.00000000","0.36468000"],["69913.80000000","0.00448000"],["69913.79000000","0.00000000"],["62146.00000000","0.00000000"],["62145.59000000","0.00000000"]],"a":[["77682.00000000","0.11943000"],["77682.01000000","0.00070000"],["77697.05000000","0.00257000"],["77697.06000000","0.00000000"],["79020.00000000","0.02790000"]]}}
{"type":"depth","received_at_ms":1788407412210,"data":{"e":"depthUpdate","E":1788407412414,"s":"BTCUSDT","U":99603313248,"u":99603313264,"b":[["77681.99000000","8.82708000"],["77680.01000000","0.00214000"],["77676.96000000","0.00000000"],["69913.80000000","0.00464000"]],"a":[["77682.00000000","0.10950000"],["77687.21000000","0.13823000"],["77693.85000000","0.00400000"],["77694.33000000","0.00400000"],["77697.04000000","0.00257000"],["77697.05000000","0.00000000"]]}}
{"type":"depth","received_at_ms":1788407412309,"data":{"e":"depthUpdate","E":1788407412514,"s":"BTCUSDT","U":99603313265,"u":99603313288,"b":[["77680.01000000","0.00014000"],["77667.67000000","0.00007000"],["69913.80000000","0.00448000"],["62145.60000000","0.00032000"]],"a":[["77686.28000000","0.11845000"],["77686.33000000","0.10329000"],["77687.21000000","0.00000000"],["77690.23000000","0.07000000"],["77691.93000000","0.00000000"],["77693.83000000","0.08000000"],["77697.03000000","0.00257000"],["77697.04000000","0.00000000"],["77697.24000000","0.00000000"],["77698.76000000","0.00007000"],["77699.99000000","0.00000000"],["77700.54000000","0.00400000"],["77701.18000000","0.00600000"],["77708.53000000","0.00000000"],["77709.78000000","0.64386000"]]}}
{"type":"depth","received_at_ms":1788407412408,"data":{"e":"depthUpdate","E":1788407412614,"s":"BTCUSDT","U":99603313289,"u":99603313311,"b":[["77680.01000000","0.00014000"],["77671.23000000","0.00298000"],["77606.89000000","0.56522000"],["77604.16000000","0.72109000"],["77602.78000000","0.00000000"],["77601.61000000","0.00000000"],["69913.80000000","0.00464000"],["62145.60000000","0.00000000"]],"a":[["77682.00000000","0.10950000"],["77686.22000000","0.00548000"],["77686.28000000","0.11859000"],["77686.33000000","0.10315000"],["77697.02000000","0.00257000"],["77697.03000000","0.00000000"]]}}
{"type":"depth","received_at_ms":1788407412509,"data":{"e":"depthUpdate","E":1788407412714,"s":"BTCUSDT","U":99603313312,"u":99603313323,"b":[["77680.01000000","0.00214000"],["77678.27000000","0.00000000"],["69913.80000000","0.00457000"],["62146.00000000","0.00000000"]],"a":[["77682.00000000","0.07711000"],["77697.01000000","0.00257000"],["77697.02000000","0.00000000"]]}}
{"type":"depth","received_at_ms":1788407412609,"data":{"e":"depthUpdate","E":1788407412814,"s":"BTCUSDT","U":99603313324,"u":99603313331,"b":[["76516.76000000","0.00030000"],["75561.74000000","0.00010000"],["69913.80000000","0.00473000"]],"a":[["77697.00000000","0.00257000"],["77697.01000000","0.00000000"]]}}
{"type":"depth","received_at_ms":1788407412709,"data":{"e":"depthUpdate","E":1788407412914,"s":"BTCUSDT","U":99603313332,"u":99603313348,"b":[["77681.99000000","8.82700000"],["77680.01000000","0.00014000"],["77678.27000000","0.00200000"],["69913.80000000","0.00457000"]],"a":[["77696.96000000","0.00257000"],["77697.00000000","0.00000000"],["77733.95000000","0.00000000"],["77733.96000000","0.00000000"],["77734.11000000","0.00000000"],["77734.60000000","0.00000000"],["77735.29000000","0.00000000"]]}}
{"type":"depth","received_at_ms":1788407412809,"data":{"e":"depthUpdate","E":1788407413014,"s":"BTCUSDT","U":99603313349,"u":99603313361,"b":[["69913.80000000","0.00457000"],["62145.60000000","0.00032000"],["40885.30000000","0.00000000"]],"a":[["77696.95000000","0.00257000"],["77696.96000000","0.00000000"],["77734.15000000","0.00000000"],["78847.23000000","0.00030000"],["81006.07000000","0.00010000"]]}}
{"type":"depth","received_at_ms":1788407412909,"data":{"e":"depthUpdate","E":1788407413114,"s":"BTCUSDT","U":99603313362,"u":99603313373,"b":[["77680.01000000","0.00214000"],["77678.27000000","0.00000000"],["77665.24000000","0.04592000"],["77659.07000000","0.00000000"],["77606.89000000","0.48173000"],["77604.16000000","0.00000000"],["77601.61000000","0.72109000"],["69913.80000000","0.00457000"]],"a":[["77696.95000000","0.00000000"],["77708.55000000","0.00000000"],["77708.80000000","0.04699000"]]}}
{"type":"depth","received_at_ms":1788407413008,"data":{"e":"depthUpdate","E":1788407413214,"s":"BTCUSDT","U":99603313374,"u":99603313378,"b":[["71467.44000000","0.00014000"],["69913.80000000","0.00441000"],["62145.60000000","0.00000000"]],"a":[]}}
{"type":"depth","received_at_ms":1788407413109,"data":{"e":"depthUpdate","E":1788407413314,"s":"BTCUSDT","U":99603313379,"u":99603313402,"b":[["77681.40000000","0.00014000"],["69913.80000000","0.00473000"],["62146.00000000","0.00000000"],["62145.59000000","0.00000000"]],"a":[["77694.33000000","0.00000000"],["77694.85000000","0.00400000"],["77697.25000000","0.00000000"],["77698.71000000","0.00000000"],["77700.34000000","0.00400000"],["77700.54000000","0.00000000"],["77701.00000000","0.01600000"]]}}
{"type":"depth","received_at_ms":1788407413211,"data":{"e":"depthUpdate","E":1788407413415,"s":"BTCUSDT","U":99603313403,"u":99603313418,"b":[["69913.80000000","0.00457000"]],"a":[["77682.00000000","0.07711000"],["77682.01000000","0.00077000"],["77685.38000000","0.12465000"],["77686.28000000","0.00014000"],["77697.25000000","0.01600000"],["77701.00000000","0.00000000"]]}}
{"type":"depth","received_at_ms":1788407413308,"data":{"e":"depthUpdate","E":1788407413514,"s":"BTCUSDT","U":99603313419,"u":99603313451,"b":[["77681.99000000","8.82672000"],["77680.01000000","0.00014000"],["77678.27000000","0.00200000"],["77667.67000000","0.00007000"],["69913.80000000","0.00448000"],["69913.79000000","0.00009000"],["62145.60000000","0.00032000"]],"a":[["77682.00000000","0.21052000"],["77682.01000000","0.00070000"],["77684.47000000","0.00007000"],["77684.48000000","0.11916000"],["77685.05000000","0.00000000"],["77685.06000000","0.32214000"],["77685.38000000","0.00014000"],["77686.22000000","0.00548000"],["77686.28000000","0.00000000"],["77698.76000000","0.00007000"],["77735.09000000","0.07711000"]]}}
{"type":"depth","received_at_ms":1788407413408,"data":{"e":"depthUpdate","E":1788407413614,"s":"BTCUSDT","U":99603313452,"u":99603313483,"b":[["69913.80000000","0.00448000"],["62145.60000000","0.00000000"]],"a":[["77682.00000000","0.22232000"],["77683.34000000","0.00007000"],["77683.35000000","0.14771000"],["77684.00000000","0.03028000"],["77684.47000000","0.00000000"],["77684.48000000","0.00014000"],["77685.06000000","0.32214000"],["77685.38000000","0.00000000"],["77691.93000000","0.00007000"],["77693.18000000","0.00534000"],["77697.24000000","0.00000000"],["77698.91000000","0.10887000"],["77700.34000000","0.00000000"],["77701.18000000","0.00400000"],["77735.09000000","0.00000000"],["78499.99000000","1.27356000"],["78888.00000000","0.93972000"]]}}
{"type":"depth","received_at_ms":1788407413508,"data":{"e":"depthUpdate","E":1788407413714,"s":"BTCUSDT","U":99603313484,"u":99603313505,"b":[["69913.80000000","0.00464000"]],"a":[["77682.00000000","0.21439000"],["77682.01000000","0.00077000"],["77683.35000000","0.14785000"],["77684.00000000","0.03028000"],["77684.48000000","0.00000000"],["77701.18000000","0.00600000"]]}}
{"type":"depth","received_at_ms":1788407413615,"data":{"e":"depthUpdate","E":1788407413814,"s":"BTCUSDT","U":99603313506,"u":99603313522,"b":[["76516.76000000","0.00030000"],["71467.44000000","0.00000000"],["69913.80000000","0.00448000"],["62146.00000000","0.00000000"]],"a":[["77682.00000000","0.21115000"],["77693.25000000","0.00400000"],["77694.85000000","0.00000000"],["77697.24000000","0.00000000"],["77701.18000000","0.00400000"],["77734.92000000","0.00000000"],["77735.56000000","0.12878000"]]}}
{"type":"depth","received_at_ms":1788407413708,"data":{"e":"depthUpdate","E":1788407413914,"s":"BTCUSDT","U":99603313523,"u":99603313533,"b":[["77670.03000000","0.00000000"],["69913.80000000","0.00464000"],["69913.79000000","0.00000000"],["40885.30000000","0.00037000"]],"a":[["77682.00000000","0.19935000"],["77682.27000000","0.00000000"],["77683.82000000","0.00000000"],["77693.25000000","0.00000000"],["77693.78000000","0.00400000"],["77697.24000000","0.00200000"]]}}
{"type":"depth","received_at_ms":1788407413808,"data":{"e":"depthUpdate","E":1788407414014,"s":"BTCUSDT","U":99603313534,"u":99603313541,"b":[["69913.80000000","0.00448000"],["62145.60000000","0.00032000"]],"a":[["77682.00000000","0.19735000"],["77735.56000000","0.00000000"],["78847.23000000","0.00030000"]]}}
{"type":"depth","received_at_ms":1788407413909,"data":{"e":"depthUpdate","E":1788407414114,"s":"BTCUSDT","U":99603313542,"u":99603313553,"b":[["77681.99000000","8.79454000"],["77655.71000000","0.00000000"],["69913.80000000","0.00464000"],["62146.00000000","0.00200000"]],"a":[["77682.00000000","0.19449000"]]}}
{"type":"depth","received_at_ms":1788407414009,"data":{"e":"depthUpdate","E":1788407414214,"s":"BTCUSDT","U":99603313554,"u":99603314021,"b":[["77683.34000000","8.74249000"],["77683.33000000","0.00014000"],["77683.16000000","0.00027000"],["77683.03000000","0.00000000"],["77682.76000000","0.00000000"],["77682.75000000","0.00000000"],["77682.50000000","0.00014000"],["77682.15000000","0.00400000"],["77682.00000000","3.37147000"],["77681.99000000","4.94290000"],["77681.98000000","0.00000000"],["77681.40000000","0.00000000"],["77680.75000000","0.00000000"],["77680.68000000","0.03275000"],["77680.01000000","0.00000000"],["77680.00000000","0.00014000"],["77679.83000000","0.00000000"],["77679.33000000","0.00000000"],["77678.37000000","0.00007000"],["77678.27000000","0.00000000"],["77677.81000000","0.12873000"],["77675.57000000","0.16877000"],["77673.66000000","0.09958000"],["77673.65000000","0.00000000"],["77672.00000000","0.23193000"],["77671.24000000","0.25754000"],["77670.91000000","0.19809000"],["77670.81000000","0.02400000"],["77670.58000000","0.00000000"],["77667.59000000","0.00000000"],["77665.91000000","0.00000000"],["77665.20000000","0.00200000"],["77662.26000000","0.00000000"],["77655.53000000","0.64412000"],["77650.95000000","0.00000000"],["77643.90000000","0.00000000"],["77638.36000000","4.63427000"],["77638.34000000","0.00000000"],["77627.85000000","0.00000000"],["77605.66000000","0.00008000"],["77597.20000000","0.00000000"],["77596.72000000","0.00000000"],["77578.13000000","0.00030000"],["77551.37000000","0.00000000"],["77527.97000000","0.00008000"],["77519.52000000","0.00000000"],["77498.35000000","0.00000000"],["77450.29000000","0.00008000"],["77441.85000000","0.00000000"],["77372.61000000","0.00008000"],["77364.17000000","0.00000000"],["77294.92000000","0.00008000"],["77286.50000000","0.00000000"],["77217.24000000","0.00008000"],["77208.82000000","0.00000000"],["77139.56000000","0.00008000"],["77131.15000000","0.00000000"],["77061.87000000","0.00008000"],["77053.47000000","0.00000000"],["76516.76000000","0.00000000"],["69913.80000000","0.00009000"],["62146.00000000","0.00000000"],["62145.60000000","0.00000000"]],"a":[["77682.00000000","0.00000000"],["77682.01000000","0.00000000"],["77682.50000000","0.00000000"],["77682.61000000","0.00000000"],["77682.76000000","0.00000000"],["77682.77000000","0.00000000"],["77683.04000000","0.00000000"],["77683.34000000","0.00000000"],["77683.35000000","0.01534000"],["77683.36000000","0.00084000"],["77683.44000000","0.00028000"],["77683.45000000","0.00014000"],["77684.77000000","0.00028000"],["77684.90000000","0.00014000"],["77685.05000000","0.00014000"],["77685.06000000","0.00021000"],["77686.12000000","0.03162000"],["77686.33000000","0.00000000"],["77688.02000000","0.00000000"],["77688.29000000","0.00000000"],["77688.60000000","0.00000000"],["77688.64000000","0.00000000"],["77689.50000000","0.00000000"],["77689.95000000","0.01068000"],["77690.07000000","0.00000000"],["77690.22000000","0.00007000"],["77690.23000000","0.00000000"],["77691.90000000","0.00000000"],["77693.18000000","0.00000000"],["77693.30000000","0.00000000"],["77693.38000000","0.00000000"],["77693.62000000","0.32190000"],["77693.78000000","0.00000000"],["77693.88000000","0.00000000"],["77694.08000000","0.00007000"],["77694.34000000","0.07000000"],["77694.95000000","0.09328000"],["77695.08000000","0.00321000"],["77695.21000000","0.00000000"],["77695.24000000","0.00400000"],["77695.42000000","0.00536000"],["77695.53000000","0.00000000"],["77696.76000000","0.00000000"],["77696.79000000","0.00000000"],["77697.24000000","0.00000000"],["77697.25000000","0.00000000"],["77697.35000000","0.00007000"],["77697.94000000","0.00014000"],["77698.13000000","0.00000000"],["77698.40000000","0.00000000"],["77698.41000000","0.00000000"],["77698.91000000","0.10487000"],["77699.87000000","0.00000000"],["77700.34000000","0.00400000"],["77701.17000000","0.00000000"],["77701.18000000","0.02200000"],["77701.20000000","0.00000000"],["77701.21000000","0.00000000"],["77701.80000000","0.00007000"],["77702.29000000","0.12869000"],["77702.82000000","0.00000000"],["77706.47000000","0.30866000"],["77706.49000000","1.15151000"],["77707.69000000","0.00000000"],["77708.80000000","0.00000000"],["77709.11000000","0.00000000"],["77709.77000000","0.30234000"],["77709.78000000","0.00000000"],["77709.79000000","0.00000000"],["77709.99000000","0.00000000"],["77710.73000000","0.00000000"],["77711.17000000","0.00000000"],["77711.88000000","0.00000000"],["77712.00000000","0.03007000"],["77712.67000000","0.64386000"],["77713.93000000","0.25754000"],["77714.65000000","0.00013000"],["77715.06000000","0.30866000"],["77719.05000000","0.00000000"],["77719.91000000","0.00000000"],["77720.00000000","0.03000000"],["77721.00000000","0.00000000"],["77721.10000000","0.00014000"],["77721.93000000","0.00000000"],["77723.76000000","0.64355000"],["77724.20000000","0.30866000"],["77725.05000000","0.00400000"],["77725.21000000","0.00000000"],["77726.22000000","0.00000000"],["77726.75000000","0.00847000"],["77727.00000000","0.00400000"],["77727.09000000","0.00000000"],["77728.82000000","0.00007000"],["77732.04000000","0.10000000"],["77732.10000000","0.04624000"],["77737.98000000","0.00000000"],["77752.55000000","0.00000000"],["77761.03000000","0.00008000"],["77763.33000000","0.00000000"],["77782.24000000","0.00000000"],["77784.87000000","0.00000000"],["77785.19000000","0.00000000"],["77787.74000000","2.60864000"],["77797.26000000","4.63427000"],["77830.23000000","0.00000000"],["77838.72000000","0.00008000"],["77895.29000000","0.00000000"],["77907.90000000","0.00018000"],["77916.40000000","0.00008000"],["77918.70000000","0.01287000"],["77985.58000000","0.00000000"],["77994.08000000","0.00008000"],["77997.28000000","7.69561000"],["78063.25000000","0.00000000"],["78071.77000000","0.00020000"],["78140.93000000","0.00000000"],["78149.45000000","0.00136000"],["78218.60000000","0.00000000"],["78227.13000000","0.00008000"],["78847.23000000","0.00000000"]]}}
{"type":"depth","received_at_ms":1788407414110,"data":{"e":"depthUpdate","E":1788407414314,"s":"BTCUSDT","U":99603314022,"u":99603314372,"b":[["77683.34000000","8.71876000"],["77683.17000000","0.00200000"],["77683.16000000","0.00000000"],["77682.12000000","0.00000000"],["77682.02000000","0.00014000"],["77682.01000000","0.01614000"],["77682.00000000","2.23927000"],["77681.99000000","4.91852000"],["77681.23000000","0.00000000"],["77680.74000000","0.00021000"],["77680.68000000","0.03289000"],["77680.21000000","0.01556000"],["77680.00000000","0.00000000"],["77679.99000000","0.22563000"],["77679.82000000","0.14054000"],["77679.50000000","0.00000000"],["77679.31000000","0.00014000"],["77679.30000000","1.14124000"],["77679.29000000","0.00000000"],["77678.39000000","0.00000000"],["77678.38000000","0.01335000"],["77678.26000000","0.00000000"],["77677.84000000","0.00546000"],["77677.62000000","0.00000000"],["77677.60000000","0.00008000"],["77676.92000000","0.00007000"],["77676.31000000","0.00000000"],["77676.21000000","0.00000000"],["77676.18000000","0.00000000"],["77675.68000000","0.00535000"],["77675.57000000","0.16884000"],["77674.90000000","0.30873000"],["77674.89000000","0.09041000"],["77674.10000000","0.11000000"],["77672.32000000","0.00000000"],["77672.00000000","0.23451000"],["77670.77000000","0.10702000"],["77668.83000000","0.10703000"],["77667.70000000","0.02200000"],["77666.48000000","0.30866000"],["77666.47000000","0.00000000"],["77665.47000000","0.00000000"],["77665.20000000","0.00000000"],["77663.51000000","0.00000000"],["77661.57000000","0.00008000"],["77658.49000000","0.00000000"],["77649.65000000","0.85333000"],["77647.96000000","0.02491000"],["77644.00000000","0.04000000"],["77643.00000000","0.00000000"],["77642.30000000","0.00000000"],["77638.37000000","2.74113000"],["77638.35000000","0.00000000"],["77637.41000000","0.00000000"],["77633.20000000","0.00425000"],["77629.18000000","0.60081000"],["77623.24000000","0.85362000"],["77621.20000000","0.00000000"],["77618.01000000","0.00321000"],["77616.01000000","0.00000000"],["77612.73000000","0.00321000"],["77611.24000000","0.00000000"],["77609.29000000","0.00000000"],["77608.11000000","0.00319000"],["77607.88000000","0.00000000"],["77607.29000000","0.00000000"],["77592.42000000","0.00000000"],["77592.41000000","0.00000000"],["77579.55000000","0.20008000"],["77555.47000000","0.02016000"],["77540.01000000","0.00128000"],["77538.01000000","0.00000000"],["77534.96000000","0.00128000"],["77532.96000000","0.00000000"],["77530.01000000","0.00128000"],["77529.46000000","0.00000000"],["69915.01000000","0.00032000"],["62146.67000000","0.00000000"],["62146.00000000","0.00000000"]],"a":[["77683.35000000","0.01492000"],["77683.36000000","0.00063000"],["77683.44000000","0.00014000"],["77683.45000000","0.00000000"],["77684.00000000","0.03021000"],["77684.76000000","0.00000000"],["77684.77000000","0.00000000"],["77684.89000000","0.00000000"],["77684.90000000","0.00000000"],["77685.05000000","0.00000000"],["77685.06000000","0.00007000"],["77685.99000000","0.00014000"],["77686.00000000","0.03035000"],["77686.11000000","0.00000000"],["77686.12000000","0.00014000"],["77686.22000000","0.00021000"],["77686.24000000","0.00014000"],["77686.25000000","0.10315000"],["77687.47000000","0.00021000"],["77687.69000000","0.00014000"],["77687.70000000","0.10315000"],["77687.76000000","0.00014000"],["77687.77000000","0.02917000"],["77687.79000000","0.00000000"],["77687.80000000","0.10337000"],["77688.00000000","0.03228000"],["77688.01000000","0.01191000"],["77688.71000000","0.00000000"],["77689.72000000","0.00000000"],["77689.95000000","0.00000000"],["77690.09000000","0.03162000"],["77690.43000000","0.00000000"],["77692.76000000","0.00000000"],["77693.57000000","0.00000000"],["77693.61000000","0.00000000"],["77693.69000000","0.00208000"],["77693.98000000","0.00000000"],["77694.00000000","0.15364000"],["77694.08000000","0.00014000"],["77694.31000000","0.00000000"],["77694.36000000","0.00000000"],["77694.46000000","0.00000000"],["77695.24000000","0.00000000"],["77695.42000000","0.00000000"],["77695.77000000","0.00000000"],["77695.83000000","0.00673000"],["77696.62000000","0.00400000"],["77697.27000000","0.37291000"],["77697.94000000","0.00021000"],["77698.91000000","0.00000000"],["77699.30000000","0.10315000"],["77699.46000000","0.10315000"],["77700.34000000","0.00000000"],["77700.85000000","0.00000000"],["77701.14000000","0.09243000"],["77701.18000000","0.02000000"],["77701.19000000","0.45804000"],["77701.52000000","0.00400000"],["77701.80000000","0.00014000"],["77702.28000000","0.10315000"],["77702.65000000","0.00000000"],["77702.93000000","0.00000000"],["77703.52000000","0.00643000"],["77704.44000000","0.00000000"],["77705.10000000","0.09345000"],["77705.66000000","0.00014000"],["77706.23000000","0.10315000"],["77706.24000000","0.10697000"],["77706.45000000","1.98477000"],["77706.46000000","4.63427000"],["77706.48000000","0.00000000"],["77707.59000000","0.18155000"],["77708.18000000","0.10697000"],["77711.89000000","0.00000000"],["77712.67000000","0.00000000"],["77715.68000000","0.64386000"],["77717.48000000","0.00202000"],["77718.26000000","0.00060000"],["77719.86000000","0.00191000"],["77720.00000000","0.03258000"],["77720.78000000","1.25691000"],["77721.95000000","0.00000000"],["77722.98000000","0.00000000"],["77723.00000000","0.01000000"],["77725.59000000","0.00000000"],["77726.75000000","0.00000000"],["77727.84000000","0.00000000"],["77728.41000000","0.00000000"],["77728.58000000","0.00000000"],["77729.03000000","0.00845000"],["77732.51000000","0.32960000"],["77732.68000000","0.00000000"],["77734.12000000","0.00615000"],["77738.60000000","0.00000000"],["77739.80000000","0.00321000"],["77739.81000000","0.00000000"],["77740.50000000","0.00000000"],["77741.28000000","0.00320000"],["77741.72000000","0.00000000"],["77742.93000000","0.03863000"],["77744.38000000","0.25026000"],["77746.21000000","0.00000000"],["77755.85000000","0.00537000"],["77757.16000000","0.01720000"],["77763.32000000","1.88015000"],["77782.57000000","0.03463000"],["77787.73000000","2.23148000"],["77787.92000000","0.00000000"],["77816.62000000","0.00000000"],["77817.83000000","0.00128000"],["77817.84000000","0.00000000"],["77818.55000000","0.00128000"],["77873.42000000","0.00000000"],["77890.22000000","0.00000000"],["77900.32000000","0.02016000"],["77920.47000000","0.11451000"]]}}
{"type":"depth","received_at_ms":1788407414209,"data":{"e":"depthUpdate","E":1788407414414,"s":"BTCUSDT","U":99603314373,"u":99603314460,"b":[["77683.34000000","8.83138000"],["77683.33000000","0.01024000"],["77683.17000000","0.00000000"],["77682.09000000","0.01684000"],["77682.02000000","0.00214000"],["77682.01000000","0.01628000"],["77681.39000000","0.00014000"],["77680.85000000","0.02021000"],["77680.74000000","0.00007000"],["77680.21000000","0.01570000"],["77679.82000000","0.14040000"],["77679.61000000","0.02021000"],["77655.79000000","0.00000000"],["77623.25000000","0.80116000"],["77623.19000000","0.00000000"],["77612.11000000","3.24692000"],["77592.33000000","0.33316000"],["77591.48000000","0.03992000"],["77585.44000000","0.00000000"],["76982.85000000","0.00000000"],["69915.01000000","0.00048000"],["62147.00000000","0.00032000"],["62146.67000000","0.00000000"]],"a":[["77683.35000000","0.01520000"],["77683.36000000","0.00077000"],["77686.00000000","0.03035000"],["77686.12000000","0.00000000"],["77686.22000000","0.00007000"],["77686.25000000","0.10329000"],["77687.47000000","0.00007000"],["77687.58000000","0.00534000"],["77687.70000000","0.10329000"],["77688.01000000","0.01205000"],["77688.44000000","0.10814000"],["77688.82000000","0.00889000"],["77690.06000000","0.01068000"],["77690.10000000","0.00000000"],["77690.54000000","0.00000000"],["77691.30000000","0.01068000"],["77697.02000000","0.00523000"],["77698.68000000","0.00069000"],["77699.06000000","0.00048000"],["77701.18000000","0.00400000"],["77702.27000000","0.01600000"],["77703.92000000","0.02000000"],["77719.37000000","0.50823000"],["77756.14000000","0.02000000"],["77765.96000000","3.24050000"],["77775.56000000","0.00000000"],["77801.05000000","0.04601000"],["77818.56000000","0.00000000"],["77824.61000000","0.00971000"]]}}
{"type":"depth","received_at_ms":1788407414309,"data":{"e":"depthUpdate","E":1788407414514,"s":"BTCUSDT","U":99603314461,"u":99603314520,"b":[["77683.34000000","8.83145000"],["77683.33000000","0.01045000"],["77682.09000000","0.01698000"],["77682.02000000","0.00214000"],["77681.99000000","4.91845000"],["77681.39000000","0.00000000"],["77679.99000000","0.22549000"],["77668.05000000","0.00012000"],["77667.70000000","0.02000000"],["77667.67000000","0.00000000"],["77665.41000000","0.00200000"],["77547.88000000","0.00000000"],["77535.43000000","0.00000000"],["77486.39000000","0.00812000"],["77474.76000000","0.00000000"],["77456.88000000","0.02016000"],["69915.01000000","0.00064000"],["62146.68000000","0.00032000"]],"a":[["77683.35000000","0.00890000"],["77683.36000000","0.00091000"],["77683.44000000","0.00000000"],["77683.82000000","0.00007000"],["77686.25000000","0.10329000"],["77687.58000000","0.00548000"],["77688.01000000","0.01191000"],["77698.76000000","0.00000000"],["77700.89000000","0.02000000"],["77703.21000000","0.02010000"],["77703.87000000","0.02000000"],["77704.72000000","0.00000000"],["77711.18000000","1.79535000"],["77715.68000000","0.00000000"],["77752.42000000","0.02000000"],["77756.14000000","0.00000000"],["77774.04000000","0.02000000"],["77775.59000000","0.02000000"],["77824.51000000","0.01324000"]]}}
{"type":"depth","received_at_ms":1788407414409,"data":{"e":"depthUpdate","E":1788407414614,"s":"BTCUSDT","U":99603314521,"u":99603315219,"b":[["77685.99000000","14.06877000"],["77685.98000000","0.00014000"],["77685.71000000","0.00000000"],["77685.37000000","0.00000000"],["77685.09000000","0.00014000"],["77685.06000000","1.06097000"],["77685.05000000","4.63441000"],["77684.10000000","0.00400000"],["77684.00000000","0.00000000"],["77683.99000000","0.61500000"],["77683.98000000","0.00000000"],["77683.92000000","0.00000000"],["77683.85000000","0.12051000"],["77683.81000000","0.00000000"],["77683.43000000","0.00000000"],["77683.35000000","1.18723000"],["77683.34000000","0.60927000"],["77683.33000000","0.03296000"],["77682.09000000","0.00014000"],["77682.07000000","0.00027000"],["77682.02000000","0.00000000"],["77682.01000000","0.32487000"],["77682.00000000","0.20439000"],["77681.99000000","0.12815000"],["77681.16000000","0.00007000"],["77681.06000000","0.00000000"],["77680.85000000","0.00000000"],["77680.74000000","0.00000000"],["77680.68000000","0.00000000"],["77680.21000000","0.01556000"],["77680.17000000","0.00013000"],["77680.00000000","0.00007000"],["77679.99000000","0.22556000"],["77679.83000000","0.43399000"],["77679.82000000","0.14040000"],["77679.61000000","0.00000000"],["77679.31000000","0.00000000"],["77678.42000000","0.00000000"],["77678.22000000","0.00008000"],["77676.93000000","0.03860000"],["77676.29000000","0.00007000"],["77676.17000000","0.00000000"],["77676.06000000","0.00008000"],["77675.58000000","0.08648000"],["77675.57000000","0.16877000"],["77674.90000000","0.00000000"],["77674.89000000","0.00400000"],["77674.87000000","0.06596000"],["77674.22000000","0.00000000"],["77672.32000000","0.30866000"],["77671.67000000","0.00007000"],["77670.45000000","0.00408000"],["77669.86000000","0.04988000"],["77668.96000000","0.00200000"],["77668.31000000","0.00000000"],["77666.57000000","0.00008000"],["77666.48000000","0.00000000"],["77666.25000000","0.00000000"],["77665.75000000","0.64403000"],["77665.41000000","0.00000000"],["77664.28000000","0.00000000"],["77664.11000000","0.12875000"],["77664.00000000","0.00007000"],["77662.68000000","0.00008000"],["77661.27000000","0.00257000"],["77660.40000000","0.00000000"],["77660.18000000","0.00000000"],["77659.05000000","0.30866000"],["77658.80000000","0.00015000"],["77657.62000000","0.47656000"],["77657.41000000","0.00000000"],["77656.65000000","0.00000000"],["77656.52000000","0.00010000"],["77656.31000000","0.00000000"],["77656.00000000","0.03007000"],["77654.92000000","0.00008000"],["77653.86000000","1.54288000"],["77652.90000000","0.00000000"],["77652.63000000","0.00000000"],["77651.45000000","0.56612000"],["77651.03000000","0.00008000"],["77648.75000000","0.00000000"],["77647.15000000","0.00008000"],["77646.00000000","0.04000000"],["77644.86000000","0.00000000"],["77644.00000000","0.03000000"],["77640.98000000","0.00000000"],["77638.38000000","4.63427000"],["77638.37000000","0.00000000"],["77638.36000000","0.00000000"],["77635.89000000","0.00000000"],["77634.03000000","0.25000000"],["77630.03000000","0.00000000"],["77619.05000000","0.00000000"],["77617.57000000","0.00000000"],["77597.32000000","0.00000000"],["77513.74000000","0.03480000"],["77484.14000000","0.00000000"],["77464.80000000","0.00000000"],["77297.22000000","0.00000000"],["69917.40000000","0.00016000"],["69915.01000000","0.00000000"],["69913.80000000","0.00000000"],["69913.79000000","0.00009000"],["62149.00000000","0.00083000"],["62146.68000000","0.00000000"]],"a":[["77683.35000000","0.00000000"],["77683.36000000","0.00000000"],["77683.82000000","0.00000000"],["77683.86000000","0.00000000"],["77683.99000000","0.00000000"],["77684.00000000","0.00000000"],["77685.06000000","0.00000000"],["77685.10000000","0.00000000"],["77685.72000000","0.00000000"],["77685.99000000","0.00000000"],["77686.00000000","0.03867000"],["77686.01000000","0.00070000"],["77686.24000000","0.00000000"],["77686.25000000","0.00014000"],["77686.75000000","0.00000000"],["77687.58000000","0.00014000"],["77687.69000000","0.00000000"],["77687.70000000","0.00014000"],["77687.79000000","0.00000000"],["77687.80000000","0.00021000"],["77687.82000000","0.00000000"],["77687.99000000","0.00014000"],["77688.00000000","0.03221000"],["77688.01000000","0.01205000"],["77688.44000000","0.00014000"],["77688.82000000","0.00000000"],["77689.07000000","0.00000000"],["77689.23000000","0.00007000"],["77689.54000000","0.00000000"],["77689.77000000","0.00000000"],["77689.80000000","0.00027000"],["77689.99000000","0.00014000"],["77690.00000000","0.03007000"],["77690.06000000","0.00000000"],["77690.08000000","0.00014000"],["77690.09000000","0.03169000"],["77690.37000000","0.00007000"],["77690.38000000","0.09631000"],["77690.50000000","0.00000000"],["77691.29000000","0.00000000"],["77691.30000000","0.00000000"],["77691.52000000","0.00000000"],["77691.82000000","0.00013000"],["77691.83000000","0.00007000"],["77691.84000000","0.10386000"],["77691.99000000","0.00000000"],["77692.27000000","0.00000000"],["77692.83000000","0.00008000"],["77692.94000000","0.00000000"],["77693.30000000","0.10386000"],["77693.35000000","0.00000000"],["77693.61000000","0.00000000"],["77693.69000000","0.00000000"],["77693.83000000","0.00000000"],["77693.85000000","0.00000000"],["77694.00000000","0.03000000"],["77694.08000000","0.00014000"],["77694.34000000","0.00000000"],["77694.76000000","0.10386000"],["77694.95000000","0.00000000"],["77695.05000000","0.00000000"],["77695.24000000","0.02000000"],["77695.37000000","0.00000000"],["77695.83000000","0.00000000"],["77696.22000000","0.10386000"],["77696.62000000","0.00000000"],["77696.96000000","0.12870000"],["77697.02000000","0.00000000"],["77697.27000000","0.21005000"],["77697.53000000","0.00000000"],["77697.94000000","0.00021000"],["77698.36000000","0.00400000"],["77698.54000000","0.00000000"],["77699.10000000","0.00000000"],["77699.14000000","0.09541000"],["77699.25000000","0.00000000"],["77699.47000000","0.00000000"],["77699.92000000","0.00048000"],["77700.24000000","0.13000000"],["77700.60000000","0.00008000"],["77700.78000000","0.00000000"],["77700.88000000","0.00532000"],["77701.24000000","0.02000000"],["77701.52000000","0.00000000"],["77702.27000000","0.00000000"],["77702.28000000","0.10386000"],["77702.35000000","0.00000000"],["77702.76000000","0.00007000"],["77703.13000000","0.00000000"],["77703.52000000","0.00000000"],["77703.99000000","0.01600000"],["77704.07000000","0.00000000"],["77704.48000000","0.00008000"],["77704.67000000","0.00526000"],["77704.81000000","0.02000000"],["77704.98000000","0.10323000"],["77705.10000000","0.00000000"],["77706.22000000","0.00000000"],["77706.23000000","0.10386000"],["77706.45000000","0.53575000"],["77706.46000000","0.00000000"],["77707.01000000","0.00643000"],["77707.02000000","0.00000000"],["77707.70000000","0.00000000"],["77707.87000000","0.00000000"],["77708.37000000","0.00008000"],["77708.56000000","0.00534000"],["77709.00000000","0.00000000"],["77710.90000000","0.00000000"],["77711.18000000","1.15151000"],["77711.84000000","0.55246000"],["77711.89000000","0.12868000"],["77712.25000000","0.00008000"],["77712.45000000","0.00524000"],["77713.36000000","0.00128000"],["77713.92000000","0.64384000"],["77714.11000000","0.00000000"],["77714.79000000","0.02000000"],["77716.13000000","0.00008000"],["77716.34000000","0.00523000"],["77718.31000000","0.00000000"],["77718.67000000","0.00000000"],["77720.02000000","0.00008000"],["77721.18000000","0.00012000"],["77723.00000000","0.00000000"],["77723.90000000","0.00008000"],["77724.00000000","0.03000000"],["77724.77000000","0.00000000"],["77725.00000000","0.01000000"],["77727.02000000","0.00000000"],["77728.19000000","0.00000000"],["77728.95000000","0.00400000"],["77729.03000000","0.00000000"],["77729.58000000","0.00000000"],["77729.98000000","0.00000000"],["77730.03000000","0.00000000"],["77731.31000000","0.00824000"],["77732.68000000","0.00000000"],["77736.09000000","0.00425000"],["77737.03000000","0.00000000"],["77737.19000000","0.00426000"],["77738.89000000","0.34745000"],["77739.80000000","0.00000000"],["77741.03000000","0.25000000"],["77741.28000000","0.00000000"],["77742.27000000","0.00321000"],["77743.54000000","0.00321000"],["77745.02000000","0.00000000"],["77756.17000000","0.02000000"],["77756.28000000","1.27371000"],["77758.57000000","0.00110000"],["77787.73000000","0.00000000"],["77787.74000000","0.00000000"],["77806.59000000","4.63403000"],["77820.96000000","0.00008000"],["77920.00000000","0.53280000"]]}}
{"type":"depth","received_at_ms":1788407414508,"data":{"e":"depthUpdate","E":1788407414714,"s":"BTCUSDT","U":99603315220,"u":99603315336,"b":[["77685.99000000","14.02138000"],["77685.09000000","0.00000000"],["77685.07000000","0.01800000"],["77685.06000000","1.06111000"],["77684.74000000","0.01684000"],["77683.99000000","0.61500000"],["77683.85000000","0.12065000"],["77683.50000000","0.02021000"],["77683.35000000","1.18737000"],["77683.34000000","0.59927000"],["77683.33000000","0.03289000"],["77682.26000000","0.02021000"],["77682.09000000","0.00000000"],["77682.01000000","0.30887000"],["77682.00000000","0.20425000"],["77657.17000000","0.00000000"],["77647.00000000","0.01000000"],["77646.00000000","0.03000000"],["77612.72000000","0.00000000"],["77564.01000000","0.00000000"],["77561.57000000","0.00000000"],["69917.40000000","0.00048000"]],"a":[["77686.00000000","0.03874000"],["77686.01000000","0.00077000"],["77686.25000000","0.00000000"],["77687.58000000","0.00000000"],["77687.70000000","0.00000000"],["77687.77000000","0.02917000"],["77687.80000000","0.00007000"],["77688.01000000","0.01205000"],["77688.44000000","0.00000000"],["77690.00000000","0.03021000"],["77690.09000000","0.03190000"],["77690.22000000","0.00541000"],["77690.38000000","0.09652000"],["77690.94000000","0.00000000"],["77691.47000000","0.00889000"],["77691.80000000","0.00657000"],["77691.84000000","0.10407000"],["77691.93000000","0.00000000"],["77692.71000000","0.01068000"],["77693.61000000","0.31864000"],["77693.95000000","0.01068000"],["77699.43000000","0.00047000"],["77701.19000000","0.17483000"],["77704.38000000","0.00400000"],["77706.22000000","0.00200000"],["77706.46000000","0.10386000"],["77709.09000000","0.10386000"],["77711.40000000","0.00400000"],["77714.35000000","0.00000000"],["77727.20000000","0.00000000"],["77736.07000000","0.00425000"],["77752.43000000","0.00000000"],["77774.04000000","0.00000000"],["77775.59000000","0.00000000"],["77776.94000000","0.06626000"]]}}
{"type":"depth","received_at_ms":1788407414610,"data":{"e":"depthUpdate","E":1788407414814,"s":"BTCUSDT","U":99603315337,"u":99603315404,"b":[["77685.99000000","14.12558000"],["77685.08000000","0.00014000"],["77685.07000000","0.01835000"],["77685.06000000","1.06125000"],["77685.05000000","4.63441000"],["77684.74000000","0.01698000"],["77684.00000000","0.00014000"],["77683.85000000","0.12065000"],["77683.34000000","0.49051000"],["77683.33000000","0.03275000"],["77682.01000000","0.30873000"],["77675.68000000","0.00528000"],["77670.91000000","0.00000000"],["77637.17000000","0.01158000"],["77586.01000000","0.04533000"],["76520.70000000","0.00030000"],["69917.40000000","0.00064000"],["40885.30000000","0.00000000"]],"a":[["77686.00000000","0.03881000"],["77686.01000000","0.00084000"],["77688.91000000","0.00014000"],["77688.92000000","0.10386000"],["77690.09000000","0.03190000"],["77690.22000000","0.00555000"],["77690.37000000","0.00000000"],["77690.38000000","0.09652000"],["77691.47000000","0.00903000"],["77691.80000000","0.00643000"],["77691.83000000","0.00000000"],["77691.84000000","0.10393000"],["77692.96000000","0.11439000"],["77693.61000000","0.00000000"],["77700.15000000","0.02200000"],["77758.04000000","0.02200000"]]}}
{"type":"depth","received_at_ms":1788407414708,"data":{"e":"depthUpdate","E":1788407414914,"s":"BTCUSDT","U":99603315405,"u":99603315426,"b":[["77685.99000000","14.12565000"],["77685.06000000","2.18929000"],["77662.00000000","0.00500000"],["77492.26000000","0.00812000"],["77486.39000000","0.00000000"],["69917.40000000","0.00080000"]],"a":[["77688.01000000","0.01205000"],["77688.92000000","0.10400000"],["77691.47000000","0.00889000"],["77704.03000000","0.02000000"],["77738.38000000","0.00000000"],["77738.61000000","0.02200000"],["77738.71000000","0.03881000"],["77761.93000000","0.02000000"]]}}
{"type":"depth","received_at_ms":1788407414809,"data":{"e":"depthUpdate","E":1788407415014,"s":"BTCUSDT","U":99603315427,"u":99603315441,"b":[["77684.60000000","0.00007000"],["77670.78000000","0.44163000"],["77660.41000000","0.00000000"],["77637.43000000","0.00000000"],["77276.58000000","0.00007000"],["69917.40000000","0.00112000"],["62149.00000000","0.00083000"],["62148.80000000","0.00032000"]],"a":[["77738.71000000","0.00000000"],["77739.01000000","0.00000000"],["77758.04000000","0.00000000"],["77761.93000000","0.00000000"],["78851.29000000","0.00094000"]]}}
{"type":"depth","received_at_ms":1788407414908,"data":{"e":"depthUpdate","E":1788407415114,"s":"BTCUSDT","U":99603315442,"u":99603315462,"b":[["77685.99000000","14.12551000"],["77683.85000000","0.12072000"],["77683.50000000","0.02035000"],["77676.23000000","0.12732000"],["77675.72000000","0.00000000"],["77553.54000000","0.00012000"],["77549.55000000","0.00000000"],["69913.79000000","0.00000000"]],"a":[["77686.00000000","0.03842000"],["77704.01000000","0.02400000"],["77739.07000000","0.00000000"],["77739.93000000","0.03881000"],["77774.77000000","0.02400000"],["77778.32000000","0.00000000"],["77782.32000000","0.00033000"],["77791.31000000","0.00000000"],["77795.43000000","0.00000000"],["77799.48000000","0.00000000"]]}}
{"type":"depth","received_at_ms":1788407415008,"data":{"e":"depthUpdate","E":1788407415214,"s":"BTCUSDT","U":99603315463,"u":99603315478,"b":[["77683.33000000","0.03282000"],["77676.93000000","0.03853000"],["77676.92000000","0.00000000"],["77675.84000000","0.00000000"],["77492.26000000","0.00000000"],["77489.01000000","0.00812000"],["69917.40000000","0.00144000"],["62148.80000000","0.00000000"]],"a":[["77688.01000000","0.01212000"],["77690.09000000","0.03197000"],["77697.73000000","0.00000000"],["77703.52000000","0.00007000"],["77739.93000000","0.00000000"],["77795.32000000","0.00012000"],["77799.44000000","0.00019000"],["77803.49000000","0.00032000"]]}}
{"type":"depth","received_at_ms":1788407415109,"data":{"e":"depthUpdate","E":1788407415314,"s":"BTCUSDT","U":99603315479,"u":99603315493,"b":[["77662.00000000","0.70500000"],["69917.40000000","0.00144000"],["62149.00000000","0.00083000"],["62148.79000000","0.00000000"]],"a":[["77686.00000000","0.03806000"],["77692.96000000","0.00000000"],["77704.42000000","0.02600000"],["77740.03000000","0.00000000"],["77773.44000000","0.00007000"],["77774.77000000","0.00000000"],["77775.27000000","0.02600000"]]}}
{"type":"depth","received_at_ms":1788407415209,"data":{"e":"depthUpdate","E":1788407415414,"s":"BTCUSDT","U":99603315494,"u":99603315521,"b":[["77676.23000000","0.00000000"],["77670.48000000","0.52584000"],["77638.39000000","2.04245000"],["77615.14000000","1.77440000"],["77564.01000000","0.02279000"],["77557.70000000","0.00000000"],["77528.61000000","0.00671000"],["77513.10000000","0.00000000"],["76986.82000000","0.00010000"],["69917.40000000","0.00144000"],["62149.00000000","0.00083000"],["62148.79000000","0.00000000"],["40885.30000000","0.00037000"]],"a":[["77702.88000000","0.00257000"],["77712.68000000","0.87829000"],["77730.00000000","0.73000000"],["77744.10000000","0.50469000"],["77744.38000000","0.00000000"],["77756.14000000","0.02000000"],["77775.27000000","0.00000000"],["77787.92000000","1.45280000"]]}}
{"type":"depth","received_at_ms":1788407415309,"data":{"e":"depthUpdate","E":1788407415514,"s":"BTCUSDT","U":99603315522,"u":99603315547,"b":[["77664.07000000","0.34778000"],["77654.35000000","1.27538000"],["77644.77000000","0.00000000"],["77635.14000000","0.00000000"],["69917.40000000","0.00160000"],["62148.80000000","0.00032000"]],"a":[["77686.00000000","0.03816000"],["77695.54000000","0.00000000"],["77695.57000000","0.00000000"],["77698.36000000","0.00000000"],["77698.84000000","0.00400000"],["77701.24000000","0.00000000"],["77702.88000000","0.00000000"],["77702.91000000","0.00257000"],["77703.99000000","0.00400000"],["77704.97000000","0.01200000"],["77707.55000000","0.02000000"],["77711.32000000","0.16870000"],["77712.69000000","0.00000000"],["77730.74000000","0.64350000"],["77739.31000000","0.03806000"]]}}
{"type":"depth","received_at_ms":1788407415409,"data":{"e":"depthUpdate","E":1788407415614,"s":"BTCUSDT","U":99603315548,"u":99603315563,"b":[["77671.67000000","0.00007000"],["77518.92000000","0.00000000"],["69917.40000000","0.00176000"],["62148.80000000","0.00000000"]],"a":[["77686.14000000","0.00007000"],["77702.76000000","0.00007000"],["77702.91000000","0.00000000"],["77702.93000000","0.00257000"],["77704.38000000","0.00000000"],["77704.89000000","0.00400000"],["77739.31000000","0.00000000"],["77739.72000000","0.00007000"]]}}
{"type":"depth","received_at_ms":1788407415509,"data":{"e":"depthUpdate","E":1788407415714,"s":"BTCUSDT","U":99603315564,"u":99603315570,"b":[["77677.76000000","0.13116000"],["69917.40000000","0.00176000"]],"a":[["77698.87000000","0.00000000"],["77700.88000000","0.00008000"],["77701.76000000","0.00540000"],["77702.93000000","0.00000000"]]}}
{"type":"depth","received_at_ms":1788407415609,"data":{"e":"depthUpdate","E":1788407415814,"s":"BTCUSDT","U":99603315571,"u":99603315579,"b":[["77685.99000000","14.12559000"],["76520.70000000","0.00030000"],["69917.40000000","0.00192000"]],"a":[["77686.00000000","0.03842000"],["77702.95000000","0.00000000"],["77702.97000000","0.00257000"]]}}
{"type":"depth","received_at_ms":1788407415707,"data":{"e":"depthUpdate","E":1788407415914,"s":"BTCUSDT","U":99603315580,"u":99603315583,"b":[["69917.40000000","0.00192000"]],"a":[["77702.97000000","0.00000000"],["77787.74000000","2.60864000"]]}}
{"type":"depth","received_at_ms":1788407415809,"data":{"e":"depthUpdate","E":1788407416014,"s":"BTCUSDT","U":99603315584,"u":99603315598,"b":[["77503.42000000","0.00000000"],["69917.40000000","0.00208000"],["62148.80000000","0.00032000"]],"a":[["77694.66000000","0.00208000"],["77695.32000000","0.12364000"],["77697.02000000","0.11107000"],["77702.99000000","0.00257000"],["77714.65000000","0.00000000"],["77717.99000000","0.00013000"],["77860.40000000","0.00000000"],["78000.00000000","22.90061000"],["78851.29000000","0.00094000"]]}}
{"type":"depth","received_at_ms":1788407415908,"data":{"e":"depthUpdate","E":1788407416114,"s":"BTCUSDT","U":99603315599,"u":99603315600,"b":[],"a":[["77702.99000000","0.00000000"],["77703.00000000","0.00257000"]]}}
{"type":"depth","received_at_ms":1788407416009,"data":{"e":"depthUpdate","E":1788407416214,"s":"BTCUSDT","U":99603315601,"u":99603315612,"b":[["77517.88000000","4.44764000"],["77516.44000000","0.00000000"],["77492.26000000","0.00812000"],["77489.01000000","0.00000000"],["69917.40000000","0.00224000"],["62148.80000000","0.00000000"]],"a":[["77703.00000000","0.00000000"],["77703.02000000","0.00257000"],["77723.92000000","0.82742000"],["77737.12000000","0.85265000"],["77873.76000000","4.52928000"]]}}
{"type":"depth","received_at_ms":1788407416108,"data":{"e":"depthUpdate","E":1788407416314,"s":"BTCUSDT","U":99603315613,"u":99603315628,"b":[["77523.32000000","0.00025000"],["69917.40000000","0.00249000"],["62149.00000000","0.00083000"],["62148.79000000","0.00020000"],["40885.30000000","0.00000000"]],"a":[["77686.00000000","0.03824000"],["77703.02000000","0.00000000"],["77703.04000000","0.00000000"],["77703.06000000","0.00257000"],["77739.30000000","0.00000000"]]}}
{"type":"depth","received_at_ms":1788407416209,"data":{"e":"depthUpdate","E":1788407416414,"s":"BTCUSDT","U":99603315629,"u":99603315631,"b":[["62148.79000000","0.00000000"]],"a":[]}}
{"type":"depth","received_at_ms":1788407416308,"data":{"e":"depthUpdate","E":1788407416514,"s":"BTCUSDT","U":99603315632,"u":99603315666,"b":[["77685.99000000","14.12688000"],["77685.08000000","0.00014000"],["77685.07000000","0.01635000"],["77683.34000000","0.48922000"],["77671.87000000","0.00200000"],["77668.96000000","0.00000000"],["77657.62000000","0.70275000"],["77619.05000000","0.39529000"],["69917.40000000","0.00265000"],["62148.80000000","0.00032000"]],"a":[["77686.00000000","0.03856000"],["77698.84000000","0.00000000"],["77698.94000000","0.00400000"],["77703.06000000","0.00000000"],["77703.07000000","0.00000000"],["77703.09000000","0.00257000"],["77703.99000000","0.00000000"],["77705.29000000","0.00400000"],["77706.22000000","0.00000000"],["77728.89000000","1.02098000"],["77738.61000000","0.02200000"],["77738.84000000","0.00000000"],["77738.98000000","0.00000000"],["77740.52000000","0.01278000"],["77763.32000000","2.60707000"],["77787.73000000","2.23148000"],["77787.92000000","0.00000000"],["77837.05000000","1.16435000"]]}}
{"type":"depth","received_at_ms":1788407416409,"data":{"e":"depthUpdate","E":1788407416614,"s":"BTCUSDT","U":99603315667,"u":99603317411,"b":[["77693.99000000","10.39904000"],["77693.98000000","6.02157000"],["77693.97000000","0.00000000"],["77693.95000000","0.00007000"],["77693.94000000","0.00769000"],["77693.85000000","0.00551000"],["77693.61000000","0.00000000"],["77693.30000000","0.07500000"],["77693.29000000","0.00000000"],["77693.28000000","0.00388000"],["77693.11000000","0.00000000"],["77692.83000000","0.00000000"],["77692.82000000","0.01865000"],["77692.70000000","0.12364000"],["77692.33000000","0.00000000"],["77692.02000000","0.00014000"],["77692.01000000","0.45359000"],["77692.00000000","0.33331000"],["77691.99000000","0.13914000"],["77691.90000000","0.00400000"],["77691.84000000","0.00000000"],["77691.83000000","0.00007000"],["77691.81000000","0.00000000"],["77691.80000000","0.07507000"],["77691.79000000","0.00021000"],["77691.46000000","0.00007000"],["77691.35000000","0.03302000"],["77690.64000000","0.00000000"],["77690.40000000","0.00000000"],["77690.38000000","0.00832000"],["77690.37000000","0.12946000"],["77690.22000000","0.00014000"],["77690.21000000","0.00007000"],["77690.09000000","1.11217000"],["77690.08000000","0.00000000"],["77690.07000000","0.00000000"],["77689.99000000","0.00007000"],["77689.98000000","0.00000000"],["77689.95000000","0.00400000"],["77689.94000000","0.00027000"],["77689.80000000","0.00000000"],["77689.79000000","0.00014000"],["77689.22000000","0.00007000"],["77689.15000000","0.00000000"],["77689.11000000","0.00000000"],["77688.91000000","0.00000000"],["77688.90000000","0.00000000"],["77688.36000000","0.00007000"],["77688.32000000","0.00007000"],["77688.01000000","0.56736000"],["77688.00000000","0.00400000"],["77687.99000000","0.53611000"],["77687.79000000","0.00000000"],["77687.76000000","0.41269000"],["77687.61000000","0.00000000"],["77687.46000000","0.00000000"],["77686.80000000","0.00007000"],["77686.76000000","0.00007000"],["77686.57000000","0.00000000"],["77686.53000000","0.00013000"],["77686.36000000","0.00014000"],["77686.35000000","0.00007000"],["77686.21000000","0.00000000"],["77686.17000000","0.00008000"],["77686.13000000","0.00000000"],["77686.11000000","0.00000000"],["77686.05000000","0.00400000"],["77686.01000000","0.08640000"],["77686.00000000","4.70903000"],["77685.99000000","0.97935000"],["77685.98000000","0.00000000"],["77685.36000000","0.00008000"],["77685.08000000","0.30866000"],["77685.07000000","0.00007000"],["77685.06000000","0.76103000"],["77685.05000000","0.00000000"],["77684.91000000","0.00007000"],["77684.74000000","0.01684000"],["77684.60000000","0.00000000"],["77684.55000000","0.00000000"],["77684.00000000","0.00000000"],["77683.99000000","0.30000000"],["77683.96000000","0.00007000"],["77683.86000000","0.00000000"],["77683.85000000","0.12044000"],["77683.50000000","0.02021000"],["77683.36000000","0.00624000"],["77683.35000000","1.11223000"],["77683.34000000","0.44861000"],["77683.33000000","0.00000000"],["77682.57000000","0.12872000"],["77682.01000000","0.00000000"],["77682.00000000","0.12925000"],["77681.99000000","0.12801000"],["77681.80000000","0.00007000"],["77680.89000000","0.00008000"],["77680.41000000","0.00007000"],["77680.22000000","0.00000000"],["77680.17000000","0.00000000"],["77680.00000000","0.01607000"],["77679.99000000","0.13710000"],["77679.89000000","1.84507000"],["77679.88000000","4.63403000"],["77679.86000000","0.00010000"],["77679.83000000","0.00000000"],["77679.82000000","0.01192000"],["77679.81000000","0.00000000"],["77679.75000000","0.10575000"],["77679.67000000","0.00007000"],["77679.31000000","0.01967000"],["77678.69000000","0.00007000"],["77678.38000000","0.00015000"],["77678.30000000","0.04000000"],["77678.22000000","0.00000000"],["77677.84000000","0.00539000"],["77677.82000000","0.00000000"],["77677.81000000","0.10703000"],["77676.95000000","0.53996000"],["77676.93000000","0.00000000"],["77675.58000000","0.00000000"],["77675.18000000","0.64396000"],["77674.89000000","0.00000000"],["77674.88000000","1.11240000"],["77674.87000000","0.00673000"],["77674.83000000","0.00008000"],["77674.25000000","0.00200000"],["77673.66000000","0.00000000"],["77672.47000000","0.00000000"],["77672.33000000","0.00000000"],["77672.01000000","0.00000000"],["77672.00000000","0.00265000"],["77671.99000000","0.47843000"],["77671.87000000","0.00000000"],["77671.67000000","0.00000000"],["77671.24000000","0.00000000"],["77670.95000000","0.00008000"],["77670.77000000","0.00000000"],["77670.54000000","0.00000000"],["77670.53000000","0.00000000"],["77670.45000000","0.00400000"],["77669.36000000","0.00000000"],["77669.13000000","0.00000000"],["77668.99000000","0.00257000"],["77668.92000000","0.00007000"],["77668.83000000","0.00000000"],["77668.51000000","0.00335000"],["77667.06000000","0.00022000"],["77666.57000000","0.00000000"],["77665.90000000","0.00665000"],["77665.29000000","0.00000000"],["77664.34000000","0.34778000"],["77664.11000000","0.00000000"],["77663.18000000","0.00008000"],["77663.16000000","0.00000000"],["77662.68000000","0.00000000"],["77662.65000000","0.00000000"],["77661.69000000","0.00000000"],["77661.27000000","0.00000000"],["77660.70000000","0.00000000"],["77660.37000000","0.00000000"],["77659.29000000","0.00008000"],["77658.80000000","0.00007000"],["77658.75000000","0.00000000"],["77658.57000000","0.82812000"],["77656.84000000","0.37682000"],["77656.80000000","0.00000000"],["77656.63000000","0.00000000"],["77656.53000000","0.00000000"],["77655.41000000","0.00008000"],["77654.92000000","0.00000000"],["77654.85000000","0.00000000"],["77652.68000000","4.63403000"],["77652.67000000","0.00000000"],["77652.26000000","0.00310000"],["77651.62000000","0.00000000"],["77651.52000000","0.00008000"],["77651.03000000","0.00000000"],["77649.65000000","0.00000000"],["77649.08000000","0.75799000"],["77647.76000000","0.00000000"],["77647.15000000","0.00000000"],["77647.00000000","0.00000000"],["77646.86000000","0.00434000"],["77646.70000000","0.00000000"],["77646.53000000","0.00634000"],["77646.32000000","0.00000000"],["77646.08000000","0.58208000"],["77646.03000000","0.00000000"],["77645.36000000","0.85366000"],["77644.71000000","0.00014000"],["77643.75000000","0.00000000"],["77640.14000000","0.00000000"],["77639.02000000","0.00424000"],["77638.40000000","0.00000000"],["77638.39000000","0.55527000"],["77638.38000000","0.00000000"],["77634.83000000","0.00000000"],["77634.03000000","0.00000000"],["77632.59000000","0.00000000"],["77632.16000000","0.00000000"],["77629.18000000","0.00000000"],["77629.17000000","0.00000000"],["77628.01000000","0.00320000"],["77627.19000000","0.33738000"],["77627.07000000","0.03508000"],["77627.06000000","0.00000000"],["77625.34000000","0.00000000"],["77624.74000000","0.01702000"],["77623.54000000","0.00543000"],["77623.25000000","1.44992000"],["77621.17000000","2.51333000"],["77621.02000000","0.00321000"],["77618.02000000","0.00321000"],["77618.01000000","0.00000000"],["77614.19000000","0.00007000"],["77614.10000000","0.00016000"],["77612.73000000","0.00000000"],["77610.81000000","0.04213000"],["77608.11000000","0.00000000"],["77605.66000000","0.00000000"],["77605.38000000","0.00000000"],["77604.28000000","0.00000000"],["77603.78000000","0.00000000"],["77602.78000000","0.44589000"],["77591.95000000","0.26124000"],["77591.94000000","0.00000000"],["77588.24000000","0.00000000"],["77588.23000000","0.00011000"],["77588.01000000","0.03241000"],["77587.89000000","0.00128000"],["77584.19000000","0.08787000"],["77584.18000000","0.00000000"],["77556.92000000","1.54284000"],["77550.62000000","0.00128000"],["77540.01000000","0.00000000"],["77539.75000000","0.00000000"],["77536.41000000","0.00008000"],["77527.97000000","0.00000000"],["77506.12000000","0.00038000"],["77458.71000000","0.00008000"],["77450.29000000","0.00000000"],["77433.45000000","0.11358000"],["77418.49000000","0.00000000"],["77413.02000000","0.00000000"],["77381.02000000","0.00008000"],["77377.28000000","0.00000000"],["77372.61000000","0.00000000"],["77363.76000000","0.00000000"],["77303.33000000","0.00008000"],["77294.92000000","0.00000000"],["77225.64000000","0.00008000"],["77217.24000000","0.00000000"],["77147.95000000","0.00019000"],["77139.56000000","0.00000000"],["77070.26000000","0.00008000"],["77061.87000000","0.00000000"],["76520.70000000","0.00000000"],["69924.60000000","0.00016000"],["69917.40000000","0.00000000"],["69917.39000000","0.00009000"],["62148.80000000","0.00000000"]],"a":[["77686.00000000","0.00000000"],["77686.01000000","0.00000000"],["77686.14000000","0.00000000"],["77686.22000000","0.00000000"],["77686.36000000","0.00000000"],["77687.47000000","0.00000000"],["77687.76000000","0.00000000"],["77687.77000000","0.00000000"],["77687.80000000","0.00000000"],["77687.99000000","0.00000000"],["77688.00000000","0.00000000"],["77688.01000000","0.00000000"],["77688.37000000","0.00000000"],["77688.91000000","0.00000000"],["77688.92000000","0.00000000"],["77689.23000000","0.00000000"],["77689.80000000","0.00000000"],["77689.99000000","0.00000000"],["77690.00000000","0.00000000"],["77690.08000000","0.00000000"],["77690.09000000","0.00000000"],["77690.22000000","0.00000000"],["77690.38000000","0.00000000"],["77690.41000000","0.00000000"],["77690.55000000","0.00000000"],["77691.13000000","0.00000000"],["77691.47000000","0.00000000"],["77691.80000000","0.00000000"],["77691.82000000","0.00000000"],["77691.84000000","0.00000000"],["77692.00000000","0.00000000"],["77692.01000000","0.00000000"],["77692.34000000","0.00000000"],["77692.71000000","0.00000000"],["77692.83000000","0.00000000"],["77693.12000000","0.00000000"],["77693.29000000","0.00000000"],["77693.30000000","0.00000000"],["77693.61000000","0.00000000"],["77693.62000000","0.00000000"],["77693.94000000","0.00000000"],["77693.95000000","0.00000000"],["77693.99000000","0.00000000"],["77694.00000000","0.02678000"],["77694.01000000","0.00070000"],["77694.08000000","0.00007000"],["77694.24000000","0.00000000"],["77694.50000000","0.00000000"],["77694.51000000","0.00014000"],["77694.64000000","0.00007000"],["77694.66000000","0.00000000"],["77694.75000000","0.00000000"],["77694.76000000","0.00021000"],["77695.14000000","0.00000000"],["77695.24000000","0.00014000"],["77695.31000000","0.00000000"],["77695.32000000","0.00000000"],["77695.33000000","0.00000000"],["77695.34000000","0.00007000"],["77695.35000000","0.00000000"],["77695.36000000","0.00007000"],["77695.37000000","0.00000000"],["77695.38000000","0.00015000"],["77695.77000000","0.00000000"],["77695.80000000","0.00000000"],["77695.99000000","0.00014000"],["77696.00000000","0.03014000"],["77696.10000000","0.00000000"],["77696.11000000","0.00000000"],["77696.20000000","0.00000000"],["77696.22000000","0.00000000"],["77696.74000000","0.00000000"],["77696.88000000","0.10244000"],["77696.89000000","0.00014000"],["77696.96000000","0.00000000"],["77697.02000000","0.00000000"],["77697.26000000","0.00000000"],["77697.27000000","0.00000000"],["77697.35000000","0.00000000"],["77697.71000000","0.00007000"],["77697.75000000","0.00000000"],["77697.94000000","0.00014000"],["77697.99000000","0.00014000"],["77698.04000000","0.00014000"],["77698.05000000","0.03134000"],["77698.18000000","0.00013000"],["77698.32000000","0.10295000"],["77698.37000000","0.00007000"],["77698.38000000","0.09787000"],["77698.68000000","0.00000000"],["77698.78000000","0.00007000"],["77698.79000000","0.02895000"],["77698.94000000","0.00000000"],["77699.14000000","0.00000000"],["77699.24000000","0.00000000"],["77699.30000000","0.00000000"],["77699.43000000","0.00000000"],["77699.46000000","0.00000000"],["77699.63000000","0.00000000"],["77699.70000000","0.00400000"],["77699.84000000","0.10385000"],["77699.92000000","0.00000000"],["77700.24000000","0.15000000"],["77700.46000000","0.00007000"],["77700.48000000","0.00008000"],["77700.60000000","0.00000000"],["77701.07000000","0.00000000"],["77701.13000000","0.00000000"],["77701.14000000","0.00000000"],["77701.15000000","0.00000000"],["77701.17000000","0.00000000"],["77701.18000000","0.00000000"],["77701.19000000","0.00000000"],["77701.76000000","0.00000000"],["77701.77000000","0.16870000"],["77701.80000000","0.00007000"],["77702.29000000","0.00000000"],["77702.76000000","0.00000000"],["77703.09000000","0.00000000"],["77703.55000000","0.00000000"],["77703.57000000","0.00007000"],["77703.77000000","0.00000000"],["77703.87000000","0.00000000"],["77703.99000000","0.10295000"],["77704.10000000","0.00048000"],["77704.17000000","0.10385000"],["77704.48000000","0.00000000"],["77704.51000000","0.00000000"],["77704.67000000","0.00000000"],["77704.89000000","0.00000000"],["77704.97000000","0.15124000"],["77704.98000000","0.00000000"],["77705.05000000","0.00000000"],["77705.29000000","0.00000000"],["77705.36000000","0.00070000"],["77705.59000000","0.00000000"],["77705.63000000","0.00000000"],["77705.66000000","0.00007000"],["77705.67000000","0.00000000"],["77705.70000000","0.00000000"],["77705.82000000","0.32185000"],["77706.22000000","0.00000000"],["77706.24000000","0.00000000"],["77706.26000000","0.00000000"],["77706.45000000","0.00000000"],["77706.46000000","0.00000000"],["77706.47000000","0.00000000"],["77706.49000000","0.00000000"],["77706.68000000","0.00007000"],["77707.01000000","0.00000000"],["77707.04000000","0.00400000"],["77707.05000000","0.00000000"],["77707.55000000","0.00000000"],["77707.59000000","0.00000000"],["77708.18000000","0.00000000"],["77708.37000000","0.00000000"],["77708.40000000","0.10295000"],["77708.55000000","0.10385000"],["77709.08000000","0.00000000"],["77709.09000000","0.00000000"],["77709.10000000","0.58780000"],["77709.51000000","0.00000000"],["77709.52000000","0.00007000"],["77709.53000000","0.00008000"],["77709.77000000","0.00000000"],["77709.80000000","0.00000000"],["77709.84000000","0.00161000"],["77709.85000000","0.00000000"],["77710.76000000","0.00007000"],["77711.16000000","0.10332000"],["77711.17000000","1.18596000"],["77711.18000000","0.00000000"],["77711.19000000","0.00000000"],["77711.64000000","0.00400000"],["77711.83000000","0.10385000"],["77711.89000000","0.00000000"],["77712.05000000","0.02000000"],["77712.25000000","0.00000000"],["77712.67000000","0.00000000"],["77712.68000000","0.60432000"],["77712.83000000","0.00665000"],["77713.36000000","0.00000000"],["77713.38000000","0.00007000"],["77713.40000000","0.00000000"],["77713.41000000","0.00008000"],["77713.92000000","0.00000000"],["77713.93000000","0.00643000"],["77714.16000000","0.10295000"],["77714.44000000","0.10385000"],["77714.94000000","0.10570000"],["77715.05000000","0.00000000"],["77715.68000000","0.10295000"],["77716.13000000","0.00000000"],["77716.71000000","0.00000000"],["77716.89000000","0.10697000"],["77717.24000000","0.00007000"],["77717.28000000","0.00000000"],["77717.29000000","0.37682000"],["77717.30000000","0.00008000"],["77717.99000000","0.00000000"],["77718.82000000","0.09354000"],["77719.16000000","0.10385000"],["77719.17000000","0.18216000"],["77719.36000000","0.41227000"],["77720.00000000","0.03000000"],["77720.02000000","0.00000000"],["77720.61000000","0.00648000"],["77720.75000000","0.00000000"],["77720.78000000","0.90438000"],["77720.80000000","0.00000000"],["77720.97000000","0.00128000"],["77721.10000000","0.00007000"],["77721.17000000","0.00000000"],["77721.18000000","0.00020000"],["77721.47000000","0.00000000"],["77721.98000000","0.00013000"],["77721.99000000","0.25752000"],["77722.34000000","0.01278000"],["77722.39000000","0.64382000"],["77722.85000000","0.00000000"],["77723.90000000","0.00000000"],["77723.92000000","0.00000000"],["77724.16000000","0.00008000"],["77724.96000000","0.00007000"],["77725.00000000","0.00000000"],["77725.05000000","0.00400000"],["77725.08000000","0.00008000"],["77725.24000000","0.00000000"],["77727.00000000","0.00400000"],["77727.72000000","0.00000000"],["77727.87000000","0.00000000"],["77728.39000000","0.00646000"],["77728.82000000","0.00007000"],["77728.94000000","0.00000000"],["77728.95000000","0.00408000"],["77729.29000000","0.00000000"],["77729.80000000","0.00000000"],["77730.00000000","0.03000000"],["77730.90000000","0.00400000"],["77731.31000000","0.00000000"],["77731.63000000","0.00000000"],["77732.45000000","0.00000000"],["77732.51000000","0.00000000"],["77732.55000000","0.82733000"],["77732.68000000","0.00014000"],["77732.77000000","0.00000000"],["77732.84000000","0.00008000"],["77732.85000000","0.00400000"],["77733.00000000","0.01000000"],["77734.85000000","0.00000000"],["77735.46000000","0.00000000"],["77735.68000000","0.00000000"],["77736.17000000","0.00651000"],["77736.43000000","0.64345000"],["77736.54000000","0.00007000"],["77737.07000000","1.16522000"],["77737.52000000","0.00000000"],["77738.66000000","0.37242000"],["77738.85000000","0.00008000"],["77739.22000000","0.00000000"],["77740.40000000","0.00007000"],["77741.03000000","0.00000000"],["77742.06000000","0.00000000"],["77742.27000000","0.00000000"],["77742.93000000","0.00000000"],["77743.54000000","0.00000000"],["77743.71000000","0.51538000"],["77743.72000000","0.56145000"],["77744.10000000","0.00000000"],["77744.11000000","0.00000000"],["77744.90000000","0.12782000"],["77745.57000000","0.16870000"],["77747.55000000","0.34741000"],["77749.60000000","0.00639000"],["77749.86000000","0.34740000"],["77752.75000000","0.00000000"],["77755.40000000","0.50875000"],["77758.96000000","0.85241000"],["77761.03000000","0.00000000"],["77761.08000000","1.27363000"],["77763.20000000","0.01157000"],["77769.49000000","0.00008000"],["77773.49000000","0.00000000"],["77787.73000000","0.07020000"],["77787.74000000","0.00000000"],["77787.92000000","1.45280000"],["77790.86000000","1.56048000"],["77790.87000000","3.85801000"],["77791.99000000","0.00000000"],["77794.95000000","1.39539000"],["77805.72000000","1.50782000"],["77806.28000000","0.00000000"],["77817.83000000","0.00000000"],["77818.55000000","0.00000000"],["77827.17000000","0.00256000"],["77834.94000000","0.00000000"],["77834.95000000","0.00000000"],["77838.72000000","0.00000000"],["77841.18000000","0.14305000"],["77844.76000000","0.03633000"],["77847.18000000","0.00008000"],["77849.49000000","1.29500000"],["77855.16000000","0.46297000"],["77859.56000000","0.05164000"],["77884.26000000","0.00007000"],["77888.14000000","0.00007000"],["77903.57000000","0.00000000"],["77916.40000000","0.00000000"],["77924.88000000","0.00008000"],["77927.33000000","0.00007000"],["77927.35000000","0.00386000"],["77942.08000000","0.00218000"],["77952.14000000","0.00030000"],["77994.08000000","0.00000000"],["78002.57000000","0.00008000"],["78071.77000000","0.00012000"],["78080.26000000","0.00008000"],["78089.64000000","0.00007000"],["78149.45000000","0.00128000"],["78157.95000000","0.00008000"],["78227.13000000","0.00000000"],["78235.64000000","0.00008000"],["78851.29000000","0.00064000"]]}}
