{"type":"depth","received_at_ms":1788333207647,"data":{"e":"depthUpdate","E":1788333207814,"s":"BTCUSDT","U":99556335617,"u":99556335636,"b":[["77727.75000000","4.23427000"],["77727.70000000","0.00000000"],["77725.99000000","0.50858000"],["77724.00000000","3.96222000"],["69954.98000000","0.00144000"],["69954.97000000","0.00009000"],["69954.00000000","0.00028000"]],"a":[["77727.76000000","0.16600000"],["77747.18000000","0.00128000"],["77748.38000000","0.00000000"]]}}
{"type":"trade","received_at_ms":1788333207738,"data":{"e":"trade","E":1788333207905,"s":"BTCUSDT","t":6646666392,"p":"77727.76000000","q":"0.00777000","T":1788333207904,"m":false,"M":true}}
{"type":"depth","received_at_ms":1788333207747,"data":{"e":"depthUpdate","E":1788333207914,"s":"BTCUSDT","U":99556335637,"u":99556335649,"b":[["77727.75000000","4.23770000"],["77726.52000000","0.00257000"],["77723.12000000","0.00007000"],["76561.83000000","0.00030000"],["69954.00000000","0.00008000"]],"a":[["77727.76000000","0.17153000"],["77815.91000000","0.00007000"]]}}
{"type":"depth","received_at_ms":1788333207848,"data":{"e":"depthUpdate","E":1788333208014,"s":"BTCUSDT","U":99556335650,"u":99556335677,"b":[["77727.75000000","4.28777000"],["77727.55000000","0.00000000"],["77727.45000000","0.05000000"],["77704.00000000","0.00507000"],["77656.06000000","0.00320000"],["77652.48000000","0.00000000"],["77578.01000000","0.00128000"],["77574.01000000","0.00000000"],["69954.98000000","0.00160000"],["62182.20000000","0.00032000"],["62182.00000000","0.00000000"]],"a":[["77727.76000000","0.15846000"],["77727.77000000","0.00083000"],["77727.78000000","0.00013000"],["77783.34000000","0.00000000"],["77787.53000000","0.00320000"],["77861.98000000","0.00000000"],["77867.41000000","0.00128000"]]}}
{"type":"trade","received_at_ms":1788333207924,"data":{"e":"trade","E":1788333208091,"s":"BTCUSDT","t":6646666393,"p":"77727.76000000","q":"0.01744000","T":1788333208091,"m":false,"M":true}}
{"type":"trade","received_at_ms":1788333207926,"data":{"e":"trade","E":1788333208091,"s":"BTCUSDT","t":6646666394,"p":"77727.76000000","q":"0.00007000","T":1788333208091,"m":false,"M":true}}
{"type":"trade","received_at_ms":1788333207926,"data":{"e":"trade","E":1788333208091,"s":"BTCUSDT","t":6646666395,"p":"77727.76000000","q":"0.00007000","T":1788333208091,"m":false,"M":true}}
{"type":"trade","received_at_ms":1788333207926,"data":{"e":"trade","E":1788333208091,"s":"BTCUSDT","t":6646666396,"p":"77727.76000000","q":"0.00118000","T":1788333208091,"m":false,"M":true}}
{"type":"trade","received_at_ms":1788333207926,"data":{"e":"trade","E":1788333208091,"s":"BTCUSDT","t":6646666397,"p":"77727.76000000","q":"0.00007000","T":1788333208091,"m":false,"M":true}}
{"type":"trade","received_at_ms":1788333207926,"data":{"e":"trade","E":1788333208091,"s":"BTCUSDT","t":6646666398,"p":"77727.76000000","q":"0.00217000","T":1788333208091,"m":false,"M":true}}
{"type":"trade","received_at_ms":1788333207926,"data":{"e":"trade","E":1788333208092,"s":"BTCUSDT","t":6646666399,"p":"77727.76000000","q":"0.00133000","T":1788333208091,"m":false,"M":true}}
{"type":"trade","received_at_ms":1788333207926,"data":{"e":"trade","E":1788333208092,"s":"BTCUSDT","t":6646666400,"p":"77727.76000000","q":"0.00007000","T":1788333208091,"m":false,"M":true}}
{"type":"trade","received_at_ms":1788333207926,"data":{"e":"trade","E":1788333208092,"s":"BTCUSDT","t":6646666401,"p":"77727.76000000","q":"0.00007000","T":1788333208091,"m":false,"M":true}}
{"type":"trade","received_at_ms":1788333207926,"data":{"e":"trade","E":1788333208092,"s":"BTCUSDT","t":6646666402,"p":"77727.76000000","q":"0.00007000","T":1788333208091,"m":false,"M":true}}
{"type":"trade","received_at_ms":1788333207926,"data":{"e":"trade","E":1788333208092,"s":"BTCUSDT","t":6646666403,"p":"77727.76000000","q":"0.00007000","T":1788333208091,"m":false,"M":true}}
{"type":"trade","received_at_ms":1788333207926,"data":{"e":"trade","E":1788333208092,"s":"BTCUSDT","t":6646666404,"p":"77727.76000000","q":"0.00007000","T":1788333208091,"m":false,"M":true}}
{"type":"trade","received_at_ms":1788333207926,"data":{"e":"trade","E":1788333208092,"s":"BTCUSDT","t":6646666405,"p":"77727.76000000","q":"0.00007000","T":1788333208091,"m":false,"M":true}}
{"type":"trade","received_at_ms":1788333207926,"data":{"e":"trade","E":1788333208092,"s":"BTCUSDT","t":6646666406,"p":"77727.76000000","q":"0.00007000","T":1788333208091,"m":false,"M":true}}
{"type":"trade","received_at_ms":1788333207926,"data":{"e":"trade","E":1788333208092,"s":"BTCUSDT","t":6646666407,"p":"77727.76000000","q":"0.00007000","T":1788333208091,"m":false,"M":true}}
{"type":"trade","received_at_ms":1788333207926,"data":{"e":"trade","E":1788333208092,"s":"BTCUSDT","t":6646666408,"p":"77727.76000000","q":"0.00007000","T":1788333208091,"m":false,"M":true}}
{"type":"trade","received_at_ms":1788333207926,"data":{"e":"trade","E":1788333208092,"s":"BTCUSDT","t":6646666409,"p":"77727.76000000","q":"0.00007000","T":1788333208091,"m":false,"M":true}}
{"type":"trade","received_at_ms":1788333207926,"data":{"e":"trade","E":1788333208092,"s":"BTCUSDT","t":6646666410,"p":"77727.76000000","q":"0.00007000","T":1788333208091,"m":false,"M":true}}
{"type":"trade","received_at_ms":1788333207926,"data":{"e":"trade","E":1788333208092,"s":"BTCUSDT","t":6646666411,"p":"77727.76000000","q":"0.00007000","T":1788333208091,"m":false,"M":true}}
{"type":"trade","received_at_ms":1788333207926,"data":{"e":"trade","E":1788333208092,"s":"BTCUSDT","t":6646666412,"p":"77727.76000000","q":"0.00064000","T":1788333208091,"m":false,"M":true}}
{"type":"trade","received_at_ms":1788333207926,"data":{"e":"trade","E":1788333208092,"s":"BTCUSDT","t":6646666413,"p":"77727.76000000","q":"0.00065000","T":1788333208091,"m":false,"M":true}}
{"type":"trade","received_at_ms":1788333207926,"data":{"e":"trade","E":1788333208092,"s":"BTCUSDT","t":6646666414,"p":"77727.76000000","q":"0.00150000","T":1788333208091,"m":false,"M":true}}
{"type":"trade","received_at_ms":1788333207926,"data":{"e":"trade","E":1788333208092,"s":"BTCUSDT","t":6646666415,"p":"77727.76000000","q":"0.00007000","T":1788333208091,"m":false,"M":true}}
{"type":"trade","received_at_ms":1788333207926,"data":{"e":"trade","E":1788333208092,"s":"BTCUSDT","t":6646666416,"p":"77727.76000000","q":"0.00008000","T":1788333208091,"m":false,"M":true}}
{"type":"trade","received_at_ms":1788333207926,"data":{"e":"trade","E":1788333208092,"s":"BTCUSDT","t":6646666417,"p":"77727.76000000","q":"0.00007000","T":1788333208091,"m":false,"M":true}}
{"type":"trade","received_at_ms":1788333207926,"data":{"e":"trade","E":1788333208092,"s":"BTCUSDT","t":6646666418,"p":"77727.76000000","q":"0.00007000","T":1788333208091,"m":false,"M":true}}
{"type":"trade","received_at_ms":1788333207926,"data":{"e":"trade","E":1788333208092,"s":"BTCUSDT","t":6646666419,"p":"77727.76000000","q":"0.01575000","T":1788333208091,"m":false,"M":true}}
{"type":"trade","received_at_ms":1788333207926,"data":{"e":"trade","E":1788333208092,"s":"BTCUSDT","t":6646666420,"p":"77727.76000000","q":"0.02100000","T":1788333208092,"m":false,"M":true}}
{"type":"depth","received_at_ms":1788333207947,"data":{"e":"depthUpdate","E":1788333208114,"s":"BTCUSDT","U":99556335678,"u":99556335752,"b":[["77727.75000000","4.24177000"],["77727.51000000","0.00014000"],["77727.50000000","0.05000000"],["77726.53000000","0.00643000"],["77726.52000000","0.00000000"],["77725.03000000","0.00014000"],["77725.00000000","0.00000000"],["77670.09000000","0.00000000"],["69954.98000000","0.00176000"],["69954.97000000","0.00000000"]],"a":[["77727.76000000","0.10315000"],["77728.39000000","0.00014000"],["77728.40000000","0.13812000"],["77730.21000000","0.00000000"],["77732.35000000","0.00000000"],["77737.50000000","0.00000000"],["77738.17000000","0.00400000"],["77740.13000000","0.00000000"],["77740.63000000","0.00643000"],["77743.85000000","0.00257000"],["77743.86000000","0.00000000"],["77752.78000000","0.00000000"],["77791.66000000","0.00000000"],["77820.37000000","0.00000000"],["77822.57000000","0.00000000"],["77824.13000000","0.00025000"],["77946.98000000","0.00007000"],["77950.86000000","0.00016000"]]}}
{"type":"depth","received_at_ms":1788333208047,"data":{"e":"depthUpdate","E":1788333208215,"s":"BTCUSDT","U":99556335753,"u":99556335786,"b":[["77727.75000000","4.24177000"],["77727.50000000","0.05014000"],["77727.45000000","0.05021000"],["77726.53000000","0.00657000"],["77725.08000000","0.01308000"],["77725.03000000","0.00000000"],["77724.99000000","0.30014000"],["77028.20000000","0.00042000"],["62182.20000000","0.00000000"]],"a":[["77728.00000000","0.03014000"],["77728.40000000","0.13826000"],["77731.76000000","0.11191000"],["77758.02000000","0.00000000"],["77758.07000000","0.10315000"],["77950.86000000","0.00009000"]]}}
{"type":"depth","received_at_ms":1788333208146,"data":{"e":"depthUpdate","E":1788333208314,"s":"BTCUSDT","U":99556335787,"u":99556335806,"b":[["77727.75000000","4.24184000"],["77727.61000000","0.00014000"],["77727.60000000","0.05007000"],["77727.55000000","0.05000000"],["77727.51000000","0.00000000"],["77727.50000000","0.00014000"],["77727.45000000","0.00021000"],["69954.98000000","0.00192000"],["62182.00000000","0.00000000"],["62179.00000000","0.01200000"]],"a":[["77727.76000000","0.10322000"],["77727.77000000","0.00090000"],["77758.07000000","0.00000000"]]}}
{"type":"depth","received_at_ms":1788333208247,"data":{"e":"depthUpdate","E":1788333208414,"s":"BTCUSDT","U":99556335807,"u":99556335837,"b":[["77727.75000000","4.24177000"],["77727.61000000","0.00000000"],["77727.60000000","0.00021000"],["77727.55000000","0.00014000"],["77727.50000000","0.00000000"],["77727.45000000","0.00007000"],["77725.00000000","0.00014000"],["77709.13000000","0.00007000"],["77704.00000000","0.01507000"],["69954.98000000","0.00192000"],["62179.00000000","0.01200000"]],"a":[["77727.76000000","0.11652000"],["77740.23000000","0.00000000"],["77743.84000000","0.00257000"],["77743.85000000","0.00000000"]]}}
{"type":"trade","received_at_ms":1788333208250,"data":{"e":"trade","E":1788333208414,"s":"BTCUSDT","t":6646666421,"p":"77727.75000000","q":"0.00009000","T":1788333208414,"m":true,"M":true}}
{"type":"depth","received_at_ms":1788333208353,"data":{"e":"depthUpdate","E":1788333208514,"s":"BTCUSDT","U":99556335838,"u":99556335865,"b":[["77727.75000000","4.24161000"],["77727.60000000","0.00000000"],["77727.55000000","0.00000000"],["77725.08000000","0.01322000"],["77724.99000000","0.30028000"],["77716.89000000","0.00000000"],["77709.13000000","0.00014000"],["77697.39000000","0.00000000"],["77674.33000000","0.00411000"],["77669.76000000","0.00000000"],["69954.98000000","0.00192000"],["69954.97000000","0.00009000"],["62182.20000000","0.00032000"],["62182.00000000","0.00000000"]],"a":[["77727.76000000","0.11659000"],["77737.73000000","0.00000000"],["77740.23000000","0.00007000"],["77757.18000000","0.00000000"],["77776.64000000","0.00000000"]]}}
{"type":"trade","received_at_ms":1788333208442,"data":{"e":"trade","E":1788333208608,"s":"BTCUSDT","t":6646666422,"p":"77727.76000000","q":"0.02100000","T":1788333208608,"m":false,"M":true}}
{"type":"depth","received_at_ms":1788333208446,"data":{"e":"depthUpdate","E":1788333208614,"s":"BTCUSDT","U":99556335866,"u":99556335878,"b":[["77724.02000000","0.01407000"],["77724.01000000","0.94135000"],["77724.00000000","2.02996000"],["69954.98000000","0.00208000"],["62182.20000000","0.00000000"]],"a":[["77727.76000000","0.09566000"],["77739.75000000","0.00000000"]]}}
{"type":"depth","received_at_ms":1788333208547,"data":{"e":"depthUpdate","E":1788333208714,"s":"BTCUSDT","U":99556335879,"u":99556335907,"b":[["77727.75000000","4.24161000"],["77727.55000000","0.00000000"],["77724.02000000","0.01207000"],["77719.43000000","0.00320000"],["77716.43000000","0.02000000"],["77677.52000000","0.02000000"],["77657.31000000","0.02000000"],["69954.98000000","0.00224000"],["62182.00000000","0.00000000"]],"a":[["77727.76000000","0.24144000"],["77734.14000000","0.00000000"],["77741.66000000","0.02800000"],["77743.83000000","0.00257000"],["77743.84000000","0.00000000"],["77761.11000000","0.02800000"],["77780.57000000","0.02800000"],["77821.72000000","2.15325000"],["77824.31000000","1.93226000"],["78893.68000000","0.00030000"]]}}
{"type":"trade","received_at_ms":1788333208643,"data":{"e":"trade","E":1788333208809,"s":"BTCUSDT","t":6646666423,"p":"77727.75000000","q":"0.01500000","T":1788333208809,"m":true,"M":true}}
{"type":"depth","received_at_ms":1788333208647,"data":{"e":"depthUpdate","E":1788333208814,"s":"BTCUSDT","U":99556335908,"u":99556335918,"b":[["77727.75000000","4.22661000"],["69954.98000000","0.00208000"],["69954.97000000","0.00000000"],["69954.96000000","0.00009000"]],"a":[["77727.76000000","0.09566000"],["77729.51000000","0.00007000"],["77740.06000000","0.00000000"],["77758.14000000","0.00000000"],["77758.17000000","0.12871000"],["77848.35000000","0.00000000"],["77887.27000000","0.00000000"]]}}
{"type":"depth","received_at_ms":1788333208748,"data":{"e":"depthUpdate","E":1788333208914,"s":"BTCUSDT","U":99556335919,"u":99556335931,"b":[["77724.02000000","0.00007000"],["77722.68000000","0.37345000"],["77720.45000000","0.01200000"],["76561.83000000","0.00030000"],["69954.98000000","0.00240000"]],"a":[["77727.76000000","0.22211000"],["77794.11000000","0.00788000"]]}}
{"type":"depth","received_at_ms":1788333208852,"data":{"e":"depthUpdate","E":1788333209014,"s":"BTCUSDT","U":99556335932,"u":99556335960,"b":[["77727.75000000","4.22668000"],["77727.40000000","0.00000000"],["77727.35000000","0.05000000"],["77726.53000000","0.00014000"],["77725.71000000","0.00643000"],["77724.99000000","0.30028000"],["77724.02000000","0.00007000"],["77720.46000000","0.01200000"],["77720.45000000","0.00000000"],["77704.00000000","0.02507000"],["69954.98000000","0.00240000"],["62182.20000000","0.00032000"]],"a":[["77734.84000000","0.00206000"],["77743.82000000","0.00257000"],["77743.83000000","0.00000000"]]}}
{"type":"trade","received_at_ms":1788333208893,"data":{"e":"trade","E":1788333209058,"s":"BTCUSDT","t":6646666424,"p":"77727.76000000","q":"0.00200000","T":1788333209057,"m":false,"M":true}}
{"type":"trade","received_at_ms":1788333208897,"data":{"e":"trade","E":1788333209058,"s":"BTCUSDT","t":6646666425,"p":"77727.76000000","q":"0.00200000","T":1788333209057,"m":false,"M":true}}
{"type":"trade","received_at_ms":1788333208899,"data":{"e":"trade","E":1788333209058,"s":"BTCUSDT","t":6646666426,"p":"77727.76000000","q":"0.00200000","T":1788333209058,"m":false,"M":true}}
{"type":"trade","received_at_ms":1788333208899,"data":{"e":"trade","E":1788333209058,"s":"BTCUSDT","t":6646666427,"p":"77727.76000000","q":"0.00200000","T":1788333209058,"m":false,"M":true}}
{"type":"trade","received_at_ms":1788333208899,"data":{"e":"trade","E":1788333209058,"s":"BTCUSDT","t":6646666428,"p":"77727.76000000","q":"0.00200000","T":1788333209058,"m":false,"M":true}}
{"type":"trade","received_at_ms":1788333208899,"data":{"e":"trade","E":1788333209058,"s":"BTCUSDT","t":6646666429,"p":"77727.76000000","q":"0.00200000","T":1788333209058,"m":false,"M":true}}
{"type":"trade","received_at_ms":1788333208899,"data":{"e":"trade","E":1788333209059,"s":"BTCUSDT","t":6646666430,"p":"77727.76000000","q":"0.00200000","T":1788333209058,"m":false,"M":true}}
{"type":"trade","received_at_ms":1788333208899,"data":{"e":"trade","E":1788333209059,"s":"BTCUSDT","t":6646666431,"p":"77727.76000000","q":"0.00200000","T":1788333209058,"m":false,"M":true}}
{"type":"trade","received_at_ms":1788333208899,"data":{"e":"trade","E":1788333209059,"s":"BTCUSDT","t":6646666432,"p":"77727.76000000","q":"0.00200000","T":1788333209058,"m":false,"M":true}}
{"type":"trade","received_at_ms":1788333208899,"data":{"e":"trade","E":1788333209059,"s":"BTCUSDT","t":6646666433,"p":"77727.76000000","q":"0.00200000","T":1788333209058,"m":false,"M":true}}
{"type":"trade","received_at_ms":1788333208899,"data":{"e":"trade","E":1788333209059,"s":"BTCUSDT","t":6646666434,"p":"77727.76000000","q":"0.00200000","T":1788333209059,"m":false,"M":true}}
{"type":"trade","received_at_ms":1788333208899,"data":{"e":"trade","E":1788333209059,"s":"BTCUSDT","t":6646666435,"p":"77727.76000000","q":"0.00200000","T":1788333209059,"m":false,"M":true}}
{"type":"trade","received_at_ms":1788333208899,"data":{"e":"trade","E":1788333209059,"s":"BTCUSDT","t":6646666436,"p":"77727.76000000","q":"0.00200000","T":1788333209059,"m":false,"M":true}}
{"type":"trade","received_at_ms":1788333208899,"data":{"e":"trade","E":1788333209059,"s":"BTCUSDT","t":6646666437,"p":"77727.76000000","q":"0.00200000","T":1788333209059,"m":false,"M":true}}
{"type":"trade","received_at_ms":1788333208899,"data":{"e":"trade","E":1788333209060,"s":"BTCUSDT","t":6646666438,"p":"77727.76000000","q":"0.00200000","T":1788333209060,"m":false,"M":true}}
{"type":"trade","received_at_ms":1788333208902,"data":{"e":"trade","E":1788333209060,"s":"BTCUSDT","t":6646666439,"p":"77727.76000000","q":"0.00200000","T":1788333209060,"m":false,"M":true}}
{"type":"trade","received_at_ms":1788333208902,"data":{"e":"trade","E":1788333209061,"s":"BTCUSDT","t":6646666440,"p":"77727.76000000","q":"0.00200000","T":1788333209060,"m":false,"M":true}}
{"type":"trade","received_at_ms":1788333208902,"data":{"e":"trade","E":1788333209061,"s":"BTCUSDT","t":6646666441,"p":"77727.76000000","q":"0.02000000","T":1788333209061,"m":false,"M":true}}
{"type":"trade","received_at_ms":1788333208902,"data":{"e":"trade","E":1788333209062,"s":"BTCUSDT","t":6646666442,"p":"77727.76000000","q":"0.01450000","T":1788333209061,"m":false,"M":true}}
{"type":"trade","received_at_ms":1788333208902,"data":{"e":"trade","E":1788333209062,"s":"BTCUSDT","t":6646666443,"p":"77727.76000000","q":"0.00070000","T":1788333209061,"m":false,"M":true}}
{"type":"trade","received_at_ms":1788333208902,"data":{"e":"trade","E":1788333209062,"s":"BTCUSDT","t":6646666444,"p":"77727.76000000","q":"0.00048000","T":1788333209061,"m":false,"M":true}}
{"type":"trade","received_at_ms":1788333208902,"data":{"e":"trade","E":1788333209062,"s":"BTCUSDT","t":6646666445,"p":"77727.76000000","q":"0.00013000","T":1788333209061,"m":false,"M":true}}
{"type":"trade","received_at_ms":1788333208902,"data":{"e":"trade","E":1788333209062,"s":"BTCUSDT","t":6646666446,"p":"77727.76000000","q":"0.00007000","T":1788333209061,"m":false,"M":true}}
{"type":"trade","received_at_ms":1788333208902,"data":{"e":"trade","E":1788333209062,"s":"BTCUSDT","t":6646666447,"p":"77727.76000000","q":"0.00428000","T":1788333209061,"m":false,"M":true}}
{"type":"trade","received_at_ms":1788333208902,"data":{"e":"trade","E":1788333209062,"s":"BTCUSDT","t":6646666448,"p":"77727.76000000","q":"0.00007000","T":1788333209061,"m":false,"M":true}}
{"type":"trade","received_at_ms":1788333208902,"data":{"e":"trade","E":1788333209062,"s":"BTCUSDT","t":6646666449,"p":"77727.76000000","q":"0.00013000","T":1788333209061,"m":false,"M":true}}
{"type":"trade","received_at_ms":1788333208902,"data":{"e":"trade","E":1788333209062,"s":"BTCUSDT","t":6646666450,"p":"77727.76000000","q":"0.00020000","T":1788333209061,"m":false,"M":true}}
{"type":"trade","received_at_ms":1788333208902,"data":{"e":"trade","E":1788333209062,"s":"BTCUSDT","t":6646666451,"p":"77727.76000000","q":"0.00007000","T":1788333209061,"m":false,"M":true}}
{"type":"trade","received_at_ms":1788333208902,"data":{"e":"trade","E":1788333209062,"s":"BTCUSDT","t":6646666452,"p":"77727.76000000","q":"0.00007000","T":1788333209061,"m":false,"M":true}}
{"type":"trade","received_at_ms":1788333208902,"data":{"e":"trade","E":1788333209062,"s":"BTCUSDT","t":6646666453,"p":"77727.76000000","q":"0.00007000","T":1788333209061,"m":false,"M":true}}
{"type":"trade","received_at_ms":1788333208902,"data":{"e":"trade","E":1788333209062,"s":"BTCUSDT","t":6646666454,"p":"77727.76000000","q":"0.00023000","T":1788333209061,"m":false,"M":true}}
{"type":"trade","received_at_ms":1788333208906,"data":{"e":"trade","E":1788333209063,"s":"BTCUSDT","t":6646666455,"p":"77727.76000000","q":"0.00042000","T":1788333209062,"m":false,"M":true}}
{"type":"trade","received_at_ms":1788333208906,"data":{"e":"trade","E":1788333209063,"s":"BTCUSDT","t":6646666456,"p":"77727.76000000","q":"0.00007000","T":1788333209062,"m":false,"M":true}}
{"type":"trade","received_at_ms":1788333208906,"data":{"e":"trade","E":1788333209063,"s":"BTCUSDT","t":6646666457,"p":"77727.76000000","q":"0.00064000","T":1788333209062,"m":false,"M":true}}
{"type":"trade","received_at_ms":1788333208906,"data":{"e":"trade","E":1788333209063,"s":"BTCUSDT","t":6646666458,"p":"77727.76000000","q":"0.00140000","T":1788333209062,"m":false,"M":true}}
{"type":"trade","received_at_ms":1788333208906,"data":{"e":"trade","E":1788333209063,"s":"BTCUSDT","t":6646666459,"p":"77727.76000000","q":"0.00210000","T":1788333209062,"m":false,"M":true}}
{"type":"trade","received_at_ms":1788333208906,"data":{"e":"trade","E":1788333209063,"s":"BTCUSDT","t":6646666460,"p":"77727.76000000","q":"0.00008000","T":1788333209062,"m":false,"M":true}}
{"type":"trade","received_at_ms":1788333208906,"data":{"e":"trade","E":1788333209063,"s":"BTCUSDT","t":6646666461,"p":"77727.76000000","q":"0.00150000","T":1788333209062,"m":false,"M":true}}
{"type":"trade","received_at_ms":1788333208906,"data":{"e":"trade","E":1788333209063,"s":"BTCUSDT","t":6646666462,"p":"77727.76000000","q":"0.00007000","T":1788333209062,"m":false,"M":true}}
{"type":"trade","received_at_ms":1788333208906,"data":{"e":"trade","E":1788333209063,"s":"BTCUSDT","t":6646666463,"p":"77727.76000000","q":"0.00007000","T":1788333209062,"m":false,"M":true}}
{"type":"trade","received_at_ms":1788333208906,"data":{"e":"trade","E":1788333209063,"s":"BTCUSDT","t":6646666464,"p":"77727.76000000","q":"0.00007000","T":1788333209062,"m":false,"M":true}}
{"type":"trade","received_at_ms":1788333208906,"data":{"e":"trade","E":1788333209063,"s":"BTCUSDT","t":6646666465,"p":"77727.76000000","q":"0.00007000","T":1788333209062,"m":false,"M":true}}
{"type":"trade","received_at_ms":1788333208906,"data":{"e":"trade","E":1788333209063,"s":"BTCUSDT","t":6646666466,"p":"77727.76000000","q":"0.00007000","T":1788333209062,"m":false,"M":true}}
{"type":"trade","received_at_ms":1788333208906,"data":{"e":"trade","E":1788333209063,"s":"BTCUSDT","t":6646666467,"p":"77727.76000000","q":"0.00007000","T":1788333209062,"m":false,"M":true}}
{"type":"trade","received_at_ms":1788333208906,"data":{"e":"trade","E":1788333209063,"s":"BTCUSDT","t":6646666468,"p":"77727.76000000","q":"0.00007000","T":1788333209062,"m":false,"M":true}}
{"type":"trade","received_at_ms":1788333208906,"data":{"e":"trade","E":1788333209063,"s":"BTCUSDT","t":6646666469,"p":"77727.76000000","q":"0.00007000","T":1788333209062,"m":false,"M":true}}
{"type":"trade","received_at_ms":1788333208906,"data":{"e":"trade","E":1788333209063,"s":"BTCUSDT","t":6646666470,"p":"77727.76000000","q":"0.00007000","T":1788333209062,"m":false,"M":true}}
{"type":"trade","received_at_ms":1788333208906,"data":{"e":"trade","E":1788333209063,"s":"BTCUSDT","t":6646666471,"p":"77727.76000000","q":"0.00007000","T":1788333209062,"m":false,"M":true}}
{"type":"trade","received_at_ms":1788333208906,"data":{"e":"trade","E":1788333209063,"s":"BTCUSDT","t":6646666472,"p":"77727.76000000","q":"0.00007000","T":1788333209062,"m":false,"M":true}}
{"type":"trade","received_at_ms":1788333208906,"data":{"e":"trade","E":1788333209063,"s":"BTCUSDT","t":6646666473,"p":"77727.76000000","q":"0.00007000","T":1788333209062,"m":false,"M":true}}
{"type":"trade","received_at_ms":1788333208906,"data":{"e":"trade","E":1788333209063,"s":"BTCUSDT","t":6646666474,"p":"77727.76000000","q":"0.00010000","T":1788333209062,"m":false,"M":true}}
{"type":"trade","received_at_ms":1788333208906,"data":{"e":"trade","E":1788333209063,"s":"BTCUSDT","t":6646666475,"p":"77727.76000000","q":"0.00007000","T":1788333209062,"m":false,"M":true}}
{"type":"trade","received_at_ms":1788333208906,"data":{"e":"trade","E":1788333209063,"s":"BTCUSDT","t":6646666476,"p":"77727.76000000","q":"0.00010000","T":1788333209062,"m":false,"M":true}}
{"type":"trade","received_at_ms":1788333208906,"data":{"e":"trade","E":1788333209063,"s":"BTCUSDT","t":6646666477,"p":"77727.76000000","q":"0.01320000","T":1788333209062,"m":false,"M":true}}
{"type":"trade","received_at_ms":1788333208906,"data":{"e":"trade","E":1788333209063,"s":"BTCUSDT","t":6646666478,"p":"77727.76000000","q":"0.00007000","T":1788333209062,"m":false,"M":true}}
{"type":"trade","received_at_ms":1788333208906,"data":{"e":"trade","E":1788333209063,"s":"BTCUSDT","t":6646666479,"p":"77727.76000000","q":"0.00007000","T":1788333209062,"m":false,"M":true}}
{"type":"trade","received_at_ms":1788333208906,"data":{"e":"trade","E":1788333209063,"s":"BTCUSDT","t":6646666480,"p":"77727.76000000","q":"0.00034000","T":1788333209062,"m":false,"M":true}}
{"type":"trade","received_at_ms":1788333208906,"data":{"e":"trade","E":1788333209063,"s":"BTCUSDT","t":6646666481,"p":"77727.76000000","q":"0.02100000","T":1788333209062,"m":false,"M":true}}
{"type":"trade","received_at_ms":1788333208906,"data":{"e":"trade","E":1788333209063,"s":"BTCUSDT","t":6646666482,"p":"77727.76000000","q":"0.02100000","T":1788333209063,"m":false,"M":true}}
{"type":"trade","received_at_ms":1788333208906,"data":{"e":"trade","E":1788333209064,"s":"BTCUSDT","t":6646666483,"p":"77727.76000000","q":"0.02100000","T":1788333209063,"m":false,"M":true}}
{"type":"trade","received_at_ms":1788333208907,"data":{"e":"trade","E":1788333209064,"s":"BTCUSDT","t":6646666484,"p":"77727.76000000","q":"0.02100000","T":1788333209064,"m":false,"M":true}}
{"type":"trade","received_at_ms":1788333208911,"data":{"e":"trade","E":1788333209066,"s":"BTCUSDT","t":6646666485,"p":"77727.76000000","q":"0.00200000","T":1788333209066,"m":false,"M":true}}
{"type":"trade","received_at_ms":1788333208911,"data":{"e":"trade","E":1788333209068,"s":"BTCUSDT","t":6646666486,"p":"77727.76000000","q":"0.02100000","T":1788333209068,"m":false,"M":true}}
{"type":"trade","received_at_ms":1788333208953,"data":{"e":"trade","E":1788333209112,"s":"BTCUSDT","t":6646666487,"p":"77727.76000000","q":"0.00664000","T":1788333209112,"m":false,"M":true}}
{"type":"trade","received_at_ms":1788333208953,"data":{"e":"trade","E":1788333209112,"s":"BTCUSDT","t":6646666488,"p":"77727.76000000","q":"0.01436000","T":1788333209112,"m":false,"M":true}}
{"type":"depth","received_at_ms":1788333208953,"data":{"e":"depthUpdate","E":1788333209114,"s":"BTCUSDT","U":99556335961,"u":99556336086,"b":[["77727.75000000","4.22540000"],["77727.56000000","0.00014000"],["77727.55000000","0.05007000"],["77727.50000000","0.05000000"],["77727.45000000","0.00000000"],["77727.35000000","0.00014000"],["77726.53000000","0.00000000"],["77726.52000000","0.00257000"],["77725.99000000","0.50865000"],["77725.00000000","0.00000000"],["77724.02000000","0.00007000"],["77722.68000000","0.37338000"],["77720.46000000","0.00000000"],["77720.45000000","0.00000000"],["77720.33000000","0.01200000"],["69954.98000000","0.00256000"],["69954.96000000","0.00000000"],["69954.00000000","0.00008000"]],"a":[["77727.76000000","0.27965000"],["77736.84000000","0.00048000"]]}}
{"type":"depth","received_at_ms":1788333209046,"data":{"e":"depthUpdate","E":1788333209214,"s":"BTCUSDT","U":99556336087,"u":99556336115,"b":[["77727.75000000","4.22533000"],["77727.56000000","0.00000000"],["77727.55000000","0.00021000"],["77727.51000000","0.00014000"],["77727.50000000","0.00014000"],["77727.35000000","0.00000000"],["77724.99000000","0.30014000"],["77724.02000000","0.01207000"],["77720.33000000","0.00000000"],["62182.20000000","0.00000000"]],"a":[["77727.76000000","0.27979000"],["77743.82000000","0.00000000"],["77743.83000000","0.00257000"]]}}
{"type":"depth","received_at_ms":1788333209146,"data":{"e":"depthUpdate","E":1788333209314,"s":"BTCUSDT","U":99556336116,"u":99556336156,"b":[["77727.75000000","4.22790000"],["77727.55000000","0.00000000"],["77727.51000000","0.00000000"],["77727.50000000","0.00000000"],["77727.46000000","0.00000000"],["77727.45000000","0.00007000"],["77727.41000000","0.00014000"],["77727.40000000","0.00000000"],["77726.52000000","0.00000000"],["77725.71000000","0.00657000"],["77725.00000000","0.00000000"],["77724.99000000","0.30028000"],["69954.98000000","0.00272000"],["62182.20000000","0.00000000"]],"a":[["77736.24000000","0.00000000"],["77739.77000000","0.00000000"],["77740.67000000","0.18089000"]]}}
{"type":"depth","received_at_ms":1788333209247,"data":{"e":"depthUpdate","E":1788333209415,"s":"BTCUSDT","U":99556336157,"u":99556336174,"b":[["77727.75000000","4.22526000"],["77727.45000000","0.00000000"],["77727.41000000","0.00000000"],["77726.52000000","0.00257000"],["77725.00000000","0.00014000"],["77724.02000000","0.00007000"],["77720.26000000","0.01200000"],["69954.98000000","0.00272000"]],"a":[["77736.21000000","0.12097000"],["77758.17000000","0.00000000"]]}}
{"type":"depth","received_at_ms":1788333209347,"data":{"e":"depthUpdate","E":1788333209515,"s":"BTCUSDT","U":99556336175,"u":99556336192,"b":[["77724.99000000","0.30028000"],["77724.02000000","0.01207000"],["77720.26000000","0.00000000"],["77709.13000000","0.00014000"],["69954.98000000","0.00288000"],["62182.20000000","0.00032000"]],"a":[["77727.76000000","0.15768000"],["77740.23000000","0.00007000"],["77755.23000000","0.00411000"]]}}
{"type":"depth","received_at_ms":1788333209447,"data":{"e":"depthUpdate","E":1788333209614,"s":"BTCUSDT","U":99556336193,"u":99556336215,"b":[["77724.99000000","0.30028000"],["77704.00000000","0.03007000"],["69954.98000000","0.00320000"],["62182.20000000","0.00000000"],["62182.00000000","0.00000000"]],"a":[["77727.76000000","0.30164000"],["77743.83000000","0.00000000"],["77743.84000000","0.00257000"]]}}
{"type":"depth","received_at_ms":1788333209546,"data":{"e":"depthUpdate","E":1788333209714,"s":"BTCUSDT","U":99556336216,"u":99556336226,"b":[["77727.60000000","0.00000000"],["77658.07000000","0.02000000"],["77542.04000000","0.02015000"],["77511.73000000","0.00000000"],["69954.98000000","0.00320000"]],"a":[["77727.76000000","0.15768000"],["77758.27000000","0.12871000"],["78893.68000000","0.00030000"]]}}
{"type":"depth","received_at_ms":1788333209647,"data":{"e":"depthUpdate","E":1788333209814,"s":"BTCUSDT","U":99556336227,"u":99556336235,"b":[["77724.02000000","0.00007000"],["77720.45000000","0.00400000"],["69954.98000000","0.00336000"]],"a":[["77727.76000000","0.29475000"],["77758.24000000","0.00000000"],["77758.27000000","0.00000000"]]}}
{"type":"trade","received_at_ms":1788333209659,"data":{"e":"trade","E":1788333209827,"s":"BTCUSDT","t":6646666489,"p":"77727.75000000","q":"0.00662000","T":1788333209827,"m":true,"M":true}}
{"type":"depth","received_at_ms":1788333209747,"data":{"e":"depthUpdate","E":1788333209914,"s":"BTCUSDT","U":99556336236,"u":99556336266,"b":[["77727.75000000","4.21864000"],["77724.99000000","0.30028000"],["77724.02000000","0.00007000"],["77720.45000000","0.00400000"],["77700.69000000","0.04738000"],["77700.52000000","0.00000000"],["77674.33000000","0.00000000"],["76561.83000000","0.00030000"],["69954.98000000","0.00336000"],["69954.97000000","0.00009000"],["62179.00000000","0.01200000"]],"a":[["77737.56000000","0.00400000"],["77738.12000000","0.00400000"],["77738.17000000","0.00000000"],["77738.71000000","0.00000000"],["77740.63000000","0.01043000"],["77740.64000000","0.00400000"],["77755.23000000","0.00000000"],["77794.11000000","0.00377000"],["77806.52000000","0.56798000"],["77825.21000000","0.00419000"]]}}
{"type":"depth","received_at_ms":1788333209848,"data":{"e":"depthUpdate","E":1788333210014,"s":"BTCUSDT","U":99556336267,"u":99556336287,"b":[["77727.75000000","4.21871000"],["77727.46000000","0.00014000"],["77727.45000000","0.05007000"],["77727.40000000","0.05000000"],["77725.00000000","0.00000000"],["71506.07000000","0.00014000"],["69954.98000000","0.00352000"],["69954.00000000","0.00008000"],["62182.20000000","0.00032000"]],"a":[["77737.55000000","0.11436000"],["77743.84000000","0.00000000"],["77743.85000000","0.00257000"],["77757.68000000","0.00000000"],["86422.88000000","0.20801000"]]}}
{"type":"trade","received_at_ms":1788333209887,"data":{"e":"trade","E":1788333210052,"s":"BTCUSDT","t":6646666490,"p":"77727.76000000","q":"0.00007000","T":1788333210051,"m":false,"M":true}}
{"type":"trade","received_at_ms":1788333209887,"data":{"e":"trade","E":1788333210052,"s":"BTCUSDT","t":6646666491,"p":"77727.76000000","q":"0.00023000","T":1788333210051,"m":false,"M":true}}
{"type":"trade","received_at_ms":1788333209887,"data":{"e":"trade","E":1788333210052,"s":"BTCUSDT","t":6646666492,"p":"77727.76000000","q":"0.00013000","T":1788333210051,"m":false,"M":true}}
{"type":"trade","received_at_ms":1788333209887,"data":{"e":"trade","E":1788333210052,"s":"BTCUSDT","t":6646666493,"p":"77727.76000000","q":"0.00150000","T":1788333210051,"m":false,"M":true}}
{"type":"depth","received_at_ms":1788333209947,"data":{"e":"depthUpdate","E":1788333210114,"s":"BTCUSDT","U":99556336288,"u":99556336327,"b":[["77727.75000000","4.21901000"],["77727.51000000","0.00014000"],["77727.50000000","0.05007000"],["77727.46000000","0.00000000"],["77727.45000000","0.00014000"],["77727.40000000","0.00000000"],["77727.35000000","0.05000000"],["77724.99000000","0.30014000"],["77724.02000000","0.00407000"],["77720.45000000","0.00000000"],["69954.98000000","0.00336000"],["69954.00000000","0.00018000"]],"a":[["77727.76000000","0.22414000"],["77735.91000000","0.20255000"],["77736.21000000","0.00000000"],["77738.12000000","0.00000000"],["77739.05000000","0.00400000"],["77740.63000000","0.00400000"],["77741.33000000","0.00643000"],["77821.72000000","0.00000000"],["77824.31000000","4.08551000"],["86422.88000000","0.22692000"]]}}
{"type":"trade","received_at_ms":1788333209956,"data":{"e":"trade","E":1788333210122,"s":"BTCUSDT","t":6646666494,"p":"77727.76000000","q":"0.00200000","T":1788333210122,"m":false,"M":true}}
{"type":"trade","received_at_ms":1788333209956,"data":{"e":"trade","E":1788333210122,"s":"BTCUSDT","t":6646666495,"p":"77727.76000000","q":"0.00200000","T":1788333210122,"m":false,"M":true}}
{"type":"trade","received_at_ms":1788333209956,"data":{"e":"trade","E":1788333210122,"s":"BTCUSDT","t":6646666496,"p":"77727.76000000","q":"0.00200000","T":1788333210122,"m":false,"M":true}}
{"type":"trade","received_at_ms":1788333209957,"data":{"e":"trade","E":1788333210123,"s":"BTCUSDT","t":6646666497,"p":"77727.76000000","q":"0.00200000","T":1788333210122,"m":false,"M":true}}
{"type":"trade","received_at_ms":1788333209957,"data":{"e":"trade","E":1788333210123,"s":"BTCUSDT","t":6646666498,"p":"77727.76000000","q":"0.00200000","T":1788333210122,"m":false,"M":true}}
{"type":"trade","received_at_ms":1788333209957,"data":{"e":"trade","E":1788333210123,"s":"BTCUSDT","t":6646666499,"p":"77727.76000000","q":"0.00200000","T":1788333210123,"m":false,"M":true}}
{"type":"trade","received_at_ms":1788333209957,"data":{"e":"trade","E":1788333210123,"s":"BTCUSDT","t":6646666500,"p":"77727.76000000","q":"0.00200000","T":1788333210123,"m":false,"M":true}}
{"type":"trade","received_at_ms":1788333209957,"data":{"e":"trade","E":1788333210124,"s":"BTCUSDT","t":6646666501,"p":"77727.76000000","q":"0.00200000","T":1788333210123,"m":false,"M":true}}
{"type":"trade","received_at_ms":1788333209957,"data":{"e":"trade","E":1788333210124,"s":"BTCUSDT","t":6646666502,"p":"77727.76000000","q":"0.00200000","T":1788333210123,"m":false,"M":true}}
{"type":"trade","received_at_ms":1788333209957,"data":{"e":"trade","E":1788333210124,"s":"BTCUSDT","t":6646666503,"p":"77727.76000000","q":"0.00200000","T":1788333210123,"m":false,"M":true}}
{"type":"trade","received_at_ms":1788333209957,"data":{"e":"trade","E":1788333210124,"s":"BTCUSDT","t":6646666504,"p":"77727.76000000","q":"0.00200000","T":1788333210123,"m":false,"M":true}}
{"type":"trade","received_at_ms":1788333209957,"data":{"e":"trade","E":1788333210124,"s":"BTCUSDT","t":6646666505,"p":"77727.76000000","q":"0.00200000","T":1788333210123,"m":false,"M":true}}
{"type":"trade","received_at_ms":1788333209957,"data":{"e":"trade","E":1788333210124,"s":"BTCUSDT","t":6646666506,"p":"77727.76000000","q":"0.00200000","T":1788333210123,"m":false,"M":true}}
{"type":"trade","received_at_ms":1788333209958,"data":{"e":"trade","E":1788333210124,"s":"BTCUSDT","t":6646666507,"p":"77727.76000000","q":"0.00200000","T":1788333210124,"m":false,"M":true}}
{"type":"trade","received_at_ms":1788333209959,"data":{"e":"trade","E":1788333210125,"s":"BTCUSDT","t":6646666508,"p":"77727.75000000","q":"0.00019000","T":1788333210125,"m":true,"M":true}}
{"type":"trade","received_at_ms":1788333209959,"data":{"e":"trade","E":1788333210125,"s":"BTCUSDT","t":6646666509,"p":"77727.76000000","q":"0.00200000","T":1788333210125,"m":false,"M":true}}
{"type":"trade","received_at_ms":1788333209959,"data":{"e":"trade","E":1788333210125,"s":"BTCUSDT","t":6646666510,"p":"77727.76000000","q":"0.00200000","T":1788333210125,"m":false,"M":true}}
{"type":"trade","received_at_ms":1788333209959,"data":{"e":"trade","E":1788333210125,"s":"BTCUSDT","t":6646666511,"p":"77727.76000000","q":"0.00200000","T":1788333210125,"m":false,"M":true}}
{"type":"trade","received_at_ms":1788333209959,"data":{"e":"trade","E":1788333210126,"s":"BTCUSDT","t":6646666512,"p":"77727.76000000","q":"0.00200000","T":1788333210125,"m":false,"M":true}}
{"type":"trade","received_at_ms":1788333209959,"data":{"e":"trade","E":1788333210126,"s":"BTCUSDT","t":6646666513,"p":"77727.76000000","q":"0.02100000","T":1788333210126,"m":false,"M":true}}
{"type":"trade","received_at_ms":1788333209980,"data":{"e":"trade","E":1788333210147,"s":"BTCUSDT","t":6646666514,"p":"77727.76000000","q":"0.00200000","T":1788333210146,"m":false,"M":true}}
{"type":"trade","received_at_ms":1788333209980,"data":{"e":"trade","E":1788333210147,"s":"BTCUSDT","t":6646666515,"p":"77727.76000000","q":"0.00200000","T":1788333210146,"m":false,"M":true}}
{"type":"trade","received_at_ms":1788333209980,"data":{"e":"trade","E":1788333210147,"s":"BTCUSDT","t":6646666516,"p":"77727.76000000","q":"0.00200000","T":1788333210147,"m":false,"M":true}}
{"type":"trade","received_at_ms":1788333209980,"data":{"e":"trade","E":1788333210147,"s":"BTCUSDT","t":6646666517,"p":"77727.76000000","q":"0.00200000","T":1788333210147,"m":false,"M":true}}
{"type":"trade","received_at_ms":1788333209981,"data":{"e":"trade","E":1788333210147,"s":"BTCUSDT","t":6646666518,"p":"77727.76000000","q":"0.00200000","T":1788333210147,"m":false,"M":true}}
{"type":"trade","received_at_ms":1788333209981,"data":{"e":"trade","E":1788333210147,"s":"BTCUSDT","t":6646666519,"p":"77727.76000000","q":"0.00200000","T":1788333210147,"m":false,"M":true}}
{"type":"trade","received_at_ms":1788333209981,"data":{"e":"trade","E":1788333210147,"s":"BTCUSDT","t":6646666520,"p":"77727.76000000","q":"0.00200000","T":1788333210147,"m":false,"M":true}}
{"type":"trade","received_at_ms":1788333209981,"data":{"e":"trade","E":1788333210148,"s":"BTCUSDT","t":6646666521,"p":"77727.76000000","q":"0.00200000","T":1788333210147,"m":false,"M":true}}
{"type":"trade","received_at_ms":1788333209981,"data":{"e":"trade","E":1788333210148,"s":"BTCUSDT","t":6646666522,"p":"77727.76000000","q":"0.00200000","T":1788333210147,"m":false,"M":true}}
{"type":"trade","received_at_ms":1788333209981,"data":{"e":"trade","E":1788333210148,"s":"BTCUSDT","t":6646666523,"p":"77727.76000000","q":"0.00200000","T":1788333210147,"m":false,"M":true}}
{"type":"trade","received_at_ms":1788333209981,"data":{"e":"trade","E":1788333210148,"s":"BTCUSDT","t":6646666524,"p":"77727.76000000","q":"0.00200000","T":1788333210147,"m":false,"M":true}}
{"type":"trade","received_at_ms":1788333209981,"data":{"e":"trade","E":1788333210148,"s":"BTCUSDT","t":6646666525,"p":"77727.76000000","q":"0.00200000","T":1788333210147,"m":false,"M":true}}
{"type":"trade","received_at_ms":1788333209981,"data":{"e":"trade","E":1788333210148,"s":"BTCUSDT","t":6646666526,"p":"77727.76000000","q":"0.00200000","T":1788333210147,"m":false,"M":true}}
{"type":"trade","received_at_ms":1788333209981,"data":{"e":"trade","E":1788333210148,"s":"BTCUSDT","t":6646666527,"p":"77727.76000000","q":"0.00200000","T":1788333210147,"m":false,"M":true}}
{"type":"trade","received_at_ms":1788333209981,"data":{"e":"trade","E":1788333210148,"s":"BTCUSDT","t":6646666528,"p":"77727.76000000","q":"0.00200000","T":1788333210147,"m":false,"M":true}}
{"type":"trade","received_at_ms":1788333209984,"data":{"e":"trade","E":1788333210149,"s":"BTCUSDT","t":6646666529,"p":"77727.76000000","q":"0.00200000","T":1788333210149,"m":false,"M":true}}
{"type":"trade","received_at_ms":1788333209984,"data":{"e":"trade","E":1788333210149,"s":"BTCUSDT","t":6646666530,"p":"77727.76000000","q":"0.00200000","T":1788333210149,"m":false,"M":true}}
{"type":"trade","received_at_ms":1788333209984,"data":{"e":"trade","E":1788333210149,"s":"BTCUSDT","t":6646666531,"p":"77727.76000000","q":"0.00200000","T":1788333210149,"m":false,"M":true}}
{"type":"trade","received_at_ms":1788333209986,"data":{"e":"trade","E":1788333210150,"s":"BTCUSDT","t":6646666532,"p":"77727.76000000","q":"0.02100000","T":1788333210150,"m":false,"M":true}}
{"type":"trade","received_at_ms":1788333209986,"data":{"e":"trade","E":1788333210150,"s":"BTCUSDT","t":6646666533,"p":"77727.76000000","q":"0.01649000","T":1788333210150,"m":false,"M":true}}
{"type":"trade","received_at_ms":1788333209986,"data":{"e":"trade","E":1788333210150,"s":"BTCUSDT","t":6646666534,"p":"77727.76000000","q":"0.00007000","T":1788333210150,"m":false,"M":true}}
{"type":"trade","received_at_ms":1788333209986,"data":{"e":"trade","E":1788333210150,"s":"BTCUSDT","t":6646666535,"p":"77727.76000000","q":"0.00007000","T":1788333210150,"m":false,"M":true}}
{"type":"trade","received_at_ms":1788333209986,"data":{"e":"trade","E":1788333210150,"s":"BTCUSDT","t":6646666536,"p":"77727.76000000","q":"0.00007000","T":1788333210150,"m":false,"M":true}}
{"type":"trade","received_at_ms":1788333209986,"data":{"e":"trade","E":1788333210150,"s":"BTCUSDT","t":6646666537,"p":"77727.76000000","q":"0.00007000","T":1788333210150,"m":false,"M":true}}
{"type":"trade","received_at_ms":1788333209986,"data":{"e":"trade","E":1788333210150,"s":"BTCUSDT","t":6646666538,"p":"77727.76000000","q":"0.00007000","T":1788333210150,"m":false,"M":true}}
{"type":"trade","received_at_ms":1788333209986,"data":{"e":"trade","E":1788333210150,"s":"BTCUSDT","t":6646666539,"p":"77727.76000000","q":"0.00007000","T":1788333210150,"m":false,"M":true}}
{"type":"trade","received_at_ms":1788333209986,"data":{"e":"trade","E":1788333210150,"s":"BTCUSDT","t":6646666540,"p":"77727.76000000","q":"0.00007000","T":1788333210150,"m":false,"M":true}}
{"type":"trade","received_at_ms":1788333209986,"data":{"e":"trade","E":1788333210150,"s":"BTCUSDT","t":6646666541,"p":"77727.76000000","q":"0.00007000","T":1788333210150,"m":false,"M":true}}
{"type":"trade","received_at_ms":1788333209986,"data":{"e":"trade","E":1788333210150,"s":"BTCUSDT","t":6646666542,"p":"77727.76000000","q":"0.00008000","T":1788333210150,"m":false,"M":true}}
{"type":"trade","received_at_ms":1788333209986,"data":{"e":"trade","E":1788333210150,"s":"BTCUSDT","t":6646666543,"p":"77727.76000000","q":"0.00007000","T":1788333210150,"m":false,"M":true}}
{"type":"trade","received_at_ms":1788333209986,"data":{"e":"trade","E":1788333210150,"s":"BTCUSDT","t":6646666544,"p":"77727.76000000","q":"0.00380000","T":1788333210150,"m":false,"M":true}}
{"type":"trade","received_at_ms":1788333209986,"data":{"e":"trade","E":1788333210151,"s":"BTCUSDT","t":6646666545,"p":"77727.76000000","q":"0.00009000","T":1788333210150,"m":false,"M":true}}
{"type":"trade","received_at_ms":1788333209986,"data":{"e":"trade","E":1788333210151,"s":"BTCUSDT","t":6646666546,"p":"77727.76000000","q":"0.00007000","T":1788333210150,"m":false,"M":true}}
{"type":"trade","received_at_ms":1788333209986,"data":{"e":"trade","E":1788333210151,"s":"BTCUSDT","t":6646666547,"p":"77727.76000000","q":"0.00007000","T":1788333210150,"m":false,"M":true}}
{"type":"trade","received_at_ms":1788333209986,"data":{"e":"trade","E":1788333210151,"s":"BTCUSDT","t":6646666548,"p":"77727.76000000","q":"0.00007000","T":1788333210150,"m":false,"M":true}}
{"type":"trade","received_at_ms":1788333209986,"data":{"e":"trade","E":1788333210151,"s":"BTCUSDT","t":6646666549,"p":"77727.76000000","q":"0.00007000","T":1788333210150,"m":false,"M":true}}
{"type":"trade","received_at_ms":1788333209986,"data":{"e":"trade","E":1788333210151,"s":"BTCUSDT","t":6646666550,"p":"77727.76000000","q":"0.00007000","T":1788333210150,"m":false,"M":true}}
{"type":"trade","received_at_ms":1788333209986,"data":{"e":"trade","E":1788333210151,"s":"BTCUSDT","t":6646666551,"p":"77727.76000000","q":"0.00007000","T":1788333210150,"m":false,"M":true}}
{"type":"trade","received_at_ms":1788333209986,"data":{"e":"trade","E":1788333210151,"s":"BTCUSDT","t":6646666552,"p":"77727.76000000","q":"0.00007000","T":1788333210150,"m":false,"M":true}}
{"type":"trade","received_at_ms":1788333209986,"data":{"e":"trade","E":1788333210151,"s":"BTCUSDT","t":6646666553,"p":"77727.76000000","q":"0.00007000","T":1788333210150,"m":false,"M":true}}
{"type":"trade","received_at_ms":1788333209986,"data":{"e":"trade","E":1788333210151,"s":"BTCUSDT","t":6646666554,"p":"77727.76000000","q":"0.00150000","T":1788333210150,"m":false,"M":true}}
{"type":"trade","received_at_ms":1788333209986,"data":{"e":"trade","E":1788333210151,"s":"BTCUSDT","t":6646666555,"p":"77727.76000000","q":"0.00070000","T":1788333210150,"m":false,"M":true}}
{"type":"trade","received_at_ms":1788333209986,"data":{"e":"trade","E":1788333210151,"s":"BTCUSDT","t":6646666556,"p":"77727.76000000","q":"0.00014000","T":1788333210150,"m":false,"M":true}}
{"type":"trade","received_at_ms":1788333209986,"data":{"e":"trade","E":1788333210151,"s":"BTCUSDT","t":6646666557,"p":"77727.76000000","q":"0.00350000","T":1788333210150,"m":false,"M":true}}
{"type":"trade","received_at_ms":1788333209986,"data":{"e":"trade","E":1788333210151,"s":"BTCUSDT","t":6646666558,"p":"77727.76000000","q":"0.00003000","T":1788333210150,"m":false,"M":true}}
{"type":"trade","received_at_ms":1788333209986,"data":{"e":"trade","E":1788333210151,"s":"BTCUSDT","t":6646666559,"p":"77727.76000000","q":"0.00013000","T":1788333210150,"m":false,"M":true}}
{"type":"trade","received_at_ms":1788333209986,"data":{"e":"trade","E":1788333210151,"s":"BTCUSDT","t":6646666560,"p":"77727.76000000","q":"0.01435000","T":1788333210150,"m":false,"M":true}}
{"type":"trade","received_at_ms":1788333209986,"data":{"e":"trade","E":1788333210152,"s":"BTCUSDT","t":6646666561,"p":"77727.76000000","q":"0.02100000","T":1788333210151,"m":false,"M":true}}
{"type":"trade","received_at_ms":1788333209987,"data":{"e":"trade","E":1788333210152,"s":"BTCUSDT","t":6646666562,"p":"77727.76000000","q":"0.02100000","T":1788333210152,"m":false,"M":true}}
{"type":"trade","received_at_ms":1788333209987,"data":{"e":"trade","E":1788333210152,"s":"BTCUSDT","t":6646666563,"p":"77727.76000000","q":"0.01165000","T":1788333210152,"m":false,"M":true}}
{"type":"trade","received_at_ms":1788333209987,"data":{"e":"trade","E":1788333210152,"s":"BTCUSDT","t":6646666564,"p":"77727.76000000","q":"0.00007000","T":1788333210152,"m":false,"M":true}}
{"type":"trade","received_at_ms":1788333209987,"data":{"e":"trade","E":1788333210152,"s":"BTCUSDT","t":6646666565,"p":"77727.76000000","q":"0.00008000","T":1788333210152,"m":false,"M":true}}
{"type":"trade","received_at_ms":1788333209987,"data":{"e":"trade","E":1788333210152,"s":"BTCUSDT","t":6646666566,"p":"77727.76000000","q":"0.00007000","T":1788333210152,"m":false,"M":true}}
{"type":"trade","received_at_ms":1788333209987,"data":{"e":"trade","E":1788333210152,"s":"BTCUSDT","t":6646666567,"p":"77727.76000000","q":"0.00007000","T":1788333210152,"m":false,"M":true}}
{"type":"trade","received_at_ms":1788333209987,"data":{"e":"trade","E":1788333210152,"s":"BTCUSDT","t":6646666568,"p":"77727.76000000","q":"0.00007000","T":1788333210152,"m":false,"M":true}}
{"type":"trade","received_at_ms":1788333209987,"data":{"e":"trade","E":1788333210152,"s":"BTCUSDT","t":6646666569,"p":"77727.76000000","q":"0.00350000","T":1788333210152,"m":false,"M":true}}
{"type":"trade","received_at_ms":1788333209987,"data":{"e":"trade","E":1788333210152,"s":"BTCUSDT","t":6646666570,"p":"77727.76000000","q":"0.00007000","T":1788333210152,"m":false,"M":true}}
{"type":"trade","received_at_ms":1788333209987,"data":{"e":"trade","E":1788333210152,"s":"BTCUSDT","t":6646666571,"p":"77727.76000000","q":"0.00013000","T":1788333210152,"m":false,"M":true}}
{"type":"trade","received_at_ms":1788333209987,"data":{"e":"trade","E":1788333210152,"s":"BTCUSDT","t":6646666572,"p":"77727.76000000","q":"0.00007000","T":1788333210152,"m":false,"M":true}}
{"type":"trade","received_at_ms":1788333209987,"data":{"e":"trade","E":1788333210152,"s":"BTCUSDT","t":6646666573,"p":"77727.76000000","q":"0.00007000","T":1788333210152,"m":false,"M":true}}
{"type":"trade","received_at_ms":1788333209987,"data":{"e":"trade","E":1788333210152,"s":"BTCUSDT","t":6646666574,"p":"77727.76000000","q":"0.00007000","T":1788333210152,"m":false,"M":true}}
{"type":"trade","received_at_ms":1788333209987,"data":{"e":"trade","E":1788333210152,"s":"BTCUSDT","t":6646666575,"p":"77727.76000000","q":"0.00007000","T":1788333210152,"m":false,"M":true}}
{"type":"trade","received_at_ms":1788333209987,"data":{"e":"trade","E":1788333210152,"s":"BTCUSDT","t":6646666576,"p":"77727.76000000","q":"0.00501000","T":1788333210152,"m":false,"M":true}}
{"type":"trade","received_at_ms":1788333209987,"data":{"e":"trade","E":1788333210153,"s":"BTCUSDT","t":6646666577,"p":"77727.76000000","q":"0.02100000","T":1788333210153,"m":false,"M":true}}
{"type":"depth","received_at_ms":1788333210048,"data":{"e":"depthUpdate","E":1788333210214,"s":"BTCUSDT","U":99556336328,"u":99556336515,"b":[["77727.75000000","3.49066000"],["77727.51000000","0.00000000"],["77727.50000000","0.00014000"],["77727.45000000","0.00000000"],["77727.35000000","0.00000000"],["77726.52000000","0.00257000"],["77726.00000000","0.33002000"],["77725.00000000","0.00014000"],["77724.02000000","0.37752000"],["77723.99000000","0.40443000"],["77723.39000000","0.00051000"],["77722.74000000","0.00000000"],["77722.68000000","0.00000000"],["77720.33000000","0.00000000"],["77719.43000000","0.00260000"],["77630.77000000","0.13878000"],["77028.20000000","0.00032000"],["69954.98000000","0.00368000"],["69954.97000000","0.00000000"],["69954.96000000","0.00009000"],["69954.00000000","0.00008000"],["62182.20000000","0.00000000"]],"a":[["77727.76000000","0.10167000"],["77727.77000000","0.00076000"],["77729.15000000","0.00000000"],["77729.16000000","0.00014000"],["77729.45000000","0.00000000"],["77729.46000000","0.00014000"],["77730.21000000","0.00014000"],["77730.83000000","0.00007000"],["77734.50000000","0.00000000"],["77734.68000000","0.00000000"],["77734.84000000","0.00000000"],["77734.96000000","0.00000000"],["77735.88000000","0.11436000"],["77737.38000000","0.00069000"],["77738.82000000","0.00400000"],["77739.05000000","0.00000000"],["77743.53000000","0.00000000"],["77743.85000000","0.00000000"],["77745.50000000","0.00264000"],["77757.60000000","0.00000000"],["77758.22000000","0.12871000"],["77759.02000000","0.00000000"],["77761.25000000","0.00000000"],["77821.69000000","0.00000000"],["77824.32000000","0.00094000"]]}}
{"type":"depth","received_at_ms":1788333210147,"data":{"e":"depthUpdate","E":1788333210314,"s":"BTCUSDT","U":99556336516,"u":99556336566,"b":[["77727.75000000","3.49059000"],["77727.60000000","0.05000000"],["77727.55000000","0.05000000"],["77727.50000000","0.00000000"],["77724.99000000","0.30028000"],["77724.03000000","0.00000000"],["77724.02000000","0.37352000"],["77674.33000000","0.00411000"],["69954.98000000","0.00368000"],["62182.20000000","0.00000000"],["62182.00000000","0.00000000"]],"a":[["77727.76000000","0.25786000"],["77728.40000000","0.13826000"],["77729.16000000","0.00000000"],["77729.46000000","0.00000000"],["77731.76000000","0.11205000"],["77731.99000000","0.19262000"],["77747.18000000","0.00000000"],["77748.40000000","0.00128000"],["77758.22000000","0.00000000"],["84202.54000000","0.01768000"]]}}
{"type":"depth","received_at_ms":1788333210246,"data":{"e":"depthUpdate","E":1788333210414,"s":"BTCUSDT","U":99556336567,"u":99556336620,"b":[["77727.75000000","3.50066000"],["77727.61000000","0.00014000"],["77727.60000000","0.05014000"],["77727.56000000","0.00000000"],["77727.55000000","0.00000000"],["77725.00000000","0.00000000"],["77724.99000000","0.30021000"],["77724.03000000","0.00800000"],["77724.02000000","0.37345000"],["77720.33000000","0.00000000"],["77603.39000000","0.00064000"],["69954.98000000","0.00368000"],["62182.00000000","0.00000000"]],"a":[["77727.76000000","0.25800000"],["77727.77000000","0.00083000"],["77729.15000000","0.00014000"],["77729.16000000","0.11436000"],["77730.56000000","0.11436000"],["77730.83000000","0.00000000"],["77740.66000000","0.01000000"],["77745.48000000","0.00257000"],["77745.50000000","0.00007000"]]}}
{"type":"depth","received_at_ms":1788333210347,"data":{"e":"depthUpdate","E":1788333210514,"s":"BTCUSDT","U":99556336621,"u":99556336659,"b":[["77727.60000000","0.05014000"],["77724.99000000","0.30014000"],["77724.03000000","0.00800000"],["77723.99000000","0.40450000"],["77720.33000000","0.00000000"],["77709.13000000","0.00014000"],["71506.07000000","0.00000000"],["69954.98000000","0.00384000"],["69954.00000000","0.00018000"],["62182.20000000","0.00032000"]],"a":[["77728.40000000","0.13826000"],["77729.16000000","0.11450000"],["77730.52000000","0.01280000"],["77730.56000000","0.11450000"],["77731.76000000","0.11191000"],["77731.99000000","0.19248000"],["77740.23000000","0.00007000"],["77757.93000000","0.00000000"]]}}
{"type":"depth","received_at_ms":1788333210454,"data":{"e":"depthUpdate","E":1788333210614,"s":"BTCUSDT","U":99556336660,"u":99556336698,"b":[["77724.99000000","0.30014000"],["77724.03000000","0.00000000"],["77723.99000000","0.40443000"],["77720.33000000","0.00800000"],["77720.26000000","0.00000000"],["77717.19000000","0.00000000"],["77705.89000000","0.00000000"],["70400.00000000","2.11344000"],["69954.98000000","0.00400000"],["69954.00000000","0.00008000"],["62182.20000000","0.00000000"],["62182.00000000","0.00000000"]],"a":[["77727.76000000","0.25281000"],["77745.45000000","0.00257000"],["77745.48000000","0.00000000"],["77758.08000000","0.12871000"],["77821.72000000","2.15325000"],["77824.31000000","1.93226000"]]}}
{"type":"depth","received_at_ms":1788333210557,"data":{"e":"depthUpdate","E":1788333210714,"s":"BTCUSDT","U":99556336699,"u":99556336719,"b":[["77727.60000000","0.00014000"],["77727.55000000","0.05000000"],["77724.99000000","0.30021000"],["77724.03000000","0.01200000"],["77723.99000000","0.40443000"],["77720.33000000","0.00000000"],["77564.58000000","0.00064000"],["69954.98000000","0.00400000"]],"a":[["77745.43000000","0.00265000"],["77745.45000000","0.00000000"],["77757.66000000","0.02036000"],["77758.08000000","0.00000000"],["77759.09000000","0.09778000"],["77761.31000000","0.05361000"],["78893.68000000","0.00030000"]]}}
{"type":"trade","received_at_ms":1788333210593,"data":{"e":"trade","E":1788333210760,"s":"BTCUSDT","t":6646666578,"p":"77727.76000000","q":"0.00007000","T":1788333210760,"m":false,"M":true}}
{"type":"depth","received_at_ms":1788333210646,"data":{"e":"depthUpdate","E":1788333210814,"s":"BTCUSDT","U":99556336720,"u":99556336772,"b":[["77727.75000000","3.50066000"],["77727.61000000","0.00000000"],["77727.60000000","0.00000000"],["77727.56000000","0.00000000"],["77727.55000000","0.00014000"],["77725.00000000","0.00014000"],["77724.99000000","0.30021000"],["77724.04000000","0.01200000"],["77724.03000000","0.00000000"],["77723.99000000","0.40443000"],["77720.33000000","0.00000000"],["77705.13000000","0.48977000"],["69954.98000000","0.00416000"],["69954.96000000","0.00000000"]],"a":[["77727.76000000","0.25274000"],["77745.42000000","0.00257000"],["77745.43000000","0.00008000"]]}}
{"type":"depth","received_at_ms":1788333210748,"data":{"e":"depthUpdate","E":1788333210915,"s":"BTCUSDT","U":99556336773,"u":99556336790,"b":[["77727.75000000","3.50059000"],["77727.55000000","0.00000000"],["77724.99000000","0.30035000"],["77717.37000000","0.09237000"],["76561.83000000","0.00030000"],["69954.98000000","0.00416000"],["69954.00000000","0.00018000"]],"a":[["77745.42000000","0.00000000"],["77746.22000000","0.00000000"],["77852.11000000","0.00095000"]]}}
{"type":"depth","received_at_ms":1788333210847,"data":{"e":"depthUpdate","E":1788333211014,"s":"BTCUSDT","U":99556336791,"u":99556336806,"b":[["77727.35000000","0.05000000"],["77727.30000000","0.05000000"],["75557.14000000","0.00000000"],["69954.98000000","0.00432000"],["69954.00000000","0.00018000"],["62182.20000000","0.00032000"],["62182.00000000","0.00000000"]],"a":[["77745.39000000","0.00257000"],["77745.40000000","0.00000000"],["77756.99000000","0.00000000"],["81001.15000000","0.00328000"]]}}
{"type":"depth","received_at_ms":1788333210946,"data":{"e":"depthUpdate","E":1788333211114,"s":"BTCUSDT","U":99556336807,"u":99556336835,"b":[["77727.75000000","3.50330000"],["77727.40000000","0.05000000"],["77727.36000000","0.00014000"],["77727.35000000","0.05014000"],["77727.30000000","0.00000000"],["77726.52000000","0.00000000"],["77725.00000000","0.00000000"],["77724.99000000","0.30021000"],["77674.38000000","0.25736000"],["77665.97000000","0.00000000"],["69954.98000000","0.00448000"],["69954.00000000","0.00008000"]],"a":[["77727.76000000","0.10317000"],["77745.38000000","0.00257000"],["77745.39000000","0.00000000"],["77794.11000000","0.00788000"],["77891.03000000","0.00095000"]]}}
{"type":"depth","received_at_ms":1788333211047,"data":{"e":"depthUpdate","E":1788333211214,"s":"BTCUSDT","U":99556336836,"u":99556336858,"b":[["77727.75000000","3.50330000"],["77727.40000000","0.00014000"],["77727.36000000","0.00000000"],["77727.35000000","0.00000000"],["77727.31000000","0.00014000"],["77727.30000000","0.05000000"],["77028.20000000","0.00042000"],["69954.98000000","0.00448000"],["62182.20000000","0.00000000"]],"a":[["77727.76000000","0.10317000"]]}}
{"type":"depth","received_at_ms":1788333211148,"data":{"e":"depthUpdate","E":1788333211314,"s":"BTCUSDT","U":99556336859,"u":99556336889,"b":[["77727.75000000","3.50323000"],["77727.40000000","0.00000000"],["77727.31000000","0.00000000"],["77727.30000000","0.00014000"],["77725.00000000","0.00014000"],["77714.00000000","0.70008000"],["77699.00000000","0.00000000"],["69954.98000000","0.00464000"],["69954.00000000","0.00008000"],["62182.20000000","0.00000000"]],"a":[["77727.76000000","0.10317000"],["77737.56000000","0.00000000"],["77738.23000000","0.00400000"],["77745.34000000","0.00257000"],["77745.38000000","0.00000000"],["77756.85000000","0.00000000"]]}}
{"type":"trade","received_at_ms":1788333211219,"data":{"e":"trade","E":1788333211386,"s":"BTCUSDT","t":6646666579,"p":"77727.76000000","q":"0.01500000","T":1788333211386,"m":false,"M":true}}
{"type":"depth","received_at_ms":1788333211247,"data":{"e":"depthUpdate","E":1788333211414,"s":"BTCUSDT","U":99556336890,"u":99556336916,"b":[["77727.75000000","3.50323000"],["77727.61000000","0.00014000"],["77727.60000000","0.05000000"],["77727.50000000","0.00000000"],["77727.30000000","0.00000000"],["77725.00000000","0.00000000"],["77724.99000000","0.30035000"],["69954.98000000","0.00457000"],["62182.00000000","0.00000000"]],"a":[["77727.76000000","0.08827000"],["77745.31000000","0.00257000"],["77745.34000000","0.00000000"]]}}
{"type":"depth","received_at_ms":1788333211347,"data":{"e":"depthUpdate","E":1788333211514,"s":"BTCUSDT","U":99556336917,"u":99556336943,"b":[["77727.75000000","3.50316000"],["77727.61000000","0.00000000"],["77727.60000000","0.00000000"],["77725.00000000","0.00014000"],["77710.52000000","0.00000000"],["77709.13000000","0.00014000"],["77674.33000000","0.00000000"],["77640.49000000","0.00000000"],["69954.98000000","0.00473000"],["62182.20000000","0.00032000"],["62182.00000000","0.00000000"]],"a":[["77740.23000000","0.00007000"],["77755.23000000","0.00411000"],["77794.11000000","0.00377000"],["77821.72000000","0.00000000"],["77824.31000000","4.08551000"],["77825.21000000","0.00008000"]]}}
{"type":"depth","received_at_ms":1788333211448,"data":{"e":"depthUpdate","E":1788333211615,"s":"BTCUSDT","U":99556336944,"u":99556336956,"b":[["77727.75000000","3.50316000"],["77549.59000000","0.00000000"],["69954.98000000","0.00457000"],["62182.20000000","0.00000000"]],"a":[["77745.27000000","0.00257000"],["77745.31000000","0.00000000"]]}}
{"type":"trade","received_at_ms":1788333211518,"data":{"e":"trade","E":1788333211685,"s":"BTCUSDT","t":6646666580,"p":"77727.76000000","q":"0.02547000","T":1788333211684,"m":false,"M":true}}
{"type":"depth","received_at_ms":1788333211546,"data":{"e":"depthUpdate","E":1788333211714,"s":"BTCUSDT","U":99556336957,"u":99556336976,"b":[["77727.75000000","3.51716000"],["77727.20000000","0.00400000"],["77725.99000000","0.50065000"],["77724.04000000","0.00400000"],["77724.03000000","0.00800000"],["77644.14000000","0.00411000"],["69954.98000000","0.00448000"],["69954.97000000","0.00009000"]],"a":[["77727.76000000","0.06280000"],["77745.24000000","0.00257000"],["77745.27000000","0.00000000"],["77755.92000000","0.00000000"],["78893.68000000","0.00030000"]]}}
{"type":"depth","received_at_ms":1788333211647,"data":{"e":"depthUpdate","E":1788333211815,"s":"BTCUSDT","U":99556336977,"u":99556336987,"b":[["77727.75000000","3.51723000"],["77727.55000000","0.05000000"],["77724.99000000","0.30042000"],["69954.98000000","0.00448000"]],"a":[["77745.22000000","0.00257000"],["77745.24000000","0.00000000"]]}}
{"type":"depth","received_at_ms":1788333211748,"data":{"e":"depthUpdate","E":1788333211915,"s":"BTCUSDT","U":99556336988,"u":99556337002,"b":[["77727.75000000","3.51716000"],["77727.55000000","0.00000000"],["77549.91000000","4.46122000"],["77530.01000000","0.00000000"],["77528.01000000","0.00811000"],["76561.83000000","0.00000000"],["75557.14000000","0.00010000"],["69954.98000000","0.00464000"]],"a":[["77745.22000000","0.00000000"],["77795.00000000","0.00411000"]]}}
{"type":"trade","received_at_ms":1788333211847,"data":{"e":"trade","E":1788333212014,"s":"BTCUSDT","t":6646666581,"p":"77727.76000000","q":"0.00035000","T":1788333212013,"m":false,"M":true}}
{"type":"depth","received_at_ms":1788333211847,"data":{"e":"depthUpdate","E":1788333212014,"s":"BTCUSDT","U":99556337003,"u":99556337022,"b":[["77727.75000000","3.51716000"],["76561.83000000","0.00030000"],["69954.98000000","0.00432000"],["62182.20000000","0.00032000"]],"a":[["77727.76000000","0.06245000"],["77734.24000000","0.00206000"],["77734.25000000","0.08205000"],["77738.82000000","0.00000000"],["77739.49000000","0.00400000"],["77743.21000000","0.00257000"],["77745.20000000","0.00000000"],["77821.72000000","2.15325000"],["77824.31000000","1.93226000"],["81001.15000000","0.00338000"]]}}
{"type":"depth","received_at_ms":1788333211947,"data":{"e":"depthUpdate","E":1788333212114,"s":"BTCUSDT","U":99556337023,"u":99556337035,"b":[["77727.75000000","3.51723000"],["77727.36000000","0.00014000"],["77727.35000000","0.05007000"],["77727.30000000","0.05000000"],["77725.00000000","0.00000000"],["69954.98000000","0.00464000"],["69954.97000000","0.00000000"]],"a":[["77743.21000000","0.00000000"],["77826.11000000","0.00411000"]]}}
{"type":"depth","received_at_ms":1788333212057,"data":{"e":"depthUpdate","E":1788333212215,"s":"BTCUSDT","U":99556337036,"u":99556337057,"b":[["77727.75000000","3.51737000"],["77727.41000000","0.00643000"],["77727.40000000","0.05000000"],["77727.35000000","0.05014000"],["77727.30000000","0.00000000"],["77725.99000000","0.49422000"],["77724.99000000","0.30028000"],["69954.98000000","0.00448000"],["62182.20000000","0.00000000"]],"a":[["77743.19000000","0.00257000"],["77755.82000000","0.43583000"],["77755.95000000","0.00000000"]]}}
{"type":"depth","received_at_ms":1788333212147,"data":{"e":"depthUpdate","E":1788333212314,"s":"BTCUSDT","U":99556337058,"u":99556337094,"b":[["77727.75000000","3.51737000"],["77727.41000000","0.00657000"],["77727.40000000","0.00014000"],["77727.36000000","0.00000000"],["77727.35000000","0.00007000"],["77727.31000000","0.00014000"],["77727.30000000","0.05000000"],["77725.08000000","0.01308000"],["77675.23000000","0.00411000"],["77530.01000000","0.00811000"],["77528.01000000","0.00000000"],["69954.98000000","0.00432000"],["69954.00000000","0.00028000"],["62182.20000000","0.00000000"],["62182.00000000","0.00000000"]],"a":[["77743.15000000","0.00257000"],["77743.19000000","0.00000000"],["77755.82000000","0.37338000"],["77756.09000000","0.00000000"]]}}
{"type":"depth","received_at_ms":1788333212247,"data":{"e":"depthUpdate","E":1788333212414,"s":"BTCUSDT","U":99556337095,"u":99556337124,"b":[["77727.75000000","3.51716000"],["77727.41000000","0.00657000"],["77727.40000000","0.00000000"],["77727.31000000","0.00000000"],["77727.30000000","0.00014000"],["77725.00000000","0.00014000"],["77719.97000000","0.00020000"],["77712.20000000","0.00020000"],["77704.43000000","0.00020000"],["77696.65000000","0.00020000"],["69954.98000000","0.00448000"],["69954.00000000","0.00008000"]],"a":[["77743.13000000","0.00257000"],["77743.15000000","0.00000000"],["77821.72000000","0.00000000"],["77824.31000000","4.08551000"]]}}
{"type":"trade","received_at_ms":1788333212256,"data":{"e":"trade","E":1788333212421,"s":"BTCUSDT","t":6646666582,"p":"77727.75000000","q":"0.01500000","T":1788333212420,"m":true,"M":true}}
{"type":"depth","received_at_ms":1788333212346,"data":{"e":"depthUpdate","E":1788333212514,"s":"BTCUSDT","U":99556337125,"u":99556337159,"b":[["77727.75000000","3.50216000"],["77727.51000000","0.00014000"],["77727.50000000","0.05000000"],["77727.45000000","0.00000000"],["77727.41000000","0.00657000"],["77727.35000000","0.00000000"],["77727.30000000","0.00000000"],["77725.08000000","0.01322000"],["77725.00000000","0.00000000"],["77714.09000000","0.00411000"],["77709.13000000","0.00007000"],["77675.23000000","0.00000000"],["77644.14000000","0.00000000"],["69954.98000000","0.00448000"],["69954.97000000","0.00009000"],["62182.20000000","0.00032000"]],"a":[["77740.23000000","0.00000000"],["77742.85000000","0.10443000"],["77755.23000000","0.00000000"],["77795.00000000","0.00000000"],["77826.11000000","0.00000000"]]}}
{"type":"depth","received_at_ms":1788333212446,"data":{"e":"depthUpdate","E":1788333212614,"s":"BTCUSDT","U":99556337160,"u":99556337178,"b":[["77727.75000000","3.50209000"],["77727.51000000","0.00000000"],["77727.50000000","0.00000000"],["77725.00000000","0.00014000"],["77717.76000000","0.00000000"],["77709.13000000","0.00014000"],["69954.98000000","0.00464000"],["62182.20000000","0.00000000"],["62182.00000000","0.00000000"]],"a":[["77740.23000000","0.00007000"],["77743.11000000","0.00257000"],["77743.13000000","0.00000000"]]}}
{"type":"depth","received_at_ms":1788333212546,"data":{"e":"depthUpdate","E":1788333212714,"s":"BTCUSDT","U":99556337179,"u":99556337185,"b":[["69954.98000000","0.00448000"],["62182.20000000","0.00000000"]],"a":[["77743.06000000","0.00257000"],["77743.11000000","0.00000000"],["78893.68000000","0.00030000"]]}}
{"type":"trade","received_at_ms":1788333212646,"data":{"e":"trade","E":1788333212813,"s":"BTCUSDT","t":6646666583,"p":"77727.76000000","q":"0.00064000","T":1788333212813,"m":false,"M":true}}
{"type":"depth","received_at_ms":1788333212646,"data":{"e":"depthUpdate","E":1788333212814,"s":"BTCUSDT","U":99556337186,"u":99556337194,"b":[["77727.40000000","0.00000000"],["69954.98000000","0.00464000"]],"a":[["77727.76000000","0.06181000"],["77743.04000000","0.00257000"],["77743.06000000","0.00000000"],["77755.81000000","0.06339000"]]}}
{"type":"depth","received_at_ms":1788333212746,"data":{"e":"depthUpdate","E":1788333212914,"s":"BTCUSDT","U":99556337195,"u":99556337211,"b":[["77724.03000000","0.00807000"],["77675.24000000","0.00411000"],["69954.98000000","0.00448000"],["69954.97000000","0.00000000"],["69954.96000000","0.00009000"]],"a":[["77727.76000000","0.06031000"],["77728.39000000","0.00000000"],["77728.40000000","0.00014000"],["77730.55000000","0.00007000"],["77743.04000000","0.00000000"],["77755.81000000","0.00094000"],["77755.93000000","0.00000000"]]}}
{"type":"trade","received_at_ms":1788333212796,"data":{"e":"trade","E":1788333212963,"s":"BTCUSDT","t":6646666584,"p":"77727.76000000","q":"0.00012000","T":1788333212963,"m":false,"M":true}}
{"type":"trade","received_at_ms":1788333212838,"data":{"e":"trade","E":1788333213005,"s":"BTCUSDT","t":6646666585,"p":"77727.76000000","q":"0.00051000","T":1788333213004,"m":false,"M":true}}
{"type":"trade","received_at_ms":1788333212840,"data":{"e":"trade","E":1788333213008,"s":"BTCUSDT","t":6646666586,"p":"77727.76000000","q":"0.00200000","T":1788333213007,"m":false,"M":true}}
{"type":"trade","received_at_ms":1788333212840,"data":{"e":"trade","E":1788333213008,"s":"BTCUSDT","t":6646666587,"p":"77727.76000000","q":"0.00200000","T":1788333213007,"m":false,"M":true}}
{"type":"trade","received_at_ms":1788333212840,"data":{"e":"trade","E":1788333213008,"s":"BTCUSDT","t":6646666588,"p":"77727.76000000","q":"0.00200000","T":1788333213008,"m":false,"M":true}}
{"type":"trade","received_at_ms":1788333212841,"data":{"e":"trade","E":1788333213008,"s":"BTCUSDT","t":6646666589,"p":"77727.76000000","q":"0.00200000","T":1788333213008,"m":false,"M":true}}
{"type":"trade","received_at_ms":1788333212841,"data":{"e":"trade","E":1788333213008,"s":"BTCUSDT","t":6646666590,"p":"77727.76000000","q":"0.00200000","T":1788333213008,"m":false,"M":true}}
{"type":"trade","received_at_ms":1788333212841,"data":{"e":"trade","E":1788333213009,"s":"BTCUSDT","t":6646666591,"p":"77727.76000000","q":"0.00007000","T":1788333213008,"m":false,"M":true}}
{"type":"trade","received_at_ms":1788333212841,"data":{"e":"trade","E":1788333213009,"s":"BTCUSDT","t":6646666592,"p":"77727.76000000","q":"0.00007000","T":1788333213008,"m":false,"M":true}}
{"type":"trade","received_at_ms":1788333212841,"data":{"e":"trade","E":1788333213009,"s":"BTCUSDT","t":6646666593,"p":"77727.76000000","q":"0.00007000","T":1788333213008,"m":false,"M":true}}
{"type":"trade","received_at_ms":1788333212841,"data":{"e":"trade","E":1788333213009,"s":"BTCUSDT","t":6646666594,"p":"77727.76000000","q":"0.00007000","T":1788333213008,"m":false,"M":true}}
{"type":"trade","received_at_ms":1788333212842,"data":{"e":"trade","E":1788333213009,"s":"BTCUSDT","t":6646666595,"p":"77727.76000000","q":"0.00007000","T":1788333213008,"m":false,"M":true}}
{"type":"trade","received_at_ms":1788333212842,"data":{"e":"trade","E":1788333213009,"s":"BTCUSDT","t":6646666596,"p":"77727.76000000","q":"0.00007000","T":1788333213008,"m":false,"M":true}}
{"type":"trade","received_at_ms":1788333212842,"data":{"e":"trade","E":1788333213009,"s":"BTCUSDT","t":6646666597,"p":"77727.76000000","q":"0.00158000","T":1788333213008,"m":false,"M":true}}
{"type":"trade","received_at_ms":1788333212842,"data":{"e":"trade","E":1788333213009,"s":"BTCUSDT","t":6646666598,"p":"77727.76000000","q":"0.00198000","T":1788333213008,"m":false,"M":true}}
{"type":"trade","received_at_ms":1788333212842,"data":{"e":"trade","E":1788333213009,"s":"BTCUSDT","t":6646666599,"p":"77727.76000000","q":"0.00002000","T":1788333213008,"m":false,"M":true}}
{"type":"trade","received_at_ms":1788333212842,"data":{"e":"trade","E":1788333213009,"s":"BTCUSDT","t":6646666600,"p":"77727.76000000","q":"0.00006000","T":1788333213008,"m":false,"M":true}}
{"type":"trade","received_at_ms":1788333212845,"data":{"e":"trade","E":1788333213009,"s":"BTCUSDT","t":6646666601,"p":"77727.76000000","q":"0.00007000","T":1788333213008,"m":false,"M":true}}
{"type":"trade","received_at_ms":1788333212845,"data":{"e":"trade","E":1788333213009,"s":"BTCUSDT","t":6646666602,"p":"77727.76000000","q":"0.00007000","T":1788333213008,"m":false,"M":true}}
{"type":"trade","received_at_ms":1788333212845,"data":{"e":"trade","E":1788333213009,"s":"BTCUSDT","t":6646666603,"p":"77727.76000000","q":"0.00007000","T":1788333213008,"m":false,"M":true}}
{"type":"trade","received_at_ms":1788333212845,"data":{"e":"trade","E":1788333213009,"s":"BTCUSDT","t":6646666604,"p":"77727.76000000","q":"0.00007000","T":1788333213008,"m":false,"M":true}}
{"type":"trade","received_at_ms":1788333212845,"data":{"e":"trade","E":1788333213009,"s":"BTCUSDT","t":6646666605,"p":"77727.76000000","q":"0.00007000","T":1788333213008,"m":false,"M":true}}
{"type":"trade","received_at_ms":1788333212845,"data":{"e":"trade","E":1788333213009,"s":"BTCUSDT","t":6646666606,"p":"77727.76000000","q":"0.00007000","T":1788333213008,"m":false,"M":true}}
{"type":"trade","received_at_ms":1788333212845,"data":{"e":"trade","E":1788333213009,"s":"BTCUSDT","t":6646666607,"p":"77727.76000000","q":"0.00007000","T":1788333213008,"m":false,"M":true}}
{"type":"trade","received_at_ms":1788333212845,"data":{"e":"trade","E":1788333213009,"s":"BTCUSDT","t":6646666608,"p":"77727.76000000","q":"0.00007000","T":1788333213008,"m":false,"M":true}}
{"type":"trade","received_at_ms":1788333212845,"data":{"e":"trade","E":1788333213009,"s":"BTCUSDT","t":6646666609,"p":"77727.76000000","q":"0.00013000","T":1788333213008,"m":false,"M":true}}
{"type":"trade","received_at_ms":1788333212845,"data":{"e":"trade","E":1788333213009,"s":"BTCUSDT","t":6646666610,"p":"77727.76000000","q":"0.00007000","T":1788333213008,"m":false,"M":true}}
{"type":"trade","received_at_ms":1788333212845,"data":{"e":"trade","E":1788333213009,"s":"BTCUSDT","t":6646666611,"p":"77727.76000000","q":"0.00040000","T":1788333213008,"m":false,"M":true}}
{"type":"trade","received_at_ms":1788333212845,"data":{"e":"trade","E":1788333213009,"s":"BTCUSDT","t":6646666612,"p":"77727.76000000","q":"0.00007000","T":1788333213008,"m":false,"M":true}}
{"type":"trade","received_at_ms":1788333212845,"data":{"e":"trade","E":1788333213009,"s":"BTCUSDT","t":6646666613,"p":"77727.76000000","q":"0.00007000","T":1788333213008,"m":false,"M":true}}
{"type":"trade","received_at_ms":1788333212845,"data":{"e":"trade","E":1788333213009,"s":"BTCUSDT","t":6646666614,"p":"77727.76000000","q":"0.00007000","T":1788333213008,"m":false,"M":true}}
{"type":"trade","received_at_ms":1788333212845,"data":{"e":"trade","E":1788333213009,"s":"BTCUSDT","t":6646666615,"p":"77727.76000000","q":"0.00014000","T":1788333213008,"m":false,"M":true}}
{"type":"trade","received_at_ms":1788333212845,"data":{"e":"trade","E":1788333213009,"s":"BTCUSDT","t":6646666616,"p":"77727.76000000","q":"0.00043000","T":1788333213008,"m":false,"M":true}}
{"type":"trade","received_at_ms":1788333212845,"data":{"e":"trade","E":1788333213009,"s":"BTCUSDT","t":6646666617,"p":"77727.76000000","q":"0.00022000","T":1788333213009,"m":false,"M":true}}
{"type":"trade","received_at_ms":1788333212845,"data":{"e":"trade","E":1788333213009,"s":"BTCUSDT","t":6646666618,"p":"77727.76000000","q":"0.00064000","T":1788333213009,"m":false,"M":true}}
{"type":"trade","received_at_ms":1788333212845,"data":{"e":"trade","E":1788333213009,"s":"BTCUSDT","t":6646666619,"p":"77727.76000000","q":"0.00007000","T":1788333213009,"m":false,"M":true}}
{"type":"trade","received_at_ms":1788333212846,"data":{"e":"trade","E":1788333213009,"s":"BTCUSDT","t":6646666620,"p":"77727.76000000","q":"0.00007000","T":1788333213009,"m":false,"M":true}}
{"type":"trade","received_at_ms":1788333212846,"data":{"e":"trade","E":1788333213009,"s":"BTCUSDT","t":6646666621,"p":"77727.76000000","q":"0.00010000","T":1788333213009,"m":false,"M":true}}
{"type":"trade","received_at_ms":1788333212846,"data":{"e":"trade","E":1788333213009,"s":"BTCUSDT","t":6646666622,"p":"77727.76000000","q":"0.00007000","T":1788333213009,"m":false,"M":true}}
{"type":"trade","received_at_ms":1788333212846,"data":{"e":"trade","E":1788333213009,"s":"BTCUSDT","t":6646666623,"p":"77727.76000000","q":"0.00002000","T":1788333213009,"m":false,"M":true}}
{"type":"trade","received_at_ms":1788333212846,"data":{"e":"trade","E":1788333213009,"s":"BTCUSDT","t":6646666624,"p":"77727.77000000","q":"0.00007000","T":1788333213009,"m":false,"M":true}}
{"type":"trade","received_at_ms":1788333212846,"data":{"e":"trade","E":1788333213009,"s":"BTCUSDT","t":6646666625,"p":"77727.77000000","q":"0.00007000","T":1788333213009,"m":false,"M":true}}
{"type":"trade","received_at_ms":1788333212846,"data":{"e":"trade","E":1788333213009,"s":"BTCUSDT","t":6646666626,"p":"77727.77000000","q":"0.00007000","T":1788333213009,"m":false,"M":true}}
{"type":"trade","received_at_ms":1788333212846,"data":{"e":"trade","E":1788333213009,"s":"BTCUSDT","t":6646666627,"p":"77727.77000000","q":"0.00007000","T":1788333213009,"m":false,"M":true}}
{"type":"trade","received_at_ms":1788333212846,"data":{"e":"trade","E":1788333213009,"s":"BTCUSDT","t":6646666628,"p":"77727.77000000","q":"0.00007000","T":1788333213009,"m":false,"M":true}}
{"type":"trade","received_at_ms":1788333212846,"data":{"e":"trade","E":1788333213009,"s":"BTCUSDT","t":6646666629,"p":"77727.77000000","q":"0.00007000","T":1788333213009,"m":false,"M":true}}
{"type":"trade","received_at_ms":1788333212846,"data":{"e":"trade","E":1788333213009,"s":"BTCUSDT","t":6646666630,"p":"77727.77000000","q":"0.00007000","T":1788333213009,"m":false,"M":true}}
{"type":"trade","received_at_ms":1788333212846,"data":{"e":"trade","E":1788333213009,"s":"BTCUSDT","t":6646666631,"p":"77727.77000000","q":"0.00007000","T":1788333213009,"m":false,"M":true}}
{"type":"trade","received_at_ms":1788333212846,"data":{"e":"trade","E":1788333213009,"s":"BTCUSDT","t":6646666632,"p":"77727.77000000","q":"0.00013000","T":1788333213009,"m":false,"M":true}}
{"type":"trade","received_at_ms":1788333212846,"data":{"e":"trade","E":1788333213009,"s":"BTCUSDT","t":6646666633,"p":"77727.77000000","q":"0.00007000","T":1788333213009,"m":false,"M":true}}
{"type":"trade","received_at_ms":1788333212846,"data":{"e":"trade","E":1788333213009,"s":"BTCUSDT","t":6646666634,"p":"77727.78000000","q":"0.00005000","T":1788333213009,"m":false,"M":true}}
{"type":"trade","received_at_ms":1788333212846,"data":{"e":"trade","E":1788333213009,"s":"BTCUSDT","t":6646666635,"p":"77727.78000000","q":"0.00008000","T":1788333213009,"m":false,"M":true}}
{"type":"trade","received_at_ms":1788333212846,"data":{"e":"trade","E":1788333213009,"s":"BTCUSDT","t":6646666636,"p":"77727.89000000","q":"0.00136000","T":1788333213009,"m":false,"M":true}}
{"type":"trade","received_at_ms":1788333212846,"data":{"e":"trade","E":1788333213009,"s":"BTCUSDT","t":6646666637,"p":"77727.99000000","q":"0.00007000","T":1788333213009,"m":false,"M":true}}
{"type":"trade","received_at_ms":1788333212846,"data":{"e":"trade","E":1788333213009,"s":"BTCUSDT","t":6646666638,"p":"77727.99000000","q":"0.00007000","T":1788333213009,"m":false,"M":true}}
{"type":"trade","received_at_ms":1788333212846,"data":{"e":"trade","E":1788333213009,"s":"BTCUSDT","t":6646666639,"p":"77727.99000000","q":"0.00007000","T":1788333213009,"m":false,"M":true}}
{"type":"trade","received_at_ms":1788333212846,"data":{"e":"trade","E":1788333213009,"s":"BTCUSDT","t":6646666640,"p":"77728.00000000","q":"0.00035000","T":1788333213009,"m":false,"M":true}}
{"type":"trade","received_at_ms":1788333212846,"data":{"e":"trade","E":1788333213009,"s":"BTCUSDT","t":6646666641,"p":"77728.00000000","q":"0.00200000","T":1788333213009,"m":false,"M":true}}
{"type":"trade","received_at_ms":1788333212846,"data":{"e":"trade","E":1788333213009,"s":"BTCUSDT","t":6646666642,"p":"77728.00000000","q":"0.00200000","T":1788333213009,"m":false,"M":true}}
{"type":"depth","received_at_ms":1788333212847,"data":{"e":"depthUpdate","E":1788333213014,"s":"BTCUSDT","U":99556337212,"u":99556337485,"b":[["77727.99000000","4.67212000"],["77727.98000000","0.00014000"],["77727.88000000","0.41262000"],["77727.77000000","1.80588000"],["77727.76000000","1.25908000"],["77727.75000000","0.77373000"],["77727.74000000","0.00000000"],["77727.73000000","0.00000000"],["77727.20000000","0.00000000"],["77727.08000000","0.00400000"],["77726.51000000","0.00000000"],["77726.00000000","0.07528000"],["77725.00000000","0.00000000"],["77724.04000000","0.00000000"],["77724.03000000","0.00400000"],["77724.02000000","0.37359000"],["77724.01000000","0.94142000"],["77724.00000000","1.95496000"],["77722.17000000","0.00013000"],["77720.25000000","0.00067000"],["77720.22000000","0.00008000"],["77720.17000000","0.00000000"],["77719.43000000","0.00200000"],["77718.22000000","0.00000000"],["77716.05000000","0.00007000"],["77715.81000000","0.02000000"],["77688.92000000","0.00000000"],["77635.97000000","0.00000000"],["76561.83000000","0.00000000"],["69954.98000000","0.00000000"],["62182.20000000","0.00032000"]],"a":[["77727.76000000","0.00000000"],["77727.77000000","0.00000000"],["77727.78000000","0.00000000"],["77727.89000000","0.00000000"],["77727.99000000","0.00000000"],["77728.00000000","0.30997000"],["77728.01000000","0.00063000"],["77728.40000000","0.00000000"],["77730.55000000","0.00014000"],["77730.83000000","0.00007000"],["77731.76000000","0.11205000"],["77731.82000000","0.00000000"],["77731.99000000","0.19262000"],["77733.59000000","0.00000000"],["77733.77000000","0.00000000"],["77733.82000000","0.00013000"],["77735.77000000","0.00008000"],["77743.02000000","0.00257000"],["77743.03000000","0.00000000"],["77755.72000000","0.00000000"],["77757.66000000","0.00000000"],["77759.09000000","0.00000000"],["77761.31000000","0.00000000"],["77797.72000000","0.00000000"],["77805.73000000","0.00008000"],["77821.72000000","2.15325000"],["77824.31000000","1.93226000"],["78893.68000000","0.00000000"]]}}
{"type":"trade","received_at_ms":1788333212850,"data":{"e":"trade","E":1788333213017,"s":"BTCUSDT","t":6646666643,"p":"77728.00000000","q":"0.00565000","T":1788333213016,"m":false,"M":true}}
{"type":"trade","received_at_ms":1788333212851,"data":{"e":"trade","E":1788333213017,"s":"BTCUSDT","t":6646666644,"p":"77728.00000000","q":"0.00500000","T":1788333213016,"m":false,"M":true}}
{"type":"trade","received_at_ms":1788333212851,"data":{"e":"trade","E":1788333213017,"s":"BTCUSDT","t":6646666645,"p":"77728.00000000","q":"0.00500000","T":1788333213016,"m":false,"M":true}}
{"type":"trade","received_at_ms":1788333212851,"data":{"e":"trade","E":1788333213017,"s":"BTCUSDT","t":6646666646,"p":"77728.00000000","q":"0.00535000","T":1788333213016,"m":false,"M":true}}
{"type":"trade","received_at_ms":1788333212851,"data":{"e":"trade","E":1788333213018,"s":"BTCUSDT","t":6646666647,"p":"77728.00000000","q":"0.00276000","T":1788333213017,"m":false,"M":true}}
{"type":"depth","received_at_ms":1788333212947,"data":{"e":"depthUpdate","E":1788333213114,"s":"BTCUSDT","U":99556337486,"u":99556337600,"b":[["77727.99000000","5.11027000"],["77727.98000000","0.00027000"],["77727.97000000","0.00013000"],["77727.91000000","0.00007000"],["77727.90000000","1.01477000"],["77727.89000000","1.32685000"],["77727.88000000","0.41290000"],["77727.78000000","0.00014000"],["77727.77000000","0.40521000"],["77727.76000000","0.07528000"],["77727.75000000","0.61857000"],["77727.55000000","0.05007000"],["77727.41000000","0.00014000"],["77727.40000000","0.05000000"],["77726.52000000","0.00643000"],["77726.01000000","0.00000000"],["77726.00000000","0.07514000"],["77725.71000000","0.00643000"],["77725.26000000","0.02041000"],["77725.08000000","0.01308000"],["77724.99000000","0.30014000"],["77724.03000000","0.00000000"],["77724.02000000","0.37345000"],["77724.01000000","0.71497000"],["77723.99000000","0.10443000"],["77720.25000000","0.00060000"],["77718.29000000","0.00007000"],["77689.00000000","0.01000000"],["77688.00000000","0.03000000"],["77679.58000000","0.25000000"],["77675.58000000","0.00000000"],["77644.15000000","0.00411000"],["77588.03000000","0.00000000"],["69955.20000000","0.00016000"]],"a":[["77728.00000000","0.15497000"],["77730.90000000","0.00000000"],["77731.42000000","0.00000000"],["77740.60000000","0.11436000"],["77743.02000000","0.00000000"],["77766.00000000","0.03400000"],["77779.77000000","0.00000000"],["77783.77000000","0.25000000"],["77817.10000000","0.00007000"],["77838.41000000","0.00000000"],["77840.76000000","0.00000000"],["77993.49000000","0.00000000"],["78023.36000000","1.19998000"]]}}
{"type":"trade","received_at_ms":1788333212978,"data":{"e":"trade","E":1788333213144,"s":"BTCUSDT","t":6646666648,"p":"77728.00000000","q":"0.00189000","T":1788333213144,"m":false,"M":true}}
{"type":"trade","received_at_ms":1788333212978,"data":{"e":"trade","E":1788333213144,"s":"BTCUSDT","t":6646666649,"p":"77728.00000000","q":"0.00007000","T":1788333213144,"m":false,"M":true}}
{"type":"trade","received_at_ms":1788333212978,"data":{"e":"trade","E":1788333213144,"s":"BTCUSDT","t":6646666650,"p":"77728.00000000","q":"0.00004000","T":1788333213144,"m":false,"M":true}}
{"type":"trade","received_at_ms":1788333212978,"data":{"e":"trade","E":1788333213144,"s":"BTCUSDT","t":6646666651,"p":"77728.00000000","q":"0.00003000","T":1788333213144,"m":false,"M":true}}
{"type":"trade","received_at_ms":1788333212978,"data":{"e":"trade","E":1788333213144,"s":"BTCUSDT","t":6646666652,"p":"77728.00000000","q":"0.00007000","T":1788333213144,"m":false,"M":true}}
{"type":"trade","received_at_ms":1788333212978,"data":{"e":"trade","E":1788333213144,"s":"BTCUSDT","t":6646666653,"p":"77728.00000000","q":"0.00007000","T":1788333213144,"m":false,"M":true}}
{"type":"trade","received_at_ms":1788333212978,"data":{"e":"trade","E":1788333213144,"s":"BTCUSDT","t":6646666654,"p":"77728.00000000","q":"0.00007000","T":1788333213144,"m":false,"M":true}}
{"type":"trade","received_at_ms":1788333212978,"data":{"e":"trade","E":1788333213144,"s":"BTCUSDT","t":6646666655,"p":"77728.00000000","q":"0.00007000","T":1788333213144,"m":false,"M":true}}
{"type":"trade","received_at_ms":1788333212978,"data":{"e":"trade","E":1788333213144,"s":"BTCUSDT","t":6646666656,"p":"77728.00000000","q":"0.00007000","T":1788333213144,"m":false,"M":true}}
{"type":"trade","received_at_ms":1788333212978,"data":{"e":"trade","E":1788333213144,"s":"BTCUSDT","t":6646666657,"p":"77728.00000000","q":"0.00007000","T":1788333213144,"m":false,"M":true}}
{"type":"trade","received_at_ms":1788333212978,"data":{"e":"trade","E":1788333213144,"s":"BTCUSDT","t":6646666658,"p":"77728.00000000","q":"0.00007000","T":1788333213144,"m":false,"M":true}}
{"type":"trade","received_at_ms":1788333212978,"data":{"e":"trade","E":1788333213144,"s":"BTCUSDT","t":6646666659,"p":"77728.00000000","q":"0.00007000","T":1788333213144,"m":false,"M":true}}
{"type":"trade","received_at_ms":1788333212978,"data":{"e":"trade","E":1788333213144,"s":"BTCUSDT","t":6646666660,"p":"77728.00000000","q":"0.00141000","T":1788333213144,"m":false,"M":true}}
{"type":"trade","received_at_ms":1788333212979,"data":{"e":"trade","E":1788333213145,"s":"BTCUSDT","t":6646666661,"p":"77728.00000000","q":"0.00200000","T":1788333213144,"m":false,"M":true}}
{"type":"trade","received_at_ms":1788333212979,"data":{"e":"trade","E":1788333213145,"s":"BTCUSDT","t":6646666662,"p":"77728.00000000","q":"0.00200000","T":1788333213144,"m":false,"M":true}}
{"type":"trade","received_at_ms":1788333212979,"data":{"e":"trade","E":1788333213145,"s":"BTCUSDT","t":6646666663,"p":"77728.00000000","q":"0.00200000","T":1788333213144,"m":false,"M":true}}
{"type":"trade","received_at_ms":1788333212984,"data":{"e":"trade","E":1788333213145,"s":"BTCUSDT","t":6646666664,"p":"77728.00000000","q":"0.00013000","T":1788333213145,"m":false,"M":true}}
{"type":"trade","received_at_ms":1788333212984,"data":{"e":"trade","E":1788333213145,"s":"BTCUSDT","t":6646666665,"p":"77728.00000000","q":"0.00007000","T":1788333213145,"m":false,"M":true}}
{"type":"trade","received_at_ms":1788333212984,"data":{"e":"trade","E":1788333213145,"s":"BTCUSDT","t":6646666666,"p":"77728.00000000","q":"0.00007000","T":1788333213145,"m":false,"M":true}}
{"type":"trade","received_at_ms":1788333212984,"data":{"e":"trade","E":1788333213145,"s":"BTCUSDT","t":6646666667,"p":"77728.00000000","q":"0.00007000","T":1788333213145,"m":false,"M":true}}
{"type":"trade","received_at_ms":1788333212984,"data":{"e":"trade","E":1788333213145,"s":"BTCUSDT","t":6646666668,"p":"77728.00000000","q":"0.00007000","T":1788333213145,"m":false,"M":true}}
{"type":"trade","received_at_ms":1788333212984,"data":{"e":"trade","E":1788333213145,"s":"BTCUSDT","t":6646666669,"p":"77728.00000000","q":"0.00007000","T":1788333213145,"m":false,"M":true}}
{"type":"trade","received_at_ms":1788333212984,"data":{"e":"trade","E":1788333213145,"s":"BTCUSDT","t":6646666670,"p":"77728.00000000","q":"0.00007000","T":1788333213145,"m":false,"M":true}}
{"type":"trade","received_at_ms":1788333212984,"data":{"e":"trade","E":1788333213145,"s":"BTCUSDT","t":6646666671,"p":"77728.00000000","q":"0.00007000","T":1788333213145,"m":false,"M":true}}
{"type":"trade","received_at_ms":1788333212984,"data":{"e":"trade","E":1788333213145,"s":"BTCUSDT","t":6646666672,"p":"77728.00000000","q":"0.00013000","T":1788333213145,"m":false,"M":true}}
{"type":"trade","received_at_ms":1788333212984,"data":{"e":"trade","E":1788333213145,"s":"BTCUSDT","t":6646666673,"p":"77728.00000000","q":"0.00008000","T":1788333213145,"m":false,"M":true}}
{"type":"trade","received_at_ms":1788333212985,"data":{"e":"trade","E":1788333213145,"s":"BTCUSDT","t":6646666674,"p":"77728.00000000","q":"0.00007000","T":1788333213145,"m":false,"M":true}}
{"type":"trade","received_at_ms":1788333212985,"data":{"e":"trade","E":1788333213145,"s":"BTCUSDT","t":6646666675,"p":"77728.00000000","q":"0.00007000","T":1788333213145,"m":false,"M":true}}
{"type":"trade","received_at_ms":1788333212985,"data":{"e":"trade","E":1788333213145,"s":"BTCUSDT","t":6646666676,"p":"77728.01000000","q":"0.00007000","T":1788333213145,"m":false,"M":true}}
{"type":"trade","received_at_ms":1788333212985,"data":{"e":"trade","E":1788333213145,"s":"BTCUSDT","t":6646666677,"p":"77728.01000000","q":"0.00007000","T":1788333213145,"m":false,"M":true}}
{"type":"trade","received_at_ms":1788333212985,"data":{"e":"trade","E":1788333213145,"s":"BTCUSDT","t":6646666678,"p":"77728.01000000","q":"0.00007000","T":1788333213145,"m":false,"M":true}}
{"type":"trade","received_at_ms":1788333212985,"data":{"e":"trade","E":1788333213145,"s":"BTCUSDT","t":6646666679,"p":"77728.01000000","q":"0.00007000","T":1788333213145,"m":false,"M":true}}
{"type":"trade","received_at_ms":1788333212985,"data":{"e":"trade","E":1788333213145,"s":"BTCUSDT","t":6646666680,"p":"77728.01000000","q":"0.00007000","T":1788333213145,"m":false,"M":true}}
{"type":"trade","received_at_ms":1788333212985,"data":{"e":"trade","E":1788333213145,"s":"BTCUSDT","t":6646666681,"p":"77728.01000000","q":"0.00007000","T":1788333213145,"m":false,"M":true}}
{"type":"trade","received_at_ms":1788333212985,"data":{"e":"trade","E":1788333213145,"s":"BTCUSDT","t":6646666682,"p":"77728.01000000","q":"0.00007000","T":1788333213145,"m":false,"M":true}}
{"type":"trade","received_at_ms":1788333212985,"data":{"e":"trade","E":1788333213145,"s":"BTCUSDT","t":6646666683,"p":"77728.01000000","q":"0.00007000","T":1788333213145,"m":false,"M":true}}
{"type":"trade","received_at_ms":1788333212985,"data":{"e":"trade","E":1788333213145,"s":"BTCUSDT","t":6646666684,"p":"77728.01000000","q":"0.00007000","T":1788333213145,"m":false,"M":true}}
{"type":"trade","received_at_ms":1788333212985,"data":{"e":"trade","E":1788333213145,"s":"BTCUSDT","t":6646666685,"p":"77728.03000000","q":"0.00040000","T":1788333213145,"m":false,"M":true}}
{"type":"trade","received_at_ms":1788333212985,"data":{"e":"trade","E":1788333213145,"s":"BTCUSDT","t":6646666686,"p":"77728.03000000","q":"0.00160000","T":1788333213145,"m":false,"M":true}}
{"type":"trade","received_at_ms":1788333212985,"data":{"e":"trade","E":1788333213145,"s":"BTCUSDT","t":6646666687,"p":"77728.32000000","q":"0.00007000","T":1788333213145,"m":false,"M":true}}
{"type":"trade","received_at_ms":1788333212985,"data":{"e":"trade","E":1788333213145,"s":"BTCUSDT","t":6646666688,"p":"77728.64000000","q":"0.00008000","T":1788333213145,"m":false,"M":true}}
{"type":"trade","received_at_ms":1788333212985,"data":{"e":"trade","E":1788333213145,"s":"BTCUSDT","t":6646666689,"p":"77729.11000000","q":"0.00008000","T":1788333213145,"m":false,"M":true}}
{"type":"trade","received_at_ms":1788333212985,"data":{"e":"trade","E":1788333213145,"s":"BTCUSDT","t":6646666690,"p":"77729.15000000","q":"0.00007000","T":1788333213145,"m":false,"M":true}}
{"type":"trade","received_at_ms":1788333212985,"data":{"e":"trade","E":1788333213145,"s":"BTCUSDT","t":6646666691,"p":"77729.15000000","q":"0.00007000","T":1788333213145,"m":false,"M":true}}
{"type":"trade","received_at_ms":1788333212985,"data":{"e":"trade","E":1788333213145,"s":"BTCUSDT","t":6646666692,"p":"77729.15000000","q":"0.00003000","T":1788333213145,"m":false,"M":true}}
{"type":"trade","received_at_ms":1788333212985,"data":{"e":"trade","E":1788333213145,"s":"BTCUSDT","t":6646666693,"p":"77729.15000000","q":"0.00004000","T":1788333213145,"m":false,"M":true}}
{"type":"trade","received_at_ms":1788333212985,"data":{"e":"trade","E":1788333213145,"s":"BTCUSDT","t":6646666694,"p":"77729.16000000","q":"0.00007000","T":1788333213145,"m":false,"M":true}}
{"type":"trade","received_at_ms":1788333212985,"data":{"e":"trade","E":1788333213145,"s":"BTCUSDT","t":6646666695,"p":"77729.16000000","q":"0.00007000","T":1788333213145,"m":false,"M":true}}
{"type":"trade","received_at_ms":1788333212985,"data":{"e":"trade","E":1788333213145,"s":"BTCUSDT","t":6646666696,"p":"77729.51000000","q":"0.00007000","T":1788333213145,"m":false,"M":true}}
{"type":"trade","received_at_ms":1788333212985,"data":{"e":"trade","E":1788333213145,"s":"BTCUSDT","t":6646666697,"p":"77729.60000000","q":"0.00175000","T":1788333213145,"m":false,"M":true}}
{"type":"trade","received_at_ms":1788333212985,"data":{"e":"trade","E":1788333213146,"s":"BTCUSDT","t":6646666698,"p":"77729.60000000","q":"0.00200000","T":1788333213145,"m":false,"M":true}}
{"type":"trade","received_at_ms":1788333212985,"data":{"e":"trade","E":1788333213146,"s":"BTCUSDT","t":6646666699,"p":"77729.60000000","q":"0.00011000","T":1788333213145,"m":false,"M":true}}
{"type":"trade","received_at_ms":1788333212985,"data":{"e":"trade","E":1788333213146,"s":"BTCUSDT","t":6646666700,"p":"77729.72000000","q":"0.00160000","T":1788333213145,"m":false,"M":true}}
{"type":"trade","received_at_ms":1788333212985,"data":{"e":"trade","E":1788333213146,"s":"BTCUSDT","t":6646666701,"p":"77729.99000000","q":"0.00007000","T":1788333213145,"m":false,"M":true}}
{"type":"trade","received_at_ms":1788333212985,"data":{"e":"trade","E":1788333213146,"s":"BTCUSDT","t":6646666702,"p":"77729.99000000","q":"0.00007000","T":1788333213145,"m":false,"M":true}}
{"type":"trade","received_at_ms":1788333212985,"data":{"e":"trade","E":1788333213146,"s":"BTCUSDT","t":6646666703,"p":"77729.99000000","q":"0.00007000","T":1788333213145,"m":false,"M":true}}
{"type":"trade","received_at_ms":1788333212985,"data":{"e":"trade","E":1788333213146,"s":"BTCUSDT","t":6646666704,"p":"77730.00000000","q":"0.00008000","T":1788333213145,"m":false,"M":true}}
{"type":"trade","received_at_ms":1788333212986,"data":{"e":"trade","E":1788333213146,"s":"BTCUSDT","t":6646666705,"p":"77730.00000000","q":"0.00042000","T":1788333213145,"m":false,"M":true}}
{"type":"trade","received_at_ms":1788333212986,"data":{"e":"trade","E":1788333213146,"s":"BTCUSDT","t":6646666706,"p":"77730.00000000","q":"0.00158000","T":1788333213145,"m":false,"M":true}}
{"type":"trade","received_at_ms":1788333212986,"data":{"e":"trade","E":1788333213146,"s":"BTCUSDT","t":6646666707,"p":"77730.00000000","q":"0.00200000","T":1788333213145,"m":false,"M":true}}
{"type":"trade","received_at_ms":1788333212986,"data":{"e":"trade","E":1788333213146,"s":"BTCUSDT","t":6646666708,"p":"77730.00000000","q":"0.00200000","T":1788333213145,"m":false,"M":true}}
{"type":"trade","received_at_ms":1788333212986,"data":{"e":"trade","E":1788333213146,"s":"BTCUSDT","t":6646666709,"p":"77730.00000000","q":"0.00200000","T":1788333213145,"m":false,"M":true}}
{"type":"trade","received_at_ms":1788333212986,"data":{"e":"trade","E":1788333213146,"s":"BTCUSDT","t":6646666710,"p":"77730.00000000","q":"0.00200000","T":1788333213145,"m":false,"M":true}}
{"type":"trade","received_at_ms":1788333212986,"data":{"e":"trade","E":1788333213147,"s":"BTCUSDT","t":6646666711,"p":"77730.00000000","q":"0.00042000","T":1788333213147,"m":false,"M":true}}
{"type":"trade","received_at_ms":1788333212986,"data":{"e":"trade","E":1788333213147,"s":"BTCUSDT","t":6646666712,"p":"77730.00000000","q":"0.00158000","T":1788333213147,"m":false,"M":true}}
{"type":"trade","received_at_ms":1788333212986,"data":{"e":"trade","E":1788333213147,"s":"BTCUSDT","t":6646666713,"p":"77730.00000000","q":"0.00200000","T":1788333213147,"m":false,"M":true}}
{"type":"trade","received_at_ms":1788333212986,"data":{"e":"trade","E":1788333213148,"s":"BTCUSDT","t":6646666714,"p":"77730.00000000","q":"0.00142000","T":1788333213147,"m":false,"M":true}}
{"type":"trade","received_at_ms":1788333212986,"data":{"e":"trade","E":1788333213148,"s":"BTCUSDT","t":6646666715,"p":"77730.00000000","q":"0.00058000","T":1788333213147,"m":false,"M":true}}
{"type":"trade","received_at_ms":1788333212991,"data":{"e":"trade","E":1788333213154,"s":"BTCUSDT","t":6646666716,"p":"77730.00000000","q":"0.00442000","T":1788333213154,"m":false,"M":true}}
{"type":"trade","received_at_ms":1788333212991,"data":{"e":"trade","E":1788333213154,"s":"BTCUSDT","t":6646666717,"p":"77730.00000000","q":"0.01000000","T":1788333213154,"m":false,"M":true}}
{"type":"trade","received_at_ms":1788333212991,"data":{"e":"trade","E":1788333213154,"s":"BTCUSDT","t":6646666718,"p":"77730.00000000","q":"0.00007000","T":1788333213154,"m":false,"M":true}}
{"type":"trade","received_at_ms":1788333212991,"data":{"e":"trade","E":1788333213154,"s":"BTCUSDT","t":6646666719,"p":"77730.00000000","q":"0.00007000","T":1788333213154,"m":false,"M":true}}
{"type":"trade","received_at_ms":1788333212991,"data":{"e":"trade","E":1788333213154,"s":"BTCUSDT","t":6646666720,"p":"77730.00000000","q":"0.00007000","T":1788333213154,"m":false,"M":true}}
{"type":"trade","received_at_ms":1788333212991,"data":{"e":"trade","E":1788333213154,"s":"BTCUSDT","t":6646666721,"p":"77730.00000000","q":"0.00007000","T":1788333213154,"m":false,"M":true}}
{"type":"trade","received_at_ms":1788333212991,"data":{"e":"trade","E":1788333213154,"s":"BTCUSDT","t":6646666722,"p":"77730.00000000","q":"0.00355000","T":1788333213154,"m":false,"M":true}}
{"type":"trade","received_at_ms":1788333212991,"data":{"e":"trade","E":1788333213154,"s":"BTCUSDT","t":6646666723,"p":"77730.00000000","q":"0.00007000","T":1788333213154,"m":false,"M":true}}
{"type":"trade","received_at_ms":1788333212991,"data":{"e":"trade","E":1788333213154,"s":"BTCUSDT","t":6646666724,"p":"77730.00000000","q":"0.00007000","T":1788333213154,"m":false,"M":true}}
{"type":"trade","received_at_ms":1788333212991,"data":{"e":"trade","E":1788333213154,"s":"BTCUSDT","t":6646666725,"p":"77730.00000000","q":"0.00007000","T":1788333213154,"m":false,"M":true}}
{"type":"trade","received_at_ms":1788333212991,"data":{"e":"trade","E":1788333213154,"s":"BTCUSDT","t":6646666726,"p":"77730.00000000","q":"0.00007000","T":1788333213154,"m":false,"M":true}}
{"type":"trade","received_at_ms":1788333212991,"data":{"e":"trade","E":1788333213154,"s":"BTCUSDT","t":6646666727,"p":"77730.00000000","q":"0.00007000","T":1788333213154,"m":false,"M":true}}
{"type":"trade","received_at_ms":1788333212991,"data":{"e":"trade","E":1788333213154,"s":"BTCUSDT","t":6646666728,"p":"77730.00000000","q":"0.00007000","T":1788333213154,"m":false,"M":true}}
{"type":"trade","received_at_ms":1788333212991,"data":{"e":"trade","E":1788333213154,"s":"BTCUSDT","t":6646666729,"p":"77730.00000000","q":"0.00007000","T":1788333213154,"m":false,"M":true}}
{"type":"trade","received_at_ms":1788333212991,"data":{"e":"trade","E":1788333213154,"s":"BTCUSDT","t":6646666730,"p":"77730.00000000","q":"0.00007000","T":1788333213154,"m":false,"M":true}}
{"type":"trade","received_at_ms":1788333212991,"data":{"e":"trade","E":1788333213154,"s":"BTCUSDT","t":6646666731,"p":"77730.00000000","q":"0.00007000","T":1788333213154,"m":false,"M":true}}
{"type":"trade","received_at_ms":1788333212991,"data":{"e":"trade","E":1788333213154,"s":"BTCUSDT","t":6646666732,"p":"77730.00000000","q":"0.00007000","T":1788333213154,"m":false,"M":true}}
{"type":"trade","received_at_ms":1788333212991,"data":{"e":"trade","E":1788333213154,"s":"BTCUSDT","t":6646666733,"p":"77730.00000000","q":"0.00007000","T":1788333213154,"m":false,"M":true}}
{"type":"trade","received_at_ms":1788333212991,"data":{"e":"trade","E":1788333213154,"s":"BTCUSDT","t":6646666734,"p":"77730.00000000","q":"0.00007000","T":1788333213154,"m":false,"M":true}}
{"type":"trade","received_at_ms":1788333212991,"data":{"e":"trade","E":1788333213154,"s":"BTCUSDT","t":6646666735,"p":"77730.00000000","q":"0.00007000","T":1788333213154,"m":false,"M":true}}
{"type":"trade","received_at_ms":1788333212991,"data":{"e":"trade","E":1788333213154,"s":"BTCUSDT","t":6646666736,"p":"77730.01000000","q":"0.00007000","T":1788333213154,"m":false,"M":true}}
{"type":"trade","received_at_ms":1788333212991,"data":{"e":"trade","E":1788333213154,"s":"BTCUSDT","t":6646666737,"p":"77730.01000000","q":"0.00007000","T":1788333213154,"m":false,"M":true}}
{"type":"trade","received_at_ms":1788333212991,"data":{"e":"trade","E":1788333213154,"s":"BTCUSDT","t":6646666738,"p":"77730.01000000","q":"0.00007000","T":1788333213154,"m":false,"M":true}}
{"type":"trade","received_at_ms":1788333212992,"data":{"e":"trade","E":1788333213154,"s":"BTCUSDT","t":6646666739,"p":"77730.01000000","q":"0.00007000","T":1788333213154,"m":false,"M":true}}
{"type":"trade","received_at_ms":1788333212992,"data":{"e":"trade","E":1788333213154,"s":"BTCUSDT","t":6646666740,"p":"77730.01000000","q":"0.00007000","T":1788333213154,"m":false,"M":true}}
{"type":"trade","received_at_ms":1788333212992,"data":{"e":"trade","E":1788333213154,"s":"BTCUSDT","t":6646666741,"p":"77730.01000000","q":"0.00007000","T":1788333213154,"m":false,"M":true}}
{"type":"trade","received_at_ms":1788333212992,"data":{"e":"trade","E":1788333213154,"s":"BTCUSDT","t":6646666742,"p":"77730.01000000","q":"0.00007000","T":1788333213154,"m":false,"M":true}}
{"type":"trade","received_at_ms":1788333212992,"data":{"e":"trade","E":1788333213154,"s":"BTCUSDT","t":6646666743,"p":"77730.01000000","q":"0.00007000","T":1788333213154,"m":false,"M":true}}
{"type":"trade","received_at_ms":1788333212992,"data":{"e":"trade","E":1788333213154,"s":"BTCUSDT","t":6646666744,"p":"77730.01000000","q":"0.00007000","T":1788333213154,"m":false,"M":true}}
{"type":"trade","received_at_ms":1788333212992,"data":{"e":"trade","E":1788333213154,"s":"BTCUSDT","t":6646666745,"p":"77730.21000000","q":"0.00007000","T":1788333213154,"m":false,"M":true}}
{"type":"trade","received_at_ms":1788333212992,"data":{"e":"trade","E":1788333213154,"s":"BTCUSDT","t":6646666746,"p":"77730.21000000","q":"0.00007000","T":1788333213154,"m":false,"M":true}}
{"type":"trade","received_at_ms":1788333212992,"data":{"e":"trade","E":1788333213154,"s":"BTCUSDT","t":6646666747,"p":"77730.21000000","q":"0.00007000","T":1788333213154,"m":false,"M":true}}
{"type":"trade","received_at_ms":1788333212992,"data":{"e":"trade","E":1788333213154,"s":"BTCUSDT","t":6646666748,"p":"77730.22000000","q":"0.00100000","T":1788333213154,"m":false,"M":true}}
{"type":"trade","received_at_ms":1788333212992,"data":{"e":"trade","E":1788333213156,"s":"BTCUSDT","t":6646666749,"p":"77730.22000000","q":"0.02100000","T":1788333213155,"m":false,"M":true}}
{"type":"trade","received_at_ms":1788333212992,"data":{"e":"trade","E":1788333213156,"s":"BTCUSDT","t":6646666750,"p":"77730.22000000","q":"0.00694000","T":1788333213156,"m":false,"M":true}}
{"type":"trade","received_at_ms":1788333212992,"data":{"e":"trade","E":1788333213156,"s":"BTCUSDT","t":6646666751,"p":"77730.22000000","q":"0.00007000","T":1788333213156,"m":false,"M":true}}
{"type":"trade","received_at_ms":1788333212992,"data":{"e":"trade","E":1788333213156,"s":"BTCUSDT","t":6646666752,"p":"77730.22000000","q":"0.00007000","T":1788333213156,"m":false,"M":true}}
{"type":"trade","received_at_ms":1788333212992,"data":{"e":"trade","E":1788333213156,"s":"BTCUSDT","t":6646666753,"p":"77730.22000000","q":"0.01392000","T":1788333213156,"m":false,"M":true}}
{"type":"trade","received_at_ms":1788333212992,"data":{"e":"trade","E":1788333213156,"s":"BTCUSDT","t":6646666754,"p":"77730.22000000","q":"0.02100000","T":1788333213156,"m":false,"M":true}}
{"type":"trade","received_at_ms":1788333212992,"data":{"e":"trade","E":1788333213156,"s":"BTCUSDT","t":6646666755,"p":"77730.22000000","q":"0.02100000","T":1788333213156,"m":false,"M":true}}
{"type":"trade","received_at_ms":1788333212992,"data":{"e":"trade","E":1788333213156,"s":"BTCUSDT","t":6646666756,"p":"77730.22000000","q":"0.02100000","T":1788333213156,"m":false,"M":true}}
{"type":"trade","received_at_ms":1788333212996,"data":{"e":"trade","E":1788333213159,"s":"BTCUSDT","t":6646666757,"p":"77730.22000000","q":"0.00007000","T":1788333213158,"m":false,"M":true}}
{"type":"trade","received_at_ms":1788333212996,"data":{"e":"trade","E":1788333213159,"s":"BTCUSDT","t":6646666758,"p":"77730.22000000","q":"0.00007000","T":1788333213158,"m":false,"M":true}}
{"type":"trade","received_at_ms":1788333212996,"data":{"e":"trade","E":1788333213159,"s":"BTCUSDT","t":6646666759,"p":"77730.22000000","q":"0.00007000","T":1788333213158,"m":false,"M":true}}
{"type":"trade","received_at_ms":1788333212996,"data":{"e":"trade","E":1788333213159,"s":"BTCUSDT","t":6646666760,"p":"77730.22000000","q":"0.00007000","T":1788333213158,"m":false,"M":true}}
{"type":"trade","received_at_ms":1788333212996,"data":{"e":"trade","E":1788333213159,"s":"BTCUSDT","t":6646666761,"p":"77730.22000000","q":"0.00007000","T":1788333213158,"m":false,"M":true}}
{"type":"trade","received_at_ms":1788333212996,"data":{"e":"trade","E":1788333213159,"s":"BTCUSDT","t":6646666762,"p":"77730.22000000","q":"0.00007000","T":1788333213158,"m":false,"M":true}}
{"type":"trade","received_at_ms":1788333212996,"data":{"e":"trade","E":1788333213159,"s":"BTCUSDT","t":6646666763,"p":"77730.22000000","q":"0.00644000","T":1788333213158,"m":false,"M":true}}
{"type":"trade","received_at_ms":1788333212996,"data":{"e":"trade","E":1788333213159,"s":"BTCUSDT","t":6646666764,"p":"77730.22000000","q":"0.00007000","T":1788333213158,"m":false,"M":true}}
{"type":"trade","received_at_ms":1788333212996,"data":{"e":"trade","E":1788333213159,"s":"BTCUSDT","t":6646666765,"p":"77730.22000000","q":"0.00007000","T":1788333213158,"m":false,"M":true}}
{"type":"trade","received_at_ms":1788333212996,"data":{"e":"trade","E":1788333213159,"s":"BTCUSDT","t":6646666766,"p":"77730.22000000","q":"0.00007000","T":1788333213158,"m":false,"M":true}}
{"type":"trade","received_at_ms":1788333212996,"data":{"e":"trade","E":1788333213159,"s":"BTCUSDT","t":6646666767,"p":"77730.22000000","q":"0.00007000","T":1788333213158,"m":false,"M":true}}
{"type":"trade","received_at_ms":1788333212996,"data":{"e":"trade","E":1788333213159,"s":"BTCUSDT","t":6646666768,"p":"77730.22000000","q":"0.00007000","T":1788333213158,"m":false,"M":true}}
{"type":"trade","received_at_ms":1788333212996,"data":{"e":"trade","E":1788333213159,"s":"BTCUSDT","t":6646666769,"p":"77730.22000000","q":"0.00007000","T":1788333213158,"m":false,"M":true}}
{"type":"trade","received_at_ms":1788333212996,"data":{"e":"trade","E":1788333213159,"s":"BTCUSDT","t":6646666770,"p":"77730.22000000","q":"0.00007000","T":1788333213158,"m":false,"M":true}}
{"type":"trade","received_at_ms":1788333212996,"data":{"e":"trade","E":1788333213159,"s":"BTCUSDT","t":6646666771,"p":"77730.22000000","q":"0.00007000","T":1788333213158,"m":false,"M":true}}
{"type":"trade","received_at_ms":1788333212996,"data":{"e":"trade","E":1788333213159,"s":"BTCUSDT","t":6646666772,"p":"77730.22000000","q":"0.00007000","T":1788333213158,"m":false,"M":true}}
{"type":"trade","received_at_ms":1788333212996,"data":{"e":"trade","E":1788333213159,"s":"BTCUSDT","t":6646666773,"p":"77730.23000000","q":"0.00007000","T":1788333213158,"m":false,"M":true}}
{"type":"trade","received_at_ms":1788333212996,"data":{"e":"trade","E":1788333213159,"s":"BTCUSDT","t":6646666774,"p":"77730.23000000","q":"0.00007000","T":1788333213158,"m":false,"M":true}}
{"type":"trade","received_at_ms":1788333212996,"data":{"e":"trade","E":1788333213159,"s":"BTCUSDT","t":6646666775,"p":"77730.23000000","q":"0.00007000","T":1788333213158,"m":false,"M":true}}
{"type":"trade","received_at_ms":1788333212996,"data":{"e":"trade","E":1788333213159,"s":"BTCUSDT","t":6646666776,"p":"77730.23000000","q":"0.00007000","T":1788333213158,"m":false,"M":true}}
{"type":"trade","received_at_ms":1788333212996,"data":{"e":"trade","E":1788333213159,"s":"BTCUSDT","t":6646666777,"p":"77730.23000000","q":"0.00007000","T":1788333213158,"m":false,"M":true}}
{"type":"trade","received_at_ms":1788333212996,"data":{"e":"trade","E":1788333213159,"s":"BTCUSDT","t":6646666778,"p":"77730.23000000","q":"0.00007000","T":1788333213158,"m":false,"M":true}}
{"type":"trade","received_at_ms":1788333212996,"data":{"e":"trade","E":1788333213159,"s":"BTCUSDT","t":6646666779,"p":"77730.23000000","q":"0.00007000","T":1788333213158,"m":false,"M":true}}
{"type":"trade","received_at_ms":1788333212996,"data":{"e":"trade","E":1788333213159,"s":"BTCUSDT","t":6646666780,"p":"77730.23000000","q":"0.00007000","T":1788333213158,"m":false,"M":true}}
{"type":"trade","received_at_ms":1788333212996,"data":{"e":"trade","E":1788333213159,"s":"BTCUSDT","t":6646666781,"p":"77730.45000000","q":"0.00085000","T":1788333213158,"m":false,"M":true}}
{"type":"trade","received_at_ms":1788333212996,"data":{"e":"trade","E":1788333213159,"s":"BTCUSDT","t":6646666782,"p":"77730.52000000","q":"0.00007000","T":1788333213158,"m":false,"M":true}}
{"type":"trade","received_at_ms":1788333212996,"data":{"e":"trade","E":1788333213159,"s":"BTCUSDT","t":6646666783,"p":"77730.52000000","q":"0.00007000","T":1788333213158,"m":false,"M":true}}
{"type":"trade","received_at_ms":1788333212996,"data":{"e":"trade","E":1788333213159,"s":"BTCUSDT","t":6646666784,"p":"77730.56000000","q":"0.00007000","T":1788333213158,"m":false,"M":true}}
{"type":"trade","received_at_ms":1788333212996,"data":{"e":"trade","E":1788333213159,"s":"BTCUSDT","t":6646666785,"p":"77730.56000000","q":"0.00007000","T":1788333213158,"m":false,"M":true}}
{"type":"trade","received_at_ms":1788333212996,"data":{"e":"trade","E":1788333213159,"s":"BTCUSDT","t":6646666786,"p":"77730.84000000","q":"0.00007000","T":1788333213158,"m":false,"M":true}}
{"type":"trade","received_at_ms":1788333212996,"data":{"e":"trade","E":1788333213159,"s":"BTCUSDT","t":6646666787,"p":"77730.84000000","q":"0.00007000","T":1788333213158,"m":false,"M":true}}
{"type":"trade","received_at_ms":1788333212996,"data":{"e":"trade","E":1788333213159,"s":"BTCUSDT","t":6646666788,"p":"77731.19000000","q":"0.00008000","T":1788333213158,"m":false,"M":true}}
{"type":"trade","received_at_ms":1788333212996,"data":{"e":"trade","E":1788333213159,"s":"BTCUSDT","t":6646666789,"p":"77731.32000000","q":"0.00051000","T":1788333213158,"m":false,"M":true}}
{"type":"trade","received_at_ms":1788333212996,"data":{"e":"trade","E":1788333213159,"s":"BTCUSDT","t":6646666790,"p":"77731.33000000","q":"0.00024000","T":1788333213158,"m":false,"M":true}}
{"type":"trade","received_at_ms":1788333212996,"data":{"e":"trade","E":1788333213159,"s":"BTCUSDT","t":6646666791,"p":"77731.36000000","q":"0.00010000","T":1788333213158,"m":false,"M":true}}
{"type":"trade","received_at_ms":1788333212996,"data":{"e":"trade","E":1788333213159,"s":"BTCUSDT","t":6646666792,"p":"77731.73000000","q":"0.00321000","T":1788333213158,"m":false,"M":true}}
{"type":"trade","received_at_ms":1788333212996,"data":{"e":"trade","E":1788333213159,"s":"BTCUSDT","t":6646666793,"p":"77731.76000000","q":"0.00007000","T":1788333213158,"m":false,"M":true}}
{"type":"trade","received_at_ms":1788333212996,"data":{"e":"trade","E":1788333213159,"s":"BTCUSDT","t":6646666794,"p":"77731.76000000","q":"0.00007000","T":1788333213158,"m":false,"M":true}}
{"type":"trade","received_at_ms":1788333212996,"data":{"e":"trade","E":1788333213159,"s":"BTCUSDT","t":6646666795,"p":"77731.92000000","q":"0.00008000","T":1788333213158,"m":false,"M":true}}
{"type":"trade","received_at_ms":1788333212996,"data":{"e":"trade","E":1788333213159,"s":"BTCUSDT","t":6646666796,"p":"77731.99000000","q":"0.00007000","T":1788333213158,"m":false,"M":true}}
{"type":"trade","received_at_ms":1788333212996,"data":{"e":"trade","E":1788333213159,"s":"BTCUSDT","t":6646666797,"p":"77731.99000000","q":"0.00007000","T":1788333213158,"m":false,"M":true}}
{"type":"trade","received_at_ms":1788333212996,"data":{"e":"trade","E":1788333213159,"s":"BTCUSDT","t":6646666798,"p":"77731.99000000","q":"0.00007000","T":1788333213158,"m":false,"M":true}}
{"type":"trade","received_at_ms":1788333212996,"data":{"e":"trade","E":1788333213159,"s":"BTCUSDT","t":6646666799,"p":"77731.99000000","q":"0.00007000","T":1788333213158,"m":false,"M":true}}
{"type":"trade","received_at_ms":1788333212996,"data":{"e":"trade","E":1788333213159,"s":"BTCUSDT","t":6646666800,"p":"77731.99000000","q":"0.00007000","T":1788333213158,"m":false,"M":true}}
{"type":"trade","received_at_ms":1788333212996,"data":{"e":"trade","E":1788333213159,"s":"BTCUSDT","t":6646666801,"p":"77732.00000000","q":"0.00100000","T":1788333213158,"m":false,"M":true}}
{"type":"trade","received_at_ms":1788333212996,"data":{"e":"trade","E":1788333213159,"s":"BTCUSDT","t":6646666802,"p":"77732.00000000","q":"0.00597000","T":1788333213158,"m":false,"M":true}}
{"type":"trade","received_at_ms":1788333213037,"data":{"e":"trade","E":1788333213203,"s":"BTCUSDT","t":6646666803,"p":"77732.00000000","q":"0.00403000","T":1788333213203,"m":false,"M":true}}
{"type":"trade","received_at_ms":1788333213037,"data":{"e":"trade","E":1788333213203,"s":"BTCUSDT","t":6646666804,"p":"77732.00000000","q":"0.00500000","T":1788333213203,"m":false,"M":true}}
{"type":"trade","received_at_ms":1788333213037,"data":{"e":"trade","E":1788333213203,"s":"BTCUSDT","t":6646666805,"p":"77732.00000000","q":"0.00500000","T":1788333213203,"m":false,"M":true}}
{"type":"trade","received_at_ms":1788333213037,"data":{"e":"trade","E":1788333213203,"s":"BTCUSDT","t":6646666806,"p":"77732.00000000","q":"0.01000000","T":1788333213203,"m":false,"M":true}}
{"type":"trade","received_at_ms":1788333213037,"data":{"e":"trade","E":1788333213203,"s":"BTCUSDT","t":6646666807,"p":"77732.00000000","q":"0.00007000","T":1788333213203,"m":false,"M":true}}
{"type":"trade","received_at_ms":1788333213037,"data":{"e":"trade","E":1788333213203,"s":"BTCUSDT","t":6646666808,"p":"77732.00000000","q":"0.00007000","T":1788333213203,"m":false,"M":true}}
{"type":"trade","received_at_ms":1788333213037,"data":{"e":"trade","E":1788333213203,"s":"BTCUSDT","t":6646666809,"p":"77732.00000000","q":"0.00150000","T":1788333213203,"m":false,"M":true}}
{"type":"trade","received_at_ms":1788333213037,"data":{"e":"trade","E":1788333213203,"s":"BTCUSDT","t":6646666810,"p":"77732.00000000","q":"0.00007000","T":1788333213203,"m":false,"M":true}}
{"type":"depth","received_at_ms":1788333213047,"data":{"e":"depthUpdate","E":1788333213214,"s":"BTCUSDT","U":99556337601,"u":99556338874,"b":[["77731.99000000","3.24538000"],["77731.98000000","0.00041000"],["77731.97000000","0.00013000"],["77731.91000000","0.00000000"],["77731.75000000","0.00000000"],["77731.72000000","0.00000000"],["77730.83000000","0.00000000"],["77730.82000000","0.00000000"],["77730.59000000","0.00000000"],["77730.55000000","0.00021000"],["77730.54000000","0.00000000"],["77730.51000000","0.00000000"],["77730.23000000","0.00014000"],["77730.22000000","0.10336000"],["77730.21000000","0.39441000"],["77730.20000000","0.00000000"],["77730.19000000","0.00000000"],["77730.01000000","0.00014000"],["77730.00000000","0.07514000"],["77729.99000000","0.41327000"],["77729.98000000","0.00007000"],["77729.97000000","0.00000000"],["77729.95000000","0.00007000"],["77729.71000000","0.00000000"],["77729.59000000","0.00007000"],["77729.55000000","0.00400000"],["77729.50000000","0.00000000"],["77729.32000000","0.01322000"],["77729.28000000","0.00000000"],["77729.15000000","0.00007000"],["77729.14000000","0.00000000"],["77729.10000000","0.00000000"],["77728.87000000","0.00161000"],["77728.63000000","0.00000000"],["77728.32000000","0.00014000"],["77728.31000000","0.00000000"],["77728.04000000","0.00007000"],["77728.03000000","0.73876000"],["77728.02000000","0.71276000"],["77728.00000000","0.20458000"],["77727.99000000","0.40906000"],["77727.98000000","0.00000000"],["77727.97000000","0.00000000"],["77727.91000000","0.01200000"],["77727.90000000","0.00014000"],["77727.89000000","1.31485000"],["77727.88000000","0.41276000"],["77727.78000000","0.00000000"],["77727.77000000","0.00000000"],["77727.76000000","0.00000000"],["77727.75000000","0.49093000"],["77727.56000000","0.00643000"],["77727.55000000","0.00000000"],["77727.45000000","0.00000000"],["77727.41000000","0.00000000"],["77727.40000000","0.00000000"],["77727.32000000","0.00000000"],["77727.08000000","0.00000000"],["77727.00000000","0.00400000"],["77726.50000000","0.01701000"],["77726.43000000","0.00000000"],["77726.00000000","0.00000000"],["77725.99000000","0.15358000"],["77725.92000000","0.00007000"],["77725.86000000","0.00027000"],["77725.71000000","0.00000000"],["77725.70000000","0.00000000"],["77725.65000000","0.00000000"],["77725.08000000","0.00000000"],["77724.99000000","0.00014000"],["77724.22000000","0.00008000"],["77724.17000000","0.00000000"],["77724.16000000","0.00008000"],["77724.07000000","0.00007000"],["77724.01000000","0.63997000"],["77724.00000000","1.65496000"],["77723.87000000","0.00007000"],["77723.39000000","0.00044000"],["77723.11000000","0.00060000"],["77723.06000000","0.00000000"],["77722.46000000","0.12866000"],["77722.29000000","0.00007000"],["77722.22000000","0.00000000"],["77722.17000000","0.00000000"],["77722.15000000","0.00000000"],["77722.14000000","0.00000000"],["77721.99000000","0.00179000"],["77721.41000000","0.00117000"],["77721.32000000","0.00000000"],["77721.16000000","0.00000000"],["77720.96000000","0.00007000"],["77720.87000000","0.00000000"],["77720.73000000","0.00000000"],["77720.72000000","0.00000000"],["77720.25000000","0.00000000"],["77720.22000000","0.00000000"],["77720.05000000","0.00007000"],["77719.43000000","0.62947000"],["77719.34000000","0.00000000"],["77718.90000000","0.00007000"],["77718.88000000","0.00008000"],["77718.46000000","0.00000000"],["77718.27000000","0.00000000"],["77718.05000000","0.00000000"],["77717.99000000","0.00652000"],["77717.98000000","0.00000000"],["77716.09000000","0.34758000"],["77716.05000000","0.00000000"],["77714.86000000","0.00000000"],["77714.74000000","0.00000000"],["77714.44000000","0.00008000"],["77713.87000000","0.00000000"],["77713.31000000","0.10447000"],["77711.63000000","0.00000000"],["77711.37000000","0.10447000"],["77710.56000000","0.00008000"],["77710.44000000","0.00000000"],["77708.55000000","0.12868000"],["77706.67000000","0.34770000"],["77706.56000000","0.00060000"],["77706.37000000","0.00257000"],["77705.22000000","0.00000000"],["77704.32000000","0.16267000"],["77704.24000000","0.00008000"],["77703.28000000","0.00000000"],["77702.78000000","0.00008000"],["77702.67000000","0.00000000"],["77702.42000000","0.00000000"],["77699.45000000","0.33791000"],["77698.90000000","0.00008000"],["77698.79000000","0.00000000"],["77695.80000000","0.00000000"],["77695.01000000","0.00008000"],["77694.90000000","3.20708000"],["77693.56000000","0.80297000"],["77692.86000000","0.00000000"],["77692.62000000","0.00000000"],["77691.13000000","0.00008000"],["77691.01000000","0.00000000"],["77691.00000000","0.01000000"],["77690.76000000","0.00000000"],["77689.01000000","0.00000000"],["77689.00000000","0.00000000"],["77687.13000000","0.00000000"],["77685.45000000","0.00000000"],["77685.15000000","0.00000000"],["77680.34000000","0.80311000"],["77679.58000000","0.00000000"],["77677.09000000","0.00000000"],["77675.63000000","0.00436000"],["77664.61000000","1.67587000"],["77664.60000000","2.25374000"],["77664.50000000","0.00000000"],["77664.22000000","0.00000000"],["77663.27000000","0.00000000"],["77661.96000000","0.00000000"],["77659.03000000","0.00321000"],["77654.01000000","0.00000000"],["77653.33000000","0.00007000"],["77652.26000000","0.00008000"],["77644.27000000","0.00000000"],["77642.04000000","0.00000000"],["77642.02000000","0.00000000"],["77637.04000000","0.00000000"],["77634.72000000","0.21065000"],["77634.01000000","0.00000000"],["77626.69000000","0.00126000"],["77622.30000000","0.04496000"],["77614.59000000","0.00000000"],["77607.76000000","0.18488000"],["77604.01000000","0.00012000"],["77600.01000000","0.00000000"],["77574.53000000","0.00008000"],["77567.56000000","0.00160000"],["77566.55000000","0.00000000"],["77558.99000000","1.20000000"],["77541.03000000","0.00000000"],["77533.12000000","0.00010000"],["77511.97000000","0.00000000"],["77508.03000000","0.00024000"],["77507.17000000","0.00085000"],["77497.77000000","0.00008000"],["77496.80000000","0.00008000"],["77496.65000000","0.00008000"],["77487.27000000","0.00000000"],["77485.65000000","0.00000000"],["77457.63000000","0.00000000"],["77419.07000000","0.00008000"],["77411.10000000","0.00000000"],["77341.84000000","0.00000000"],["77341.34000000","0.00008000"],["77331.83000000","0.00000000"],["77328.87000000","0.00000000"],["77263.61000000","0.00008000"],["77255.66000000","0.00000000"],["77234.52000000","0.00000000"],["77185.88000000","0.00008000"],["77177.94000000","0.00000000"],["77163.76000000","9.72421000"],["77108.15000000","0.00008000"],["77100.21000000","0.00000000"],["77028.20000000","0.00032000"],["76498.62000000","0.00000000"],["76498.61000000","0.00000000"],["69958.80000000","0.00032000"],["69955.20000000","0.00000000"],["69954.96000000","0.00000000"],["62182.20000000","0.00000000"]],"a":[["77728.00000000","0.00000000"],["77728.01000000","0.00000000"],["77728.03000000","0.00000000"],["77728.32000000","0.00000000"],["77728.64000000","0.00000000"],["77729.11000000","0.00000000"],["77729.15000000","0.00000000"],["77729.16000000","0.00000000"],["77729.51000000","0.00000000"],["77729.60000000","0.00000000"],["77729.72000000","0.00000000"],["77729.99000000","0.00000000"],["77730.00000000","0.00000000"],["77730.01000000","0.00000000"],["77730.21000000","0.00000000"],["77730.22000000","0.00000000"],["77730.23000000","0.00000000"],["77730.45000000","0.00000000"],["77730.51000000","0.00000000"],["77730.52000000","0.00000000"],["77730.55000000","0.00000000"],["77730.56000000","0.00000000"],["77730.83000000","0.00000000"],["77730.84000000","0.00000000"],["77731.19000000","0.00000000"],["77731.32000000","0.00000000"],["77731.33000000","0.00000000"],["77731.36000000","0.00000000"],["77731.73000000","0.00000000"],["77731.75000000","0.00000000"],["77731.76000000","0.00000000"],["77731.92000000","0.00000000"],["77731.99000000","0.00000000"],["77732.00000000","0.09453000"],["77732.01000000","0.00063000"],["77732.15000000","0.00536000"],["77732.26000000","0.00007000"],["77732.75000000","0.00007000"],["77732.76000000","0.00000000"],["77732.85000000","0.00000000"],["77733.13000000","0.00000000"],["77733.36000000","0.00014000"],["77733.40000000","0.00885000"],["77733.53000000","0.00000000"],["77733.82000000","0.00000000"],["77733.87000000","0.00014000"],["77733.99000000","0.00014000"],["77734.00000000","0.03014000"],["77734.24000000","0.00000000"],["77734.25000000","0.00000000"],["77734.40000000","0.00000000"],["77734.67000000","0.00000000"],["77734.75000000","0.00014000"],["77734.76000000","0.01266000"],["77735.77000000","0.00000000"],["77735.81000000","0.00014000"],["77735.82000000","0.11435000"],["77735.88000000","0.00000000"],["77735.91000000","0.00000000"],["77735.92000000","0.00000000"],["77735.99000000","0.00014000"],["77736.20000000","0.00014000"],["77736.43000000","0.00000000"],["77736.84000000","0.00000000"],["77736.87000000","0.00000000"],["77736.99000000","0.00007000"],["77737.00000000","0.11435000"],["77737.07000000","0.00321000"],["77737.38000000","0.00000000"],["77737.55000000","0.00000000"],["77737.70000000","0.00000000"],["77737.77000000","0.00000000"],["77737.78000000","0.16877000"],["77737.94000000","0.00000000"],["77737.95000000","0.00000000"],["77737.99000000","0.00000000"],["77738.23000000","0.00000000"],["77738.40000000","0.11443000"],["77738.88000000","0.00000000"],["77738.89000000","0.07000000"],["77739.07000000","0.00000000"],["77739.10000000","0.02894000"],["77739.26000000","0.00000000"],["77739.35000000","0.00000000"],["77739.49000000","0.00000000"],["77739.75000000","0.11435000"],["77739.76000000","0.00000000"],["77739.77000000","0.00008000"],["77739.79000000","0.00000000"],["77739.82000000","0.12863000"],["77739.89000000","0.08411000"],["77740.14000000","0.00014000"],["77740.15000000","0.00000000"],["77740.18000000","0.00000000"],["77740.22000000","0.00643000"],["77740.30000000","0.00000000"],["77740.44000000","0.00000000"],["77740.45000000","0.00000000"],["77740.58000000","0.00000000"],["77740.59000000","0.00400000"],["77740.63000000","0.00000000"],["77740.64000000","0.00000000"],["77740.66000000","0.00200000"],["77740.67000000","0.08000000"],["77740.68000000","0.58499000"],["77740.76000000","0.32173000"],["77740.98000000","0.00000000"],["77741.19000000","0.00000000"],["77741.21000000","0.00000000"],["77741.33000000","1.93226000"],["77741.34000000","1.31471000"],["77741.35000000","0.00000000"],["77741.49000000","0.00000000"],["77741.55000000","0.00008000"],["77741.75000000","0.00000000"],["77742.01000000","0.00000000"],["77742.85000000","0.00000000"],["77742.92000000","0.00000000"],["77743.20000000","0.00000000"],["77743.98000000","0.00000000"],["77743.99000000","0.00643000"],["77744.00000000","0.03014000"],["77744.52000000","0.00000000"],["77744.61000000","0.04604000"],["77745.43000000","0.00000000"],["77745.55000000","0.00008000"],["77746.22000000","0.37338000"],["77746.23000000","0.00000000"],["77749.32000000","0.00000000"],["77749.43000000","0.00008000"],["77749.95000000","0.00000000"],["77749.96000000","0.51153000"],["77750.35000000","0.00000000"],["77751.23000000","0.00000000"],["77751.34000000","0.00000000"],["77751.73000000","0.10442000"],["77751.95000000","0.00038000"],["77752.13000000","0.00000000"],["77752.14000000","0.50973000"],["77752.83000000","0.00000000"],["77753.20000000","0.00000000"],["77753.26000000","0.00000000"],["77753.27000000","0.00000000"],["77753.32000000","0.00008000"],["77753.67000000","0.10462000"],["77753.99000000","0.45684000"],["77754.08000000","0.00000000"],["77755.27000000","0.12860000"],["77755.45000000","0.00000000"],["77755.78000000","0.64354000"],["77755.79000000","0.34535000"],["77756.45000000","0.25741000"],["77756.89000000","0.00000000"],["77757.09000000","0.00000000"],["77757.21000000","0.00008000"],["77757.92000000","0.00008000"],["77758.89000000","0.00000000"],["77759.15000000","0.00000000"],["77759.40000000","0.00000000"],["77760.66000000","0.00000000"],["77760.83000000","0.00000000"],["77760.98000000","0.00000000"],["77761.09000000","0.00008000"],["77761.57000000","0.00000000"],["77762.10000000","0.00400000"],["77762.66000000","0.00000000"],["77762.81000000","0.00000000"],["77764.86000000","0.00000000"],["77764.98000000","0.00008000"],["77767.00000000","0.00000000"],["77767.72000000","0.00014000"],["77768.86000000","0.00008000"],["77769.00000000","0.00000000"],["77770.00000000","0.03059000"],["77770.77000000","0.00007000"],["77770.78000000","0.80217000"],["77771.00000000","0.01000000"],["77771.18000000","0.64321000"],["77771.63000000","0.34733000"],["77771.66000000","0.00007000"],["77772.36000000","0.00000000"],["77772.74000000","0.00000000"],["77775.60000000","0.00000000"],["77779.87000000","0.00000000"],["77780.24000000","0.34729000"],["77783.33000000","0.00000000"],["77783.77000000","0.00000000"],["77784.00000000","0.83204000"],["77787.52000000","0.00319000"],["77787.53000000","0.00000000"],["77789.64000000","0.00000000"],["77791.99000000","0.00350000"],["77794.00000000","0.03008000"],["77797.21000000","0.80190000"],["77803.88000000","1.27303000"],["77809.85000000","0.39595000"],["77815.50000000","0.00007000"],["77821.72000000","0.00000000"],["77828.41000000","0.05146000"],["77842.42000000","0.00012000"],["77844.77000000","0.00019000"],["77845.51000000","0.00000000"],["77861.97000000","0.00000000"],["77865.28000000","0.00143000"],["77867.40000000","0.00128000"],["77877.32000000","0.00000000"],["77885.46000000","0.00008000"],["77922.22000000","0.00000000"],["77930.34000000","0.02015000"],["77945.86000000","0.00000000"],["77952.29000000","0.00007000"],["77952.53000000","0.00000000"],["77955.05000000","0.00000000"],["77956.17000000","0.00007000"],["77963.19000000","0.00008000"],["77966.47000000","0.00007000"],["77977.28000000","0.00385000"],["78032.77000000","0.00000000"],["78040.92000000","0.00008000"],["78041.39000000","0.16870000"],["78110.49000000","0.00000000"],["78118.65000000","0.00008000"],["78188.21000000","0.00000000"],["78196.38000000","0.00008000"],["78343.66000000","0.00000000"],["78351.84000000","0.00008000"]]}}
{"type":"trade","received_at_ms":1788333213098,"data":{"e":"trade","E":1788333213265,"s":"BTCUSDT","t":6646666811,"p":"77731.99000000","q":"0.00100000","T":1788333213265,"m":true,"M":true}}
{"type":"depth","received_at_ms":1788333213146,"data":{"e":"depthUpdate","E":1788333213314,"s":"BTCUSDT","U":99556338875,"u":99556339034,"b":[["77731.99000000","3.31285000"],["77730.55000000","0.00007000"],["77730.22000000","0.10350000"],["77730.21000000","0.39441000"],["77730.00000000","0.07528000"],["77729.99000000","0.41327000"],["77729.32000000","0.01336000"],["77728.03000000","0.73890000"],["77728.02000000","0.71276000"],["77727.99000000","0.38892000"],["77727.90000000","0.00000000"],["77727.89000000","1.31471000"],["77727.88000000","0.41262000"],["77727.75000000","0.48046000"],["77726.50000000","0.00000000"],["77725.99000000","0.15351000"],["77725.26000000","0.00000000"],["77724.21000000","0.00020000"],["77724.01000000","0.61956000"],["77719.97000000","0.00000000"],["77716.44000000","0.00020000"],["77712.20000000","0.00000000"],["77708.67000000","0.00020000"],["77706.22000000","0.00189000"],["77704.43000000","0.00000000"],["77700.89000000","0.00020000"],["77696.65000000","0.00000000"],["77693.00000000","0.01000000"],["77691.00000000","0.00000000"],["77683.58000000","0.25000000"],["77682.98000000","1.29759000"],["77658.58000000","0.12782000"],["77630.98000000","0.00000000"],["77514.75000000","0.00000000"],["62185.59000000","0.00000000"]],"a":[["77732.00000000","0.10779000"],["77732.01000000","0.00070000"],["77732.15000000","0.00014000"],["77733.36000000","0.00000000"],["77733.40000000","0.00028000"],["77733.41000000","0.11516000"],["77733.87000000","0.00000000"],["77734.00000000","0.03014000"],["77734.64000000","0.00014000"],["77734.75000000","0.00000000"],["77734.76000000","0.01280000"],["77734.81000000","0.00007000"],["77734.82000000","0.11516000"],["77735.82000000","0.11449000"],["77735.89000000","0.00014000"],["77735.98000000","0.00007000"],["77735.99000000","0.18749000"],["77736.00000000","0.03021000"],["77736.99000000","0.00000000"],["77739.42000000","0.00144000"],["77739.74000000","0.01200000"],["77740.66000000","0.00200000"],["77740.68000000","1.07054000"],["77741.88000000","0.00187000"],["77742.83000000","0.00400000"],["77748.40000000","0.00000000"],["77749.83000000","0.00000000"],["77751.11000000","0.09622000"],["77753.06000000","0.00128000"],["77755.77000000","0.64686000"],["77755.79000000","0.00000000"],["77759.17000000","1.29632000"],["77763.53000000","0.00335000"],["77782.64000000","0.47543000"],["77787.77000000","0.25000000"],["77826.12000000","0.00411000"],["77849.52000000","0.00032000"],["78000.19000000","0.07576000"]]}}
{"type":"depth","received_at_ms":1788333213246,"data":{"e":"depthUpdate","E":1788333213414,"s":"BTCUSDT","U":99556339035,"u":99556339147,"b":[["77731.99000000","3.42967000"],["77731.98000000","0.00027000"],["77731.97000000","0.00027000"],["77731.96000000","0.04345000"],["77731.95000000","0.05007000"],["77730.74000000","0.01701000"],["77730.22000000","0.07528000"],["77730.01000000","0.00000000"],["77730.00000000","0.07514000"],["77729.99000000","0.41334000"],["77729.50000000","0.02041000"],["77729.32000000","0.01343000"],["77728.25000000","0.02041000"],["77728.04000000","0.00000000"],["77727.75000000","0.40695000"],["77723.99000000","0.10436000"],["77723.87000000","0.00000000"],["77723.54000000","0.00000000"],["77690.55000000","0.00000000"],["77677.74000000","0.00100000"],["77628.15000000","0.04532000"],["77607.12000000","0.00000000"],["77489.76000000","0.00000000"],["69958.80000000","0.00064000"]],"a":[["77732.00000000","0.14254000"],["77732.01000000","0.00091000"],["77732.15000000","0.00000000"],["77732.16000000","0.06494000"],["77732.97000000","0.00014000"],["77732.98000000","0.00000000"],["77733.39000000","0.00014000"],["77733.40000000","0.08531000"],["77733.41000000","0.11530000"],["77733.56000000","0.00000000"],["77733.68000000","0.00000000"],["77734.00000000","0.03014000"],["77734.64000000","0.00000000"],["77734.76000000","0.01280000"],["77734.81000000","0.00014000"],["77734.82000000","0.11530000"],["77735.81000000","0.00000000"],["77735.82000000","0.11449000"],["77735.89000000","0.00000000"],["77735.98000000","0.00000000"],["77735.99000000","0.18756000"],["77736.39000000","0.00522000"],["77737.00000000","0.11449000"],["77737.64000000","0.00871000"],["77738.88000000","0.01045000"],["77739.74000000","0.00400000"],["77739.89000000","0.08205000"],["77740.13000000","0.01045000"],["77740.59000000","0.00800000"],["77740.68000000","0.88620000"],["77742.70000000","0.00054000"],["77742.86000000","0.00048000"],["77745.94000000","0.00000000"],["77765.64000000","0.00000000"],["77896.04000000","0.00100000"],["77996.77000000","0.00000000"],["78158.52000000","0.00384000"],["78230.29000000","0.00100000"]]}}
{"type":"depth","received_at_ms":1788333213347,"data":{"e":"depthUpdate","E":1788333213514,"s":"BTCUSDT","U":99556339148,"u":99556339202,"b":[["77731.99000000","3.42981000"],["77731.96000000","0.25891000"],["77731.95000000","0.00021000"],["77730.75000000","0.00014000"],["77730.74000000","0.01715000"],["77730.01000000","0.00007000"],["77729.99000000","0.41320000"],["77729.32000000","0.01329000"],["77728.03000000","0.73876000"],["77728.02000000","0.71262000"],["77698.60000000","0.00012000"],["77323.95000000","0.00387000"],["69958.80000000","0.00080000"],["62185.60000000","0.00032000"]],"a":[["77732.00000000","0.14247000"],["77732.01000000","0.00084000"],["77732.15000000","0.00014000"],["77732.16000000","0.06508000"],["77732.97000000","0.00000000"],["77733.39000000","0.00000000"],["77733.40000000","0.00028000"],["77735.81000000","0.00007000"],["77736.00000000","0.03007000"],["77737.00000000","0.11435000"],["77739.89000000","0.00000000"],["77773.70000000","0.00012000"]]}}
{"type":"depth","received_at_ms":1788333213447,"data":{"e":"depthUpdate","E":1788333213614,"s":"BTCUSDT","U":99556339203,"u":99556339251,"b":[["77731.96000000","0.25898000"],["77731.95000000","0.00007000"],["77730.81000000","0.00000000"],["77730.80000000","0.00007000"],["77730.76000000","0.00014000"],["77730.75000000","0.00000000"],["77730.01000000","0.00007000"],["77729.99000000","0.41334000"],["77727.75000000","0.38695000"],["77724.00000000","1.65489000"],["77716.77000000","0.00007000"],["77713.36000000","0.00007000"],["77709.13000000","0.00007000"],["77532.01000000","0.00811000"],["77530.01000000","0.00000000"],["69958.80000000","0.00096000"],["62186.00000000","0.00000000"],["62185.60000000","0.00000000"]],"a":[["77732.00000000","0.14254000"],["77732.01000000","0.00091000"],["77732.16000000","0.06508000"],["77733.39000000","0.00007000"],["77733.40000000","0.08519000"],["77735.81000000","0.00000000"],["77736.00000000","0.03021000"],["77740.23000000","0.00000000"],["77744.47000000","0.00007000"],["77826.90000000","2.15325000"]]}}
{"type":"trade","received_at_ms":1788333213472,"data":{"e":"trade","E":1788333213638,"s":"BTCUSDT","t":6646666812,"p":"77732.00000000","q":"0.00007000","T":1788333213638,"m":false,"M":true}}
{"type":"trade","received_at_ms":1788333213472,"data":{"e":"trade","E":1788333213638,"s":"BTCUSDT","t":6646666813,"p":"77732.00000000","q":"0.00007000","T":1788333213638,"m":false,"M":true}}
{"type":"trade","received_at_ms":1788333213472,"data":{"e":"trade","E":1788333213638,"s":"BTCUSDT","t":6646666814,"p":"77732.00000000","q":"0.00007000","T":1788333213638,"m":false,"M":true}}
{"type":"trade","received_at_ms":1788333213472,"data":{"e":"trade","E":1788333213638,"s":"BTCUSDT","t":6646666815,"p":"77732.00000000","q":"0.00007000","T":1788333213638,"m":false,"M":true}}
{"type":"trade","received_at_ms":1788333213472,"data":{"e":"trade","E":1788333213638,"s":"BTCUSDT","t":6646666816,"p":"77732.00000000","q":"0.00001000","T":1788333213638,"m":false,"M":true}}
{"type":"depth","received_at_ms":1788333213546,"data":{"e":"depthUpdate","E":1788333213714,"s":"BTCUSDT","U":99556339252,"u":99556339293,"b":[["77731.99000000","3.44967000"],["77731.96000000","0.25891000"],["77730.80000000","0.00000000"],["77730.76000000","0.00000000"],["77730.75000000","0.00007000"],["77730.29000000","0.00007000"],["77729.50000000","0.02055000"],["77727.75000000","0.37695000"],["77665.11000000","0.00386000"],["77608.00000000","0.03012000"],["77598.54000000","0.00000000"],["69958.80000000","0.00121000"],["69958.00000000","0.00217000"],["62185.59000000","0.00000000"]],"a":[["77732.00000000","0.14246000"],["77732.16000000","0.06508000"],["77733.39000000","0.00014000"],["77733.40000000","0.08533000"],["77736.00000000","0.03007000"],["77759.41000000","0.02038000"],["77761.13000000","0.09558000"],["77763.06000000","0.05332000"],["77795.01000000","0.00411000"],["77842.42000000","0.00000000"],["77844.77000000","0.00000000"],["77846.42000000","0.00012000"],["77849.52000000","0.00000000"]]}}
{"type":"depth","received_at_ms":1788333213647,"data":{"e":"depthUpdate","E":1788333213814,"s":"BTCUSDT","U":99556339294,"u":99556339302,"b":[["77731.99000000","3.45975000"],["77594.80000000","0.00000000"],["69958.80000000","0.00153000"]],"a":[["77765.74000000","0.00000000"],["77848.77000000","0.00019000"],["77853.52000000","0.00032000"],["78897.98000000","0.00030000"]]}}
{"type":"depth","received_at_ms":1788333213748,"data":{"e":"depthUpdate","E":1788333213914,"s":"BTCUSDT","U":99556339303,"u":99556339310,"b":[["77731.99000000","3.46575000"],["77731.96000000","0.25898000"],["77730.86000000","0.00007000"],["77730.85000000","0.05000000"],["77730.75000000","0.00000000"],["77727.75000000","0.37095000"],["77600.48000000","0.02015000"],["69958.80000000","0.00137000"]],"a":[["77774.74000000","0.00672000"]]}}
{"type":"trade","received_at_ms":1788333213775,"data":{"e":"trade","E":1788333213942,"s":"BTCUSDT","t":6646666817,"p":"77732.00000000","q":"0.00006000","T":1788333213941,"m":false,"M":true}}
{"type":"trade","received_at_ms":1788333213775,"data":{"e":"trade","E":1788333213942,"s":"BTCUSDT","t":6646666818,"p":"77732.00000000","q":"0.00007000","T":1788333213941,"m":false,"M":true}}
{"type":"trade","received_at_ms":1788333213775,"data":{"e":"trade","E":1788333213942,"s":"BTCUSDT","t":6646666819,"p":"77732.00000000","q":"0.00007000","T":1788333213941,"m":false,"M":true}}
{"type":"trade","received_at_ms":1788333213775,"data":{"e":"trade","E":1788333213942,"s":"BTCUSDT","t":6646666820,"p":"77732.00000000","q":"0.00007000","T":1788333213941,"m":false,"M":true}}
{"type":"trade","received_at_ms":1788333213775,"data":{"e":"trade","E":1788333213942,"s":"BTCUSDT","t":6646666821,"p":"77732.00000000","q":"0.00007000","T":1788333213941,"m":false,"M":true}}
{"type":"trade","received_at_ms":1788333213775,"data":{"e":"trade","E":1788333213942,"s":"BTCUSDT","t":6646666822,"p":"77732.00000000","q":"0.02539000","T":1788333213941,"m":false,"M":true}}
{"type":"depth","received_at_ms":1788333213851,"data":{"e":"depthUpdate","E":1788333214014,"s":"BTCUSDT","U":99556339311,"u":99556339336,"b":[["77731.96000000","0.25898000"],["77730.87000000","0.00257000"],["77730.30000000","0.01286000"],["77727.99000000","0.38635000"],["77727.56000000","0.00000000"],["77726.52000000","0.00000000"],["76566.01000000","0.00030000"],["69958.80000000","0.00160000"],["69958.79000000","0.00009000"],["62186.00000000","0.00000000"],["62185.60000000","0.00032000"]],"a":[["77732.00000000","0.11701000"],["77740.22000000","0.00000000"],["77741.32000000","0.00643000"],["77758.57000000","0.00000000"],["77759.41000000","0.00000000"],["77763.06000000","0.00000000"]]}}
{"type":"depth","received_at_ms":1788333213947,"data":{"e":"depthUpdate","E":1788333214114,"s":"BTCUSDT","U":99556339337,"u":99556339371,"b":[["77731.96000000","0.25898000"],["77730.86000000","0.00000000"],["77730.85000000","0.00014000"],["77730.81000000","0.00014000"],["77730.80000000","0.05007000"],["77730.75000000","0.05000000"],["77730.74000000","0.01722000"],["77730.01000000","0.00000000"],["77729.50000000","0.02041000"],["77727.75000000","0.37081000"],["77724.99000000","0.00007000"],["77724.02000000","0.37338000"],["77600.48000000","0.00000000"],["77542.04000000","0.00000000"],["77519.71000000","0.02015000"],["73331.84000000","0.00000000"],["69958.80000000","0.00176000"]],"a":[["77758.68000000","0.76033000"],["77824.13000000","0.00000000"],["77828.38000000","0.00025000"]]}}
{"type":"depth","received_at_ms":1788333214046,"data":{"e":"depthUpdate","E":1788333214214,"s":"BTCUSDT","U":99556339372,"u":99556339407,"b":[["77731.96000000","0.25905000"],["77730.96000000","0.00014000"],["77730.95000000","0.05000000"],["77730.85000000","0.00000000"],["77730.81000000","0.00000000"],["77730.80000000","0.00021000"],["77730.75000000","0.00014000"],["77729.99000000","0.41320000"],["77720.00000000","0.00265000"],["77710.00000000","0.00500000"],["77708.00000000","0.70500000"],["77706.00000000","0.00500000"],["77646.16000000","0.00007000"],["77592.33000000","0.00000000"],["77558.15000000","0.02015000"],["77032.40000000","0.00010000"],["69958.80000000","0.00176000"],["62185.60000000","0.00000000"]],"a":[]}}
{"type":"trade","received_at_ms":1788333214092,"data":{"e":"trade","E":1788333214257,"s":"BTCUSDT","t":6646666823,"p":"77732.00000000","q":"0.00200000","T":1788333214257,"m":false,"M":true}}
{"type":"trade","received_at_ms":1788333214092,"data":{"e":"trade","E":1788333214257,"s":"BTCUSDT","t":6646666824,"p":"77732.00000000","q":"0.00200000","T":1788333214257,"m":false,"M":true}}
{"type":"trade","received_at_ms":1788333214092,"data":{"e":"trade","E":1788333214257,"s":"BTCUSDT","t":6646666825,"p":"77732.00000000","q":"0.00200000","T":1788333214257,"m":false,"M":true}}
{"type":"trade","received_at_ms":1788333214092,"data":{"e":"trade","E":1788333214257,"s":"BTCUSDT","t":6646666826,"p":"77732.00000000","q":"0.00200000","T":1788333214257,"m":false,"M":true}}
{"type":"trade","received_at_ms":1788333214092,"data":{"e":"trade","E":1788333214257,"s":"BTCUSDT","t":6646666827,"p":"77732.00000000","q":"0.00200000","T":1788333214257,"m":false,"M":true}}
{"type":"trade","received_at_ms":1788333214092,"data":{"e":"trade","E":1788333214257,"s":"BTCUSDT","t":6646666828,"p":"77732.00000000","q":"0.00200000","T":1788333214257,"m":false,"M":true}}
{"type":"trade","received_at_ms":1788333214092,"data":{"e":"trade","E":1788333214258,"s":"BTCUSDT","t":6646666829,"p":"77732.00000000","q":"0.00200000","T":1788333214257,"m":false,"M":true}}
{"type":"trade","received_at_ms":1788333214092,"data":{"e":"trade","E":1788333214258,"s":"BTCUSDT","t":6646666830,"p":"77732.00000000","q":"0.00200000","T":1788333214257,"m":false,"M":true}}
{"type":"trade","received_at_ms":1788333214092,"data":{"e":"trade","E":1788333214258,"s":"BTCUSDT","t":6646666831,"p":"77732.00000000","q":"0.00200000","T":1788333214257,"m":false,"M":true}}
{"type":"trade","received_at_ms":1788333214092,"data":{"e":"trade","E":1788333214258,"s":"BTCUSDT","t":6646666832,"p":"77732.00000000","q":"0.00200000","T":1788333214257,"m":false,"M":true}}
{"type":"trade","received_at_ms":1788333214092,"data":{"e":"trade","E":1788333214259,"s":"BTCUSDT","t":6646666833,"p":"77732.00000000","q":"0.00200000","T":1788333214259,"m":false,"M":true}}
{"type":"trade","received_at_ms":1788333214094,"data":{"e":"trade","E":1788333214259,"s":"BTCUSDT","t":6646666834,"p":"77732.00000000","q":"0.00200000","T":1788333214259,"m":false,"M":true}}
{"type":"trade","received_at_ms":1788333214094,"data":{"e":"trade","E":1788333214259,"s":"BTCUSDT","t":6646666835,"p":"77732.00000000","q":"0.00200000","T":1788333214259,"m":false,"M":true}}
{"type":"depth","received_at_ms":1788333214151,"data":{"e":"depthUpdate","E":1788333214314,"s":"BTCUSDT","U":99556339408,"u":99556339508,"b":[["77731.99000000","3.76582000"],["77731.96000000","0.25898000"],["77730.96000000","0.00000000"],["77730.95000000","0.00014000"],["77730.80000000","0.00000000"],["77730.75000000","0.00014000"],["77730.30000000","0.01300000"],["77730.01000000","0.00007000"],["77727.75000000","0.07081000"],["77727.22000000","0.00116000"],["77725.99000000","0.15344000"],["77724.99000000","0.00000000"],["77724.03000000","0.37338000"],["77724.02000000","0.00000000"],["77714.09000000","0.00000000"],["77697.66000000","0.00000000"],["77675.24000000","0.00000000"],["77655.98000000","1.61330000"],["77653.39000000","0.00000000"],["77644.15000000","0.00000000"],["77558.15000000","0.00000000"],["77543.64000000","0.02015000"],["69958.80000000","0.00192000"],["69958.79000000","0.00000000"],["62186.00000000","0.00000000"],["62185.59000000","0.00000000"],["62182.00000000","0.00000000"]],"a":[["77732.00000000","0.09101000"],["77732.01000000","0.00084000"],["77732.15000000","0.00000000"],["77732.16000000","0.00014000"],["77735.81000000","0.00007000"],["77736.20000000","0.00014000"],["77739.33000000","0.08205000"],["77739.61000000","0.00000000"],["77740.41000000","0.00206000"],["77748.20000000","0.03257000"],["77748.50000000","0.00000000"],["77749.56000000","0.00000000"],["77756.13000000","0.00000000"],["77759.72000000","0.00000000"],["77761.13000000","0.00000000"],["77761.33000000","0.09778000"],["77763.38000000","0.00000000"],["77795.01000000","0.00000000"],["77826.12000000","0.00000000"],["77860.06000000","0.00000000"]]}}
{"type":"depth","received_at_ms":1788333214247,"data":{"e":"depthUpdate","E":1788333214414,"s":"BTCUSDT","U":99556339509,"u":99556339544,"b":[["77731.96000000","0.25898000"],["77730.95000000","0.00000000"],["77730.91000000","0.00007000"],["77730.90000000","0.05000000"],["77730.75000000","0.00000000"],["77727.99000000","0.38628000"],["77727.91000000","0.00000000"],["77724.22000000","0.00408000"],["69958.80000000","0.00192000"]],"a":[["77732.00000000","0.09125000"],["77732.16000000","0.00000000"],["77733.39000000","0.00014000"],["77733.40000000","0.08533000"],["77735.81000000","0.00014000"],["77735.98000000","0.00000000"],["77736.00000000","0.03021000"],["77748.20000000","0.03000000"]]}}
{"type":"depth","received_at_ms":1788333214347,"data":{"e":"depthUpdate","E":1788333214514,"s":"BTCUSDT","U":99556339545,"u":99556339564,"b":[["77731.96000000","0.25898000"],["77730.90000000","0.00000000"],["77728.04000000","0.00000000"],["77724.22000000","0.00008000"],["69958.80000000","0.00208000"],["62186.00000000","0.00000000"],["62185.60000000","0.00032000"]],"a":[["77759.87000000","0.01984000"],["77761.33000000","0.00000000"],["77763.52000000","0.05442000"],["77829.54000000","0.00411000"]]}}
{"type":"depth","received_at_ms":1788333214446,"data":{"e":"depthUpdate","E":1788333214614,"s":"BTCUSDT","U":99556339565,"u":99556339584,"b":[["77731.96000000","0.25891000"],["77730.91000000","0.00000000"],["77730.90000000","0.05000000"],["77730.85000000","0.05000000"],["77730.75000000","0.00007000"],["77713.36000000","0.00007000"],["77710.00000000","0.01500000"],["77708.00000000","0.71500000"],["77706.00000000","0.01500000"],["62185.60000000","0.00000000"]],"a":[["77744.47000000","0.00007000"],["77758.30000000","0.00000000"],["77758.44000000","0.09125000"],["77758.68000000","0.64332000"]]}}
{"type":"trade","received_at_ms":1788333214536,"data":{"e":"trade","E":1788333214703,"s":"BTCUSDT","t":6646666836,"p":"77731.99000000","q":"0.00006000","T":1788333214703,"m":true,"M":true}}
{"type":"depth","received_at_ms":1788333214547,"data":{"e":"depthUpdate","E":1788333214714,"s":"BTCUSDT","U":99556339585,"u":99556339614,"b":[["77731.99000000","3.76576000"],["77731.96000000","0.25898000"],["77730.91000000","0.00014000"],["77730.90000000","0.05021000"],["77730.85000000","0.00000000"],["77730.75000000","0.00000000"],["77730.01000000","0.00000000"],["77678.65000000","0.00411000"],["77655.98000000","0.00000000"],["77653.39000000","1.61330000"],["77532.01000000","0.00000000"],["77530.01000000","0.00811000"],["69958.80000000","0.00224000"],["69958.79000000","0.00009000"],["62185.59000000","0.00000000"]],"a":[["77732.00000000","0.07791000"],["77740.41000000","0.00000000"],["77743.99000000","0.00000000"],["77744.99000000","0.00643000"]]}}
{"type":"trade","received_at_ms":1788333214575,"data":{"e":"trade","E":1788333214742,"s":"BTCUSDT","t":6646666837,"p":"77732.00000000","q":"0.02574000","T":1788333214742,"m":false,"M":true}}
{"type":"depth","received_at_ms":1788333214646,"data":{"e":"depthUpdate","E":1788333214814,"s":"BTCUSDT","U":99556339615,"u":99556339629,"b":[["77730.90000000","0.00014000"],["69958.80000000","0.00224000"]],"a":[["77732.00000000","0.05217000"],["77758.44000000","0.00000000"],["77758.47000000","0.00000000"],["77832.20000000","0.00051000"],["78897.98000000","0.00030000"]]}}
{"type":"depth","received_at_ms":1788333214746,"data":{"e":"depthUpdate","E":1788333214914,"s":"BTCUSDT","U":99556339630,"u":99556339647,"b":[["77731.96000000","0.25891000"],["77730.91000000","0.00000000"],["77730.90000000","0.00000000"],["77730.85000000","0.05000000"],["77730.75000000","0.00014000"],["77729.99000000","0.41334000"],["69958.80000000","0.00240000"],["69958.00000000","0.00217000"]],"a":[["77759.55000000","0.00411000"]]}}
{"type":"trade","received_at_ms":1788333214847,"data":{"e":"trade","E":1788333215013,"s":"BTCUSDT","t":6646666838,"p":"77732.00000000","q":"0.00655000","T":1788333215013,"m":false,"M":true}}
{"type":"depth","received_at_ms":1788333214847,"data":{"e":"depthUpdate","E":1788333215014,"s":"BTCUSDT","U":99556339648,"u":99556339686,"b":[["77731.96000000","0.25891000"],["77730.86000000","0.00000000"],["77730.85000000","0.00000000"],["77730.75000000","0.00014000"],["77583.00000000","0.00011000"],["76566.01000000","0.00030000"],["69958.80000000","0.00240000"],["62185.60000000","0.00032000"]],"a":[["77732.00000000","0.06809000"],["77732.01000000","0.00097000"],["77732.02000000","0.00021000"],["77732.61000000","0.13028000"],["77732.62000000","0.14798000"],["77733.39000000","0.00000000"],["77733.40000000","0.00028000"],["77735.81000000","0.00000000"],["77735.89000000","0.00136000"],["77761.37000000","0.09613000"]]}}
{"type":"trade","received_at_ms":1788333214852,"data":{"e":"trade","E":1788333215015,"s":"BTCUSDT","t":6646666839,"p":"77732.00000000","q":"0.00670000","T":1788333215014,"m":false,"M":true}}
{"type":"trade","received_at_ms":1788333214852,"data":{"e":"trade","E":1788333215015,"s":"BTCUSDT","t":6646666840,"p":"77732.00000000","q":"0.00008000","T":1788333215014,"m":false,"M":true}}
{"type":"trade","received_at_ms":1788333214852,"data":{"e":"trade","E":1788333215015,"s":"BTCUSDT","t":6646666841,"p":"77732.00000000","q":"0.00007000","T":1788333215014,"m":false,"M":true}}
{"type":"trade","received_at_ms":1788333214852,"data":{"e":"trade","E":1788333215015,"s":"BTCUSDT","t":6646666842,"p":"77732.00000000","q":"0.00007000","T":1788333215014,"m":false,"M":true}}
{"type":"trade","received_at_ms":1788333214852,"data":{"e":"trade","E":1788333215015,"s":"BTCUSDT","t":6646666843,"p":"77732.00000000","q":"0.00048000","T":1788333215014,"m":false,"M":true}}
{"type":"trade","received_at_ms":1788333214852,"data":{"e":"trade","E":1788333215015,"s":"BTCUSDT","t":6646666844,"p":"77732.00000000","q":"0.00150000","T":1788333215014,"m":false,"M":true}}
{"type":"trade","received_at_ms":1788333214852,"data":{"e":"trade","E":1788333215015,"s":"BTCUSDT","t":6646666845,"p":"77732.00000000","q":"0.00007000","T":1788333215014,"m":false,"M":true}}
{"type":"trade","received_at_ms":1788333214852,"data":{"e":"trade","E":1788333215015,"s":"BTCUSDT","t":6646666846,"p":"77732.00000000","q":"0.00069000","T":1788333215014,"m":false,"M":true}}
{"type":"trade","received_at_ms":1788333214852,"data":{"e":"trade","E":1788333215015,"s":"BTCUSDT","t":6646666847,"p":"77732.00000000","q":"0.00013000","T":1788333215014,"m":false,"M":true}}
{"type":"trade","received_at_ms":1788333214852,"data":{"e":"trade","E":1788333215015,"s":"BTCUSDT","t":6646666848,"p":"77732.00000000","q":"0.00007000","T":1788333215014,"m":false,"M":true}}
{"type":"trade","received_at_ms":1788333214853,"data":{"e":"trade","E":1788333215015,"s":"BTCUSDT","t":6646666849,"p":"77732.00000000","q":"0.00007000","T":1788333215014,"m":false,"M":true}}
{"type":"trade","received_at_ms":1788333214853,"data":{"e":"trade","E":1788333215015,"s":"BTCUSDT","t":6646666850,"p":"77732.00000000","q":"0.00007000","T":1788333215014,"m":false,"M":true}}
{"type":"trade","received_at_ms":1788333214853,"data":{"e":"trade","E":1788333215015,"s":"BTCUSDT","t":6646666851,"p":"77732.00000000","q":"0.00007000","T":1788333215014,"m":false,"M":true}}
{"type":"trade","received_at_ms":1788333214853,"data":{"e":"trade","E":1788333215015,"s":"BTCUSDT","t":6646666852,"p":"77732.00000000","q":"0.00007000","T":1788333215014,"m":false,"M":true}}
{"type":"trade","received_at_ms":1788333214853,"data":{"e":"trade","E":1788333215015,"s":"BTCUSDT","t":6646666853,"p":"77732.00000000","q":"0.00007000","T":1788333215014,"m":false,"M":true}}
{"type":"trade","received_at_ms":1788333214853,"data":{"e":"trade","E":1788333215015,"s":"BTCUSDT","t":6646666854,"p":"77732.00000000","q":"0.00007000","T":1788333215014,"m":false,"M":true}}
{"type":"trade","received_at_ms":1788333214853,"data":{"e":"trade","E":1788333215015,"s":"BTCUSDT","t":6646666855,"p":"77732.00000000","q":"0.00472000","T":1788333215014,"m":false,"M":true}}
{"type":"trade","received_at_ms":1788333214918,"data":{"e":"trade","E":1788333215084,"s":"BTCUSDT","t":6646666856,"p":"77731.99000000","q":"0.00192000","T":1788333215084,"m":true,"M":true}}
{"type":"depth","received_at_ms":1788333214946,"data":{"e":"depthUpdate","E":1788333215114,"s":"BTCUSDT","U":99556339687,"u":99556339750,"b":[["77731.99000000","3.76391000"],["77731.96000000","0.25891000"],["77730.75000000","0.05014000"],["77726.17000000","0.00013000"],["77683.85000000","1.17434000"],["69958.80000000","0.00256000"],["69958.79000000","0.00000000"],["69958.78000000","0.00009000"],["69958.00000000","0.00217000"]],"a":[["77732.00000000","0.05770000"],["77732.01000000","0.00104000"],["77732.60000000","0.00014000"],["77732.61000000","0.13042000"],["77732.62000000","0.14812000"],["77733.40000000","0.00014000"],["77736.00000000","0.03007000"],["77737.82000000","0.00013000"],["77738.35000000","0.00206000"],["77740.80000000","0.00048000"],["77740.99000000","0.00070000"],["77757.87000000","0.00000000"],["77759.16000000","1.64708000"],["77760.44000000","0.00000000"],["77802.39000000","1.30601000"]]}}
{"type":"trade","received_at_ms":1788333215012,"data":{"e":"trade","E":1788333215175,"s":"BTCUSDT","t":6646666857,"p":"77732.00000000","q":"0.02975000","T":1788333215175,"m":false,"M":true}}
{"type":"trade","received_at_ms":1788333215012,"data":{"e":"trade","E":1788333215175,"s":"BTCUSDT","t":6646666858,"p":"77732.00000000","q":"0.00007000","T":1788333215175,"m":false,"M":true}}
{"type":"trade","received_at_ms":1788333215012,"data":{"e":"trade","E":1788333215175,"s":"BTCUSDT","t":6646666859,"p":"77732.00000000","q":"0.00007000","T":1788333215175,"m":false,"M":true}}
{"type":"trade","received_at_ms":1788333215012,"data":{"e":"trade","E":1788333215175,"s":"BTCUSDT","t":6646666860,"p":"77732.00000000","q":"0.00007000","T":1788333215175,"m":false,"M":true}}
{"type":"trade","received_at_ms":1788333215012,"data":{"e":"trade","E":1788333215175,"s":"BTCUSDT","t":6646666861,"p":"77732.00000000","q":"0.00007000","T":1788333215175,"m":false,"M":true}}
{"type":"trade","received_at_ms":1788333215012,"data":{"e":"trade","E":1788333215175,"s":"BTCUSDT","t":6646666862,"p":"77732.00000000","q":"0.00007000","T":1788333215175,"m":false,"M":true}}
{"type":"trade","received_at_ms":1788333215012,"data":{"e":"trade","E":1788333215175,"s":"BTCUSDT","t":6646666863,"p":"77732.00000000","q":"0.00007000","T":1788333215175,"m":false,"M":true}}
{"type":"trade","received_at_ms":1788333215012,"data":{"e":"trade","E":1788333215175,"s":"BTCUSDT","t":6646666864,"p":"77732.00000000","q":"0.00007000","T":1788333215175,"m":false,"M":true}}
{"type":"trade","received_at_ms":1788333215012,"data":{"e":"trade","E":1788333215175,"s":"BTCUSDT","t":6646666865,"p":"77732.00000000","q":"0.00007000","T":1788333215175,"m":false,"M":true}}
{"type":"trade","received_at_ms":1788333215012,"data":{"e":"trade","E":1788333215175,"s":"BTCUSDT","t":6646666866,"p":"77732.00000000","q":"0.00010000","T":1788333215175,"m":false,"M":true}}
{"type":"trade","received_at_ms":1788333215012,"data":{"e":"trade","E":1788333215175,"s":"BTCUSDT","t":6646666867,"p":"77732.00000000","q":"0.00013000","T":1788333215175,"m":false,"M":true}}
{"type":"trade","received_at_ms":1788333215012,"data":{"e":"trade","E":1788333215175,"s":"BTCUSDT","t":6646666868,"p":"77732.00000000","q":"0.00914000","T":1788333215175,"m":false,"M":true}}
{"type":"trade","received_at_ms":1788333215012,"data":{"e":"trade","E":1788333215175,"s":"BTCUSDT","t":6646666869,"p":"77732.00000000","q":"0.00008000","T":1788333215175,"m":false,"M":true}}
{"type":"trade","received_at_ms":1788333215012,"data":{"e":"trade","E":1788333215175,"s":"BTCUSDT","t":6646666870,"p":"77732.00000000","q":"0.00007000","T":1788333215175,"m":false,"M":true}}
{"type":"trade","received_at_ms":1788333215012,"data":{"e":"trade","E":1788333215175,"s":"BTCUSDT","t":6646666871,"p":"77732.00000000","q":"0.00007000","T":1788333215175,"m":false,"M":true}}
{"type":"trade","received_at_ms":1788333215012,"data":{"e":"trade","E":1788333215175,"s":"BTCUSDT","t":6646666872,"p":"77732.00000000","q":"0.00007000","T":1788333215175,"m":false,"M":true}}
{"type":"trade","received_at_ms":1788333215012,"data":{"e":"trade","E":1788333215175,"s":"BTCUSDT","t":6646666873,"p":"77732.00000000","q":"0.00007000","T":1788333215175,"m":false,"M":true}}
{"type":"trade","received_at_ms":1788333215012,"data":{"e":"trade","E":1788333215175,"s":"BTCUSDT","t":6646666874,"p":"77732.00000000","q":"0.00150000","T":1788333215175,"m":false,"M":true}}
{"type":"trade","received_at_ms":1788333215012,"data":{"e":"trade","E":1788333215175,"s":"BTCUSDT","t":6646666875,"p":"77732.00000000","q":"0.00007000","T":1788333215175,"m":false,"M":true}}
{"type":"trade","received_at_ms":1788333215012,"data":{"e":"trade","E":1788333215175,"s":"BTCUSDT","t":6646666876,"p":"77732.00000000","q":"0.00254000","T":1788333215175,"m":false,"M":true}}
{"type":"trade","received_at_ms":1788333215012,"data":{"e":"trade","E":1788333215175,"s":"BTCUSDT","t":6646666877,"p":"77732.00000000","q":"0.00007000","T":1788333215175,"m":false,"M":true}}
{"type":"trade","received_at_ms":1788333215012,"data":{"e":"trade","E":1788333215175,"s":"BTCUSDT","t":6646666878,"p":"77732.00000000","q":"0.00007000","T":1788333215175,"m":false,"M":true}}
{"type":"trade","received_at_ms":1788333215012,"data":{"e":"trade","E":1788333215175,"s":"BTCUSDT","t":6646666879,"p":"77732.00000000","q":"0.00007000","T":1788333215175,"m":false,"M":true}}
{"type":"trade","received_at_ms":1788333215012,"data":{"e":"trade","E":1788333215175,"s":"BTCUSDT","t":6646666880,"p":"77732.00000000","q":"0.00007000","T":1788333215175,"m":false,"M":true}}
{"type":"trade","received_at_ms":1788333215012,"data":{"e":"trade","E":1788333215175,"s":"BTCUSDT","t":6646666881,"p":"77732.00000000","q":"0.00007000","T":1788333215175,"m":false,"M":true}}
{"type":"trade","received_at_ms":1788333215012,"data":{"e":"trade","E":1788333215175,"s":"BTCUSDT","t":6646666882,"p":"77732.00000000","q":"0.00013000","T":1788333215175,"m":false,"M":true}}
{"type":"trade","received_at_ms":1788333215012,"data":{"e":"trade","E":1788333215175,"s":"BTCUSDT","t":6646666883,"p":"77732.01000000","q":"0.00007000","T":1788333215175,"m":false,"M":true}}
{"type":"trade","received_at_ms":1788333215012,"data":{"e":"trade","E":1788333215175,"s":"BTCUSDT","t":6646666884,"p":"77732.01000000","q":"0.00007000","T":1788333215175,"m":false,"M":true}}
{"type":"trade","received_at_ms":1788333215012,"data":{"e":"trade","E":1788333215175,"s":"BTCUSDT","t":6646666885,"p":"77732.01000000","q":"0.00007000","T":1788333215175,"m":false,"M":true}}
{"type":"trade","received_at_ms":1788333215012,"data":{"e":"trade","E":1788333215175,"s":"BTCUSDT","t":6646666886,"p":"77732.01000000","q":"0.00007000","T":1788333215175,"m":false,"M":true}}
{"type":"trade","received_at_ms":1788333215012,"data":{"e":"trade","E":1788333215175,"s":"BTCUSDT","t":6646666887,"p":"77732.01000000","q":"0.00007000","T":1788333215175,"m":false,"M":true}}
{"type":"trade","received_at_ms":1788333215012,"data":{"e":"trade","E":1788333215175,"s":"BTCUSDT","t":6646666888,"p":"77732.01000000","q":"0.00007000","T":1788333215175,"m":false,"M":true}}
{"type":"trade","received_at_ms":1788333215012,"data":{"e":"trade","E":1788333215175,"s":"BTCUSDT","t":6646666889,"p":"77732.01000000","q":"0.00007000","T":1788333215175,"m":false,"M":true}}
{"type":"trade","received_at_ms":1788333215012,"data":{"e":"trade","E":1788333215175,"s":"BTCUSDT","t":6646666890,"p":"77732.01000000","q":"0.00007000","T":1788333215175,"m":false,"M":true}}
{"type":"trade","received_at_ms":1788333215012,"data":{"e":"trade","E":1788333215175,"s":"BTCUSDT","t":6646666891,"p":"77732.01000000","q":"0.00007000","T":1788333215175,"m":false,"M":true}}
{"type":"trade","received_at_ms":1788333215012,"data":{"e":"trade","E":1788333215175,"s":"BTCUSDT","t":6646666892,"p":"77732.01000000","q":"0.00007000","T":1788333215175,"m":false,"M":true}}
{"type":"trade","received_at_ms":1788333215012,"data":{"e":"trade","E":1788333215175,"s":"BTCUSDT","t":6646666893,"p":"77732.01000000","q":"0.00007000","T":1788333215175,"m":false,"M":true}}
{"type":"trade","received_at_ms":1788333215012,"data":{"e":"trade","E":1788333215175,"s":"BTCUSDT","t":6646666894,"p":"77732.01000000","q":"0.00013000","T":1788333215175,"m":false,"M":true}}
{"type":"trade","received_at_ms":1788333215012,"data":{"e":"trade","E":1788333215175,"s":"BTCUSDT","t":6646666895,"p":"77732.01000000","q":"0.00007000","T":1788333215175,"m":false,"M":true}}
{"type":"trade","received_at_ms":1788333215012,"data":{"e":"trade","E":1788333215175,"s":"BTCUSDT","t":6646666896,"p":"77732.01000000","q":"0.00007000","T":1788333215175,"m":false,"M":true}}
{"type":"trade","received_at_ms":1788333215012,"data":{"e":"trade","E":1788333215175,"s":"BTCUSDT","t":6646666897,"p":"77732.02000000","q":"0.00013000","T":1788333215175,"m":false,"M":true}}
{"type":"trade","received_at_ms":1788333215012,"data":{"e":"trade","E":1788333215175,"s":"BTCUSDT","t":6646666898,"p":"77732.02000000","q":"0.00008000","T":1788333215175,"m":false,"M":true}}
{"type":"trade","received_at_ms":1788333215012,"data":{"e":"trade","E":1788333215175,"s":"BTCUSDT","t":6646666899,"p":"77732.26000000","q":"0.00007000","T":1788333215175,"m":false,"M":true}}
{"type":"trade","received_at_ms":1788333215012,"data":{"e":"trade","E":1788333215175,"s":"BTCUSDT","t":6646666900,"p":"77732.60000000","q":"0.00007000","T":1788333215175,"m":false,"M":true}}
{"type":"trade","received_at_ms":1788333215012,"data":{"e":"trade","E":1788333215175,"s":"BTCUSDT","t":6646666901,"p":"77732.60000000","q":"0.00007000","T":1788333215175,"m":false,"M":true}}
{"type":"trade","received_at_ms":1788333215012,"data":{"e":"trade","E":1788333215175,"s":"BTCUSDT","t":6646666902,"p":"77732.60000000","q":"0.00007000","T":1788333215175,"m":false,"M":true}}
{"type":"depth","received_at_ms":1788333215046,"data":{"e":"depthUpdate","E":1788333215214,"s":"BTCUSDT","U":99556339751,"u":99556340051,"b":[["77732.60000000","3.35410000"],["77732.59000000","0.27364000"],["77732.58000000","0.00013000"],["77732.45000000","0.00400000"],["77732.26000000","0.00014000"],["77732.25000000","0.00000000"],["77732.01000000","0.00000000"],["77732.00000000","0.74922000"],["77731.99000000","1.03802000"],["77731.98000000","0.00000000"],["77731.97000000","0.00000000"],["77731.96000000","0.00021000"],["77730.81000000","0.00000000"],["77730.80000000","0.00000000"],["77730.76000000","0.00000000"],["77730.75000000","0.05000000"],["77730.23000000","0.00000000"],["77730.00000000","0.07528000"],["77729.99000000","0.40927000"],["77729.93000000","0.01308000"],["77729.55000000","0.00000000"],["77729.32000000","0.00021000"],["77728.04000000","0.00000000"],["77728.00000000","0.12965000"],["77724.04000000","0.00060000"],["77723.99000000","0.03184000"],["77723.11000000","0.00000000"],["77720.66000000","0.00007000"],["77720.05000000","0.00000000"],["77667.20000000","0.00321000"],["77662.31000000","0.00000000"],["77658.09000000","0.63114000"],["77655.98000000","1.61330000"],["77653.39000000","0.00000000"],["77558.75000000","0.00025000"],["77552.96000000","0.00000000"],["76566.01000000","0.00000000"],["76000.01000000","0.01832000"],["69958.80000000","0.00000000"],["62186.00000000","0.00000000"],["62185.60000000","0.00000000"]],"a":[["77732.00000000","0.00000000"],["77732.01000000","0.00000000"],["77732.02000000","0.00000000"],["77732.26000000","0.00000000"],["77732.60000000","0.00000000"],["77732.61000000","0.02779000"],["77732.62000000","0.14875000"],["77733.39000000","0.00014000"],["77733.40000000","0.08519000"],["77734.76000000","0.00014000"],["77735.37000000","0.01266000"],["77735.81000000","0.00000000"],["77736.00000000","0.03021000"],["77740.80000000","0.00000000"],["77740.99000000","0.00000000"],["77742.83000000","0.00000000"],["77743.32000000","0.00400000"],["77759.87000000","0.00000000"],["77761.37000000","0.00000000"],["77761.48000000","0.09534000"],["77763.52000000","0.00000000"],["77771.00000000","0.00000000"],["77772.00000000","0.04000000"],["77808.00000000","0.00007000"],["78897.98000000","0.00000000"]]}}
{"type":"trade","received_at_ms":1788333215051,"data":{"e":"trade","E":1788333215215,"s":"BTCUSDT","t":6646666903,"p":"77732.61000000","q":"0.00007000","T":1788333215215,"m":false,"M":true}}
{"type":"trade","received_at_ms":1788333215051,"data":{"e":"trade","E":1788333215215,"s":"BTCUSDT","t":6646666904,"p":"77732.61000000","q":"0.00007000","T":1788333215215,"m":false,"M":true}}
{"type":"trade","received_at_ms":1788333215051,"data":{"e":"trade","E":1788333215215,"s":"BTCUSDT","t":6646666905,"p":"77732.61000000","q":"0.00007000","T":1788333215215,"m":false,"M":true}}
{"type":"trade","received_at_ms":1788333215051,"data":{"e":"trade","E":1788333215215,"s":"BTCUSDT","t":6646666906,"p":"77732.61000000","q":"0.00007000","T":1788333215215,"m":false,"M":true}}
{"type":"trade","received_at_ms":1788333215051,"data":{"e":"trade","E":1788333215215,"s":"BTCUSDT","t":6646666907,"p":"77732.61000000","q":"0.00007000","T":1788333215215,"m":false,"M":true}}
{"type":"trade","received_at_ms":1788333215052,"data":{"e":"trade","E":1788333215215,"s":"BTCUSDT","t":6646666908,"p":"77732.61000000","q":"0.00007000","T":1788333215215,"m":false,"M":true}}
{"type":"trade","received_at_ms":1788333215052,"data":{"e":"trade","E":1788333215215,"s":"BTCUSDT","t":6646666909,"p":"77732.61000000","q":"0.00007000","T":1788333215215,"m":false,"M":true}}
{"type":"trade","received_at_ms":1788333215052,"data":{"e":"trade","E":1788333215215,"s":"BTCUSDT","t":6646666910,"p":"77732.61000000","q":"0.01320000","T":1788333215215,"m":false,"M":true}}
{"type":"trade","received_at_ms":1788333215052,"data":{"e":"trade","E":1788333215215,"s":"BTCUSDT","t":6646666911,"p":"77732.61000000","q":"0.00007000","T":1788333215215,"m":false,"M":true}}
{"type":"trade","received_at_ms":1788333215052,"data":{"e":"trade","E":1788333215215,"s":"BTCUSDT","t":6646666912,"p":"77732.61000000","q":"0.00007000","T":1788333215215,"m":false,"M":true}}
{"type":"trade","received_at_ms":1788333215052,"data":{"e":"trade","E":1788333215215,"s":"BTCUSDT","t":6646666913,"p":"77732.61000000","q":"0.00007000","T":1788333215215,"m":false,"M":true}}
{"type":"trade","received_at_ms":1788333215052,"data":{"e":"trade","E":1788333215215,"s":"BTCUSDT","t":6646666914,"p":"77732.61000000","q":"0.00150000","T":1788333215215,"m":false,"M":true}}
{"type":"trade","received_at_ms":1788333215052,"data":{"e":"trade","E":1788333215215,"s":"BTCUSDT","t":6646666915,"p":"77732.61000000","q":"0.00025000","T":1788333215215,"m":false,"M":true}}
{"type":"trade","received_at_ms":1788333215052,"data":{"e":"trade","E":1788333215215,"s":"BTCUSDT","t":6646666916,"p":"77732.61000000","q":"0.00007000","T":1788333215215,"m":false,"M":true}}
{"type":"trade","received_at_ms":1788333215052,"data":{"e":"trade","E":1788333215215,"s":"BTCUSDT","t":6646666917,"p":"77732.61000000","q":"0.00007000","T":1788333215215,"m":false,"M":true}}
{"type":"trade","received_at_ms":1788333215052,"data":{"e":"trade","E":1788333215215,"s":"BTCUSDT","t":6646666918,"p":"77732.61000000","q":"0.00007000","T":1788333215215,"m":false,"M":true}}
{"type":"trade","received_at_ms":1788333215052,"data":{"e":"trade","E":1788333215215,"s":"BTCUSDT","t":6646666919,"p":"77732.61000000","q":"0.00007000","T":1788333215215,"m":false,"M":true}}
{"type":"trade","received_at_ms":1788333215052,"data":{"e":"trade","E":1788333215215,"s":"BTCUSDT","t":6646666920,"p":"77732.61000000","q":"0.00007000","T":1788333215215,"m":false,"M":true}}
{"type":"trade","received_at_ms":1788333215052,"data":{"e":"trade","E":1788333215215,"s":"BTCUSDT","t":6646666921,"p":"77732.61000000","q":"0.00958000","T":1788333215215,"m":false,"M":true}}
{"type":"trade","received_at_ms":1788333215052,"data":{"e":"trade","E":1788333215215,"s":"BTCUSDT","t":6646666922,"p":"77732.61000000","q":"0.00007000","T":1788333215215,"m":false,"M":true}}
{"type":"trade","received_at_ms":1788333215052,"data":{"e":"trade","E":1788333215215,"s":"BTCUSDT","t":6646666923,"p":"77732.61000000","q":"0.00007000","T":1788333215215,"m":false,"M":true}}
{"type":"trade","received_at_ms":1788333215052,"data":{"e":"trade","E":1788333215215,"s":"BTCUSDT","t":6646666924,"p":"77732.61000000","q":"0.00007000","T":1788333215215,"m":false,"M":true}}
{"type":"trade","received_at_ms":1788333215052,"data":{"e":"trade","E":1788333215215,"s":"BTCUSDT","t":6646666925,"p":"77732.61000000","q":"0.00007000","T":1788333215215,"m":false,"M":true}}
{"type":"trade","received_at_ms":1788333215052,"data":{"e":"trade","E":1788333215215,"s":"BTCUSDT","t":6646666926,"p":"77732.61000000","q":"0.00007000","T":1788333215215,"m":false,"M":true}}
{"type":"trade","received_at_ms":1788333215052,"data":{"e":"trade","E":1788333215215,"s":"BTCUSDT","t":6646666927,"p":"77732.61000000","q":"0.00007000","T":1788333215215,"m":false,"M":true}}
{"type":"trade","received_at_ms":1788333215052,"data":{"e":"trade","E":1788333215215,"s":"BTCUSDT","t":6646666928,"p":"77732.61000000","q":"0.00007000","T":1788333215215,"m":false,"M":true}}
{"type":"trade","received_at_ms":1788333215052,"data":{"e":"trade","E":1788333215215,"s":"BTCUSDT","t":6646666929,"p":"77732.61000000","q":"0.00007000","T":1788333215215,"m":false,"M":true}}
{"type":"trade","received_at_ms":1788333215052,"data":{"e":"trade","E":1788333215215,"s":"BTCUSDT","t":6646666930,"p":"77732.61000000","q":"0.00007000","T":1788333215215,"m":false,"M":true}}
{"type":"trade","received_at_ms":1788333215052,"data":{"e":"trade","E":1788333215215,"s":"BTCUSDT","t":6646666931,"p":"77732.61000000","q":"0.00007000","T":1788333215215,"m":false,"M":true}}
{"type":"trade","received_at_ms":1788333215052,"data":{"e":"trade","E":1788333215215,"s":"BTCUSDT","t":6646666932,"p":"77732.61000000","q":"0.00007000","T":1788333215215,"m":false,"M":true}}
{"type":"trade","received_at_ms":1788333215052,"data":{"e":"trade","E":1788333215215,"s":"BTCUSDT","t":6646666933,"p":"77732.61000000","q":"0.00008000","T":1788333215215,"m":false,"M":true}}
{"type":"trade","received_at_ms":1788333215052,"data":{"e":"trade","E":1788333215215,"s":"BTCUSDT","t":6646666934,"p":"77732.61000000","q":"0.00007000","T":1788333215215,"m":false,"M":true}}
{"type":"trade","received_at_ms":1788333215052,"data":{"e":"trade","E":1788333215215,"s":"BTCUSDT","t":6646666935,"p":"77732.61000000","q":"0.00065000","T":1788333215215,"m":false,"M":true}}
{"type":"trade","received_at_ms":1788333215052,"data":{"e":"trade","E":1788333215215,"s":"BTCUSDT","t":6646666936,"p":"77732.61000000","q":"0.00064000","T":1788333215215,"m":false,"M":true}}
{"type":"trade","received_at_ms":1788333215052,"data":{"e":"trade","E":1788333215215,"s":"BTCUSDT","t":6646666937,"p":"77732.61000000","q":"0.00007000","T":1788333215215,"m":false,"M":true}}
{"type":"depth","received_at_ms":1788333215146,"data":{"e":"depthUpdate","E":1788333215314,"s":"BTCUSDT","U":99556340052,"u":99556340334,"b":[["77732.61000000","4.63559000"],["77732.60000000","0.39523000"],["77732.59000000","0.00034000"],["77732.58000000","0.00000000"],["77732.45000000","0.00000000"],["77732.21000000","0.00400000"],["77732.01000000","0.00014000"],["77732.00000000","0.07535000"],["77731.99000000","0.68890000"],["77731.96000000","0.00000000"],["77730.91000000","0.00014000"],["77730.90000000","0.05000000"],["77730.75000000","0.00000000"],["77730.23000000","0.00007000"],["77730.22000000","0.07514000"],["77730.21000000","0.39420000"],["77730.00000000","0.00000000"],["77728.04000000","0.00000000"],["77724.00000000","1.58382000"],["77720.67000000","0.00007000"],["77720.66000000","0.00000000"],["77710.00000000","0.02500000"],["77708.00000000","0.72500000"],["77706.00000000","0.02500000"],["77705.18000000","0.00000000"],["77704.00000000","0.03000000"],["69959.35000000","0.00032000"],["62186.08000000","0.00020000"]],"a":[["77732.61000000","0.00000000"],["77732.62000000","0.16955000"],["77732.63000000","0.00063000"],["77733.40000000","0.08533000"],["77734.00000000","0.03014000"],["77734.76000000","0.00000000"],["77734.82000000","0.11530000"],["77735.37000000","0.01280000"],["77735.81000000","0.00007000"],["77736.00000000","0.03014000"],["77761.48000000","0.00000000"],["77798.43000000","0.00411000"]]}}
{"type":"depth","received_at_ms":1788333215247,"data":{"e":"depthUpdate","E":1788333215414,"s":"BTCUSDT","U":99556340335,"u":99556340365,"b":[["77732.61000000","4.65510000"],["77732.60000000","0.39516000"],["77732.59000000","0.00020000"],["77731.99000000","0.66890000"],["77730.91000000","0.00000000"],["77730.90000000","0.00014000"],["77730.23000000","0.00014000"],["77730.22000000","0.07521000"],["77540.00000000","0.03050000"],["69959.35000000","0.00048000"],["62186.08000000","0.00000000"]],"a":[["77732.62000000","0.16968000"]]}}
{"type":"depth","received_at_ms":1788333215346,"data":{"e":"depthUpdate","E":1788333215514,"s":"BTCUSDT","U":99556340366,"u":99556340407,"b":[["77732.61000000","4.65461000"],["77732.60000000","0.09102000"],["77732.00000000","0.56392000"],["77731.99000000","0.66890000"],["77731.16000000","0.00000000"],["77731.15000000","0.00000000"],["77730.90000000","0.00000000"],["77730.22000000","0.07521000"],["77730.21000000","0.39434000"],["77724.21000000","0.00000000"],["77722.28000000","0.00128000"],["77717.51000000","0.00411000"],["77708.67000000","0.00000000"],["77700.89000000","0.00000000"],["77688.20000000","0.00000000"],["69959.35000000","0.00064000"],["69959.00000000","0.00010000"],["62186.09000000","0.00032000"]],"a":[["77748.39000000","0.00257000"]]}}
{"type":"trade","received_at_ms":1788333215387,"data":{"e":"trade","E":1788333215550,"s":"BTCUSDT","t":6646666938,"p":"77732.62000000","q":"0.02573000","T":1788333215550,"m":false,"M":true}}
{"type":"depth","received_at_ms":1788333215447,"data":{"e":"depthUpdate","E":1788333215614,"s":"BTCUSDT","U":99556340408,"u":99556340440,"b":[["77732.61000000","4.65481000"],["77731.99000000","0.64870000"],["77724.83000000","0.00020000"],["77717.06000000","0.00020000"],["77716.44000000","0.00000000"],["77713.98000000","0.00007000"],["77713.36000000","0.00000000"],["77709.29000000","0.00020000"],["77701.51000000","0.00020000"],["71506.07000000","0.00014000"],["69959.35000000","0.00096000"],["69959.00000000","0.00000000"],["69958.78000000","0.00000000"],["62186.09000000","0.00000000"],["62186.00000000","0.00000000"]],"a":[["77732.62000000","0.14395000"],["77744.47000000","0.00000000"],["77745.09000000","0.00007000"],["77748.37000000","0.00257000"],["77748.39000000","0.00000000"]]}}
{"type":"depth","received_at_ms":1788333215547,"data":{"e":"depthUpdate","E":1788333215714,"s":"BTCUSDT","U":99556340441,"u":99556340453,"b":[["77732.61000000","4.67481000"],["77731.99000000","0.63877000"],["77731.20000000","0.00007000"],["77731.15000000","0.05000000"],["77710.00000000","0.03000000"],["69959.35000000","0.00112000"],["62186.09000000","0.00000000"]],"a":[["77759.96000000","0.01991000"],["77763.61000000","0.05277000"]]}}
{"type":"depth","received_at_ms":1788333215647,"data":{"e":"depthUpdate","E":1788333215815,"s":"BTCUSDT","U":99556340454,"u":99556340470,"b":[["77732.61000000","4.68489000"],["77731.99000000","0.63877000"],["77731.06000000","0.00007000"],["77708.00000000","0.73000000"],["77706.00000000","0.03000000"],["77650.76000000","0.00401000"],["77648.13000000","0.00000000"],["69959.35000000","0.00144000"]],"a":[["77748.37000000","0.00000000"],["77761.49000000","0.09678000"],["77824.32000000","0.00007000"],["78898.61000000","0.00030000"]]}}
{"type":"depth","received_at_ms":1788333215746,"data":{"e":"depthUpdate","E":1788333215914,"s":"BTCUSDT","U":99556340471,"u":99556340474,"b":[["77732.61000000","4.69089000"],["77731.99000000","0.63277000"],["77622.54000000","0.00108000"],["77613.46000000","0.00000000"],["69959.00000000","0.00010000"]],"a":[]}}
{"type":"depth","received_at_ms":1788333215848,"data":{"e":"depthUpdate","E":1788333216014,"s":"BTCUSDT","U":99556340475,"u":99556340489,"b":[["77732.47000000","0.00400000"],["77732.21000000","0.00000000"],["77731.15000000","0.05007000"],["77731.10000000","0.05000000"],["77596.01000000","0.00020000"],["76566.62000000","0.00030000"],["69959.35000000","0.00160000"],["69959.00000000","0.00010000"],["62186.09000000","0.00032000"]],"a":[["77732.62000000","0.14395000"],["77868.08000000","0.00020000"]]}}
{"type":"trade","received_at_ms":1788333215878,"data":{"e":"trade","E":1788333216045,"s":"BTCUSDT","t":6646666939,"p":"77732.61000000","q":"0.01500000","T":1788333216045,"m":true,"M":true}}
{"type":"depth","received_at_ms":1788333215947,"data":{"e":"depthUpdate","E":1788333216114,"s":"BTCUSDT","U":99556340490,"u":99556340517,"b":[["77732.61000000","4.67589000"],["77731.15000000","0.00014000"],["77731.10000000","0.00000000"],["77730.21000000","0.39420000"],["77717.51000000","0.00000000"],["77686.16000000","1.08967000"],["77678.65000000","0.00000000"],["77647.56000000","0.00411000"],["77637.05000000","0.00000000"],["77453.72000000","0.00000000"],["77379.64000000","0.00000000"],["71506.07000000","0.00000000"],["69959.35000000","0.00160000"],["69959.34000000","0.00009000"],["69959.00000000","0.00000000"]],"a":[["77742.52000000","0.00000000"],["77759.55000000","0.00000000"],["77798.43000000","0.00000000"],["77828.38000000","0.00000000"],["77829.00000000","0.00025000"],["77829.54000000","0.00000000"]]}}
{"type":"depth","received_at_ms":1788333216046,"data":{"e":"depthUpdate","E":1788333216214,"s":"BTCUSDT","U":99556340518,"u":99556340540,"b":[["77731.99000000","0.63277000"],["77731.25000000","0.00007000"],["77731.20000000","0.00000000"],["77731.15000000","0.00000000"],["77731.10000000","0.05000000"],["77730.21000000","0.39434000"],["77719.42000000","1.05765000"],["77717.37000000","0.00000000"],["77667.99000000","0.00000000"],["77032.40000000","0.00000000"],["69959.35000000","0.00176000"],["62186.09000000","0.00000000"]],"a":[["77750.49000000","0.00152000"]]}}
{"type":"trade","received_at_ms":1788333216085,"data":{"e":"trade","E":1788333216252,"s":"BTCUSDT","t":6646666940,"p":"77732.62000000","q":"0.00052000","T":1788333216251,"m":false,"M":true}}
{"type":"trade","received_at_ms":1788333216090,"data":{"e":"trade","E":1788333216257,"s":"BTCUSDT","t":6646666941,"p":"77732.62000000","q":"0.00200000","T":1788333216257,"m":false,"M":true}}
{"type":"trade","received_at_ms":1788333216090,"data":{"e":"trade","E":1788333216257,"s":"BTCUSDT","t":6646666942,"p":"77732.62000000","q":"0.00200000","T":1788333216257,"m":false,"M":true}}
{"type":"trade","received_at_ms":1788333216090,"data":{"e":"trade","E":1788333216257,"s":"BTCUSDT","t":6646666943,"p":"77732.62000000","q":"0.00200000","T":1788333216257,"m":false,"M":true}}
{"type":"trade","received_at_ms":1788333216090,"data":{"e":"trade","E":1788333216257,"s":"BTCUSDT","t":6646666944,"p":"77732.62000000","q":"0.00200000","T":1788333216257,"m":false,"M":true}}
{"type":"trade","received_at_ms":1788333216090,"data":{"e":"trade","E":1788333216257,"s":"BTCUSDT","t":6646666945,"p":"77732.62000000","q":"0.00200000","T":1788333216257,"m":false,"M":true}}
{"type":"trade","received_at_ms":1788333216090,"data":{"e":"trade","E":1788333216258,"s":"BTCUSDT","t":6646666946,"p":"77732.62000000","q":"0.00200000","T":1788333216257,"m":false,"M":true}}
{"type":"trade","received_at_ms":1788333216090,"data":{"e":"trade","E":1788333216258,"s":"BTCUSDT","t":6646666947,"p":"77732.62000000","q":"0.00200000","T":1788333216257,"m":false,"M":true}}
{"type":"trade","received_at_ms":1788333216090,"data":{"e":"trade","E":1788333216258,"s":"BTCUSDT","t":6646666948,"p":"77732.62000000","q":"0.00200000","T":1788333216257,"m":false,"M":true}}
{"type":"trade","received_at_ms":1788333216091,"data":{"e":"trade","E":1788333216258,"s":"BTCUSDT","t":6646666949,"p":"77732.62000000","q":"0.00200000","T":1788333216258,"m":false,"M":true}}
{"type":"trade","received_at_ms":1788333216092,"data":{"e":"trade","E":1788333216259,"s":"BTCUSDT","t":6646666950,"p":"77732.62000000","q":"0.00200000","T":1788333216259,"m":false,"M":true}}
{"type":"trade","received_at_ms":1788333216093,"data":{"e":"trade","E":1788333216261,"s":"BTCUSDT","t":6646666951,"p":"77732.62000000","q":"0.00200000","T":1788333216260,"m":false,"M":true}}
{"type":"trade","received_at_ms":1788333216093,"data":{"e":"trade","E":1788333216261,"s":"BTCUSDT","t":6646666952,"p":"77732.62000000","q":"0.00200000","T":1788333216260,"m":false,"M":true}}
{"type":"trade","received_at_ms":1788333216096,"data":{"e":"trade","E":1788333216263,"s":"BTCUSDT","t":6646666953,"p":"77732.62000000","q":"0.00200000","T":1788333216262,"m":false,"M":true}}
{"type":"trade","received_at_ms":1788333216137,"data":{"e":"trade","E":1788333216305,"s":"BTCUSDT","t":6646666954,"p":"77732.62000000","q":"0.02573000","T":1788333216305,"m":false,"M":true}}
{"type":"depth","received_at_ms":1788333216147,"data":{"e":"depthUpdate","E":1788333216314,"s":"BTCUSDT","U":99556340541,"u":99556340629,"b":[["77732.61000000","4.68189000"],["77732.47000000","0.00000000"],["77731.99000000","0.62277000"],["77731.85000000","0.00400000"],["77731.25000000","0.00000000"],["77731.15000000","0.00000000"],["77731.10000000","0.00000000"],["77724.41000000","0.08000000"],["77708.51000000","0.00000000"],["77701.63000000","0.00335000"],["77691.74000000","0.02518000"],["77687.53000000","0.00000000"],["77658.09000000","0.14299000"],["77655.98000000","0.00000000"],["77653.39000000","1.61329000"],["77630.77000000","0.34652000"],["77626.98000000","0.00000000"],["69959.35000000","0.00176000"],["69959.34000000","0.00000000"],["69959.33000000","0.00009000"],["62186.00000000","0.00000000"]],"a":[["77732.62000000","0.09041000"],["77738.35000000","0.00000000"],["77741.90000000","0.00000000"],["77755.78000000","0.00000000"],["77758.67000000","0.64353000"],["77758.79000000","0.00000000"],["77759.96000000","0.00000000"],["77760.00000000","0.05900000"],["77760.48000000","0.00000000"],["77760.56000000","0.00000000"],["77760.85000000","0.02039000"],["77761.49000000","0.00000000"],["77761.82000000","0.11980000"],["77763.61000000","0.00000000"],["77764.13000000","0.00000000"],["77764.21000000","0.00000000"],["77764.50000000","0.05459000"],["77765.26000000","0.00000000"],["77768.00000000","0.03258000"],["77829.94000000","0.00411000"],["77948.94000000","0.00007000"]]}}
{"type":"depth","received_at_ms":1788333216246,"data":{"e":"depthUpdate","E":1788333216414,"s":"BTCUSDT","U":99556340630,"u":99556340650,"b":[["77732.61000000","4.68589000"],["77731.99000000","0.62270000"],["77731.06000000","0.00000000"],["77693.80000000","0.00000000"],["76183.39000000","0.00349000"],["69959.35000000","0.00192000"],["62186.09000000","0.00000000"],["62186.00000000","0.00000000"]],"a":[["77732.62000000","0.22670000"],["77749.61000000","0.14162000"],["77751.95000000","0.00000000"],["77756.24000000","0.00038000"],["77956.17000000","0.00000000"]]}}
{"type":"depth","received_at_ms":1788333216347,"data":{"e":"depthUpdate","E":1788333216514,"s":"BTCUSDT","U":99556340651,"u":99556340662,"b":[["77731.99000000","0.62270000"],["77731.25000000","0.00000000"],["77717.91000000","0.00411000"],["76031.02000000","0.00399000"],["62186.09000000","0.00032000"]],"a":[["77732.62000000","0.23262000"],["77738.62000000","0.00206000"],["77760.00000000","0.06158000"]]}}
{"type":"depth","received_at_ms":1788333216448,"data":{"e":"depthUpdate","E":1788333216615,"s":"BTCUSDT","U":99556340663,"u":99556340672,"b":[["77719.27000000","0.09487000"],["77713.98000000","0.00000000"],["77644.94000000","3.24555000"],["69959.35000000","0.00208000"],["62186.09000000","0.00000000"],["62186.00000000","0.00000000"]],"a":[["77732.62000000","0.09041000"],["77745.09000000","0.00000000"]]}}
{"type":"depth","received_at_ms":1788333216552,"data":{"e":"depthUpdate","E":1788333216714,"s":"BTCUSDT","U":99556340673,"u":99556340693,"b":[["77731.99000000","0.62277000"],["77731.20000000","0.05007000"],["77731.15000000","0.05000000"],["77724.01000000","0.89375000"],["77723.99000000","1.53184000"],["77721.42000000","0.00200000"],["77719.43000000","0.62747000"],["77715.39000000","0.00000000"],["77713.98000000","0.00007000"],["69959.35000000","0.00208000"],["62186.09000000","0.00000000"]],"a":[["77732.62000000","0.07728000"],["77741.32000000","0.00000000"],["77742.33000000","0.00643000"],["77745.09000000","0.00007000"],["77826.90000000","0.00000000"],["77829.49000000","2.15325000"],["77859.39000000","0.00000000"]]}}
{"type":"depth","received_at_ms":1788333216647,"data":{"e":"depthUpdate","E":1788333216814,"s":"BTCUSDT","U":99556340694,"u":99556340709,"b":[["77731.99000000","0.62277000"],["77731.20000000","0.05021000"],["77730.21000000","0.39420000"],["77724.04000000","0.00260000"],["77721.42000000","0.00000000"],["77705.31000000","0.10000000"],["77696.69000000","0.00000000"],["69959.35000000","0.00224000"]],"a":[["77748.23000000","0.00257000"],["78898.61000000","0.00030000"]]}}
{"type":"depth","received_at_ms":1788333216746,"data":{"e":"depthUpdate","E":1788333216914,"s":"BTCUSDT","U":99556340710,"u":99556340715,"b":[["77731.20000000","0.00021000"],["77731.06000000","0.00007000"],["75878.95000000","0.00457000"],["75557.14000000","0.00000000"],["69959.35000000","0.00224000"]],"a":[["81001.15000000","0.00328000"]]}}
{"type":"trade","received_at_ms":1788333216748,"data":{"e":"trade","E":1788333216915,"s":"BTCUSDT","t":6646666955,"p":"77732.61000000","q":"0.00032000","T":1788333216915,"m":true,"M":true}}
{"type":"depth","received_at_ms":1788333216847,"data":{"e":"depthUpdate","E":1788333217014,"s":"BTCUSDT","U":99556340716,"u":99556340745,"b":[["77732.61000000","4.68557000"],["77731.99000000","0.62277000"],["77731.20000000","0.00007000"],["77731.15000000","0.05014000"],["77731.10000000","0.05000000"],["77705.13000000","0.00000000"],["76566.62000000","0.00030000"],["76000.01000000","0.01858000"],["75727.19000000","0.00524000"],["75575.73000000","0.00605000"],["69959.35000000","0.00240000"],["69959.33000000","0.00000000"],["62186.09000000","0.00032000"],["62186.00000000","0.00000000"]],"a":[["77732.62000000","0.07741000"],["77732.63000000","0.00076000"],["77732.64000000","0.00013000"],["77748.22000000","0.00257000"],["77748.23000000","0.00000000"],["77758.69000000","0.00000000"]]}}
{"type":"depth","received_at_ms":1788333217069,"data":{"e":"depthUpdate","E":1788333217114,"s":"BTCUSDT","U":99556340746,"u":99556340756,"b":[["77731.15000000","0.05021000"],["77682.58000000","0.00000000"],["77646.05000000","1.32824000"],["69959.35000000","0.00240000"]],"a":[["77732.62000000","0.07734000"],["77746.21000000","0.00200000"]]}}
{"type":"trade","received_at_ms":1788333217069,"data":{"e":"trade","E":1788333217118,"s":"BTCUSDT","t":6646666956,"p":"77732.62000000","q":"0.00007000","T":1788333217118,"m":false,"M":true}}
{"type":"trade","received_at_ms":1788333217069,"data":{"e":"trade","E":1788333217118,"s":"BTCUSDT","t":6646666957,"p":"77732.62000000","q":"0.00007000","T":1788333217118,"m":false,"M":true}}
{"type":"trade","received_at_ms":1788333217069,"data":{"e":"trade","E":1788333217118,"s":"BTCUSDT","t":6646666958,"p":"77732.62000000","q":"0.00007000","T":1788333217118,"m":false,"M":true}}
{"type":"trade","received_at_ms":1788333217069,"data":{"e":"trade","E":1788333217118,"s":"BTCUSDT","t":6646666959,"p":"77732.62000000","q":"0.00007000","T":1788333217118,"m":false,"M":true}}
{"type":"trade","received_at_ms":1788333217069,"data":{"e":"trade","E":1788333217118,"s":"BTCUSDT","t":6646666960,"p":"77732.62000000","q":"0.00007000","T":1788333217118,"m":false,"M":true}}
{"type":"trade","received_at_ms":1788333217069,"data":{"e":"trade","E":1788333217118,"s":"BTCUSDT","t":6646666961,"p":"77732.62000000","q":"0.00007000","T":1788333217118,"m":false,"M":true}}
{"type":"trade","received_at_ms":1788333217069,"data":{"e":"trade","E":1788333217118,"s":"BTCUSDT","t":6646666962,"p":"77732.62000000","q":"0.00007000","T":1788333217118,"m":false,"M":true}}
{"type":"trade","received_at_ms":1788333217069,"data":{"e":"trade","E":1788333217118,"s":"BTCUSDT","t":6646666963,"p":"77732.62000000","q":"0.00007000","T":1788333217118,"m":false,"M":true}}
{"type":"trade","received_at_ms":1788333217069,"data":{"e":"trade","E":1788333217118,"s":"BTCUSDT","t":6646666964,"p":"77732.62000000","q":"0.00007000","T":1788333217118,"m":false,"M":true}}
{"type":"trade","received_at_ms":1788333217069,"data":{"e":"trade","E":1788333217118,"s":"BTCUSDT","t":6646666965,"p":"77732.62000000","q":"0.00137000","T":1788333217118,"m":false,"M":true}}
{"type":"trade","received_at_ms":1788333217069,"data":{"e":"trade","E":1788333217118,"s":"BTCUSDT","t":6646666966,"p":"77732.62000000","q":"0.00200000","T":1788333217118,"m":false,"M":true}}
{"type":"trade","received_at_ms":1788333217069,"data":{"e":"trade","E":1788333217118,"s":"BTCUSDT","t":6646666967,"p":"77732.62000000","q":"0.00052000","T":1788333217118,"m":false,"M":true}}
{"type":"trade","received_at_ms":1788333217069,"data":{"e":"trade","E":1788333217118,"s":"BTCUSDT","t":6646666968,"p":"77732.62000000","q":"0.00007000","T":1788333217118,"m":false,"M":true}}
{"type":"trade","received_at_ms":1788333217069,"data":{"e":"trade","E":1788333217118,"s":"BTCUSDT","t":6646666969,"p":"77732.62000000","q":"0.00007000","T":1788333217118,"m":false,"M":true}}
{"type":"trade","received_at_ms":1788333217069,"data":{"e":"trade","E":1788333217118,"s":"BTCUSDT","t":6646666970,"p":"77732.62000000","q":"0.00007000","T":1788333217118,"m":false,"M":true}}
{"type":"trade","received_at_ms":1788333217069,"data":{"e":"trade","E":1788333217118,"s":"BTCUSDT","t":6646666971,"p":"77732.62000000","q":"0.00007000","T":1788333217118,"m":false,"M":true}}
{"type":"trade","received_at_ms":1788333217069,"data":{"e":"trade","E":1788333217118,"s":"BTCUSDT","t":6646666972,"p":"77732.62000000","q":"0.00007000","T":1788333217118,"m":false,"M":true}}
{"type":"trade","received_at_ms":1788333217069,"data":{"e":"trade","E":1788333217118,"s":"BTCUSDT","t":6646666973,"p":"77732.62000000","q":"0.00007000","T":1788333217118,"m":false,"M":true}}
{"type":"trade","received_at_ms":1788333217069,"data":{"e":"trade","E":1788333217118,"s":"BTCUSDT","t":6646666974,"p":"77732.62000000","q":"0.00007000","T":1788333217118,"m":false,"M":true}}
{"type":"trade","received_at_ms":1788333217069,"data":{"e":"trade","E":1788333217118,"s":"BTCUSDT","t":6646666975,"p":"77732.62000000","q":"0.00007000","T":1788333217118,"m":false,"M":true}}
{"type":"trade","received_at_ms":1788333217069,"data":{"e":"trade","E":1788333217118,"s":"BTCUSDT","t":6646666976,"p":"77732.62000000","q":"0.00007000","T":1788333217118,"m":false,"M":true}}
{"type":"trade","received_at_ms":1788333217069,"data":{"e":"trade","E":1788333217118,"s":"BTCUSDT","t":6646666977,"p":"77732.62000000","q":"0.00007000","T":1788333217118,"m":false,"M":true}}
{"type":"trade","received_at_ms":1788333217069,"data":{"e":"trade","E":1788333217118,"s":"BTCUSDT","t":6646666978,"p":"77732.62000000","q":"0.00007000","T":1788333217118,"m":false,"M":true}}
{"type":"trade","received_at_ms":1788333217069,"data":{"e":"trade","E":1788333217118,"s":"BTCUSDT","t":6646666979,"p":"77732.62000000","q":"0.00007000","T":1788333217118,"m":false,"M":true}}
{"type":"trade","received_at_ms":1788333217069,"data":{"e":"trade","E":1788333217118,"s":"BTCUSDT","t":6646666980,"p":"77732.62000000","q":"0.00007000","T":1788333217118,"m":false,"M":true}}
{"type":"trade","received_at_ms":1788333217069,"data":{"e":"trade","E":1788333217118,"s":"BTCUSDT","t":6646666981,"p":"77732.62000000","q":"0.00008000","T":1788333217118,"m":false,"M":true}}
{"type":"trade","received_at_ms":1788333217069,"data":{"e":"trade","E":1788333217118,"s":"BTCUSDT","t":6646666982,"p":"77732.62000000","q":"0.00007000","T":1788333217118,"m":false,"M":true}}
{"type":"trade","received_at_ms":1788333217069,"data":{"e":"trade","E":1788333217118,"s":"BTCUSDT","t":6646666983,"p":"77732.62000000","q":"0.00013000","T":1788333217118,"m":false,"M":true}}
{"type":"trade","received_at_ms":1788333217069,"data":{"e":"trade","E":1788333217118,"s":"BTCUSDT","t":6646666984,"p":"77732.62000000","q":"0.00013000","T":1788333217118,"m":false,"M":true}}
{"type":"trade","received_at_ms":1788333217069,"data":{"e":"trade","E":1788333217118,"s":"BTCUSDT","t":6646666985,"p":"77732.63000000","q":"0.00007000","T":1788333217118,"m":false,"M":true}}
{"type":"trade","received_at_ms":1788333217069,"data":{"e":"trade","E":1788333217118,"s":"BTCUSDT","t":6646666986,"p":"77732.63000000","q":"0.00007000","T":1788333217118,"m":false,"M":true}}
{"type":"trade","received_at_ms":1788333217069,"data":{"e":"trade","E":1788333217118,"s":"BTCUSDT","t":6646666987,"p":"77732.63000000","q":"0.00002000","T":1788333217118,"m":false,"M":true}}
{"type":"trade","received_at_ms":1788333217069,"data":{"e":"trade","E":1788333217118,"s":"BTCUSDT","t":6646666988,"p":"77732.63000000","q":"0.00005000","T":1788333217118,"m":false,"M":true}}
{"type":"trade","received_at_ms":1788333217069,"data":{"e":"trade","E":1788333217118,"s":"BTCUSDT","t":6646666989,"p":"77732.63000000","q":"0.00007000","T":1788333217118,"m":false,"M":true}}
{"type":"trade","received_at_ms":1788333217069,"data":{"e":"trade","E":1788333217118,"s":"BTCUSDT","t":6646666990,"p":"77732.63000000","q":"0.00007000","T":1788333217118,"m":false,"M":true}}
{"type":"trade","received_at_ms":1788333217069,"data":{"e":"trade","E":1788333217118,"s":"BTCUSDT","t":6646666991,"p":"77732.63000000","q":"0.00007000","T":1788333217118,"m":false,"M":true}}
{"type":"trade","received_at_ms":1788333217069,"data":{"e":"trade","E":1788333217118,"s":"BTCUSDT","t":6646666992,"p":"77732.63000000","q":"0.00007000","T":1788333217118,"m":false,"M":true}}
{"type":"trade","received_at_ms":1788333217069,"data":{"e":"trade","E":1788333217118,"s":"BTCUSDT","t":6646666993,"p":"77732.63000000","q":"0.00007000","T":1788333217118,"m":false,"M":true}}
{"type":"trade","received_at_ms":1788333217069,"data":{"e":"trade","E":1788333217118,"s":"BTCUSDT","t":6646666994,"p":"77732.63000000","q":"0.00007000","T":1788333217118,"m":false,"M":true}}
{"type":"trade","received_at_ms":1788333217069,"data":{"e":"trade","E":1788333217118,"s":"BTCUSDT","t":6646666995,"p":"77732.63000000","q":"0.00013000","T":1788333217118,"m":false,"M":true}}
{"type":"trade","received_at_ms":1788333217069,"data":{"e":"trade","E":1788333217118,"s":"BTCUSDT","t":6646666996,"p":"77732.64000000","q":"0.00013000","T":1788333217118,"m":false,"M":true}}
{"type":"trade","received_at_ms":1788333217070,"data":{"e":"trade","E":1788333217118,"s":"BTCUSDT","t":6646666997,"p":"77732.75000000","q":"0.00007000","T":1788333217118,"m":false,"M":true}}
{"type":"trade","received_at_ms":1788333217070,"data":{"e":"trade","E":1788333217118,"s":"BTCUSDT","t":6646666998,"p":"77733.33000000","q":"0.00046000","T":1788333217118,"m":false,"M":true}}
{"type":"trade","received_at_ms":1788333217070,"data":{"e":"trade","E":1788333217118,"s":"BTCUSDT","t":6646666999,"p":"77733.33000000","q":"0.00074000","T":1788333217118,"m":false,"M":true}}
{"type":"trade","received_at_ms":1788333217070,"data":{"e":"trade","E":1788333217118,"s":"BTCUSDT","t":6646667000,"p":"77733.33000000","q":"0.00131000","T":1788333217118,"m":false,"M":true}}
{"type":"trade","received_at_ms":1788333217070,"data":{"e":"trade","E":1788333217118,"s":"BTCUSDT","t":6646667001,"p":"77733.34000000","q":"0.00007000","T":1788333217118,"m":false,"M":true}}
{"type":"trade","received_at_ms":1788333217070,"data":{"e":"trade","E":1788333217118,"s":"BTCUSDT","t":6646667002,"p":"77733.39000000","q":"0.00007000","T":1788333217118,"m":false,"M":true}}
{"type":"trade","received_at_ms":1788333217070,"data":{"e":"trade","E":1788333217118,"s":"BTCUSDT","t":6646667003,"p":"77733.39000000","q":"0.00007000","T":1788333217118,"m":false,"M":true}}
{"type":"trade","received_at_ms":1788333217070,"data":{"e":"trade","E":1788333217118,"s":"BTCUSDT","t":6646667004,"p":"77733.39000000","q":"0.00007000","T":1788333217118,"m":false,"M":true}}
{"type":"trade","received_at_ms":1788333217070,"data":{"e":"trade","E":1788333217118,"s":"BTCUSDT","t":6646667005,"p":"77733.40000000","q":"0.00007000","T":1788333217118,"m":false,"M":true}}
{"type":"trade","received_at_ms":1788333217070,"data":{"e":"trade","E":1788333217118,"s":"BTCUSDT","t":6646667006,"p":"77733.40000000","q":"0.00007000","T":1788333217118,"m":false,"M":true}}
{"type":"trade","received_at_ms":1788333217070,"data":{"e":"trade","E":1788333217118,"s":"BTCUSDT","t":6646667007,"p":"77733.40000000","q":"0.00027000","T":1788333217118,"m":false,"M":true}}
{"type":"trade","received_at_ms":1788333217070,"data":{"e":"trade","E":1788333217118,"s":"BTCUSDT","t":6646667008,"p":"77733.40000000","q":"0.00200000","T":1788333217118,"m":false,"M":true}}
{"type":"trade","received_at_ms":1788333217070,"data":{"e":"trade","E":1788333217118,"s":"BTCUSDT","t":6646667009,"p":"77733.40000000","q":"0.00200000","T":1788333217118,"m":false,"M":true}}
{"type":"trade","received_at_ms":1788333217070,"data":{"e":"trade","E":1788333217118,"s":"BTCUSDT","t":6646667010,"p":"77733.40000000","q":"0.00200000","T":1788333217118,"m":false,"M":true}}
{"type":"trade","received_at_ms":1788333217070,"data":{"e":"trade","E":1788333217119,"s":"BTCUSDT","t":6646667011,"p":"77733.40000000","q":"0.00200000","T":1788333217118,"m":false,"M":true}}
{"type":"trade","received_at_ms":1788333217070,"data":{"e":"trade","E":1788333217120,"s":"BTCUSDT","t":6646667012,"p":"77733.40000000","q":"0.00200000","T":1788333217120,"m":false,"M":true}}
