{"type":"depth","received_at_ms":1788407359510,"data":{"e":"depthUpdate","E":1788407359714,"s":"BTCUSDT","U":99603303696,"u":99603303697,"b":[["77612.73000000","0.00320000"],["77534.96000000","0.00128000"]],"a":[]}}
{"type":"depth","received_at_ms":1788407359610,"data":{"e":"depthUpdate","E":1788407359814,"s":"BTCUSDT","U":99603303698,"u":99603303706,"b":[["77602.78000000","0.41643000"],["69910.55000000","0.00441000"],["62143.00000000","0.01609000"]],"a":[["77678.39000000","1.31708000"],["77679.95000000","0.00611000"]]}}
{"type":"depth","received_at_ms":1788407359710,"data":{"e":"depthUpdate","E":1788407359914,"s":"BTCUSDT","U":99603303707,"u":99603303726,"b":[["77678.38000000","12.54234000"],["77678.37000000","0.00063000"],["77664.07000000","0.00007000"],["69910.55000000","0.00457000"]],"a":[["77678.39000000","1.31715000"],["77678.40000000","0.00077000"],["77679.30000000","0.02917000"],["77679.95000000","0.00625000"],["77682.71000000","0.10245000"],["77695.15000000","0.00007000"]]}}
{"type":"depth","received_at_ms":1788407359810,"data":{"e":"depthUpdate","E":1788407360014,"s":"BTCUSDT","U":99603303727,"u":99603303734,"b":[["77677.90000000","0.00000000"],["77677.19000000","0.00643000"],["77561.96000000","0.01571000"],["77534.02000000","0.00000000"],["69910.55000000","0.00425000"],["62142.71000000","0.00032000"]],"a":[["77692.04000000","0.00400000"],["77693.46000000","0.00000000"],["77693.56000000","0.00643000"],["77694.35000000","0.00000000"]]}}
{"type":"depth","received_at_ms":1788407359910,"data":{"e":"depthUpdate","E":1788407360114,"s":"BTCUSDT","U":99603303735,"u":99603303744,"b":[["77678.38000000","12.54241000"],["77677.64000000","0.22223000"],["69910.55000000","0.00457000"],["62143.00000000","0.01809000"]],"a":[["77678.39000000","1.31865000"]]}}
{"type":"depth","received_at_ms":1788407360010,"data":{"e":"depthUpdate","E":1788407360214,"s":"BTCUSDT","U":99603303745,"u":99603303952,"b":[["77678.38000000","6.16090000"],["77678.37000000","0.00063000"],["77678.26000000","0.00000000"],["77677.92000000","0.00000000"],["77677.91000000","0.00000000"],["77677.76000000","0.00000000"],["77677.66000000","0.00000000"],["77677.65000000","0.00028000"],["77677.64000000","0.09305000"],["77677.19000000","0.00000000"],["77677.18000000","0.00000000"],["77677.14000000","0.00014000"],["77677.07000000","0.00000000"],["77676.96000000","0.00014000"],["77676.95000000","0.58674000"],["77676.94000000","0.00851000"],["77676.93000000","0.03890000"],["77676.31000000","0.00098000"],["77675.90000000","0.00021000"],["77675.85000000","0.00007000"],["77675.72000000","0.03283000"],["77675.68000000","0.00928000"],["77674.89000000","0.00007000"],["77674.88000000","1.18740000"],["77674.78000000","0.00007000"],["77674.75000000","0.00000000"],["77674.65000000","0.02021000"],["77674.29000000","0.00000000"],["77673.11000000","0.00257000"],["77672.22000000","0.00000000"],["77672.01000000","0.00935000"],["77670.82000000","0.00200000"],["77670.55000000","0.00800000"],["77670.04000000","0.00000000"],["77670.03000000","0.00000000"],["77670.02000000","0.01200000"],["77670.01000000","0.00000000"],["77666.46000000","0.30866000"],["77666.45000000","0.00000000"],["77665.14000000","0.00000000"],["77663.52000000","0.13635000"],["77663.18000000","0.00000000"],["77662.41000000","0.00000000"],["77660.89000000","0.00000000"],["77660.38000000","0.25756000"],["77659.05000000","0.32182000"],["77655.17000000","0.00000000"],["77652.84000000","0.00200000"],["77620.71000000","4.63449000"],["77610.22000000","4.63449000"],["77602.78000000","0.23067000"],["77601.61000000","0.00000000"],["69910.55000000","0.00432000"],["69910.54000000","0.00009000"],["62143.00000000","0.01609000"],["62142.71000000","0.00000000"],["62142.70000000","0.00042000"]],"a":[["77678.39000000","1.52319000"],["77678.64000000","0.00014000"],["77679.30000000","0.02924000"],["77679.82000000","0.10699000"],["77679.83000000","0.10245000"],["77679.93000000","0.00007000"],["77679.94000000","0.00000000"],["77679.95000000","0.00021000"],["77680.79000000","0.00208000"],["77681.10000000","0.12364000"],["77681.25000000","0.00007000"],["77681.98000000","0.00000000"],["77681.99000000","0.03176000"],["77682.83000000","0.00000000"],["77684.72000000","0.00000000"],["77685.75000000","0.00526000"],["77686.89000000","0.00400000"],["77688.45000000","0.00000000"],["77688.63000000","0.00257000"],["77688.92000000","0.00400000"],["77689.34000000","0.00535000"],["77689.54000000","0.61436000"],["77690.21000000","0.00643000"],["77690.63000000","0.00200000"],["77691.79000000","0.00000000"],["77691.89000000","0.00000000"],["77692.04000000","0.00000000"],["77692.45000000","1.15659000"],["77693.39000000","1.72081000"],["77693.56000000","0.00000000"],["77694.22000000","0.00000000"],["77694.23000000","0.00000000"],["77695.51000000","0.38627000"],["77695.67000000","0.00000000"],["77696.61000000","4.63449000"],["77696.89000000","0.00000000"],["77697.11000000","0.00000000"],["77697.26000000","0.00000000"],["77701.22000000","0.64391000"],["77702.34000000","0.25756000"],["77706.47000000","0.00000000"],["77707.49000000","0.00000000"],["77714.45000000","0.87686000"],["77715.43000000","0.00000000"],["77717.24000000","0.00000000"]]}}
{"type":"depth","received_at_ms":1788407360110,"data":{"e":"depthUpdate","E":1788407360314,"s":"BTCUSDT","U":99603303953,"u":99603304062,"b":[["77678.38000000","10.79524000"],["77678.37000000","0.00063000"],["77677.76000000","0.00100000"],["77677.65000000","0.00014000"],["77677.64000000","0.09305000"],["77677.15000000","0.00643000"],["77677.13000000","0.01698000"],["77676.95000000","0.58688000"],["77676.92000000","0.01028000"],["77676.31000000","0.00000000"],["77676.11000000","0.00643000"],["77675.91000000","0.00000000"],["77675.90000000","0.00007000"],["77675.68000000","0.00528000"],["77674.78000000","0.00014000"],["77674.42000000","0.00027000"],["77672.31000000","2.22541000"],["77672.30000000","4.63449000"],["77672.00000000","0.00014000"],["77670.82000000","0.00000000"],["77670.54000000","0.25131000"],["77670.02000000","0.00400000"],["77669.99000000","0.00200000"],["77666.47000000","0.08642000"],["77656.11000000","0.00200000"],["77652.84000000","0.00000000"],["77620.71000000","0.00000000"],["77610.22000000","0.00000000"],["77573.90000000","0.00000000"],["69910.55000000","0.00432000"],["62143.00000000","0.01609000"],["62142.70000000","0.00022000"]],"a":[["77678.39000000","1.34161000"],["77678.40000000","0.00098000"],["77679.30000000","0.02924000"],["77679.81000000","0.00007000"],["77679.82000000","0.10713000"],["77679.83000000","0.10259000"],["77679.93000000","0.00000000"],["77679.95000000","0.00007000"],["77680.00000000","0.03028000"],["77681.10000000","0.12378000"],["77682.61000000","0.00534000"],["77682.70000000","0.23385000"],["77685.75000000","0.00000000"],["77686.89000000","0.00000000"],["77687.14000000","0.00520000"],["77688.92000000","0.00000000"],["77690.21000000","0.00000000"],["77690.63000000","0.00000000"],["77690.71000000","0.00400000"],["77692.27000000","0.00643000"],["77692.44000000","0.00200000"],["77708.00000000","0.73000000"],["77710.00000000","0.03200000"],["77806.98000000","0.00000000"]]}}
{"type":"depth","received_at_ms":1788407360210,"data":{"e":"depthUpdate","E":1788407360414,"s":"BTCUSDT","U":99603304063,"u":99603304095,"b":[["77678.38000000","10.79531000"],["77678.37000000","0.00070000"],["77677.76000000","0.00000000"],["77677.64000000","0.09312000"],["77677.25000000","0.00000000"],["77677.16000000","0.00099000"],["77677.15000000","0.00657000"],["77676.92000000","0.01021000"],["77672.32000000","0.01400000"],["77671.99000000","0.60292000"],["77670.02000000","0.00000000"],["77669.99000000","0.00000000"],["77656.11000000","0.00000000"],["77654.85000000","0.00600000"],["77582.91000000","0.04378000"],["76513.20000000","0.00030000"],["69910.55000000","0.00432000"],["62143.00000000","0.01609000"]],"a":[["77704.00000000","0.03265000"],["77816.02000000","0.00971000"]]}}
{"type":"depth","received_at_ms":1788407360312,"data":{"e":"depthUpdate","E":1788407360516,"s":"BTCUSDT","U":99603304096,"u":99603304106,"b":[["77677.35000000","0.00400000"],["69910.55000000","0.00448000"],["62142.71000000","0.00032000"]],"a":[["77678.64000000","0.00007000"],["77701.22000000","0.00000000"],["77703.54000000","0.64391000"],["77717.24000000","0.00007000"],["77731.46000000","0.00000000"],["77731.64000000","0.12878000"]]}}
{"type":"depth","received_at_ms":1788407360410,"data":{"e":"depthUpdate","E":1788407360614,"s":"BTCUSDT","U":99603304107,"u":99603304124,"b":[["69910.55000000","0.00432000"],["62143.00000000","0.01609000"],["62142.71000000","0.00000000"]],"a":[["77688.12000000","0.00400000"],["77731.64000000","0.00000000"],["77731.84000000","0.00000000"],["78843.57000000","0.00030000"]]}}
{"type":"depth","received_at_ms":1788407360510,"data":{"e":"depthUpdate","E":1788407360714,"s":"BTCUSDT","U":99603304125,"u":99603304135,"b":[["77678.38000000","10.80182000"],["77678.37000000","0.00077000"],["77676.92000000","0.01014000"],["77676.11000000","0.00000000"],["77674.65000000","0.02028000"],["69910.55000000","0.00448000"]],"a":[["77678.39000000","1.34168000"],["77678.40000000","0.00105000"],["77679.81000000","0.00653000"]]}}
{"type":"depth","received_at_ms":1788407360610,"data":{"e":"depthUpdate","E":1788407360814,"s":"BTCUSDT","U":99603304136,"u":99603304164,"b":[["77678.38000000","10.80168000"],["77677.35000000","0.00000000"],["77677.16000000","0.00000000"],["77677.15000000","0.00014000"],["77676.92000000","0.01028000"],["77676.57000000","0.00400000"],["77676.31000000","0.00099000"],["77675.34000000","0.00643000"],["77674.42000000","0.00000000"],["77654.85000000","0.00400000"],["77651.41000000","0.00200000"],["69910.55000000","0.00432000"],["69910.54000000","0.00000000"]],"a":[["77678.39000000","1.34156000"],["77678.64000000","0.00014000"],["77679.30000000","0.02924000"],["77679.81000000","0.00667000"],["77682.00000000","0.03000000"],["77689.52000000","0.00200000"],["77692.44000000","0.00000000"],["77702.99000000","0.00000000"],["77717.24000000","0.00000000"]]}}
{"type":"depth","received_at_ms":1788407360709,"data":{"e":"depthUpdate","E":1788407360914,"s":"BTCUSDT","U":99603304165,"u":99603304200,"b":[["77678.38000000","10.80146000"],["77678.37000000","0.00063000"],["77678.25000000","0.00000000"],["77677.64000000","0.09305000"],["77677.15000000","0.00000000"],["77676.90000000","0.00400000"],["77676.57000000","0.00000000"],["77675.89000000","0.02035000"],["77675.68000000","0.00535000"],["77664.07000000","0.00007000"],["77654.73000000","0.00200000"],["77651.41000000","0.00000000"],["77643.15000000","0.00400000"],["69910.55000000","0.00448000"]],"a":[["77684.10000000","0.10645000"],["77684.74000000","0.00536000"],["77689.52000000","0.00000000"],["77692.44000000","0.00200000"],["77695.15000000","0.00007000"],["77705.00000000","0.70000000"],["77708.00000000","0.03000000"],["77715.30000000","0.00000000"]]}}
{"type":"depth","received_at_ms":1788407360810,"data":{"e":"depthUpdate","E":1788407361014,"s":"BTCUSDT","U":99603304201,"u":99603304223,"b":[["77678.38000000","10.76921000"],["77678.37000000","0.00063000"],["77677.76000000","0.00099000"],["77677.16000000","0.00400000"],["77677.15000000","0.00643000"],["77676.90000000","0.00000000"],["77676.31000000","0.00000000"],["77675.34000000","0.00000000"],["77674.29000000","0.00027000"],["77672.32000000","0.10042000"],["77666.47000000","0.00000000"],["77654.73000000","0.00000000"],["77654.58000000","0.00200000"],["77599.06000000","0.72112000"],["69910.55000000","0.00432000"],["62143.00000000","0.01609000"],["62142.71000000","0.00032000"]],"a":[["77678.39000000","1.30956000"],["77683.75000000","0.00670000"],["77731.28000000","0.00000000"],["77731.34000000","0.00000000"]]}}
{"type":"depth","received_at_ms":1788407360911,"data":{"e":"depthUpdate","E":1788407361114,"s":"BTCUSDT","U":99603304224,"u":99603304246,"b":[["77678.38000000","10.76935000"],["77678.37000000","0.00077000"],["77677.64000000","0.09312000"],["77675.68000000","0.00528000"],["77582.91000000","0.00000000"],["77376.94000000","0.00020000"],["69910.55000000","0.00432000"]],"a":[["77678.64000000","0.00007000"],["77717.24000000","0.00007000"],["77747.28000000","0.00000000"],["77755.40000000","0.20237000"],["77755.41000000","0.25753000"],["77755.73000000","0.00000000"],["77776.98000000","0.00089000"]]}}
{"type":"depth","received_at_ms":1788407361010,"data":{"e":"depthUpdate","E":1788407361214,"s":"BTCUSDT","U":99603304247,"u":99603304260,"b":[["77678.38000000","10.80161000"],["77673.90000000","0.00257000"],["77673.11000000","0.00000000"],["77615.41000000","0.06394000"],["77581.09000000","0.03992000"],["76951.02000000","0.00000000"],["69910.55000000","0.00432000"],["62142.71000000","0.00000000"]],"a":[["77688.63000000","0.00000000"],["77689.43000000","0.00257000"],["77744.43000000","0.06429000"],["78386.45000000","0.00000000"]]}}
{"type":"depth","received_at_ms":1788407361110,"data":{"e":"depthUpdate","E":1788407361314,"s":"BTCUSDT","U":99603304261,"u":99603304274,"b":[["77678.38000000","10.92725000"],["77645.10000000","0.00400000"],["77643.15000000","0.00000000"],["69910.55000000","0.00432000"],["62143.00000000","0.01609000"],["62142.70000000","0.00022000"]],"a":[]}}
{"type":"depth","received_at_ms":1788407361212,"data":{"e":"depthUpdate","E":1788407361415,"s":"BTCUSDT","U":99603304275,"u":99603304285,"b":[["76513.20000000","0.00030000"],["76277.83000000","0.00000000"],["71462.78000000","0.00014000"],["69910.55000000","0.00448000"],["62143.00000000","0.01609000"]],"a":[]}}
{"type":"depth","received_at_ms":1788407361310,"data":{"e":"depthUpdate","E":1788407361514,"s":"BTCUSDT","U":99603304286,"u":99603304289,"b":[["69910.55000000","0.00432000"],["62142.71000000","0.00032000"]],"a":[]}}
{"type":"depth","received_at_ms":1788407361411,"data":{"e":"depthUpdate","E":1788407361614,"s":"BTCUSDT","U":99603304290,"u":99603304295,"b":[["69910.55000000","0.00448000"],["62142.71000000","0.00000000"]],"a":[["78843.57000000","0.00030000"]]}}
{"type":"depth","received_at_ms":1788407361510,"data":{"e":"depthUpdate","E":1788407361715,"s":"BTCUSDT","U":99603304296,"u":99603304303,"b":[["77674.89000000","0.30866000"],["75805.56000000","0.00000000"],["69910.55000000","0.00448000"]],"a":[["77679.81000000","0.00674000"],["77730.21000000","0.00000000"]]}}
{"type":"depth","received_at_ms":1788407361610,"data":{"e":"depthUpdate","E":1788407361814,"s":"BTCUSDT","U":99603304304,"u":99603304309,"b":[["69910.55000000","0.00464000"]],"a":[["77730.52000000","0.12878000"],["77730.85000000","0.00000000"]]}}
{"type":"depth","received_at_ms":1788407361710,"data":{"e":"depthUpdate","E":1788407361914,"s":"BTCUSDT","U":99603304310,"u":99603304317,"b":[["77678.38000000","10.92466000"],["77664.07000000","0.00000000"],["69910.55000000","0.00432000"],["69910.54000000","0.00009000"]],"a":[["77695.15000000","0.00000000"],["77730.52000000","0.00000000"],["77731.35000000","0.00000000"]]}}
{"type":"depth","received_at_ms":1788407361812,"data":{"e":"depthUpdate","E":1788407362014,"s":"BTCUSDT","U":99603304318,"u":99603304325,"b":[["77664.07000000","0.00007000"],["71462.78000000","0.00000000"],["69910.55000000","0.00464000"],["62142.71000000","0.00032000"]],"a":[["77678.39000000","1.30699000"],["77695.15000000","0.00007000"],["77730.62000000","0.12878000"]]}}
{"type":"depth","received_at_ms":1788407361911,"data":{"e":"depthUpdate","E":1788407362115,"s":"BTCUSDT","U":99603304326,"u":99603304333,"b":[["77678.38000000","10.92459000"],["77678.37000000","0.00070000"],["77615.41000000","0.00000000"],["69910.55000000","0.00448000"]],"a":[["77730.62000000","0.00000000"],["77744.43000000","0.00000000"]]}}
{"type":"depth","received_at_ms":1788407362009,"data":{"e":"depthUpdate","E":1788407362214,"s":"BTCUSDT","U":99603304334,"u":99603304357,"b":[["77678.38000000","10.92467000"],["77615.24000000","0.06509000"],["76968.19000000","0.00000000"],["69910.55000000","0.00448000"],["62142.71000000","0.00000000"]],"a":[["77678.39000000","1.30703000"],["77678.40000000","0.00098000"],["77679.81000000","0.00660000"],["77679.82000000","0.00028000"],["77681.09000000","0.00014000"],["77690.71000000","0.00000000"],["77691.21000000","0.00400000"],["77730.80000000","0.12878000"],["77749.62000000","0.06294000"],["77780.09000000","2.60864000"],["77782.57000000","0.03463000"],["77785.19000000","0.00000000"],["78353.79000000","0.00000000"]]}}
{"type":"depth","received_at_ms":1788407362110,"data":{"e":"depthUpdate","E":1788407362314,"s":"BTCUSDT","U":99603304358,"u":99603304375,"b":[["69910.55000000","0.00448000"],["62143.00000000","0.01609000"],["62142.70000000","0.00022000"]],"a":[["77679.81000000","0.00660000"],["77679.82000000","0.00014000"],["77682.00000000","0.03014000"],["77692.27000000","0.00000000"],["77693.11000000","0.00643000"],["77816.02000000","0.00000000"]]}}
{"type":"depth","received_at_ms":1788407362210,"data":{"e":"depthUpdate","E":1788407362414,"s":"BTCUSDT","U":99603304376,"u":99603304382,"b":[["76513.20000000","0.00030000"],["69910.55000000","0.00464000"]],"a":[["77730.80000000","0.00000000"],["77807.81000000","0.00971000"]]}}
{"type":"depth","received_at_ms":1788407362309,"data":{"e":"depthUpdate","E":1788407362514,"s":"BTCUSDT","U":99603304383,"u":99603304387,"b":[["69910.55000000","0.00448000"],["62142.71000000","0.00032000"]],"a":[["77807.81000000","0.00000000"]]}}
{"type":"depth","received_at_ms":1788407362410,"data":{"e":"depthUpdate","E":1788407362614,"s":"BTCUSDT","U":99603304388,"u":99603304395,"b":[["69910.55000000","0.00448000"],["62142.71000000","0.00000000"]],"a":[["77678.39000000","1.30710000"],["77729.57000000","0.12878000"],["77815.70000000","0.00971000"],["78843.57000000","0.00030000"]]}}
{"type":"depth","received_at_ms":1788407362510,"data":{"e":"depthUpdate","E":1788407362714,"s":"BTCUSDT","U":99603304396,"u":99603304427,"b":[["77678.38000000","10.92404000"],["77678.37000000","0.00014000"],["77647.05000000","0.00400000"],["77645.10000000","0.00000000"],["69910.55000000","0.00448000"],["69910.54000000","0.00000000"],["69910.53000000","0.00009000"]],"a":[["77678.39000000","1.27096000"],["77683.75000000","0.00000000"],["77684.74000000","0.00000000"],["77687.14000000","0.00000000"],["77691.21000000","0.00000000"],["77692.57000000","0.00400000"],["77693.11000000","0.00000000"],["77694.29000000","0.00643000"],["77729.57000000","0.00000000"]]}}
{"type":"depth","received_at_ms":1788407362610,"data":{"e":"depthUpdate","E":1788407362814,"s":"BTCUSDT","U":99603304428,"u":99603304435,"b":[["69910.55000000","0.00448000"],["62143.00000000","0.01609000"]],"a":[["77678.39000000","1.27086000"],["77715.13000000","0.09501000"]]}}
{"type":"depth","received_at_ms":1788407362710,"data":{"e":"depthUpdate","E":1788407362914,"s":"BTCUSDT","U":99603304436,"u":99603304439,"b":[["77678.38000000","10.92396000"],["69910.55000000","0.00464000"]],"a":[]}}
{"type":"depth","received_at_ms":1788407362811,"data":{"e":"depthUpdate","E":1788407363015,"s":"BTCUSDT","U":99603304440,"u":99603304450,"b":[["77675.06000000","0.00257000"],["77673.90000000","0.00000000"],["77664.07000000","0.00007000"],["69910.55000000","0.00448000"],["62142.71000000","0.00032000"]],"a":[["77689.43000000","0.00000000"],["77690.59000000","0.00257000"],["77695.15000000","0.00007000"]]}}
{"type":"depth","received_at_ms":1788407362910,"data":{"e":"depthUpdate","E":1788407363114,"s":"BTCUSDT","U":99603304451,"u":99603304454,"b":[["69910.55000000","0.00464000"],["62143.00000000","0.01809000"]],"a":[]}}
{"type":"depth","received_at_ms":1788407363212,"data":{"e":"depthUpdate","E":1788407363214,"s":"BTCUSDT","U":99603304455,"u":99603304460,"b":[["69910.55000000","0.00448000"],["62143.00000000","0.01609000"],["62142.71000000","0.00000000"]],"a":[["77728.72000000","0.12878000"],["77729.64000000","0.00000000"]]}}
{"type":"depth","received_at_ms":1788407363212,"data":{"e":"depthUpdate","E":1788407363314,"s":"BTCUSDT","U":99603304461,"u":99603304473,"b":[["69910.55000000","0.00464000"],["62143.00000000","0.01609000"],["62142.70000000","0.00022000"]],"a":[["77728.72000000","0.00000000"],["77728.83000000","0.00000000"],["77729.01000000","0.12878000"]]}}
{"type":"depth","received_at_ms":1788407363212,"data":{"e":"depthUpdate","E":1788407363415,"s":"BTCUSDT","U":99603304474,"u":99603304479,"b":[["76513.20000000","0.00030000"],["69910.55000000","0.00448000"]],"a":[["77729.01000000","0.00000000"]]}}
{"type":"depth","received_at_ms":1788407363310,"data":{"e":"depthUpdate","E":1788407363514,"s":"BTCUSDT","U":99603304480,"u":99603304486,"b":[["77677.84000000","0.00539000"],["77615.24000000","0.00000000"],["77590.61000000","0.06499000"],["69910.55000000","0.00448000"],["62142.71000000","0.00032000"]],"a":[["77729.11000000","0.12878000"]]}}
{"type":"depth","received_at_ms":1788407363410,"data":{"e":"depthUpdate","E":1788407363614,"s":"BTCUSDT","U":99603304487,"u":99603304505,"b":[["77678.38000000","10.92411000"],["77678.37000000","0.00021000"],["77677.84000000","0.00553000"],["77675.89000000","0.02021000"],["69910.55000000","0.00448000"],["62143.00000000","0.01609000"],["62142.71000000","0.00000000"]],"a":[["77729.11000000","0.00000000"]]}}
{"type":"depth","received_at_ms":1788407363510,"data":{"e":"depthUpdate","E":1788407363714,"s":"BTCUSDT","U":99603304506,"u":99603304510,"b":[["69910.55000000","0.00464000"]],"a":[["78843.57000000","0.00030000"]]}}
{"type":"depth","received_at_ms":1788407363611,"data":{"e":"depthUpdate","E":1788407363814,"s":"BTCUSDT","U":99603304511,"u":99603304513,"b":[["69910.55000000","0.00432000"]],"a":[["77837.53000000","0.00061000"]]}}
{"type":"depth","received_at_ms":1788407363710,"data":{"e":"depthUpdate","E":1788407363915,"s":"BTCUSDT","U":99603304514,"u":99603304516,"b":[["69910.55000000","0.00464000"]],"a":[["77715.13000000","0.00000000"]]}}
{"type":"depth","received_at_ms":1788407363811,"data":{"e":"depthUpdate","E":1788407364015,"s":"BTCUSDT","U":99603304517,"u":99603304525,"b":[["77664.07000000","0.00007000"],["69910.55000000","0.00448000"],["62143.00000000","0.01609000"],["62142.71000000","0.00032000"]],"a":[["77695.15000000","0.00007000"]]}}
{"type":"depth","received_at_ms":1788407363910,"data":{"e":"depthUpdate","E":1788407364114,"s":"BTCUSDT","U":99603304526,"u":99603304529,"b":[["69910.55000000","0.00448000"]],"a":[]}}
{"type":"depth","received_at_ms":1788407364010,"data":{"e":"depthUpdate","E":1788407364214,"s":"BTCUSDT","U":99603304530,"u":99603304531,"b":[["75500.00000000","46.12765000"],["62142.71000000","0.00000000"]],"a":[]}}
{"type":"depth","received_at_ms":1788407364110,"data":{"e":"depthUpdate","E":1788407364314,"s":"BTCUSDT","U":99603304532,"u":99603304549,"b":[["77656.86000000","0.00000000"],["77633.57000000","0.00000000"],["75561.55000000","0.00009000"],["69910.55000000","0.00448000"],["69910.53000000","0.00000000"],["62143.00000000","0.01609000"],["62142.70000000","0.00022000"]],"a":[["77678.39000000","1.26827000"],["77707.17000000","0.00000000"],["77725.79000000","0.00000000"],["77730.15000000","0.12878000"],["81006.26000000","0.00000000"]]}}
{"type":"depth","received_at_ms":1788407364210,"data":{"e":"depthUpdate","E":1788407364414,"s":"BTCUSDT","U":99603304550,"u":99603305156,"b":[["77679.99000000","14.23008000"],["77679.98000000","0.00014000"],["77679.94000000","0.00000000"],["77679.83000000","0.00129000"],["77679.82000000","5.07129000"],["77679.81000000","0.00007000"],["77679.80000000","0.00000000"],["77679.70000000","0.00000000"],["77679.30000000","1.11228000"],["77679.29000000","0.41262000"],["77679.28000000","0.00000000"],["77679.19000000","0.00000000"],["77678.98000000","0.00000000"],["77678.78000000","0.00000000"],["77678.64000000","0.00014000"],["77678.63000000","0.00000000"],["77678.39000000","3.55269000"],["77678.38000000","0.49195000"],["77678.37000000","0.00000000"],["77678.25000000","0.00400000"],["77677.76000000","0.00000000"],["77677.65000000","0.00000000"],["77677.64000000","0.00428000"],["77677.33000000","0.03276000"],["77677.15000000","0.00007000"],["77677.14000000","0.00000000"],["77676.96000000","0.00000000"],["77676.94000000","0.00837000"],["77676.93000000","0.03883000"],["77676.92000000","0.01014000"],["77676.58000000","0.00000000"],["77675.90000000","0.00807000"],["77675.85000000","0.00800000"],["77675.72000000","0.00007000"],["77675.68000000","0.00535000"],["77675.57000000","0.00007000"],["77675.06000000","0.00000000"],["77674.90000000","0.00000000"],["77674.00000000","0.00013000"],["77673.65000000","0.12874000"],["77672.32000000","0.00000000"],["77672.05000000","0.00008000"],["77672.01000000","0.00535000"],["77671.14000000","0.00000000"],["77671.11000000","0.00000000"],["77670.55000000","0.00400000"],["77669.99000000","0.14187000"],["77669.53000000","0.00000000"],["77669.50000000","0.00000000"],["77669.16000000","0.00000000"],["77668.81000000","0.00007000"],["77668.64000000","0.00000000"],["77667.20000000","0.00000000"],["77666.89000000","0.34897000"],["77666.88000000","0.41262000"],["77665.90000000","0.10123000"],["77665.47000000","0.03000000"],["77665.13000000","0.00000000"],["77664.28000000","0.00008000"],["77663.52000000","0.00000000"],["77660.40000000","0.00008000"],["77659.34000000","0.00022000"],["77659.05000000","0.00000000"],["77658.91000000","0.00200000"],["77656.92000000","0.00000000"],["77656.64000000","0.00000000"],["77656.63000000","0.30000000"],["77656.52000000","0.30018000"],["77656.51000000","0.00000000"],["77656.31000000","0.00000000"],["77655.45000000","0.00000000"],["77655.08000000","0.34782000"],["77654.58000000","0.00000000"],["77652.63000000","0.00008000"],["77651.57000000","0.00000000"],["77648.75000000","0.00008000"],["77647.68000000","0.00000000"],["77647.05000000","0.00000000"],["77644.92000000","1.27553000"],["77644.86000000","0.00008000"],["77643.80000000","0.00000000"],["77640.98000000","0.00008000"],["77640.14000000","0.37684000"],["77640.04000000","0.00000000"],["77639.92000000","0.00000000"],["77638.33000000","4.63449000"],["77637.96000000","0.00200000"],["77636.03000000","0.00000000"],["77635.49000000","0.00000000"],["77634.17000000","0.00000000"],["77631.20000000","0.00000000"],["77625.47000000","0.00000000"],["77623.61000000","0.00000000"],["77573.64000000","0.00000000"],["76513.20000000","0.00000000"],["69912.00000000","0.00030000"],["69910.55000000","0.00000000"]],"a":[["77678.39000000","0.00000000"],["77678.40000000","0.00000000"],["77678.64000000","0.00000000"],["77678.99000000","0.00000000"],["77679.20000000","0.00000000"],["77679.29000000","0.00000000"],["77679.30000000","0.00000000"],["77679.71000000","0.00000000"],["77679.81000000","0.00000000"],["77679.82000000","0.00000000"],["77679.83000000","0.00000000"],["77679.95000000","0.00000000"],["77679.99000000","0.00000000"],["77680.00000000","0.01532000"],["77680.01000000","0.00063000"],["77680.79000000","0.00000000"],["77681.10000000","0.00021000"],["77681.15000000","0.00000000"],["77681.25000000","0.00014000"],["77681.26000000","0.00014000"],["77681.98000000","0.00014000"],["77681.99000000","0.00028000"],["77682.00000000","0.03021000"],["77682.20000000","0.00000000"],["77682.50000000","0.00007000"],["77682.61000000","0.00548000"],["77682.69000000","0.00007000"],["77682.70000000","0.00014000"],["77682.71000000","0.00014000"],["77682.76000000","0.00321000"],["77682.77000000","0.03162000"],["77683.86000000","0.00904000"],["77683.95000000","0.00000000"],["77684.00000000","0.03000000"],["77684.10000000","0.00400000"],["77684.71000000","0.00000000"],["77685.07000000","0.00000000"],["77685.36000000","0.00000000"],["77685.65000000","0.00013000"],["77685.89000000","0.00000000"],["77686.36000000","0.00007000"],["77686.95000000","0.00000000"],["77687.01000000","0.00000000"],["77687.02000000","0.00000000"],["77687.38000000","0.00000000"],["77687.49000000","0.00000000"],["77687.60000000","0.00008000"],["77687.91000000","0.02896000"],["77688.12000000","0.00000000"],["77688.43000000","0.00000000"],["77688.46000000","0.00000000"],["77689.07000000","0.00407000"],["77689.34000000","0.00000000"],["77689.53000000","0.00000000"],["77689.54000000","0.00007000"],["77690.22000000","0.00007000"],["77690.41000000","0.00008000"],["77690.59000000","0.00000000"],["77690.64000000","0.00000000"],["77691.09000000","0.00000000"],["77691.32000000","0.00000000"],["77692.28000000","0.00000000"],["77692.35000000","0.00400000"],["77692.45000000","0.01200000"],["77692.46000000","0.00000000"],["77692.47000000","0.00000000"],["77692.48000000","0.00000000"],["77692.57000000","0.00000000"],["77694.29000000","0.00000000"],["77694.30000000","0.00000000"],["77695.37000000","0.00008000"],["77695.51000000","0.00000000"],["77695.54000000","0.16870000"],["77696.58000000","0.00000000"],["77696.61000000","0.00000000"],["77697.34000000","0.02000000"],["77697.83000000","0.00000000"],["77698.13000000","0.12870000"],["77698.18000000","0.00000000"],["77698.46000000","0.00000000"],["77698.86000000","0.00643000"],["77699.25000000","0.00008000"],["77699.86000000","0.00000000"],["77699.87000000","0.17745000"],["77701.51000000","0.00000000"],["77702.07000000","0.00000000"],["77702.34000000","0.00000000"],["77702.86000000","0.00128000"],["77703.13000000","0.00008000"],["77703.54000000","0.00000000"],["77704.00000000","0.03007000"],["77704.99000000","0.33909000"],["77705.00000000","0.00000000"],["77705.54000000","0.00000000"],["77705.95000000","0.00000000"],["77706.65000000","0.00000000"],["77707.02000000","0.00008000"],["77708.26000000","0.90147000"],["77708.27000000","0.00000000"],["77709.59000000","0.00000000"],["77709.83000000","0.00000000"],["77710.90000000","0.00008000"],["77713.72000000","0.00000000"],["77714.79000000","0.00008000"],["77717.24000000","0.00014000"],["77717.30000000","0.64361000"],["77718.39000000","0.00000000"],["77718.67000000","0.00008000"],["77721.10000000","0.00007000"],["77721.69000000","0.00000000"],["77724.96000000","0.00007000"],["77728.42000000","0.10000000"],["77729.80000000","0.34749000"],["77730.15000000","0.00000000"],["77730.52000000","0.00000000"],["77730.71000000","0.12878000"],["77734.61000000","0.00000000"],["77735.99000000","0.00321000"],["77736.40000000","0.00000000"],["77737.79000000","0.00321000"],["77749.61000000","1.27382000"],["77780.09000000","0.00000000"],["77782.64000000","2.60864000"],["77787.93000000","4.63449000"],["77797.26000000","4.63449000"],["78843.57000000","0.00000000"]]}}
{"type":"depth","received_at_ms":1788407364310,"data":{"e":"depthUpdate","E":1788407364514,"s":"BTCUSDT","U":99603305157,"u":99603305704,"b":[["77681.99000000","12.81037000"],["77681.98000000","0.00014000"],["77681.28000000","0.00000000"],["77681.15000000","0.00000000"],["77681.09000000","0.00000000"],["77681.08000000","0.00000000"],["77680.88000000","0.00000000"],["77680.63000000","0.00000000"],["77680.55000000","0.00000000"],["77680.20000000","0.00400000"],["77680.00000000","1.61608000"],["77679.99000000","5.52675000"],["77679.98000000","0.00000000"],["77679.83000000","0.01929000"],["77679.82000000","0.43479000"],["77679.33000000","0.03276000"],["77679.31000000","0.00000000"],["77679.30000000","1.11242000"],["77679.29000000","0.41283000"],["77678.39000000","0.17635000"],["77678.38000000","0.44739000"],["77677.84000000","0.00560000"],["77677.75000000","0.00000000"],["77677.64000000","0.00000000"],["77677.33000000","0.00007000"],["77677.16000000","0.00000000"],["77677.15000000","0.00000000"],["77677.13000000","0.00000000"],["77676.95000000","0.54010000"],["77676.94000000","0.00823000"],["77676.92000000","0.01007000"],["77676.17000000","0.00013000"],["77675.90000000","0.00000000"],["77675.89000000","0.00000000"],["77675.85000000","0.00000000"],["77675.84000000","0.00007000"],["77674.87000000","0.19444000"],["77674.74000000","0.41269000"],["77674.65000000","0.00000000"],["77674.22000000","0.00008000"],["77674.00000000","0.00000000"],["77672.61000000","0.00000000"],["77672.47000000","0.00007000"],["77672.32000000","0.08642000"],["77672.29000000","0.00007000"],["77672.21000000","0.00000000"],["77672.08000000","0.00010000"],["77672.05000000","0.00000000"],["77672.01000000","0.00528000"],["77672.00000000","0.00007000"],["77671.99000000","0.58947000"],["77671.23000000","0.00008000"],["77670.81000000","0.02407000"],["77670.29000000","0.00007000"],["77668.92000000","0.00007000"],["77668.81000000","0.00000000"],["77664.00000000","0.00265000"],["77663.14000000","0.00000000"],["77658.91000000","0.00000000"],["77657.69000000","0.00128000"],["77657.62000000","0.70030000"],["77657.41000000","0.00257000"],["77656.52000000","0.00018000"],["77653.91000000","0.34783000"],["77649.00000000","0.00000000"],["77646.32000000","2.21163000"],["77641.83000000","0.00010000"],["77640.00000000","0.04188000"],["77639.00000000","0.00000000"],["77638.34000000","4.63449000"],["77638.33000000","0.00000000"],["77637.97000000","0.00000000"],["77634.48000000","0.00000000"],["77630.03000000","0.25000000"],["77628.07000000","0.06287000"],["77627.07000000","0.00000000"],["77626.58000000","0.00426000"],["77622.93000000","0.00000000"],["77622.92000000","0.00000000"],["77614.71000000","0.00000000"],["77590.61000000","0.00000000"],["77575.87000000","0.39154000"],["77551.37000000","0.02016000"],["77548.20000000","0.00000000"],["77535.23000000","2.61862000"],["77506.12000000","0.00038000"],["77504.09000000","0.00000000"],["77476.77000000","0.00000000"],["77475.34000000","0.30049000"],["77442.50000000","0.00000000"],["69912.00000000","0.00014000"],["62145.60000000","0.00032000"]],"a":[["77680.00000000","0.00000000"],["77680.01000000","0.00000000"],["77680.64000000","0.00000000"],["77680.89000000","0.00000000"],["77681.09000000","0.00000000"],["77681.10000000","0.00000000"],["77681.16000000","0.00000000"],["77681.25000000","0.00000000"],["77681.26000000","0.00000000"],["77681.29000000","0.00000000"],["77681.50000000","0.00000000"],["77681.98000000","0.00000000"],["77681.99000000","0.00000000"],["77682.00000000","0.02698000"],["77682.01000000","0.00070000"],["77682.61000000","0.00021000"],["77682.69000000","0.00000000"],["77682.70000000","0.00000000"],["77682.71000000","0.00000000"],["77682.76000000","0.00321000"],["77682.77000000","0.00021000"],["77683.86000000","0.00021000"],["77683.99000000","0.00014000"],["77684.00000000","0.03028000"],["77684.09000000","0.00000000"],["77684.10000000","0.00000000"],["77684.76000000","0.00014000"],["77684.77000000","0.03162000"],["77684.91000000","0.00000000"],["77685.05000000","0.00014000"],["77685.06000000","0.32214000"],["77685.10000000","0.00021000"],["77685.65000000","0.00000000"],["77685.99000000","0.00014000"],["77686.00000000","0.03035000"],["77686.31000000","0.00007000"],["77686.32000000","0.09258000"],["77686.34000000","0.00014000"],["77687.19000000","0.00007000"],["77687.20000000","0.09638000"],["77687.33000000","0.03007000"],["77687.43000000","0.12007000"],["77687.60000000","0.00000000"],["77687.65000000","0.00000000"],["77687.82000000","0.00013000"],["77688.64000000","0.10245000"],["77688.87000000","0.00000000"],["77689.00000000","0.00000000"],["77689.06000000","0.00000000"],["77689.07000000","0.00007000"],["77689.21000000","0.00000000"],["77689.26000000","0.00000000"],["77689.50000000","0.00681000"],["77689.77000000","0.00008000"],["77690.08000000","0.10245000"],["77690.22000000","0.00014000"],["77691.19000000","0.00047000"],["77691.52000000","0.10245000"],["77692.27000000","0.10245000"],["77692.35000000","0.00000000"],["77692.44000000","0.00000000"],["77692.45000000","0.00000000"],["77693.20000000","0.00000000"],["77693.38000000","0.00000000"],["77693.39000000","0.23644000"],["77694.24000000","0.00007000"],["77694.96000000","0.10245000"],["77695.53000000","0.09550000"],["77697.26000000","0.10245000"],["77697.27000000","0.37291000"],["77698.72000000","0.10089000"],["77699.46000000","0.10645000"],["77701.00000000","0.00800000"],["77701.22000000","0.10245000"],["77701.50000000","0.65063000"],["77702.34000000","0.10085000"],["77703.45000000","0.00000000"],["77703.80000000","0.00000000"],["77705.30000000","0.00128000"],["77707.49000000","0.00013000"],["77707.70000000","0.12868000"],["77717.29000000","0.60028000"],["77718.00000000","0.03000000"],["77718.30000000","0.00000000"],["77719.00000000","0.00000000"],["77719.20000000","0.00400000"],["77721.00000000","0.01000000"],["77722.65000000","0.00853000"],["77729.19000000","0.00008000"],["77729.91000000","0.00000000"],["77730.71000000","0.00000000"],["77737.03000000","0.25000000"],["77737.07000000","0.00000000"],["77737.66000000","0.00000000"],["77741.29000000","1.88394000"],["77741.32000000","0.00000000"],["77763.32000000","1.76285000"],["77765.09000000","0.00007000"],["77766.81000000","2.48171000"],["77776.98000000","0.00000000"],["77782.64000000","0.00000000"],["77787.92000000","1.45285000"],["77788.96000000","0.00000000"],["77827.18000000","0.14455000"],["77830.29000000","0.00000000"],["77855.30000000","1.24090000"],["78069.42000000","0.00007000"]]}}
{"type":"depth","received_at_ms":1788407364410,"data":{"e":"depthUpdate","E":1788407364614,"s":"BTCUSDT","U":99603305705,"u":99603305839,"b":[["77681.99000000","12.89917000"],["77681.98000000","0.00021000"],["77680.74000000","0.01684000"],["77680.22000000","0.00014000"],["77680.21000000","0.01556000"],["77680.01000000","0.00014000"],["77680.00000000","1.61636000"],["77679.99000000","5.35805000"],["77679.83000000","0.01936000"],["77679.82000000","0.26595000"],["77679.50000000","0.02021000"],["77679.31000000","0.00014000"],["77678.38000000","0.31477000"],["77678.26000000","0.02021000"],["77677.84000000","0.00539000"],["77677.33000000","0.00000000"],["77676.10000000","0.00000000"],["77675.33000000","0.00000000"],["77673.65000000","0.12881000"],["77661.95000000","0.00200000"],["77661.37000000","0.50568000"],["77656.00000000","0.03014000"],["77649.61000000","0.00000000"],["77643.00000000","0.71000000"],["77640.00000000","0.03188000"],["77638.07000000","1.00236000"],["77634.83000000","0.00424000"],["77623.56000000","0.00000000"],["77585.48000000","0.04011000"],["77581.09000000","0.00000000"],["77506.12000000","0.16908000"],["77480.65000000","0.00000000"],["69913.80000000","0.00032000"],["62145.60000000","0.00000000"]],"a":[["77682.00000000","0.01355000"],["77682.01000000","0.00084000"],["77682.27000000","0.00007000"],["77682.61000000","0.00007000"],["77682.77000000","0.00007000"],["77683.86000000","0.00007000"],["77684.00000000","0.03028000"],["77684.77000000","0.03176000"],["77685.06000000","0.32214000"],["77685.10000000","0.00007000"],["77686.00000000","0.03028000"],["77686.05000000","0.00000000"],["77686.22000000","0.00534000"],["77686.30000000","0.00007000"],["77686.31000000","0.00007000"],["77686.32000000","0.09272000"],["77686.34000000","0.00000000"],["77687.19000000","0.00000000"],["77687.20000000","0.09652000"],["77687.33000000","0.03021000"],["77687.43000000","0.12021000"],["77687.47000000","0.00890000"],["77688.12000000","0.13796000"],["77688.71000000","0.01068000"],["77689.95000000","0.01468000"],["77690.07000000","0.16151000"],["77693.80000000","0.00400000"],["77698.40000000","0.00400000"],["77699.45000000","0.01000000"],["77702.86000000","0.00000000"],["77707.54000000","0.51302000"],["77709.00000000","0.00128000"],["77711.65000000","0.00000000"],["77715.30000000","0.00400000"],["77730.85000000","1.02395000"],["77733.12000000","0.01156000"],["77815.70000000","0.00000000"],["77818.59000000","0.00971000"],["77883.18000000","0.00007000"],["77887.06000000","0.00007000"]]}}
{"type":"depth","received_at_ms":1788407364510,"data":{"e":"depthUpdate","E":1788407364714,"s":"BTCUSDT","U":99603305840,"u":99603305904,"b":[["77681.99000000","13.50766000"],["77681.98000000","0.00014000"],["77680.75000000","0.00007000"],["77680.74000000","0.01698000"],["77680.21000000","0.01570000"],["77679.83000000","0.01943000"],["77679.82000000","0.12869000"],["77679.30000000","1.11228000"],["77679.29000000","0.41269000"],["77678.39000000","0.17621000"],["77676.93000000","0.03876000"],["77665.38000000","0.00000000"],["77663.65000000","0.00192000"],["77662.31000000","0.00060000"],["77650.98000000","0.00000000"],["77629.84000000","0.00012000"],["77619.85000000","0.00000000"],["69913.80000000","0.00048000"],["62146.00000000","0.00000000"]],"a":[["77682.00000000","0.02634000"],["77682.01000000","0.00070000"],["77686.00000000","0.03028000"],["77686.22000000","0.00548000"],["77686.30000000","0.00000000"],["77687.19000000","0.00000000"],["77687.43000000","0.12007000"],["77689.19000000","0.00208000"],["77689.32000000","0.12364000"],["77691.93000000","0.00000000"],["77693.14000000","0.00000000"],["77693.48000000","0.00000000"],["77694.88000000","0.00000000"],["77701.07000000","0.00835000"],["77887.06000000","0.00000000"],["78847.23000000","0.00030000"]]}}
{"type":"depth","received_at_ms":1788407364610,"data":{"e":"depthUpdate","E":1788407364814,"s":"BTCUSDT","U":99603305905,"u":99603305925,"b":[["77681.99000000","13.52773000"],["77679.99000000","5.33805000"],["77677.62000000","0.02896000"],["77667.81000000","0.00000000"],["69913.80000000","0.00064000"]],"a":[["77682.00000000","0.02641000"],["77687.29000000","0.13591000"],["77688.12000000","0.00000000"],["77693.80000000","0.00000000"],["77694.30000000","0.00400000"],["77697.35000000","0.02000000"],["77699.45000000","0.00800000"],["77701.21000000","0.00200000"],["77735.99000000","0.00000000"],["77738.60000000","0.00320000"],["77747.15000000","0.02000000"],["77813.09000000","0.00000000"],["77816.62000000","0.00128000"],["77874.06000000","0.00007000"],["77883.18000000","0.00000000"]]}}
{"type":"depth","received_at_ms":1788407364710,"data":{"e":"depthUpdate","E":1788407364914,"s":"BTCUSDT","U":99603305926,"u":99603305954,"b":[["77681.99000000","13.51780000"],["77679.50000000","0.02035000"],["77678.42000000","0.00007000"],["77542.44000000","0.00000000"],["69913.80000000","0.00080000"],["69913.79000000","0.00009000"]],"a":[["77682.00000000","0.02634000"],["77686.39000000","0.00612000"],["77687.20000000","0.09652000"],["77687.29000000","0.13605000"],["77687.33000000","0.03007000"],["77717.31000000","0.00000000"],["77737.79000000","0.00000000"],["77739.81000000","0.00321000"],["77747.15000000","0.00000000"],["77756.06000000","0.00032000"],["77784.18000000","0.00000000"],["77788.30000000","0.00000000"],["77792.35000000","0.00000000"]]}}
{"type":"depth","received_at_ms":1788407364811,"data":{"e":"depthUpdate","E":1788407365014,"s":"BTCUSDT","U":99603305955,"u":99603305978,"b":[["77672.63000000","0.15658000"],["77667.29000000","0.25754000"],["77664.07000000","0.00000000"],["77660.38000000","0.00000000"],["77549.55000000","0.00012000"],["69913.80000000","0.00112000"],["62145.60000000","0.00032000"]],"a":[["77682.00000000","0.02641000"],["77686.32000000","0.09272000"],["77686.39000000","0.00626000"],["77687.19000000","0.17429000"],["77687.29000000","0.13591000"],["77695.15000000","0.00000000"],["77696.48000000","0.25795000"],["77697.35000000","0.04000000"],["77704.88000000","0.00012000"],["77708.30000000","0.00000000"],["77747.28000000","0.02000000"],["77791.31000000","0.00012000"],["77795.43000000","0.00019000"]]}}
{"type":"depth","received_at_ms":1788407364910,"data":{"e":"depthUpdate","E":1788407365114,"s":"BTCUSDT","U":99603305979,"u":99603305995,"b":[["77680.74000000","0.01705000"],["77667.67000000","0.00007000"],["77474.76000000","0.00812000"],["77464.81000000","0.00000000"]],"a":[["77686.39000000","0.00626000"],["77687.19000000","0.17443000"],["77687.20000000","0.09638000"],["77698.76000000","0.00007000"],["77708.43000000","0.00000000"],["77747.28000000","0.00000000"],["77774.70000000","0.00000000"],["77778.32000000","0.00025000"],["77799.48000000","0.00032000"]]}}
{"type":"depth","received_at_ms":1788407365010,"data":{"e":"depthUpdate","E":1788407365214,"s":"BTCUSDT","U":99603305996,"u":99603306002,"b":[["77670.18000000","0.00459000"],["77652.00000000","0.73000000"],["75561.74000000","0.00010000"],["69913.80000000","0.00144000"],["62145.60000000","0.00000000"]],"a":[["77720.00000000","0.73000000"]]}}
{"type":"depth","received_at_ms":1788407365110,"data":{"e":"depthUpdate","E":1788407365314,"s":"BTCUSDT","U":99603306003,"u":99603306022,"b":[["77681.99000000","13.51788000"],["69913.80000000","0.00144000"],["62145.59000000","0.00000000"],["62143.00000000","0.01609000"]],"a":[["77682.00000000","0.04057000"],["77683.99000000","0.00674000"],["77686.39000000","0.00014000"],["77697.28000000","0.02000000"],["77747.34000000","0.02000000"],["77807.27000000","0.00000000"],["77815.04000000","0.02016000"],["77825.08000000","0.01567000"],["77867.47000000","0.00000000"]]}}
{"type":"depth","received_at_ms":1788407365211,"data":{"e":"depthUpdate","E":1788407365414,"s":"BTCUSDT","U":99603306023,"u":99603306049,"b":[["76979.27000000","0.00000000"],["69913.80000000","0.00144000"]],"a":[["77682.00000000","0.10849000"],["77682.01000000","0.00077000"],["77683.99000000","0.00688000"],["77684.59000000","0.00007000"],["77686.32000000","0.09272000"],["77686.39000000","0.00000000"],["77701.15000000","0.02000000"],["77708.49000000","0.00000000"],["77714.16000000","0.00000000"],["77733.79000000","0.00000000"],["77759.25000000","0.02000000"],["77765.98000000","3.74138000"]]}}
{"type":"depth","received_at_ms":1788407365310,"data":{"e":"depthUpdate","E":1788407365514,"s":"BTCUSDT","U":99603306050,"u":99603306061,"b":[["77681.99000000","13.51938000"],["77678.38000000","0.31327000"],["76516.76000000","0.00030000"],["69913.80000000","0.00160000"],["69913.79000000","0.00000000"],["69913.78000000","0.00009000"],["62145.60000000","0.00032000"]],"a":[["77682.00000000","0.10847000"],["77687.19000000","0.00014000"],["77697.86000000","0.00257000"],["77756.16000000","0.02000000"],["81006.07000000","0.00010000"]]}}
{"type":"depth","received_at_ms":1788407365410,"data":{"e":"depthUpdate","E":1788407365614,"s":"BTCUSDT","U":99603306062,"u":99603306080,"b":[["77664.16000000","0.00000000"],["77658.00000000","0.00500000"],["77625.31000000","0.00000000"],["77605.88000000","0.00015000"],["69913.80000000","0.00176000"],["62145.60000000","0.00000000"]],"a":[["77682.00000000","0.10847000"],["77686.32000000","0.09272000"],["77687.19000000","0.17429000"],["77687.20000000","0.09652000"],["77696.48000000","0.00000000"],["77697.28000000","0.00000000"],["77697.86000000","0.00000000"],["77727.91000000","0.00000000"],["77747.34000000","0.00000000"]]}}
{"type":"depth","received_at_ms":1788407365510,"data":{"e":"depthUpdate","E":1788407365714,"s":"BTCUSDT","U":99603306081,"u":99603306101,"b":[["69913.80000000","0.00176000"],["69913.78000000","0.00000000"]],"a":[["77682.00000000","0.10317000"],["77683.04000000","0.00007000"],["77683.86000000","0.00636000"],["77683.99000000","0.00028000"],["77686.32000000","0.09272000"],["77687.19000000","0.17443000"],["77687.20000000","0.09638000"],["77697.87000000","0.00257000"],["78847.23000000","0.00030000"]]}}
{"type":"depth","received_at_ms":1788407365611,"data":{"e":"depthUpdate","E":1788407365814,"s":"BTCUSDT","U":99603306102,"u":99603306117,"b":[["77680.76000000","0.00400000"],["77673.65000000","0.12874000"],["69913.80000000","0.00192000"],["62146.00000000","0.00000000"]],"a":[["77682.00000000","0.10331000"],["77682.01000000","0.00077000"],["77683.99000000","0.00014000"],["77747.15000000","0.02000000"]]}}
{"type":"depth","received_at_ms":1788407365710,"data":{"e":"depthUpdate","E":1788407365914,"s":"BTCUSDT","U":99603306118,"u":99603306155,"b":[["77681.99000000","13.51621000"],["77680.76000000","0.00000000"],["77680.75000000","0.00007000"],["77661.95000000","0.00000000"],["77661.26000000","0.00200000"],["77638.35000000","3.13444000"],["69913.80000000","0.00208000"]],"a":[["77682.00000000","0.10310000"],["77683.86000000","0.00650000"],["77687.19000000","0.00014000"],["77688.00000000","0.03207000"],["77699.24000000","0.00200000"],["77701.21000000","0.00000000"],["77722.65000000","0.00000000"],["77723.10000000","0.00400000"],["77723.28000000","0.00000000"],["77728.19000000","1.20876000"],["77763.32000000","2.80620000"],["77794.95000000","1.39548000"],["77829.63000000","1.15712000"]]}}
{"type":"depth","received_at_ms":1788407365810,"data":{"e":"depthUpdate","E":1788407366014,"s":"BTCUSDT","U":99603306156,"u":99603306172,"b":[["77678.39000000","0.17687000"],["77652.24000000","0.00000000"],["69913.80000000","0.00208000"],["62145.60000000","0.00032000"]],"a":[["77686.32000000","0.09272000"],["77687.19000000","0.00000000"],["77687.20000000","0.09652000"],["77699.24000000","0.00000000"],["77700.72000000","0.00200000"],["77716.40000000","0.09512000"],["77747.28000000","0.02000000"]]}}
{"type":"depth","received_at_ms":1788407365910,"data":{"e":"depthUpdate","E":1788407366114,"s":"BTCUSDT","U":99603306173,"u":99603306182,"b":[["77667.67000000","0.00007000"],["77664.97000000","0.06771000"],["77647.24000000","0.00000000"],["69913.80000000","0.00224000"],["62146.00000000","0.00200000"]],"a":[["77698.76000000","0.00007000"],["77708.56000000","0.04735000"],["77715.05000000","0.00000000"],["77785.19000000","2.60864000"]]}}
{"type":"depth","received_at_ms":1788407366010,"data":{"e":"depthUpdate","E":1788407366215,"s":"BTCUSDT","U":99603306183,"u":99603306188,"b":[["69913.80000000","0.00224000"],["62146.00000000","0.00000000"],["62145.60000000","0.00000000"]],"a":[["77733.66000000","0.00000000"]]}}
{"type":"depth","received_at_ms":1788407366110,"data":{"e":"depthUpdate","E":1788407366315,"s":"BTCUSDT","U":99603306189,"u":99603306205,"b":[["77671.56000000","0.02200000"],["77632.71000000","0.02200000"],["77503.64000000","0.00000000"],["69913.80000000","0.00240000"],["62143.00000000","0.01609000"]],"a":[["77697.19000000","0.02000000"],["77697.85000000","0.00257000"],["77697.87000000","0.00000000"],["77716.62000000","0.02000000"],["77732.78000000","1.85643000"],["77733.44000000","0.00000000"],["77860.74000000","0.00000000"]]}}
{"type":"depth","received_at_ms":1788407366210,"data":{"e":"depthUpdate","E":1788407366414,"s":"BTCUSDT","U":99603306206,"u":99603306255,"b":[["77680.75000000","0.00407000"],["77679.99000000","5.20010000"],["77679.82000000","0.14061000"],["77665.90000000","0.09599000"],["77662.40000000","0.00000000"],["77649.07000000","0.41262000"],["77554.09000000","0.00000000"],["77478.80000000","0.00812000"],["77474.76000000","0.00000000"],["76982.85000000","0.00010000"],["75159.40000000","0.00665000"],["62146.00000000","0.00000000"],["62145.59000000","0.00000000"]],"a":[["77682.00000000","0.28315000"],["77682.01000000","0.00084000"],["77684.89000000","0.00014000"],["77684.90000000","0.10316000"],["77685.88000000","0.00007000"],["77685.89000000","0.15052000"],["77685.99000000","0.00000000"],["77686.31000000","0.00000000"],["77687.29000000","0.00000000"],["77689.11000000","0.00208000"],["77689.19000000","0.00000000"],["77689.32000000","0.00000000"],["77689.42000000","0.12364000"],["77693.82000000","0.25324000"],["77697.85000000","0.00000000"],["77701.48000000","2.02523000"],["77701.49000000","4.63427000"],["77701.50000000","0.00000000"],["77702.34000000","0.00000000"],["77717.25000000","0.00400000"],["77723.10000000","0.00000000"],["77723.52000000","0.00854000"],["77733.69000000","0.10310000"],["77794.95000000","0.01379000"],["77797.26000000","0.00000000"]]}}
{"type":"depth","received_at_ms":1788407366310,"data":{"e":"depthUpdate","E":1788407366514,"s":"BTCUSDT","U":99603306256,"u":99603306289,"b":[["77681.99000000","13.51491000"],["77679.83000000","0.01814000"],["77664.06000000","0.00000000"],["77653.00000000","0.70000000"],["77652.00000000","0.03000000"],["77625.21000000","0.00000000"],["77605.78000000","0.00023000"],["77507.70000000","4.40518000"],["76516.76000000","0.00030000"],["69913.80000000","0.00265000"],["62145.60000000","0.00032000"]],"a":[["77682.00000000","0.28138000"],["77684.77000000","0.03176000"],["77684.90000000","0.10330000"],["77685.06000000","0.32214000"],["77685.89000000","0.15066000"],["77686.32000000","0.09258000"],["77687.20000000","0.09638000"],["77697.35000000","0.02000000"],["77727.85000000","0.00000000"],["77733.69000000","0.00000000"],["77747.28000000","0.00000000"],["77865.23000000","4.49572000"]]}}
{"type":"depth","received_at_ms":1788407366410,"data":{"e":"depthUpdate","E":1788407366614,"s":"BTCUSDT","U":99603306290,"u":99603306302,"b":[["77681.99000000","13.52020000"],["77515.31000000","0.00000000"],["69913.80000000","0.00265000"],["62146.00000000","0.00000000"],["62145.60000000","0.00000000"]],"a":[]}}
{"type":"depth","received_at_ms":1788407366510,"data":{"e":"depthUpdate","E":1788407366714,"s":"BTCUSDT","U":99603306303,"u":99603306311,"b":[["69913.80000000","0.00281000"]],"a":[["77682.00000000","0.28145000"],["77682.01000000","0.00091000"],["77693.82000000","0.00000000"],["77733.53000000","0.00000000"],["77800.00000000","0.06972000"],["78847.23000000","0.00030000"]]}}
{"type":"depth","received_at_ms":1788407366609,"data":{"e":"depthUpdate","E":1788407366814,"s":"BTCUSDT","U":99603306312,"u":99603306316,"b":[["69913.80000000","0.00281000"]],"a":[["77682.27000000","0.00000000"],["77683.86000000","0.00021000"],["77683.99000000","0.00651000"]]}}
{"type":"depth","received_at_ms":1788407366709,"data":{"e":"depthUpdate","E":1788407366914,"s":"BTCUSDT","U":99603306317,"u":99603306340,"b":[["77681.99000000","13.52012000"],["77631.20000000","0.43296000"],["69913.80000000","0.00297000"]],"a":[["77682.00000000","0.28145000"],["77682.01000000","0.00091000"],["77683.86000000","0.00007000"],["77683.99000000","0.00665000"],["77691.93000000","0.00007000"],["77737.07000000","0.79746000"],["77782.57000000","0.80883000"],["77802.67000000","0.00000000"],["77815.03000000","0.01756000"]]}}
{"type":"depth","received_at_ms":1788407366810,"data":{"e":"depthUpdate","E":1788407367014,"s":"BTCUSDT","U":99603306341,"u":99603306356,"b":[["77681.99000000","13.52020000"],["77671.50000000","0.02000000"],["77660.00000000","0.01000000"],["77658.00000000","0.01500000"],["77632.64000000","0.02000000"],["71462.78000000","0.00014000"],["69913.80000000","0.00281000"],["62146.00000000","0.00000000"],["62145.60000000","0.00032000"]],"a":[["77682.00000000","0.41413000"],["77693.80000000","0.25324000"],["77697.16000000","0.02000000"],["77716.59000000","0.02000000"]]}}
{"type":"depth","received_at_ms":1788407366911,"data":{"e":"depthUpdate","E":1788407367115,"s":"BTCUSDT","U":99603306357,"u":99603306374,"b":[["77667.67000000","0.00007000"],["77660.00000000","0.01176000"],["77658.00000000","0.02000000"],["69913.80000000","0.00313000"]],"a":[["77682.00000000","0.41413000"],["77682.01000000","0.00091000"],["77684.39000000","0.00007000"],["77684.40000000","0.13169000"],["77685.88000000","0.00000000"],["77685.89000000","0.00014000"],["77698.76000000","0.00007000"],["77734.03000000","0.00000000"],["77841.57000000","0.00000000"]]}}
{"type":"depth","received_at_ms":1788407367010,"data":{"e":"depthUpdate","E":1788407367214,"s":"BTCUSDT","U":99603306375,"u":99603306389,"b":[["69913.80000000","0.00313000"],["62145.60000000","0.00000000"]],"a":[["77684.00000000","0.03028000"],["77684.40000000","0.13183000"],["77685.06000000","0.32214000"],["77685.89000000","0.00000000"]]}}
{"type":"depth","received_at_ms":1788407367111,"data":{"e":"depthUpdate","E":1788407367314,"s":"BTCUSDT","U":99603306390,"u":99603306400,"b":[["77660.00000000","0.02176000"],["77658.00000000","0.03000000"],["77613.28000000","0.02200000"],["77490.18000000","0.02016000"],["77461.86000000","0.00000000"],["69913.80000000","0.00313000"],["62146.00000000","0.00000000"]],"a":[["77693.80000000","0.00000000"],["77736.04000000","0.02000000"]]}}
{"type":"depth","received_at_ms":1788407367210,"data":{"e":"depthUpdate","E":1788407367414,"s":"BTCUSDT","U":99603306401,"u":99603306411,"b":[["77478.80000000","0.00000000"],["77475.35000000","0.00812000"],["69913.80000000","0.00345000"],["62146.00000000","0.00000000"],["62145.59000000","0.00000000"]],"a":[]}}
{"type":"depth","received_at_ms":1788407367310,"data":{"e":"depthUpdate","E":1788407367514,"s":"BTCUSDT","U":99603306412,"u":99603306421,"b":[["77663.96000000","0.00000000"],["77625.11000000","0.00000000"],["77605.69000000","0.00000000"],["77490.18000000","0.00000000"],["76516.76000000","0.00030000"],["75688.00000000","3.54298000"],["71462.78000000","0.00000000"],["69913.80000000","0.00345000"],["62145.60000000","0.00032000"]],"a":[["77696.55000000","0.00257000"],["77697.35000000","0.00000000"],["77727.72000000","0.00000000"],["77747.15000000","0.00000000"]]}}
{"type":"depth","received_at_ms":1788407367410,"data":{"e":"depthUpdate","E":1788407367614,"s":"BTCUSDT","U":99603306422,"u":99603306428,"b":[["77681.99000000","13.22020000"],["77466.85000000","0.02016000"],["69913.80000000","0.00361000"],["62145.60000000","0.00000000"]],"a":[["77684.59000000","0.00000000"]]}}
{"type":"depth","received_at_ms":1788407367510,"data":{"e":"depthUpdate","E":1788407367714,"s":"BTCUSDT","U":99603306429,"u":99603306450,"b":[["77681.99000000","13.22020000"],["69913.80000000","0.00352000"],["69913.79000000","0.00009000"]],"a":[["77682.00000000","0.40877000"],["77696.85000000","0.00400000"],["77698.40000000","0.00000000"],["77716.40000000","0.00008000"],["78847.23000000","0.00030000"]]}}
{"type":"depth","received_at_ms":1788407367610,"data":{"e":"depthUpdate","E":1788407367814,"s":"BTCUSDT","U":99603306451,"u":99603306464,"b":[["77671.44000000","0.02000000"],["77653.00000000","0.00000000"],["77643.00000000","0.01000000"],["77637.96000000","0.00000000"],["77632.58000000","0.02000000"],["77606.89000000","0.57214000"],["77604.16000000","0.72109000"],["77599.06000000","0.00000000"],["69913.80000000","0.00368000"]],"a":[["77696.85000000","0.00000000"],["77697.06000000","0.02000000"],["77716.49000000","0.04400000"]]}}
{"type":"depth","received_at_ms":1788407367709,"data":{"e":"depthUpdate","E":1788407367914,"s":"BTCUSDT","U":99603306465,"u":99603306469,"b":[["69913.80000000","0.00368000"]],"a":[["77682.00000000","0.27601000"],["77697.40000000","0.00400000"],["78070.41000000","0.00007000"]]}}
{"type":"depth","received_at_ms":1788407367810,"data":{"e":"depthUpdate","E":1788407368014,"s":"BTCUSDT","U":99603306470,"u":99603306476,"b":[["77627.07000000","0.30824000"],["77613.21000000","0.02000000"],["69913.80000000","0.00384000"],["62145.60000000","0.00032000"]],"a":[["77682.00000000","0.40426000"],["77736.01000000","0.02000000"],["77834.94000000","0.46064000"]]}}
{"type":"depth","received_at_ms":1788407367911,"data":{"e":"depthUpdate","E":1788407368114,"s":"BTCUSDT","U":99603306477,"u":99603306494,"b":[["77680.75000000","0.00007000"],["76362.91000000","0.00007000"],["69913.80000000","0.00384000"]],"a":[["77682.00000000","0.27601000"],["77682.01000000","0.00084000"],["77684.39000000","0.00000000"],["77684.40000000","0.00014000"],["77685.99000000","0.00007000"],["77697.40000000","0.00000000"],["77697.91000000","0.00400000"],["77734.14000000","0.00000000"],["77734.37000000","0.00000000"],["77734.44000000","0.12878000"]]}}
{"type":"depth","received_at_ms":1788407368010,"data":{"e":"depthUpdate","E":1788407368214,"s":"BTCUSDT","U":99603306495,"u":99603306515,"b":[["77667.67000000","0.00007000"],["69913.80000000","0.00400000"],["62145.60000000","0.00000000"]],"a":[["77684.00000000","0.03028000"],["77684.40000000","0.00000000"],["77686.32000000","0.09272000"],["77698.76000000","0.00007000"],["77715.00000000","0.70000000"],["77720.00000000","0.03000000"],["77734.43000000","0.00000000"],["77734.44000000","0.00000000"],["77734.93000000","0.12878000"]]}}
{"type":"depth","received_at_ms":1788407368110,"data":{"e":"depthUpdate","E":1788407368314,"s":"BTCUSDT","U":99603306516,"u":99603306521,"b":[["77680.75000000","0.00407000"],["62146.00000000","0.00000000"]],"a":[["77682.00000000","0.40412000"],["77734.62000000","0.18027000"],["77734.93000000","0.00000000"]]}}
{"type":"depth","received_at_ms":1788407368209,"data":{"e":"depthUpdate","E":1788407368414,"s":"BTCUSDT","U":99603306522,"u":99603306531,"b":[["77680.75000000","0.00007000"],["69913.80000000","0.00416000"],["62145.59000000","0.00000000"]],"a":[["77682.00000000","0.27601000"],["77734.62000000","0.05149000"]]}}
{"type":"depth","received_at_ms":1788407368310,"data":{"e":"depthUpdate","E":1788407368514,"s":"BTCUSDT","U":99603306532,"u":99603306543,"b":[["77680.75000000","0.00407000"],["77664.65000000","0.00000000"],["77625.80000000","0.00000000"],["77606.37000000","0.00000000"],["77557.70000000","0.00101000"],["76516.76000000","0.00030000"],["69913.80000000","0.00416000"],["62145.60000000","0.00032000"]],"a":[["77682.00000000","0.40191000"],["77691.15000000","0.00000000"],["77710.58000000","0.00000000"],["77730.01000000","0.00000000"],["77733.85000000","0.00000000"],["77782.24000000","0.00089000"]]}}
{"type":"depth","received_at_ms":1788407368410,"data":{"e":"depthUpdate","E":1788407368615,"s":"BTCUSDT","U":99603306544,"u":99603306549,"b":[["69913.80000000","0.00416000"],["62145.60000000","0.00000000"]],"a":[["77682.00000000","0.40198000"],["77682.01000000","0.00091000"],["77685.28000000","0.11069000"]]}}
{"type":"depth","received_at_ms":1788407368510,"data":{"e":"depthUpdate","E":1788407368714,"s":"BTCUSDT","U":99603306550,"u":99603306565,"b":[["77660.00000000","0.02676000"],["77653.00000000","0.70000000"],["69913.80000000","0.00432000"],["69913.79000000","0.00000000"]],"a":[["77682.00000000","0.40191000"],["77684.59000000","0.00007000"],["77685.06000000","0.32214000"],["77685.28000000","0.11083000"],["77686.32000000","0.09258000"],["78847.23000000","0.00030000"]]}}
{"type":"depth","received_at_ms":1788407368609,"data":{"e":"depthUpdate","E":1788407368814,"s":"BTCUSDT","U":99603306566,"u":99603306579,"b":[["77613.15000000","0.02000000"],["77518.92000000","0.00101000"],["69913.80000000","0.00432000"],["62146.00000000","0.00000000"]],"a":[["77683.45000000","0.10301000"],["77684.36000000","0.00007000"],["77684.37000000","0.12510000"],["77685.28000000","0.00014000"],["77685.99000000","0.00000000"],["77735.92000000","0.02000000"]]}}
{"type":"depth","received_at_ms":1788407368710,"data":{"e":"depthUpdate","E":1788407368914,"s":"BTCUSDT","U":99603306580,"u":99603306626,"b":[["77681.99000000","13.22012000"],["77672.16000000","0.02000000"],["77633.31000000","0.02051000"],["69913.80000000","0.00432000"]],"a":[["77682.00000000","0.40212000"],["77682.01000000","0.00098000"],["77683.44000000","0.00014000"],["77683.45000000","0.10315000"],["77683.86000000","0.00680000"],["77683.99000000","0.00028000"],["77684.00000000","0.03028000"],["77684.37000000","0.12524000"],["77685.05000000","0.00000000"],["77685.06000000","0.32200000"],["77685.28000000","0.00000000"],["77686.22000000","0.00534000"],["77696.18000000","0.02000000"],["77715.61000000","0.02000000"],["77720.21000000","0.00202000"],["78070.41000000","0.00000000"]]}}
{"type":"depth","received_at_ms":1788407368809,"data":{"e":"depthUpdate","E":1788407369014,"s":"BTCUSDT","U":99603306627,"u":99603306639,"b":[["69913.80000000","0.00432000"],["62145.60000000","0.00032000"]],"a":[["77683.45000000","0.10315000"],["77683.82000000","0.00007000"],["77683.86000000","0.00694000"],["77683.99000000","0.00014000"],["77806.28000000","0.00078000"]]}}
{"type":"depth","received_at_ms":1788407368909,"data":{"e":"depthUpdate","E":1788407369114,"s":"BTCUSDT","U":99603306640,"u":99603306644,"b":[["77678.39000000","0.17621000"],["69913.80000000","0.00448000"],["62146.00000000","0.00200000"]],"a":[]}}
{"type":"depth","received_at_ms":1788407369010,"data":{"e":"depthUpdate","E":1788407369214,"s":"BTCUSDT","U":99603306645,"u":99603306656,"b":[["77667.67000000","0.00007000"],["69913.80000000","0.00432000"],["62146.00000000","0.00000000"],["62145.60000000","0.00000000"]],"a":[["77682.00000000","0.40205000"],["77682.01000000","0.00091000"],["77683.86000000","0.00021000"],["77684.59000000","0.00000000"],["77698.76000000","0.00007000"]]}}
{"type":"depth","received_at_ms":1788407369110,"data":{"e":"depthUpdate","E":1788407369314,"s":"BTCUSDT","U":99603306657,"u":99603306678,"b":[["77681.99000000","13.22020000"],["77680.76000000","0.00000000"],["77680.75000000","0.00007000"],["69913.80000000","0.00448000"],["62146.00000000","0.00000000"]],"a":[["77682.00000000","0.27615000"],["77683.45000000","0.10315000"],["77683.86000000","0.00007000"],["77685.06000000","0.32214000"],["77693.24000000","0.00536000"],["77699.45000000","0.01200000"],["77701.00000000","0.00400000"],["77845.18000000","0.00105000"]]}}
{"type":"depth","received_at_ms":1788407369211,"data":{"e":"depthUpdate","E":1788407369414,"s":"BTCUSDT","U":99603306679,"u":99603306687,"b":[["69913.80000000","0.00432000"],["62145.59000000","0.00000000"]],"a":[["77723.52000000","0.00000000"],["77736.34000000","0.12878000"]]}}
{"type":"depth","received_at_ms":1788407369310,"data":{"e":"depthUpdate","E":1788407369514,"s":"BTCUSDT","U":99603306688,"u":99603306698,"b":[["76516.76000000","0.00030000"],["69913.80000000","0.00448000"],["62146.00000000","0.00000000"],["62145.60000000","0.00032000"]],"a":[["77693.24000000","0.00000000"],["77736.34000000","0.00000000"],["77737.02000000","0.12878000"]]}}
{"type":"depth","received_at_ms":1788407369410,"data":{"e":"depthUpdate","E":1788407369615,"s":"BTCUSDT","U":99603306699,"u":99603306707,"b":[["69913.80000000","0.00432000"],["62146.00000000","0.00000000"],["62145.60000000","0.00000000"]],"a":[["77693.84000000","0.25324000"],["77737.02000000","0.00000000"],["85450.19000000","0.00383000"]]}}
{"type":"depth","received_at_ms":1788407369511,"data":{"e":"depthUpdate","E":1788407369715,"s":"BTCUSDT","U":99603306708,"u":99603306716,"b":[["69913.80000000","0.00448000"]],"a":[["77682.00000000","0.40806000"],["77807.72000000","0.00000000"],["77815.59000000","0.00108000"],["78847.23000000","0.00030000"],["85450.19000000","0.00000000"]]}}
{"type":"depth","received_at_ms":1788407369610,"data":{"e":"depthUpdate","E":1788407369814,"s":"BTCUSDT","U":99603306717,"u":99603306836,"b":[["77681.99000000","13.18802000"],["77680.75000000","0.00014000"],["77680.22000000","0.00014000"],["77680.01000000","0.00014000"],["77680.00000000","1.61636000"],["77679.82000000","0.14068000"],["77679.31000000","0.00007000"],["77678.38000000","0.31334000"],["77675.68000000","0.00528000"],["77674.90000000","0.30866000"],["77674.89000000","0.00000000"],["77670.04000000","0.02200000"],["77660.32000000","0.00335000"],["77660.18000000","0.12876000"],["77656.29000000","0.00000000"],["77638.32000000","0.00000000"],["69913.80000000","0.00441000"]],"a":[["77682.00000000","0.20664000"],["77682.01000000","0.00077000"],["77683.44000000","0.00000000"],["77683.45000000","0.00014000"],["77684.36000000","0.00000000"],["77684.37000000","0.00014000"],["77684.89000000","0.00000000"],["77684.90000000","0.00014000"],["77685.05000000","0.00014000"],["77685.99000000","0.00014000"],["77686.00000000","0.03021000"],["77686.32000000","0.00000000"],["77686.35000000","0.10316000"],["77687.20000000","0.00007000"],["77687.33000000","0.00007000"],["77687.43000000","0.00007000"],["77687.79000000","0.00007000"],["77687.80000000","0.10316000"],["77688.43000000","0.00000000"],["77689.11000000","0.00000000"],["77689.42000000","0.00000000"],["77690.22000000","0.00007000"],["77690.23000000","0.15000000"],["77694.30000000","0.00000000"],["77694.59000000","0.00400000"],["77696.55000000","0.00000000"],["77697.91000000","0.00000000"],["77698.86000000","0.00000000"],["77699.45000000","0.00400000"],["77700.36000000","0.00257000"],["77700.72000000","0.00600000"],["77700.84000000","0.00800000"],["77700.99000000","0.00643000"],["77701.21000000","0.41182000"],["77701.22000000","0.00000000"],["77701.23000000","0.00000000"],["77701.48000000","0.61180000"],["77701.49000000","0.00000000"],["77708.26000000","0.00000000"],["77708.56000000","0.00000000"],["77711.17000000","0.90140000"],["77714.45000000","0.48184000"],["77714.46000000","0.00000000"],["77715.00000000","0.00000000"],["77719.06000000","0.04623000"],["77724.18000000","0.00000000"],["77728.82000000","0.00007000"],["77933.04000000","0.00000000"]]}}
{"type":"depth","received_at_ms":1788407369710,"data":{"e":"depthUpdate","E":1788407369914,"s":"BTCUSDT","U":99603306837,"u":99603306884,"b":[["77661.08000000","0.00000000"],["77652.13000000","0.00000000"],["77613.88000000","0.02000000"],["77354.79000000","0.00000000"],["69913.80000000","0.00441000"]],"a":[["77682.00000000","0.38675000"],["77683.45000000","0.00000000"],["77684.00000000","0.03028000"],["77684.37000000","0.00000000"],["77684.77000000","0.03176000"],["77684.90000000","0.00000000"],["77686.22000000","0.00548000"],["77686.35000000","0.10330000"],["77689.68000000","0.00208000"],["77689.99000000","0.12364000"],["77690.22000000","0.00014000"],["77693.84000000","0.00000000"],["77698.07000000","0.04859000"],["77698.08000000","0.00000000"],["77700.36000000","0.00000000"],["77701.19000000","2.11805000"],["77701.20000000","4.63427000"],["77701.21000000","0.30866000"],["77701.48000000","0.00000000"],["77728.82000000","0.00000000"],["77735.04000000","0.02000000"],["77757.96000000","0.00000000"],["77780.35000000","0.04578000"],["77942.08000000","0.00246000"]]}}
{"type":"depth","received_at_ms":1788407369810,"data":{"e":"depthUpdate","E":1788407370014,"s":"BTCUSDT","U":99603306885,"u":99603306903,"b":[["77363.76000000","0.00027000"],["69913.80000000","0.00457000"],["62146.00000000","0.00000000"],["62145.60000000","0.00032000"]],"a":[["77682.00000000","0.38668000"],["77682.01000000","0.00063000"],["77683.82000000","0.00000000"],["77698.05000000","0.00257000"],["77698.07000000","0.04602000"]]}}
{"type":"depth","received_at_ms":1788407369909,"data":{"e":"depthUpdate","E":1788407370114,"s":"BTCUSDT","U":99603306904,"u":99603306918,"b":[["77680.75000000","0.00414000"],["77646.70000000","1.29819000"],["77483.42000000","0.00812000"],["77475.35000000","0.00000000"],["69913.80000000","0.00457000"]],"a":[["77684.76000000","0.13710000"],["77697.94000000","0.00421000"],["77698.03000000","0.00257000"],["77698.05000000","0.00000000"],["77699.45000000","0.00000000"],["77722.85000000","1.29692000"],["86422.88000000","0.24583000"]]}}
{"type":"depth","received_at_ms":1788407370025,"data":{"e":"depthUpdate","E":1788407370214,"s":"BTCUSDT","U":99603306919,"u":99603307069,"b":[["77681.99000000","13.21440000"],["77681.98000000","0.00063000"],["77681.90000000","0.00257000"],["77681.52000000","0.00000000"],["77681.51000000","0.00400000"],["77680.01000000","0.00414000"],["77680.00000000","1.54136000"],["77679.99000000","4.86019000"],["77679.83000000","0.01414000"],["77672.32000000","0.08642000"],["77667.67000000","0.00007000"],["77661.26000000","0.00000000"],["77660.00000000","0.03000000"],["77658.90000000","0.00200000"],["77606.89000000","0.39362000"],["77604.16000000","0.00000000"],["77602.78000000","0.41642000"],["77601.61000000","0.72109000"],["75561.74000000","0.00000000"],["69913.80000000","0.00441000"],["62145.60000000","0.00000000"]],"a":[["77682.00000000","0.60132000"],["77682.01000000","0.00084000"],["77682.41000000","0.00014000"],["77682.42000000","0.15011000"],["77683.44000000","0.00014000"],["77683.45000000","0.10316000"],["77684.00000000","0.03028000"],["77684.59000000","0.00007000"],["77684.73000000","0.00000000"],["77684.74000000","0.00014000"],["77684.75000000","0.10316000"],["77684.76000000","0.00007000"],["77685.05000000","0.00000000"],["77685.99000000","0.00000000"],["77686.34000000","0.12001000"],["77686.36000000","0.00014000"],["77687.51000000","0.00208000"],["77687.79000000","0.00000000"],["77689.68000000","0.00000000"],["77689.99000000","0.00000000"],["77693.29000000","0.00400000"],["77694.59000000","0.00000000"],["77696.36000000","0.00400000"],["77697.26000000","0.10502000"],["77697.94000000","0.00021000"],["77698.03000000","0.00000000"],["77698.12000000","0.00000000"],["77698.76000000","0.00007000"],["77698.90000000","0.00200000"],["77699.45000000","0.01200000"],["77700.72000000","0.00000000"],["77700.84000000","0.00000000"],["77701.14000000","0.10316000"],["77724.77000000","1.27422000"],["77724.96000000","0.00000000"],["77746.52000000","0.00000000"],["81006.07000000","0.00000000"],["84202.54000000","0.01326000"]]}}
{"type":"depth","received_at_ms":1788407370124,"data":{"e":"depthUpdate","E":1788407370314,"s":"BTCUSDT","U":99603307070,"u":99603307093,"b":[["77681.99000000","13.21447000"],["77681.98000000","0.00070000"],["77653.00000000","0.00000000"],["77585.48000000","0.00019000"],["69913.80000000","0.00457000"],["62146.00000000","0.00000000"]],"a":[["77682.00000000","0.60146000"],["77682.42000000","0.15025000"],["77683.45000000","0.10330000"],["77684.00000000","0.03014000"],["77686.22000000","0.00534000"],["77686.35000000","0.10316000"],["77718.57000000","0.09425000"],["77725.21000000","0.00833000"],["84202.54000000","0.01768000"]]}}
{"type":"depth","received_at_ms":1788407370210,"data":{"e":"depthUpdate","E":1788407370414,"s":"BTCUSDT","U":99603307094,"u":99603307102,"b":[["77580.55000000","0.04378000"],["69913.80000000","0.00473000"],["62145.59000000","0.00000000"]],"a":[["77715.00000000","0.70000000"]]}}
{"type":"depth","received_at_ms":1788407370310,"data":{"e":"depthUpdate","E":1788407370514,"s":"BTCUSDT","U":99603307103,"u":99603307110,"b":[["77681.90000000","0.00000000"],["76516.76000000","0.00030000"],["69913.80000000","0.00441000"],["62145.60000000","0.00032000"]],"a":[["77687.83000000","0.12364000"],["77697.26000000","0.10245000"]]}}
{"type":"depth","received_at_ms":1788407370409,"data":{"e":"depthUpdate","E":1788407370614,"s":"BTCUSDT","U":99603307111,"u":99603307125,"b":[["77681.99000000","13.21847000"],["77680.30000000","0.00257000"],["77669.20000000","0.02000000"],["69913.80000000","0.00473000"],["62146.00000000","0.00200000"],["62145.60000000","0.00000000"]],"a":[["77683.04000000","0.00000000"],["77683.82000000","0.00007000"],["77695.82000000","0.00257000"],["77737.65000000","0.00000000"],["77738.68000000","0.00000000"]]}}
{"type":"depth","received_at_ms":1788407370508,"data":{"e":"depthUpdate","E":1788407370714,"s":"BTCUSDT","U":99603307126,"u":99603307141,"b":[["77681.99000000","13.21847000"],["77681.98000000","0.00070000"],["69913.80000000","0.00457000"],["62146.00000000","0.00000000"]],"a":[["77684.59000000","0.00000000"],["77692.89000000","0.00516000"],["78847.23000000","0.00030000"]]}}
{"type":"depth","received_at_ms":1788407370610,"data":{"e":"depthUpdate","E":1788407370814,"s":"BTCUSDT","U":99603307142,"u":99603307149,"b":[["77673.88000000","0.02000000"],["77660.34000000","0.00000000"],["69913.80000000","0.00473000"]],"a":[["77682.00000000","0.60943000"]]}}
{"type":"depth","received_at_ms":1788407370709,"data":{"e":"depthUpdate","E":1788407370914,"s":"BTCUSDT","U":99603307150,"u":99603307157,"b":[["77681.99000000","13.21839000"],["77664.97000000","0.04771000"],["69913.80000000","0.00457000"]],"a":[["77682.00000000","0.62238000"]]}}
{"type":"depth","received_at_ms":1788407370810,"data":{"e":"depthUpdate","E":1788407371014,"s":"BTCUSDT","U":99603307158,"u":99603307169,"b":[["77649.08000000","1.15009000"],["77647.00000000","0.70000000"],["69913.80000000","0.00473000"],["62145.60000000","0.00032000"]],"a":[["77682.00000000","0.61988000"],["77712.68000000","0.90507000"],["77714.45000000","0.00000000"],["77738.98000000","0.00000000"],["77739.31000000","0.12878000"]]}}
{"type":"depth","received_at_ms":1788407370911,"data":{"e":"depthUpdate","E":1788407371114,"s":"BTCUSDT","U":99603307170,"u":99603307176,"b":[["77483.42000000","0.00000000"],["77475.35000000","0.00812000"],["76566.69000000","0.00000000"],["76321.00000000","1.01537000"],["69913.80000000","0.00457000"]],"a":[["77739.31000000","0.00000000"]]}}
{"type":"depth","received_at_ms":1788407371010,"data":{"e":"depthUpdate","E":1788407371214,"s":"BTCUSDT","U":99603307177,"u":99603307180,"b":[["77667.67000000","0.00000000"],["75561.74000000","0.00010000"],["69913.80000000","0.00473000"],["62145.60000000","0.00000000"]],"a":[["77698.76000000","0.00000000"]]}}
{"type":"depth","received_at_ms":1788407371112,"data":{"e":"depthUpdate","E":1788407371314,"s":"BTCUSDT","U":99603307181,"u":99603307196,"b":[["77681.99000000","13.21203000"],["77681.98000000","0.00077000"],["77680.76000000","0.00643000"],["77680.30000000","0.00000000"],["77667.67000000","0.00007000"],["69913.80000000","0.00457000"],["62146.00000000","0.00000000"]],"a":[["77682.00000000","0.60958000"],["77695.82000000","0.00000000"],["77696.87000000","0.00257000"],["77698.76000000","0.00007000"],["77724.96000000","0.00007000"],["81006.07000000","0.00010000"]]}}
{"type":"depth","received_at_ms":1788407371209,"data":{"e":"depthUpdate","E":1788407371415,"s":"BTCUSDT","U":99603307197,"u":99603307214,"b":[["77681.99000000","13.21197000"],["76938.81000000","0.00032000"],["69913.80000000","0.00448000"],["69913.79000000","0.00036000"]],"a":[["77682.00000000","0.60699000"],["77684.00000000","0.03028000"],["77734.62000000","0.00000000"]]}}
{"type":"depth","received_at_ms":1788407371309,"data":{"e":"depthUpdate","E":1788407371514,"s":"BTCUSDT","U":99603307215,"u":99603307233,"b":[["77681.99000000","13.21826000"],["77681.98000000","0.00063000"],["77680.76000000","0.00000000"],["76516.76000000","0.00030000"],["76277.83000000","0.00300000"],["62145.60000000","0.00032000"],["62145.59000000","0.00000000"]],"a":[["77682.00000000","0.61964000"],["77739.48000000","0.00000000"],["77752.75000000","0.05149000"]]}}
{"type":"depth","received_at_ms":1788407371409,"data":{"e":"depthUpdate","E":1788407371614,"s":"BTCUSDT","U":99603307234,"u":99603307241,"b":[["69913.80000000","0.00448000"],["62145.60000000","0.00000000"]],"a":[["77682.00000000","0.62108000"]]}}
{"type":"depth","received_at_ms":1788407371510,"data":{"e":"depthUpdate","E":1788407371714,"s":"BTCUSDT","U":99603307242,"u":99603307250,"b":[["69913.80000000","0.00448000"]],"a":[["77682.00000000","0.61858000"],["77695.76000000","0.00257000"],["77696.87000000","0.00000000"],["77724.96000000","0.00000000"],["77736.23000000","0.12878000"],["78847.23000000","0.00030000"]]}}
{"type":"depth","received_at_ms":1788407371609,"data":{"e":"depthUpdate","E":1788407371814,"s":"BTCUSDT","U":99603307251,"u":99603307256,"b":[["69913.80000000","0.00448000"],["62146.00000000","0.00000000"]],"a":[["77682.00000000","0.60828000"],["77736.23000000","0.00000000"]]}}
{"type":"depth","received_at_ms":1788407371709,"data":{"e":"depthUpdate","E":1788407371914,"s":"BTCUSDT","U":99603307257,"u":99603307262,"b":[["69913.80000000","0.00464000"]],"a":[["77735.64000000","0.00000000"],["77735.84000000","0.12878000"]]}}
{"type":"depth","received_at_ms":1788407371809,"data":{"e":"depthUpdate","E":1788407372014,"s":"BTCUSDT","U":99603307263,"u":99603307267,"b":[["69913.80000000","0.00448000"],["62145.60000000","0.00032000"]],"a":[["77735.84000000","0.00000000"]]}}
{"type":"depth","received_at_ms":1788407371909,"data":{"e":"depthUpdate","E":1788407372114,"s":"BTCUSDT","U":99603307268,"u":99603307276,"b":[["69913.80000000","0.00448000"],["62146.00000000","0.00200000"]],"a":[["77682.00000000","0.62108000"],["77736.07000000","0.00000000"],["77736.31000000","0.00000000"]]}}
{"type":"depth","received_at_ms":1788407372009,"data":{"e":"depthUpdate","E":1788407372214,"s":"BTCUSDT","U":99603307277,"u":99603307283,"b":[["77483.41000000","0.00000000"],["69913.80000000","0.00448000"],["62146.00000000","0.00000000"],["62145.60000000","0.00000000"]],"a":[["77736.89000000","0.00000000"]]}}
{"type":"depth","received_at_ms":1788407372109,"data":{"e":"depthUpdate","E":1788407372314,"s":"BTCUSDT","U":99603307284,"u":99603307293,"b":[["77667.67000000","0.00007000"],["69913.80000000","0.00464000"],["62146.00000000","0.00000000"]],"a":[["77695.76000000","0.00000000"],["77696.57000000","0.00257000"],["77698.76000000","0.00007000"]]}}
{"type":"depth","received_at_ms":1788407372210,"data":{"e":"depthUpdate","E":1788407372415,"s":"BTCUSDT","U":99603307294,"u":99603307298,"b":[["77681.82000000","0.00257000"],["69913.80000000","0.00432000"],["62146.00000000","0.00000000"]],"a":[]}}
{"type":"depth","received_at_ms":1788407372309,"data":{"e":"depthUpdate","E":1788407372514,"s":"BTCUSDT","U":99603307299,"u":99603307311,"b":[["77648.00000000","0.73007000"],["76516.76000000","0.00030000"],["69913.80000000","0.00464000"],["69913.79000000","0.00009000"],["62145.60000000","0.00032000"],["62145.59000000","0.00000000"]],"a":[["77682.00000000","0.62108000"]]}}
{"type":"depth","received_at_ms":1788407372409,"data":{"e":"depthUpdate","E":1788407372614,"s":"BTCUSDT","U":99603307312,"u":99603307326,"b":[["77681.99000000","13.21833000"],["77681.98000000","0.00070000"],["71462.78000000","0.00014000"],["69913.80000000","0.00448000"],["62146.00000000","0.00000000"],["62145.60000000","0.00000000"]],"a":[]}}
{"type":"depth","received_at_ms":1788407372509,"data":{"e":"depthUpdate","E":1788407372714,"s":"BTCUSDT","U":99603307327,"u":99603307333,"b":[["69913.80000000","0.00464000"]],"a":[["77737.54000000","0.00000000"],["78847.23000000","0.00030000"]]}}
{"type":"depth","received_at_ms":1788407372609,"data":{"e":"depthUpdate","E":1788407372814,"s":"BTCUSDT","U":99603307334,"u":99603307334,"b":[["69913.80000000","0.00448000"]],"a":[]}}
{"type":"depth","received_at_ms":1788407372709,"data":{"e":"depthUpdate","E":1788407372914,"s":"BTCUSDT","U":99603307335,"u":99603307542,"b":[["77681.99000000","5.26783000"],["77681.98000000","0.00063000"],["77681.87000000","0.00000000"],["77681.82000000","0.00000000"],["77681.51000000","0.00000000"],["77680.76000000","0.00000000"],["77680.75000000","0.00014000"],["77680.33000000","0.00000000"],["77680.23000000","0.00000000"],["77680.21000000","0.01577000"],["77680.01000000","0.00014000"],["77680.00000000","0.61674000"],["77679.99000000","0.22570000"],["77679.83000000","0.00021000"],["77679.51000000","0.00105000"],["77679.29000000","0.41262000"],["77678.65000000","0.00000000"],["77678.64000000","0.00007000"],["77678.39000000","0.00000000"],["77678.38000000","0.01334000"],["77678.26000000","0.02021000"],["77677.92000000","0.00145000"],["77677.91000000","0.00000000"],["77677.84000000","0.00546000"],["77677.62000000","0.02903000"],["77676.96000000","0.00643000"],["77676.95000000","0.54003000"],["77676.94000000","0.00000000"],["77676.21000000","0.02000000"],["77675.85000000","0.00643000"],["77674.90000000","0.00000000"],["77672.79000000","0.00000000"],["77672.41000000","0.00000000"],["77672.33000000","0.02411000"],["77670.55000000","0.00000000"],["77669.99000000","0.00000000"],["77667.30000000","0.12715000"],["77667.29000000","0.00000000"],["77666.89000000","0.02000000"],["77666.47000000","0.30866000"],["77666.46000000","0.00000000"],["77664.97000000","0.00000000"],["77663.52000000","0.31454000"],["77663.18000000","0.25755000"],["77660.17000000","0.04515000"],["77658.90000000","0.00000000"],["77657.62000000","0.47656000"],["77656.31000000","0.00200000"],["77656.00000000","0.33014000"],["77655.53000000","0.94412000"],["77655.08000000","0.00000000"],["77647.00000000","0.00000000"],["77644.92000000","0.00000000"],["77634.82000000","0.34791000"],["77629.18000000","1.92610000"],["77627.85000000","4.63427000"],["77617.58000000","4.63427000"],["77613.85000000","1.27604000"],["77602.78000000","0.23067000"],["77601.61000000","0.00000000"],["77599.06000000","0.72109000"],["69913.80000000","0.00448000"],["69913.79000000","0.00000000"]],"a":[["77682.00000000","2.25881000"],["77682.01000000","0.00091000"],["77682.40000000","0.00014000"],["77682.41000000","0.22282000"],["77682.50000000","0.00014000"],["77683.44000000","0.00000000"],["77683.45000000","0.00014000"],["77683.46000000","0.00027000"],["77684.75000000","0.10330000"],["77684.76000000","0.00000000"],["77686.22000000","0.00548000"],["77687.51000000","0.00000000"],["77687.83000000","0.00000000"],["77688.00000000","0.03607000"],["77690.69000000","0.00518000"],["77691.19000000","0.00000000"],["77693.29000000","0.00000000"],["77693.38000000","0.30866000"],["77693.97000000","0.00000000"],["77694.95000000","0.00643000"],["77695.52000000","0.00400000"],["77696.17000000","0.00200000"],["77696.35000000","0.00800000"],["77696.36000000","0.00000000"],["77696.57000000","0.00000000"],["77697.25000000","0.00000000"],["77697.27000000","0.76404000"],["77698.41000000","1.11223000"],["77698.72000000","0.00000000"],["77698.90000000","0.00000000"],["77699.45000000","0.00000000"],["77699.46000000","0.00400000"],["77700.99000000","0.00000000"],["77701.00000000","0.00000000"],["77701.14000000","0.00000000"],["77703.54000000","0.00000000"],["77706.47000000","0.64391000"],["77711.17000000","0.25754000"],["77719.20000000","0.00000000"],["77721.10000000","0.00000000"]]}}
{"type":"depth","received_at_ms":1788407372810,"data":{"e":"depthUpdate","E":1788407373014,"s":"BTCUSDT","U":99603307543,"u":99603307626,"b":[["77681.99000000","5.35055000"],["77681.98000000","0.00063000"],["77680.76000000","0.00106000"],["77680.20000000","0.00000000"],["77679.99000000","0.22570000"],["77679.83000000","0.00007000"],["77679.52000000","0.00145000"],["77679.51000000","0.00000000"],["77678.78000000","0.00400000"],["77678.64000000","0.00014000"],["77678.39000000","0.04040000"],["77678.37000000","0.00000000"],["77678.29000000","0.00400000"],["77677.92000000","0.00000000"],["77674.89000000","0.00200000"],["77672.79000000","0.00400000"],["77672.64000000","0.00800000"],["77672.34000000","0.00000000"],["77672.33000000","0.02011000"],["77659.20000000","0.00200000"],["77656.31000000","0.30000000"],["77645.10000000","0.00400000"],["69913.80000000","0.00448000"],["62146.00000000","0.00000000"],["62145.60000000","0.00032000"]],"a":[["77682.00000000","2.25917000"],["77682.01000000","0.00091000"],["77682.41000000","0.22296000"],["77682.42000000","0.15025000"],["77683.19000000","0.00208000"],["77683.44000000","0.12364000"],["77683.45000000","0.00000000"],["77683.46000000","0.00000000"],["77684.75000000","0.00014000"],["77686.05000000","0.00400000"],["77686.35000000","0.00000000"],["77689.86000000","0.00400000"],["77690.72000000","0.00048000"],["77696.17000000","0.00000000"],["77717.25000000","0.00000000"],["77721.47000000","0.02487000"]]}}
{"type":"depth","received_at_ms":1788407372910,"data":{"e":"depthUpdate","E":1788407373114,"s":"BTCUSDT","U":99603307627,"u":99603307658,"b":[["77681.99000000","5.35076000"],["77679.29000000","0.41269000"],["77674.89000000","0.00200000"],["77674.74000000","0.41262000"],["77648.00000000","0.03007000"],["76350.00000000","0.17724000"],["71462.78000000","0.00000000"],["69913.80000000","0.00448000"]],"a":[["77682.00000000","2.25965000"],["77682.42000000","0.15025000"],["77683.43000000","0.00014000"],["77683.44000000","0.12378000"],["77684.00000000","0.03028000"],["77684.74000000","0.00000000"],["77684.75000000","0.00000000"],["77689.70000000","0.00400000"],["77690.72000000","0.00000000"],["77695.52000000","0.00800000"]]}}
{"type":"depth","received_at_ms":1788407373009,"data":{"e":"depthUpdate","E":1788407373214,"s":"BTCUSDT","U":99603307659,"u":99603307677,"b":[["77681.99000000","5.35076000"],["77681.98000000","0.00063000"],["77674.89000000","0.01400000"],["77672.79000000","0.00000000"],["77672.64000000","0.00000000"],["77475.35000000","0.00000000"],["77474.76000000","0.00812000"],["69913.80000000","0.00448000"],["62145.60000000","0.00000000"]],"a":[["77682.00000000","2.25958000"],["77682.01000000","0.00084000"],["77689.93000000","0.00000000"],["77690.50000000","0.00048000"],["77696.34000000","0.00200000"]]}}
{"type":"depth","received_at_ms":1788407373109,"data":{"e":"depthUpdate","E":1788407373314,"s":"BTCUSDT","U":99603307678,"u":99603307690,"b":[["77667.67000000","0.00007000"],["69913.80000000","0.00448000"],["62146.00000000","0.00000000"]],"a":[["77689.86000000","0.00000000"],["77690.36000000","0.00400000"],["77698.76000000","0.00007000"],["77737.43000000","0.00000000"]]}}
{"type":"depth","received_at_ms":1788407373209,"data":{"e":"depthUpdate","E":1788407373414,"s":"BTCUSDT","U":99603307691,"u":99603307710,"b":[["77681.99000000","5.35083000"],["77681.98000000","0.00070000"],["77680.61000000","0.00007000"],["77680.60000000","0.10989000"],["77680.22000000","0.00000000"],["69913.80000000","0.00448000"],["62146.00000000","0.00000000"]],"a":[["77684.76000000","0.00007000"],["77693.37000000","0.38336000"],["77693.39000000","0.00000000"],["77696.21000000","0.28802000"],["77736.92000000","0.00000000"],["77737.27000000","0.00000000"]]}}
{"type":"depth","received_at_ms":1788407373310,"data":{"e":"depthUpdate","E":1788407373515,"s":"BTCUSDT","U":99603307711,"u":99603307734,"b":[["77681.99000000","5.35083000"],["77681.98000000","0.00070000"],["77681.40000000","0.00113000"],["77681.39000000","0.09117000"],["77680.76000000","0.00000000"],["77680.74000000","0.01705000"],["77680.61000000","0.00000000"],["77680.60000000","0.00000000"],["76516.76000000","0.00030000"],["69913.80000000","0.00432000"],["62145.60000000","0.00032000"],["62145.59000000","0.00000000"]],"a":[["77710.00000000","0.73200000"]]}}
{"type":"depth","received_at_ms":1788407373410,"data":{"e":"depthUpdate","E":1788407373614,"s":"BTCUSDT","U":99603307735,"u":99603307750,"b":[["77681.99000000","5.35083000"],["77681.39000000","0.09131000"],["77680.74000000","0.01691000"],["77647.05000000","0.00400000"],["77645.10000000","0.00000000"],["69913.80000000","0.00448000"],["62145.60000000","0.00000000"]],"a":[["77687.57000000","0.00652000"],["77737.78000000","0.12878000"]]}}
{"type":"depth","received_at_ms":1788407373510,"data":{"e":"depthUpdate","E":1788407373714,"s":"BTCUSDT","U":99603307751,"u":99603307758,"b":[["77680.74000000","0.01684000"],["69913.80000000","0.00425000"]],"a":[["77682.00000000","2.22832000"],["77737.78000000","0.00000000"],["78847.23000000","0.00030000"]]}}
{"type":"depth","received_at_ms":1788407373609,"data":{"e":"depthUpdate","E":1788407373814,"s":"BTCUSDT","U":99603307759,"u":99603307782,"b":[["77681.99000000","5.38686000"],["77680.74000000","0.01698000"],["77679.72000000","0.00400000"],["77678.29000000","0.00000000"],["77674.90000000","0.00400000"],["77674.89000000","0.00000000"],["77672.79000000","0.00000000"],["77672.64000000","0.00200000"],["77659.20000000","0.00000000"],["77657.72000000","0.00200000"],["69913.80000000","0.00457000"]],"a":[["77682.00000000","2.22818000"]]}}
{"type":"depth","received_at_ms":1788407373710,"data":{"e":"depthUpdate","E":1788407373914,"s":"BTCUSDT","U":99603307783,"u":99603307806,"b":[["77681.99000000","5.38686000"],["77681.98000000","0.00077000"],["77681.40000000","0.00007000"],["77680.76000000","0.00106000"],["77676.82000000","0.00257000"],["77674.90000000","0.00000000"],["77674.89000000","0.01200000"],["77672.79000000","0.00000000"],["77672.64000000","0.00000000"],["69913.80000000","0.00441000"]],"a":[["77692.35000000","0.00257000"]]}}
{"type":"depth","received_at_ms":1788407373809,"data":{"e":"depthUpdate","E":1788407374014,"s":"BTCUSDT","U":99603307807,"u":99603307813,"b":[["77681.41000000","0.00106000"],["77680.76000000","0.00000000"],["77674.89000000","0.01400000"],["77672.79000000","0.00000000"],["69913.80000000","0.00441000"],["62145.60000000","0.00032000"]],"a":[]}}
{"type":"depth","received_at_ms":1788407373909,"data":{"e":"depthUpdate","E":1788407374114,"s":"BTCUSDT","U":99603307814,"u":99603307816,"b":[["77643.00000000","0.71000000"],["69913.80000000","0.00441000"]],"a":[]}}
{"type":"depth","received_at_ms":1788407374009,"data":{"e":"depthUpdate","E":1788407374214,"s":"BTCUSDT","U":99603307817,"u":99603307826,"b":[["77678.38000000","0.01327000"],["77657.62000000","0.68368000"],["77619.05000000","1.89502000"],["69913.80000000","0.00457000"],["62145.60000000","0.00000000"]],"a":[["77682.00000000","2.05948000"],["77689.70000000","0.00000000"],["77690.23000000","0.15400000"]]}}
{"type":"depth","received_at_ms":1788407374110,"data":{"e":"depthUpdate","E":1788407374314,"s":"BTCUSDT","U":99603307827,"u":99603307861,"b":[["77681.99000000","5.38771000"],["77681.41000000","0.00000000"],["77677.90000000","0.00257000"],["77676.82000000","0.00000000"],["77667.67000000","0.00000000"],["77474.76000000","0.00000000"],["77466.86000000","0.00812000"],["69913.80000000","0.00441000"],["62146.00000000","0.00000000"]],"a":[["77682.00000000","1.70075000"],["77682.50000000","0.00007000"],["77687.57000000","0.00000000"],["77688.66000000","0.00000000"],["77690.23000000","0.15000000"],["77690.36000000","0.00000000"],["77690.85000000","0.00400000"],["77690.90000000","0.00400000"],["77692.35000000","0.00000000"],["77693.42000000","0.00257000"],["77695.52000000","0.00000000"],["77696.34000000","0.00000000"],["77696.35000000","0.00400000"],["77696.58000000","0.00800000"],["77697.25000000","0.00200000"],["77698.76000000","0.00000000"],["77721.10000000","0.00007000"]]}}
{"type":"depth","received_at_ms":1788407374210,"data":{"e":"depthUpdate","E":1788407374414,"s":"BTCUSDT","U":99603307862,"u":99603307931,"b":[["77681.99000000","10.03264000"],["77681.98000000","0.00077000"],["77681.44000000","0.00400000"],["77681.42000000","0.00643000"],["77681.41000000","0.00643000"],["77679.72000000","0.00000000"],["77679.52000000","0.00000000"],["77678.78000000","0.00000000"],["77677.62000000","0.02896000"],["77676.96000000","0.00000000"],["77675.85000000","0.00000000"],["77675.69000000","0.00400000"],["77675.58000000","0.00200000"],["77674.89000000","0.01200000"],["77672.33000000","0.01611000"],["77667.67000000","0.00007000"],["77661.59000000","0.00007000"],["77660.38000000","0.00200000"],["77657.72000000","0.00000000"],["77619.05000000","0.58670000"],["77617.58000000","0.00000000"],["77599.06000000","0.00000000"],["77596.51000000","0.72109000"],["69913.80000000","0.00432000"],["69913.79000000","0.00009000"]],"a":[["77682.00000000","1.69777000"],["77688.74000000","0.00000000"],["77690.69000000","0.00000000"],["77690.85000000","0.00000000"],["77690.90000000","0.00048000"],["77696.35000000","0.00000000"],["77696.58000000","0.00000000"],["77697.25000000","0.00000000"],["77697.34000000","0.00000000"],["77698.40000000","0.01600000"],["77698.76000000","0.00007000"],["77699.54000000","0.02000000"],["77715.00000000","0.00000000"],["77735.57000000","0.00000000"],["77735.91000000","0.02400000"]]}}
{"type":"depth","received_at_ms":1788407374309,"data":{"e":"depthUpdate","E":1788407374514,"s":"BTCUSDT","U":99603307932,"u":99603307964,"b":[["77681.99000000","10.03278000"],["77681.98000000","0.00091000"],["77681.42000000","0.00657000"],["77679.50000000","0.02021000"],["77673.64000000","0.32961000"],["77667.68000000","0.00000000"],["76516.76000000","0.00030000"],["69913.80000000","0.00432000"],["62145.60000000","0.00032000"],["62145.59000000","0.00000000"]],"a":[["77682.00000000","1.69766000"],["77691.97000000","0.00400000"],["77693.71000000","0.00400000"],["77697.25000000","0.00200000"],["77736.21000000","0.00000000"],["77736.31000000","0.00000000"],["77736.75000000","0.02000000"]]}}
{"type":"depth","received_at_ms":1788407374410,"data":{"e":"depthUpdate","E":1788407374614,"s":"BTCUSDT","U":99603307965,"u":99603307975,"b":[["77681.99000000","10.03278000"],["77681.98000000","0.00091000"],["77681.44000000","0.00000000"],["77680.96000000","0.00400000"],["69913.80000000","0.00432000"],["62145.60000000","0.00000000"]],"a":[]}}
{"type":"depth","received_at_ms":1788407374509,"data":{"e":"depthUpdate","E":1788407374714,"s":"BTCUSDT","U":99603307976,"u":99603307992,"b":[["69913.80000000","0.00448000"]],"a":[["77682.00000000","1.69744000"],["77682.01000000","0.00077000"],["77682.40000000","0.00000000"],["77682.41000000","0.19886000"],["77684.76000000","0.00014000"],["77685.05000000","0.00000000"],["77736.06000000","0.00000000"],["78847.23000000","0.00030000"]]}}
{"type":"depth","received_at_ms":1788407374609,"data":{"e":"depthUpdate","E":1788407374814,"s":"BTCUSDT","U":99603307993,"u":99603308031,"b":[["77681.99000000","10.03285000"],["77679.64000000","0.00257000"],["77677.90000000","0.00000000"],["77649.00000000","0.00400000"],["77647.05000000","0.00000000"],["69913.80000000","0.00432000"],["62146.00000000","0.00000000"]],"a":[["77682.00000000","1.69730000"],["77682.01000000","0.00070000"],["77682.40000000","0.00000000"],["77682.41000000","0.00028000"],["77683.19000000","0.00000000"],["77683.43000000","0.00000000"],["77683.44000000","0.00014000"],["77683.82000000","0.00000000"],["77685.05000000","0.00014000"],["77685.99000000","0.00007000"],["77691.97000000","0.00000000"],["77692.42000000","0.00400000"],["77693.42000000","0.00000000"],["77695.17000000","0.00257000"],["77697.25000000","0.00000000"],["77698.39000000","0.00200000"],["77736.20000000","0.00000000"],["77736.23000000","0.00000000"],["77736.29000000","0.00000000"]]}}
{"type":"depth","received_at_ms":1788407374709,"data":{"e":"depthUpdate","E":1788407374914,"s":"BTCUSDT","U":99603308032,"u":99603308050,"b":[["77681.99000000","10.03277000"],["69913.80000000","0.00448000"]],"a":[["77682.00000000","1.69759000"],["77682.41000000","0.00014000"],["77682.42000000","0.15025000"],["77683.44000000","0.00000000"],["77686.34000000","0.12015000"]]}}
{"type":"depth","received_at_ms":1788407374810,"data":{"e":"depthUpdate","E":1788407375014,"s":"BTCUSDT","U":99603308051,"u":99603308060,"b":[["77681.99000000","10.03293000"],["77679.64000000","0.00000000"],["77637.98000000","0.00200000"],["69913.80000000","0.00432000"],["62145.60000000","0.00032000"]],"a":[["77690.75000000","0.00532000"],["77694.24000000","0.00264000"],["77695.17000000","0.00000000"]]}}
{"type":"depth","received_at_ms":1788407374909,"data":{"e":"depthUpdate","E":1788407375114,"s":"BTCUSDT","U":99603308061,"u":99603308065,"b":[["69913.80000000","0.00448000"],["62146.00000000","0.00200000"]],"a":[["77684.59000000","0.00007000"]]}}
{"type":"depth","received_at_ms":1788407375010,"data":{"e":"depthUpdate","E":1788407375214,"s":"BTCUSDT","U":99603308066,"u":99603308092,"b":[["77681.99000000","10.03136000"],["77681.98000000","0.00098000"],["77680.97000000","0.00159000"],["77680.96000000","0.00000000"],["77680.35000000","0.00400000"],["77660.38000000","0.00000000"],["77659.11000000","0.00200000"],["77615.14000000","0.84713000"],["69913.80000000","0.00432000"],["62146.00000000","0.00000000"],["62145.60000000","0.00000000"]],"a":[["77682.00000000","1.69773000"],["77682.01000000","0.00077000"],["77682.40000000","0.00007000"],["77682.41000000","0.16117000"],["77685.99000000","0.00000000"],["77686.33000000","0.10315000"],["77689.38000000","0.00000000"]]}}
{"type":"depth","received_at_ms":1788407375109,"data":{"e":"depthUpdate","E":1788407375314,"s":"BTCUSDT","U":99603308093,"u":99603308114,"b":[["77681.99000000","10.02936000"],["77474.76000000","0.00812000"],["77466.86000000","0.00000000"],["69913.80000000","0.00432000"],["69913.79000000","0.00000000"],["62146.00000000","0.00000000"]],"a":[["77682.00000000","1.83340000"],["77682.41000000","0.16131000"],["77686.22000000","0.00548000"],["77686.33000000","0.10329000"],["77686.34000000","0.12001000"]]}}
{"type":"depth","received_at_ms":1788407375209,"data":{"e":"depthUpdate","E":1788407375414,"s":"BTCUSDT","U":99603308115,"u":99603308128,"b":[["77667.67000000","0.00007000"],["77646.00000000","0.73000000"],["77643.00000000","0.01000000"],["69913.80000000","0.00432000"]],"a":[["77682.00000000","1.84597000"],["77698.76000000","0.00007000"],["77737.27000000","0.00000000"],["77737.60000000","0.00000000"]]}}
{"type":"depth","received_at_ms":1788407375309,"data":{"e":"depthUpdate","E":1788407375514,"s":"BTCUSDT","U":99603308129,"u":99603308138,"b":[["76516.76000000","0.00030000"],["69913.80000000","0.00448000"],["62145.60000000","0.00032000"],["62145.59000000","0.00000000"]],"a":[]}}
{"type":"depth","received_at_ms":1788407375410,"data":{"e":"depthUpdate","E":1788407375614,"s":"BTCUSDT","U":99603308139,"u":99603308149,"b":[["75805.56000000","0.00035000"],["69913.80000000","0.00416000"],["62146.00000000","0.00000000"],["62145.60000000","0.00000000"]],"a":[["77807.03000000","0.02016000"],["77815.03000000","0.00000000"],["77815.04000000","0.00000000"]]}}
{"type":"depth","received_at_ms":1788407375509,"data":{"e":"depthUpdate","E":1788407375714,"s":"BTCUSDT","U":99603308150,"u":99603308153,"b":[["69913.80000000","0.00448000"]],"a":[["78847.23000000","0.00030000"]]}}
{"type":"depth","received_at_ms":1788407375609,"data":{"e":"depthUpdate","E":1788407375814,"s":"BTCUSDT","U":99603308154,"u":99603308159,"b":[["69913.80000000","0.00432000"]],"a":[["77682.00000000","1.70069000"],["77807.03000000","0.00000000"],["77826.76000000","0.02016000"]]}}
{"type":"depth","received_at_ms":1788407375710,"data":{"e":"depthUpdate","E":1788407375914,"s":"BTCUSDT","U":99603308160,"u":99603308165,"b":[["69913.80000000","0.00416000"]],"a":[["77826.76000000","0.00000000"],["77853.54000000","0.00000000"]]}}
{"type":"depth","received_at_ms":1788407375810,"data":{"e":"depthUpdate","E":1788407376015,"s":"BTCUSDT","U":99603308166,"u":99603308175,"b":[["77679.75000000","0.00257000"],["77603.42000000","0.00483000"],["77598.16000000","0.00000000"],["69913.80000000","0.00432000"],["62146.00000000","0.00000000"],["62145.60000000","0.00032000"]],"a":[["77694.24000000","0.00007000"],["77695.28000000","0.00257000"],["77870.38000000","0.02016000"]]}}
{"type":"depth","received_at_ms":1788407375910,"data":{"e":"depthUpdate","E":1788407376114,"s":"BTCUSDT","U":99603308176,"u":99603308187,"b":[["77681.99000000","10.02922000"],["77681.98000000","0.00091000"],["69913.80000000","0.00441000"]],"a":[["77682.00000000","1.70003000"],["77728.00000000","0.03207000"]]}}
{"type":"depth","received_at_ms":1788407376009,"data":{"e":"depthUpdate","E":1788407376214,"s":"BTCUSDT","U":99603308188,"u":99603308198,"b":[["77599.06000000","0.72109000"],["77596.51000000","0.00000000"],["77507.70000000","0.00000000"],["75561.74000000","0.00000000"],["69913.80000000","0.00457000"],["62145.60000000","0.00000000"]],"a":[["77735.51000000","0.00000000"],["77865.23000000","0.00000000"],["81006.07000000","0.00000000"]]}}
{"type":"depth","received_at_ms":1788407376110,"data":{"e":"depthUpdate","E":1788407376314,"s":"BTCUSDT","U":99603308199,"u":99603308211,"b":[["69913.80000000","0.00441000"],["62146.00000000","0.00000000"]],"a":[["77682.00000000","1.69996000"],["77682.01000000","0.00070000"],["77682.40000000","0.00000000"],["77682.41000000","0.00028000"],["77685.99000000","0.00007000"],["77687.95000000","0.00000000"],["77735.24000000","0.12878000"],["77735.86000000","0.00000000"]]}}
{"type":"depth","received_at_ms":1788407376209,"data":{"e":"depthUpdate","E":1788407376414,"s":"BTCUSDT","U":99603308212,"u":99603308232,"b":[["77681.99000000","10.02891000"],["77667.67000000","0.00007000"],["77505.10000000","4.49751000"],["69913.80000000","0.00448000"],["69913.79000000","0.00009000"]],"a":[["77682.00000000","1.69737000"],["77682.41000000","0.00014000"],["77686.34000000","0.12015000"],["77698.76000000","0.00007000"],["77735.24000000","0.00000000"],["77764.19000000","0.00200000"],["77861.44000000","4.59123000"]]}}
{"type":"depth","received_at_ms":1788407376310,"data":{"e":"depthUpdate","E":1788407376514,"s":"BTCUSDT","U":99603308233,"u":99603308244,"b":[["77670.18000000","0.00000000"],["77474.76000000","0.00000000"],["77466.86000000","0.00812000"],["76516.76000000","0.00030000"],["69913.80000000","0.00432000"],["62145.60000000","0.00032000"],["62145.59000000","0.00040000"]],"a":[["77735.53000000","0.12878000"],["80000.00000000","79.98161000"]]}}
{"type":"depth","received_at_ms":1788407376410,"data":{"e":"depthUpdate","E":1788407376615,"s":"BTCUSDT","U":99603308245,"u":99603308261,"b":[["77675.58000000","0.00000000"],["77674.89000000","0.01400000"],["69913.80000000","0.00448000"],["62145.60000000","0.00000000"],["62145.59000000","0.00000000"]],"a":[["77682.00000000","1.69751000"],["77686.23000000","0.00208000"],["77686.54000000","0.12364000"],["77689.31000000","0.00661000"],["77735.12000000","0.00000000"],["77735.40000000","0.00000000"],["77735.53000000","0.00000000"]]}}
{"type":"depth","received_at_ms":1788407376510,"data":{"e":"depthUpdate","E":1788407376714,"s":"BTCUSDT","U":99603308262,"u":99603308272,"b":[["69913.80000000","0.00432000"],["62146.00000000","0.00000000"]],"a":[["77686.34000000","0.12015000"],["78847.23000000","0.00030000"]]}}
{"type":"depth","received_at_ms":1788407376609,"data":{"e":"depthUpdate","E":1788407376814,"s":"BTCUSDT","U":99603308273,"u":99603308279,"b":[["77474.76000000","0.00812000"],["77466.86000000","0.00000000"],["69913.80000000","0.00448000"]],"a":[["77735.29000000","0.12878000"],["77735.36000000","0.00000000"]]}}
{"type":"depth","received_at_ms":1788407376709,"data":{"e":"depthUpdate","E":1788407376914,"s":"BTCUSDT","U":99603308280,"u":99603308290,"b":[["77681.99000000","10.02883000"],["69913.80000000","0.00432000"]],"a":[["77682.00000000","1.83065000"],["77689.31000000","0.00000000"],["77735.03000000","0.00000000"],["77735.29000000","0.00000000"],["77735.30000000","0.12878000"]]}}
{"type":"depth","received_at_ms":1788407376810,"data":{"e":"depthUpdate","E":1788407377014,"s":"BTCUSDT","U":99603308291,"u":99603308305,"b":[["77681.99000000","9.92839000"],["69913.80000000","0.00448000"],["69913.79000000","0.00000000"],["62145.60000000","0.00032000"]],"a":[["77682.00000000","1.82887000"],["77687.94000000","0.00000000"],["77690.74000000","0.02000000"],["77699.54000000","0.00000000"],["77735.30000000","0.00000000"]]}}
{"type":"depth","received_at_ms":1788407376909,"data":{"e":"depthUpdate","E":1788407377114,"s":"BTCUSDT","U":99603308306,"u":99603308314,"b":[["77681.99000000","9.92800000"],["69913.80000000","0.00432000"]],"a":[["77734.81000000","0.12878000"],["77735.07000000","0.00000000"],["77735.10000000","0.00000000"]]}}
{"type":"depth","received_at_ms":1788407377009,"data":{"e":"depthUpdate","E":1788407377214,"s":"BTCUSDT","U":99603308315,"u":99603308320,"b":[["75561.74000000","0.00010000"],["69913.80000000","0.00432000"],["62145.60000000","0.00000000"]],"a":[["77682.00000000","1.80313000"],["77734.81000000","0.00000000"]]}}
{"type":"depth","received_at_ms":1788407377110,"data":{"e":"depthUpdate","E":1788407377314,"s":"BTCUSDT","U":99603308321,"u":99603308332,"b":[["77681.99000000","9.92800000"],["77674.89000000","0.01200000"],["77673.66000000","0.00200000"],["69913.80000000","0.00432000"],["62146.00000000","0.00000000"]],"a":[["77690.74000000","0.00000000"],["77695.34000000","0.02000000"],["77696.89000000","0.00200000"],["77698.39000000","0.00000000"]]}}
{"type":"depth","received_at_ms":1788407377209,"data":{"e":"depthUpdate","E":1788407377414,"s":"BTCUSDT","U":99603308333,"u":99603308348,"b":[["77681.99000000","9.92786000"],["77679.75000000","0.00000000"],["77678.95000000","0.00257000"],["77667.67000000","0.00000000"],["69913.80000000","0.00441000"],["62146.00000000","0.00000000"]],"a":[["77682.00000000","1.80195000"],["77694.48000000","0.00257000"],["77695.28000000","0.00000000"],["77698.76000000","0.00000000"],["81006.07000000","0.00010000"]]}}
{"type":"depth","received_at_ms":1788407377309,"data":{"e":"depthUpdate","E":1788407377514,"s":"BTCUSDT","U":99603308349,"u":99603308354,"b":[["77667.67000000","0.00007000"],["76516.76000000","0.00030000"],["69913.80000000","0.00425000"],["62145.60000000","0.00032000"]],"a":[["77698.76000000","0.00007000"]]}}
{"type":"depth","received_at_ms":1788407377409,"data":{"e":"depthUpdate","E":1788407377614,"s":"BTCUSDT","U":99603308355,"u":99603308367,"b":[["77491.18000000","0.02016000"],["77466.85000000","0.00000000"],["69913.80000000","0.00441000"],["62145.60000000","0.00000000"],["62145.59000000","0.00000000"]],"a":[["77682.00000000","1.79681000"]]}}
{"type":"depth","received_at_ms":1788407377509,"data":{"e":"depthUpdate","E":1788407377714,"s":"BTCUSDT","U":99603308368,"u":99603308374,"b":[["77681.99000000","9.92748000"],["69913.80000000","0.00448000"],["69913.79000000","0.00009000"]],"a":[["78847.23000000","0.00030000"]]}}
{"type":"depth","received_at_ms":1788407377610,"data":{"e":"depthUpdate","E":1788407377814,"s":"BTCUSDT","U":99603308375,"u":99603308379,"b":[["69913.80000000","0.00432000"],["62146.00000000","0.00000000"]],"a":[]}}
{"type":"depth","received_at_ms":1788407377709,"data":{"e":"depthUpdate","E":1788407377914,"s":"BTCUSDT","U":99603308380,"u":99603308380,"b":[["69913.80000000","0.00448000"]],"a":[]}}
{"type":"depth","received_at_ms":1788407377809,"data":{"e":"depthUpdate","E":1788407378014,"s":"BTCUSDT","U":99603308381,"u":99603308390,"b":[["77681.99000000","9.92724000"],["77293.58000000","0.00007000"],["69913.80000000","0.00432000"],["69913.79000000","0.00000000"],["62145.60000000","0.00032000"]],"a":[["77682.00000000","1.79551000"]]}}
{"type":"depth","received_at_ms":1788407377909,"data":{"e":"depthUpdate","E":1788407378114,"s":"BTCUSDT","U":99603308391,"u":99603308396,"b":[["69913.80000000","0.00448000"],["62146.00000000","0.00200000"]],"a":[["77734.93000000","0.12878000"],["77837.53000000","0.00033000"]]}}
{"type":"depth","received_at_ms":1788407378010,"data":{"e":"depthUpdate","E":1788407378214,"s":"BTCUSDT","U":99603308397,"u":99603308400,"b":[["71467.43000000","0.00014000"],["69913.80000000","0.00432000"],["62146.00000000","0.00000000"],["62145.60000000","0.00000000"]],"a":[]}}
{"type":"depth","received_at_ms":1788407378110,"data":{"e":"depthUpdate","E":1788407378314,"s":"BTCUSDT","U":99603308401,"u":99603308414,"b":[["69913.80000000","0.00457000"],["62146.00000000","0.00000000"]],"a":[["77682.00000000","1.79511000"],["77734.73000000","0.00000000"],["77734.93000000","0.00000000"],["77734.98000000","0.12878000"],["77734.99000000","0.00000000"]]}}
{"type":"depth","received_at_ms":1788407378209,"data":{"e":"depthUpdate","E":1788407378414,"s":"BTCUSDT","U":99603308415,"u":99603308428,"b":[["77674.89000000","0.01400000"],["77673.66000000","0.00000000"],["69913.80000000","0.00457000"],["62146.00000000","0.00000000"]],"a":[["77682.00000000","1.66826000"],["77734.79000000","0.00000000"],["77734.80000000","0.00000000"],["77734.98000000","0.00000000"]]}}
{"type":"depth","received_at_ms":1788407378309,"data":{"e":"depthUpdate","E":1788407378514,"s":"BTCUSDT","U":99603308429,"u":99603308435,"b":[["77667.67000000","0.00007000"],["76516.76000000","0.00000000"],["69913.80000000","0.00473000"],["62145.60000000","0.00032000"]],"a":[["77687.92000000","0.00664000"],["77698.76000000","0.00007000"]]}}
{"type":"depth","received_at_ms":1788407378410,"data":{"e":"depthUpdate","E":1788407378615,"s":"BTCUSDT","U":99603308436,"u":99603308455,"b":[["76516.76000000","0.00030000"],["69913.80000000","0.00457000"],["62146.00000000","0.00000000"],["62145.60000000","0.00000000"],["62145.59000000","0.00000000"]],"a":[["77734.75000000","0.00000000"],["77734.98000000","0.12878000"]]}}
{"type":"depth","received_at_ms":1788407378510,"data":{"e":"depthUpdate","E":1788407378714,"s":"BTCUSDT","U":99603308456,"u":99603308462,"b":[["71467.43000000","0.00000000"],["69913.80000000","0.00473000"]],"a":[["77682.00000000","1.79220000"],["78847.23000000","0.00030000"]]}}
{"type":"depth","received_at_ms":1788407378609,"data":{"e":"depthUpdate","E":1788407378814,"s":"BTCUSDT","U":99603308463,"u":99603308473,"b":[["77681.99000000","9.92738000"],["77661.37000000","0.00000000"],["77638.07000000","0.00000000"],["69913.80000000","0.00441000"]],"a":[["77682.41000000","0.16117000"],["77685.99000000","0.00000000"],["77696.21000000","0.00000000"],["77707.54000000","0.00000000"],["77730.85000000","0.00000000"]]}}
{"type":"depth","received_at_ms":1788407378710,"data":{"e":"depthUpdate","E":1788407378914,"s":"BTCUSDT","U":99603308474,"u":99603308499,"b":[["77681.99000000","9.92730000"],["77672.63000000","0.00000000"],["69913.80000000","0.00457000"],["62146.00000000","0.00000000"]],"a":[["77682.00000000","1.79234000"],["77682.01000000","0.00070000"],["77682.40000000","0.00000000"],["77682.41000000","0.00014000"],["77684.89000000","0.00007000"],["77684.90000000","0.10315000"],["77685.99000000","0.00000000"],["77686.34000000","0.12001000"],["77698.06000000","0.10315000"],["77734.98000000","0.00000000"]]}}
{"type":"depth","received_at_ms":1788407378809,"data":{"e":"depthUpdate","E":1788407379014,"s":"BTCUSDT","U":99603308500,"u":99603308512,"b":[["77293.58000000","0.00000000"],["69913.80000000","0.00457000"],["62146.00000000","0.00000000"],["62145.60000000","0.00032000"]],"a":[["77682.00000000","1.79241000"],["77682.01000000","0.00077000"],["77684.77000000","0.03176000"],["78253.05000000","0.00000000"]]}}
{"type":"depth","received_at_ms":1788407378910,"data":{"e":"depthUpdate","E":1788407379114,"s":"BTCUSDT","U":99603308513,"u":99603308522,"b":[["77681.99000000","9.92723000"],["77670.91000000","0.02020000"],["77658.36000000","0.51907000"],["77635.06000000","1.05127000"],["69913.80000000","0.00441000"]],"a":[["77695.71000000","0.25468000"],["77707.26000000","0.49514000"],["77730.58000000","0.98518000"]]}}
{"type":"depth","received_at_ms":1788407379009,"data":{"e":"depthUpdate","E":1788407379214,"s":"BTCUSDT","U":99603308523,"u":99603308525,"b":[["69913.80000000","0.00473000"],["62145.60000000","0.00000000"]],"a":[]}}
{"type":"depth","received_at_ms":1788407379109,"data":{"e":"depthUpdate","E":1788407379314,"s":"BTCUSDT","U":99603308526,"u":99603308537,"b":[["77681.99000000","9.92730000"],["77631.31000000","0.25750000"],["77627.07000000","0.22540000"],["77625.75000000","0.00000000"],["69913.80000000","0.00457000"],["62146.00000000","0.00000000"]],"a":[["77687.92000000","0.00000000"],["77687.96000000","0.00670000"]]}}
{"type":"depth","received_at_ms":1788407379209,"data":{"e":"depthUpdate","E":1788407379414,"s":"BTCUSDT","U":99603308538,"u":99603308544,"b":[["69913.80000000","0.00473000"],["62146.00000000","0.00000000"]],"a":[]}}
{"type":"depth","received_at_ms":1788407379310,"data":{"e":"depthUpdate","E":1788407379514,"s":"BTCUSDT","U":99603308545,"u":99603308552,"b":[["77667.67000000","0.00007000"],["69913.80000000","0.00457000"],["62145.60000000","0.00032000"]],"a":[["77698.76000000","0.00007000"],["77736.04000000","0.02000000"],["77736.40000000","0.12878000"]]}}
{"type":"depth","received_at_ms":1788407379410,"data":{"e":"depthUpdate","E":1788407379614,"s":"BTCUSDT","U":99603308553,"u":99603308564,"b":[["76516.76000000","0.00030000"],["69913.80000000","0.00473000"],["62145.60000000","0.00000000"],["62145.59000000","0.00000000"]],"a":[["77736.40000000","0.00000000"],["77756.06000000","0.00060000"]]}}
{"type":"depth","received_at_ms":1788407379509,"data":{"e":"depthUpdate","E":1788407379714,"s":"BTCUSDT","U":99603308565,"u":99603308570,"b":[["77659.66000000","0.00000000"],["69913.80000000","0.00457000"]],"a":[["77687.96000000","0.00000000"],["78847.23000000","0.00000000"]]}}
{"type":"depth","received_at_ms":1788407379610,"data":{"e":"depthUpdate","E":1788407379814,"s":"BTCUSDT","U":99603308571,"u":99603308574,"b":[["69913.80000000","0.00464000"],["69913.79000000","0.00009000"]],"a":[["77682.00000000","1.79202000"],["78847.23000000","0.00030000"]]}}
{"type":"depth","received_at_ms":1788407379709,"data":{"e":"depthUpdate","E":1788407379914,"s":"BTCUSDT","U":99603308575,"u":99603308579,"b":[["77681.99000000","9.92716000"],["69913.80000000","0.00448000"]],"a":[]}}
{"type":"depth","received_at_ms":1788407379810,"data":{"e":"depthUpdate","E":1788407380014,"s":"BTCUSDT","U":99603308580,"u":99603308585,"b":[["69913.80000000","0.00464000"],["62145.60000000","0.00032000"]],"a":[["77682.00000000","1.76965000"],["77718.57000000","0.00000000"]]}}
{"type":"depth","received_at_ms":1788407379909,"data":{"e":"depthUpdate","E":1788407380114,"s":"BTCUSDT","U":99603308586,"u":99603308593,"b":[["77681.99000000","9.92738000"],["69913.80000000","0.00448000"]],"a":[["77682.00000000","1.76939000"],["77708.56000000","0.04536000"],["77719.06000000","0.00000000"]]}}
{"type":"depth","received_at_ms":1788407380009,"data":{"e":"depthUpdate","E":1788407380214,"s":"BTCUSDT","U":99603308594,"u":99603308597,"b":[["69913.80000000","0.00464000"],["62145.60000000","0.00000000"]],"a":[]}}
{"type":"depth","received_at_ms":1788407380109,"data":{"e":"depthUpdate","E":1788407380314,"s":"BTCUSDT","U":99603308598,"u":99603308602,"b":[["69913.80000000","0.00448000"],["62146.00000000","0.00000000"]],"a":[]}}
{"type":"depth","received_at_ms":1788407380210,"data":{"e":"depthUpdate","E":1788407380414,"s":"BTCUSDT","U":99603308603,"u":99603308607,"b":[["69913.80000000","0.00448000"],["62146.00000000","0.00000000"]],"a":[["77682.00000000","1.77005000"]]}}
{"type":"depth","received_at_ms":1788407380309,"data":{"e":"depthUpdate","E":1788407380514,"s":"BTCUSDT","U":99603308608,"u":99603308617,"b":[["77681.99000000","9.92479000"],["69913.80000000","0.00448000"],["69913.79000000","0.00000000"],["62145.60000000","0.00032000"]],"a":[["77682.00000000","1.76991000"],["77684.90000000","0.10329000"],["77718.65000000","0.09588000"]]}}
{"type":"depth","received_at_ms":1788407380409,"data":{"e":"depthUpdate","E":1788407380614,"s":"BTCUSDT","U":99603308618,"u":99603308637,"b":[["77667.67000000","0.00007000"],["77660.17000000","0.00000000"],["77655.50000000","0.04679000"],["76516.76000000","0.00030000"],["69913.80000000","0.00448000"],["62145.60000000","0.00000000"],["62145.59000000","0.00000000"]],"a":[["77682.00000000","1.76979000"],["77698.76000000","0.00007000"],["77736.36000000","0.12878000"],["77736.43000000","0.00000000"]]}}
{"type":"depth","received_at_ms":1788407380509,"data":{"e":"depthUpdate","E":1788407380714,"s":"BTCUSDT","U":99603308638,"u":99603308645,"b":[["69913.80000000","0.00448000"]],"a":[["77682.00000000","1.79201000"],["77689.20000000","0.00655000"],["77736.36000000","0.00000000"],["77736.63000000","0.00000000"]]}}
{"type":"depth","received_at_ms":1788407380614,"data":{"e":"depthUpdate","E":1788407380818,"s":"BTCUSDT","U":99603308646,"u":99603308703,"b":[["77681.99000000","5.24163000"],["77681.98000000","0.00084000"],["77681.43000000","0.00109000"],["77681.42000000","0.00014000"],["77681.41000000","0.00000000"],["77681.06000000","0.00400000"],["77680.97000000","0.00000000"],["77680.35000000","0.00000000"],["77680.22000000","0.00146000"],["77679.51000000","0.00643000"],["77679.48000000","0.00400000"],["77678.96000000","0.00643000"],["77675.69000000","0.00000000"],["77674.89000000","0.00000000"],["77673.66000000","0.01600000"],["77659.11000000","0.00000000"],["77657.57000000","0.00200000"],["77619.05000000","1.89502000"],["77617.58000000","4.63427000"],["77611.24000000","0.00321000"],["77607.89000000","0.00000000"],["77607.29000000","0.00320000"],["77604.01000000","0.00000000"],["77532.96000000","0.00128000"],["77530.01000000","0.00000000"],["77529.46000000","0.00128000"],["77526.01000000","0.00000000"],["69913.80000000","0.00457000"],["62146.00000000","0.00000000"]],"a":[["77682.00000000","1.96034000"],["77682.01000000","0.00084000"],["77682.40000000","0.00007000"],["77682.41000000","0.19203000"],["77685.05000000","0.00007000"],["77692.42000000","0.00000000"],["77693.60000000","0.00643000"],["77693.71000000","0.00000000"],["77694.95000000","0.00000000"],["77695.52000000","0.00400000"],["77698.40000000","0.00400000"],["77815.19000000","0.00000000"],["77817.84000000","0.00128000"],["78847.23000000","0.00030000"]]}}
{"type":"depth","received_at_ms":1788407380709,"data":{"e":"depthUpdate","E":1788407380914,"s":"BTCUSDT","U":99603308704,"u":99603308744,"b":[["77681.99000000","5.24162000"],["77681.98000000","0.00070000"],["77681.42000000","0.00000000"],["77679.82000000","0.14068000"],["77679.32000000","0.00643000"],["77678.96000000","0.00000000"],["77672.79000000","0.00200000"],["69913.80000000","0.00473000"]],"a":[["77682.00000000","1.96048000"],["77682.41000000","0.19217000"],["77686.33000000","0.10315000"],["77688.67000000","0.00000000"],["77690.11000000","0.00400000"],["77691.65000000","0.00400000"],["77696.17000000","0.00800000"]]}}
{"type":"depth","received_at_ms":1788407380810,"data":{"e":"depthUpdate","E":1788407381014,"s":"BTCUSDT","U":99603308745,"u":99603308754,"b":[["77681.99000000","5.24170000"],["77679.51000000","0.00000000"],["77679.34000000","0.00643000"],["77679.32000000","0.00000000"],["77678.96000000","0.00643000"],["77670.91000000","0.00000000"],["77658.36000000","0.00000000"],["69913.80000000","0.00441000"],["62145.60000000","0.00032000"]],"a":[["77682.00000000","1.96096000"],["77690.90000000","0.00000000"]]}}
{"type":"depth","received_at_ms":1788407380910,"data":{"e":"depthUpdate","E":1788407381114,"s":"BTCUSDT","U":99603308755,"u":99603308769,"b":[["77681.99000000","5.24163000"],["77681.88000000","0.00520000"],["77679.82000000","0.14068000"],["69913.80000000","0.00473000"],["62146.00000000","0.00000000"]],"a":[["77695.71000000","0.00000000"],["77737.03000000","0.25000000"]]}}
{"type":"depth","received_at_ms":1788407381009,"data":{"e":"depthUpdate","E":1788407381214,"s":"BTCUSDT","U":99603308770,"u":99603308780,"b":[["77681.99000000","5.24170000"],["77681.98000000","0.00077000"],["76146.32000000","0.00000000"],["69913.80000000","0.00457000"],["62145.60000000","0.00000000"]],"a":[]}}
{"type":"depth","received_at_ms":1788407381110,"data":{"e":"depthUpdate","E":1788407381314,"s":"BTCUSDT","U":99603308781,"u":99603308788,"b":[["77658.37000000","0.49560000"],["69913.80000000","0.00473000"],["62146.00000000","0.00000000"]],"a":[["77688.76000000","0.00000000"]]}}
{"type":"depth","received_at_ms":1788407381209,"data":{"e":"depthUpdate","E":1788407381414,"s":"BTCUSDT","U":99603308789,"u":99603308794,"b":[["77670.90000000","0.01539000"],["77599.06000000","0.00000000"],["77596.51000000","0.72109000"],["76982.85000000","0.00000000"],["69913.80000000","0.00457000"]],"a":[["77695.73000000","0.26692000"]]}}
{"type":"depth","received_at_ms":1788407381309,"data":{"e":"depthUpdate","E":1788407381514,"s":"BTCUSDT","U":99603308795,"u":99603308806,"b":[["77681.43000000","0.00000000"],["77681.07000000","0.00111000"],["77680.22000000","0.00000000"],["77679.51000000","0.00147000"],["77674.89000000","0.00800000"],["77673.66000000","0.00800000"],["76536.66000000","0.00032000"],["69913.80000000","0.00473000"],["62145.60000000","0.00032000"]],"a":[["77688.74000000","0.00519000"]]}}
{"type":"depth","received_at_ms":1788407381409,"data":{"e":"depthUpdate","E":1788407381614,"s":"BTCUSDT","U":99603308807,"u":99603308824,"b":[["77667.67000000","0.00007000"],["76516.76000000","0.00030000"],["69913.80000000","0.00457000"],["62146.00000000","0.00000000"],["62145.60000000","0.00000000"],["62145.59000000","0.00000000"]],"a":[["77698.76000000","0.00007000"],["77800.00000000","0.05515000"]]}}
{"type":"depth","received_at_ms":1788407381508,"data":{"e":"depthUpdate","E":1788407381714,"s":"BTCUSDT","U":99603308825,"u":99603308825,"b":[["69913.80000000","0.00473000"]],"a":[]}}
{"type":"depth","received_at_ms":1788407381610,"data":{"e":"depthUpdate","E":1788407381814,"s":"BTCUSDT","U":99603308826,"u":99603308834,"b":[["69913.80000000","0.00441000"]],"a":[["77734.90000000","0.00000000"],["77864.66000000","0.00000000"],["78847.23000000","0.00030000"]]}}
{"type":"depth","received_at_ms":1788407381709,"data":{"e":"depthUpdate","E":1788407381914,"s":"BTCUSDT","U":99603308835,"u":99603308842,"b":[["69913.80000000","0.00441000"]],"a":[["77734.44000000","0.00000000"],["77734.63000000","0.00000000"]]}}
{"type":"depth","received_at_ms":1788407381810,"data":{"e":"depthUpdate","E":1788407382014,"s":"BTCUSDT","U":99603308843,"u":99603308852,"b":[["77679.32000000","0.00643000"],["77678.96000000","0.00000000"],["77674.89000000","0.01000000"],["77672.79000000","0.00000000"],["77628.07000000","0.00000000"],["77591.97000000","0.06511000"],["62146.00000000","0.00000000"],["62145.60000000","0.00032000"]],"a":[["77682.00000000","1.79226000"],["77695.52000000","0.00000000"]]}}
{"type":"depth","received_at_ms":1788407381909,"data":{"e":"depthUpdate","E":1788407382114,"s":"BTCUSDT","U":99603308853,"u":99603308869,"b":[["77681.99000000","5.24177000"],["77674.89000000","0.00800000"],["77672.34000000","0.00200000"],["77599.06000000","0.72109000"],["77596.51000000","0.00000000"],["75561.74000000","0.00000000"],["69913.80000000","0.00441000"]],"a":[["77691.65000000","0.00000000"],["77692.16000000","0.00400000"],["77693.60000000","0.00000000"],["77693.84000000","0.00643000"],["77696.58000000","0.00400000"],["77734.01000000","0.12878000"],["77734.51000000","0.00000000"],["81006.07000000","0.00000000"]]}}
{"type":"depth","received_at_ms":1788407382009,"data":{"e":"depthUpdate","E":1788407382214,"s":"BTCUSDT","U":99603308870,"u":99603308874,"b":[["69913.80000000","0.00457000"],["62145.60000000","0.00000000"]],"a":[["77734.01000000","0.00000000"]]}}
{"type":"depth","received_at_ms":1788407382109,"data":{"e":"depthUpdate","E":1788407382314,"s":"BTCUSDT","U":99603308875,"u":99603308882,"b":[["77674.89000000","0.01000000"],["77672.34000000","0.00000000"],["69913.80000000","0.00425000"],["62146.00000000","0.00000000"]],"a":[["77734.28000000","0.00000000"]]}}
{"type":"depth","received_at_ms":1788407382209,"data":{"e":"depthUpdate","E":1788407382414,"s":"BTCUSDT","U":99603308883,"u":99603308885,"b":[["76982.85000000","0.00010000"],["69913.80000000","0.00457000"]],"a":[]}}
{"type":"depth","received_at_ms":1788407382309,"data":{"e":"depthUpdate","E":1788407382514,"s":"BTCUSDT","U":99603308886,"u":99603308891,"b":[["76350.00000000","0.17950000"],["69913.80000000","0.00441000"],["62145.60000000","0.00032000"]],"a":[["77682.00000000","1.79236000"]]}}
{"type":"depth","received_at_ms":1788407382409,"data":{"e":"depthUpdate","E":1788407382614,"s":"BTCUSDT","U":99603308892,"u":99603308911,"b":[["77681.99000000","5.28129000"],["77681.07000000","0.00000000"],["77667.67000000","0.00007000"],["76516.76000000","0.00030000"],["69913.80000000","0.00441000"],["62146.00000000","0.00200000"],["62145.60000000","0.00000000"]],"a":[["77690.11000000","0.00000000"],["77690.60000000","0.00400000"],["77696.17000000","0.00000000"],["77696.58000000","0.01200000"],["77698.76000000","0.00007000"]]}}
{"type":"depth","received_at_ms":1788407382510,"data":{"e":"depthUpdate","E":1788407382714,"s":"BTCUSDT","U":99603308912,"u":99603308929,"b":[["69913.80000000","0.00432000"],["69913.79000000","0.00009000"],["62146.00000000","0.00000000"],["62145.59000000","0.00000000"]],"a":[["77682.00000000","1.79180000"],["77690.49000000","0.00000000"],["77733.34000000","0.00000000"]]}}
{"type":"depth","received_at_ms":1788407382609,"data":{"e":"depthUpdate","E":1788407382814,"s":"BTCUSDT","U":99603308930,"u":99603308946,"b":[["77681.99000000","5.28115000"],["77674.89000000","0.00800000"],["77672.79000000","0.00000000"],["69913.80000000","0.00448000"]],"a":[["77682.00000000","1.79180000"],["77690.51000000","0.00048000"],["77734.33000000","0.00010000"],["78847.23000000","0.00030000"]]}}
{"type":"depth","received_at_ms":1788407382710,"data":{"e":"depthUpdate","E":1788407382914,"s":"BTCUSDT","U":99603308947,"u":99603308957,"b":[["77681.99000000","5.28115000"],["77674.89000000","0.01000000"],["69913.80000000","0.00432000"]],"a":[["77682.00000000","1.79180000"],["77690.51000000","0.00000000"]]}}
{"type":"depth","received_at_ms":1788407382809,"data":{"e":"depthUpdate","E":1788407383014,"s":"BTCUSDT","U":99603308958,"u":99603309010,"b":[["77681.99000000","9.91541000"],["77681.41000000","0.00643000"],["77680.02000000","0.00643000"],["77679.34000000","0.00000000"],["77679.32000000","0.00000000"],["77671.18000000","0.00290000"],["77619.06000000","0.00000000"],["77619.05000000","0.58670000"],["77617.58000000","0.00000000"],["77599.06000000","0.00000000"],["77596.51000000","0.72109000"],["75561.74000000","0.00010000"],["69913.80000000","0.00448000"],["69913.79000000","0.00000000"],["62145.60000000","0.00032000"]],"a":[["77682.00000000","1.57321000"],["77686.36000000","0.00007000"],["77686.54000000","0.00000000"],["77688.74000000","0.00000000"],["77689.20000000","0.00000000"],["77690.49000000","0.00048000"],["77690.60000000","0.00000000"],["77690.75000000","0.00000000"],["77690.87000000","0.00532000"],["77691.08000000","0.00400000"],["77692.16000000","0.00000000"],["77693.19000000","0.00000000"],["77693.84000000","0.00000000"],["77694.95000000","0.00000000"],["77695.72000000","0.00643000"]]}}
{"type":"depth","received_at_ms":1788407382909,"data":{"e":"depthUpdate","E":1788407383114,"s":"BTCUSDT","U":99603309011,"u":99603309033,"b":[["77681.99000000","9.91563000"],["77681.98000000","0.00091000"],["77681.88000000","0.00534000"],["77681.41000000","0.00657000"],["77680.21000000","0.01563000"],["77679.82000000","0.14054000"],["77674.89000000","0.00800000"],["77673.66000000","0.01000000"],["69913.80000000","0.00432000"]],"a":[["77682.00000000","1.42642000"],["77686.36000000","0.00014000"],["77693.81000000","0.00400000"]]}}
{"type":"depth","received_at_ms":1788407383010,"data":{"e":"depthUpdate","E":1788407383215,"s":"BTCUSDT","U":99603309034,"u":99603309038,"b":[["69913.80000000","0.00448000"],["62145.60000000","0.00000000"]],"a":[["81006.07000000","0.00010000"]]}}
{"type":"depth","received_at_ms":1788407383110,"data":{"e":"depthUpdate","E":1788407383315,"s":"BTCUSDT","U":99603309039,"u":99603309044,"b":[["69913.80000000","0.00441000"],["62146.00000000","0.00000000"]],"a":[["77682.00000000","1.42633000"],["77800.00000000","0.05613000"],["78000.00000000","22.90709000"]]}}
{"type":"depth","received_at_ms":1788407383210,"data":{"e":"depthUpdate","E":1788407383414,"s":"BTCUSDT","U":99603309045,"u":99603309051,"b":[["76500.11000000","0.00000000"],["69913.80000000","0.00441000"]],"a":[["77733.91000000","0.00000000"]]}}
{"type":"depth","received_at_ms":1788407383310,"data":{"e":"depthUpdate","E":1788407383515,"s":"BTCUSDT","U":99603309052,"u":99603309056,"b":[["69913.80000000","0.00441000"],["62145.60000000","0.00032000"]],"a":[["77734.24000000","0.00000000"]]}}
{"type":"depth","received_at_ms":1788407383411,"data":{"e":"depthUpdate","E":1788407383614,"s":"BTCUSDT","U":99603309057,"u":99603309067,"b":[["77667.67000000","0.00000000"],["77599.06000000","0.72109000"],["77596.51000000","0.00000000"],["76516.76000000","0.00030000"],["69913.80000000","0.00441000"],["62145.60000000","0.00000000"]],"a":[["77688.92000000","0.00664000"],["77698.76000000","0.00000000"],["77732.98000000","0.00000000"]]}}
{"type":"depth","received_at_ms":1788407383509,"data":{"e":"depthUpdate","E":1788407383714,"s":"BTCUSDT","U":99603309068,"u":99603309092,"b":[["77681.99000000","9.91660000"],["77680.21000000","0.01577000"],["77667.67000000","0.00007000"],["69913.80000000","0.00448000"],["69913.79000000","0.00009000"],["62145.59000000","0.00000000"]],"a":[["77682.00000000","1.66938000"],["77698.76000000","0.00007000"]]}}
{"type":"depth","received_at_ms":1788407383609,"data":{"e":"depthUpdate","E":1788407383814,"s":"BTCUSDT","U":99603309093,"u":99603309102,"b":[["77681.99000000","9.91653000"],["71467.43000000","0.00014000"],["69913.80000000","0.00432000"],["62146.00000000","0.00000000"]],"a":[["77682.00000000","1.66628000"],["78847.23000000","0.00030000"]]}}
{"type":"depth","received_at_ms":1788407383709,"data":{"e":"depthUpdate","E":1788407383914,"s":"BTCUSDT","U":99603309103,"u":99603309107,"b":[["69913.80000000","0.00432000"]],"a":[["77682.00000000","1.66504000"],["77732.49000000","0.00000000"]]}}
{"type":"depth","received_at_ms":1788407383809,"data":{"e":"depthUpdate","E":1788407384014,"s":"BTCUSDT","U":99603309108,"u":99603309111,"b":[["69913.80000000","0.00432000"],["62145.60000000","0.00032000"]],"a":[["77682.41000000","0.00028000"]]}}
{"type":"depth","received_at_ms":1788407383909,"data":{"e":"depthUpdate","E":1788407384114,"s":"BTCUSDT","U":99603309112,"u":99603309164,"b":[["77681.99000000","9.92430000"],["77681.98000000","0.00084000"],["77681.41000000","0.00014000"],["77681.22000000","0.00000000"],["77680.76000000","0.00643000"],["77680.73000000","0.00400000"],["77680.02000000","0.00000000"],["77679.51000000","0.00000000"],["77679.48000000","0.00000000"],["77676.18000000","0.00000000"],["77674.89000000","0.01000000"],["77673.66000000","0.00800000"],["77661.11000000","0.00000000"],["77659.04000000","4.63718000"],["77657.57000000","0.00000000"],["77577.33000000","0.00108000"],["77571.42000000","0.00168000"],["69913.80000000","0.00448000"],["62146.00000000","0.00200000"]],"a":[["77682.00000000","1.66533000"],["77682.01000000","0.00077000"],["77682.40000000","0.00000000"],["77682.41000000","0.00014000"],["77684.89000000","0.00014000"],["77691.08000000","0.00000000"],["77693.81000000","0.00000000"],["77694.69000000","0.00400000"],["77695.72000000","0.00000000"],["77696.57000000","0.00643000"]]}}
{"type":"depth","received_at_ms":1788407384011,"data":{"e":"depthUpdate","E":1788407384215,"s":"BTCUSDT","U":99603309165,"u":99603309191,"b":[["77681.99000000","9.92430000"],["77681.98000000","0.00084000"],["77681.88000000","0.00534000"],["77681.41000000","0.00000000"],["77681.39000000","0.09131000"],["77680.76000000","0.00657000"],["77680.21000000","0.01563000"],["69913.80000000","0.00416000"],["69913.79000000","0.00000000"],["62146.00000000","0.00000000"],["62145.60000000","0.00000000"]],"a":[["77682.00000000","1.66518000"],["77686.33000000","0.10329000"],["77691.67000000","0.00400000"]]}}
{"type":"depth","received_at_ms":1788407384109,"data":{"e":"depthUpdate","E":1788407384314,"s":"BTCUSDT","U":99603309192,"u":99603309196,"b":[["71467.43000000","0.00000000"],["69913.80000000","0.00448000"],["62146.00000000","0.00000000"]],"a":[]}}
{"type":"depth","received_at_ms":1788407384209,"data":{"e":"depthUpdate","E":1788407384414,"s":"BTCUSDT","U":99603309197,"u":99603309202,"b":[["69913.80000000","0.00432000"],["62146.00000000","0.00000000"]],"a":[["77733.23000000","0.12878000"]]}}
{"type":"depth","received_at_ms":1788407384310,"data":{"e":"depthUpdate","E":1788407384514,"s":"BTCUSDT","U":99603309203,"u":99603309210,"b":[["77676.93000000","0.03867000"],["69913.80000000","0.00432000"],["62145.60000000","0.00032000"]],"a":[["77732.15000000","0.00000000"],["77732.31000000","0.12878000"],["77733.23000000","0.00000000"]]}}
{"type":"depth","received_at_ms":1788407384410,"data":{"e":"depthUpdate","E":1788407384614,"s":"BTCUSDT","U":99603309211,"u":99603309230,"b":[["77681.99000000","9.91886000"],["77680.21000000","0.01577000"],["76516.76000000","0.00030000"],["69913.80000000","0.00432000"],["69913.79000000","0.00009000"],["62146.00000000","0.00000000"],["62145.60000000","0.00000000"]],"a":[["77682.00000000","1.66504000"],["77732.31000000","0.00000000"]]}}
{"type":"depth","received_at_ms":1788407384509,"data":{"e":"depthUpdate","E":1788407384714,"s":"BTCUSDT","U":99603309231,"u":99603309241,"b":[["77667.67000000","0.00007000"],["69913.80000000","0.00448000"],["62145.59000000","0.00000000"]],"a":[["77682.00000000","1.66396000"],["77698.76000000","0.00007000"]]}}
{"type":"depth","received_at_ms":1788407384609,"data":{"e":"depthUpdate","E":1788407384814,"s":"BTCUSDT","U":99603309242,"u":99603309248,"b":[["69913.80000000","0.00432000"]],"a":[["77732.57000000","0.00000000"],["78847.23000000","0.00030000"]]}}
{"type":"depth","received_at_ms":1788407384709,"data":{"e":"depthUpdate","E":1788407384914,"s":"BTCUSDT","U":99603309249,"u":99603309265,"b":[["77681.99000000","9.91886000"],["77681.88000000","0.00014000"],["69913.80000000","0.00432000"]],"a":[["77682.00000000","1.83273000"],["77682.01000000","0.00084000"],["77682.40000000","0.00007000"],["77682.41000000","0.19203000"],["77685.05000000","0.00000000"],["77732.55000000","0.00000000"]]}}
{"type":"depth","received_at_ms":1788407384810,"data":{"e":"depthUpdate","E":1788407385014,"s":"BTCUSDT","U":99603309266,"u":99603309289,"b":[["77681.99000000","9.92394000"],["77681.88000000","0.00000000"],["77681.39000000","0.09138000"],["69913.80000000","0.00432000"],["62146.00000000","0.00000000"],["62145.60000000","0.00032000"]],"a":[["77682.00000000","1.83287000"],["77682.40000000","0.00000000"],["77682.41000000","0.00028000"],["77685.05000000","0.00007000"],["77686.33000000","0.10315000"],["77688.77000000","0.00519000"]]}}
{"type":"depth","received_at_ms":1788407384909,"data":{"e":"depthUpdate","E":1788407385114,"s":"BTCUSDT","U":99603309290,"u":99603309303,"b":[["77681.99000000","9.92394000"],["77681.98000000","0.00077000"],["69913.80000000","0.00432000"]],"a":[["77682.00000000","1.66410000"],["77682.01000000","0.00077000"],["77682.41000000","0.00014000"],["77686.33000000","0.10329000"]]}}
{"type":"depth","received_at_ms":1788407385009,"data":{"e":"depthUpdate","E":1788407385214,"s":"BTCUSDT","U":99603309304,"u":99603309313,"b":[["77681.99000000","9.92408000"],["77667.30000000","0.00000000"],["77663.52000000","0.00000000"],["69913.80000000","0.00448000"],["69913.79000000","0.00000000"],["69913.78000000","0.00009000"],["62145.60000000","0.00000000"]],"a":[["77682.00000000","1.66397000"],["77704.99000000","0.00000000"],["77706.47000000","0.00000000"]]}}
{"type":"depth","received_at_ms":1788407385110,"data":{"e":"depthUpdate","E":1788407385314,"s":"BTCUSDT","U":99603309314,"u":99603309318,"b":[["69913.80000000","0.00432000"],["62146.00000000","0.00000000"]],"a":[]}}
{"type":"depth","received_at_ms":1788407385209,"data":{"e":"depthUpdate","E":1788407385414,"s":"BTCUSDT","U":99603309319,"u":99603309337,"b":[["77681.99000000","9.91772000"],["77681.98000000","0.00084000"],["77681.07000000","0.00643000"],["77680.76000000","0.00014000"],["77680.22000000","0.00643000"],["77648.00000000","0.73007000"],["77646.00000000","0.03000000"],["69913.80000000","0.00448000"],["62146.00000000","0.00000000"]],"a":[["77682.00000000","1.80363000"],["77733.12000000","0.14034000"]]}}
{"type":"depth","received_at_ms":1788407385309,"data":{"e":"depthUpdate","E":1788407385514,"s":"BTCUSDT","U":99603309338,"u":99603309357,"b":[["77681.99000000","9.91772000"],["77681.98000000","0.00084000"],["77681.39000000","0.09138000"],["77681.07000000","0.00657000"],["77680.76000000","0.00000000"],["77680.74000000","0.01698000"],["69913.80000000","0.00432000"],["62145.60000000","0.00032000"]],"a":[]}}
{"type":"depth","received_at_ms":1788407385409,"data":{"e":"depthUpdate","E":1788407385614,"s":"BTCUSDT","U":99603309358,"u":99603309363,"b":[["76516.76000000","0.00030000"],["69913.80000000","0.00448000"],["62145.60000000","0.00000000"]],"a":[]}}
{"type":"depth","received_at_ms":1788407385513,"data":{"e":"depthUpdate","E":1788407385717,"s":"BTCUSDT","U":99603309364,"u":99603309380,"b":[["77681.99000000","9.91751000"],["77667.67000000","0.00007000"],["69913.80000000","0.00432000"],["62145.59000000","0.00000000"]],"a":[["77682.00000000","1.66404000"],["77682.01000000","0.00084000"],["77685.85000000","0.12364000"],["77698.76000000","0.00007000"]]}}
{"type":"depth","received_at_ms":1788407385609,"data":{"e":"depthUpdate","E":1788407385814,"s":"BTCUSDT","U":99603309381,"u":99603309392,"b":[["69913.80000000","0.00432000"]],"a":[["77685.06000000","0.32214000"],["77685.85000000","0.12378000"],["77686.33000000","0.10315000"],["78847.23000000","0.00030000"]]}}
{"type":"depth","received_at_ms":1788407385709,"data":{"e":"depthUpdate","E":1788407385914,"s":"BTCUSDT","U":99603309393,"u":99603309394,"b":[["69913.80000000","0.00432000"]],"a":[]}}
{"type":"depth","received_at_ms":1788407385809,"data":{"e":"depthUpdate","E":1788407386014,"s":"BTCUSDT","U":99603309395,"u":99603309399,"b":[["69913.80000000","0.00448000"],["62145.60000000","0.00032000"]],"a":[["77870.38000000","0.00000000"]]}}
{"type":"depth","received_at_ms":1788407385909,"data":{"e":"depthUpdate","E":1788407386114,"s":"BTCUSDT","U":99603309400,"u":99603309403,"b":[["69913.80000000","0.00416000"]],"a":[["77682.00000000","1.66411000"],["77807.03000000","0.02016000"]]}}
{"type":"depth","received_at_ms":1788407386009,"data":{"e":"depthUpdate","E":1788407386214,"s":"BTCUSDT","U":99603309404,"u":99603309409,"b":[["77505.10000000","0.00000000"],["69913.80000000","0.00432000"],["62145.60000000","0.00000000"]],"a":[["77861.44000000","0.00000000"]]}}
{"type":"depth","received_at_ms":1788407386109,"data":{"e":"depthUpdate","E":1788407386314,"s":"BTCUSDT","U":99603309410,"u":99603309413,"b":[["69913.80000000","0.00432000"],["62146.00000000","0.00000000"]],"a":[]}}
{"type":"depth","received_at_ms":1788407386209,"data":{"e":"depthUpdate","E":1788407386414,"s":"BTCUSDT","U":99603309414,"u":99603309419,"b":[["77505.17000000","4.51273000"],["69913.80000000","0.00432000"]],"a":[["77860.54000000","4.55645000"]]}}
{"type":"depth","received_at_ms":1788407386309,"data":{"e":"depthUpdate","E":1788407386514,"s":"BTCUSDT","U":99603309420,"u":99603309421,"b":[["77474.76000000","0.00000000"],["77464.81000000","0.00812000"],["62145.60000000","0.00032000"]],"a":[]}}
{"type":"depth","received_at_ms":1788407386409,"data":{"e":"depthUpdate","E":1788407386614,"s":"BTCUSDT","U":99603309422,"u":99603309432,"b":[["76516.76000000","0.00030000"],["69913.80000000","0.00432000"],["69913.78000000","0.00000000"],["62145.60000000","0.00000000"]],"a":[["77682.00000000","1.66395000"],["77688.77000000","0.00000000"],["78300.00000000","4.41633000"]]}}
{"type":"depth","received_at_ms":1788407386509,"data":{"e":"depthUpdate","E":1788407386714,"s":"BTCUSDT","U":99603309433,"u":99603309454,"b":[["77681.99000000","9.92387000"],["77681.07000000","0.00014000"],["77667.67000000","0.00000000"],["69913.80000000","0.00448000"],["62145.59000000","0.00040000"]],"a":[["77682.00000000","1.66388000"],["77686.34000000","0.00000000"],["77688.92000000","0.00000000"],["77690.07000000","0.00000000"],["77690.87000000","0.00000000"],["77693.37000000","0.38380000"],["77698.76000000","0.00000000"],["77733.12000000","0.01156000"]]}}
{"type":"depth","received_at_ms":1788407386608,"data":{"e":"depthUpdate","E":1788407386814,"s":"BTCUSDT","U":99603309455,"u":99603309494,"b":[["77681.99000000","9.92296000"],["77681.98000000","0.00077000"],["77681.39000000","0.09131000"],["77681.07000000","0.00000000"],["77680.74000000","0.01705000"],["77680.22000000","0.00657000"],["77679.84000000","0.00257000"],["77679.82000000","0.14068000"],["77678.95000000","0.00000000"],["77667.67000000","0.00007000"],["69913.80000000","0.00432000"],["62146.00000000","0.00000000"],["62145.59000000","0.00000000"]],"a":[["77682.00000000","1.66381000"],["77682.01000000","0.00091000"],["77685.84000000","0.17060000"],["77690.07000000","0.20319000"],["77694.48000000","0.00000000"],["77695.36000000","0.00257000"],["77698.76000000","0.00007000"],["77732.41000000","0.00000000"],["77732.82000000","0.00000000"],["78847.23000000","0.00030000"]]}}
{"type":"depth","received_at_ms":1788407386709,"data":{"e":"depthUpdate","E":1788407386914,"s":"BTCUSDT","U":99603309495,"u":99603309532,"b":[["77681.99000000","9.91654000"],["77681.07000000","0.00128000"],["77680.73000000","0.00000000"],["77680.30000000","0.00400000"],["77674.89000000","0.00800000"],["77673.66000000","0.01000000"],["77659.04000000","4.63518000"],["77657.82000000","0.00200000"],["77612.73000000","0.00000000"],["77534.96000000","0.00000000"],["69913.80000000","0.00464000"]],"a":[["77682.00000000","1.66381000"],["77685.06000000","0.32214000"],["77685.84000000","0.17074000"],["77686.22000000","0.00534000"],["77688.86000000","0.00672000"],["77689.69000000","0.00523000"],["77693.18000000","0.00400000"],["77694.69000000","0.00000000"],["77732.43000000","0.00000000"]]}}
{"type":"depth","received_at_ms":1788407386809,"data":{"e":"depthUpdate","E":1788407387014,"s":"BTCUSDT","U":99603309533,"u":99603309560,"b":[["77681.99000000","9.91539000"],["77681.98000000","0.00077000"],["77680.75000000","0.00657000"],["77673.66000000","0.00800000"],["77672.79000000","0.00200000"],["77616.01000000","0.00320000"],["77538.01000000","0.00128000"],["69913.80000000","0.00448000"],["62145.60000000","0.00032000"]],"a":[["77682.00000000","1.66388000"],["77682.01000000","0.00098000"],["77682.40000000","0.00007000"],["77682.41000000","0.19203000"],["77685.05000000","0.00000000"],["77689.69000000","0.00000000"],["77689.86000000","0.00530000"],["77695.52000000","0.00200000"],["77696.89000000","0.00000000"],["77733.27000000","0.12878000"]]}}
{"type":"depth","received_at_ms":1788407386909,"data":{"e":"depthUpdate","E":1788407387114,"s":"BTCUSDT","U":99603309561,"u":99603309581,"b":[["77681.99000000","9.91546000"],["77681.98000000","0.00084000"],["77681.39000000","0.09131000"],["69913.80000000","0.00464000"],["62146.00000000","0.00200000"]],"a":[["77682.00000000","1.66388000"],["77682.41000000","0.19217000"],["77686.00000000","0.03007000"],["77695.52000000","0.00000000"],["77696.17000000","0.00200000"],["77733.27000000","0.00000000"]]}}
{"type":"depth","received_at_ms":1788407387009,"data":{"e":"depthUpdate","E":1788407387214,"s":"BTCUSDT","U":99603309582,"u":99603309595,"b":[["77681.99000000","9.91287000"],["69913.80000000","0.00457000"],["62146.00000000","0.00000000"],["62145.60000000","0.00000000"]],"a":[["77682.00000000","1.66188000"],["77693.18000000","0.00000000"],["77693.72000000","0.00400000"],["77732.31000000","0.00000000"],["77733.01000000","0.00000000"]]}}
{"type":"depth","received_at_ms":1788407387110,"data":{"e":"depthUpdate","E":1788407387314,"s":"BTCUSDT","U":99603309596,"u":99603309600,"b":[["69913.80000000","0.00473000"],["62146.00000000","0.00000000"]],"a":[]}}
{"type":"depth","received_at_ms":1788407387209,"data":{"e":"depthUpdate","E":1788407387414,"s":"BTCUSDT","U":99603309601,"u":99603309604,"b":[["69913.80000000","0.00441000"]],"a":[["77688.86000000","0.00000000"],["77689.86000000","0.00000000"]]}}
{"type":"depth","received_at_ms":1788407387308,"data":{"e":"depthUpdate","E":1788407387514,"s":"BTCUSDT","U":99603309605,"u":99603309608,"b":[["77474.76000000","0.00812000"],["77464.81000000","0.00000000"],["69913.80000000","0.00473000"],["62145.60000000","0.00032000"]],"a":[]}}
{"type":"depth","received_at_ms":1788407387409,"data":{"e":"depthUpdate","E":1788407387614,"s":"BTCUSDT","U":99603309609,"u":99603309619,"b":[["77491.18000000","0.00000000"],["76516.76000000","0.00030000"],["69913.80000000","0.00457000"],["62146.00000000","0.00000000"],["62145.60000000","0.00000000"]],"a":[]}}
{"type":"depth","received_at_ms":1788407387510,"data":{"e":"depthUpdate","E":1788407387714,"s":"BTCUSDT","U":99603309620,"u":99603309625,"b":[["77513.76000000","0.02016000"],["69913.80000000","0.00432000"],["69913.79000000","0.00009000"]],"a":[["77682.00000000","1.62775000"]]}}
{"type":"depth","received_at_ms":1788407387609,"data":{"e":"depthUpdate","E":1788407387814,"s":"BTCUSDT","U":99603309626,"u":99603309646,"b":[["77673.66000000","0.00800000"],["77672.79000000","0.00000000"],["77672.52000000","0.00321000"],["77672.33000000","0.01811000"],["77668.67000000","0.00000000"],["77667.67000000","0.00007000"],["69913.80000000","0.00448000"],["62145.59000000","0.00000000"]],"a":[["77682.40000000","0.00007000"],["77682.41000000","0.19215000"],["77698.76000000","0.00007000"],["77728.42000000","0.00000000"],["78847.23000000","0.00030000"]]}}
{"type":"depth","received_at_ms":1788407387709,"data":{"e":"depthUpdate","E":1788407387914,"s":"BTCUSDT","U":99603309647,"u":99603309650,"b":[["69913.80000000","0.00448000"]],"a":[]}}
{"type":"depth","received_at_ms":1788407387809,"data":{"e":"depthUpdate","E":1788407388014,"s":"BTCUSDT","U":99603309651,"u":99603309659,"b":[["77673.66000000","0.01000000"],["77672.33000000","0.01611000"],["75561.74000000","0.00000000"],["69913.80000000","0.00448000"],["62146.00000000","0.00000000"],["62145.60000000","0.00032000"]],"a":[["78070.41000000","0.00007000"],["81006.07000000","0.00000000"]]}}
{"type":"depth","received_at_ms":1788407387909,"data":{"e":"depthUpdate","E":1788407388114,"s":"BTCUSDT","U":99603309660,"u":99603309666,"b":[["77681.99000000","9.91087000"],["77673.66000000","0.00800000"],["77672.79000000","0.00200000"],["69913.80000000","0.00448000"],["69913.79000000","0.00000000"]],"a":[["77682.00000000","1.62739000"]]}}
{"type":"depth","received_at_ms":1788407388009,"data":{"e":"depthUpdate","E":1788407388214,"s":"BTCUSDT","U":99603309667,"u":99603309686,"b":[["77681.99000000","9.91087000"],["77681.98000000","0.00091000"],["77681.00000000","0.00257000"],["77679.84000000","0.00000000"],["69913.80000000","0.00464000"],["62145.60000000","0.00000000"]],"a":[["77682.00000000","1.62732000"],["77682.01000000","0.00091000"],["77685.85000000","0.00014000"],["77695.36000000","0.00000000"],["77696.53000000","0.00257000"],["77733.56000000","0.00000000"],["77733.90000000","0.00000000"],["77734.37000000","0.00000000"]]}}
{"type":"depth","received_at_ms":1788407388110,"data":{"e":"depthUpdate","E":1788407388314,"s":"BTCUSDT","U":99603309687,"u":99603309706,"b":[["69913.80000000","0.00448000"],["62146.00000000","0.00000000"]],"a":[["77682.40000000","0.00000000"],["77682.41000000","0.00028000"],["77685.84000000","0.17074000"],["77685.85000000","0.00000000"],["77686.00000000","0.03021000"],["77733.76000000","0.00000000"],["77734.20000000","0.00000000"],["77734.24000000","0.12878000"]]}}
{"type":"depth","received_at_ms":1788407388210,"data":{"e":"depthUpdate","E":1788407388414,"s":"BTCUSDT","U":99603309707,"u":99603309722,"b":[["77681.99000000","9.90921000"],["69913.80000000","0.00464000"],["69913.79000000","0.00009000"]],"a":[["77682.00000000","1.62725000"],["77682.01000000","0.00084000"],["77682.41000000","0.00014000"],["77685.05000000","0.00007000"],["77686.22000000","0.00548000"],["77734.24000000","0.00000000"],["77735.21000000","0.12878000"]]}}
{"type":"depth","received_at_ms":1788407388310,"data":{"e":"depthUpdate","E":1788407388514,"s":"BTCUSDT","U":99603309723,"u":99603309742,"b":[["77681.99000000","9.90921000"],["77681.98000000","0.00084000"],["77681.00000000","0.00000000"],["77679.58000000","0.00257000"],["77673.66000000","0.01000000"],["77672.79000000","0.00000000"],["69913.80000000","0.00448000"],["62145.60000000","0.00032000"]],"a":[["77688.26000000","0.00648000"],["77689.48000000","0.00523000"],["77695.10000000","0.00257000"],["77696.17000000","0.00000000"],["77696.53000000","0.00000000"],["77696.57000000","0.00843000"],["77734.08000000","0.00000000"],["77735.21000000","0.00000000"]]}}
{"type":"depth","received_at_ms":1788407388409,"data":{"e":"depthUpdate","E":1788407388614,"s":"BTCUSDT","U":99603309743,"u":99603309749,"b":[["76516.76000000","0.00030000"],["69913.80000000","0.00464000"],["62145.60000000","0.00000000"]],"a":[["77734.40000000","0.12878000"]]}}
{"type":"depth","received_at_ms":1788407388510,"data":{"e":"depthUpdate","E":1788407388714,"s":"BTCUSDT","U":99603309750,"u":99603309755,"b":[["69913.80000000","0.00448000"],["62146.00000000","0.00000000"]],"a":[["77682.00000000","1.62732000"],["77686.30000000","0.12364000"],["77734.40000000","0.00000000"]]}}
{"type":"depth","received_at_ms":1788407388609,"data":{"e":"depthUpdate","E":1788407388814,"s":"BTCUSDT","U":99603309756,"u":99603309780,"b":[["77674.89000000","0.01000000"],["77673.66000000","0.00800000"],["77667.67000000","0.00007000"],["69913.80000000","0.00464000"],["69913.79000000","0.00000000"],["69913.78000000","0.00009000"],["62145.59000000","0.00000000"]],"a":[["77682.00000000","1.62724000"],["77682.42000000","0.00014000"],["77686.22000000","0.00548000"],["77688.26000000","0.00000000"],["77688.68000000","0.00654000"],["77689.48000000","0.00000000"],["77690.00000000","0.03522000"],["77698.76000000","0.00007000"],["78847.23000000","0.00030000"]]}}
{"type":"depth","received_at_ms":1788407388710,"data":{"e":"depthUpdate","E":1788407388914,"s":"BTCUSDT","U":99603309781,"u":99603309877,"b":[["77681.99000000","9.92621000"],["77681.98000000","0.00014000"],["77681.41000000","0.00000000"],["77681.07000000","0.00000000"],["77680.75000000","0.00014000"],["77680.30000000","0.00000000"],["77680.22000000","0.00014000"],["77680.20000000","0.00400000"],["77677.63000000","0.00800000"],["77676.96000000","0.01000000"],["77674.89000000","0.30866000"],["77673.66000000","0.00000000"],["77661.16000000","0.00200000"],["77657.82000000","0.00000000"],["77649.00000000","0.00000000"],["75561.74000000","0.00010000"],["69913.80000000","0.00448000"]],"a":[["77682.00000000","0.45697000"],["77682.01000000","0.00084000"],["77682.41000000","0.00000000"],["77682.42000000","0.00000000"],["77684.88000000","0.00007000"],["77684.89000000","0.00014000"],["77685.05000000","0.00014000"],["77685.83000000","0.00000000"],["77688.68000000","0.00000000"],["77690.00000000","0.03000000"],["77691.67000000","0.00000000"],["77692.38000000","0.00000000"],["77693.72000000","0.00000000"],["77694.09000000","0.00400000"],["77694.98000000","0.00000000"],["77696.57000000","0.00000000"],["77696.58000000","0.00400000"],["77697.01000000","0.00400000"],["77697.25000000","0.01000000"],["77698.86000000","0.00643000"],["77736.16000000","0.12878000"]]}}
{"type":"depth","received_at_ms":1788407388809,"data":{"e":"depthUpdate","E":1788407389014,"s":"BTCUSDT","U":99603309878,"u":99603309930,"b":[["77681.99000000","9.92629000"],["77681.39000000","0.09131000"],["77680.74000000","0.01698000"],["77680.56000000","0.00257000"],["77680.22000000","0.00000000"],["77679.58000000","0.00000000"],["77677.84000000","0.00546000"],["77677.63000000","0.00000000"],["77676.31000000","0.00800000"],["77585.44000000","0.03992000"],["77580.55000000","0.00000000"],["69913.80000000","0.00464000"],["62145.60000000","0.00032000"]],"a":[["77682.00000000","0.20497000"],["77682.01000000","0.00084000"],["77683.44000000","0.00014000"],["77683.45000000","0.10315000"],["77684.88000000","0.00000000"],["77684.89000000","0.00014000"],["77685.05000000","0.00007000"],["77685.83000000","0.00000000"],["77686.30000000","0.12378000"],["77695.10000000","0.00000000"],["77696.09000000","0.00257000"],["77697.01000000","0.00000000"],["77697.55000000","0.00400000"],["77710.00000000","0.03200000"],["77818.56000000","0.00971000"],["77818.59000000","0.00000000"],["78070.41000000","0.00000000"]]}}
{"type":"depth","received_at_ms":1788407388910,"data":{"e":"depthUpdate","E":1788407389115,"s":"BTCUSDT","U":99603309931,"u":99603309947,"b":[["77677.62000000","0.02903000"],["77676.96000000","0.00800000"],["77676.18000000","0.00200000"],["77602.78000000","0.41642000"],["77601.61000000","0.72109000"],["77599.06000000","0.00000000"],["69913.80000000","0.00448000"]],"a":[["77682.00000000","0.20511000"],["77683.04000000","0.00007000"],["77686.30000000","0.12364000"],["77692.89000000","0.00000000"],["77736.16000000","0.00000000"],["81006.07000000","0.00010000"]]}}
{"type":"depth","received_at_ms":1788407389010,"data":{"e":"depthUpdate","E":1788407389215,"s":"BTCUSDT","U":99603309948,"u":99603309968,"b":[["77681.99000000","9.92313000"],["77679.50000000","0.02035000"],["77676.96000000","0.00800000"],["77676.18000000","0.00200000"],["77475.35000000","0.00812000"],["77474.76000000","0.00000000"],["69913.80000000","0.00448000"],["69913.78000000","0.00000000"],["62145.60000000","0.00000000"]],"a":[["77682.00000000","0.20483000"],["77683.45000000","0.10329000"],["77684.95000000","0.10973000"]]}}
{"type":"depth","received_at_ms":1788407389110,"data":{"e":"depthUpdate","E":1788407389314,"s":"BTCUSDT","U":99603309969,"u":99603310001,"b":[["77681.35000000","0.00257000"],["77680.56000000","0.00000000"],["77676.18000000","0.00000000"],["77675.73000000","0.00200000"],["69913.80000000","0.00432000"],["62146.00000000","0.00000000"]],"a":[["77682.00000000","0.21641000"],["77682.01000000","0.00091000"],["77683.89000000","0.00007000"],["77683.90000000","0.11248000"],["77684.90000000","0.10329000"],["77684.95000000","0.00014000"],["77685.05000000","0.00000000"],["77686.22000000","0.00534000"],["77686.23000000","0.00000000"],["77686.30000000","0.00000000"],["77686.36000000","0.00007000"],["77696.09000000","0.00000000"],["77696.87000000","0.00257000"],["77724.96000000","0.00007000"]]}}
{"type":"depth","received_at_ms":1788407389209,"data":{"e":"depthUpdate","E":1788407389414,"s":"BTCUSDT","U":99603310002,"u":99603310050,"b":[["77681.99000000","9.91913000"],["77681.51000000","0.00400000"],["77681.39000000","0.09131000"],["77680.76000000","0.00000000"],["77677.62000000","0.02896000"],["77676.96000000","0.00000000"],["77676.92000000","0.01014000"],["77676.31000000","0.00000000"],["77675.73000000","0.00000000"],["77674.90000000","0.01800000"],["77661.16000000","0.00000000"],["77659.75000000","0.00200000"],["71467.43000000","0.00014000"],["69913.80000000","0.00448000"]],"a":[["77682.00000000","0.35084000"],["77683.45000000","0.10329000"],["77683.90000000","0.11262000"],["77684.90000000","0.10329000"],["77684.95000000","0.00000000"],["77689.41000000","0.00653000"],["77690.25000000","0.00533000"],["77692.00000000","0.03200000"],["77692.20000000","0.00532000"],["77692.57000000","0.00400000"],["77694.09000000","0.00000000"],["77696.05000000","0.00400000"],["77697.55000000","0.00000000"],["77837.53000000","0.00000000"]]}}
{"type":"depth","received_at_ms":1788407389309,"data":{"e":"depthUpdate","E":1788407389514,"s":"BTCUSDT","U":99603310051,"u":99603310059,"b":[["69913.80000000","0.00448000"],["62146.00000000","0.00000000"],["62145.60000000","0.00032000"]],"a":[["77682.00000000","0.48669000"],["77684.59000000","0.00000000"],["77735.39000000","0.12878000"]]}}
{"type":"depth","received_at_ms":1788407389409,"data":{"e":"depthUpdate","E":1788407389614,"s":"BTCUSDT","U":99603310060,"u":99603310086,"b":[["77681.99000000","9.91913000"],["76516.76000000","0.00030000"],["69913.80000000","0.00441000"],["62145.60000000","0.00000000"]],"a":[["77682.00000000","0.47470000"],["77683.82000000","0.00007000"],["77735.39000000","0.00000000"],["77736.27000000","0.00000000"]]}}
{"type":"depth","received_at_ms":1788407389509,"data":{"e":"depthUpdate","E":1788407389714,"s":"BTCUSDT","U":99603310087,"u":99603310090,"b":[["69913.80000000","0.00473000"]],"a":[["77715.00000000","0.70000000"],["78850.00000000","0.57529000"]]}}
{"type":"depth","received_at_ms":1788407389610,"data":{"e":"depthUpdate","E":1788407389814,"s":"BTCUSDT","U":99603310091,"u":99603310103,"b":[["77667.67000000","0.00000000"],["69913.80000000","0.00457000"],["62146.00000000","0.00000000"],["62145.59000000","0.00000000"]],"a":[["77682.00000000","0.47211000"],["77698.76000000","0.00000000"],["78847.23000000","0.00030000"]]}}
{"type":"depth","received_at_ms":1788407389709,"data":{"e":"depthUpdate","E":1788407389914,"s":"BTCUSDT","U":99603310104,"u":99603310141,"b":[["77681.99000000","9.92011000"],["77681.98000000","0.00063000"],["77667.67000000","0.00007000"],["71467.43000000","0.00000000"],["69913.80000000","0.00473000"]],"a":[["77682.00000000","0.58585000"],["77682.01000000","0.00091000"],["77683.01000000","0.00007000"],["77683.02000000","0.11931000"],["77683.89000000","0.00000000"],["77683.90000000","0.00014000"],["77698.76000000","0.00007000"]]}}
{"type":"depth","received_at_ms":1788407389810,"data":{"e":"depthUpdate","E":1788407390015,"s":"BTCUSDT","U":99603310142,"u":99603310156,"b":[["77670.90000000","0.00000000"],["77658.47000000","0.50798000"],["77658.37000000","0.00000000"],["69913.80000000","0.00448000"],["69913.79000000","0.00009000"],["62145.60000000","0.00032000"]],"a":[["77682.00000000","0.58560000"],["77683.02000000","0.11945000"],["77683.45000000","0.10315000"],["77683.90000000","0.00000000"]]}}
{"type":"depth","received_at_ms":1788407389910,"data":{"e":"depthUpdate","E":1788407390114,"s":"BTCUSDT","U":99603310157,"u":99603310163,"b":[["69913.80000000","0.00464000"],["63352.22000000","0.00000000"],["62146.00000000","0.00200000"]],"a":[["77682.00000000","0.58554000"],["77683.04000000","0.00000000"]]}}
{"type":"depth","received_at_ms":1788407390009,"data":{"e":"depthUpdate","E":1788407390214,"s":"BTCUSDT","U":99603310164,"u":99603310176,"b":[["77670.91000000","0.04876000"],["69913.80000000","0.00432000"],["62146.00000000","0.00000000"],["62145.60000000","0.00000000"]],"a":[["77682.00000000","0.58563000"],["77682.23000000","0.00007000"],["77682.24000000","0.14085000"],["77683.01000000","0.00000000"],["77683.02000000","0.00014000"]]}}
{"type":"depth","received_at_ms":1788407390109,"data":{"e":"depthUpdate","E":1788407390314,"s":"BTCUSDT","U":99603310177,"u":99603310193,"b":[["77681.35000000","0.00000000"],["77680.42000000","0.00257000"],["69913.80000000","0.00448000"],["62146.00000000","0.00000000"]],"a":[["77682.00000000","0.58577000"],["77682.01000000","0.00091000"],["77683.02000000","0.00000000"],["77686.36000000","0.00014000"],["77695.95000000","0.00257000"],["77696.87000000","0.00000000"],["77724.96000000","0.00000000"]]}}
{"type":"depth","received_at_ms":1788407390208,"data":{"e":"depthUpdate","E":1788407390414,"s":"BTCUSDT","U":99603310194,"u":99603310207,"b":[["77681.99000000","9.92011000"],["77681.98000000","0.00063000"],["76982.85000000","0.00000000"],["69913.80000000","0.00432000"],["62146.00000000","0.00000000"]],"a":[["77692.57000000","0.00000000"],["77693.23000000","0.00400000"],["77714.00000000","0.73000000"],["77715.00000000","0.00000000"]]}}
{"type":"depth","received_at_ms":1788407390309,"data":{"e":"depthUpdate","E":1788407390514,"s":"BTCUSDT","U":99603310208,"u":99603310212,"b":[["69913.80000000","0.00448000"],["62145.60000000","0.00032000"]],"a":[["77698.07000000","0.00000000"]]}}
{"type":"depth","received_at_ms":1788407390409,"data":{"e":"depthUpdate","E":1788407390614,"s":"BTCUSDT","U":99603310213,"u":99603310225,"b":[["76516.76000000","0.00030000"],["73100.00000000","7.42884000"],["69913.80000000","0.00432000"],["62146.00000000","0.00000000"],["62145.60000000","0.00000000"]],"a":[]}}
{"type":"depth","received_at_ms":1788407390509,"data":{"e":"depthUpdate","E":1788407390714,"s":"BTCUSDT","U":99603310226,"u":99603310245,"b":[["77681.99000000","9.91975000"],["69913.80000000","0.00432000"],["69913.79000000","0.00000000"]],"a":[["77682.00000000","0.58549000"],["77682.24000000","0.14099000"],["77683.04000000","0.00007000"],["77683.45000000","0.10329000"],["77734.16000000","0.12878000"],["77734.62000000","0.00000000"],["77734.65000000","0.00000000"]]}}
{"type":"depth","received_at_ms":1788407390610,"data":{"e":"depthUpdate","E":1788407390814,"s":"BTCUSDT","U":99603310246,"u":99603310259,"b":[["77681.99000000","9.91332000"],["77681.07000000","0.00643000"],["77602.78000000","0.23067000"],["77601.61000000","0.00000000"],["77599.06000000","0.72109000"],["69913.80000000","0.00432000"],["62145.59000000","0.00000000"]],"a":[["77682.00000000","0.58543000"],["77734.16000000","0.00000000"],["78847.23000000","0.00030000"]]}}
{"type":"depth","received_at_ms":1788407390710,"data":{"e":"depthUpdate","E":1788407390914,"s":"BTCUSDT","U":99603310260,"u":99603310273,"b":[["77681.99000000","9.91324000"],["77681.39000000","0.09131000"],["77667.67000000","0.00007000"],["69913.80000000","0.00416000"]],"a":[["77682.00000000","0.58524000"],["77698.76000000","0.00007000"]]}}
{"type":"depth","received_at_ms":1788407390810,"data":{"e":"depthUpdate","E":1788407391014,"s":"BTCUSDT","U":99603310274,"u":99603310279,"b":[["77681.99000000","9.91331000"],["77681.98000000","0.00070000"],["69913.80000000","0.00432000"],["62146.00000000","0.00000000"],["62145.60000000","0.00032000"]],"a":[]}}
{"type":"depth","received_at_ms":1788407390909,"data":{"e":"depthUpdate","E":1788407391114,"s":"BTCUSDT","U":99603310280,"u":99603310295,"b":[["77681.99000000","9.91339000"],["77661.27000000","0.04677000"],["77655.50000000","0.00000000"],["69913.80000000","0.00432000"]],"a":[["77682.00000000","0.79884000"],["77708.55000000","0.04541000"],["77708.56000000","0.00000000"],["77734.36000000","0.00000000"],["77734.62000000","0.00000000"]]}}
{"type":"depth","received_at_ms":1788407391010,"data":{"e":"depthUpdate","E":1788407391214,"s":"BTCUSDT","U":99603310296,"u":99603310298,"b":[["69913.80000000","0.00432000"],["62145.60000000","0.00000000"]],"a":[]}}
{"type":"depth","received_at_ms":1788407391109,"data":{"e":"depthUpdate","E":1788407391314,"s":"BTCUSDT","U":99603310299,"u":99603310302,"b":[["69913.80000000","0.00432000"],["62146.00000000","0.00000000"]],"a":[]}}
{"type":"depth","received_at_ms":1788407391210,"data":{"e":"depthUpdate","E":1788407391414,"s":"BTCUSDT","U":99603310303,"u":99603310321,"b":[["77670.91000000","0.00000000"],["76982.85000000","0.00010000"],["69913.80000000","0.00448000"],["62146.00000000","0.00000000"]],"a":[["77682.00000000","0.79891000"],["77682.01000000","0.00098000"],["77682.23000000","0.00014000"],["77683.43000000","0.00007000"],["77683.44000000","0.17697000"],["77684.89000000","0.00000000"],["77694.47000000","0.00400000"],["77695.73000000","0.00000000"],["77696.05000000","0.00000000"]]}}
{"type":"depth","received_at_ms":1788407391309,"data":{"e":"depthUpdate","E":1788407391514,"s":"BTCUSDT","U":99603310322,"u":99603310335,"b":[["69913.80000000","0.00432000"],["62145.60000000","0.00032000"]],"a":[["77682.00000000","0.79901000"],["77682.24000000","0.14099000"],["77683.44000000","0.17711000"],["77686.00000000","0.03007000"],["77696.17000000","0.00643000"],["77698.86000000","0.00000000"]]}}
{"type":"depth","received_at_ms":1788407391409,"data":{"e":"depthUpdate","E":1788407391614,"s":"BTCUSDT","U":99603310336,"u":99603310343,"b":[["77681.99000000","9.91045000"],["76516.76000000","0.00030000"],["69913.80000000","0.00448000"],["69913.79000000","0.00009000"],["62145.60000000","0.00000000"]],"a":[["77696.79000000","0.00202000"],["77720.21000000","0.00000000"]]}}
{"type":"depth","received_at_ms":1788407391509,"data":{"e":"depthUpdate","E":1788407391714,"s":"BTCUSDT","U":99603310344,"u":99603310352,"b":[["77678.39000000","0.04049000"],["77670.91000000","0.03923000"],["69913.80000000","0.00432000"]],"a":[["77686.85000000","0.00208000"],["77687.17000000","0.12364000"],["77759.68000000","0.00033000"]]}}
{"type":"depth","received_at_ms":1788407391610,"data":{"e":"depthUpdate","E":1788407391814,"s":"BTCUSDT","U":99603310353,"u":99603310360,"b":[["69913.80000000","0.00448000"],["69913.79000000","0.00000000"],["69913.78000000","0.00009000"],["62145.59000000","0.00020000"]],"a":[["77682.00000000","0.79737000"],["78847.23000000","0.00030000"]]}}
{"type":"depth","received_at_ms":1788407391708,"data":{"e":"depthUpdate","E":1788407391914,"s":"BTCUSDT","U":99603310361,"u":99603310368,"b":[["77667.67000000","0.00007000"],["69913.80000000","0.00432000"],["62145.59000000","0.00000000"]],"a":[["77698.76000000","0.00007000"],["77734.58000000","0.12878000"]]}}
{"type":"depth","received_at_ms":1788407391810,"data":{"e":"depthUpdate","E":1788407392015,"s":"BTCUSDT","U":99603310369,"u":99603310375,"b":[["69913.80000000","0.00448000"],["62145.60000000","0.00032000"]],"a":[["77733.99000000","0.00000000"],["77734.58000000","0.00000000"]]}}
{"type":"depth","received_at_ms":1788407391910,"data":{"e":"depthUpdate","E":1788407392114,"s":"BTCUSDT","U":99603310376,"u":99603310378,"b":[["69913.80000000","0.00432000"]],"a":[]}}
{"type":"depth","received_at_ms":1788407392009,"data":{"e":"depthUpdate","E":1788407392214,"s":"BTCUSDT","U":99603310379,"u":99603310383,"b":[["69913.80000000","0.00432000"],["62145.60000000","0.00000000"]],"a":[["77733.85000000","0.00000000"]]}}
{"type":"depth","received_at_ms":1788407392139,"data":{"e":"depthUpdate","E":1788407392314,"s":"BTCUSDT","U":99603310384,"u":99603310390,"b":[["77681.99000000","9.90786000"],["69913.80000000","0.00432000"],["69913.78000000","0.00000000"],["62146.00000000","0.00000000"]],"a":[["77732.56000000","0.12878000"]]}}
{"type":"depth","received_at_ms":1788407392209,"data":{"e":"depthUpdate","E":1788407392414,"s":"BTCUSDT","U":99603310391,"u":99603310395,"b":[["69913.80000000","0.00432000"]],"a":[["77732.56000000","0.00000000"]]}}
{"type":"depth","received_at_ms":1788407392309,"data":{"e":"depthUpdate","E":1788407392514,"s":"BTCUSDT","U":99603310396,"u":99603310397,"b":[["69913.80000000","0.00416000"],["62145.60000000","0.00032000"]],"a":[]}}
{"type":"depth","received_at_ms":1788407392409,"data":{"e":"depthUpdate","E":1788407392614,"s":"BTCUSDT","U":99603310398,"u":99603310405,"b":[["76516.76000000","0.00030000"],["69913.80000000","0.00432000"],["62145.60000000","0.00000000"]],"a":[["77682.00000000","0.79766000"]]}}
{"type":"depth","received_at_ms":1788407392510,"data":{"e":"depthUpdate","E":1788407392714,"s":"BTCUSDT","U":99603310406,"u":99603310408,"b":[["69913.80000000","0.00448000"]],"a":[]}}
{"type":"depth","received_at_ms":1788407392609,"data":{"e":"depthUpdate","E":1788407392814,"s":"BTCUSDT","U":99603310409,"u":99603310418,"b":[["69913.80000000","0.00416000"],["62146.00000000","0.00000000"]],"a":[["77689.41000000","0.00000000"],["77690.25000000","0.00000000"],["77733.54000000","0.00000000"],["78847.23000000","0.00030000"]]}}
{"type":"depth","received_at_ms":1788407392709,"data":{"e":"depthUpdate","E":1788407392914,"s":"BTCUSDT","U":99603310419,"u":99603310439,"b":[["77681.99000000","9.90747000"],["77667.67000000","0.00000000"],["69913.80000000","0.00448000"],["69913.79000000","0.00009000"],["62145.59000000","0.00000000"]],"a":[["77682.00000000","0.92605000"],["77698.76000000","0.00000000"],["77732.57000000","0.00000000"]]}}
{"type":"depth","received_at_ms":1788407392814,"data":{"e":"depthUpdate","E":1788407393018,"s":"BTCUSDT","U":99603310440,"u":99603310445,"b":[["77667.67000000","0.00007000"],["69913.80000000","0.00432000"],["62145.60000000","0.00032000"]],"a":[["77698.76000000","0.00007000"]]}}
{"type":"depth","received_at_ms":1788407392909,"data":{"e":"depthUpdate","E":1788407393114,"s":"BTCUSDT","U":99603310446,"u":99603310452,"b":[["69913.80000000","0.00432000"],["69913.79000000","0.00000000"],["69913.78000000","0.00009000"],["62146.00000000","0.00200000"]],"a":[["77682.00000000","0.79757000"]]}}
{"type":"depth","received_at_ms":1788407393010,"data":{"e":"depthUpdate","E":1788407393214,"s":"BTCUSDT","U":99603310453,"u":99603310456,"b":[["69913.80000000","0.00432000"],["62146.00000000","0.00000000"],["62145.60000000","0.00000000"]],"a":[]}}
{"type":"depth","received_at_ms":1788407393109,"data":{"e":"depthUpdate","E":1788407393314,"s":"BTCUSDT","U":99603310457,"u":99603310467,"b":[["77658.47000000","0.00000000"],["77635.06000000","0.00000000"],["69913.80000000","0.00448000"],["62146.00000000","0.00000000"]],"a":[["77682.00000000","0.92407000"],["77707.26000000","0.00000000"],["77730.58000000","0.00000000"]]}}
{"type":"depth","received_at_ms":1788407393209,"data":{"e":"depthUpdate","E":1788407393414,"s":"BTCUSDT","U":99603310468,"u":99603310472,"b":[["69913.80000000","0.00432000"]],"a":[["77682.00000000","0.92371000"],["77733.91000000","0.12878000"]]}}
{"type":"depth","received_at_ms":1788407393309,"data":{"e":"depthUpdate","E":1788407393514,"s":"BTCUSDT","U":99603310473,"u":99603310474,"b":[["69913.80000000","0.00448000"],["62145.60000000","0.00032000"]],"a":[]}}
{"type":"depth","received_at_ms":1788407393409,"data":{"e":"depthUpdate","E":1788407393614,"s":"BTCUSDT","U":99603310475,"u":99603310496,"b":[["77658.49000000","0.58616000"],["77635.19000000","0.98861000"],["77602.78000000","0.41642000"],["77601.61000000","0.72109000"],["77599.06000000","0.00000000"],["76516.76000000","0.00030000"],["69913.80000000","0.00432000"],["62146.00000000","0.00000000"],["62145.60000000","0.00000000"]],"a":[["77682.00000000","0.79721000"],["77694.47000000","0.00000000"],["77695.00000000","0.00400000"],["77708.05000000","0.50248000"],["77731.36000000","1.03061000"]]}}
{"type":"depth","received_at_ms":1788407393509,"data":{"e":"depthUpdate","E":1788407393714,"s":"BTCUSDT","U":99603310497,"u":99603310501,"b":[["69913.80000000","0.00432000"]],"a":[["77733.91000000","0.00000000"]]}}
{"type":"depth","received_at_ms":1788407393609,"data":{"e":"depthUpdate","E":1788407393814,"s":"BTCUSDT","U":99603310502,"u":99603310503,"b":[],"a":[["78847.23000000","0.00030000"]]}}
{"type":"depth","received_at_ms":1788407393709,"data":{"e":"depthUpdate","E":1788407393914,"s":"BTCUSDT","U":99603310504,"u":99603310513,"b":[["77642.09000000","0.91058000"],["75561.74000000","0.00000000"],["69913.80000000","0.00432000"],["62145.59000000","0.00000000"]],"a":[["81006.07000000","0.00000000"]]}}
{"type":"depth","received_at_ms":1788407393811,"data":{"e":"depthUpdate","E":1788407394016,"s":"BTCUSDT","U":99603310514,"u":99603310520,"b":[["77667.67000000","0.00007000"],["69913.80000000","0.00448000"],["62145.60000000","0.00032000"]],"a":[["77698.76000000","0.00007000"]]}}
{"type":"depth","received_at_ms":1788407393909,"data":{"e":"depthUpdate","E":1788407394114,"s":"BTCUSDT","U":99603310521,"u":99603310526,"b":[["77678.38000000","0.01342000"],["77602.78000000","0.26752000"],["77601.61000000","0.00000000"],["77599.06000000","0.72109000"],["69913.80000000","0.00432000"]],"a":[["77733.79000000","0.12878000"]]}}
{"type":"depth","received_at_ms":1788407394008,"data":{"e":"depthUpdate","E":1788407394214,"s":"BTCUSDT","U":99603310527,"u":99603310531,"b":[["69913.80000000","0.00448000"],["62145.60000000","0.00000000"]],"a":[["77733.79000000","0.00000000"]]}}
{"type":"depth","received_at_ms":1788407394109,"data":{"e":"depthUpdate","E":1788407394314,"s":"BTCUSDT","U":99603310532,"u":99603310542,"b":[["69913.80000000","0.00432000"],["62146.00000000","0.00000000"]],"a":[["77682.00000000","0.79721000"],["77689.40000000","0.00647000"],["77689.49000000","0.00528000"]]}}
{"type":"depth","received_at_ms":1788407394215,"data":{"e":"depthUpdate","E":1788407394414,"s":"BTCUSDT","U":99603310543,"u":99603310548,"b":[["69913.80000000","0.00432000"]],"a":[["77682.00000000","0.79721000"]]}}
{"type":"depth","received_at_ms":1788407394309,"data":{"e":"depthUpdate","E":1788407394514,"s":"BTCUSDT","U":99603310549,"u":99603310567,"b":[["77681.99000000","9.90181000"],["77681.51000000","0.00000000"],["77681.02000000","0.00400000"],["77659.75000000","0.00000000"],["69913.80000000","0.00432000"],["69913.78000000","0.00000000"],["62145.60000000","0.00032000"]],"a":[["77682.00000000","1.11393000"],["77687.77000000","0.02896000"],["77687.91000000","0.00000000"],["77693.23000000","0.00000000"],["77733.64000000","0.00000000"]]}}
{"type":"depth","received_at_ms":1788407394409,"data":{"e":"depthUpdate","E":1788407394614,"s":"BTCUSDT","U":99603310568,"u":99603310589,"b":[["77681.99000000","9.90181000"],["77681.98000000","0.00070000"],["77681.39000000","0.09138000"],["77674.90000000","0.01600000"],["77672.79000000","0.00000000"],["77658.00000000","0.03200000"],["76516.76000000","0.00030000"],["69913.80000000","0.00448000"],["62146.00000000","0.00200000"],["62145.60000000","0.00000000"]],"a":[["77687.20000000","0.00000000"],["77687.33000000","0.00000000"],["77687.43000000","0.00000000"],["77691.49000000","0.00400000"],["77733.39000000","0.00000000"]]}}
{"type":"depth","received_at_ms":1788407394510,"data":{"e":"depthUpdate","E":1788407394714,"s":"BTCUSDT","U":99603310590,"u":99603310600,"b":[["77674.91000000","0.00200000"],["77601.61000000","0.72109000"],["77599.06000000","0.00000000"],["77000.00000000","7.58685000"],["69913.80000000","0.00416000"],["62146.00000000","0.00000000"]],"a":[]}}
{"type":"depth","received_at_ms":1788407394609,"data":{"e":"depthUpdate","E":1788407394814,"s":"BTCUSDT","U":99603310601,"u":99603310604,"b":[["69913.80000000","0.00448000"]],"a":[["78847.23000000","0.00030000"]]}}
{"type":"depth","received_at_ms":1788407394709,"data":{"e":"depthUpdate","E":1788407394914,"s":"BTCUSDT","U":99603310605,"u":99603310626,"b":[["77681.99000000","9.90173000"],["77602.78000000","0.41171000"],["75561.74000000","0.00010000"],["69913.80000000","0.00441000"],["62145.59000000","0.00000000"]],"a":[["77682.00000000","1.11141000"],["77682.24000000","0.14106000"],["77683.44000000","0.17718000"],["77686.00000000","0.03000000"],["77734.36000000","0.12878000"]]}}
{"type":"depth","received_at_ms":1788407394810,"data":{"e":"depthUpdate","E":1788407395014,"s":"BTCUSDT","U":99603310627,"u":99603310633,"b":[["77667.67000000","0.00007000"],["69913.80000000","0.00457000"],["62145.60000000","0.00032000"]],"a":[["77698.76000000","0.00007000"]]}}
{"type":"depth","received_at_ms":1788407394909,"data":{"e":"depthUpdate","E":1788407395114,"s":"BTCUSDT","U":99603310634,"u":99603310641,"b":[["77591.97000000","0.00000000"],["76890.40000000","0.00000000"],["69913.80000000","0.00441000"]],"a":[["77749.62000000","0.00000000"],["77799.64000000","0.00000000"],["81006.07000000","0.00010000"]]}}
{"type":"depth","received_at_ms":1788407395012,"data":{"e":"depthUpdate","E":1788407395216,"s":"BTCUSDT","U":99603310642,"u":99603310675,"b":[["77681.99000000","9.90039000"],["77681.98000000","0.00063000"],["77681.39000000","0.09131000"],["77681.07000000","0.00000000"],["77681.02000000","0.00000000"],["77680.76000000","0.00127000"],["77680.74000000","0.01705000"],["77680.42000000","0.00000000"],["77680.39000000","0.00400000"],["77680.22000000","0.00643000"],["77678.74000000","0.00257000"],["77674.91000000","0.00000000"],["77672.79000000","0.00000000"],["77621.01000000","0.06509000"],["69913.80000000","0.00441000"],["62145.60000000","0.00000000"]],"a":[["77693.38000000","0.31266000"],["77694.26000000","0.00257000"],["77695.00000000","0.00000000"],["77695.52000000","0.00200000"],["77695.95000000","0.00000000"],["77697.25000000","0.00800000"],["77752.43000000","0.06506000"]]}}
{"type":"depth","received_at_ms":1788407395109,"data":{"e":"depthUpdate","E":1788407395314,"s":"BTCUSDT","U":99603310676,"u":99603310695,"b":[["77681.99000000","9.89403000"],["77681.98000000","0.00070000"],["77681.39000000","0.09131000"],["77680.77000000","0.00643000"],["77680.74000000","0.01705000"],["77674.91000000","0.00000000"],["77672.79000000","0.00200000"],["69913.80000000","0.00457000"],["62146.00000000","0.00000000"]],"a":[["77695.52000000","0.00000000"]]}}
{"type":"depth","received_at_ms":1788407395210,"data":{"e":"depthUpdate","E":1788407395414,"s":"BTCUSDT","U":99603310696,"u":99603310721,"b":[["77681.99000000","9.89411000"],["77681.39000000","0.09131000"],["77680.77000000","0.00657000"],["77679.50000000","0.02021000"],["77674.91000000","0.00200000"],["77672.79000000","0.00000000"],["77602.78000000","0.03685000"],["77601.61000000","0.00000000"],["77599.06000000","0.72109000"],["69913.80000000","0.00457000"]],"a":[["77682.00000000","0.79476000"],["77691.49000000","0.00000000"],["77691.98000000","0.00400000"],["77693.38000000","0.30866000"],["77694.01000000","0.00400000"]]}}
{"type":"depth","received_at_ms":1788407395309,"data":{"e":"depthUpdate","E":1788407395514,"s":"BTCUSDT","U":99603310722,"u":99603310726,"b":[["69913.80000000","0.00473000"],["62145.60000000","0.00032000"]],"a":[["77696.17000000","0.00843000"]]}}
{"type":"depth","received_at_ms":1788407395409,"data":{"e":"depthUpdate","E":1788407395614,"s":"BTCUSDT","U":99603310727,"u":99603310737,"b":[["77681.99000000","9.90047000"],["77681.98000000","0.00063000"],["77680.77000000","0.00014000"],["77671.56000000","0.00000000"],["77632.71000000","0.00000000"],["77613.28000000","0.00000000"],["69913.80000000","0.00457000"],["62145.60000000","0.00000000"]],"a":[["77694.01000000","0.00000000"],["77694.58000000","0.00400000"],["77695.75000000","0.26711000"],["77697.19000000","0.00000000"],["77716.62000000","0.00000000"],["77736.04000000","0.00000000"]]}}
{"type":"depth","received_at_ms":1788407395509,"data":{"e":"depthUpdate","E":1788407395714,"s":"BTCUSDT","U":99603310738,"u":99603310761,"b":[["77681.39000000","0.09131000"],["77680.77000000","0.00000000"],["77680.22000000","0.00657000"],["76516.76000000","0.00030000"],["74100.00000000","3.91336000"],["69913.80000000","0.00473000"]],"a":[["77682.00000000","0.81713000"],["77693.35000000","0.71407000"],["77693.36000000","1.11223000"],["77693.37000000","0.00000000"],["77698.06000000","0.00000000"],["77712.00000000","0.73265000"],["77714.00000000","0.03000000"],["77734.36000000","0.00000000"]]}}
{"type":"depth","received_at_ms":1788407395609,"data":{"e":"depthUpdate","E":1788407395814,"s":"BTCUSDT","U":99603310762,"u":99603310780,"b":[["69913.80000000","0.00457000"],["62146.00000000","0.00000000"]],"a":[["77682.00000000","0.81713000"],["77693.34000000","0.00200000"],["77696.17000000","0.00643000"],["77696.58000000","0.00000000"],["77697.25000000","0.00000000"],["77698.12000000","0.01200000"],["78847.23000000","0.00030000"]]}}
{"type":"depth","received_at_ms":1788407395709,"data":{"e":"depthUpdate","E":1788407395914,"s":"BTCUSDT","U":99603310781,"u":99603310787,"b":[["69913.80000000","0.00473000"],["62145.59000000","0.00000000"]],"a":[]}}
{"type":"depth","received_at_ms":1788407395810,"data":{"e":"depthUpdate","E":1788407396015,"s":"BTCUSDT","U":99603310788,"u":99603310796,"b":[["77667.67000000","0.00007000"],["77666.89000000","0.02007000"],["77602.78000000","0.22596000"],["77475.35000000","0.00000000"],["77474.76000000","0.00812000"],["69913.80000000","0.00441000"],["62145.60000000","0.00032000"]],"a":[["77698.76000000","0.00007000"]]}}
{"type":"depth","received_at_ms":1788407395910,"data":{"e":"depthUpdate","E":1788407396115,"s":"BTCUSDT","U":99603310797,"u":99603310804,"b":[["77681.99000000","9.86829000"],["77505.17000000","0.00039000"],["69913.80000000","0.00464000"],["69913.79000000","0.00009000"],["62146.00000000","0.00200000"]],"a":[["77682.00000000","0.80613000"],["77860.54000000","0.00000000"]]}}
{"type":"depth","received_at_ms":1788407396009,"data":{"e":"depthUpdate","E":1788407396214,"s":"BTCUSDT","U":99603310805,"u":99603310810,"b":[["77681.99000000","9.90047000"],["69913.80000000","0.00448000"],["62146.00000000","0.00000000"],["62145.60000000","0.00000000"]],"a":[]}}
{"type":"depth","received_at_ms":1788407396110,"data":{"e":"depthUpdate","E":1788407396315,"s":"BTCUSDT","U":99603310811,"u":99603310822,"b":[["77672.12000000","0.02200000"],["77633.27000000","0.02200000"],["69913.80000000","0.00448000"],["62146.00000000","0.00000000"]],"a":[["77682.00000000","0.97444000"],["77695.36000000","0.02000000"],["77714.79000000","0.02008000"],["77733.82000000","0.12878000"]]}}
{"type":"depth","received_at_ms":1788407396209,"data":{"e":"depthUpdate","E":1788407396414,"s":"BTCUSDT","U":99603310823,"u":99603310837,"b":[["77504.50000000","4.50566000"],["71467.43000000","0.00014000"],["69913.80000000","0.00448000"],["62146.00000000","0.00000000"],["50000.00000000","488.57738000"]],"a":[["77682.00000000","1.11359000"],["77694.26000000","0.00000000"],["77694.27000000","0.00257000"],["77733.82000000","0.00000000"],["77733.91000000","0.00000000"],["77861.33000000","4.45326000"]]}}
{"type":"depth","received_at_ms":1788407396309,"data":{"e":"depthUpdate","E":1788407396514,"s":"BTCUSDT","U":99603310838,"u":99603310848,"b":[["77680.29000000","0.00257000"],["77678.74000000","0.00000000"],["77671.50000000","0.00000000"],["77632.64000000","0.00000000"],["77613.21000000","0.00000000"],["69913.80000000","0.00464000"],["62145.60000000","0.00032000"]],"a":[["77697.16000000","0.00000000"],["77716.59000000","0.00000000"],["77733.97000000","0.00000000"],["77734.11000000","0.00000000"],["77736.01000000","0.00000000"]]}}
{"type":"depth","received_at_ms":1788407396409,"data":{"e":"depthUpdate","E":1788407396614,"s":"BTCUSDT","U":99603310849,"u":99603310903,"b":[["77681.99000000","9.08011000"],["77681.98000000","0.00070000"],["77680.22000000","0.00014000"],["77677.63000000","0.00000000"],["77676.96000000","0.00000000"],["77674.91000000","0.00000000"],["77674.90000000","0.01200000"],["77674.89000000","0.00000000"],["77672.79000000","0.00200000"],["77672.33000000","0.00811000"],["77672.32000000","0.00000000"],["69913.80000000","0.00448000"],["69913.79000000","0.00000000"],["62146.00000000","0.00000000"],["62145.60000000","0.00000000"]],"a":[["77682.00000000","1.92320000"],["77686.85000000","0.00000000"],["77694.96000000","0.00000000"],["77695.53000000","0.00000000"],["77697.26000000","0.00000000"],["77734.01000000","0.00000000"]]}}
{"type":"depth","received_at_ms":1788407396509,"data":{"e":"depthUpdate","E":1788407396714,"s":"BTCUSDT","U":99603310904,"u":99603310946,"b":[["77681.99000000","9.08018000"],["77681.98000000","0.00070000"],["77680.77000000","0.00643000"],["77680.74000000","0.01698000"],["77680.22000000","0.00000000"],["77679.84000000","0.00643000"],["77679.50000000","0.02035000"],["77676.22000000","0.00400000"],["77674.91000000","0.00800000"],["77672.32000000","0.08642000"],["77577.33000000","0.00000000"],["77567.52000000","0.00108000"],["76516.76000000","0.00030000"],["69913.80000000","0.00448000"]],"a":[["77682.00000000","1.92383000"],["77684.77000000","0.03183000"],["77687.27000000","0.00528000"],["77690.49000000","0.00000000"],["77723.18000000","0.08784000"],["77733.89000000","0.00000000"],["77733.94000000","0.00007000"],["77734.09000000","0.00000000"],["77734.30000000","0.12878000"]]}}
{"type":"depth","received_at_ms":1788407396608,"data":{"e":"depthUpdate","E":1788407396814,"s":"BTCUSDT","U":99603310947,"u":99603310961,"b":[["77681.39000000","0.09131000"],["77680.77000000","0.00657000"],["77679.99000000","0.22570000"],["77679.50000000","0.02021000"],["69913.80000000","0.00448000"]],"a":[["77734.30000000","0.00000000"]]}}
{"type":"depth","received_at_ms":1788407396709,"data":{"e":"depthUpdate","E":1788407396914,"s":"BTCUSDT","U":99603310962,"u":99603310977,"b":[["77681.99000000","9.07974000"],["69913.80000000","0.00448000"],["69913.79000000","0.00009000"]],"a":[["77682.00000000","1.75513000"],["77733.51000000","0.00000000"],["77734.09000000","0.00000000"],["78847.23000000","0.00030000"]]}}
{"type":"depth","received_at_ms":1788407396813,"data":{"e":"depthUpdate","E":1788407397017,"s":"BTCUSDT","U":99603310978,"u":99603311001,"b":[["77680.39000000","0.00000000"],["77679.85000000","0.00400000"],["77674.91000000","0.00400000"],["77674.90000000","0.00000000"],["77673.66000000","0.01600000"],["77672.08000000","0.02010000"],["77667.67000000","0.00000000"],["77633.23000000","0.02000000"],["71467.43000000","0.00000000"],["69913.80000000","0.00464000"],["62146.00000000","0.00000000"],["62145.60000000","0.00032000"],["62145.59000000","0.00000000"]],"a":[["77695.38000000","0.02008000"],["77698.76000000","0.00000000"],["77714.81000000","0.02000000"]]}}
{"type":"depth","received_at_ms":1788407396909,"data":{"e":"depthUpdate","E":1788407397114,"s":"BTCUSDT","U":99603311002,"u":99603311010,"b":[["77681.99000000","9.07974000"],["77681.98000000","0.00063000"],["77667.67000000","0.00007000"],["69913.80000000","0.00448000"]],"a":[["77698.76000000","0.00007000"],["77733.89000000","0.12878000"]]}}
{"type":"depth","received_at_ms":1788407397009,"data":{"e":"depthUpdate","E":1788407397214,"s":"BTCUSDT","U":99603311011,"u":99603311016,"b":[["69913.80000000","0.00464000"],["62145.60000000","0.00000000"]],"a":[["77733.89000000","0.00000000"],["77734.17000000","0.12878000"]]}}
{"type":"depth","received_at_ms":1788407397114,"data":{"e":"depthUpdate","E":1788407397317,"s":"BTCUSDT","U":99603311017,"u":99603311023,"b":[["77613.84000000","0.02200000"],["69913.80000000","0.00448000"],["62146.00000000","0.00000000"]],"a":[["77687.27000000","0.00000000"],["77734.17000000","0.00000000"],["77734.22000000","0.02000000"]]}}
{"type":"depth","received_at_ms":1788407397208,"data":{"e":"depthUpdate","E":1788407397414,"s":"BTCUSDT","U":99603311024,"u":99603311032,"b":[["77681.99000000","9.07715000"],["69913.80000000","0.00464000"],["69913.79000000","0.00000000"],["69913.78000000","0.00009000"],["62146.00000000","0.00000000"]],"a":[]}}
{"type":"depth","received_at_ms":1788407397309,"data":{"e":"depthUpdate","E":1788407397514,"s":"BTCUSDT","U":99603311033,"u":99603311038,"b":[["77671.44000000","0.00000000"],["77632.58000000","0.00000000"],["77613.15000000","0.00000000"],["69913.80000000","0.00448000"],["62145.60000000","0.00032000"]],"a":[["77682.00000000","1.75499000"],["77697.06000000","0.00000000"],["77716.49000000","0.02400000"],["77735.92000000","0.00000000"]]}}
{"type":"depth","received_at_ms":1788407397409,"data":{"e":"depthUpdate","E":1788407397614,"s":"BTCUSDT","U":99603311039,"u":99603311049,"b":[["77681.99000000","9.07723000"],["77668.01000000","0.13365000"],["77665.30000000","0.27614000"],["73159.29000000","0.00683000"],["69913.80000000","0.00464000"],["62145.60000000","0.00000000"]],"a":[["77682.00000000","1.92354000"],["77702.81000000","0.28034000"],["77706.47000000","0.64389000"],["77730.67000000","0.00000000"]]}}
{"type":"depth","received_at_ms":1788407397509,"data":{"e":"depthUpdate","E":1788407397714,"s":"BTCUSDT","U":99603311050,"u":99603311058,"b":[["77670.91000000","0.00000000"],["77527.30000000","0.02016000"],["77513.76000000","0.00000000"],["76516.76000000","0.00030000"],["69913.80000000","0.00448000"]],"a":[["77682.00000000","1.89182000"]]}}
{"type":"depth","received_at_ms":1788407397609,"data":{"e":"depthUpdate","E":1788407397814,"s":"BTCUSDT","U":99603311059,"u":99603311074,"b":[["77681.99000000","9.20287000"],["77672.07000000","0.02000000"],["77633.21000000","0.02000000"],["69913.80000000","0.00464000"]],"a":[["77682.00000000","1.89197000"],["77685.84000000","0.17282000"],["77694.27000000","0.00000000"],["77694.28000000","0.00257000"],["77695.34000000","0.04000000"],["77714.76000000","0.02000000"]]}}
{"type":"depth","received_at_ms":1788407397708,"data":{"e":"depthUpdate","E":1788407397914,"s":"BTCUSDT","U":99603311075,"u":99603311081,"b":[["77667.60000000","0.09281000"],["69913.80000000","0.00432000"],["69913.78000000","0.00000000"]],"a":[["77682.00000000","1.88974000"],["78847.23000000","0.00030000"]]}}
{"type":"depth","received_at_ms":1788407397809,"data":{"e":"depthUpdate","E":1788407398014,"s":"BTCUSDT","U":99603311082,"u":99603311091,"b":[["77613.80000000","0.02000000"],["69913.80000000","0.00464000"],["62145.60000000","0.00032000"],["62145.59000000","0.00000000"]],"a":[["77686.96000000","0.00520000"],["77734.24000000","0.02000000"]]}}
{"type":"depth","received_at_ms":1788407397908,"data":{"e":"depthUpdate","E":1788407398114,"s":"BTCUSDT","U":99603311092,"u":99603311106,"b":[["77673.67000000","0.00000000"],["77672.79000000","0.00000000"],["77672.33000000","0.01011000"],["77667.67000000","0.00007000"],["77293.58000000","0.00007000"],["69913.80000000","0.00448000"]],"a":[["77686.96000000","0.00000000"],["77687.02000000","0.00526000"],["77690.57000000","0.00400000"],["77691.98000000","0.00000000"],["77698.76000000","0.00007000"]]}}
{"type":"depth","received_at_ms":1788407398009,"data":{"e":"depthUpdate","E":1788407398214,"s":"BTCUSDT","U":99603311107,"u":99603311114,"b":[["69913.80000000","0.00432000"],["62145.60000000","0.00000000"]],"a":[["77734.02000000","0.00008000"],["77734.19000000","0.00000000"]]}}
{"type":"depth","received_at_ms":1788407398109,"data":{"e":"depthUpdate","E":1788407398314,"s":"BTCUSDT","U":99603311115,"u":99603311121,"b":[["69913.80000000","0.00448000"],["62146.00000000","0.00000000"]],"a":[["77733.92000000","0.00000000"],["77734.23000000","0.00000000"]]}}
{"type":"depth","received_at_ms":1788407398210,"data":{"e":"depthUpdate","E":1788407398415,"s":"BTCUSDT","U":99603311122,"u":99603311130,"b":[["69913.80000000","0.00457000"]],"a":[["77682.00000000","1.88928000"],["77734.38000000","0.12878000"],["77734.49000000","0.00000000"]]}}
{"type":"depth","received_at_ms":1788407398309,"data":{"e":"depthUpdate","E":1788407398514,"s":"BTCUSDT","U":99603311131,"u":99603311142,"b":[["77672.16000000","0.00000000"],["77633.31000000","0.00051000"],["77613.88000000","0.00000000"],["69913.80000000","0.00473000"],["62145.60000000","0.00032000"]],"a":[["77687.02000000","0.00000000"],["77696.18000000","0.00000000"],["77715.61000000","0.00000000"],["77733.98000000","0.00000000"],["77734.30000000","0.00000000"],["77734.38000000","0.00000000"],["77734.53000000","0.12878000"],["77735.04000000","0.00000000"]]}}
{"type":"depth","received_at_ms":1788407398409,"data":{"e":"depthUpdate","E":1788407398614,"s":"BTCUSDT","U":99603311143,"u":99603311145,"b":[["69913.80000000","0.00457000"],["62145.60000000","0.00000000"]],"a":[["77734.53000000","0.00000000"]]}}
{"type":"depth","received_at_ms":1788407398509,"data":{"e":"depthUpdate","E":1788407398714,"s":"BTCUSDT","U":99603311146,"u":99603311157,"b":[["77673.67000000","0.00200000"],["77672.33000000","0.00811000"],["76516.76000000","0.00030000"],["69913.80000000","0.00457000"]],"a":[["77690.57000000","0.00000000"],["77691.06000000","0.00400000"],["77734.68000000","0.00000000"]]}}
{"type":"depth","received_at_ms":1788407398609,"data":{"e":"depthUpdate","E":1788407398814,"s":"BTCUSDT","U":99603311158,"u":99603311167,"b":[["77613.79000000","0.02000000"],["69913.80000000","0.00432000"],["69913.79000000","0.00009000"],["62146.00000000","0.00000000"]],"a":[["77682.00000000","1.88892000"],["77686.91000000","0.00522000"],["77734.19000000","0.02000000"]]}}
{"type":"depth","received_at_ms":1788407398708,"data":{"e":"depthUpdate","E":1788407398914,"s":"BTCUSDT","U":99603311168,"u":99603311186,"b":[["77681.99000000","9.20295000"],["77672.84000000","0.02000000"],["77633.99000000","0.02043000"],["69913.80000000","0.00448000"]],"a":[["77682.00000000","1.88891000"],["77686.91000000","0.00000000"],["77686.97000000","0.00539000"],["77690.44000000","0.00000000"],["77693.16000000","0.00400000"],["77694.51000000","0.02000000"],["77694.58000000","0.00000000"],["77713.94000000","0.02000000"],["77736.05000000","0.12878000"],["78847.23000000","0.00030000"]]}}
{"type":"depth","received_at_ms":1788407398808,"data":{"e":"depthUpdate","E":1788407399014,"s":"BTCUSDT","U":99603311187,"u":99603311200,"b":[["69913.80000000","0.00432000"],["62145.60000000","0.00032000"],["62145.59000000","0.00000000"]],"a":[["77682.00000000","1.88844000"],["77685.49000000","0.00000000"],["77736.05000000","0.00000000"]]}}
{"type":"depth","received_at_ms":1788407398909,"data":{"e":"depthUpdate","E":1788407399114,"s":"BTCUSDT","U":99603311201,"u":99603311210,"b":[["77667.67000000","0.00007000"],["77293.58000000","0.00000000"],["69913.80000000","0.00448000"],["62146.00000000","0.00200000"]],"a":[["77682.00000000","1.88544000"],["77690.46000000","0.00047000"],["77698.76000000","0.00007000"]]}}
{"type":"depth","received_at_ms":1788407399010,"data":{"e":"depthUpdate","E":1788407399214,"s":"BTCUSDT","U":99603311211,"u":99603311216,"b":[["69913.80000000","0.00432000"],["62146.00000000","0.00000000"],["62145.60000000","0.00000000"]],"a":[["77682.00000000","1.88591000"],["77686.97000000","0.00000000"],["77690.46000000","0.00000000"]]}}
{"type":"depth","received_at_ms":1788407399109,"data":{"e":"depthUpdate","E":1788407399314,"s":"BTCUSDT","U":99603311217,"u":99603311222,"b":[["69913.80000000","0.00448000"],["62146.00000000","0.00000000"]],"a":[["79700.00000000","4.69371000"]]}}
{"type":"depth","received_at_ms":1788407399210,"data":{"e":"depthUpdate","E":1788407399414,"s":"BTCUSDT","U":99603311223,"u":99603311229,"b":[["77673.67000000","0.00200000"],["77672.85000000","0.00000000"],["69913.80000000","0.00432000"]],"a":[]}}
{"type":"depth","received_at_ms":1788407399309,"data":{"e":"depthUpdate","E":1788407399514,"s":"BTCUSDT","U":99603311230,"u":99603311233,"b":[["69913.80000000","0.00432000"],["62145.60000000","0.00032000"]],"a":[["77686.73000000","0.00534000"]]}}
{"type":"depth","received_at_ms":1788407399409,"data":{"e":"depthUpdate","E":1788407399614,"s":"BTCUSDT","U":99603311234,"u":99603311240,"b":[["69913.80000000","0.00432000"],["62146.00000000","0.00200000"],["62145.60000000","0.00000000"]],"a":[["77736.08000000","0.12878000"]]}}
{"type":"depth","received_at_ms":1788407399508,"data":{"e":"depthUpdate","E":1788407399714,"s":"BTCUSDT","U":99603311241,"u":99603311250,"b":[["76516.76000000","0.00030000"],["69913.80000000","0.00432000"],["62146.00000000","0.00000000"]],"a":[["77736.08000000","0.00000000"],["77736.47000000","0.00000000"]]}}
{"type":"depth","received_at_ms":1788407399609,"data":{"e":"depthUpdate","E":1788407399814,"s":"BTCUSDT","U":99603311251,"u":99603311255,"b":[["77681.99000000","9.20095000"],["77673.67000000","0.00000000"],["77672.85000000","0.00200000"],["69913.80000000","0.00416000"],["69913.79000000","0.00000000"]],"a":[]}}
{"type":"depth","received_at_ms":1788407399709,"data":{"e":"depthUpdate","E":1788407399914,"s":"BTCUSDT","U":99603311256,"u":99603311270,"b":[["77673.67000000","0.00000000"],["77672.86000000","0.00000000"],["77672.85000000","0.00000000"],["77672.79000000","0.00200000"],["77614.56000000","0.02000000"],["69913.80000000","0.00432000"],["62146.00000000","0.00000000"]],"a":[["77733.36000000","0.02000000"],["78847.23000000","0.00030000"]]}}
{"type":"depth","received_at_ms":1788407399809,"data":{"e":"depthUpdate","E":1788407400014,"s":"BTCUSDT","U":99603311271,"u":99603311300,"b":[["77676.22000000","0.00000000"],["77676.18000000","0.00400000"],["77674.91000000","0.00000000"],["77674.89000000","0.00400000"],["77673.67000000","0.00000000"],["77672.85000000","0.00200000"],["77672.80000000","0.00000000"],["77672.79000000","0.00000000"],["77664.61000000","0.25755000"],["77663.18000000","0.00000000"],["77660.41000000","0.44169000"],["77653.52000000","0.00000000"],["77507.36000000","0.00000000"],["75561.74000000","0.00000000"],["69913.80000000","0.00448000"],["62145.60000000","0.00032000"],["62145.59000000","0.00000000"]],"a":[["77696.89000000","0.00400000"],["77699.46000000","0.00000000"],["77707.49000000","0.25768000"],["77711.17000000","0.00000000"],["81006.07000000","0.00000000"],["86422.88000000","0.22692000"]]}}
{"type":"depth","received_at_ms":1788407399909,"data":{"e":"depthUpdate","E":1788407400114,"s":"BTCUSDT","U":99603311301,"u":99603311315,"b":[["77672.86000000","0.00000000"],["77672.85000000","0.00200000"],["77667.67000000","0.00007000"],["77513.35000000","0.00025000"],["69913.80000000","0.00432000"]],"a":[["77682.00000000","1.88544000"],["77686.73000000","0.00000000"],["77698.76000000","0.00007000"],["77720.52000000","0.00000000"],["86422.88000000","0.24583000"]]}}
{"type":"depth","received_at_ms":1788407400015,"data":{"e":"depthUpdate","E":1788407400214,"s":"BTCUSDT","U":99603311316,"u":99603311325,"b":[["77681.99000000","9.20047000"],["77673.67000000","0.00200000"],["77672.86000000","0.00000000"],["77672.85000000","0.00000000"],["77626.58000000","0.00000000"],["77331.89000000","0.00000000"],["69913.80000000","0.00448000"],["62145.60000000","0.00000000"]],"a":[["77682.00000000","1.88544000"],["77690.45000000","0.00000000"],["77727.16000000","0.00000000"],["77918.17000000","0.00000000"]]}}
{"type":"depth","received_at_ms":1788407400109,"data":{"e":"depthUpdate","E":1788407400314,"s":"BTCUSDT","U":99603311326,"u":99603311333,"b":[["69913.80000000","0.00432000"],["62146.00000000","0.00000000"]],"a":[["77682.00000000","1.88555000"],["84202.54000000","0.01768000"]]}}
{"type":"depth","received_at_ms":1788407400209,"data":{"e":"depthUpdate","E":1788407400414,"s":"BTCUSDT","U":99603311334,"u":99603311351,"b":[["77681.99000000","9.10698000"],["77673.67000000","0.00000000"],["77672.85000000","0.00200000"],["77631.71000000","0.00000000"],["69913.80000000","0.00448000"],["69913.79000000","0.00009000"]],"a":[["77682.00000000","1.88296000"],["77686.69000000","0.00000000"],["77686.71000000","0.00000000"],["77686.78000000","0.00526000"]]}}
{"type":"depth","received_at_ms":1788407400309,"data":{"e":"depthUpdate","E":1788407400514,"s":"BTCUSDT","U":99603311352,"u":99603311360,"b":[["77673.67000000","0.00200000"],["77672.85000000","0.00000000"],["77672.79000000","0.00000000"],["69913.80000000","0.00432000"],["62145.60000000","0.00032000"]],"a":[["77716.49000000","0.00000000"]]}}
{"type":"depth","received_at_ms":1788407400409,"data":{"e":"depthUpdate","E":1788407400614,"s":"BTCUSDT","U":99603311361,"u":99603311368,"b":[["77673.67000000","0.00000000"],["77672.85000000","0.00200000"],["77672.79000000","0.00000000"],["69913.80000000","0.00448000"],["62145.60000000","0.00000000"]],"a":[]}}
{"type":"depth","received_at_ms":1788407400510,"data":{"e":"depthUpdate","E":1788407400714,"s":"BTCUSDT","U":99603311369,"u":99603311380,"b":[["77672.85000000","0.00000000"],["77672.79000000","0.00200000"],["76516.76000000","0.00030000"],["69913.80000000","0.00432000"],["62146.00000000","0.00000000"]],"a":[["77734.73000000","0.00000000"],["77734.82000000","0.12878000"]]}}
{"type":"depth","received_at_ms":1788407400611,"data":{"e":"depthUpdate","E":1788407400814,"s":"BTCUSDT","U":99603311381,"u":99603311388,"b":[["77681.99000000","9.10827000"],["69913.80000000","0.00448000"],["69913.79000000","0.00000000"],["69913.78000000","0.00009000"]],"a":[["77682.00000000","1.76751000"],["77715.76000000","0.00000000"],["77734.82000000","0.00000000"],["77735.10000000","0.00000000"]]}}
{"type":"depth","received_at_ms":1788407400711,"data":{"e":"depthUpdate","E":1788407400914,"s":"BTCUSDT","U":99603311389,"u":99603311399,"b":[["77681.99000000","9.10690000"],["77655.71000000","0.00200000"],["69913.80000000","0.00432000"]],"a":[["77685.26000000","0.00658000"],["78847.23000000","0.00030000"]]}}
{"type":"depth","received_at_ms":1788407400809,"data":{"e":"depthUpdate","E":1788407401014,"s":"BTCUSDT","U":99603311400,"u":99603311417,"b":[["77680.29000000","0.00000000"],["77679.52000000","0.00257000"],["69913.80000000","0.00448000"],["62145.60000000","0.00032000"],["62145.59000000","0.00020000"]],"a":[["77682.00000000","1.76758000"],["77685.06000000","0.32214000"],["77685.26000000","0.00672000"],["77685.84000000","0.17268000"]]}}
