{"type":"snapshot","received_at_ms":1788333138649,"data":{"lastUpdateId":99556309913,"bids":[["77708.39000000","1.95604000"],["77708.38000000","0.00138000"],["77708.37000000","0.00119000"],["77708.36000000","0.05868000"],["77708.35000000","0.05014000"],["77708.31000000","0.00014000"],["77708.30000000","0.05014000"],["77707.50000000","0.00400000"],["77707.17000000","0.00014000"],["77707.16000000","0.00014000"],["77707.15000000","0.01664000"],["77707.11000000","0.00007000"],["77706.57000000","0.00024000"],["77706.34000000","0.00014000"],["77705.92000000","0.00014000"],["77705.91000000","0.01993000"],["77705.71000000","0.01330000"],["77705.55000000","0.00400000"],["77705.05000000","0.00180000"],["77705.04000000","0.04014000"],["77704.80000000","0.00167000"],["77704.68000000","0.00014000"],["77704.66000000","0.02007000"],["77704.29000000","0.10000000"],["77704.28000000","0.10272000"],["77704.24000000","0.00008000"],["77704.00000000","0.00007000"],["77703.77000000","0.00257000"],["77703.61000000","0.00255000"],["77703.60000000","0.00400000"],["77703.55000000","0.00643000"],["77703.54000000","0.00007000"],["77703.20000000","0.00044000"],["77703.09000000","0.00400000"],["77702.95000000","0.11048000"],["77702.58000000","0.00013000"],["77702.31000000","0.00180000"],["77702.30000000","0.00007000"],["77702.14000000","0.00010000"],["77701.65000000","0.00400000"],["77701.62000000","0.11055000"],["77700.89000000","0.00643000"],["77700.88000000","0.00008000"],["77700.74000000","0.00021000"],["77700.63000000","0.00008000"],["77700.61000000","0.00012000"],["77700.55000000","0.00200000"],["77700.54000000","0.00321000"],["77700.50000000","0.02895000"],["77700.42000000","0.00007000"],["77700.31000000","0.11048000"],["77700.00000000","0.00007000"],["77699.93000000","0.00027000"],["77699.70000000","0.00400000"],["77699.57000000","1.09442000"],["77699.56000000","1.93226000"],["77699.36000000","0.00008000"],["77699.24000000","0.00121000"],["77699.19000000","0.00007000"],["77698.89000000","1.31471000"],["77698.44000000","0.00008000"],["77698.43000000","0.16870000"],["77697.95000000","0.00007000"],["77697.83000000","0.00007000"],["77697.75000000","0.00400000"],["77697.66000000","0.00115000"],["77697.51000000","0.00400000"],["77697.50000000","0.12870000"],["77696.81000000","0.00800000"],["77696.80000000","0.00014000"],["77696.21000000","1.02862000"],["77696.08000000","0.00007000"],["77696.00000000","0.00265000"],["77695.80000000","0.00400000"],["77695.64000000","0.00039000"],["77695.15000000","0.00007000"],["77695.08000000","0.02000000"],["77694.89000000","0.37338000"],["77694.88000000","1.31471000"],["77694.48000000","0.00008000"],["77694.42000000","0.00010000"],["77694.30000000","0.01000000"],["77694.01000000","0.00483000"],["77694.00000000","0.03000000"],["77693.85000000","0.00442000"],["77693.59000000","0.00007000"],["77693.33000000","1.93226000"],["77693.12000000","0.00808000"],["77693.11000000","0.74631000"],["77693.10000000","0.06000000"],["77692.88000000","0.02000000"],["77692.86000000","0.00022000"],["77692.84000000","0.00012000"],["77692.53000000","0.00007000"],["77692.45000000","0.02000000"],["77692.37000000","0.04000000"],["77692.35000000","0.00007000"],["77692.10000000","0.02000000"],["77692.00000000","0.03000000"],["77691.91000000","0.00200000"],["77691.90000000","0.00400000"],["77691.85000000","0.00127000"],["77691.75000000","0.00027000"],["77691.60000000","0.08000000"],["77690.66000000","0.62764000"],["77690.65000000","0.16870000"],["77690.57000000","0.00257000"],["77690.27000000","0.00115000"],["77690.14000000","1.31471000"],["77690.10000000","0.01400000"],["77690.00000000","0.03000000"],["77689.95000000","0.00400000"],["77689.77000000","0.02007000"],["77689.72000000","0.12871000"],["77689.60000000","0.00008000"],["77689.55000000","0.00007000"],["77689.46000000","0.20422000"],["77689.01000000","1.25938000"],["77688.99000000","0.02000000"],["77688.97000000","0.00008000"],["77688.92000000","0.00014000"],["77688.87000000","0.02000000"],["77688.45000000","0.02000000"],["77688.34000000","0.02000000"],["77688.29000000","0.00007000"],["77688.21000000","0.04000000"],["77688.20000000","0.00128000"],["77688.11000000","0.02000000"],["77688.00000000","0.73665000"],["77686.76000000","0.00007000"],["77686.70000000","0.00010000"],["77686.14000000","0.37338000"],["77686.13000000","1.93226000"],["77686.09000000","1.31471000"],["77686.06000000","0.64392000"],["77686.05000000","0.00400000"],["77686.00000000","0.03000000"],["77685.94000000","0.00007000"],["77685.39000000","0.44159000"],["77685.36000000","0.00008000"],["77685.09000000","0.00008000"],["77685.07000000","0.00012000"],["77684.98000000","0.00014000"],["77684.72000000","0.00008000"],["77684.53000000","0.76649000"],["77684.46000000","0.00126000"],["77684.10000000","0.00400000"],["77684.00000000","0.03000000"],["77683.96000000","0.00007000"],["77683.87000000","0.00027000"],["77683.80000000","0.00019000"],["77683.77000000","0.10429000"],["77683.21000000","0.12872000"],["77682.88000000","0.00127000"],["77682.16000000","1.31471000"],["77682.15000000","0.00400000"],["77682.00000000","0.03000000"],["77681.98000000","0.00128000"],["77681.89000000","0.00200000"],["77681.88000000","0.03210000"],["77681.83000000","0.10429000"],["77681.70000000","0.16870000"],["77681.58000000","0.34773000"],["77681.20000000","0.00008000"],["77681.16000000","0.00007000"],["77681.11000000","0.10000000"],["77681.07000000","0.34774000"],["77681.04000000","0.00014000"],["77680.68000000","0.32965000"],["77680.20000000","0.00400000"],["77680.19000000","0.00007000"],["77680.00000000","0.03007000"],["77679.84000000","0.00008000"],["77679.15000000","0.50853000"],["77678.98000000","0.00010000"],["77678.85000000","0.00010000"],["77678.74000000","1.08483000"],["77678.73000000","1.93226000"],["77678.37000000","0.00007000"],["77678.27000000","1.31471000"],["77678.25000000","0.00400000"],["77678.00000000","0.03000000"],["77677.60000000","0.00008000"],["77677.57000000","0.37338000"],["77677.56000000","1.54365000"],["77677.32000000","0.00008000"],["77677.30000000","0.00012000"],["77677.10000000","0.00014000"],["77677.07000000","0.00126000"],["77676.73000000","0.00335000"],["77676.59000000","0.64400000"],["77676.52000000","0.00007000"],["77676.00000000","0.03000000"],["77675.99000000","0.01429000"],["77675.57000000","0.00007000"],["77675.49000000","0.00126000"],["77674.96000000","0.00008000"],["77674.85000000","0.04515000"],["77674.78000000","0.00059000"],["77674.65000000","0.09488000"],["77674.12000000","0.34777000"],["77674.05000000","1.93226000"],["77674.03000000","1.31471000"],["77674.00000000","0.03000000"],["77673.99000000","0.21156000"],["77673.77000000","0.00007000"],["77673.59000000","0.00012000"],["77673.58000000","0.00189000"],["77673.43000000","0.00008000"],["77673.16000000","0.00014000"],["77672.89000000","0.02042000"],["77672.78000000","0.00007000"],["77672.53000000","0.23763000"],["77672.14000000","0.34778000"],["77672.00000000","0.03000000"],["77671.45000000","0.00007000"],["77671.26000000","0.00010000"],["77671.09000000","0.02480000"],["77670.08000000","0.00008000"],["77670.00000000","0.03000000"],["77669.98000000","0.00007000"],["77669.91000000","0.33804000"],["77669.84000000","0.00008000"],["77669.70000000","0.37338000"],["77669.55000000","0.00008000"],["77669.24000000","1.77749000"],["77669.23000000","1.93226000"],["77669.22000000","0.00007000"],["77669.18000000","1.31471000"],["77669.05000000","0.00007000"],["77669.00000000","0.01000000"],["77668.92000000","0.00007000"],["77668.22000000","0.16870000"],["77668.00000000","0.03462000"],["77667.99000000","0.00017000"],["77667.88000000","0.00077000"],["77667.58000000","0.03862000"],["77667.23000000","0.79901000"],["77667.19000000","0.64407000"],["77667.18000000","0.00007000"],["77666.84000000","0.01137000"],["77666.33000000","0.00027000"],["77666.31000000","1.27529000"],["77666.29000000","0.00007000"],["77666.18000000","0.02000000"],["77666.00000000","0.03000000"],["77665.69000000","0.34781000"],["77665.38000000","0.02000000"],["77665.20000000","0.00008000"],["77664.39000000","0.00007000"],["77664.22000000","1.00076000"],["77664.21000000","1.93226000"],["77664.00000000","0.03007000"],["77663.99000000","0.00007000"],["77663.54000000","0.00010000"],["77663.22000000","1.31471000"],["77663.04000000","0.02000000"],["77662.30000000","0.02000000"],["77662.28000000","0.02000000"],["77662.08000000","0.00008000"],["77662.00000000","0.03000000"],["77661.99000000","0.00007000"],["77661.81000000","0.02000000"],["77661.59000000","0.00007000"],["77661.51000000","0.04000000"],["77661.44000000","1.25245000"],["77660.32000000","0.00008000"],["77660.22000000","0.16870000"],["77660.00000000","0.28000000"],["77659.90000000","0.03210000"],["77659.37000000","0.01164000"],["77658.80000000","0.00007000"],["77658.63000000","1.93226000"],["77658.48000000","1.31471000"],["77658.29000000","0.00007000"],["77658.09000000","0.91798000"],["77658.08000000","0.37338000"],["77658.04000000","0.54193000"],["77658.00000000","0.03000000"],["77657.93000000","0.00027000"],["77657.52000000","0.64415000"],["77657.42000000","0.02000000"],["77657.36000000","0.00007000"],["77656.05000000","0.00300000"],["77656.00000000","0.03207000"],["77655.99000000","0.00007000"],["77655.95000000","0.02000000"],["77655.82000000","0.00010000"],["77655.48000000","1.29805000"],["77655.07000000","1.00362000"],["77654.32000000","0.00008000"],["77654.00000000","0.03000000"],["77653.90000000","1.40059000"],["77653.89000000","1.31471000"],["77653.38000000","0.00007000"],["77653.20000000","0.00007000"],["77652.19000000","1.93226000"],["77652.08000000","0.00007000"],["77652.00000000","0.03000000"],["77651.99000000","0.00233000"],["77650.88000000","0.79917000"],["77650.56000000","0.00008000"],["77650.41000000","0.00007000"],["77650.30000000","0.37338000"],["77650.22000000","0.16870000"],["77650.04000000","0.00027000"],["77650.02000000","0.70020000"],["77650.00000000","0.03045000"],["77649.99000000","0.00018000"],["77649.96000000","1.31471000"],["77648.29000000","0.00007000"],["77648.25000000","0.11557000"],["77648.10000000","0.00010000"],["77648.00000000","0.03007000"],["77647.61000000","0.00007000"],["77647.50000000","0.00615000"],["77647.31000000","0.00425000"],["77647.01000000","1.93226000"],["77646.56000000","0.00008000"],["77646.48000000","0.02000000"],["77646.05000000","0.82294000"],["77646.04000000","1.31471000"],["77646.00000000","0.03000000"],["77645.58000000","0.02000000"],["77645.46000000","0.02000000"],["77645.43000000","0.02000000"],["77644.87000000","1.27564000"],["77644.82000000","0.00007000"],["77644.41000000","0.00007000"],["77644.16000000","0.00643000"],["77644.02000000","0.00430000"],["77644.00000000","0.03000000"],["77643.97000000","0.25743000"],["77643.93000000","0.00425000"],["77643.59000000","0.02000000"],["77642.84000000","0.00320000"],["77642.83000000","0.02000000"],["77642.52000000","0.34778000"],["77642.36000000","0.02000000"],["77642.29000000","0.00007000"],["77642.26000000","0.00027000"],["77642.06000000","0.02000000"],["77642.05000000","2.18487000"],["77642.04000000","1.31471000"],["77642.03000000","1.93226000"],["77642.02000000","0.00007000"],["77642.01000000","0.16870000"],["77642.00000000","0.03000000"],["77640.80000000","0.00008000"],["77640.75000000","3.61493000"],["77640.38000000","0.00010000"],["77640.26000000","0.00010000"],["77640.08000000","0.00007000"],["77640.03000000","0.79755000"],["77640.00000000","0.03000000"],["77639.84000000","0.00100000"],["77639.23000000","0.00007000"],["77638.93000000","0.00107000"],["77638.92000000","0.00039000"],["77638.91000000","0.00102000"],["77638.80000000","0.00008000"],["77638.00000000","0.03200000"],["77637.99000000","0.00076000"],["77637.84000000","0.00007000"],["77637.70000000","0.00077000"],["77637.08000000","0.00320000"],["77637.06000000","0.00321000"],["77637.05000000","1.88929000"],["77637.04000000","2.25459000"],["77636.43000000","0.00007000"],["77636.29000000","0.00007000"],["77636.27000000","0.00008000"],["77636.00000000","0.03000000"],["77635.97000000","1.31471000"],["77635.91000000","1.93226000"],["77634.71000000","0.34778000"],["77634.54000000","0.06433000"],["77634.47000000","0.00007000"],["77634.29000000","0.00007000"],["77634.21000000","0.00530000"],["77634.05000000","0.01719000"],["77634.01000000","0.50181000"],["77634.00000000","0.03000000"],["77633.64000000","0.00007000"],["77633.45000000","0.00112000"],["77633.11000000","0.00027000"],["77632.66000000","0.00010000"],["77632.29000000","0.00007000"],["77632.03000000","0.00007000"],["77632.00000000","0.03007000"],["77631.88000000","0.12841000"],["77631.80000000","1.31471000"],["77631.16000000","0.16870000"],["77631.04000000","0.00016000"],["77630.98000000","0.12782000"],["77630.93000000","0.71902000"],["77630.87000000","0.00515000"],["77630.76000000","1.93226000"],["77630.37000000","0.00093000"],["77630.00000000","0.03000000"],["77629.80000000","0.02000000"],["77629.23000000","0.00007000"],["77629.03000000","0.02000000"],["77628.05000000","0.00007000"],["77628.00000000","0.03000000"],["77627.11000000","1.98169000"],["77627.03000000","0.02000000"],["77626.98000000","3.24630000"],["77626.60000000","0.00057000"],["77626.29000000","0.00007000"],["77626.13000000","0.02000000"],["77626.01000000","0.02000000"],["77626.00000000","0.03000000"],["77625.98000000","0.02000000"],["77625.91000000","0.02000000"],["77625.65000000","1.31471000"],["77625.26000000","0.00007000"],["77625.14000000","0.02000000"],["77624.97000000","0.00007000"],["77624.94000000","0.00010000"],["77624.90000000","1.61379000"],["77624.36000000","0.00027000"],["77624.31000000","0.00007000"],["77624.01000000","1.93226000"],["77624.00000000","0.03007000"],["77623.99000000","0.00008000"],["77623.76000000","0.07150000"],["77623.72000000","0.34778000"],["77623.69000000","0.04000000"],["77623.28000000","0.00008000"],["77622.46000000","0.00007000"],["77622.43000000","0.06951000"],["77622.30000000","0.00007000"],["77622.29000000","0.00007000"],["77622.00000000","0.03000000"],["77621.83000000","0.00400000"],["77621.28000000","0.00008000"],["77620.22000000","0.16870000"],["77620.04000000","0.00007000"],["77620.00000000","0.03200000"],["77619.76000000","0.00187000"],["77619.19000000","0.71074000"],["77619.18000000","1.93226000"],["77618.94000000","0.00007000"],["77618.51000000","0.00063000"],["77618.50000000","0.01324000"],["77618.27000000","0.00106000"],["77618.00000000","0.03000000"],["77617.92000000","0.00007000"],["77617.22000000","0.00010000"],["77616.91000000","0.00007000"],["77616.87000000","0.00007000"],["77616.34000000","0.11557000"],["77616.12000000","0.00027000"],["77616.00000000","0.03000000"],["77615.59000000","0.04627000"],["77615.52000000","0.00008000"],["77614.55000000","0.59475000"],["77614.29000000","0.00007000"],["77614.19000000","0.00007000"],["77614.00000000","0.03000000"],["77613.33000000","1.93226000"],["77612.29000000","0.00007000"],["77612.00000000","0.03000000"],["77611.52000000","0.00008000"],["77610.40000000","0.75671000"],["77610.06000000","0.00007000"],["77610.00000000","0.37778000"],["77609.99000000","0.16870000"],["77609.84000000","0.00128000"],["77609.50000000","0.00010000"],["77608.90000000","0.00370000"],["77608.49000000","0.00007000"],["77608.35000000","0.00027000"],["77608.00000000","0.03000000"],["77607.82000000","1.93226000"],["77607.81000000","0.00072000"],["77607.76000000","0.93083000"],["77607.75000000","3.86743000"],["77607.12000000","0.04534000"],["77606.79000000","0.04877000"],["77606.76000000","0.00007000"],["77606.29000000","0.00007000"],["77606.00000000","0.03000000"],["77604.00000000","0.03000000"],["77603.41000000","0.00007000"],["77603.00000000","0.00022000"],["77602.90000000","0.00007000"],["77602.89000000","0.11557000"],["77602.74000000","0.00007000"],["77602.24000000","0.17101000"],["77602.23000000","0.34778000"],["77602.01000000","0.00259000"],["77602.00000000","0.03000000"],["77601.79000000","0.00200000"],["77601.78000000","0.00010000"],["77601.76000000","0.00008000"],["77601.67000000","0.00010000"],["77600.65000000","0.00007000"],["77600.44000000","0.00027000"],["77600.04000000","0.16870000"],["77600.00000000","0.03830000"],["77599.55000000","0.00100000"],["77598.94000000","0.24780000"],["77598.93000000","0.80000000"],["77598.29000000","0.00007000"],["77598.00000000","0.03000000"],["77597.82000000","0.00108000"],["77597.73000000","0.00007000"],["77596.00000000","0.03000000"],["77594.65000000","0.00007000"],["77594.52000000","0.00007000"],["77594.06000000","0.00010000"],["77594.05000000","0.11447000"],["77594.04000000","0.34778000"],["77594.00000000","0.03000000"],["77592.60000000","0.00027000"],["77592.32000000","0.00007000"],["77592.00000000","0.03008000"],["77591.82000000","0.09548000"],["77591.81000000","0.12089000"],["77591.22000000","0.00007000"],["77590.35000000","0.00007000"],["77590.00000000","0.03000000"],["77588.94000000","0.00007000"],["77588.63000000","0.16870000"],["77588.37000000","0.00007000"],["77588.30000000","0.02772000"],["77588.29000000","0.03210000"],["77588.00000000","0.03000000"],["77587.88000000","0.00007000"],["77587.87000000","0.00011000"],["77586.34000000","0.00010000"],["77586.23000000","0.00007000"],["77586.00000000","0.03000000"],["77584.73000000","0.00027000"],["77584.48000000","0.00015000"],["77584.32000000","0.12212000"],["77584.31000000","0.34778000"],["77584.23000000","0.00007000"],["77584.06000000","0.00073000"],["77584.00000000","0.03000000"],["77583.33000000","0.00100000"],["77582.24000000","0.00008000"],["77582.13000000","0.00007000"],["77582.00000000","0.03000000"],["77580.98000000","0.00011000"],["77580.56000000","0.00007000"],["77580.23000000","0.16870000"],["77580.00000000","0.03000000"],["77579.69000000","0.79705000"],["77579.68000000","3.87654000"],["77578.93000000","0.00038000"],["77578.62000000","0.00010000"],["77578.48000000","0.00007000"],["77578.31000000","0.00007000"],["77578.00000000","0.03000000"],["77577.50000000","0.00067000"],["77576.76000000","0.00027000"],["77576.37000000","0.03210000"],["77576.30000000","0.00007000"],["77576.00000000","0.03000000"],["77575.68000000","0.00007000"],["77575.45000000","0.34778000"],["77575.05000000","0.00007000"],["77574.97000000","0.00007000"],["77574.32000000","0.00007000"],["77574.00000000","0.03000000"],["77572.96000000","0.02016000"],["77572.48000000","0.00008000"],["77572.45000000","0.00020000"],["77572.35000000","0.00007000"],["77572.23000000","0.16870000"],["77572.00000000","0.03000000"],["77570.90000000","0.00010000"],["77570.45000000","0.00007000"],["77570.00000000","0.03000000"],["77568.96000000","0.00008000"],["77568.94000000","0.00027000"],["77568.32000000","0.00007000"],["77568.00000000","0.03007000"],["77567.78000000","0.00100000"],["77566.98000000","0.34778000"],["77566.66000000","0.03210000"],["77566.32000000","0.00007000"],["77566.00000000","0.03000000"],["77564.12000000","0.00007000"],["77564.01000000","0.00128000"],["77564.00000000","0.03000000"],["77563.99000000","0.16870000"],["77563.80000000","0.00007000"],["77563.18000000","0.00010000"],["77563.08000000","0.00010000"],["77562.72000000","0.00008000"],["77562.42000000","0.05113000"],["77562.32000000","0.00011000"],["77562.00000000","0.03000000"],["77561.75000000","0.00350000"],["77561.47000000","1.54224000"],["77561.00000000","0.00515000"],["77560.25000000","0.00007000"],["77560.14000000","0.00007000"],["77560.00000000","0.03200000"],["77559.58000000","0.00128000"],["77559.57000000","0.00027000"],["77559.07000000","0.00128000"],["77559.06000000","0.34778000"],["77558.88000000","0.00007000"],["77558.55000000","0.00008000"],["77558.22000000","0.00007000"],["77558.00000000","0.03000000"],["77557.23000000","0.00010000"],["77556.43000000","0.00007000"],["77556.01000000","0.09402000"],["77556.00000000","0.03000000"],["77555.27000000","0.01545000"],["77554.38000000","0.00007000"],["77554.00000000","0.03000000"],["77553.66000000","0.03210000"],["77553.44000000","0.00008000"],["77552.96000000","0.00008000"],["77552.69000000","0.00023000"],["77552.18000000","0.12893000"],["77552.00000000","0.03000000"],["77551.79000000","0.00027000"],["77551.63000000","0.00031000"],["77551.59000000","0.00007000"],["77551.23000000","0.34778000"],["77551.13000000","0.05883000"],["77550.23000000","0.16870000"],["77550.00000000","0.03000000"],["77549.84000000","0.00007000"],["77549.52000000","0.00007000"],["77549.17000000","3.87034000"],["77549.12000000","0.00128000"],["77548.00000000","0.03000000"],["77547.55000000","0.00007000"],["77547.05000000","0.00007000"],["77546.00000000","0.03000000"],["77545.26000000","0.00073000"],["77544.60000000","0.00007000"],["77544.16000000","0.01545000"],["77544.00000000","0.03000000"],["77543.99000000","0.12848000"],["77543.91000000","0.00027000"],["77543.47000000","0.00026000"],["77542.45000000","0.16870000"],["77542.00000000","0.03000000"],["77541.97000000","0.34778000"],["77541.93000000","0.00007000"],["77541.03000000","1.20000000"],["77540.00000000","0.03000000"],["77539.93000000","0.00007000"],["77539.19000000","0.00025000"],["77539.04000000","0.00007000"],["77538.00000000","0.03000000"],["77537.92000000","0.00008000"],["77536.06000000","0.00034000"],["77536.00000000","0.03007000"],["77535.91000000","0.00007000"],["77535.88000000","0.00007000"],["77535.81000000","0.00010000"],["77535.29000000","0.00010000"],["77534.09000000","0.00007000"],["77534.00000000","0.03000000"],["77533.61000000","0.12841000"],["77533.44000000","0.00008000"],["77532.07000000","0.00007000"],["77532.05000000","4.47793000"],["77532.00000000","0.03000000"],["77530.30000000","0.00007000"],["77530.12000000","0.00013000"],["77530.00000000","0.03000000"],["77529.41000000","0.00193000"],["77529.26000000","0.00007000"],["77529.06000000","0.00007000"],["77528.68000000","3.87138000"],["77528.63000000","0.10000000"],["77528.10000000","0.00100000"],["77528.00000000","0.03000000"],["77527.71000000","0.00027000"],["77527.29000000","0.00007000"],["77526.00000000","0.03000000"],["77525.68000000","0.00456000"],["77525.64000000","0.12841000"],["77525.42000000","0.06500000"],["77525.12000000","0.00672000"],["77525.00000000","0.00010000"],["77524.49000000","0.00010000"],["77524.21000000","0.00007000"],["77524.00000000","0.03000000"],["77522.40000000","0.00008000"],["77522.00000000","0.03000000"],["77521.93000000","0.00007000"],["77521.64000000","0.05729000"],["77521.60000000","0.00007000"],["77521.05000000","1.27767000"],["77520.00000000","0.03057000"],["77519.66000000","0.00027000"],["77519.59000000","0.00007000"],["77519.47000000","0.00007000"],["77518.00000000","0.03000000"],["77517.56000000","0.00007000"],["77517.12000000","0.00181000"],["77516.68000000","0.01545000"],["77516.00000000","0.03000000"],["77514.75000000","0.00007000"],["77514.65000000","0.04000000"],["77514.60000000","0.00310000"],["77514.59000000","0.00042000"],["77514.01000000","0.00007000"],["77514.00000000","0.03000000"],["77513.56000000","0.00007000"],["77513.52000000","0.00017000"],["77513.33000000","0.00016000"],["77512.78000000","0.00515000"],["77512.00000000","0.03000000"],["77511.97000000","0.00007000"],["77511.95000000","0.12841000"],["77511.74000000","0.00027000"],["77511.44000000","0.00128000"],["77511.11000000","0.00007000"],["77510.89000000","0.00011000"],["77510.77000000","0.00007000"],["77510.63000000","0.00023000"],["77510.00000000","0.03050000"],["77509.94000000","0.00007000"],["77509.82000000","0.00012000"],["77509.64000000","0.00008000"],["77509.37000000","0.00007000"],["77509.01000000","0.00007000"],["77508.00000000","0.03000000"],["77507.89000000","0.00007000"],["77507.77000000","0.12841000"],["77507.32000000","2.25870000"],["77507.18000000","0.00102000"],["77506.88000000","0.00008000"],["77506.87000000","0.00017000"],["77506.01000000","0.00812000"],["77506.00000000","0.03000000"],["77505.59000000","0.00007000"],["77504.42000000","0.00008000"],["77504.16000000","0.00008000"],["77504.00000000","0.03007000"],["77503.25000000","0.00027000"],["77502.49000000","0.12841000"],["77502.40000000","0.00007000"],["77502.05000000","0.00008000"],["77502.00000000","0.03000000"],["77501.76000000","0.00007000"],["77500.00000000","1.61208000"],["77499.70000000","0.00163000"],["77499.60000000","0.00007000"],["77499.17000000","0.00007000"],["77498.36000000","0.03210000"],["77497.98000000","0.00007000"],["77496.94000000","0.00007000"],["77496.82000000","0.00007000"],["77496.77000000","0.00007000"],["77495.41000000","0.00027000"],["77494.67000000","0.02163000"],["77494.39000000","0.00387000"],["77494.34000000","0.00774000"],["77493.58000000","0.00011000"],["77492.02000000","0.00007000"],["77491.93000000","0.00011000"],["77491.78000000","0.02016000"],["77491.50000000","3.62152000"],["77491.48000000","0.00009000"],["77491.36000000","0.00008000"],["77491.20000000","0.00516000"],["77490.26000000","0.00390000"],["77490.00000000","0.00061000"],["77489.76000000","0.00100000"],["77489.19000000","3.87329000"],["77489.00000000","0.00026000"],["77488.92000000","0.03210000"],["77488.45000000","0.00007000"],["77487.43000000","0.00147000"],["77487.41000000","0.00027000"],["77486.73000000","0.50225000"],["77485.90000000","0.00010000"],["77485.44000000","0.00169000"],["77485.28000000","0.00010000"],["77484.73000000","0.00035000"],["77483.33000000","0.00020000"],["77482.87000000","0.00007000"],["77482.44000000","0.00007000"],["77481.13000000","0.00011000"],["77480.70000000","0.00077000"],["77480.66000000","0.00011000"],["77480.06000000","0.00007000"],["77480.00000000","0.00050000"],["77479.60000000","0.00027000"],["77478.85000000","0.00008000"],["77478.63000000","0.00109000"],["77478.09000000","0.00008000"],["77478.04000000","0.00051000"],["77476.84000000","0.00044000"],["77476.72000000","0.02896000"],["77476.34000000","0.11557000"],["77476.26000000","0.00007000"],["77475.84000000","0.00008000"],["77475.43000000","0.00011000"],["77475.42000000","0.00011000"],["77474.89000000","0.00021000"],["77474.88000000","0.00008000"],["77473.98000000","0.00007000"],["77473.41000000","0.00008000"],["77472.47000000","0.00008000"],["77472.14000000","0.00097000"],["77472.01000000","0.00128000"],["77471.71000000","0.00021000"],["77471.53000000","0.00036000"],["77471.42000000","0.00013000"],["77471.01000000","0.00027000"],["77470.58000000","0.00179000"],["77470.00000000","0.00050000"],["77468.92000000","0.00007000"],["77468.46000000","0.00012000"],["77467.71000000","0.00007000"],["77467.52000000","0.00010000"],["77467.45000000","0.00380000"],["77466.96000000","0.00008000"],["77466.90000000","0.00007000"],["77466.65000000","0.00013000"],["77466.44000000","0.00010000"],["77466.04000000","0.00010000"],["77465.57000000","0.00011000"],["77465.52000000","0.00015000"],["77464.76000000","0.00022000"],["77463.87000000","0.12841000"],["77463.40000000","0.00021000"],["77463.25000000","0.00027000"],["77462.06000000","0.00009000"],["77460.56000000","0.00007000"],["77460.38000000","0.00012000"],["77460.32000000","0.00028000"],["77460.16000000","0.00020000"],["77460.02000000","0.00053000"],["77460.00000000","0.01671000"],["77459.76000000","0.00502000"],["77459.68000000","0.00018000"],["77459.66000000","0.00011000"],["77459.31000000","0.00007000"],["77459.11000000","0.00010000"],["77458.68000000","0.00031000"],["77458.52000000","0.03222000"],["77458.33000000","0.00033000"],["77457.63000000","0.00007000"],["77457.60000000","0.00019000"],["77457.56000000","0.00040000"],["77457.53000000","0.00007000"],["77457.14000000","0.00008000"],["77456.77000000","0.00020000"],["77455.73000000","0.00022000"],["77455.49000000","0.00027000"],["77454.84000000","0.00046000"],["77454.54000000","0.00085000"],["77454.16000000","0.03210000"],["77453.72000000","0.00543000"],["77452.32000000","0.00265000"],["77452.19000000","0.00007000"],["77452.16000000","0.00007000"],["77451.28000000","0.00009000"],["77450.00000000","1.00122000"],["77449.76000000","0.00008000"],["77449.28000000","0.00011000"],["77449.24000000","0.00009000"],["77448.97000000","0.00007000"],["77448.67000000","0.00071000"],["77448.00000000","0.00014000"],["77447.77000000","0.00039000"],["77447.51000000","0.00011000"],["77447.31000000","0.00010000"],["77447.04000000","0.00013000"],["77446.96000000","0.00069000"],["77446.15000000","0.00046000"],["77446.00000000","0.00013000"],["77445.60000000","0.00008000"],["77444.89000000","0.00033000"],["77444.80000000","0.00008000"],["77444.61000000","0.03210000"],["77444.44000000","0.00008000"],["77444.00000000","0.10000000"],["77443.85000000","0.00025000"],["77443.83000000","0.00007000"],["77443.71000000","0.00047000"],["77443.53000000","0.00009000"],["77443.35000000","0.00007000"],["77443.34000000","0.00019000"],["77443.20000000","0.00027000"],["77442.85000000","0.00021000"],["77442.62000000","0.00021000"],["77442.06000000","0.05113000"],["77441.83000000","0.00010000"],["77441.48000000","0.00021000"],["77441.17000000","0.00078000"],["77440.95000000","0.00008000"],["77440.65000000","0.00007000"],["77440.48000000","0.00008000"],["77440.26000000","0.00592000"],["77440.00000000","0.00246000"],["77439.90000000","0.00013000"],["77438.25000000","0.00007000"],["77437.80000000","0.00061000"],["77437.66000000","0.00007000"],["77437.51000000","0.00083000"],["77437.50000000","0.00053000"],["77437.40000000","0.00011000"],["77437.11000000","0.00007000"],["77436.46000000","0.00065000"],["77435.34000000","0.00027000"],["77435.22000000","3.87596000"],["77435.12000000","0.00008000"],["77434.50000000","2.50000000"],["77434.39000000","0.00049000"],["77434.38000000","0.00016000"],["77433.72000000","0.00013000"],["77433.33000000","0.00330000"],["77433.24000000","0.00016000"],["77433.01000000","0.00043000"],["77432.91000000","0.00128000"],["77432.52000000","0.00007000"],["77431.63000000","0.00007000"],["77431.00000000","0.00064000"],["77430.79000000","0.00009000"],["77430.62000000","0.00016000"],["77430.57000000","0.00043000"],["77430.20000000","0.00133000"],["77430.00000000","0.00078000"],["77429.89000000","0.00007000"],["77429.81000000","0.00007000"],["77429.60000000","0.00041000"],["77429.50000000","0.00008000"],["77429.28000000","0.00008000"],["77428.57000000","0.00064000"],["77428.50000000","0.00016000"],["77428.46000000","0.00010000"],["77428.01000000","0.00011000"],["77428.00000000","0.11557000"],["77427.73000000","0.00015000"],["77427.61000000","0.00044000"],["77427.60000000","0.00218000"],["77427.53000000","0.00027000"],["77426.93000000","0.00007000"],["77426.43000000","0.00039000"],["77426.29000000","0.00032000"],["77426.12000000","0.00035000"],["77425.86000000","0.00020000"],["77425.00000000","0.00409000"],["77424.81000000","0.05607000"],["77424.80000000","0.00017000"],["77424.74000000","0.00049000"],["77424.31000000","0.00007000"],["77424.24000000","0.00037000"],["77424.23000000","0.00296000"],["77423.50000000","0.00190000"],["77423.27000000","0.00064000"],["77423.24000000","0.00039000"],["77423.15000000","0.00011000"],["77423.07000000","0.00054000"],["77422.73000000","0.00260000"],["77422.57000000","0.00062000"],["77422.22000000","0.00046000"],["77422.08000000","0.00007000"],["77421.81000000","0.00042000"],["77421.46000000","0.00516000"],["77421.11000000","0.00008000"],["77420.72000000","0.00007000"],["77420.53000000","0.00009000"],["77420.49000000","0.11620000"],["77420.02000000","0.00011000"],["77420.00000000","0.00556000"],["77419.61000000","0.00032000"],["77419.60000000","0.00027000"],["77419.35000000","0.00105000"],["77419.34000000","0.00008000"],["77418.74000000","0.00019000"],["77418.48000000","0.00144000"],["77418.41000000","0.00575000"],["77418.28000000","0.00023000"],["77417.65000000","0.00042000"],["77417.64000000","0.00109000"],["77417.57000000","0.00010000"],["77416.80000000","0.00008000"],["77416.72000000","0.00010000"],["77416.66000000","0.00014000"],["77416.42000000","0.00334000"],["77416.38000000","0.11557000"],["77416.32000000","0.00008000"],["77416.28000000","0.00941000"],["77416.04000000","0.00008000"],["77415.27000000","0.00010000"],["77415.00000000","0.00007000"],["77414.48000000","0.00017000"],["77414.16000000","0.00030000"],["77413.89000000","0.00011000"],["77413.76000000","0.00008000"],["77413.46000000","0.00380000"]],"asks":[["77708.40000000","2.25802000"],["77708.41000000","0.00118000"],["77708.42000000","0.00013000"],["77708.46000000","0.00014000"],["77708.47000000","0.09901000"],["77708.62000000","0.00014000"],["77708.64000000","0.00008000"],["77709.02000000","0.00208000"],["77711.14000000","0.00592000"],["77711.15000000","0.01289000"],["77711.16000000","0.00014000"],["77711.17000000","0.02909000"],["77712.27000000","0.00571000"],["77712.30000000","0.00136000"],["77712.45000000","0.00014000"],["77712.46000000","0.03224000"],["77712.56000000","0.00014000"],["77712.73000000","0.00007000"],["77712.74000000","1.13744000"],["77712.84000000","0.00027000"],["77713.52000000","0.00943000"],["77713.96000000","0.00321000"],["77714.23000000","0.00013000"],["77714.64000000","0.00400000"],["77714.72000000","0.00007000"],["77714.76000000","0.01115000"],["77715.29000000","0.00643000"],["77715.30000000","0.00400000"],["77715.78000000","0.02400000"],["77715.84000000","0.02939000"],["77716.01000000","0.01115000"],["77716.18000000","0.00008000"],["77716.22000000","0.01200000"],["77716.23000000","0.00600000"],["77716.24000000","1.93226000"],["77716.25000000","1.68809000"],["77716.28000000","0.32183000"],["77716.40000000","0.00008000"],["77716.46000000","0.46030000"],["77716.50000000","0.00014000"],["77716.51000000","0.29828000"],["77716.57000000","0.03000000"],["77716.61000000","0.03200000"],["77716.66000000","0.02400000"],["77716.76000000","0.00007000"],["77716.87000000","0.12867000"],["77717.06000000","0.00150000"],["77717.25000000","0.00400000"],["77717.52000000","0.00007000"],["77717.76000000","0.81560000"],["77717.83000000","0.00022000"],["77717.99000000","0.08048000"],["77718.00000000","0.03000000"],["77718.11000000","0.00007000"],["77718.34000000","0.00048000"],["77718.53000000","0.00048000"],["77718.73000000","0.00041000"],["77718.88000000","0.00008000"],["77718.92000000","0.03000000"],["77719.00000000","0.00600000"],["77719.05000000","0.00188000"],["77719.11000000","0.00643000"],["77719.12000000","0.00007000"],["77719.20000000","0.00400000"],["77719.30000000","0.00257000"],["77719.35000000","0.00381000"],["77719.66000000","0.02600000"],["77719.69000000","0.02800000"],["77719.79000000","0.00007000"],["77720.00000000","0.03114000"],["77720.04000000","0.03210000"],["77720.23000000","0.03000000"],["77720.31000000","0.00007000"],["77720.36000000","0.00034000"],["77720.43000000","1.10255000"],["77720.44000000","0.00014000"],["77720.47000000","0.02400000"],["77720.48000000","0.02200000"],["77720.52000000","0.00011000"],["77720.56000000","0.03000000"],["77720.57000000","0.02800000"],["77720.87000000","0.00007000"],["77720.88000000","0.00046000"],["77720.91000000","0.00027000"],["77721.15000000","0.00400000"],["77721.18000000","0.00010000"],["77721.19000000","0.00010000"],["77721.30000000","0.00008000"],["77721.50000000","0.00007000"],["77721.65000000","0.14162000"],["77721.85000000","0.00386000"],["77722.00000000","0.03000000"],["77722.23000000","0.00007000"],["77722.35000000","0.00007000"],["77722.54000000","1.31471000"],["77722.99000000","0.00011000"],["77723.10000000","0.00400000"],["77723.11000000","0.00007000"],["77723.55000000","0.03000000"],["77723.70000000","0.10424000"],["77723.76000000","0.00008000"],["77723.77000000","1.93226000"],["77723.91000000","0.00007000"],["77723.95000000","0.00008000"],["77723.99000000","0.00400000"],["77724.00000000","0.03000000"],["77724.16000000","0.00008000"],["77724.38000000","0.00014000"],["77724.86000000","0.76360000"],["77724.89000000","0.37338000"],["77725.00000000","0.00245000"],["77725.05000000","0.00400000"],["77725.18000000","0.12865000"],["77725.34000000","0.00007000"],["77725.64000000","0.10423000"],["77726.00000000","0.03000000"],["77726.02000000","0.00019000"],["77726.10000000","0.00090000"],["77726.22000000","0.00007000"],["77726.41000000","0.09622000"],["77726.42000000","0.00011000"],["77726.49000000","0.00060000"],["77726.64000000","0.02000000"],["77726.71000000","1.31471000"],["77726.98000000","0.00128000"],["77727.00000000","0.00400000"],["77727.24000000","0.00010000"],["77727.27000000","0.00157000"],["77727.54000000","0.38623000"],["77727.55000000","0.03210000"],["77727.60000000","0.00007000"],["77727.84000000","0.00008000"],["77727.90000000","0.02200000"],["77728.00000000","0.03007000"],["77728.03000000","0.00200000"],["77728.04000000","0.12000000"],["77728.32000000","0.00014000"],["77728.35000000","0.00007000"],["77728.44000000","1.35549000"],["77728.45000000","1.93226000"],["77728.48000000","0.00007000"],["77728.64000000","0.00008000"],["77728.71000000","0.00034000"],["77728.95000000","0.00400000"],["77728.96000000","0.00682000"],["77729.00000000","0.03862000"],["77729.11000000","0.00008000"],["77729.26000000","0.00128000"],["77729.50000000","0.16870000"],["77729.54000000","0.00008000"],["77729.60000000","0.00386000"],["77729.61000000","0.00128000"],["77729.72000000","0.00160000"],["77730.00000000","0.03050000"],["77730.26000000","0.00411000"],["77730.45000000","0.00085000"],["77730.89000000","0.25750000"],["77730.90000000","0.00400000"],["77730.99000000","0.00007000"],["77731.08000000","0.00007000"],["77731.19000000","0.00008000"],["77731.32000000","0.00051000"],["77731.33000000","0.00024000"],["77731.35000000","1.95849000"],["77731.36000000","0.00010000"],["77731.54000000","0.12864000"],["77731.72000000","0.00008000"],["77731.92000000","0.00008000"],["77732.00000000","0.03100000"],["77732.22000000","0.38612000"],["77732.26000000","0.00014000"],["77732.35000000","0.00007000"],["77732.74000000","0.00038000"],["77732.75000000","0.00007000"],["77732.77000000","0.78686000"],["77732.78000000","0.32953000"],["77732.85000000","0.00400000"],["77732.86000000","0.37338000"],["77733.33000000","0.00251000"],["77733.34000000","0.00007000"],["77733.50000000","0.00163000"],["77733.52000000","0.00008000"],["77734.00000000","0.03000000"],["77734.22000000","0.00007000"],["77734.31000000","0.00007000"],["77734.40000000","0.00007000"],["77734.74000000","0.00334000"],["77734.80000000","0.00400000"],["77735.06000000","1.93226000"],["77735.23000000","0.02400000"],["77735.29000000","0.02800000"],["77735.61000000","0.00008000"],["77735.80000000","0.00191000"],["77735.94000000","0.00007000"],["77736.00000000","0.03265000"],["77736.02000000","0.03000000"],["77736.04000000","0.01278000"],["77736.06000000","0.03200000"],["77736.11000000","0.02400000"],["77736.20000000","0.00014000"],["77736.42000000","0.00059000"],["77736.43000000","0.00007000"],["77736.48000000","0.00027000"],["77736.63000000","0.00192000"],["77736.65000000","0.01344000"],["77736.69000000","0.00095000"],["77736.73000000","0.00010000"],["77736.75000000","0.00412000"],["77736.90000000","1.14955000"],["77736.91000000","1.31471000"],["77737.10000000","0.00007000"],["77737.37000000","0.00386000"],["77737.45000000","0.00007000"],["77737.81000000","0.00020000"],["77737.96000000","0.00041000"],["77737.98000000","0.34748000"],["77738.00000000","0.03000000"],["77738.06000000","0.00007000"],["77738.27000000","0.00200000"],["77738.28000000","1.29666000"],["77738.37000000","0.03000000"],["77738.40000000","0.00008000"],["77738.47000000","0.00007000"],["77738.70000000","0.00400000"],["77738.84000000","0.09852000"],["77739.11000000","0.02600000"],["77739.14000000","0.02800000"],["77739.24000000","0.38609000"],["77739.42000000","0.34748000"],["77739.48000000","0.03210000"],["77739.49000000","0.00008000"],["77739.68000000","0.00015000"],["77739.79000000","0.16870000"],["77739.92000000","0.02400000"],["77739.93000000","0.02200000"],["77739.97000000","0.00008000"],["77740.00000000","0.03250000"],["77740.01000000","0.03000000"],["77740.14000000","0.00014000"],["77740.28000000","0.00018000"],["77740.47000000","0.00007000"],["77740.65000000","0.00400000"],["77740.68000000","1.11438000"],["77740.69000000","1.93238000"],["77740.74000000","0.00026000"],["77741.02000000","0.04733000"],["77741.85000000","0.37360000"],["77741.93000000","0.00105000"],["77741.96000000","0.00335000"],["77742.00000000","0.03000000"],["77742.04000000","1.31471000"],["77742.59000000","0.00007000"],["77742.70000000","0.00007000"],["77743.00000000","0.03000000"],["77743.18000000","0.00007000"],["77743.28000000","0.00008000"],["77743.38000000","0.00008000"],["77743.52000000","0.00023000"],["77743.57000000","0.51276000"],["77743.58000000","0.00007000"],["77744.00000000","0.03007000"],["77744.02000000","0.00009000"],["77744.08000000","0.00014000"],["77744.21000000","0.00007000"],["77744.25000000","0.00027000"],["77744.26000000","0.00220000"],["77744.34000000","0.00007000"],["77744.44000000","0.00029000"],["77744.50000000","0.00010000"],["77744.53000000","0.99867000"],["77744.55000000","0.00400000"],["77745.00000000","0.15000000"],["77745.18000000","0.00041000"],["77745.29000000","0.00624000"],["77745.50000000","0.00007000"],["77745.94000000","0.00100000"],["77745.97000000","0.02800000"],["77746.00000000","0.03000000"],["77746.24000000","0.02008000"],["77746.25000000","1.31471000"],["77746.26000000","1.93226000"],["77746.50000000","0.00600000"],["77746.62000000","0.00007000"],["77746.65000000","0.00007000"],["77746.85000000","0.34744000"],["77746.95000000","0.64341000"],["77746.97000000","0.00010000"],["77746.98000000","0.00429000"],["77747.14000000","0.35876000"],["77747.26000000","0.00008000"],["77747.44000000","0.00008000"],["77747.51000000","0.00008000"],["77747.52000000","0.34744000"],["77747.73000000","0.12782000"],["77747.74000000","0.00122000"],["77747.79000000","0.16870000"],["77747.99000000","0.00049000"],["77748.00000000","0.04000000"],["77748.10000000","0.99939000"],["77748.11000000","0.79644000"],["77748.16000000","0.00008000"],["77748.17000000","0.00019000"],["77748.30000000","0.00007000"],["77748.66000000","0.00012000"],["77748.67000000","0.00007000"],["77748.81000000","0.02569000"],["77749.75000000","0.00008000"],["77749.89000000","0.05517000"],["77750.00000000","0.05097000"],["77750.25000000","0.00436000"],["77750.35000000","0.00360000"],["77750.58000000","0.00256000"],["77751.10000000","0.00007000"],["77751.12000000","1.93226000"],["77751.15000000","0.11557000"],["77751.59000000","0.00390000"],["77752.00000000","0.03000000"],["77752.14000000","0.50973000"],["77752.15000000","1.31471000"],["77752.21000000","0.00007000"],["77752.27000000","0.00010000"],["77752.29000000","0.00100000"],["77752.37000000","0.00160000"],["77752.54000000","0.00007000"],["77752.84000000","0.00251000"],["77753.04000000","0.00008000"],["77753.42000000","0.00016000"],["77753.46000000","0.00424000"],["77753.52000000","0.01278000"],["77753.67000000","0.00021000"],["77753.82000000","0.34741000"],["77753.90000000","0.00019000"],["77754.00000000","0.03000000"],["77754.31000000","0.00018000"],["77754.44000000","0.00014000"],["77754.72000000","0.00007000"],["77754.74000000","0.02800000"],["77755.10000000","0.00023000"],["77755.20000000","0.00008000"],["77755.38000000","0.00027000"],["77755.51000000","0.03200000"],["77755.57000000","0.02400000"],["77755.65000000","0.00035000"],["77755.79000000","0.34535000"],["77755.80000000","0.64334000"],["77755.81000000","0.00094000"],["77755.82000000","0.37338000"],["77755.90000000","0.00064000"],["77755.93000000","0.00007000"],["77756.00000000","0.03000000"],["77756.04000000","0.00010000"],["77756.46000000","0.16870000"],["77756.50000000","0.00260000"],["77756.70000000","0.00007000"],["77756.75000000","0.00007000"],["77757.10000000","0.00044000"],["77757.29000000","0.00007000"],["77757.54000000","0.00514000"],["77757.92000000","0.00008000"],["77758.00000000","0.03000000"],["77758.19000000","0.00023000"],["77758.39000000","0.00007000"],["77759.28000000","0.00463000"],["77759.90000000","0.00008000"],["77759.91000000","0.03000000"],["77760.00000000","0.05907000"],["77760.04000000","0.00010000"],["77760.21000000","0.00054000"],["77760.26000000","0.00672000"],["77760.44000000","1.55348000"],["77760.45000000","1.93226000"],["77760.52000000","0.00007000"],["77760.55000000","0.01132000"],["77760.68000000","0.02600000"],["77760.92000000","0.00008000"],["77761.18000000","0.02200000"],["77761.19000000","0.00051000"],["77761.32000000","0.79630000"],["77761.47000000","0.03000000"],["77761.50000000","1.27373000"],["77761.55000000","0.00010000"],["77761.81000000","0.01278000"],["77761.82000000","0.00117000"],["77761.93000000","0.10000000"],["77761.95000000","0.00008000"],["77761.98000000","0.00600000"],["77762.00000000","0.03000000"],["77762.02000000","0.00183000"],["77762.16000000","0.00007000"],["77762.23000000","0.00672000"],["77762.25000000","1.31471000"],["77762.29000000","0.00007000"],["77762.45000000","0.03000000"],["77762.80000000","0.00008000"],["77762.82000000","0.11557000"],["77762.88000000","0.00010000"],["77762.96000000","0.00008000"],["77763.10000000","0.00007000"],["77763.55000000","0.00030000"],["77763.57000000","0.00027000"],["77764.00000000","0.03200000"],["77764.01000000","0.00177000"],["77764.06000000","0.75365000"],["77764.16000000","0.25000000"],["77764.37000000","0.00113000"],["77764.39000000","0.00007000"],["77764.47000000","0.00013000"],["77764.56000000","0.02849000"],["77764.57000000","0.02600000"],["77764.70000000","0.01767000"],["77764.72000000","0.37338000"],["77765.09000000","0.00007000"],["77765.15000000","0.00321000"],["77765.16000000","1.93226000"],["77765.34000000","0.02200000"],["77765.35000000","0.02400000"],["77765.41000000","0.05812000"],["77765.56000000","0.00025000"],["77765.70000000","0.00432000"],["77765.80000000","0.01378000"],["77765.99000000","0.13504000"],["77766.00000000","0.03000000"],["77766.23000000","0.00069000"],["77766.45000000","0.00046000"],["77766.52000000","0.00011000"],["77766.66000000","0.00015000"],["77766.92000000","0.00034000"],["77766.98000000","0.00007000"],["77767.08000000","0.00034000"],["77767.12000000","0.00009000"],["77767.44000000","0.00029000"],["77767.68000000","0.00008000"],["77767.81000000","0.00010000"],["77767.89000000","0.00021000"],["77767.99000000","0.00320000"],["77768.00000000","0.03000000"],["77768.09000000","0.00118000"],["77768.10000000","0.00007000"],["77768.26000000","0.00007000"],["77768.42000000","0.00014000"],["77768.57000000","0.00034000"],["77768.71000000","0.01712000"],["77768.83000000","0.00030000"],["77769.15000000","0.00411000"],["77769.23000000","0.00147000"],["77769.30000000","0.00973000"],["77769.47000000","0.07019000"],["77769.48000000","0.16870000"],["77769.60000000","0.00067000"],["77769.63000000","0.00061000"],["77769.82000000","0.00010000"],["77769.93000000","0.00100000"],["77770.00000000","0.03059000"],["77770.04000000","0.00011000"],["77770.07000000","0.00007000"],["77770.41000000","0.00007000"],["77770.53000000","0.00107000"],["77770.69000000","0.00007000"],["77770.72000000","0.00008000"],["77770.77000000","0.00014000"],["77770.80000000","0.00059000"],["77770.96000000","1.75818000"],["77770.97000000","1.31471000"],["77771.01000000","1.93226000"],["77771.34000000","0.00009000"],["77771.42000000","0.00026000"],["77771.60000000","0.00026000"],["77771.74000000","0.00052000"],["77772.00000000","0.03000000"],["77772.10000000","0.00072000"],["77772.30000000","0.00027000"],["77772.37000000","3.24023000"],["77772.40000000","0.00053000"],["77772.55000000","0.00049000"],["77772.58000000","0.00097000"],["77772.79000000","0.00026000"],["77772.85000000","0.00063000"],["77773.30000000","0.00007000"],["77773.49000000","0.00007000"],["77773.69000000","0.00015000"],["77773.88000000","0.00021000"],["77774.00000000","0.03000000"],["77774.02000000","0.00544000"],["77774.36000000","0.00007000"],["77774.38000000","0.00111000"],["77774.64000000","0.00009000"],["77775.00000000","0.01505000"],["77775.01000000","0.02651000"],["77775.14000000","0.00012000"],["77775.35000000","0.25743000"],["77775.44000000","0.00024000"],["77775.48000000","0.00027000"],["77775.58000000","0.00010000"],["77775.68000000","0.00007000"],["77775.88000000","0.00007000"],["77776.00000000","0.03007000"],["77776.05000000","0.00008000"],["77776.25000000","1.31471000"],["77776.26000000","0.86368000"],["77776.27000000","1.27349000"],["77776.29000000","0.00007000"],["77776.46000000","0.00390000"],["77776.53000000","0.00093000"],["77776.72000000","0.00231000"],["77776.73000000","0.00010000"],["77776.81000000","0.00033000"],["77776.83000000","0.00018000"],["77776.97000000","0.00010000"],["77777.00000000","0.12573000"],["77777.24000000","0.16870000"],["77777.42000000","1.27347000"],["77777.44000000","0.00008000"],["77777.50000000","0.00007000"],["77777.64000000","0.00013000"],["77777.70000000","0.00007000"],["77777.75000000","0.00013000"],["77777.77000000","0.00158000"],["77777.78000000","0.00010000"],["77777.88000000","0.00007000"],["77778.00000000","0.03000000"],["77778.10000000","0.01271000"],["77778.48000000","0.00008000"],["77778.58000000","0.00020000"],["77778.74000000","0.00253000"],["77778.96000000","0.00009000"],["77779.09000000","0.00007000"],["77779.12000000","0.01360000"],["77779.20000000","0.00010000"],["77779.35000000","0.00023000"],["77779.41000000","0.00022000"],["77779.43000000","0.00109000"],["77779.44000000","0.00931000"],["77779.49000000","0.00016000"],["77779.84000000","0.00011000"],["77779.87000000","0.79611000"],["77779.95000000","0.00009000"],["77780.00000000","0.03687000"],["77780.19000000","0.01457000"],["77780.27000000","1.00336000"],["77780.29000000","0.00010000"],["77780.32000000","1.31471000"],["77780.34000000","1.93226000"],["77780.51000000","0.00007000"],["77780.56000000","0.00007000"],["77780.58000000","0.00036000"],["77780.61000000","0.00010000"],["77780.64000000","0.02200000"],["77780.77000000","0.00159000"],["77780.81000000","0.00018000"],["77781.13000000","0.34778000"],["77781.32000000","0.06561000"],["77781.33000000","0.00016000"],["77781.74000000","0.00025000"],["77781.78000000","0.00007000"],["77781.99000000","0.00128000"],["77782.00000000","0.03000000"],["77782.04000000","0.00200000"],["77782.05000000","0.00011000"],["77782.30000000","0.00014000"],["77782.35000000","0.00009000"],["77782.42000000","0.00009000"],["77782.64000000","0.12270000"],["77782.65000000","0.11557000"],["77782.75000000","0.00007000"],["77782.81000000","0.09346000"],["77783.35000000","0.00055000"],["77784.00000000","0.03000000"],["77784.02000000","0.00007000"],["77784.69000000","0.00007000"],["77784.71000000","0.00007000"],["77784.77000000","0.00126000"],["77784.87000000","0.00018000"],["77785.00000000","0.18496000"],["77785.29000000","0.00017000"],["77785.50000000","0.00021000"],["77785.54000000","0.00041000"],["77785.55000000","0.00012000"],["77785.71000000","0.00035000"],["77785.92000000","0.00021000"],["77786.00000000","0.03000000"],["77786.04000000","0.00121000"],["77786.24000000","0.00008000"],["77786.45000000","0.00104000"],["77786.70000000","0.00647000"],["77786.80000000","0.00013000"],["77787.20000000","0.00008000"],["77787.32000000","0.00007000"],["77787.37000000","0.00009000"],["77787.39000000","0.00020000"],["77787.49000000","0.00007000"],["77787.54000000","0.01917000"],["77787.75000000","0.00035000"],["77787.90000000","0.00034000"],["77788.00000000","0.03000000"],["77788.12000000","0.00180000"],["77788.13000000","0.00011000"],["77788.22000000","0.00009000"],["77788.27000000","0.00014000"],["77788.29000000","0.00008000"],["77788.53000000","0.00010000"],["77788.57000000","0.00008000"],["77788.60000000","0.00017000"],["77788.76000000","0.00007000"],["77788.91000000","0.00009000"],["77789.00000000","0.11077000"],["77789.09000000","0.00073000"],["77789.16000000","0.00290000"],["77789.47000000","0.00007000"],["77789.49000000","0.00007000"],["77789.51000000","0.00027000"],["77789.65000000","0.98105000"],["77789.66000000","1.31471000"],["77789.67000000","1.93226000"],["77789.71000000","0.00008000"],["77790.00000000","0.03282000"],["77790.10000000","0.00681000"],["77790.27000000","0.00007000"],["77790.29000000","0.00007000"],["77790.55000000","0.01137000"],["77790.62000000","0.00020000"],["77791.12000000","0.00032000"],["77791.87000000","0.00007000"],["77791.99000000","0.00031000"],["77792.00000000","0.03007000"],["77792.03000000","0.00009000"],["77792.09000000","0.00008000"],["77792.25000000","0.00077000"],["77792.67000000","0.00010000"],["77792.76000000","0.05972000"],["77792.77000000","0.16870000"],["77792.98000000","0.00012000"],["77793.05000000","0.00034000"],["77793.08000000","0.00008000"],["77793.09000000","0.00007000"],["77793.13000000","0.00024000"],["77793.24000000","0.00007000"],["77793.27000000","0.00012000"],["77793.54000000","0.00009000"],["77793.80000000","0.00023000"],["77794.00000000","0.03000000"],["77794.03000000","0.00032000"],["77794.11000000","0.00377000"],["77794.16000000","0.00019000"],["77794.31000000","2.06019000"],["77794.32000000","0.11557000"],["77794.41000000","0.00023000"],["77794.63000000","0.00010000"],["77794.67000000","0.00007000"],["77794.68000000","0.00007000"],["77795.02000000","0.00043000"],["77795.11000000","0.34778000"],["77795.16000000","0.00007000"],["77795.34000000","0.00021000"],["77795.47000000","0.00008000"],["77795.52000000","0.00646000"],["77795.64000000","0.00015000"],["77795.78000000","0.00017000"],["77795.81000000","0.00076000"],["77795.83000000","1.31471000"],["77795.84000000","3.41719000"],["77796.00000000","0.03000000"],["77796.11000000","0.00007000"],["77796.30000000","0.00020000"],["77796.40000000","0.00378000"],["77796.54000000","0.00013000"],["77796.96000000","0.00008000"],["77797.23000000","0.00007000"],["77797.26000000","0.00027000"],["77797.35000000","0.00228000"],["77797.48000000","0.00032000"],["77797.50000000","0.00280000"],["77798.00000000","0.03000000"],["77798.10000000","0.00109000"],["77798.29000000","0.00025000"],["77798.52000000","0.00016000"],["77798.59000000","0.00057000"],["77798.64000000","0.00168000"],["77798.70000000","0.00007000"],["77798.83000000","0.00089000"],["77798.85000000","0.00010000"],["77798.98000000","1.87457000"],["77798.99000000","1.93226000"],["77799.00000000","1.00000000"],["77799.30000000","0.00012000"],["77799.48000000","0.00029000"],["77799.76000000","1.31471000"],["77799.87000000","0.00014000"],["77799.96000000","0.00011000"],["77800.00000000","1.80611000"],["77800.01000000","0.00007000"],["77800.14000000","0.00018000"],["77800.54000000","0.16870000"],["77800.65000000","0.00087000"],["77800.67000000","0.00029000"],["77801.17000000","0.00283000"],["77801.21000000","0.00010000"],["77801.37000000","0.00008000"],["77801.47000000","0.00015000"],["77801.54000000","0.00011000"],["77801.76000000","0.00008000"],["77801.83000000","0.00059000"],["77801.88000000","0.00090000"],["77801.98000000","0.13522000"],["77802.00000000","0.00024000"],["77802.01000000","0.00008000"],["77802.38000000","0.00034000"],["77802.39000000","0.91143000"],["77802.40000000","0.01360000"],["77802.46000000","2.39045000"],["77802.56000000","0.00396000"],["77802.73000000","0.00007000"],["77803.07000000","0.00008000"],["77803.09000000","0.80000000"],["77803.32000000","0.00053000"],["77803.40000000","0.00021000"],["77803.59000000","2.15180000"],["77803.93000000","0.00352000"],["77804.07000000","0.00065000"],["77804.08000000","0.00038000"],["77804.30000000","0.00007000"],["77804.35000000","0.00033000"],["77804.75000000","0.00025000"],["77804.79000000","0.00023000"],["77805.01000000","0.00027000"],["77805.04000000","0.00011000"],["77805.05000000","0.00012000"],["77805.09000000","0.02000000"],["77805.12000000","0.00011000"],["77805.17000000","0.00013000"],["77805.34000000","0.00012000"],["77805.45000000","0.00034000"],["77805.75000000","0.00015000"],["77805.84000000","0.00310000"],["77805.93000000","0.00014000"],["77805.99000000","0.11557000"],["77806.00000000","0.06476000"],["77806.20000000","0.01039000"],["77806.25000000","0.01762000"],["77806.53000000","1.93226000"],["77806.54000000","0.34778000"],["77806.60000000","0.00007000"],["77806.66000000","0.00007000"],["77806.72000000","0.00008000"],["77806.75000000","0.00012000"],["77806.77000000","0.00009000"],["77806.82000000","0.00114000"],["77807.03000000","0.00126000"],["77807.20000000","0.00015000"],["77807.42000000","0.00010000"],["77807.52000000","0.00025000"],["77807.58000000","0.00007000"],["77807.69000000","0.00107000"],["77807.99000000","0.04523000"],["77808.14000000","0.00046000"],["77808.30000000","0.00032000"],["77808.31000000","0.16870000"],["77808.66000000","0.00018000"],["77808.71000000","0.00071000"],["77808.78000000","0.00007000"],["77808.93000000","0.00008000"],["77808.96000000","0.00015000"],["77808.97000000","0.00007000"],["77808.98000000","0.00012000"],["77809.05000000","0.00024000"],["77809.16000000","0.00048000"],["77809.20000000","0.00026000"],["77809.52000000","0.00158000"],["77809.60000000","0.00009000"],["77809.86000000","1.31471000"],["77809.91000000","0.00007000"],["77810.00000000","0.00061000"],["77810.15000000","0.00035000"],["77810.33000000","0.00245000"],["77810.37000000","0.00493000"],["77810.55000000","0.00026000"],["77810.65000000","0.00010000"],["77810.81000000","0.00012000"],["77810.89000000","0.00008000"],["77810.94000000","0.00007000"],["77811.12000000","0.00017000"],["77811.33000000","0.00009000"],["77811.68000000","0.00010000"],["77811.93000000","0.00049000"],["77812.06000000","0.00020000"],["77812.09000000","0.00022000"],["77812.21000000","0.00050000"],["77812.29000000","0.00010000"],["77812.40000000","0.00044000"],["77812.50000000","0.00086000"],["77812.70000000","0.00007000"],["77812.76000000","0.00027000"],["77812.97000000","0.00007000"],["77813.21000000","0.00014000"],["77813.23000000","0.00015000"],["77813.73000000","0.00007000"],["77813.83000000","0.00009000"],["77814.01000000","0.00012000"],["77814.14000000","0.00024000"],["77814.21000000","0.00012000"],["77814.46000000","0.00007000"],["77814.77000000","0.00022000"],["77814.91000000","0.00007000"],["77814.95000000","0.00011000"],["77815.00000000","0.00032000"],["77815.12000000","0.00007000"],["77815.14000000","0.00076000"],["77815.20000000","0.00385000"],["77815.30000000","0.00007000"],["77815.52000000","0.00023000"],["77815.55000000","0.00446000"],["77815.65000000","0.00010000"],["77815.86000000","1.93226000"],["77816.08000000","0.16870000"],["77816.29000000","0.00015000"],["77816.48000000","0.00008000"],["77816.66000000","0.00016000"],["77816.72000000","0.00009000"],["77816.86000000","0.00352000"],["77817.10000000","0.05153000"],["77817.28000000","0.00008000"],["77817.41000000","0.34778000"],["77817.67000000","0.11557000"],["77817.88000000","0.00027000"],["77818.00000000","0.00015000"],["77818.18000000","0.00393000"],["77818.37000000","1.31471000"],["77818.38000000","3.85690000"],["77818.42000000","0.00039000"],["77818.56000000","0.00007000"],["77818.57000000","0.00093000"],["77818.64000000","0.00514000"],["77818.68000000","0.00650000"],["77818.89000000","0.00008000"],["77819.12000000","0.00010000"],["77819.25000000","0.00022000"],["77819.54000000","0.00010000"],["77819.77000000","0.00014000"],["77819.99000000","0.00128000"],["77820.00000000","0.00261000"],["77820.06000000","0.00010000"],["77820.14000000","0.00011000"],["77820.24000000","0.00018000"],["77820.42000000","0.00007000"],["77820.51000000","0.00136000"],["77820.62000000","0.00032000"],["77820.80000000","0.00015000"],["77820.95000000","0.00066000"],["77820.98000000","0.00007000"],["77821.10000000","0.00007000"],["77821.21000000","0.00032000"],["77821.41000000","0.00038000"],["77821.42000000","0.00010000"],["77821.66000000","0.00007000"],["77821.78000000","0.00012000"],["77822.16000000","0.00020000"],["77822.22000000","0.00202000"],["77822.31000000","0.00096000"],["77822.79000000","0.00012000"],["77822.93000000","0.00007000"],["77822.98000000","0.00385000"],["77823.35000000","0.00432000"],["77823.52000000","0.00291000"],["77823.59000000","0.00021000"],["77823.85000000","0.16870000"],["77823.95000000","0.00031000"],["77824.00000000","0.02115000"],["77824.31000000","1.93226000"],["77824.32000000","0.00007000"],["77824.38000000","0.00178000"],["77824.66000000","0.00234000"],["77825.00000000","0.00045000"],["77825.02000000","0.00007000"],["77825.15000000","0.00019000"],["77825.21000000","0.00008000"],["77825.31000000","0.00110000"],["77825.61000000","0.00010000"],["77825.63000000","0.00020000"],["77825.69000000","0.00007000"],["77825.77000000","0.00701000"],["77825.84000000","0.00007000"],["77825.95000000","0.00491000"],["77826.24000000","0.00008000"],["77826.59000000","0.00010000"],["77826.62000000","0.00076000"],["77826.71000000","0.00007000"],["77826.96000000","0.00007000"],["77827.24000000","0.00011000"],["77827.26000000","0.00010000"],["77827.58000000","0.00523000"],["77827.60000000","0.00051000"],["77827.99000000","0.00007000"],["77828.26000000","0.00027000"],["77828.28000000","0.00169000"],["77828.34000000","0.00012000"],["77828.47000000","1.31471000"],["77828.57000000","0.00007000"],["77829.05000000","0.00045000"],["77829.35000000","0.11557000"],["77829.40000000","0.00007000"],["77829.41000000","0.00014000"],["77829.44000000","0.05884000"],["77829.89000000","0.00032000"],["77830.00000000","0.00274000"],["77830.13000000","0.00017000"],["77830.17000000","0.37338000"],["77830.24000000","0.00142000"],["77830.37000000","0.00029000"],["77830.92000000","0.00025000"],["77831.22000000","0.00007000"],["77831.25000000","0.00023000"],["77831.55000000","0.00022000"],["77831.62000000","0.16870000"],["77831.80000000","0.00010000"],["77831.89000000","0.00014000"],["77832.03000000","0.00009000"],["77832.15000000","0.00050000"],["77832.36000000","0.00040000"],["77832.72000000","0.00086000"],["77832.75000000","0.00007000"],["77833.02000000","0.00140000"],["77833.10000000","0.00010000"],["77833.16000000","0.00014000"],["77833.22000000","0.00010000"],["77833.23000000","0.00010000"],["77833.24000000","0.00079000"],["77833.30000000","0.00011000"],["77833.33000000","0.02019000"],["77833.38000000","0.00352000"],["77833.61000000","0.00007000"],["77833.66000000","0.00108000"],["77833.72000000","0.00152000"],["77833.98000000","0.00007000"],["77834.09000000","0.00269000"],["77834.36000000","0.00022000"],["77834.44000000","0.00013000"],["77834.70000000","0.04627000"],["77834.75000000","0.00007000"],["77835.00000000","0.00011000"],["77835.11000000","0.00007000"],["77835.38000000","0.00011000"],["77835.71000000","0.00011000"],["77835.92000000","0.00008000"],["77835.98000000","0.00008000"],["77836.00000000","0.01307000"],["77836.01000000","0.00027000"],["77836.11000000","0.01541000"],["77836.82000000","0.00007000"],["77836.85000000","0.00182000"],["77836.87000000","0.00181000"],["77837.15000000","0.00008000"],["77837.17000000","0.00128000"],["77837.21000000","0.00053000"],["77837.24000000","0.00018000"],["77837.49000000","0.00007000"],["77837.74000000","0.00013000"],["77837.80000000","0.01274000"],["77837.89000000","0.00010000"],["77838.02000000","0.00019000"],["77838.11000000","0.00009000"],["77838.23000000","0.00102000"],["77838.24000000","0.00011000"],["77838.30000000","0.00228000"],["77838.35000000","0.00051000"],["77838.46000000","0.00130000"],["77838.57000000","1.31471000"],["77838.60000000","0.00413000"],["77839.00000000","0.00020000"],["77839.38000000","0.00007000"],["77839.39000000","0.16870000"],["77839.57000000","0.00177000"],["77839.86000000","0.00007000"],["77839.97000000","0.00971000"],["77840.00000000","0.00395000"],["77840.07000000","0.00013000"],["77840.33000000","0.00010000"],["77840.35000000","0.03255000"],["77840.45000000","0.00007000"],["77840.53000000","0.00008000"],["77840.54000000","0.00034000"],["77840.59000000","0.00033000"],["77840.71000000","0.00008000"],["77840.72000000","0.00007000"],["77840.90000000","0.00040000"],["77840.95000000","0.00016000"],["77841.00000000","0.00007000"],["77841.03000000","0.03983000"],["77841.19000000","0.00024000"],["77841.22000000","0.00342000"],["77841.46000000","0.00038000"],["77841.55000000","0.00010000"],["77841.61000000","0.00011000"],["77841.73000000","0.00021000"],["77841.78000000","0.00074000"],["77842.10000000","0.00063000"],["77842.18000000","0.00013000"],["77842.86000000","0.00008000"],["77842.87000000","0.00009000"],["77842.95000000","0.00007000"],["77843.06000000","0.00056000"],["77843.12000000","0.00043000"]]}}
{"type":"depth","received_at_ms":1788333138649,"data":{"e":"depthUpdate","E":1788333138814,"s":"BTCUSDT","U":99556309914,"u":99556309954,"b":[["77704.65000000","0.00257000"],["77703.77000000","0.00000000"],["77699.58000000","0.11129000"],["69937.56000000","0.00448000"]],"a":[["77708.40000000","1.91280000"],["77708.41000000","0.00125000"],["77708.46000000","0.00000000"],["77708.47000000","0.00014000"],["77710.19000000","0.00014000"],["77710.20000000","0.00622000"],["77710.21000000","0.09887000"],["77711.14000000","0.00014000"],["77712.73000000","0.00014000"],["77714.64000000","0.00000000"],["77715.35000000","0.00400000"],["77716.23000000","0.00600000"],["77716.46000000","0.46034000"],["77719.30000000","0.00000000"],["77720.19000000","0.00257000"]]}}
{"type":"depth","received_at_ms":1788333138748,"data":{"e":"depthUpdate","E":1788333138914,"s":"BTCUSDT","U":99556309955,"u":99556310005,"b":[["77708.36000000","0.08775000"],["77707.18000000","0.00188000"],["77705.71000000","0.01337000"],["77705.65000000","0.11129000"],["77705.39000000","0.00255000"],["77705.38000000","0.00400000"],["77705.05000000","0.00000000"],["77703.61000000","0.00000000"],["77703.09000000","0.00000000"],["77689.47000000","0.34770000"],["77665.69000000","0.00000000"],["77655.16000000","0.00411000"],["69937.56000000","0.00432000"]],"a":[["77708.40000000","1.64827000"],["77708.41000000","0.00111000"],["77708.47000000","0.00000000"],["77710.19000000","0.00000000"],["77710.20000000","0.00643000"],["77711.14000000","0.00014000"],["77712.45000000","0.00000000"],["77712.46000000","0.00014000"],["77715.35000000","0.00000000"],["77716.21000000","0.00000000"],["77716.23000000","0.00607000"],["77716.27000000","0.00400000"],["77717.47000000","0.00048000"],["77717.48000000","0.00070000"],["77726.41000000","0.00000000"],["77727.89000000","0.09622000"],["77746.98000000","0.00000000"]]}}
{"type":"trade","received_at_ms":1788333138765,"data":{"e":"trade","E":1788333138930,"s":"BTCUSDT","t":6646665150,"p":"77708.40000000","q":"0.00064000","T":1788333138930,"m":false,"M":true}}
{"type":"trade","received_at_ms":1788333138840,"data":{"e":"trade","E":1788333139002,"s":"BTCUSDT","t":6646665151,"p":"77708.40000000","q":"0.01500000","T":1788333139001,"m":false,"M":true}}
{"type":"depth","received_at_ms":1788333138849,"data":{"e":"depthUpdate","E":1788333139014,"s":"BTCUSDT","U":99556310006,"u":99556310050,"b":[["77705.71000000","0.01330000"],["77705.46000000","0.00257000"],["77704.66000000","0.02000000"],["77704.65000000","0.00000000"],["77669.22000000","0.00000000"],["77507.33000000","0.00812000"],["77506.01000000","0.00000000"],["69937.56000000","0.00448000"],["69937.55000000","0.00000000"],["62167.00000000","0.00250000"],["62166.72000000","0.00032000"],["40899.20000000","0.00000000"]],"a":[["77708.40000000","1.63256000"],["77708.41000000","0.00111000"],["77708.62000000","0.00007000"],["77709.02000000","0.00000000"],["77710.21000000","0.09901000"],["77712.27000000","0.00571000"],["77712.46000000","0.00000000"],["77714.76000000","0.01129000"],["77716.21000000","0.09622000"],["77720.19000000","0.00000000"],["77727.89000000","0.00000000"],["77745.58000000","0.00000000"],["77745.83000000","0.00000000"],["77745.88000000","0.00000000"],["77756.43000000","0.00425000"]]}}
{"type":"depth","received_at_ms":1788333138949,"data":{"e":"depthUpdate","E":1788333139114,"s":"BTCUSDT","U":99556310051,"u":99556310058,"b":[["77689.77000000","0.02007000"],["77652.43000000","0.25743000"],["77643.97000000","0.00000000"],["69937.56000000","0.00432000"]],"a":[["77711.46000000","0.13616000"],["77716.76000000","0.00000000"],["77720.87000000","0.00007000"]]}}
{"type":"depth","received_at_ms":1788333139049,"data":{"e":"depthUpdate","E":1788333139214,"s":"BTCUSDT","U":99556310059,"u":99556310081,"b":[["69937.56000000","0.00448000"],["62166.72000000","0.00000000"],["62166.71000000","0.00000000"]],"a":[["77708.40000000","1.66680000"],["77708.41000000","0.00118000"],["77710.20000000","0.00028000"],["77711.15000000","0.01867000"],["77711.17000000","0.02909000"],["77711.45000000","0.00007000"],["77711.46000000","0.13630000"],["77714.76000000","0.01115000"],["77716.21000000","0.00000000"],["77716.23000000","0.00600000"],["77726.70000000","0.09622000"]]}}
{"type":"depth","received_at_ms":1788333139148,"data":{"e":"depthUpdate","E":1788333139314,"s":"BTCUSDT","U":99556310082,"u":99556310089,"b":[["69937.56000000","0.00432000"]],"a":[["77708.40000000","1.81621000"],["77710.20000000","0.00014000"]]}}
{"type":"trade","received_at_ms":1788333139213,"data":{"e":"trade","E":1788333139379,"s":"BTCUSDT","t":6646665152,"p":"77708.40000000","q":"0.00168000","T":1788333139378,"m":false,"M":true}}
{"type":"depth","received_at_ms":1788333139249,"data":{"e":"depthUpdate","E":1788333139414,"s":"BTCUSDT","U":99556310090,"u":99556310113,"b":[["77707.18000000","0.00000000"],["77706.35000000","0.00188000"],["77700.00000000","0.70007000"],["77642.84000000","0.00000000"],["77564.01000000","0.00000000"],["69937.56000000","0.00457000"]],"a":[["77708.40000000","1.81596000"],["77708.41000000","0.00111000"],["77709.75000000","0.00007000"],["77709.76000000","0.13134000"],["77710.64000000","0.00000000"],["77710.65000000","0.00000000"],["77711.45000000","0.00000000"],["77711.46000000","0.00014000"],["77745.72000000","0.00000000"]]}}
{"type":"depth","received_at_ms":1788333139348,"data":{"e":"depthUpdate","E":1788333139514,"s":"BTCUSDT","U":99556310114,"u":99556310140,"b":[["77642.84000000","0.00320000"],["77564.01000000","0.00128000"],["76542.76000000","0.00030000"],["69937.56000000","0.00441000"],["69937.00000000","0.00020000"],["62167.00000000","0.00450000"],["62166.72000000","0.00032000"]],"a":[["77708.40000000","1.81610000"],["77708.41000000","0.00111000"],["77709.76000000","0.13148000"],["77711.17000000","0.02895000"],["77711.46000000","0.00000000"],["77800.24000000","0.00411000"],["78874.03000000","0.00030000"]]}}
{"type":"depth","received_at_ms":1788333139449,"data":{"e":"depthUpdate","E":1788333139614,"s":"BTCUSDT","U":99556310141,"u":99556310203,"b":[["77708.39000000","1.95611000"],["77708.38000000","0.00145000"],["77707.63000000","0.00000000"],["77706.21000000","0.00257000"],["77705.46000000","0.00000000"],["77705.38000000","0.00000000"],["77705.22000000","0.00400000"],["77694.90000000","0.37338000"],["77694.89000000","0.00000000"],["77686.15000000","0.37338000"],["77686.14000000","0.00000000"],["75557.14000000","0.00000000"],["69937.56000000","0.00441000"],["69937.00000000","0.00000000"],["62166.72000000","0.00000000"],["62166.71000000","0.00000000"]],"a":[["77708.40000000","1.64021000"],["77708.41000000","0.00118000"],["77709.75000000","0.00014000"],["77710.20000000","0.00000000"],["77710.21000000","0.00606000"],["77711.14000000","0.00000000"],["77711.15000000","0.01289000"],["77711.84000000","0.00007000"],["77711.85000000","0.09887000"],["77712.75000000","0.00208000"],["77712.84000000","0.00000000"],["77712.95000000","0.00027000"],["77716.20000000","0.00014000"],["77716.21000000","0.09622000"],["77716.23000000","0.00600000"],["77726.70000000","0.00000000"],["77746.51000000","0.12874000"],["77748.02000000","0.00007000"],["81001.14000000","0.00000000"]]}}
{"type":"depth","received_at_ms":1788333139549,"data":{"e":"depthUpdate","E":1788333139714,"s":"BTCUSDT","U":99556310204,"u":99556310215,"b":[["77694.01000000","0.00072000"],["77655.16000000","0.00000000"],["77624.08000000","0.00411000"],["69937.56000000","0.00425000"]],"a":[["77708.40000000","1.49094000"],["77712.75000000","0.00000000"],["77716.76000000","0.00007000"],["77730.26000000","0.00000000"],["77746.51000000","0.00000000"],["77769.15000000","0.00000000"],["77800.24000000","0.00000000"]]}}
{"type":"depth","received_at_ms":1788333139648,"data":{"e":"depthUpdate","E":1788333139814,"s":"BTCUSDT","U":99556310216,"u":99556310220,"b":[["69937.56000000","0.00441000"]],"a":[["77708.40000000","1.64033000"]]}}
{"type":"trade","received_at_ms":1788333139693,"data":{"e":"trade","E":1788333139857,"s":"BTCUSDT","t":6646665153,"p":"77708.40000000","q":"0.00012000","T":1788333139857,"m":false,"M":true}}
{"type":"depth","received_at_ms":1788333139750,"data":{"e":"depthUpdate","E":1788333139914,"s":"BTCUSDT","U":99556310221,"u":99556310265,"b":[["77708.39000000","1.95618000"],["77708.38000000","0.00152000"],["77678.67000000","0.04555000"],["77674.85000000","0.00000000"],["77655.16000000","0.00411000"],["69937.56000000","0.00448000"],["69937.55000000","0.00009000"]],"a":[["77708.40000000","1.64171000"],["77708.41000000","0.00118000"],["77708.81000000","0.00014000"],["77708.82000000","0.12975000"],["77709.75000000","0.00000000"],["77709.76000000","0.00014000"],["77710.21000000","0.00014000"],["77711.14000000","0.00014000"],["77711.15000000","0.01908000"],["77711.84000000","0.00014000"],["77712.73000000","0.00007000"],["77716.20000000","0.00000000"],["77746.62000000","0.00007000"]]}}
{"type":"trade","received_at_ms":1788333139798,"data":{"e":"trade","E":1788333139964,"s":"BTCUSDT","t":6646665154,"p":"77708.40000000","q":"0.00021000","T":1788333139963,"m":false,"M":true}}
{"type":"depth","received_at_ms":1788333139851,"data":{"e":"depthUpdate","E":1788333140014,"s":"BTCUSDT","U":99556310266,"u":99556310291,"b":[["77708.39000000","1.95646000"],["77708.38000000","0.00166000"],["69937.56000000","0.00416000"],["69937.00000000","0.00010000"],["62166.72000000","0.00032000"]],"a":[["77708.40000000","1.64740000"],["77708.41000000","0.00111000"],["77708.82000000","0.12989000"],["77709.76000000","0.00000000"],["77710.21000000","0.00000000"],["77720.95000000","0.00257000"]]}}
{"type":"trade","received_at_ms":1788333139874,"data":{"e":"trade","E":1788333140039,"s":"BTCUSDT","t":6646665155,"p":"77708.39000000","q":"0.00726000","T":1788333140038,"m":true,"M":true}}
{"type":"trade","received_at_ms":1788333139874,"data":{"e":"trade","E":1788333140039,"s":"BTCUSDT","t":6646665156,"p":"77708.39000000","q":"0.00007000","T":1788333140038,"m":true,"M":true}}
{"type":"trade","received_at_ms":1788333139874,"data":{"e":"trade","E":1788333140039,"s":"BTCUSDT","t":6646665157,"p":"77708.39000000","q":"0.00007000","T":1788333140038,"m":true,"M":true}}
{"type":"trade","received_at_ms":1788333139874,"data":{"e":"trade","E":1788333140039,"s":"BTCUSDT","t":6646665158,"p":"77708.39000000","q":"0.00760000","T":1788333140038,"m":true,"M":true}}
{"type":"trade","received_at_ms":1788333139880,"data":{"e":"trade","E":1788333140043,"s":"BTCUSDT","t":6646665159,"p":"77708.39000000","q":"0.01240000","T":1788333140043,"m":true,"M":true}}
{"type":"trade","received_at_ms":1788333139880,"data":{"e":"trade","E":1788333140043,"s":"BTCUSDT","t":6646665160,"p":"77708.39000000","q":"0.02000000","T":1788333140043,"m":true,"M":true}}
{"type":"trade","received_at_ms":1788333139880,"data":{"e":"trade","E":1788333140043,"s":"BTCUSDT","t":6646665161,"p":"77708.39000000","q":"0.00016000","T":1788333140043,"m":true,"M":true}}
{"type":"trade","received_at_ms":1788333139880,"data":{"e":"trade","E":1788333140043,"s":"BTCUSDT","t":6646665162,"p":"77708.39000000","q":"0.00325000","T":1788333140043,"m":true,"M":true}}
{"type":"trade","received_at_ms":1788333139880,"data":{"e":"trade","E":1788333140043,"s":"BTCUSDT","t":6646665163,"p":"77708.39000000","q":"0.00007000","T":1788333140043,"m":true,"M":true}}
{"type":"trade","received_at_ms":1788333139880,"data":{"e":"trade","E":1788333140043,"s":"BTCUSDT","t":6646665164,"p":"77708.39000000","q":"0.00008000","T":1788333140043,"m":true,"M":true}}
{"type":"trade","received_at_ms":1788333139880,"data":{"e":"trade","E":1788333140043,"s":"BTCUSDT","t":6646665165,"p":"77708.39000000","q":"0.00065000","T":1788333140043,"m":true,"M":true}}
{"type":"trade","received_at_ms":1788333139880,"data":{"e":"trade","E":1788333140043,"s":"BTCUSDT","t":6646665166,"p":"77708.39000000","q":"0.00064000","T":1788333140043,"m":true,"M":true}}
{"type":"trade","received_at_ms":1788333139880,"data":{"e":"trade","E":1788333140043,"s":"BTCUSDT","t":6646665167,"p":"77708.39000000","q":"0.02000000","T":1788333140043,"m":true,"M":true}}
{"type":"trade","received_at_ms":1788333139880,"data":{"e":"trade","E":1788333140043,"s":"BTCUSDT","t":6646665168,"p":"77708.39000000","q":"0.01000000","T":1788333140043,"m":true,"M":true}}
{"type":"trade","received_at_ms":1788333139880,"data":{"e":"trade","E":1788333140043,"s":"BTCUSDT","t":6646665169,"p":"77708.39000000","q":"0.00013000","T":1788333140043,"m":true,"M":true}}
{"type":"trade","received_at_ms":1788333139880,"data":{"e":"trade","E":1788333140043,"s":"BTCUSDT","t":6646665170,"p":"77708.39000000","q":"0.06129000","T":1788333140043,"m":true,"M":true}}
{"type":"trade","received_at_ms":1788333139880,"data":{"e":"trade","E":1788333140043,"s":"BTCUSDT","t":6646665171,"p":"77708.39000000","q":"0.02000000","T":1788333140043,"m":true,"M":true}}
{"type":"trade","received_at_ms":1788333139880,"data":{"e":"trade","E":1788333140043,"s":"BTCUSDT","t":6646665172,"p":"77708.39000000","q":"0.02000000","T":1788333140043,"m":true,"M":true}}
{"type":"trade","received_at_ms":1788333139880,"data":{"e":"trade","E":1788333140043,"s":"BTCUSDT","t":6646665173,"p":"77708.39000000","q":"0.02000000","T":1788333140043,"m":true,"M":true}}
{"type":"trade","received_at_ms":1788333139880,"data":{"e":"trade","E":1788333140043,"s":"BTCUSDT","t":6646665174,"p":"77708.39000000","q":"0.01000000","T":1788333140043,"m":true,"M":true}}
{"type":"depth","received_at_ms":1788333139948,"data":{"e":"depthUpdate","E":1788333140114,"s":"BTCUSDT","U":99556310292,"u":99556310338,"b":[["77708.39000000","1.87613000"],["77705.71000000","0.01337000"],["77705.65000000","0.11136000"],["77705.39000000","0.00000000"],["77705.22000000","0.00000000"],["77704.30000000","0.00257000"],["77704.16000000","0.00400000"],["77700.01000000","0.00800000"],["77696.81000000","0.00000000"],["77689.77000000","0.02000000"],["69937.56000000","0.00448000"],["69937.00000000","0.00000000"]],"a":[["77708.40000000","1.64813000"],["77711.17000000","0.02909000"],["77711.85000000","0.09901000"],["77714.76000000","0.01129000"],["77720.87000000","0.00000000"],["77730.31000000","0.00411000"]]}}
{"type":"trade","received_at_ms":1788333140009,"data":{"e":"trade","E":1788333140173,"s":"BTCUSDT","t":6646665175,"p":"77708.39000000","q":"0.00167000","T":1788333140173,"m":true,"M":true}}
{"type":"depth","received_at_ms":1788333140049,"data":{"e":"depthUpdate","E":1788333140214,"s":"BTCUSDT","U":99556310339,"u":99556310353,"b":[["77708.39000000","1.87446000"],["77689.77000000","0.02007000"],["77508.01000000","0.00812000"],["77507.33000000","0.00000000"],["69937.56000000","0.00432000"],["69937.55000000","0.00000000"],["62166.72000000","0.00000000"],["62166.71000000","0.00000000"]],"a":[["77720.87000000","0.00007000"],["77746.42000000","0.00000000"],["77746.44000000","0.00000000"]]}}
{"type":"depth","received_at_ms":1788333140150,"data":{"e":"depthUpdate","E":1788333140316,"s":"BTCUSDT","U":99556310354,"u":99556310365,"b":[["77704.43000000","0.00400000"],["69937.56000000","0.00448000"],["62167.00000000","0.00450000"],["40899.20000000","0.00037000"]],"a":[["77708.40000000","1.64820000"],["77715.32000000","0.00400000"],["77800.27000000","0.00411000"]]}}
{"type":"depth","received_at_ms":1788333140249,"data":{"e":"depthUpdate","E":1788333140414,"s":"BTCUSDT","U":99556310366,"u":99556310379,"b":[["77708.39000000","1.89466000"],["77700.61000000","0.00009000"],["77692.84000000","0.00009000"],["77685.07000000","0.00009000"],["77679.15000000","0.00000000"],["77677.30000000","0.00009000"],["77655.07000000","0.00000000"],["69937.56000000","0.00432000"]],"a":[]}}
{"type":"depth","received_at_ms":1788333140348,"data":{"e":"depthUpdate","E":1788333140514,"s":"BTCUSDT","U":99556310380,"u":99556310418,"b":[["77708.39000000","1.91466000"],["77704.82000000","0.00400000"],["77704.43000000","0.00000000"],["77704.36000000","0.00400000"],["77704.16000000","0.00000000"],["77700.02000000","0.00800000"],["77700.01000000","0.00000000"],["77694.01000000","0.00483000"],["77630.93000000","0.99828000"],["77627.49000000","1.61379000"],["77624.90000000","0.00000000"],["76542.76000000","0.00030000"],["69937.56000000","0.00448000"],["69937.00000000","0.00010000"],["62166.72000000","0.00032000"]],"a":[["77708.40000000","1.63642000"],["77708.41000000","0.00118000"],["77708.64000000","0.00000000"],["77711.14000000","0.00000000"],["77711.15000000","0.01289000"],["77711.16000000","0.00641000"],["77712.73000000","0.00014000"],["77716.20000000","0.09622000"],["77716.21000000","0.00000000"],["77716.23000000","0.00607000"],["77726.70000000","0.00000000"],["78874.03000000","0.00030000"]]}}
{"type":"depth","received_at_ms":1788333140450,"data":{"e":"depthUpdate","E":1788333140615,"s":"BTCUSDT","U":99556310419,"u":99556310445,"b":[["75556.95000000","0.00010000"],["69937.56000000","0.00432000"],["69937.00000000","0.00000000"],["62167.00000000","0.00450000"],["62166.72000000","0.00000000"],["62166.71000000","0.00000000"]],"a":[["77711.15000000","0.01289000"],["77711.16000000","0.00655000"],["77714.76000000","0.01115000"]]}}
{"type":"depth","received_at_ms":1788333140548,"data":{"e":"depthUpdate","E":1788333140714,"s":"BTCUSDT","U":99556310446,"u":99556310504,"b":[["77708.39000000","1.91438000"],["77708.38000000","0.00145000"],["77707.48000000","0.00257000"],["77706.21000000","0.00000000"],["77694.01000000","0.00072000"],["77655.16000000","0.00000000"],["77624.08000000","0.00000000"],["77508.01000000","0.00000000"],["77507.33000000","0.00812000"],["69937.56000000","0.00448000"]],"a":[["77711.84000000","0.00000000"],["77711.85000000","0.00014000"],["77713.30000000","0.00208000"],["77716.20000000","0.00000000"],["77716.21000000","0.09622000"],["77716.23000000","0.00614000"],["77716.24000000","1.93233000"],["77720.95000000","0.00000000"],["77723.02000000","0.00257000"],["77727.53000000","0.00000000"],["77730.31000000","0.00000000"],["77747.11000000","0.00000000"],["77769.18000000","0.00000000"],["77800.27000000","0.00000000"]]}}
{"type":"depth","received_at_ms":1788333140649,"data":{"e":"depthUpdate","E":1788333140814,"s":"BTCUSDT","U":99556310505,"u":99556310547,"b":[["77708.39000000","1.92459000"],["77708.38000000","0.00166000"],["77707.48000000","0.00000000"],["77705.82000000","0.00257000"],["77686.39000000","0.49735000"],["77662.97000000","1.01343000"],["69937.56000000","0.00432000"]],"a":[["77708.40000000","1.63642000"],["77708.41000000","0.00118000"],["77711.16000000","0.00028000"],["77711.17000000","0.02909000"],["77711.45000000","0.00007000"],["77711.46000000","0.09887000"],["77711.85000000","0.00000000"],["77713.30000000","0.00000000"],["77714.76000000","0.01129000"],["77716.20000000","0.00007000"],["77716.23000000","0.00607000"],["77716.24000000","1.93226000"],["77721.35000000","0.00257000"],["77723.02000000","0.00000000"],["77748.02000000","0.00000000"]]}}
{"type":"depth","received_at_ms":1788333140753,"data":{"e":"depthUpdate","E":1788333140914,"s":"BTCUSDT","U":99556310548,"u":99556310566,"b":[["69937.56000000","0.00432000"],["69937.00000000","0.00010000"]],"a":[["77711.15000000","0.01289000"],["77711.16000000","0.00014000"],["77711.17000000","0.02909000"],["77711.46000000","0.09901000"],["77773.02000000","0.00411000"],["81001.33000000","0.00010000"]]}}
{"type":"trade","received_at_ms":1788333140791,"data":{"e":"trade","E":1788333140951,"s":"BTCUSDT","t":6646665176,"p":"77708.40000000","q":"0.00607000","T":1788333140950,"m":false,"M":true}}
{"type":"depth","received_at_ms":1788333140849,"data":{"e":"depthUpdate","E":1788333141014,"s":"BTCUSDT","U":99556310567,"u":99556310581,"b":[["77708.39000000","1.92431000"],["77708.38000000","0.00138000"],["69937.56000000","0.00441000"],["69937.00000000","0.00010000"],["62166.72000000","0.00032000"]],"a":[["77708.40000000","1.63028000"],["77708.41000000","0.00111000"]]}}
{"type":"depth","received_at_ms":1788333140948,"data":{"e":"depthUpdate","E":1788333141114,"s":"BTCUSDT","U":99556310582,"u":99556310589,"b":[["77508.01000000","0.00812000"],["77507.33000000","0.00000000"],["69937.56000000","0.00441000"],["69937.00000000","0.00000000"]],"a":[["77711.17000000","0.03518000"],["77804.12000000","0.00411000"]]}}
{"type":"depth","received_at_ms":1788333141050,"data":{"e":"depthUpdate","E":1788333141215,"s":"BTCUSDT","U":99556310590,"u":99556310607,"b":[["77689.77000000","0.02007000"],["69937.56000000","0.00441000"],["69937.55000000","0.00027000"],["62166.72000000","0.00000000"],["62166.71000000","0.00000000"],["40899.20000000","0.00000000"]],"a":[["77711.45000000","0.00014000"],["77716.18000000","0.09630000"],["77716.19000000","0.00000000"],["77716.20000000","0.00000000"],["77716.21000000","0.00000000"],["77720.87000000","0.00007000"],["77727.53000000","0.00000000"]]}}
{"type":"depth","received_at_ms":1788333141149,"data":{"e":"depthUpdate","E":1788333141315,"s":"BTCUSDT","U":99556310608,"u":99556310613,"b":[["69937.56000000","0.00441000"]],"a":[["77716.18000000","0.00008000"],["77727.53000000","0.09622000"],["77729.26000000","0.00000000"],["77729.80000000","0.00128000"],["77745.87000000","0.12874000"]]}}
{"type":"depth","received_at_ms":1788333141249,"data":{"e":"depthUpdate","E":1788333141414,"s":"BTCUSDT","U":99556310614,"u":99556310617,"b":[["69937.56000000","0.00457000"]],"a":[["77708.40000000","1.49267000"]]}}
{"type":"depth","received_at_ms":1788333141348,"data":{"e":"depthUpdate","E":1788333141514,"s":"BTCUSDT","U":99556310618,"u":99556310629,"b":[["77623.05000000","0.00411000"],["76542.76000000","0.00030000"],["69937.56000000","0.00441000"],["62166.72000000","0.00032000"]],"a":[["77708.40000000","1.62665000"],["77711.17000000","0.02909000"],["77745.87000000","0.00000000"],["78874.03000000","0.00030000"]]}}
{"type":"depth","received_at_ms":1788333141448,"data":{"e":"depthUpdate","E":1788333141614,"s":"BTCUSDT","U":99556310630,"u":99556310640,"b":[["77704.37000000","0.00643000"],["77703.55000000","0.00000000"],["77703.21000000","0.00643000"],["77700.89000000","0.00000000"],["77637.08000000","0.00000000"],["77637.07000000","0.00320000"],["69937.56000000","0.00441000"],["62167.00000000","0.00650000"],["62166.72000000","0.00000000"],["62166.71000000","0.00000000"]],"a":[["77715.29000000","0.00000000"],["77715.77000000","0.00643000"],["77717.46000000","0.00643000"],["77719.11000000","0.00000000"]]}}
{"type":"depth","received_at_ms":1788333141548,"data":{"e":"depthUpdate","E":1788333141714,"s":"BTCUSDT","U":99556310641,"u":99556310663,"b":[["77704.66000000","0.02007000"],["77704.28000000","0.10272000"],["77701.62000000","0.11048000"],["69937.56000000","0.00441000"],["69937.00000000","0.00000000"],["62167.00000000","0.00450000"]],"a":[["77708.40000000","1.49117000"],["77714.76000000","0.01129000"],["77717.46000000","0.00000000"],["77717.75000000","0.00643000"],["77734.15000000","0.00411000"]]}}
{"type":"depth","received_at_ms":1788333141649,"data":{"e":"depthUpdate","E":1788333141814,"s":"BTCUSDT","U":99556310664,"u":99556310673,"b":[["69937.56000000","0.00457000"]],"a":[["77708.40000000","1.80322000"],["77711.17000000","0.03117000"]]}}
{"type":"depth","received_at_ms":1788333141749,"data":{"e":"depthUpdate","E":1788333141914,"s":"BTCUSDT","U":99556310674,"u":99556310680,"b":[["77692.98000000","0.00411000"],["69937.56000000","0.00425000"]],"a":[["77708.40000000","1.80172000"],["77745.76000000","0.12874000"],["77746.07000000","0.00000000"]]}}
{"type":"depth","received_at_ms":1788333141860,"data":{"e":"depthUpdate","E":1788333142014,"s":"BTCUSDT","U":99556310681,"u":99556310690,"b":[["69937.56000000","0.00457000"],["62167.00000000","0.00450000"],["62166.72000000","0.00032000"]],"a":[["77708.40000000","1.80322000"],["77715.29000000","0.00643000"],["77715.77000000","0.00000000"],["77745.76000000","0.00000000"]]}}
{"type":"depth","received_at_ms":1788333141948,"data":{"e":"depthUpdate","E":1788333142114,"s":"BTCUSDT","U":99556310691,"u":99556310709,"b":[["77704.66000000","0.02000000"],["77704.37000000","0.00000000"],["77704.28000000","0.10279000"],["77703.61000000","0.00643000"],["77692.98000000","0.00000000"],["77654.13000000","0.00411000"],["77623.05000000","0.00000000"],["69937.56000000","0.00457000"]],"a":[["77708.40000000","1.80322000"],["77714.76000000","0.01129000"],["77734.15000000","0.00000000"],["77773.02000000","0.00000000"],["77804.12000000","0.00000000"]]}}
{"type":"depth","received_at_ms":1788333142049,"data":{"e":"depthUpdate","E":1788333142214,"s":"BTCUSDT","U":99556310710,"u":99556310722,"b":[["77689.77000000","0.02007000"],["69937.56000000","0.00473000"],["62166.72000000","0.00000000"],["62166.71000000","0.00000000"]],"a":[["77708.40000000","1.63732000"],["77716.21000000","0.09622000"],["77717.24000000","0.00643000"],["77717.75000000","0.00000000"],["77720.87000000","0.00007000"],["77727.53000000","0.00000000"]]}}
{"type":"depth","received_at_ms":1788333142149,"data":{"e":"depthUpdate","E":1788333142314,"s":"BTCUSDT","U":99556310723,"u":99556310727,"b":[["69937.56000000","0.00457000"],["62167.00000000","0.00450000"]],"a":[]}}
{"type":"depth","received_at_ms":1788333142249,"data":{"e":"depthUpdate","E":1788333142414,"s":"BTCUSDT","U":99556310728,"u":99556310734,"b":[["69937.56000000","0.00457000"],["69937.55000000","0.00000000"]],"a":[["77716.20000000","0.09622000"],["77716.21000000","0.00000000"],["77727.53000000","0.00000000"]]}}
{"type":"trade","received_at_ms":1788333142250,"data":{"e":"trade","E":1788333142414,"s":"BTCUSDT","t":6646665177,"p":"77708.40000000","q":"0.02579000","T":1788333142414,"m":false,"M":true}}
{"type":"depth","received_at_ms":1788333142348,"data":{"e":"depthUpdate","E":1788333142514,"s":"BTCUSDT","U":99556310735,"u":99556310753,"b":[["76542.76000000","0.00030000"],["69937.56000000","0.00448000"],["69937.55000000","0.00009000"],["62167.00000000","0.00450000"],["62166.72000000","0.00032000"]],"a":[["77708.40000000","1.61003000"],["77716.19000000","0.09622000"],["77716.20000000","0.00000000"],["77727.53000000","0.00000000"],["77745.83000000","0.00000000"],["77746.09000000","0.00000000"],["77804.12000000","0.00411000"],["78874.03000000","0.00030000"]]}}
{"type":"depth","received_at_ms":1788333142453,"data":{"e":"depthUpdate","E":1788333142614,"s":"BTCUSDT","U":99556310754,"u":99556310760,"b":[["69937.56000000","0.00448000"],["62166.72000000","0.00000000"],["62166.71000000","0.00000000"]],"a":[["77746.10000000","0.00000000"]]}}
{"type":"trade","received_at_ms":1788333142453,"data":{"e":"trade","E":1788333142614,"s":"BTCUSDT","t":6646665178,"p":"77708.40000000","q":"0.01500000","T":1788333142614,"m":false,"M":true}}
{"type":"trade","received_at_ms":1788333142472,"data":{"e":"trade","E":1788333142636,"s":"BTCUSDT","t":6646665179,"p":"77708.40000000","q":"0.04292000","T":1788333142636,"m":false,"M":true}}
{"type":"depth","received_at_ms":1788333142549,"data":{"e":"depthUpdate","E":1788333142714,"s":"BTCUSDT","U":99556310761,"u":99556310767,"b":[["77708.39000000","1.92457000"],["77692.98000000","0.00411000"],["69937.56000000","0.00448000"]],"a":[["77708.40000000","1.55211000"],["77717.24000000","0.00000000"],["77717.98000000","0.00643000"]]}}
{"type":"depth","received_at_ms":1788333142658,"data":{"e":"depthUpdate","E":1788333142814,"s":"BTCUSDT","U":99556310768,"u":99556311021,"b":[["77708.39000000","2.07610000"],["77708.38000000","0.00166000"],["77707.51000000","0.00000000"],["77707.29000000","0.00000000"],["77707.28000000","0.00257000"],["77707.18000000","0.00257000"],["77707.15000000","0.01671000"],["77707.08000000","0.00000000"],["77707.03000000","0.00007000"],["77707.02000000","0.11129000"],["77706.49000000","0.00400000"],["77706.35000000","0.00400000"],["77705.92000000","0.00007000"],["77705.82000000","0.00000000"],["77705.65000000","0.11143000"],["77704.98000000","0.00000000"],["77704.82000000","0.00000000"],["77704.36000000","0.00000000"],["77704.30000000","0.00000000"],["77700.90000000","0.02000000"],["77700.55000000","0.00000000"],["77700.03000000","0.11129000"],["77699.59000000","0.37338000"],["77699.58000000","0.00000000"],["77694.90000000","0.00000000"],["77693.10000000","0.04000000"],["77689.04000000","0.00200000"],["77681.89000000","0.00000000"],["77659.07000000","0.00626000"],["77647.50000000","0.00000000"],["77647.31000000","0.00000000"],["69937.56000000","0.00448000"]],"a":[["77708.40000000","1.09323000"],["77708.41000000","0.00111000"],["77708.81000000","0.00000000"],["77708.82000000","0.00014000"],["77711.14000000","0.00014000"],["77711.17000000","0.02909000"],["77711.45000000","0.00000000"],["77711.46000000","0.00014000"],["77712.50000000","0.00014000"],["77712.51000000","0.11129000"],["77712.56000000","0.00014000"],["77712.73000000","0.00000000"],["77712.74000000","0.00014000"],["77712.95000000","0.00000000"],["77713.05000000","0.00027000"],["77713.87000000","0.00014000"],["77713.88000000","0.11129000"],["77714.98000000","0.00000000"],["77714.99000000","0.00000000"],["77715.24000000","0.00014000"],["77715.25000000","0.11129000"],["77715.29000000","0.00000000"],["77715.32000000","0.00000000"],["77715.77000000","0.00000000"],["77715.78000000","0.00000000"],["77715.83000000","0.00000000"],["77715.84000000","0.00139000"],["77715.87000000","0.00000000"],["77715.96000000","0.00000000"],["77716.16000000","0.00000000"],["77716.17000000","0.63504000"],["77716.18000000","3.37034000"],["77716.19000000","0.00000000"],["77716.22000000","0.00000000"],["77716.23000000","0.00600000"],["77716.24000000","0.00000000"],["77716.25000000","0.37338000"],["77716.27000000","0.00000000"],["77716.46000000","0.45971000"],["77716.49000000","0.00643000"],["77716.57000000","0.00000000"],["77716.61000000","0.00000000"],["77716.66000000","0.00000000"],["77716.82000000","0.00000000"],["77717.42000000","0.00400000"],["77717.43000000","0.00000000"],["77717.51000000","0.00000000"],["77717.72000000","0.00000000"],["77717.87000000","0.00400000"],["77717.97000000","0.00000000"],["77717.98000000","0.00000000"],["77718.92000000","0.00000000"],["77719.66000000","0.00000000"],["77719.68000000","0.00643000"],["77719.69000000","0.00000000"],["77720.47000000","0.00000000"],["77720.48000000","0.00000000"],["77720.56000000","0.00000000"],["77720.57000000","0.00000000"],["77721.35000000","0.00000000"],["77728.43000000","0.09622000"],["77730.89000000","0.00000000"],["77733.99000000","0.25749000"],["77736.00000000","0.03007000"],["77744.00000000","0.03265000"],["77745.29000000","0.00000000"],["77748.02000000","0.00007000"],["77755.10000000","0.00640000"]]}}
{"type":"depth","received_at_ms":1788333142750,"data":{"e":"depthUpdate","E":1788333142914,"s":"BTCUSDT","U":99556311022,"u":99556311106,"b":[["77708.39000000","2.08547000"],["77708.38000000","0.00117000"],["77707.28000000","0.00000000"],["77707.15000000","0.01671000"],["77705.04000000","0.04000000"],["77702.15000000","0.00200000"],["77658.88000000","0.00435000"],["77630.08000000","1.61379000"],["77627.49000000","0.00000000"],["71491.73000000","0.00014000"],["69937.56000000","0.00464000"],["69937.00000000","0.00000000"],["40899.20000000","0.00037000"]],"a":[["77708.40000000","1.09344000"],["77708.41000000","0.00118000"],["77708.82000000","0.00000000"],["77711.17000000","0.02909000"],["77711.46000000","0.00000000"],["77712.27000000","0.00571000"],["77712.51000000","0.11143000"],["77712.74000000","0.00000000"],["77713.52000000","0.00943000"],["77713.88000000","0.11143000"],["77714.76000000","0.01129000"],["77715.25000000","0.11143000"],["77716.17000000","1.13419000"],["77716.25000000","0.00000000"],["77724.50000000","0.04625000"],["77734.15000000","0.00411000"],["77741.02000000","0.00000000"]]}}
{"type":"depth","received_at_ms":1788333142849,"data":{"e":"depthUpdate","E":1788333143014,"s":"BTCUSDT","U":99556311107,"u":99556311131,"b":[["77708.39000000","2.08617000"],["77708.38000000","0.00166000"],["77705.93000000","0.00643000"],["77704.30000000","0.00643000"],["77703.61000000","0.00000000"],["77703.21000000","0.00000000"],["69937.56000000","0.00448000"],["62166.72000000","0.00032000"]],"a":[["77716.49000000","0.00000000"],["77717.05000000","0.00643000"],["77718.52000000","0.00643000"],["77719.68000000","0.00000000"]]}}
{"type":"depth","received_at_ms":1788333142948,"data":{"e":"depthUpdate","E":1788333143114,"s":"BTCUSDT","U":99556311132,"u":99556311156,"b":[["77708.39000000","2.08424000"],["77708.38000000","0.00166000"],["77708.36000000","0.12122000"],["77707.51000000","0.00186000"],["77707.18000000","0.00000000"],["77707.02000000","0.11150000"],["77706.50000000","0.00257000"],["77706.49000000","0.00000000"],["77705.81000000","0.00400000"],["77705.65000000","0.11129000"],["77704.66000000","0.02007000"],["77704.28000000","0.10265000"],["69937.56000000","0.00464000"]],"a":[]}}
{"type":"trade","received_at_ms":1788333142948,"data":{"e":"trade","E":1788333143115,"s":"BTCUSDT","t":6646665180,"p":"77708.40000000","q":"0.00123000","T":1788333143114,"m":false,"M":true}}
{"type":"depth","received_at_ms":1788333143049,"data":{"e":"depthUpdate","E":1788333143214,"s":"BTCUSDT","U":99556311157,"u":99556311208,"b":[["77708.39000000","2.08619000"],["77708.38000000","0.00166000"],["77707.51000000","0.00000000"],["77689.77000000","0.02000000"],["69937.56000000","0.00432000"],["69937.55000000","0.00000000"],["62167.00000000","0.00450000"],["62166.72000000","0.00000000"],["62166.71000000","0.00000000"]],"a":[["77708.40000000","1.09228000"],["77708.41000000","0.00125000"],["77710.94000000","0.00014000"],["77710.95000000","0.10616000"],["77715.24000000","0.00000000"],["77720.87000000","0.00000000"],["77738.27000000","0.00000000"],["77740.40000000","0.00200000"]]}}
{"type":"depth","received_at_ms":1788333143148,"data":{"e":"depthUpdate","E":1788333143314,"s":"BTCUSDT","U":99556311209,"u":99556311218,"b":[["77689.77000000","0.02007000"],["77630.08000000","0.00000000"],["77627.49000000","1.61379000"],["69937.56000000","0.00464000"]],"a":[["77708.40000000","1.09242000"],["77715.25000000","0.11129000"],["77720.87000000","0.00007000"]]}}
{"type":"depth","received_at_ms":1788333143249,"data":{"e":"depthUpdate","E":1788333143414,"s":"BTCUSDT","U":99556311219,"u":99556311240,"b":[["77708.39000000","2.08556000"],["77708.38000000","0.00117000"],["71491.73000000","0.00000000"],["69937.56000000","0.00448000"]],"a":[]}}
{"type":"depth","received_at_ms":1788333143348,"data":{"e":"depthUpdate","E":1788333143514,"s":"BTCUSDT","U":99556311241,"u":99556311259,"b":[["77623.05000000","0.00411000"],["76542.76000000","0.00030000"],["69937.56000000","0.00448000"],["62166.72000000","0.00032000"]],"a":[["77710.03000000","0.00014000"],["77710.04000000","0.12805000"],["77710.94000000","0.00000000"],["77710.95000000","0.00000000"],["77711.14000000","0.00000000"],["77715.24000000","0.00007000"],["77729.46000000","0.02800000"],["77784.86000000","0.02800000"],["78874.03000000","0.00030000"]]}}
{"type":"depth","received_at_ms":1788333143448,"data":{"e":"depthUpdate","E":1788333143614,"s":"BTCUSDT","U":99556311260,"u":99556311292,"b":[["69937.56000000","0.00448000"],["62167.00000000","0.00450000"],["62166.72000000","0.00000000"]],"a":[["77708.40000000","1.09242000"],["77708.41000000","0.00125000"],["77724.74000000","0.02400000"],["77724.82000000","0.02800000"],["77725.52000000","0.03000000"],["77725.59000000","0.03200000"],["77725.60000000","0.02400000"],["77728.63000000","0.02600000"],["77729.40000000","0.04600000"],["77729.45000000","0.03000000"],["77774.19000000","0.02800000"],["77774.96000000","0.03200000"],["77775.02000000","0.02400000"],["77780.13000000","0.02400000"],["77780.92000000","0.03000000"],["77784.02000000","0.02607000"],["77784.79000000","0.02200000"],["77784.80000000","0.02400000"],["77784.86000000","0.05800000"]]}}
{"type":"trade","received_at_ms":1788333143472,"data":{"e":"trade","E":1788333143638,"s":"BTCUSDT","t":6646665181,"p":"77708.40000000","q":"0.00028000","T":1788333143637,"m":false,"M":true}}
{"type":"trade","received_at_ms":1788333143476,"data":{"e":"trade","E":1788333143642,"s":"BTCUSDT","t":6646665182,"p":"77708.39000000","q":"0.01500000","T":1788333143641,"m":true,"M":true}}
{"type":"depth","received_at_ms":1788333143548,"data":{"e":"depthUpdate","E":1788333143714,"s":"BTCUSDT","U":99556311293,"u":99556311327,"b":[["77708.39000000","2.07056000"],["77705.93000000","0.00657000"],["77675.99000000","0.02716000"],["69937.56000000","0.00473000"],["62166.71000000","0.00000000"]],"a":[["77708.40000000","1.09186000"],["77710.04000000","0.00014000"],["77716.16000000","0.11129000"],["77716.18000000","3.25905000"],["77727.85000000","0.03000000"],["77728.62000000","0.02800000"],["77736.06000000","0.00000000"],["77736.11000000","0.00000000"],["77739.92000000","0.00000000"],["77739.93000000","0.00000000"],["77740.01000000","0.00000000"],["77746.05000000","0.12874000"],["77774.19000000","0.00000000"],["77779.36000000","0.03000000"],["77784.01000000","0.02800000"]]}}
{"type":"depth","received_at_ms":1788333143649,"data":{"e":"depthUpdate","E":1788333143814,"s":"BTCUSDT","U":99556311328,"u":99556311416,"b":[["77699.34000000","0.02000000"],["77689.01000000","1.78492000"],["77688.34000000","0.00000000"],["77688.26000000","0.34770000"],["77672.53000000","0.15343000"],["77672.14000000","0.00000000"],["77630.08000000","1.61379000"],["77627.49000000","0.00000000"],["69937.56000000","0.00457000"],["40899.20000000","0.00000000"]],"a":[["77708.40000000","0.94233000"],["77708.41000000","0.00118000"],["77710.03000000","0.00000000"],["77710.04000000","0.00000000"],["77711.14000000","0.00014000"],["77715.25000000","0.11143000"],["77716.15000000","0.01600000"],["77716.17000000","0.45016000"],["77716.18000000","1.31479000"],["77716.23000000","0.00200000"],["77717.05000000","0.00000000"],["77717.42000000","0.00000000"],["77717.77000000","0.00400000"],["77717.80000000","0.00400000"],["77717.82000000","0.00643000"],["77717.87000000","0.00000000"],["77718.52000000","0.00000000"],["77719.34000000","0.00643000"],["77723.28000000","0.00257000"],["77727.54000000","0.00000000"],["77729.39000000","0.27109000"],["77735.23000000","0.00000000"],["77735.29000000","0.00000000"],["77736.02000000","0.00000000"],["77738.37000000","0.00000000"],["77739.11000000","0.00000000"],["77739.14000000","0.00000000"],["77745.86000000","0.00000000"],["77746.05000000","0.00000000"],["77746.13000000","0.00000000"],["77746.36000000","0.00000000"],["77746.39000000","0.00000000"]]}}
{"type":"depth","received_at_ms":1788333143749,"data":{"e":"depthUpdate","E":1788333143914,"s":"BTCUSDT","U":99556311417,"u":99556311438,"b":[["77708.39000000","2.57320000"],["77707.03000000","0.00000000"],["77707.02000000","0.00021000"],["77701.63000000","0.00400000"],["77697.51000000","0.00000000"],["77692.98000000","0.00000000"],["77654.13000000","0.00000000"],["77623.05000000","0.00000000"],["69937.56000000","0.00457000"],["62167.00000000","0.00450000"]],"a":[["77708.40000000","0.94864000"],["77734.15000000","0.00000000"],["77773.02000000","0.00411000"],["77775.35000000","0.00000000"],["77781.42000000","0.25743000"],["77804.12000000","0.00000000"]]}}
{"type":"depth","received_at_ms":1788333143849,"data":{"e":"depthUpdate","E":1788333144014,"s":"BTCUSDT","U":99556311439,"u":99556311472,"b":[["77708.39000000","2.57063000"],["77707.15000000","0.01671000"],["77707.05000000","0.00000000"],["77707.02000000","0.00007000"],["77706.37000000","0.00257000"],["77706.35000000","0.00000000"],["77706.26000000","0.00400000"],["77705.81000000","0.00000000"],["77705.65000000","0.00014000"],["77701.63000000","0.00000000"],["77700.32000000","0.00400000"],["77700.02000000","0.00000000"],["69937.56000000","0.00457000"],["69937.00000000","0.00000000"],["62166.72000000","0.00032000"]],"a":[["77708.40000000","0.95576000"],["77711.14000000","0.11143000"],["77711.28000000","0.11385000"],["77721.90000000","0.00257000"],["77723.28000000","0.00000000"],["77784.86000000","0.03000000"]]}}
{"type":"trade","received_at_ms":1788333143912,"data":{"e":"trade","E":1788333144078,"s":"BTCUSDT","t":6646665183,"p":"77708.40000000","q":"0.00200000","T":1788333144078,"m":false,"M":true}}
{"type":"trade","received_at_ms":1788333143914,"data":{"e":"trade","E":1788333144078,"s":"BTCUSDT","t":6646665184,"p":"77708.40000000","q":"0.00200000","T":1788333144078,"m":false,"M":true}}
{"type":"trade","received_at_ms":1788333143914,"data":{"e":"trade","E":1788333144078,"s":"BTCUSDT","t":6646665185,"p":"77708.40000000","q":"0.00200000","T":1788333144078,"m":false,"M":true}}
{"type":"trade","received_at_ms":1788333143914,"data":{"e":"trade","E":1788333144078,"s":"BTCUSDT","t":6646665186,"p":"77708.40000000","q":"0.00200000","T":1788333144078,"m":false,"M":true}}
{"type":"trade","received_at_ms":1788333143914,"data":{"e":"trade","E":1788333144078,"s":"BTCUSDT","t":6646665187,"p":"77708.40000000","q":"0.00113000","T":1788333144078,"m":false,"M":true}}
{"type":"trade","received_at_ms":1788333143914,"data":{"e":"trade","E":1788333144078,"s":"BTCUSDT","t":6646665188,"p":"77708.40000000","q":"0.00087000","T":1788333144078,"m":false,"M":true}}
{"type":"depth","received_at_ms":1788333143948,"data":{"e":"depthUpdate","E":1788333144114,"s":"BTCUSDT","U":99556311473,"u":99556311563,"b":[["77708.39000000","2.56091000"],["77708.38000000","0.00781000"],["77708.36000000","0.06500000"],["77707.30000000","0.00000000"],["77706.82000000","0.00400000"],["77706.37000000","0.00000000"],["77705.71000000","0.01330000"],["77705.65000000","0.00000000"],["77705.05000000","0.00122000"],["77705.04000000","0.04014000"],["77704.81000000","0.00200000"],["77704.29000000","0.20447000"],["77704.28000000","0.10272000"],["77702.96000000","0.37338000"],["77702.15000000","0.00000000"],["77700.43000000","0.00800000"],["77699.59000000","0.00000000"],["77696.32000000","0.11370000"],["77694.89000000","0.37338000"],["77675.49000000","0.00000000"],["69937.56000000","0.00448000"],["69937.55000000","0.00009000"]],"a":[["77708.40000000","1.07040000"],["77708.41000000","0.00132000"],["77710.41000000","0.11997000"],["77711.13000000","0.00014000"],["77711.14000000","0.11157000"],["77711.17000000","0.02909000"],["77711.27000000","0.00014000"],["77711.28000000","0.00014000"],["77713.87000000","0.00000000"],["77714.76000000","0.01115000"],["77715.24000000","0.00000000"],["77715.25000000","0.11129000"],["77716.15000000","0.38938000"],["77721.90000000","0.00000000"],["77722.83000000","0.00000000"],["77734.15000000","0.00411000"],["77740.40000000","0.00000000"],["77742.51000000","0.00200000"]]}}
{"type":"trade","received_at_ms":1788333143966,"data":{"e":"trade","E":1788333144130,"s":"BTCUSDT","t":6646665189,"p":"77708.40000000","q":"0.00200000","T":1788333144130,"m":false,"M":true}}
{"type":"trade","received_at_ms":1788333143967,"data":{"e":"trade","E":1788333144131,"s":"BTCUSDT","t":6646665190,"p":"77708.40000000","q":"0.00200000","T":1788333144130,"m":false,"M":true}}
{"type":"trade","received_at_ms":1788333143967,"data":{"e":"trade","E":1788333144131,"s":"BTCUSDT","t":6646665191,"p":"77708.40000000","q":"0.00200000","T":1788333144130,"m":false,"M":true}}
{"type":"trade","received_at_ms":1788333143967,"data":{"e":"trade","E":1788333144131,"s":"BTCUSDT","t":6646665192,"p":"77708.40000000","q":"0.00200000","T":1788333144130,"m":false,"M":true}}
{"type":"trade","received_at_ms":1788333143967,"data":{"e":"trade","E":1788333144132,"s":"BTCUSDT","t":6646665193,"p":"77708.40000000","q":"0.00200000","T":1788333144131,"m":false,"M":true}}
{"type":"depth","received_at_ms":1788333144048,"data":{"e":"depthUpdate","E":1788333144214,"s":"BTCUSDT","U":99556311564,"u":99556311731,"b":[["77708.39000000","2.57062000"],["77708.38000000","0.00760000"],["77708.36000000","0.12209000"],["77707.97000000","0.00000000"],["77707.82000000","0.00000000"],["77707.51000000","0.00000000"],["77707.03000000","0.00000000"],["77707.02000000","0.00007000"],["77706.82000000","0.00000000"],["77706.50000000","0.00000000"],["77706.46000000","0.00400000"],["77706.29000000","0.00257000"],["77706.26000000","0.00000000"],["77705.93000000","0.00014000"],["77705.72000000","0.00257000"],["77705.71000000","0.01337000"],["77705.65000000","0.11136000"],["77705.45000000","0.00000000"],["77705.06000000","0.00643000"],["77705.04000000","0.04000000"],["77704.81000000","0.00000000"],["77704.66000000","0.01986000"],["77704.30000000","0.00000000"],["77704.29000000","0.43485000"],["77704.28000000","0.00082000"],["77703.61000000","0.00650000"],["77702.97000000","1.31671000"],["77702.96000000","0.00000000"],["77702.95000000","0.00000000"],["77702.60000000","0.01000000"],["77701.62000000","0.00000000"],["77700.31000000","0.00000000"],["77700.03000000","0.00000000"],["77696.33000000","0.37338000"],["77694.89000000","0.00000000"],["77694.30000000","0.00000000"],["77689.04000000","0.00000000"],["77687.57000000","0.00200000"],["77658.09000000","0.49704000"],["77655.48000000","0.00000000"],["62166.72000000","0.00000000"],["62166.71000000","0.00020000"]],"a":[["77708.40000000","1.06040000"],["77708.41000000","0.00118000"],["77710.40000000","0.00014000"],["77710.41000000","0.12011000"],["77711.13000000","0.00000000"],["77711.14000000","0.00028000"],["77711.17000000","0.02909000"],["77711.27000000","0.00000000"],["77711.28000000","0.00000000"],["77712.50000000","0.00000000"],["77712.51000000","0.00014000"],["77713.87000000","0.00014000"],["77713.88000000","0.11143000"],["77715.24000000","0.00014000"],["77716.12000000","0.11129000"],["77716.13000000","0.56639000"],["77716.14000000","0.37338000"],["77716.15000000","0.01600000"],["77716.16000000","0.00000000"],["77716.17000000","0.00000000"],["77716.39000000","0.00000000"],["77717.35000000","0.00000000"],["77717.46000000","0.00643000"],["77717.77000000","0.00000000"],["77717.80000000","0.00000000"],["77717.82000000","0.00000000"],["77718.12000000","0.00400000"],["77731.35000000","1.31471000"],["77733.98000000","0.64372000"],["77746.56000000","0.12874000"],["77746.65000000","0.00007000"]]}}
{"type":"depth","received_at_ms":1788333144149,"data":{"e":"depthUpdate","E":1788333144314,"s":"BTCUSDT","U":99556311732,"u":99556311798,"b":[["77708.39000000","2.57076000"],["77708.38000000","0.01974000"],["77707.15000000","0.01664000"],["77707.02000000","0.00000000"],["77705.93000000","0.00000000"],["77705.92000000","0.00000000"],["77705.71000000","0.01337000"],["77700.00000000","0.00007000"],["77689.77000000","0.02007000"],["77688.00000000","0.03665000"],["77675.99000000","0.01516000"],["77434.50000000","0.00000000"],["77355.08000000","0.00000000"],["77275.66000000","0.00000000"],["69937.56000000","0.00448000"],["62167.00000000","0.00450000"],["62166.71000000","0.00000000"]],"a":[["77708.40000000","0.92878000"],["77710.41000000","0.12011000"],["77711.14000000","0.00014000"],["77712.27000000","0.00571000"],["77712.51000000","0.00000000"],["77714.76000000","0.01129000"],["77715.25000000","0.11143000"],["77720.87000000","0.00007000"],["77746.56000000","0.00000000"],["77746.87000000","0.00000000"],["77804.12000000","0.00411000"]]}}
{"type":"depth","received_at_ms":1788333144249,"data":{"e":"depthUpdate","E":1788333144414,"s":"BTCUSDT","U":99556311799,"u":99556311849,"b":[["77708.39000000","2.57139000"],["77708.38000000","0.02023000"],["77708.36000000","0.06500000"],["77705.65000000","0.00007000"],["77629.72000000","0.00401000"],["77621.83000000","0.00000000"],["69937.56000000","0.00464000"],["62167.00000000","0.00450000"]],"a":[["77708.40000000","1.05121000"],["77708.41000000","0.00118000"],["77709.12000000","0.00014000"],["77709.13000000","0.11595000"],["77710.40000000","0.00000000"],["77710.41000000","0.00014000"],["77712.50000000","0.00014000"],["77712.51000000","0.11129000"],["77715.24000000","0.00000000"],["77716.12000000","0.96336000"],["77716.13000000","1.93226000"],["77717.51000000","0.00643000"],["77719.34000000","0.00000000"],["77800.65000000","0.00000000"]]}}
{"type":"trade","received_at_ms":1788333144298,"data":{"e":"trade","E":1788333144463,"s":"BTCUSDT","t":6646665194,"p":"77708.40000000","q":"0.00225000","T":1788333144463,"m":false,"M":true}}
{"type":"depth","received_at_ms":1788333144348,"data":{"e":"depthUpdate","E":1788333144514,"s":"BTCUSDT","U":99556311850,"u":99556311961,"b":[["77708.39000000","2.57118000"],["77708.38000000","0.02009000"],["77705.71000000","0.01323000"],["77704.30000000","0.11129000"],["77662.08000000","1.29802000"],["77579.69000000","0.25369000"],["76542.76000000","0.00030000"],["69937.56000000","0.00448000"],["69937.55000000","0.00000000"],["62166.72000000","0.00032000"]],"a":[["77708.40000000","1.04767000"],["77708.41000000","0.00125000"],["77709.12000000","0.00000000"],["77709.13000000","0.00014000"],["77710.41000000","0.00000000"],["77712.27000000","0.00571000"],["77712.51000000","0.11143000"],["77715.24000000","0.00007000"],["77715.25000000","0.11129000"],["77716.12000000","2.89562000"],["77716.13000000","0.00000000"],["77717.51000000","0.00000000"],["77718.52000000","0.00643000"],["78874.03000000","0.00030000"]]}}
{"type":"depth","received_at_ms":1788333144448,"data":{"e":"depthUpdate","E":1788333144614,"s":"BTCUSDT","U":99556311962,"u":99556311981,"b":[["77704.66000000","0.01993000"],["69937.56000000","0.00464000"],["62167.00000000","0.00450000"],["62166.72000000","0.00000000"]],"a":[["77708.40000000","1.04774000"],["77708.41000000","0.00118000"],["77709.13000000","0.00000000"],["77716.11000000","1.21538000"],["77716.12000000","2.04355000"],["77746.56000000","0.00000000"],["77774.19000000","0.02800000"]]}}
{"type":"depth","received_at_ms":1788333144549,"data":{"e":"depthUpdate","E":1788333144714,"s":"BTCUSDT","U":99556311982,"u":99556312006,"b":[["77708.39000000","2.57076000"],["77708.38000000","0.01974000"],["77704.66000000","0.02000000"],["77704.31000000","0.37338000"],["77654.12000000","0.00411000"],["77630.08000000","0.00000000"],["77627.49000000","1.61379000"],["69937.56000000","0.00448000"],["62166.71000000","0.00000000"]],"a":[["77708.40000000","1.07302000"],["77716.10000000","0.11129000"],["77716.12000000","1.93226000"]]}}
{"type":"depth","received_at_ms":1788333144648,"data":{"e":"depthUpdate","E":1788333144814,"s":"BTCUSDT","U":99556312007,"u":99556312012,"b":[["77434.50000000","2.50000000"],["69937.56000000","0.00448000"]],"a":[["77708.40000000","0.92688000"],["80039.65000000","0.00224000"]]}}
{"type":"depth","received_at_ms":1788333144748,"data":{"e":"depthUpdate","E":1788333144914,"s":"BTCUSDT","U":99556312013,"u":99556312020,"b":[["69937.56000000","0.00448000"]],"a":[["77712.14000000","0.00014000"],["77712.15000000","0.09887000"],["77712.16000000","0.00208000"],["77715.24000000","0.00000000"]]}}
{"type":"depth","received_at_ms":1788333144850,"data":{"e":"depthUpdate","E":1788333145014,"s":"BTCUSDT","U":99556312021,"u":99556312079,"b":[["77708.39000000","2.41242000"],["77708.38000000","0.02023000"],["77706.46000000","0.00000000"],["77704.31000000","0.00000000"],["77704.30000000","0.00000000"],["77702.97000000","0.00000000"],["77700.91000000","0.00200000"],["77699.56000000","0.00000000"],["77687.57000000","0.00000000"],["77685.28000000","0.00200000"],["69937.56000000","0.00464000"],["62167.00000000","0.00450000"],["62166.72000000","0.00032000"],["40899.20000000","0.00037000"]],"a":[["77708.40000000","1.22861000"],["77708.41000000","0.00132000"],["77710.56000000","0.00014000"],["77710.57000000","0.11506000"],["77711.17000000","0.02909000"],["77713.87000000","0.00000000"],["77718.12000000","0.00000000"]]}}
{"type":"depth","received_at_ms":1788333144948,"data":{"e":"depthUpdate","E":1788333145114,"s":"BTCUSDT","U":99556312080,"u":99556312171,"b":[["77708.39000000","2.41048000"],["77708.38000000","0.02023000"],["77707.18000000","0.00195000"],["77706.29000000","0.00000000"],["77704.66000000","0.01986000"],["77704.29000000","0.08036000"],["77704.12000000","0.00257000"],["77703.61000000","0.00007000"],["77702.91000000","0.11129000"],["77702.60000000","0.01007000"],["77702.15000000","0.00643000"],["77701.54000000","0.11129000"],["77700.17000000","0.11129000"],["77699.58000000","0.11129000"],["77699.57000000","0.48919000"],["77692.97000000","0.00411000"],["77669.22000000","0.00007000"],["69937.56000000","0.00432000"],["69937.00000000","0.00000000"]],"a":[["77708.40000000","1.22882000"],["77708.41000000","0.00125000"],["77708.62000000","0.00014000"],["77708.90000000","0.00014000"],["77708.91000000","0.13576000"],["77710.56000000","0.00000000"],["77710.57000000","0.00000000"],["77711.14000000","0.00000000"],["77712.14000000","0.00000000"],["77712.15000000","0.00000000"],["77712.16000000","0.00000000"],["77713.87000000","0.00014000"],["77714.76000000","0.01115000"],["77715.24000000","0.00007000"],["77716.09000000","0.01600000"],["77716.15000000","0.00000000"],["77718.85000000","0.00257000"],["77727.59000000","0.09622000"],["77728.43000000","0.00000000"],["77729.65000000","0.00128000"],["77729.80000000","0.00000000"],["77748.02000000","0.00000000"]]}}
{"type":"depth","received_at_ms":1788333145048,"data":{"e":"depthUpdate","E":1788333145214,"s":"BTCUSDT","U":99556312172,"u":99556312183,"b":[["69937.56000000","0.00464000"],["69937.00000000","0.00020000"],["62166.72000000","0.00000000"]],"a":[["77708.40000000","1.22896000"],["77710.82000000","0.09887000"],["77710.90000000","0.00208000"],["77711.17000000","0.02895000"],["77718.85000000","0.00000000"]]}}
{"type":"depth","received_at_ms":1788333145148,"data":{"e":"depthUpdate","E":1788333145314,"s":"BTCUSDT","U":99556312184,"u":99556312207,"b":[["77705.84000000","0.00257000"],["77704.12000000","0.00000000"],["77689.77000000","0.02007000"],["77669.22000000","0.00000000"],["77508.01000000","0.00000000"],["77507.33000000","0.00812000"],["77355.08000000","2.50000000"],["69937.56000000","0.00448000"],["69937.00000000","0.00000000"],["62166.71000000","0.00000000"]],"a":[["77708.40000000","1.22910000"],["77708.41000000","0.00139000"],["77710.81000000","0.00014000"],["77715.24000000","0.00000000"],["77719.59000000","0.00000000"],["77720.87000000","0.00007000"],["77721.37000000","0.00257000"]]}}
{"type":"depth","received_at_ms":1788333145248,"data":{"e":"depthUpdate","E":1788333145414,"s":"BTCUSDT","U":99556312208,"u":99556312214,"b":[["77708.39000000","2.41055000"],["69937.56000000","0.00448000"],["62167.00000000","0.00450000"]],"a":[]}}
{"type":"trade","received_at_ms":1788333145320,"data":{"e":"trade","E":1788333145484,"s":"BTCUSDT","t":6646665195,"p":"77708.40000000","q":"0.00246000","T":1788333145484,"m":false,"M":true}}
{"type":"depth","received_at_ms":1788333145348,"data":{"e":"depthUpdate","E":1788333145514,"s":"BTCUSDT","U":99556312215,"u":99556312239,"b":[["77708.39000000","2.41048000"],["77705.84000000","0.00000000"],["77704.89000000","0.00257000"],["77692.97000000","0.00000000"],["77669.22000000","0.00007000"],["77664.22000000","1.55818000"],["77654.12000000","0.00000000"],["77623.04000000","0.00411000"],["76542.76000000","0.00030000"],["69937.56000000","0.00441000"],["69937.00000000","0.00010000"],["62167.00000000","0.00450000"],["62166.72000000","0.00032000"]],"a":[["77708.40000000","1.22674000"],["77720.43000000","1.10512000"],["77721.37000000","0.00000000"],["77734.15000000","0.00000000"],["77773.02000000","0.00000000"],["77804.12000000","0.00000000"],["78874.03000000","0.00030000"]]}}
{"type":"depth","received_at_ms":1788333145448,"data":{"e":"depthUpdate","E":1788333145614,"s":"BTCUSDT","U":99556312240,"u":99556312254,"b":[["77708.39000000","2.43040000"],["77692.45000000","0.00000000"],["77645.43000000","0.00000000"],["77625.98000000","0.00000000"],["75556.95000000","0.00000000"],["69937.56000000","0.00441000"],["69937.00000000","0.00000000"],["62166.72000000","0.00000000"]],"a":[["77723.55000000","0.00000000"],["77743.00000000","0.00000000"],["77762.45000000","0.00000000"],["81001.33000000","0.00000000"]]}}
{"type":"depth","received_at_ms":1788333145549,"data":{"e":"depthUpdate","E":1788333145714,"s":"BTCUSDT","U":99556312255,"u":99556312269,"b":[["77708.39000000","2.43048000"],["77697.76000000","0.02000000"],["77658.86000000","0.02000000"],["77507.33000000","0.00000000"],["77506.01000000","0.00812000"],["69937.56000000","0.00441000"],["62166.71000000","0.00000000"]],"a":[["77708.40000000","1.23386000"],["77728.96000000","0.03682000"],["77734.16000000","0.00411000"],["77748.41000000","0.03000000"]]}}
{"type":"depth","received_at_ms":1788333145648,"data":{"e":"depthUpdate","E":1788333145814,"s":"BTCUSDT","U":99556312270,"u":99556312276,"b":[["77686.00000000","0.73000000"],["77275.66000000","2.50000000"],["69937.56000000","0.00441000"]],"a":[["77708.40000000","1.06516000"]]}}
{"type":"depth","received_at_ms":1788333145748,"data":{"e":"depthUpdate","E":1788333145914,"s":"BTCUSDT","U":99556312277,"u":99556312288,"b":[["77700.43000000","0.00000000"],["77692.98000000","0.00411000"],["69937.56000000","0.00457000"],["69937.00000000","0.00010000"],["40899.20000000","0.00000000"]],"a":[["77708.40000000","1.23386000"],["77746.67000000","0.12874000"]]}}
{"type":"depth","received_at_ms":1788333145849,"data":{"e":"depthUpdate","E":1788333146014,"s":"BTCUSDT","U":99556312289,"u":99556312300,"b":[["77699.59000000","0.00800000"],["77507.33000000","0.00812000"],["77506.01000000","0.00000000"],["69937.56000000","0.00441000"],["69937.00000000","0.00010000"],["62166.72000000","0.00032000"]],"a":[["77746.67000000","0.00000000"],["77746.76000000","0.00000000"]]}}
{"type":"depth","received_at_ms":1788333145948,"data":{"e":"depthUpdate","E":1788333146114,"s":"BTCUSDT","U":99556312301,"u":99556312304,"b":[["77532.05000000","0.00000000"],["69937.56000000","0.00457000"],["69937.00000000","0.00000000"]],"a":[["77708.40000000","1.35884000"]]}}
{"type":"depth","received_at_ms":1788333146048,"data":{"e":"depthUpdate","E":1788333146214,"s":"BTCUSDT","U":99556312305,"u":99556312314,"b":[["69937.56000000","0.00441000"],["62166.72000000","0.00000000"]],"a":[["77716.08000000","0.01200000"],["77716.09000000","0.00400000"]]}}
{"type":"trade","received_at_ms":1788333146057,"data":{"e":"trade","E":1788333146220,"s":"BTCUSDT","t":6646665196,"p":"77708.40000000","q":"0.01500000","T":1788333146220,"m":false,"M":true}}
{"type":"depth","received_at_ms":1788333146149,"data":{"e":"depthUpdate","E":1788333146314,"s":"BTCUSDT","U":99556312315,"u":99556312330,"b":[["77699.60000000","1.93226000"],["77689.77000000","0.02000000"],["77654.13000000","0.00411000"],["69937.56000000","0.00448000"],["69937.55000000","0.00009000"],["69937.00000000","0.00020000"],["62167.00000000","0.00450000"],["62166.71000000","0.00000000"]],"a":[["77708.40000000","1.21886000"],["77720.87000000","0.00000000"]]}}
{"type":"depth","received_at_ms":1788333146248,"data":{"e":"depthUpdate","E":1788333146414,"s":"BTCUSDT","U":99556312331,"u":99556312340,"b":[["77699.61000000","1.10755000"],["77699.58000000","0.00000000"],["77699.57000000","0.00000000"],["77689.77000000","0.02007000"],["77531.72000000","4.43553000"],["77507.33000000","0.00000000"],["77504.01000000","0.00812000"],["69937.56000000","0.00432000"],["69937.00000000","0.00000000"]],"a":[["77708.40000000","1.34575000"],["77720.87000000","0.00007000"]]}}
{"type":"depth","received_at_ms":1788333146348,"data":{"e":"depthUpdate","E":1788333146514,"s":"BTCUSDT","U":99556312341,"u":99556312351,"b":[["77692.37000000","0.02000000"],["77645.46000000","0.00000000"],["77626.01000000","0.00000000"],["76542.76000000","0.00030000"],["69937.56000000","0.00448000"],["62166.72000000","0.00032000"]],"a":[["77708.40000000","1.34582000"],["77725.60000000","0.00000000"],["77755.57000000","0.00000000"],["77773.03000000","0.00411000"],["77775.02000000","0.00000000"],["78874.03000000","0.00030000"]]}}
{"type":"trade","received_at_ms":1788333146414,"data":{"e":"trade","E":1788333146578,"s":"BTCUSDT","t":6646665197,"p":"77708.39000000","q":"0.00456000","T":1788333146578,"m":true,"M":true}}
{"type":"trade","received_at_ms":1788333146417,"data":{"e":"trade","E":1788333146582,"s":"BTCUSDT","t":6646665198,"p":"77708.39000000","q":"0.00456000","T":1788333146582,"m":true,"M":true}}
{"type":"depth","received_at_ms":1788333146448,"data":{"e":"depthUpdate","E":1788333146614,"s":"BTCUSDT","U":99556312352,"u":99556312391,"b":[["77708.39000000","2.42136000"],["77705.71000000","0.01337000"],["77705.06000000","0.00657000"],["77697.66000000","0.02115000"],["77658.76000000","0.02000000"],["75557.14000000","0.00010000"],["69937.56000000","0.00432000"],["69937.55000000","0.00000000"],["62167.00000000","0.00450000"],["62166.72000000","0.00000000"]],"a":[["77708.40000000","1.04953000"],["77708.91000000","0.13590000"],["77710.82000000","0.09901000"],["77711.17000000","0.02909000"],["77728.94000000","0.02400000"],["77748.39000000","0.02400000"]]}}
{"type":"depth","received_at_ms":1788333146548,"data":{"e":"depthUpdate","E":1788333146714,"s":"BTCUSDT","U":99556312392,"u":99556312398,"b":[["77639.41000000","0.02000000"],["69937.56000000","0.00432000"],["62166.71000000","0.00000000"]],"a":[["77767.85000000","0.00321000"],["77767.86000000","0.03000000"],["77767.99000000","0.00000000"]]}}
{"type":"depth","received_at_ms":1788333146648,"data":{"e":"depthUpdate","E":1788333146814,"s":"BTCUSDT","U":99556312399,"u":99556312404,"b":[["77508.01000000","0.00812000"],["77504.01000000","0.00000000"],["69937.56000000","0.00432000"]],"a":[["77708.40000000","1.35973000"],["81001.14000000","0.00010000"]]}}
{"type":"trade","received_at_ms":1788333146719,"data":{"e":"trade","E":1788333146885,"s":"BTCUSDT","t":6646665199,"p":"77708.39000000","q":"0.00012000","T":1788333146884,"m":true,"M":true}}
{"type":"depth","received_at_ms":1788333146748,"data":{"e":"depthUpdate","E":1788333146914,"s":"BTCUSDT","U":99556312405,"u":99556312415,"b":[["77708.39000000","2.42124000"],["77630.93000000","0.71902000"],["77627.49000000","0.00000000"],["77624.90000000","1.61379000"],["69937.56000000","0.00432000"],["69937.55000000","0.00009000"],["62167.00000000","0.00450000"]],"a":[]}}
{"type":"depth","received_at_ms":1788333146849,"data":{"e":"depthUpdate","E":1788333147014,"s":"BTCUSDT","U":99556312416,"u":99556312419,"b":[["69937.56000000","0.00416000"],["62166.72000000","0.00032000"]],"a":[["77747.13000000","0.12874000"],["79912.82000000","0.00007000"]]}}
{"type":"depth","received_at_ms":1788333146949,"data":{"e":"depthUpdate","E":1788333147114,"s":"BTCUSDT","U":99556312420,"u":99556312425,"b":[["77319.87000000","0.00025000"],["69937.56000000","0.00432000"]],"a":[["77747.13000000","0.00000000"],["77747.44000000","0.12882000"]]}}
{"type":"depth","received_at_ms":1788333147048,"data":{"e":"depthUpdate","E":1788333147214,"s":"BTCUSDT","U":99556312426,"u":99556312429,"b":[["69937.56000000","0.00432000"],["62166.72000000","0.00000000"]],"a":[["77747.44000000","0.00008000"]]}}
{"type":"trade","received_at_ms":1788333147089,"data":{"e":"trade","E":1788333147255,"s":"BTCUSDT","t":6646665200,"p":"77708.39000000","q":"0.01500000","T":1788333147254,"m":true,"M":true}}
{"type":"depth","received_at_ms":1788333147149,"data":{"e":"depthUpdate","E":1788333147314,"s":"BTCUSDT","U":99556312430,"u":99556312444,"b":[["77708.39000000","2.40624000"],["77699.61000000","0.50352000"],["77699.60000000","0.00000000"],["77654.13000000","0.00000000"],["69937.56000000","0.00432000"],["69937.55000000","0.00000000"],["69937.54000000","0.00009000"],["62166.71000000","0.00000000"]],"a":[["77708.40000000","1.36040000"],["77773.03000000","0.00000000"],["77804.13000000","0.00411000"]]}}
{"type":"depth","received_at_ms":1788333147248,"data":{"e":"depthUpdate","E":1788333147414,"s":"BTCUSDT","U":99556312445,"u":99556312448,"b":[["77689.77000000","0.02007000"],["69937.56000000","0.00448000"]],"a":[["77720.87000000","0.00007000"]]}}
{"type":"depth","received_at_ms":1788333147348,"data":{"e":"depthUpdate","E":1788333147514,"s":"BTCUSDT","U":99556312449,"u":99556312460,"b":[["77692.37000000","0.00000000"],["77645.58000000","0.00000000"],["77626.13000000","0.00000000"],["76542.76000000","0.00030000"],["69937.56000000","0.00432000"],["69937.00000000","0.00020000"],["62166.72000000","0.00032000"]],"a":[["77717.13000000","0.00048000"],["77717.47000000","0.00000000"],["77725.59000000","0.00000000"],["77755.51000000","0.00000000"],["77774.96000000","0.00000000"],["78874.03000000","0.00030000"]]}}
{"type":"depth","received_at_ms":1788333147448,"data":{"e":"depthUpdate","E":1788333147614,"s":"BTCUSDT","U":99556312461,"u":99556312492,"b":[["77708.39000000","1.90624000"],["77705.06000000","0.00014000"],["77704.66000000","0.01993000"],["77704.30000000","0.00643000"],["77703.38000000","0.00400000"],["77700.32000000","0.00000000"],["77698.90000000","0.00400000"],["77697.61000000","0.02000000"],["77658.71000000","0.02000000"],["77639.31000000","0.02000000"],["77630.93000000","0.99947000"],["77627.49000000","1.61379000"],["77624.90000000","0.00000000"],["77508.01000000","0.00000000"],["77507.33000000","0.00812000"],["69937.56000000","0.00448000"],["69937.00000000","0.00000000"],["62167.00000000","0.00450000"],["62166.72000000","0.00000000"]],"a":[["77708.40000000","1.36095000"],["77714.27000000","0.00400000"],["77716.00000000","0.00643000"],["77717.13000000","0.00000000"],["77718.52000000","0.00000000"],["77723.23000000","0.00128000"],["77728.84000000","0.03200000"],["77729.65000000","0.00000000"],["77748.29000000","0.03200000"],["77767.84000000","0.02400000"]]}}
{"type":"depth","received_at_ms":1788333147548,"data":{"e":"depthUpdate","E":1788333147714,"s":"BTCUSDT","U":99556312493,"u":99556312507,"b":[["77705.71000000","0.01330000"],["77705.65000000","0.00000000"],["77705.06000000","0.00000000"],["77705.04000000","0.04014000"],["69937.56000000","0.00432000"],["62166.71000000","0.00000000"]],"a":[["77708.40000000","1.38358000"],["77773.05000000","0.00411000"]]}}
{"type":"trade","received_at_ms":1788333147561,"data":{"e":"trade","E":1788333147727,"s":"BTCUSDT","t":6646665201,"p":"77708.40000000","q":"0.00200000","T":1788333147726,"m":false,"M":true}}
{"type":"trade","received_at_ms":1788333147561,"data":{"e":"trade","E":1788333147727,"s":"BTCUSDT","t":6646665202,"p":"77708.40000000","q":"0.00200000","T":1788333147726,"m":false,"M":true}}
{"type":"trade","received_at_ms":1788333147561,"data":{"e":"trade","E":1788333147727,"s":"BTCUSDT","t":6646665203,"p":"77708.40000000","q":"0.00200000","T":1788333147726,"m":false,"M":true}}
{"type":"trade","received_at_ms":1788333147561,"data":{"e":"trade","E":1788333147727,"s":"BTCUSDT","t":6646665204,"p":"77708.40000000","q":"0.00200000","T":1788333147726,"m":false,"M":true}}
{"type":"trade","received_at_ms":1788333147561,"data":{"e":"trade","E":1788333147727,"s":"BTCUSDT","t":6646665205,"p":"77708.40000000","q":"0.00200000","T":1788333147727,"m":false,"M":true}}
{"type":"trade","received_at_ms":1788333147565,"data":{"e":"trade","E":1788333147731,"s":"BTCUSDT","t":6646665206,"p":"77708.40000000","q":"0.02100000","T":1788333147730,"m":false,"M":true}}
{"type":"trade","received_at_ms":1788333147565,"data":{"e":"trade","E":1788333147731,"s":"BTCUSDT","t":6646665207,"p":"77708.40000000","q":"0.02100000","T":1788333147730,"m":false,"M":true}}
{"type":"trade","received_at_ms":1788333147566,"data":{"e":"trade","E":1788333147731,"s":"BTCUSDT","t":6646665208,"p":"77708.40000000","q":"0.02100000","T":1788333147731,"m":false,"M":true}}
{"type":"trade","received_at_ms":1788333147566,"data":{"e":"trade","E":1788333147732,"s":"BTCUSDT","t":6646665209,"p":"77708.40000000","q":"0.02100000","T":1788333147731,"m":false,"M":true}}
{"type":"trade","received_at_ms":1788333147567,"data":{"e":"trade","E":1788333147733,"s":"BTCUSDT","t":6646665210,"p":"77708.40000000","q":"0.02100000","T":1788333147732,"m":false,"M":true}}
{"type":"trade","received_at_ms":1788333147567,"data":{"e":"trade","E":1788333147733,"s":"BTCUSDT","t":6646665211,"p":"77708.40000000","q":"0.02100000","T":1788333147732,"m":false,"M":true}}
{"type":"depth","received_at_ms":1788333147648,"data":{"e":"depthUpdate","E":1788333147814,"s":"BTCUSDT","U":99556312508,"u":99556312529,"b":[["69937.56000000","0.00448000"],["69937.54000000","0.00000000"]],"a":[["77708.40000000","1.24710000"],["77714.27000000","0.00000000"],["77714.96000000","0.00400000"],["77717.17000000","0.00048000"],["77747.62000000","0.12874000"]]}}
{"type":"depth","received_at_ms":1788333147748,"data":{"e":"depthUpdate","E":1788333147914,"s":"BTCUSDT","U":99556312530,"u":99556312537,"b":[["77704.89000000","0.00000000"],["77507.33000000","0.00000000"],["77506.01000000","0.00812000"],["69937.56000000","0.00432000"]],"a":[["77747.42000000","0.00000000"],["77747.62000000","0.00000000"]]}}
{"type":"depth","received_at_ms":1788333147849,"data":{"e":"depthUpdate","E":1788333148014,"s":"BTCUSDT","U":99556312538,"u":99556312551,"b":[["77708.39000000","1.90624000"],["77704.01000000","0.00257000"],["77630.93000000","0.71902000"],["77627.49000000","0.00000000"],["77624.90000000","1.61379000"],["69937.56000000","0.00448000"],["62167.00000000","0.00450000"],["62166.72000000","0.00032000"]],"a":[["77719.54000000","0.00257000"],["77720.43000000","1.10255000"]]}}
{"type":"depth","received_at_ms":1788333147948,"data":{"e":"depthUpdate","E":1788333148114,"s":"BTCUSDT","U":99556312552,"u":99556312562,"b":[["77576.10000000","0.02016000"],["77572.96000000","0.00000000"],["77520.50000000","0.02016000"],["77491.78000000","0.00000000"],["69937.56000000","0.00432000"]],"a":[["77708.40000000","1.24744000"],["77717.17000000","0.00000000"]]}}
{"type":"depth","received_at_ms":1788333148048,"data":{"e":"depthUpdate","E":1788333148214,"s":"BTCUSDT","U":99556312563,"u":99556312566,"b":[["69937.56000000","0.00448000"],["62166.72000000","0.00000000"]],"a":[]}}
{"type":"trade","received_at_ms":1788333148063,"data":{"e":"trade","E":1788333148230,"s":"BTCUSDT","t":6646665212,"p":"77708.40000000","q":"0.02100000","T":1788333148230,"m":false,"M":true}}
{"type":"trade","received_at_ms":1788333148063,"data":{"e":"trade","E":1788333148230,"s":"BTCUSDT","t":6646665213,"p":"77708.40000000","q":"0.00422000","T":1788333148230,"m":false,"M":true}}
{"type":"trade","received_at_ms":1788333148066,"data":{"e":"trade","E":1788333148230,"s":"BTCUSDT","t":6646665214,"p":"77708.40000000","q":"0.00008000","T":1788333148230,"m":false,"M":true}}
{"type":"trade","received_at_ms":1788333148066,"data":{"e":"trade","E":1788333148230,"s":"BTCUSDT","t":6646665215,"p":"77708.40000000","q":"0.00007000","T":1788333148230,"m":false,"M":true}}
{"type":"trade","received_at_ms":1788333148066,"data":{"e":"trade","E":1788333148230,"s":"BTCUSDT","t":6646665216,"p":"77708.40000000","q":"0.00013000","T":1788333148230,"m":false,"M":true}}
{"type":"trade","received_at_ms":1788333148066,"data":{"e":"trade","E":1788333148230,"s":"BTCUSDT","t":6646665217,"p":"77708.40000000","q":"0.00007000","T":1788333148230,"m":false,"M":true}}
{"type":"trade","received_at_ms":1788333148066,"data":{"e":"trade","E":1788333148230,"s":"BTCUSDT","t":6646665218,"p":"77708.40000000","q":"0.00007000","T":1788333148230,"m":false,"M":true}}
{"type":"trade","received_at_ms":1788333148066,"data":{"e":"trade","E":1788333148230,"s":"BTCUSDT","t":6646665219,"p":"77708.40000000","q":"0.01636000","T":1788333148230,"m":false,"M":true}}
{"type":"depth","received_at_ms":1788333148148,"data":{"e":"depthUpdate","E":1788333148314,"s":"BTCUSDT","U":99556312567,"u":99556312587,"b":[["77654.15000000","0.00411000"],["77520.50000000","0.00000000"],["77507.33000000","0.00812000"],["77506.01000000","0.00000000"],["69937.56000000","0.00425000"],["62167.00000000","0.00450000"],["62166.71000000","0.00000000"]],"a":[["77708.40000000","1.39752000"],["77773.05000000","0.00000000"],["77803.28000000","0.00087000"],["77804.13000000","0.00000000"]]}}
{"type":"depth","received_at_ms":1788333148249,"data":{"e":"depthUpdate","E":1788333148414,"s":"BTCUSDT","U":99556312588,"u":99556312595,"b":[["77689.77000000","0.02007000"],["77487.79000000","0.02016000"],["69937.56000000","0.00441000"]],"a":[["77720.87000000","0.00007000"],["77747.44000000","0.12882000"]]}}
{"type":"depth","received_at_ms":1788333148348,"data":{"e":"depthUpdate","E":1788333148514,"s":"BTCUSDT","U":99556312596,"u":99556312611,"b":[["77695.08000000","0.00000000"],["77646.48000000","0.00000000"],["77627.03000000","0.00000000"],["76542.76000000","0.00030000"],["71491.73000000","0.00014000"],["69937.56000000","0.00441000"],["62167.00000000","0.00450000"],["62166.72000000","0.00032000"]],"a":[["77708.40000000","1.39745000"],["77717.48000000","0.00000000"],["77724.82000000","0.00000000"],["77747.44000000","0.00008000"],["77754.74000000","0.00000000"],["77774.19000000","0.00000000"],["78874.03000000","0.00030000"]]}}
{"type":"depth","received_at_ms":1788333148449,"data":{"e":"depthUpdate","E":1788333148614,"s":"BTCUSDT","U":99556312612,"u":99556312626,"b":[["77698.36000000","0.02000000"],["77659.46000000","0.02000000"],["77639.25000000","0.02000000"],["69937.56000000","0.00425000"],["69937.00000000","0.00000000"],["62166.72000000","0.00000000"]],"a":[["77708.40000000","1.39759000"],["77717.12000000","0.00069000"],["77727.98000000","0.02800000"],["77747.43000000","0.02800000"],["77767.74000000","0.03200000"]]}}
{"type":"trade","received_at_ms":1788333148475,"data":{"e":"trade","E":1788333148639,"s":"BTCUSDT","t":6646665220,"p":"77708.39000000","q":"0.00268000","T":1788333148639,"m":true,"M":true}}
{"type":"trade","received_at_ms":1788333148519,"data":{"e":"trade","E":1788333148684,"s":"BTCUSDT","t":6646665221,"p":"77708.39000000","q":"0.00388000","T":1788333148684,"m":true,"M":true}}
{"type":"depth","received_at_ms":1788333148547,"data":{"e":"depthUpdate","E":1788333148714,"s":"BTCUSDT","U":99556312627,"u":99556312642,"b":[["77708.39000000","1.89968000"],["77685.80000000","0.32950000"],["77680.68000000","0.00000000"],["69937.56000000","0.00448000"],["69937.55000000","0.00009000"],["62167.00000000","0.00450000"],["62166.71000000","0.00000000"]],"a":[["77773.06000000","0.00411000"]]}}
{"type":"depth","received_at_ms":1788333148649,"data":{"e":"depthUpdate","E":1788333148814,"s":"BTCUSDT","U":99556312643,"u":99556312646,"b":[["77696.32000000","0.00000000"],["69937.56000000","0.00432000"]],"a":[]}}
{"type":"depth","received_at_ms":1788333148749,"data":{"e":"depthUpdate","E":1788333148914,"s":"BTCUSDT","U":99556312647,"u":99556312654,"b":[["77654.15000000","0.00000000"],["69937.56000000","0.00448000"]],"a":[["77742.60000000","0.00400000"],["77746.50000000","0.00200000"],["77773.06000000","0.00000000"],["77804.16000000","0.00411000"]]}}
{"type":"trade","received_at_ms":1788333148770,"data":{"e":"trade","E":1788333148928,"s":"BTCUSDT","t":6646665222,"p":"77708.39000000","q":"0.00532000","T":1788333148928,"m":true,"M":true}}
{"type":"depth","received_at_ms":1788333148848,"data":{"e":"depthUpdate","E":1788333149014,"s":"BTCUSDT","U":99556312655,"u":99556312678,"b":[["77708.39000000","1.89436000"],["77702.60000000","0.01000000"],["77702.15000000","0.00000000"],["77700.92000000","0.00643000"],["77699.62000000","0.11129000"],["71491.73000000","0.00000000"],["69937.56000000","0.00432000"],["69937.55000000","0.00000000"],["62166.72000000","0.00032000"]],"a":[["77708.40000000","1.39829000"],["77708.41000000","0.00139000"],["77708.89000000","0.00014000"],["77708.90000000","0.11891000"],["77710.90000000","0.00000000"],["77713.87000000","0.00000000"],["77716.11000000","0.91041000"],["77717.12000000","0.00000000"]]}}
{"type":"depth","received_at_ms":1788333148950,"data":{"e":"depthUpdate","E":1788333149114,"s":"BTCUSDT","U":99556312679,"u":99556312912,"b":[["77708.39000000","1.71235000"],["77708.37000000","0.00105000"],["77708.36000000","0.00014000"],["77708.35000000","0.00014000"],["77708.31000000","0.00000000"],["77708.30000000","0.00014000"],["77707.18000000","0.00000000"],["77705.92000000","0.00014000"],["77705.72000000","0.00014000"],["77705.05000000","0.00129000"],["77704.81000000","0.00000000"],["77704.68000000","0.00007000"],["77704.66000000","0.01986000"],["77704.30000000","0.00000000"],["77704.01000000","0.00000000"],["77703.38000000","0.00000000"],["77703.21000000","0.00208000"],["77702.92000000","0.00000000"],["77702.60000000","0.01007000"],["77701.90000000","0.00000000"],["77701.80000000","0.00514000"],["77701.79000000","0.00000000"],["77700.92000000","0.00000000"],["77700.91000000","0.00000000"],["77700.01000000","0.00643000"],["77699.63000000","0.00200000"],["77699.59000000","0.00000000"],["77699.34000000","0.00000000"],["77698.90000000","0.00000000"],["77698.89000000","1.31471000"],["77697.64000000","0.00000000"],["77697.45000000","0.00000000"],["77697.31000000","0.02000000"],["77697.23000000","0.00000000"],["77697.19000000","0.00000000"],["77697.17000000","0.00000000"],["77697.03000000","0.00400000"],["77696.92000000","0.00000000"],["77696.65000000","0.00000000"],["77696.34000000","0.00643000"],["77694.89000000","0.01200000"],["77689.47000000","0.00000000"],["77688.26000000","0.00000000"],["77686.06000000","0.00000000"],["77685.28000000","0.00000000"],["77680.56000000","0.04658000"],["77680.38000000","0.00200000"],["77678.67000000","0.00000000"],["77673.40000000","0.23630000"],["77673.39000000","0.34777000"],["77672.53000000","0.00000000"],["77664.91000000","0.34781000"],["77642.43000000","1.27568000"],["77500.00000000","1.61272000"],["69937.56000000","0.00448000"]],"a":[["77708.40000000","2.54332000"],["77708.41000000","0.00139000"],["77708.90000000","0.20880000"],["77709.34000000","0.00014000"],["77709.35000000","0.32186000"],["77710.81000000","0.00643000"],["77710.82000000","0.00014000"],["77711.13000000","0.00014000"],["77711.14000000","0.00000000"],["77712.50000000","0.00000000"],["77712.70000000","0.00000000"],["77712.76000000","0.03210000"],["77713.04000000","0.00643000"],["77713.87000000","0.00000000"],["77713.88000000","0.11129000"],["77714.96000000","0.00000000"],["77716.00000000","0.00000000"],["77716.28000000","0.00000000"],["77717.33000000","0.00257000"],["77717.45000000","0.00149000"],["77717.46000000","0.00000000"],["77719.54000000","0.00000000"],["77725.12000000","0.38615000"],["77727.58000000","0.64374000"],["77730.10000000","0.34752000"],["77733.98000000","0.00000000"],["77736.00000000","0.03265000"],["77738.03000000","0.34748000"],["77746.36000000","0.00000000"],["77746.71000000","0.00000000"],["77746.85000000","0.00000000"],["77753.82000000","0.00000000"],["77801.00000000","2.15325000"],["77803.59000000","0.00000000"],["77900.48000000","0.00000000"]]}}
{"type":"depth","received_at_ms":1788333149047,"data":{"e":"depthUpdate","E":1788333149214,"s":"BTCUSDT","U":99556312913,"u":99556313028,"b":[["77708.39000000","1.56675000"],["77708.38000000","0.02023000"],["77708.36000000","0.00000000"],["77708.35000000","0.00000000"],["77708.30000000","0.00000000"],["77707.50000000","0.00000000"],["77704.66000000","0.02000000"],["77704.29000000","0.08050000"],["77702.91000000","0.11143000"],["77702.60000000","0.01014000"],["77701.80000000","0.00257000"],["77701.54000000","0.11136000"],["77700.94000000","0.00257000"],["77699.63000000","0.00200000"],["77697.03000000","0.00000000"],["77696.34000000","0.00000000"],["77696.22000000","0.00000000"],["77696.00000000","0.00007000"],["77695.55000000","0.00400000"],["77694.49000000","0.00643000"],["77686.00000000","0.03000000"],["77672.40000000","0.00400000"],["77665.28000000","0.00007000"],["77624.90000000","0.00000000"],["69937.56000000","0.00432000"],["62166.72000000","0.00000000"]],"a":[["77708.40000000","2.54290000"],["77708.41000000","0.00104000"],["77708.91000000","0.13590000"],["77709.35000000","0.32200000"],["77710.80000000","0.00643000"],["77710.81000000","0.00014000"],["77710.82000000","0.00000000"],["77711.13000000","0.00000000"],["77712.50000000","0.00007000"],["77712.51000000","0.11143000"],["77713.35000000","0.00400000"],["77713.52000000","0.00929000"],["77716.47000000","0.00257000"],["77717.33000000","0.00000000"],["77718.34000000","0.00000000"],["77723.69000000","0.26257000"],["77729.39000000","0.00000000"],["77733.52000000","0.00008000"],["77735.72000000","0.00200000"],["77742.51000000","0.00000000"],["77744.55000000","0.00000000"],["81000.00000000","102.37509000"]]}}
{"type":"depth","received_at_ms":1788333149149,"data":{"e":"depthUpdate","E":1788333149314,"s":"BTCUSDT","U":99556313029,"u":99556313062,"b":[["77708.39000000","1.56485000"],["77708.38000000","0.02023000"],["77705.55000000","0.00000000"],["77699.17000000","0.00188000"],["77676.30000000","0.00400000"],["77507.33000000","0.00000000"],["77506.01000000","0.00812000"],["69937.56000000","0.00448000"],["62166.71000000","0.00000000"]],"a":[["77708.40000000","2.54591000"],["77708.41000000","0.00118000"],["77709.35000000","0.32200000"],["77710.80000000","0.00657000"],["77710.81000000","0.00000000"],["77711.40000000","0.00400000"],["77716.51000000","0.29977000"],["77717.39000000","0.00000000"],["77717.45000000","0.00000000"],["77718.53000000","0.00000000"],["77719.05000000","0.00000000"],["77742.60000000","0.00000000"]]}}
{"type":"depth","received_at_ms":1788333149249,"data":{"e":"depthUpdate","E":1788333149414,"s":"BTCUSDT","U":99556313063,"u":99556313080,"b":[["77708.39000000","1.56492000"],["77704.66000000","0.02007000"],["77704.30000000","0.11129000"],["77695.55000000","0.00000000"],["77689.77000000","0.02000000"],["69937.56000000","0.00432000"]],"a":[["77708.40000000","2.54191000"],["77708.41000000","0.00111000"],["77708.90000000","0.14357000"],["77712.50000000","0.00000000"],["77712.51000000","0.00014000"],["77712.75000000","0.00007000"],["77720.87000000","0.00000000"]]}}
{"type":"depth","received_at_ms":1788333149348,"data":{"e":"depthUpdate","E":1788333149514,"s":"BTCUSDT","U":99556313081,"u":99556313142,"b":[["77708.39000000","1.56682000"],["77704.66000000","0.02007000"],["77704.30000000","0.11143000"],["77702.91000000","0.11129000"],["77699.63000000","0.00200000"],["77699.17000000","0.00000000"],["77696.34000000","0.00800000"],["77694.89000000","0.00000000"],["77689.77000000","0.02007000"],["77654.09000000","0.00411000"],["77619.72000000","1.61379000"],["76542.76000000","0.00030000"],["69937.56000000","0.00448000"],["62166.72000000","0.00032000"]],"a":[["77708.40000000","2.54219000"],["77708.41000000","0.00111000"],["77710.80000000","0.00014000"],["77712.26000000","0.00643000"],["77712.27000000","0.00571000"],["77712.51000000","0.00000000"],["77712.76000000","0.03224000"],["77720.87000000","0.00007000"],["77745.90000000","0.00000000"],["78874.03000000","0.00030000"]]}}
{"type":"depth","received_at_ms":1788333149448,"data":{"e":"depthUpdate","E":1788333149614,"s":"BTCUSDT","U":99556313143,"u":99556313169,"b":[["77640.01000000","0.02000000"],["77622.43000000","0.54234000"],["69937.56000000","0.00432000"],["62167.00000000","0.00450000"],["62166.72000000","0.00000000"]],"a":[["77708.40000000","2.54219000"],["77709.35000000","0.32200000"],["77710.80000000","0.00000000"],["77711.17000000","0.02909000"],["77712.26000000","0.00657000"],["77766.88000000","0.02800000"]]}}
{"type":"depth","received_at_ms":1788333149550,"data":{"e":"depthUpdate","E":1788333149714,"s":"BTCUSDT","U":99556313170,"u":99556313194,"b":[["77708.39000000","1.95953000"],["77704.29000000","0.08057000"],["77702.92000000","0.00643000"],["77700.01000000","0.00000000"],["77699.63000000","0.00600000"],["77696.34000000","0.00000000"],["77654.09000000","0.00000000"],["69937.56000000","0.00448000"],["62166.71000000","0.00020000"]],"a":[["77708.40000000","2.54034000"],["77734.16000000","0.00000000"],["77746.84000000","0.00000000"],["77772.99000000","0.00000000"],["77804.16000000","0.00000000"]]}}
{"type":"depth","received_at_ms":1788333149648,"data":{"e":"depthUpdate","E":1788333149814,"s":"BTCUSDT","U":99556313195,"u":99556313207,"b":[["77704.29000000","0.08057000"],["69937.56000000","0.00432000"],["69937.00000000","0.00000000"],["62166.71000000","0.00000000"]],"a":[["77708.40000000","2.53987000"],["77717.33000000","0.00048000"],["77717.50000000","0.00191000"]]}}
{"type":"trade","received_at_ms":1788333149668,"data":{"e":"trade","E":1788333149833,"s":"BTCUSDT","t":6646665223,"p":"77708.40000000","q":"0.01500000","T":1788333149833,"m":false,"M":true}}
{"type":"depth","received_at_ms":1788333149749,"data":{"e":"depthUpdate","E":1788333149914,"s":"BTCUSDT","U":99556313208,"u":99556313225,"b":[["77699.63000000","0.00200000"],["77696.34000000","0.00400000"],["77683.00000000","0.70000000"],["77655.16000000","0.00411000"],["69937.56000000","0.00425000"]],"a":[["77708.40000000","2.52487000"],["77717.32000000","0.00048000"],["77717.33000000","0.00000000"],["77834.95000000","0.02016000"],["77846.95000000","0.00000000"],["77846.96000000","0.00000000"],["77846.97000000","0.00000000"],["77852.70000000","0.00128000"]]}}
{"type":"depth","received_at_ms":1788333149849,"data":{"e":"depthUpdate","E":1788333150014,"s":"BTCUSDT","U":99556313226,"u":99556313240,"b":[["77708.39000000","1.95960000"],["77704.29000000","0.08050000"],["77702.92000000","0.00000000"],["77702.60000000","0.01021000"],["77701.81000000","0.00643000"],["77699.63000000","0.00200000"],["77696.35000000","0.00400000"],["77696.34000000","0.00000000"],["69937.56000000","0.00441000"],["69937.00000000","0.00000000"],["62166.72000000","0.00032000"]],"a":[["77746.70000000","0.00000000"],["86422.88000000","0.20801000"]]}}
{"type":"trade","received_at_ms":1788333149915,"data":{"e":"trade","E":1788333150079,"s":"BTCUSDT","t":6646665224,"p":"77708.39000000","q":"0.00772000","T":1788333150079,"m":true,"M":true}}
{"type":"trade","received_at_ms":1788333149915,"data":{"e":"trade","E":1788333150079,"s":"BTCUSDT","t":6646665225,"p":"77708.39000000","q":"0.00007000","T":1788333150079,"m":true,"M":true}}
{"type":"trade","received_at_ms":1788333149915,"data":{"e":"trade","E":1788333150079,"s":"BTCUSDT","t":6646665226,"p":"77708.39000000","q":"0.00570000","T":1788333150079,"m":true,"M":true}}
{"type":"depth","received_at_ms":1788333149948,"data":{"e":"depthUpdate","E":1788333150114,"s":"BTCUSDT","U":99556313241,"u":99556313258,"b":[["77708.39000000","1.96928000"],["77704.29000000","0.08050000"],["69937.56000000","0.00441000"],["69937.00000000","0.00000000"]],"a":[["77730.24000000","0.00411000"],["77834.95000000","0.00000000"],["78096.95000000","0.00025000"],["86422.88000000","0.22692000"]]}}
{"type":"depth","received_at_ms":1788333150048,"data":{"e":"depthUpdate","E":1788333150214,"s":"BTCUSDT","U":99556313259,"u":99556313275,"b":[["69937.56000000","0.00441000"],["62166.72000000","0.00000000"]],"a":[["77708.40000000","2.52528000"],["77717.32000000","0.00000000"],["77746.71000000","0.00000000"],["77746.78000000","0.00000000"],["77850.79000000","0.00000000"],["77885.97000000","0.00000000"],["77899.72000000","0.02028000"]]}}
{"type":"depth","received_at_ms":1788333150151,"data":{"e":"depthUpdate","E":1788333150314,"s":"BTCUSDT","U":99556313276,"u":99556313294,"b":[["77702.30000000","0.00407000"],["77699.63000000","0.00600000"],["77696.35000000","0.00000000"],["69937.56000000","0.00441000"],["62167.00000000","0.00450000"],["62166.71000000","0.00000000"]],"a":[["77708.40000000","2.52535000"],["77713.19000000","0.00400000"],["77717.50000000","0.00000000"],["77746.30000000","0.00000000"],["77800.20000000","0.00411000"],["84202.54000000","0.01768000"]]}}
{"type":"depth","received_at_ms":1788333150248,"data":{"e":"depthUpdate","E":1788333150414,"s":"BTCUSDT","U":99556313295,"u":99556313361,"b":[["77702.63000000","0.00000000"],["77702.62000000","0.00400000"],["77702.48000000","0.00000000"],["77702.40000000","0.00000000"],["77702.39000000","0.00000000"],["77702.30000000","0.00007000"],["77699.63000000","0.01400000"],["77696.34000000","0.00000000"],["69937.56000000","0.00457000"],["62167.00000000","0.00450000"]],"a":[["77708.40000000","2.52535000"],["77717.51000000","0.00000000"]]}}
{"type":"depth","received_at_ms":1788333150350,"data":{"e":"depthUpdate","E":1788333150515,"s":"BTCUSDT","U":99556313362,"u":99556313376,"b":[["77708.39000000","1.96935000"],["77689.77000000","0.02007000"],["76542.76000000","0.00030000"],["69937.56000000","0.00425000"],["69937.00000000","0.00010000"],["62166.72000000","0.00032000"]],"a":[["77708.40000000","2.52535000"],["77717.47000000","0.00190000"],["77720.87000000","0.00007000"],["78874.03000000","0.00030000"]]}}
{"type":"depth","received_at_ms":1788333150448,"data":{"e":"depthUpdate","E":1788333150614,"s":"BTCUSDT","U":99556313377,"u":99556313413,"b":[["77699.64000000","0.01200000"],["77699.63000000","0.00200000"],["77696.34000000","0.00000000"],["69937.56000000","0.00473000"],["69937.00000000","0.00000000"],["62167.00000000","0.00450000"],["62166.72000000","0.00000000"]],"a":[["77717.47000000","0.00000000"]]}}
{"type":"depth","received_at_ms":1788333150549,"data":{"e":"depthUpdate","E":1788333150714,"s":"BTCUSDT","U":99556313414,"u":99556313427,"b":[["77699.64000000","0.00000000"],["77696.34000000","0.01200000"],["69937.56000000","0.00457000"]],"a":[["77708.40000000","2.52724000"],["77719.78000000","0.00007000"],["77719.79000000","0.00000000"],["77746.67000000","0.00000000"]]}}
{"type":"depth","received_at_ms":1788333150650,"data":{"e":"depthUpdate","E":1788333150814,"s":"BTCUSDT","U":99556313428,"u":99556313434,"b":[["77622.31000000","1.61379000"],["77619.72000000","0.00000000"],["69937.56000000","0.00473000"],["62166.71000000","0.00000000"]],"a":[]}}
{"type":"trade","received_at_ms":1788333150698,"data":{"e":"trade","E":1788333150864,"s":"BTCUSDT","t":6646665227,"p":"77708.39000000","q":"0.01500000","T":1788333150863,"m":true,"M":true}}
{"type":"depth","received_at_ms":1788333150751,"data":{"e":"depthUpdate","E":1788333150915,"s":"BTCUSDT","U":99556313435,"u":99556313514,"b":[["77708.39000000","1.95435000"],["77655.16000000","0.00000000"],["69937.56000000","0.00448000"],["69937.55000000","0.00009000"],["69937.00000000","0.00010000"]],"a":[["77708.40000000","2.52724000"],["77730.24000000","0.00000000"],["77769.11000000","0.00411000"],["77800.20000000","0.00000000"]]}}
{"type":"depth","received_at_ms":1788333150849,"data":{"e":"depthUpdate","E":1788333151014,"s":"BTCUSDT","U":99556313515,"u":99556313530,"b":[["69937.56000000","0.00464000"],["69937.00000000","0.00000000"],["62167.00000000","0.00450000"],["62166.72000000","0.00032000"]],"a":[["77708.40000000","2.52703000"]]}}
{"type":"depth","received_at_ms":1788333150948,"data":{"e":"depthUpdate","E":1788333151114,"s":"BTCUSDT","U":99556313531,"u":99556313555,"b":[["77708.39000000","1.95428000"],["77702.62000000","0.00000000"],["77702.28000000","0.00000000"],["77702.25000000","0.00400000"],["77696.35000000","0.00800000"],["77696.34000000","0.00400000"],["69937.56000000","0.00448000"]],"a":[["77708.40000000","2.52724000"]]}}
{"type":"depth","received_at_ms":1788333151048,"data":{"e":"depthUpdate","E":1788333151214,"s":"BTCUSDT","U":99556313556,"u":99556313558,"b":[["77708.39000000","1.73006000"],["69937.56000000","0.00464000"],["62166.72000000","0.00000000"]],"a":[]}}
{"type":"depth","received_at_ms":1788333151148,"data":{"e":"depthUpdate","E":1788333151314,"s":"BTCUSDT","U":99556313559,"u":99556313570,"b":[["77692.86000000","0.18807000"],["77665.28000000","0.00000000"],["77655.16000000","0.00411000"],["69937.56000000","0.00448000"],["62166.71000000","0.00020000"]],"a":[["77708.40000000","2.52689000"]]}}
{"type":"depth","received_at_ms":1788333151248,"data":{"e":"depthUpdate","E":1788333151414,"s":"BTCUSDT","U":99556313571,"u":99556313598,"b":[["77696.35000000","0.00000000"],["77696.34000000","0.01200000"],["69937.56000000","0.00448000"],["62167.00000000","0.00450000"],["62166.71000000","0.00000000"]],"a":[["77708.40000000","2.52696000"],["77746.14000000","0.00000000"],["77746.26000000","1.93226000"],["77746.28000000","0.00000000"]]}}
{"type":"trade","received_at_ms":1788333151260,"data":{"e":"trade","E":1788333151425,"s":"BTCUSDT","t":6646665228,"p":"77708.40000000","q":"0.00258000","T":1788333151425,"m":false,"M":true}}
{"type":"depth","received_at_ms":1788333151348,"data":{"e":"depthUpdate","E":1788333151514,"s":"BTCUSDT","U":99556313599,"u":99556313621,"b":[["77702.25000000","0.00000000"],["77702.16000000","0.00400000"],["77702.15000000","0.00000000"],["77696.34000000","0.00400000"],["77689.77000000","0.02007000"],["76542.76000000","0.00030000"],["75557.14000000","0.00000000"],["69937.55000000","0.00000000"],["62167.00000000","0.00450000"],["62166.72000000","0.00032000"]],"a":[["77708.40000000","2.52431000"],["77720.87000000","0.00007000"],["77730.25000000","0.00411000"],["78874.03000000","0.00030000"],["81001.14000000","0.00000000"]]}}
{"type":"depth","received_at_ms":1788333151448,"data":{"e":"depthUpdate","E":1788333151614,"s":"BTCUSDT","U":99556313622,"u":99556313633,"b":[["77696.35000000","0.00800000"],["69937.56000000","0.00448000"],["62166.72000000","0.00000000"]],"a":[["77708.40000000","2.52466000"]]}}
{"type":"depth","received_at_ms":1788333151549,"data":{"e":"depthUpdate","E":1788333151714,"s":"BTCUSDT","U":99556313634,"u":99556313636,"b":[["69937.56000000","0.00464000"]],"a":[]}}
{"type":"depth","received_at_ms":1788333151649,"data":{"e":"depthUpdate","E":1788333151814,"s":"BTCUSDT","U":99556313637,"u":99556313645,"b":[["77708.39000000","1.83190000"],["69937.56000000","0.00432000"],["62166.71000000","0.00000000"]],"a":[["77708.40000000","2.52277000"]]}}
{"type":"depth","received_at_ms":1788333151749,"data":{"e":"depthUpdate","E":1788333151914,"s":"BTCUSDT","U":99556313646,"u":99556313652,"b":[["69937.56000000","0.00464000"]],"a":[["77717.43000000","0.00000000"],["77745.98000000","0.12874000"],["77746.31000000","0.00000000"]]}}
{"type":"depth","received_at_ms":1788333151849,"data":{"e":"depthUpdate","E":1788333152014,"s":"BTCUSDT","U":99556313653,"u":99556313668,"b":[["77708.39000000","1.73006000"],["77622.31000000","0.00000000"],["77619.72000000","1.61379000"],["69937.56000000","0.00448000"],["69937.00000000","0.00000000"],["62166.72000000","0.00032000"]],"a":[["77708.40000000","2.52469000"],["77717.44000000","0.00000000"],["77745.98000000","0.00000000"],["77746.09000000","0.00000000"]]}}
{"type":"depth","received_at_ms":1788333151949,"data":{"e":"depthUpdate","E":1788333152114,"s":"BTCUSDT","U":99556313669,"u":99556313675,"b":[["69937.56000000","0.00448000"]],"a":[["77708.40000000","2.52441000"],["77746.50000000","0.00000000"]]}}
{"type":"depth","received_at_ms":1788333152048,"data":{"e":"depthUpdate","E":1788333152214,"s":"BTCUSDT","U":99556313676,"u":99556313678,"b":[["69937.56000000","0.00448000"],["62166.72000000","0.00000000"]],"a":[]}}
{"type":"depth","received_at_ms":1788333152149,"data":{"e":"depthUpdate","E":1788333152314,"s":"BTCUSDT","U":99556313679,"u":99556313710,"b":[["77708.39000000","1.33310000"],["77708.38000000","0.03423000"],["77690.10000000","0.00000000"],["77655.16000000","0.00000000"],["69937.56000000","0.00464000"],["62167.00000000","0.00450000"]],"a":[["77708.40000000","2.52420000"],["77708.41000000","0.00104000"],["77730.25000000","0.00000000"],["77769.11000000","0.00000000"],["77800.21000000","0.00411000"]]}}
{"type":"depth","received_at_ms":1788333152249,"data":{"e":"depthUpdate","E":1788333152414,"s":"BTCUSDT","U":99556313711,"u":99556313720,"b":[["77708.39000000","1.33120000"],["77702.16000000","0.00000000"],["77701.43000000","0.00400000"],["77699.25000000","0.00191000"],["75557.14000000","0.00010000"],["69937.56000000","0.00448000"],["62166.71000000","0.00000000"]],"a":[]}}
{"type":"depth","received_at_ms":1788333152348,"data":{"e":"depthUpdate","E":1788333152514,"s":"BTCUSDT","U":99556313721,"u":99556313734,"b":[["77708.39000000","1.39884000"],["77701.73000000","0.00257000"],["77700.94000000","0.00000000"],["77689.77000000","0.02000000"],["76542.76000000","0.00030000"],["69937.56000000","0.00464000"],["62166.72000000","0.00032000"]],"a":[["77716.47000000","0.00000000"],["77717.26000000","0.00257000"],["77720.87000000","0.00000000"],["77746.14000000","0.12874000"],["78874.03000000","0.00030000"]]}}
{"type":"depth","received_at_ms":1788333152449,"data":{"e":"depthUpdate","E":1788333152614,"s":"BTCUSDT","U":99556313735,"u":99556313754,"b":[["77689.77000000","0.02007000"],["69937.56000000","0.00448000"],["62167.00000000","0.00450000"],["62166.72000000","0.00000000"]],"a":[["77708.40000000","2.52140000"],["77709.35000000","0.32864000"],["77720.87000000","0.00007000"],["77745.68000000","0.00000000"],["77745.73000000","0.00000000"],["77746.06000000","0.00000000"],["77746.14000000","0.00000000"],["81001.14000000","0.00010000"]]}}
{"type":"trade","received_at_ms":1788333152482,"data":{"e":"trade","E":1788333152645,"s":"BTCUSDT","t":6646665229,"p":"77708.40000000","q":"0.00448000","T":1788333152645,"m":false,"M":true}}
{"type":"depth","received_at_ms":1788333152551,"data":{"e":"depthUpdate","E":1788333152714,"s":"BTCUSDT","U":99556313755,"u":99556313760,"b":[["69937.56000000","0.00473000"]],"a":[["77708.40000000","2.51692000"],["77730.26000000","0.00411000"]]}}
{"type":"trade","received_at_ms":1788333152575,"data":{"e":"trade","E":1788333152740,"s":"BTCUSDT","t":6646665230,"p":"77708.39000000","q":"0.00228000","T":1788333152740,"m":true,"M":true}}
{"type":"depth","received_at_ms":1788333152648,"data":{"e":"depthUpdate","E":1788333152814,"s":"BTCUSDT","U":99556313761,"u":99556313766,"b":[["77708.39000000","1.32892000"],["69937.56000000","0.00457000"],["62166.71000000","0.00000000"]],"a":[]}}
{"type":"trade","received_at_ms":1788333152670,"data":{"e":"trade","E":1788333152836,"s":"BTCUSDT","t":6646665231,"p":"77708.39000000","q":"0.00007000","T":1788333152835,"m":true,"M":true}}
{"type":"trade","received_at_ms":1788333152670,"data":{"e":"trade","E":1788333152836,"s":"BTCUSDT","t":6646665232,"p":"77708.39000000","q":"0.00002000","T":1788333152835,"m":true,"M":true}}
{"type":"depth","received_at_ms":1788333152748,"data":{"e":"depthUpdate","E":1788333152914,"s":"BTCUSDT","U":99556313767,"u":99556314080,"b":[["77708.39000000","1.35199000"],["77708.38000000","0.00830000"],["77707.38000000","0.00014000"],["77707.37000000","0.09887000"],["77705.72000000","0.00000000"],["77705.13000000","0.00000000"],["77705.05000000","0.00014000"],["77704.80000000","0.00007000"],["77704.67000000","0.00007000"],["77704.66000000","0.02021000"],["77704.30000000","0.00014000"],["77704.29000000","0.00014000"],["77704.28000000","0.11204000"],["77703.61000000","0.00000000"],["77703.60000000","0.00000000"],["77703.21000000","0.00000000"],["77702.91000000","0.09993000"],["77702.60000000","0.00000000"],["77702.32000000","0.00000000"],["77701.81000000","0.00000000"],["77701.80000000","0.00000000"],["77701.73000000","0.00000000"],["77701.65000000","0.00000000"],["77701.55000000","0.11136000"],["77701.54000000","0.00000000"],["77701.43000000","0.00000000"],["77700.90000000","0.00000000"],["77700.89000000","0.00217000"],["77700.74000000","0.00014000"],["77700.55000000","0.00000000"],["77700.28000000","0.00000000"],["77700.18000000","0.19461000"],["77700.16000000","0.00000000"],["77699.95000000","0.00000000"],["77699.78000000","0.00000000"],["77699.71000000","0.00000000"],["77699.63000000","0.00000000"],["77699.62000000","0.11386000"],["77699.61000000","0.00000000"],["77699.01000000","0.00000000"],["77698.89000000","0.00000000"],["77698.45000000","0.00643000"],["77698.10000000","0.03000000"],["77697.75000000","0.00704000"],["77697.51000000","0.11129000"],["77697.35000000","0.00047000"],["77697.31000000","0.00000000"],["77696.60000000","0.00160000"],["77696.35000000","0.00000000"],["77696.34000000","0.00600000"],["77696.33000000","0.00000000"],["77696.22000000","0.11129000"],["77696.21000000","0.40871000"],["77695.63000000","0.00000000"],["77694.89000000","0.10059000"],["77694.49000000","0.00000000"],["77693.79000000","0.00000000"],["77693.34000000","0.00400000"],["77693.33000000","0.00000000"],["77693.12000000","0.00008000"],["77692.89000000","0.00643000"],["77690.99000000","0.00000000"],["77690.67000000","0.00400000"],["77688.99000000","0.04000000"],["77685.39000000","0.00000000"],["77684.53000000","0.50104000"],["77683.00000000","0.00000000"],["77681.88000000","0.00000000"],["77681.58000000","0.00000000"],["77680.56000000","0.00000000"],["77680.26000000","0.00000000"],["77678.38000000","0.44163000"],["77677.41000000","0.04647000"],["77675.49000000","0.00118000"],["77674.65000000","0.00000000"],["77674.35000000","0.00400000"],["77666.55000000","0.00400000"],["77666.31000000","0.00000000"],["77665.28000000","0.34788000"],["77661.34000000","0.00000000"],["77642.84000000","0.00321000"],["77635.12000000","1.27580000"],["77629.72000000","0.00000000"],["77622.43000000","0.06951000"],["77619.72000000","0.00000000"],["77619.19000000","1.03852000"],["77617.13000000","1.61379000"],["77579.69000000","0.36078000"],["77564.01000000","0.00128000"],["69937.56000000","0.00457000"]],"a":[["77708.40000000","4.72863000"],["77708.41000000","0.00097000"],["77708.53000000","0.00014000"],["77708.54000000","0.03210000"],["77708.89000000","0.00014000"],["77708.91000000","0.14137000"],["77709.35000000","0.32200000"],["77709.45000000","0.00400000"],["77710.67000000","0.00000000"],["77711.14000000","0.00000000"],["77711.15000000","0.01296000"],["77711.16000000","0.02895000"],["77711.17000000","0.00014000"],["77712.26000000","0.00014000"],["77712.51000000","0.00000000"],["77712.75000000","0.00000000"],["77713.19000000","0.00000000"],["77713.28000000","0.00257000"],["77713.88000000","0.00000000"],["77714.54000000","0.00000000"],["77715.24000000","0.00149000"],["77715.25000000","0.00000000"],["77716.10000000","0.00000000"],["77716.51000000","0.29828000"],["77717.26000000","0.00000000"],["77718.56000000","0.02000000"],["77725.99000000","0.25750000"],["77726.64000000","0.00000000"],["77731.17000000","0.34751000"],["77733.99000000","0.00000000"],["77739.42000000","0.00000000"],["77740.65000000","0.00000000"],["77744.00000000","0.03007000"],["77769.13000000","0.00411000"]]}}
{"type":"depth","received_at_ms":1788333152850,"data":{"e":"depthUpdate","E":1788333153014,"s":"BTCUSDT","U":99556314081,"u":99556314162,"b":[["77708.39000000","1.01584000"],["77708.38000000","0.00830000"],["77707.37000000","0.09901000"],["77705.05000000","0.00000000"],["77705.04000000","0.00014000"],["77704.67000000","0.00014000"],["77704.66000000","0.02007000"],["77704.30000000","0.00000000"],["77704.29000000","0.00007000"],["77704.28000000","0.11218000"],["77700.50000000","0.02902000"],["77699.70000000","0.00000000"],["77696.34000000","0.00000000"],["77694.90000000","0.00200000"],["77693.12000000","0.00408000"],["77670.45000000","0.00400000"],["69937.56000000","0.00457000"],["69937.00000000","0.00020000"],["62166.72000000","0.00032000"]],"a":[["77708.40000000","4.72821000"],["77708.41000000","0.00062000"],["77708.54000000","0.03224000"],["77711.14000000","0.00000000"],["77711.15000000","0.01296000"],["77711.16000000","0.02909000"],["77711.17000000","0.00000000"],["77712.26000000","0.00000000"]]}}
{"type":"trade","received_at_ms":1788333152929,"data":{"e":"trade","E":1788333153095,"s":"BTCUSDT","t":6646665233,"p":"77708.39000000","q":"0.00067000","T":1788333153094,"m":true,"M":true}}
{"type":"trade","received_at_ms":1788333152929,"data":{"e":"trade","E":1788333153095,"s":"BTCUSDT","t":6646665234,"p":"77708.39000000","q":"0.00048000","T":1788333153094,"m":true,"M":true}}
{"type":"trade","received_at_ms":1788333152929,"data":{"e":"trade","E":1788333153095,"s":"BTCUSDT","t":6646665235,"p":"77708.39000000","q":"0.00007000","T":1788333153094,"m":true,"M":true}}
{"type":"trade","received_at_ms":1788333152929,"data":{"e":"trade","E":1788333153095,"s":"BTCUSDT","t":6646665236,"p":"77708.39000000","q":"0.00007000","T":1788333153094,"m":true,"M":true}}
{"type":"trade","received_at_ms":1788333152929,"data":{"e":"trade","E":1788333153095,"s":"BTCUSDT","t":6646665237,"p":"77708.39000000","q":"0.00574000","T":1788333153094,"m":true,"M":true}}
{"type":"depth","received_at_ms":1788333152955,"data":{"e":"depthUpdate","E":1788333153114,"s":"BTCUSDT","U":99556314163,"u":99556314184,"b":[["77708.39000000","0.93929000"],["77705.71000000","0.01323000"],["77705.04000000","0.00000000"],["77702.91000000","0.10007000"],["77700.18000000","0.19468000"],["77655.16000000","0.00411000"],["69937.56000000","0.00448000"],["69937.55000000","0.00009000"],["69937.00000000","0.00000000"]],"a":[["77718.38000000","0.00600000"],["77719.00000000","0.00000000"],["77728.00000000","0.03265000"],["77730.26000000","0.00000000"],["77769.13000000","0.00000000"],["77800.21000000","0.00000000"]]}}
{"type":"depth","received_at_ms":1788333153051,"data":{"e":"depthUpdate","E":1788333153214,"s":"BTCUSDT","U":99556314185,"u":99556314195,"b":[["77708.39000000","0.99850000"],["77506.01000000","0.00000000"],["77500.01000000","0.00812000"],["69937.56000000","0.00464000"],["62166.72000000","0.00000000"]],"a":[["77745.53000000","0.00625000"],["77755.10000000","0.00023000"]]}}
{"type":"depth","received_at_ms":1788333153151,"data":{"e":"depthUpdate","E":1788333153314,"s":"BTCUSDT","U":99556314196,"u":99556314329,"b":[["77708.39000000","2.70458000"],["77708.38000000","0.00837000"],["77707.78000000","0.00027000"],["77707.39000000","0.00014000"],["77707.38000000","0.04484000"],["77704.81000000","0.00206000"],["77704.29000000","0.10013000"],["77704.28000000","0.11225000"],["77703.55000000","0.00257000"],["77703.21000000","0.00643000"],["77702.04000000","0.00257000"],["77700.89000000","0.00000000"],["77700.74000000","0.00021000"],["77700.19000000","0.00643000"],["77700.09000000","0.00000000"],["77699.62000000","0.11129000"],["77698.45000000","0.00000000"],["77697.75000000","0.00447000"],["77697.52000000","0.00600000"],["77696.21000000","1.07160000"],["77694.90000000","2.30564000"],["77694.89000000","0.00000000"],["77693.12000000","0.00008000"],["77692.89000000","0.00000000"],["77665.33000000","1.27530000"],["77665.28000000","0.34781000"],["77635.12000000","0.00000000"],["69937.56000000","0.00448000"]],"a":[["77708.40000000","2.32954000"],["77708.41000000","0.00111000"],["77708.53000000","0.00000000"],["77708.54000000","0.00014000"],["77708.89000000","0.00000000"],["77708.90000000","0.00028000"],["77711.15000000","0.01303000"],["77712.75000000","0.00014000"],["77713.04000000","0.00000000"],["77713.05000000","0.00000000"],["77713.28000000","0.00000000"],["77714.71000000","0.01286000"],["77715.24000000","0.00000000"],["77715.62000000","0.00000000"],["77716.08000000","0.00000000"],["77716.09000000","1.19268000"],["77716.10000000","3.25897000"],["77716.11000000","0.00000000"],["77716.12000000","0.00000000"],["77716.18000000","0.00008000"],["77716.45000000","0.00000000"],["77717.57000000","0.00257000"],["77718.56000000","0.00000000"],["77723.69000000","0.00000000"],["77723.99000000","0.00000000"],["77725.46000000","0.02000000"],["77725.98000000","0.27194000"],["77725.99000000","0.00000000"],["77728.00000000","0.03007000"],["77728.83000000","0.25751000"],["77730.10000000","0.00000000"],["77732.22000000","0.00000000"],["77736.00000000","0.03007000"],["77747.56000000","0.34744000"],["77769.11000000","0.00411000"],["77899.41000000","3.85295000"]]}}
{"type":"depth","received_at_ms":1788333153249,"data":{"e":"depthUpdate","E":1788333153414,"s":"BTCUSDT","U":99556314330,"u":99556314512,"b":[["77708.39000000","2.70881000"],["77708.38000000","0.00837000"],["77707.79000000","0.00000000"],["77707.40000000","0.00196000"],["77707.38000000","0.04498000"],["77706.35000000","0.00257000"],["77705.52000000","0.00000000"],["77704.82000000","0.00000000"],["77704.81000000","0.00000000"],["77704.68000000","0.00014000"],["77704.66000000","0.02014000"],["77704.29000000","0.10027000"],["77704.28000000","0.11211000"],["77703.55000000","0.00000000"],["77702.91000000","0.09993000"],["77702.04000000","0.00000000"],["77701.65000000","0.00400000"],["77700.21000000","0.91578000"],["77700.20000000","1.93226000"],["77700.18000000","0.00000000"],["77700.17000000","0.00000000"],["77699.70000000","0.00400000"],["77699.62000000","0.00000000"],["77699.25000000","0.00000000"],["77697.75000000","0.00400000"],["77697.52000000","0.00400000"],["77697.51000000","0.00000000"],["77697.35000000","0.00000000"],["77696.81000000","0.00000000"],["77696.22000000","0.00000000"],["77694.90000000","1.93226000"],["77694.89000000","0.37338000"],["77682.30000000","0.03210000"],["77674.60000000","0.09493000"],["77670.45000000","0.00000000"],["77669.22000000","0.00007000"],["77668.50000000","0.00000000"],["77666.55000000","0.00000000"],["69937.56000000","0.00448000"],["62166.71000000","0.00000000"]],"a":[["77708.40000000","2.20869000"],["77708.41000000","0.00111000"],["77708.54000000","0.00000000"],["77708.62000000","0.00007000"],["77708.90000000","0.00014000"],["77708.91000000","0.13590000"],["77709.35000000","0.32867000"],["77712.76000000","0.03224000"],["77713.52000000","0.00943000"],["77714.71000000","0.00014000"],["77716.06000000","0.00007000"],["77716.07000000","1.22833000"],["77716.08000000","1.93226000"],["77716.09000000","0.00000000"],["77716.10000000","1.32271000"],["77716.17000000","0.00643000"],["77717.51000000","0.00643000"],["77717.57000000","0.00000000"],["77717.95000000","0.00048000"],["77718.05000000","0.00048000"],["77720.36000000","0.00034000"],["77721.06000000","0.00000000"],["77725.98000000","0.00000000"],["77727.58000000","0.00000000"],["77728.43000000","0.29254000"],["77728.83000000","0.00000000"],["77731.16000000","0.64375000"],["77731.17000000","0.00000000"],["77732.76000000","0.25750000"],["77735.72000000","0.00000000"],["77738.32000000","0.00200000"],["77744.00000000","0.03265000"],["77755.89000000","0.34740000"]]}}
{"type":"trade","received_at_ms":1788333153276,"data":{"e":"trade","E":1788333153442,"s":"BTCUSDT","t":6646665238,"p":"77708.40000000","q":"0.01500000","T":1788333153442,"m":false,"M":true}}
{"type":"depth","received_at_ms":1788333153348,"data":{"e":"depthUpdate","E":1788333153514,"s":"BTCUSDT","U":99556314513,"u":99556314579,"b":[["77708.39000000","2.70715000"],["77708.38000000","0.00858000"],["77708.00000000","0.00014000"],["77707.99000000","0.04000000"],["77707.78000000","0.00000000"],["77706.35000000","0.00000000"],["77705.79000000","0.00257000"],["77705.55000000","0.00400000"],["77704.81000000","0.00257000"],["77704.67000000","0.00000000"],["77704.46000000","0.00000000"],["77703.60000000","0.00400000"],["77700.50000000","0.02895000"],["77700.43000000","0.00200000"],["77700.22000000","1.31471000"],["77700.21000000","0.80449000"],["77692.86000000","0.00022000"],["77687.44000000","0.00000000"],["77680.38000000","0.00000000"],["77674.35000000","0.00000000"],["77672.40000000","0.00000000"],["77669.22000000","0.00000000"],["76931.33000000","0.00025000"],["69937.56000000","0.00448000"],["69937.55000000","0.00000000"],["62166.72000000","0.00032000"]],"a":[["77708.40000000","2.19362000"],["77708.41000000","0.00111000"],["77709.45000000","0.00000000"],["77711.40000000","0.00000000"],["77713.52000000","0.00943000"],["77714.71000000","0.00000000"],["77714.76000000","0.01129000"],["77716.06000000","0.00407000"],["77718.30000000","0.00188000"],["77720.00000000","0.03114000"],["77721.33000000","0.00257000"],["77732.78000000","0.00000000"],["77735.58000000","0.32950000"],["77740.65000000","0.00400000"],["77744.55000000","0.00400000"]]}}
{"type":"depth","received_at_ms":1788333153448,"data":{"e":"depthUpdate","E":1788333153614,"s":"BTCUSDT","U":99556314580,"u":99556314610,"b":[["77708.39000000","2.70708000"],["77708.38000000","0.00851000"],["77707.99000000","0.04014000"],["77704.29000000","0.10013000"],["77689.77000000","0.02007000"],["77684.94000000","0.00200000"],["77480.97000000","0.01545000"],["77435.90000000","0.01545000"],["77365.42000000","0.00000000"],["77320.16000000","0.00000000"],["76542.76000000","0.00030000"],["69937.56000000","0.00464000"],["62167.00000000","0.00650000"],["62166.72000000","0.00000000"]],"a":[["77708.40000000","2.19355000"],["77708.41000000","0.00111000"],["77708.62000000","0.00014000"],["77713.10000000","0.00027000"],["77720.87000000","0.00007000"],["77736.00000000","0.03265000"],["78874.03000000","0.00030000"]]}}
{"type":"depth","received_at_ms":1788333153551,"data":{"e":"depthUpdate","E":1788333153714,"s":"BTCUSDT","U":99556314611,"u":99556314615,"b":[["69937.56000000","0.00432000"],["62167.00000000","0.00450000"]],"a":[["77744.28000000","0.00000000"]]}}
{"type":"depth","received_at_ms":1788333153650,"data":{"e":"depthUpdate","E":1788333153814,"s":"BTCUSDT","U":99556314616,"u":99556314620,"b":[["69937.56000000","0.00464000"],["62166.71000000","0.00000000"]],"a":[["77744.85000000","0.12874000"]]}}
{"type":"depth","received_at_ms":1788333153750,"data":{"e":"depthUpdate","E":1788333153914,"s":"BTCUSDT","U":99556314621,"u":99556314637,"b":[["77708.39000000","2.70916000"],["77704.28000000","0.00082000"],["77692.93000000","0.37207000"],["77686.00000000","0.73000000"],["69937.56000000","0.00432000"]],"a":[["77709.35000000","0.32200000"],["77711.81000000","0.10095000"],["77724.50000000","0.00000000"],["77724.70000000","0.04556000"],["77744.85000000","0.00000000"],["77745.56000000","0.12874000"]]}}
{"type":"depth","received_at_ms":1788333153852,"data":{"e":"depthUpdate","E":1788333154014,"s":"BTCUSDT","U":99556314638,"u":99556314663,"b":[["77708.39000000","2.70909000"],["77704.29000000","0.06847000"],["77700.23000000","0.11129000"],["69937.56000000","0.00448000"],["62167.00000000","0.00450000"],["62166.72000000","0.00032000"]],"a":[["77708.40000000","2.19362000"],["77708.41000000","0.00118000"],["77711.16000000","0.02909000"],["77711.80000000","0.00014000"],["77711.81000000","0.10109000"],["77714.76000000","0.01115000"],["77716.06000000","0.00400000"],["77716.07000000","1.22826000"]]}}
{"type":"depth","received_at_ms":1788333154051,"data":{"e":"depthUpdate","E":1788333154114,"s":"BTCUSDT","U":99556314664,"u":99556314695,"b":[["77708.39000000","2.70853000"],["77708.38000000","0.00851000"],["77707.40000000","0.00000000"],["77706.66000000","0.00257000"],["77706.35000000","0.00198000"],["77705.79000000","0.00000000"],["71491.73000000","0.00014000"],["69937.56000000","0.00432000"]],"a":[["77708.40000000","2.04651000"],["77708.62000000","0.00007000"],["77713.10000000","0.00027000"],["77716.06000000","0.00400000"],["77721.33000000","0.00000000"],["77722.20000000","0.00257000"],["77723.23000000","0.00000000"],["77729.75000000","0.00128000"],["77748.02000000","0.00007000"]]}}
{"type":"depth","received_at_ms":1788333154068,"data":{"e":"depthUpdate","E":1788333154214,"s":"BTCUSDT","U":99556314696,"u":99556314702,"b":[["77708.39000000","2.70860000"],["77708.38000000","0.00858000"],["69937.56000000","0.00448000"],["69937.00000000","0.00020000"],["62166.72000000","0.00000000"]],"a":[]}}
{"type":"depth","received_at_ms":1788333154150,"data":{"e":"depthUpdate","E":1788333154314,"s":"BTCUSDT","U":99556314703,"u":99556314724,"b":[["77706.66000000","0.00000000"],["77508.01000000","0.00812000"],["77500.01000000","0.00000000"],["69937.56000000","0.00432000"],["69937.00000000","0.00000000"],["62167.00000000","0.00450000"]],"a":[["77708.40000000","2.04651000"],["77711.80000000","0.00000000"],["77711.81000000","0.00014000"],["77715.25000000","0.11129000"],["77716.06000000","0.00407000"],["77722.20000000","0.00000000"],["77723.45000000","0.00257000"],["77730.24000000","0.00411000"]]}}
{"type":"trade","received_at_ms":1788333154188,"data":{"e":"trade","E":1788333154354,"s":"BTCUSDT","t":6646665239,"p":"77708.40000000","q":"0.00131000","T":1788333154354,"m":false,"M":true}}
{"type":"depth","received_at_ms":1788333154249,"data":{"e":"depthUpdate","E":1788333154414,"s":"BTCUSDT","U":99556314725,"u":99556314763,"b":[["77708.39000000","2.70860000"],["77708.38000000","0.00851000"],["76700.41000000","0.00000000"],["76234.61000000","0.00000000"],["75768.82000000","0.00000000"],["75303.03000000","0.00037000"],["74837.24000000","0.00000000"],["74371.45000000","0.00000000"],["73905.65000000","0.00000000"],["73439.86000000","0.00063000"],["72974.07000000","0.00000000"],["72508.28000000","0.00000000"],["69937.56000000","0.00441000"],["62166.71000000","0.00000000"]],"a":[["77708.40000000","2.35017000"],["77708.41000000","0.00118000"],["77711.15000000","0.01893000"],["77711.16000000","0.02909000"],["77711.81000000","0.00000000"],["77711.98000000","0.00014000"],["77711.99000000","0.10095000"],["77714.76000000","0.01129000"],["77715.24000000","0.00000000"],["77716.06000000","0.00400000"],["77721.71000000","0.00257000"],["77723.45000000","0.00000000"],["77748.02000000","0.00000000"]]}}
{"type":"trade","received_at_ms":1788333154306,"data":{"e":"trade","E":1788333154471,"s":"BTCUSDT","t":6646665240,"p":"77708.39000000","q":"0.01500000","T":1788333154471,"m":true,"M":true}}
{"type":"depth","received_at_ms":1788333154349,"data":{"e":"depthUpdate","E":1788333154514,"s":"BTCUSDT","U":99556314764,"u":99556314784,"b":[["77708.39000000","2.69374000"],["77669.22000000","0.00007000"],["69937.56000000","0.00441000"],["62167.00000000","0.00450000"],["62166.72000000","0.00032000"]],"a":[["77708.62000000","0.00014000"],["77711.16000000","0.02909000"],["77711.99000000","0.10109000"],["77714.76000000","0.01115000"],["77721.71000000","0.00000000"]]}}
{"type":"depth","received_at_ms":1788333154451,"data":{"e":"depthUpdate","E":1788333154614,"s":"BTCUSDT","U":99556314785,"u":99556314806,"b":[["77708.39000000","2.69381000"],["77700.20000000","0.00000000"],["77692.93000000","0.00000000"],["77689.77000000","0.02007000"],["77624.90000000","1.61379000"],["77619.19000000","0.71074000"],["77617.13000000","0.00000000"],["76542.76000000","0.00030000"],["71491.73000000","0.00000000"],["69937.56000000","0.00441000"],["62166.72000000","0.00000000"]],"a":[["77708.40000000","2.35003000"],["77720.76000000","0.00257000"],["77720.87000000","0.00007000"],["78874.03000000","0.00030000"]]}}
{"type":"depth","received_at_ms":1788333154548,"data":{"e":"depthUpdate","E":1788333154714,"s":"BTCUSDT","U":99556314807,"u":99556314821,"b":[["77706.35000000","0.00000000"],["77704.82000000","0.00200000"],["77704.81000000","0.00000000"],["77703.61000000","0.00257000"],["77700.43000000","0.00000000"],["77700.23000000","0.63176000"],["77700.21000000","0.00000000"],["77696.22000000","0.00200000"],["77684.94000000","0.00000000"],["77681.97000000","0.00200000"],["77655.16000000","0.00000000"],["69937.56000000","0.00457000"]],"a":[["77708.40000000","2.37235000"],["77708.90000000","0.18353000"],["77730.24000000","0.00000000"],["77769.11000000","0.00000000"],["77800.20000000","0.00411000"]]}}
{"type":"trade","received_at_ms":1788333154641,"data":{"e":"trade","E":1788333154801,"s":"BTCUSDT","t":6646665241,"p":"77708.40000000","q":"0.02317000","T":1788333154801,"m":false,"M":true}}
{"type":"depth","received_at_ms":1788333154650,"data":{"e":"depthUpdate","E":1788333154814,"s":"BTCUSDT","U":99556314822,"u":99556314856,"b":[["77708.39000000","2.69381000"],["77708.38000000","0.00844000"],["69937.56000000","0.00432000"],["69937.55000000","0.00009000"],["62166.71000000","0.00000000"]],"a":[["77708.40000000","2.34925000"],["77708.41000000","0.00125000"],["77708.89000000","0.00014000"],["77708.90000000","0.18367000"],["77709.35000000","0.32810000"],["77711.15000000","0.01303000"],["77711.98000000","0.00000000"],["77711.99000000","0.00222000"],["77712.75000000","0.00007000"],["77713.52000000","0.00929000"],["77716.07000000","0.92329000"],["77719.85000000","0.00257000"],["77720.76000000","0.00000000"]]}}
{"type":"trade","received_at_ms":1788333154729,"data":{"e":"trade","E":1788333154893,"s":"BTCUSDT","t":6646665242,"p":"77708.39000000","q":"0.00035000","T":1788333154893,"m":true,"M":true}}
{"type":"depth","received_at_ms":1788333154750,"data":{"e":"depthUpdate","E":1788333154914,"s":"BTCUSDT","U":99556314857,"u":99556314870,"b":[["77708.39000000","2.69346000"],["69937.56000000","0.00448000"]],"a":[["77711.16000000","0.02909000"],["77711.99000000","0.00000000"],["77713.52000000","0.00943000"]]}}
{"type":"trade","received_at_ms":1788333154828,"data":{"e":"trade","E":1788333154987,"s":"BTCUSDT","t":6646665243,"p":"77708.39000000","q":"0.01702000","T":1788333154987,"m":true,"M":true}}
{"type":"depth","received_at_ms":1788333154860,"data":{"e":"depthUpdate","E":1788333155014,"s":"BTCUSDT","U":99556314871,"u":99556314875,"b":[["77708.39000000","2.67644000"],["69937.56000000","0.00432000"],["69937.00000000","0.00000000"],["62166.72000000","0.00032000"]],"a":[]}}
{"type":"depth","received_at_ms":1788333154948,"data":{"e":"depthUpdate","E":1788333155114,"s":"BTCUSDT","U":99556314876,"u":99556314885,"b":[["69937.56000000","0.00448000"],["69937.00000000","0.00000000"]],"a":[["77708.40000000","2.34918000"],["77708.41000000","0.00118000"],["77719.04000000","0.00257000"],["77719.85000000","0.00000000"],["77769.07000000","0.00411000"]]}}
{"type":"trade","received_at_ms":1788333154976,"data":{"e":"trade","E":1788333155142,"s":"BTCUSDT","t":6646665244,"p":"77708.40000000","q":"0.00008000","T":1788333155141,"m":false,"M":true}}
{"type":"depth","received_at_ms":1788333155048,"data":{"e":"depthUpdate","E":1788333155214,"s":"BTCUSDT","U":99556314886,"u":99556314893,"b":[["69937.56000000","0.00432000"],["69937.55000000","0.00000000"],["62167.00000000","0.00450000"],["62166.72000000","0.00000000"]],"a":[["77708.40000000","2.34910000"]]}}
{"type":"depth","received_at_ms":1788333155148,"data":{"e":"depthUpdate","E":1788333155314,"s":"BTCUSDT","U":99556314894,"u":99556314901,"b":[["77708.39000000","2.67651000"],["77704.30000000","0.00257000"],["77686.39000000","0.00000000"],["77662.97000000","0.00000000"],["77655.16000000","0.00411000"],["69937.56000000","0.00432000"],["69937.00000000","0.00020000"]],"a":[]}}
{"type":"depth","received_at_ms":1788333155249,"data":{"e":"depthUpdate","E":1788333155414,"s":"BTCUSDT","U":99556314902,"u":99556314919,"b":[["77700.24000000","1.93226000"],["77696.22000000","0.00000000"],["77508.01000000","0.00000000"],["77506.01000000","0.00812000"],["69937.56000000","0.00432000"],["69937.00000000","0.00000000"],["62166.71000000","0.00000000"]],"a":[["77708.40000000","2.04418000"],["77708.62000000","0.00007000"],["77708.90000000","0.00028000"],["77716.06000000","0.00000000"],["77716.14000000","0.00000000"],["77724.70000000","0.00000000"],["77724.89000000","0.00000000"]]}}
{"type":"trade","received_at_ms":1788333155249,"data":{"e":"trade","E":1788333155413,"s":"BTCUSDT","t":6646665245,"p":"77708.40000000","q":"0.00009000","T":1788333155413,"m":false,"M":true}}
{"type":"depth","received_at_ms":1788333155349,"data":{"e":"depthUpdate","E":1788333155515,"s":"BTCUSDT","U":99556314920,"u":99556315055,"b":[["77708.39000000","2.67844000"],["77708.38000000","0.00865000"],["77707.50000000","0.00400000"],["77707.40000000","0.00000000"],["77707.29000000","0.00257000"],["77706.35000000","0.00255000"],["77706.11000000","0.00000000"],["77704.82000000","0.00000000"],["77704.67000000","0.00160000"],["77704.66000000","0.02021000"],["77704.30000000","0.10679000"],["77703.61000000","0.00000000"],["77702.15000000","0.00000000"],["77701.56000000","0.00000000"],["77700.75000000","0.00400000"],["77700.25000000","1.24176000"],["77700.24000000","1.93226000"],["77700.23000000","0.00000000"],["77697.52000000","0.00000000"],["77697.37000000","0.02000000"],["77696.60000000","0.00000000"],["77696.00000000","0.00265000"],["77688.99000000","0.02000000"],["77688.98000000","0.00000000"],["77681.97000000","0.00000000"],["77676.30000000","0.00000000"],["77669.22000000","0.00000000"],["77655.16000000","0.00000000"],["77624.46000000","0.00400000"],["69937.56000000","0.00457000"],["69937.00000000","0.00010000"],["62166.72000000","0.00032000"]],"a":[["77708.40000000","2.04418000"],["77708.41000000","0.00111000"],["77708.89000000","0.00000000"],["77708.90000000","0.00014000"],["77709.35000000","0.32200000"],["77711.15000000","0.01940000"],["77712.11000000","0.00208000"],["77712.56000000","0.00007000"],["77712.75000000","0.00000000"],["77712.76000000","0.00014000"],["77713.10000000","0.00000000"],["77713.35000000","0.00000000"],["77715.24000000","0.00000000"],["77715.25000000","0.00000000"],["77716.04000000","0.11143000"],["77716.05000000","1.11828000"],["77716.06000000","2.30964000"],["77716.07000000","0.00000000"],["77716.08000000","0.00000000"],["77716.17000000","0.00000000"],["77718.87000000","0.00643000"],["77719.04000000","0.00000000"],["77721.64000000","0.00000000"],["77722.83000000","0.00257000"],["77724.85000000","0.37338000"],["77730.20000000","0.00411000"],["77731.16000000","0.00000000"],["77735.05000000","0.64375000"],["77735.55000000","0.04720000"],["77738.32000000","0.00000000"],["77739.10000000","0.00200000"],["77748.02000000","0.00007000"],["77748.45000000","0.00400000"],["77769.07000000","0.00000000"],["77800.20000000","0.00000000"],["77801.00000000","0.00000000"],["77803.28000000","0.00000000"]]}}
{"type":"depth","received_at_ms":1788333155455,"data":{"e":"depthUpdate","E":1788333155614,"s":"BTCUSDT","U":99556315056,"u":99556315110,"b":[["77708.39000000","2.69622000"],["77708.38000000","0.00858000"],["77704.66000000","0.02007000"],["77700.26000000","0.00200000"],["77689.77000000","0.02000000"],["77685.08000000","0.00200000"],["76542.76000000","0.00030000"],["69937.56000000","0.00425000"],["69937.00000000","0.00000000"],["62167.00000000","0.00450000"],["62166.72000000","0.00000000"]],"a":[["77708.40000000","2.02186000"],["77712.27000000","0.00571000"],["77712.56000000","0.00014000"],["77712.76000000","0.00000000"],["77712.92000000","0.00027000"],["77713.17000000","0.00014000"],["77713.18000000","0.09887000"],["77714.76000000","0.01129000"],["77716.01000000","0.01129000"],["77716.03000000","0.00014000"],["77716.04000000","0.11129000"],["77716.05000000","1.11814000"],["77720.87000000","0.00000000"],["78874.03000000","0.00030000"]]}}
{"type":"trade","received_at_ms":1788333155456,"data":{"e":"trade","E":1788333155615,"s":"BTCUSDT","t":6646665246,"p":"77708.39000000","q":"0.00148000","T":1788333155615,"m":true,"M":true}}
{"type":"trade","received_at_ms":1788333155456,"data":{"e":"trade","E":1788333155615,"s":"BTCUSDT","t":6646665247,"p":"77708.39000000","q":"0.00043000","T":1788333155615,"m":true,"M":true}}
{"type":"depth","received_at_ms":1788333155548,"data":{"e":"depthUpdate","E":1788333155714,"s":"BTCUSDT","U":99556315111,"u":99556315141,"b":[["77708.39000000","2.69246000"],["77708.38000000","0.00865000"],["77707.30000000","0.00197000"],["77706.35000000","0.00000000"],["77704.81000000","0.00257000"],["77704.66000000","0.02021000"],["77689.77000000","0.02007000"],["77685.05000000","0.49656000"],["77661.75000000","0.99376000"],["69937.56000000","0.00457000"]],"a":[["77708.40000000","2.02179000"],["77708.41000000","0.00118000"],["77712.27000000","0.00571000"],["77713.18000000","0.09901000"],["77716.01000000","0.01115000"],["77720.87000000","0.00007000"],["77800.22000000","0.00411000"]]}}
{"type":"depth","received_at_ms":1788333155648,"data":{"e":"depthUpdate","E":1788333155814,"s":"BTCUSDT","U":99556315142,"u":99556315166,"b":[["77708.39000000","2.69282000"],["77708.38000000","0.00858000"],["77707.29000000","0.00000000"],["77706.09000000","0.00257000"],["76775.89000000","0.00043000"],["69937.56000000","0.00441000"],["62166.71000000","0.00000000"]],"a":[["77708.40000000","2.14611000"],["77708.41000000","0.00111000"],["77713.17000000","0.00000000"],["77713.18000000","0.00014000"],["77716.04000000","0.11136000"],["77721.62000000","0.00257000"],["77722.83000000","0.00000000"],["77748.02000000","0.00000000"]]}}
{"type":"depth","received_at_ms":1788333155749,"data":{"e":"depthUpdate","E":1788333155915,"s":"BTCUSDT","U":99556315167,"u":99556315183,"b":[["77655.16000000","0.00411000"],["69937.56000000","0.00441000"],["69937.00000000","0.00010000"]],"a":[["77708.40000000","2.31809000"],["77712.27000000","0.00571000"],["77713.18000000","0.00000000"],["77716.01000000","0.01129000"]]}}
{"type":"depth","received_at_ms":1788333155857,"data":{"e":"depthUpdate","E":1788333156014,"s":"BTCUSDT","U":99556315184,"u":99556315186,"b":[["69937.00000000","0.00010000"],["62166.72000000","0.00032000"]],"a":[]}}
{"type":"trade","received_at_ms":1788333155857,"data":{"e":"trade","E":1788333156020,"s":"BTCUSDT","t":6646665248,"p":"77708.39000000","q":"0.00013000","T":1788333156020,"m":true,"M":true}}
{"type":"depth","received_at_ms":1788333155948,"data":{"e":"depthUpdate","E":1788333156114,"s":"BTCUSDT","U":99556315187,"u":99556315199,"b":[["77708.39000000","2.69269000"],["77693.67000000","0.16159000"],["77688.00000000","0.73665000"],["77686.00000000","0.03000000"],["76309.64000000","0.00120000"],["69937.56000000","0.00432000"],["69937.55000000","0.00009000"],["69937.00000000","0.00000000"]],"a":[["77746.50000000","0.00400000"],["77748.45000000","0.00000000"]]}}
{"type":"depth","received_at_ms":1788333156051,"data":{"e":"depthUpdate","E":1788333156214,"s":"BTCUSDT","U":99556315200,"u":99556315223,"b":[["77708.39000000","2.69296000"],["77708.38000000","0.00858000"],["77707.30000000","0.00000000"],["77705.93000000","0.00000000"],["77704.81000000","0.00199000"],["77703.61000000","0.00257000"],["77685.08000000","0.00000000"],["77683.06000000","0.00200000"],["69937.56000000","0.00448000"],["62166.72000000","0.00000000"]],"a":[["77708.40000000","2.31816000"],["77713.51000000","0.00643000"],["77715.24000000","0.00014000"],["77715.25000000","0.11129000"],["77716.04000000","0.11129000"],["77718.87000000","0.00000000"]]}}
{"type":"depth","received_at_ms":1788333156149,"data":{"e":"depthUpdate","E":1788333156314,"s":"BTCUSDT","U":99556315224,"u":99556315249,"b":[["77704.66000000","0.02014000"],["77704.30000000","0.00000000"],["77655.16000000","0.00000000"],["69937.56000000","0.00432000"],["62167.00000000","0.00450000"]],"a":[["77708.40000000","2.31823000"],["77708.41000000","0.00118000"],["77712.27000000","0.00571000"],["77713.51000000","0.00657000"],["77714.76000000","0.01129000"],["77716.01000000","0.01115000"],["77730.20000000","0.00000000"],["77745.56000000","0.00000000"],["77769.13000000","0.00411000"],["77800.22000000","0.00000000"]]}}
{"type":"depth","received_at_ms":1788333156248,"data":{"e":"depthUpdate","E":1788333156414,"s":"BTCUSDT","U":99556315250,"u":99556315264,"b":[["77704.66000000","0.02014000"],["69937.56000000","0.00448000"],["62167.00000000","0.00450000"],["62166.71000000","0.00000000"]],"a":[["77708.40000000","2.31830000"],["77713.51000000","0.00014000"],["77715.23000000","0.00643000"]]}}
{"type":"trade","received_at_ms":1788333156341,"data":{"e":"trade","E":1788333156506,"s":"BTCUSDT","t":6646665249,"p":"77708.39000000","q":"0.00402000","T":1788333156506,"m":true,"M":true}}
{"type":"depth","received_at_ms":1788333156348,"data":{"e":"depthUpdate","E":1788333156514,"s":"BTCUSDT","U":99556315265,"u":99556315288,"b":[["77708.39000000","2.68894000"],["76700.00000000","2.89168000"],["75843.39000000","0.00043000"],["69937.56000000","0.00432000"],["69937.55000000","0.00000000"],["69937.00000000","0.00000000"],["62166.72000000","0.00032000"]],"a":[["77708.40000000","2.31823000"],["77708.41000000","0.00111000"],["77712.27000000","0.00571000"],["77713.51000000","0.00000000"],["77714.76000000","0.01129000"],["77715.23000000","0.00657000"]]}}
{"type":"depth","received_at_ms":1788333156448,"data":{"e":"depthUpdate","E":1788333156614,"s":"BTCUSDT","U":99556315289,"u":99556315299,"b":[["77508.01000000","0.00812000"],["77506.01000000","0.00000000"],["76542.76000000","0.00030000"],["69937.56000000","0.00448000"],["62167.00000000","0.00450000"],["62166.72000000","0.00000000"]],"a":[["77801.00000000","2.15325000"],["78485.49000000","0.00025000"],["78874.03000000","0.00030000"]]}}
{"type":"depth","received_at_ms":1788333156549,"data":{"e":"depthUpdate","E":1788333156714,"s":"BTCUSDT","U":99556315300,"u":99556315322,"b":[["77708.39000000","2.69296000"],["77689.77000000","0.02007000"],["77531.72000000","0.00000000"],["69937.56000000","0.00432000"]],"a":[["77708.40000000","2.31830000"],["77708.41000000","0.00118000"],["77708.89000000","0.00014000"],["77708.90000000","0.15407000"],["77709.35000000","0.32816000"],["77711.15000000","0.01303000"],["77716.03000000","0.00000000"],["77716.05000000","0.81317000"],["77720.87000000","0.00007000"],["77729.75000000","0.00000000"],["77729.98000000","0.00128000"],["77730.25000000","0.00411000"],["77742.60000000","0.00400000"],["77746.50000000","0.00000000"]]}}
{"type":"depth","received_at_ms":1788333156648,"data":{"e":"depthUpdate","E":1788333156814,"s":"BTCUSDT","U":99556315323,"u":99556315336,"b":[["75377.14000000","0.00044000"],["69937.56000000","0.00448000"],["62166.71000000","0.00020000"]],"a":[["77708.40000000","2.34062000"],["77708.90000000","0.15421000"],["77715.23000000","0.00643000"]]}}
{"type":"trade","received_at_ms":1788333156671,"data":{"e":"trade","E":1788333156835,"s":"BTCUSDT","t":6646665250,"p":"77708.40000000","q":"0.00140000","T":1788333156835,"m":false,"M":true}}
{"type":"depth","received_at_ms":1788333156748,"data":{"e":"depthUpdate","E":1788333156914,"s":"BTCUSDT","U":99556315337,"u":99556315344,"b":[["77706.09000000","0.00000000"],["77655.16000000","0.00411000"],["69937.56000000","0.00425000"],["62166.71000000","0.00000000"]],"a":[["77708.40000000","2.33922000"],["77708.62000000","0.00014000"]]}}
{"type":"trade","received_at_ms":1788333156804,"data":{"e":"trade","E":1788333156969,"s":"BTCUSDT","t":6646665251,"p":"77708.40000000","q":"0.03496000","T":1788333156969,"m":false,"M":true}}
{"type":"depth","received_at_ms":1788333156849,"data":{"e":"depthUpdate","E":1788333157014,"s":"BTCUSDT","U":99556315345,"u":99556315365,"b":[["77708.39000000","2.69296000"],["77708.38000000","0.00851000"],["77705.09000000","0.00257000"],["77669.22000000","0.00007000"],["77533.22000000","4.59262000"],["69937.56000000","0.00457000"],["62167.00000000","0.00450000"],["62166.72000000","0.00032000"]],"a":[["77708.40000000","2.30426000"],["77710.82000000","0.00014000"],["77710.83000000","0.09887000"],["77711.15000000","0.01289000"],["77720.62000000","0.00257000"],["77721.62000000","0.00000000"],["77752.25000000","0.00672000"],["77760.26000000","0.00000000"]]}}
{"type":"trade","received_at_ms":1788333156870,"data":{"e":"trade","E":1788333157035,"s":"BTCUSDT","t":6646665252,"p":"77708.40000000","q":"0.00011000","T":1788333157035,"m":false,"M":true}}
{"type":"trade","received_at_ms":1788333156886,"data":{"e":"trade","E":1788333157050,"s":"BTCUSDT","t":6646665253,"p":"77708.40000000","q":"0.01500000","T":1788333157049,"m":false,"M":true}}
{"type":"depth","received_at_ms":1788333156949,"data":{"e":"depthUpdate","E":1788333157114,"s":"BTCUSDT","U":99556315366,"u":99556315392,"b":[["77655.16000000","0.00000000"],["74910.89000000","0.00044000"],["69937.56000000","0.00441000"]],"a":[["77708.40000000","2.28922000"],["77708.41000000","0.00125000"],["77709.35000000","0.32816000"],["77710.83000000","0.09901000"],["77714.76000000","0.01115000"],["77730.25000000","0.00000000"],["77745.21000000","0.00000000"],["77745.32000000","0.00000000"],["77745.55000000","0.00000000"],["77747.31000000","0.12874000"],["77769.13000000","0.00000000"],["77800.21000000","0.00411000"]]}}
{"type":"depth","received_at_ms":1788333157048,"data":{"e":"depthUpdate","E":1788333157214,"s":"BTCUSDT","U":99556315393,"u":99556315395,"b":[["69937.56000000","0.00441000"],["62166.72000000","0.00000000"]],"a":[]}}
{"type":"depth","received_at_ms":1788333157156,"data":{"e":"depthUpdate","E":1788333157314,"s":"BTCUSDT","U":99556315396,"u":99556315397,"b":[["69937.56000000","0.00441000"]],"a":[]}}
{"type":"depth","received_at_ms":1788333157248,"data":{"e":"depthUpdate","E":1788333157414,"s":"BTCUSDT","U":99556315398,"u":99556315404,"b":[["74444.64000000","0.00044000"],["69937.56000000","0.00441000"],["62166.71000000","0.00000000"]],"a":[]}}
{"type":"depth","received_at_ms":1788333157348,"data":{"e":"depthUpdate","E":1788333157514,"s":"BTCUSDT","U":99556315405,"u":99556315413,"b":[["77655.16000000","0.00411000"],["75557.14000000","0.00000000"],["69937.56000000","0.00441000"],["62167.00000000","0.00450000"],["62166.72000000","0.00032000"]],"a":[["77729.00000000","0.00000000"],["77735.58000000","0.00000000"],["81001.14000000","0.00000000"]]}}
