{"type":"trade","received_at_ms":1788331889842,"data":{"e":"trade","E":1788331889966,"s":"BTCUSDT","t":6646634432,"p":"77585.82000000","q":"0.00007000","T":1788331889966,"m":true,"M":true}}
{"type":"trade","received_at_ms":1788331889842,"data":{"e":"trade","E":1788331889966,"s":"BTCUSDT","t":6646634433,"p":"77585.82000000","q":"0.00007000","T":1788331889966,"m":true,"M":true}}
{"type":"trade","received_at_ms":1788331889842,"data":{"e":"trade","E":1788331889966,"s":"BTCUSDT","t":6646634434,"p":"77585.82000000","q":"0.00007000","T":1788331889966,"m":true,"M":true}}
{"type":"trade","received_at_ms":1788331889842,"data":{"e":"trade","E":1788331889966,"s":"BTCUSDT","t":6646634435,"p":"77585.82000000","q":"0.00007000","T":1788331889966,"m":true,"M":true}}
{"type":"trade","received_at_ms":1788331889843,"data":{"e":"trade","E":1788331889966,"s":"BTCUSDT","t":6646634436,"p":"77585.60000000","q":"0.00007000","T":1788331889966,"m":true,"M":true}}
{"type":"trade","received_at_ms":1788331889843,"data":{"e":"trade","E":1788331889966,"s":"BTCUSDT","t":6646634437,"p":"77585.60000000","q":"0.00007000","T":1788331889966,"m":true,"M":true}}
{"type":"trade","received_at_ms":1788331889843,"data":{"e":"trade","E":1788331889967,"s":"BTCUSDT","t":6646634438,"p":"77585.56000000","q":"0.00007000","T":1788331889966,"m":true,"M":true}}
{"type":"trade","received_at_ms":1788331889843,"data":{"e":"trade","E":1788331889967,"s":"BTCUSDT","t":6646634439,"p":"77585.56000000","q":"0.00007000","T":1788331889966,"m":true,"M":true}}
{"type":"trade","received_at_ms":1788331889843,"data":{"e":"trade","E":1788331889967,"s":"BTCUSDT","t":6646634440,"p":"77585.56000000","q":"0.00007000","T":1788331889966,"m":true,"M":true}}
{"type":"trade","received_at_ms":1788331889843,"data":{"e":"trade","E":1788331889967,"s":"BTCUSDT","t":6646634441,"p":"77585.56000000","q":"0.00007000","T":1788331889966,"m":true,"M":true}}
{"type":"trade","received_at_ms":1788331889843,"data":{"e":"trade","E":1788331889967,"s":"BTCUSDT","t":6646634442,"p":"77585.56000000","q":"0.00007000","T":1788331889966,"m":true,"M":true}}
{"type":"trade","received_at_ms":1788331889843,"data":{"e":"trade","E":1788331889967,"s":"BTCUSDT","t":6646634443,"p":"77585.54000000","q":"0.00007000","T":1788331889966,"m":true,"M":true}}
{"type":"trade","received_at_ms":1788331889843,"data":{"e":"trade","E":1788331889967,"s":"BTCUSDT","t":6646634444,"p":"77585.54000000","q":"0.00007000","T":1788331889966,"m":true,"M":true}}
{"type":"trade","received_at_ms":1788331889843,"data":{"e":"trade","E":1788331889967,"s":"BTCUSDT","t":6646634445,"p":"77585.33000000","q":"0.00007000","T":1788331889966,"m":true,"M":true}}
{"type":"trade","received_at_ms":1788331889843,"data":{"e":"trade","E":1788331889967,"s":"BTCUSDT","t":6646634446,"p":"77585.33000000","q":"0.00007000","T":1788331889966,"m":true,"M":true}}
{"type":"trade","received_at_ms":1788331889843,"data":{"e":"trade","E":1788331889967,"s":"BTCUSDT","t":6646634447,"p":"77585.33000000","q":"0.00007000","T":1788331889966,"m":true,"M":true}}
{"type":"trade","received_at_ms":1788331889843,"data":{"e":"trade","E":1788331889967,"s":"BTCUSDT","t":6646634448,"p":"77585.33000000","q":"0.00007000","T":1788331889966,"m":true,"M":true}}
{"type":"trade","received_at_ms":1788331889843,"data":{"e":"trade","E":1788331889967,"s":"BTCUSDT","t":6646634449,"p":"77585.33000000","q":"0.00007000","T":1788331889966,"m":true,"M":true}}
{"type":"trade","received_at_ms":1788331889843,"data":{"e":"trade","E":1788331889967,"s":"BTCUSDT","t":6646634450,"p":"77585.32000000","q":"0.00007000","T":1788331889966,"m":true,"M":true}}
{"type":"trade","received_at_ms":1788331889843,"data":{"e":"trade","E":1788331889967,"s":"BTCUSDT","t":6646634451,"p":"77585.32000000","q":"0.00007000","T":1788331889966,"m":true,"M":true}}
{"type":"trade","received_at_ms":1788331889843,"data":{"e":"trade","E":1788331889967,"s":"BTCUSDT","t":6646634452,"p":"77585.32000000","q":"0.00007000","T":1788331889966,"m":true,"M":true}}
{"type":"trade","received_at_ms":1788331889843,"data":{"e":"trade","E":1788331889967,"s":"BTCUSDT","t":6646634453,"p":"77585.32000000","q":"0.00007000","T":1788331889966,"m":true,"M":true}}
{"type":"trade","received_at_ms":1788331889843,"data":{"e":"trade","E":1788331889967,"s":"BTCUSDT","t":6646634454,"p":"77585.32000000","q":"0.00007000","T":1788331889966,"m":true,"M":true}}
{"type":"trade","received_at_ms":1788331889843,"data":{"e":"trade","E":1788331889967,"s":"BTCUSDT","t":6646634455,"p":"77585.32000000","q":"0.00007000","T":1788331889966,"m":true,"M":true}}
{"type":"trade","received_at_ms":1788331889843,"data":{"e":"trade","E":1788331889967,"s":"BTCUSDT","t":6646634456,"p":"77585.32000000","q":"0.00007000","T":1788331889966,"m":true,"M":true}}
{"type":"trade","received_at_ms":1788331889843,"data":{"e":"trade","E":1788331889967,"s":"BTCUSDT","t":6646634457,"p":"77585.32000000","q":"0.00007000","T":1788331889966,"m":true,"M":true}}
{"type":"trade","received_at_ms":1788331889843,"data":{"e":"trade","E":1788331889967,"s":"BTCUSDT","t":6646634458,"p":"77585.32000000","q":"0.00007000","T":1788331889966,"m":true,"M":true}}
{"type":"trade","received_at_ms":1788331889843,"data":{"e":"trade","E":1788331889967,"s":"BTCUSDT","t":6646634459,"p":"77585.32000000","q":"0.00007000","T":1788331889966,"m":true,"M":true}}
{"type":"trade","received_at_ms":1788331889843,"data":{"e":"trade","E":1788331889967,"s":"BTCUSDT","t":6646634460,"p":"77584.48000000","q":"0.00013000","T":1788331889966,"m":true,"M":true}}
{"type":"trade","received_at_ms":1788331889843,"data":{"e":"trade","E":1788331889967,"s":"BTCUSDT","t":6646634461,"p":"77584.46000000","q":"0.04000000","T":1788331889966,"m":true,"M":true}}
{"type":"trade","received_at_ms":1788331889843,"data":{"e":"trade","E":1788331889967,"s":"BTCUSDT","t":6646634462,"p":"77584.15000000","q":"0.00007000","T":1788331889966,"m":true,"M":true}}
{"type":"trade","received_at_ms":1788331889843,"data":{"e":"trade","E":1788331889967,"s":"BTCUSDT","t":6646634463,"p":"77584.15000000","q":"0.00007000","T":1788331889966,"m":true,"M":true}}
{"type":"trade","received_at_ms":1788331889843,"data":{"e":"trade","E":1788331889967,"s":"BTCUSDT","t":6646634464,"p":"77584.15000000","q":"0.00007000","T":1788331889966,"m":true,"M":true}}
{"type":"trade","received_at_ms":1788331889843,"data":{"e":"trade","E":1788331889967,"s":"BTCUSDT","t":6646634465,"p":"77584.15000000","q":"0.00007000","T":1788331889966,"m":true,"M":true}}
{"type":"trade","received_at_ms":1788331889843,"data":{"e":"trade","E":1788331889967,"s":"BTCUSDT","t":6646634466,"p":"77584.15000000","q":"0.00007000","T":1788331889966,"m":true,"M":true}}
{"type":"trade","received_at_ms":1788331889843,"data":{"e":"trade","E":1788331889967,"s":"BTCUSDT","t":6646634467,"p":"77584.08000000","q":"0.16601000","T":1788331889966,"m":true,"M":true}}
{"type":"trade","received_at_ms":1788331889843,"data":{"e":"trade","E":1788331889967,"s":"BTCUSDT","t":6646634468,"p":"77584.00000000","q":"0.00007000","T":1788331889966,"m":true,"M":true}}
{"type":"trade","received_at_ms":1788331889844,"data":{"e":"trade","E":1788331889968,"s":"BTCUSDT","t":6646634469,"p":"77583.85000000","q":"0.00007000","T":1788331889967,"m":true,"M":true}}
{"type":"trade","received_at_ms":1788331889844,"data":{"e":"trade","E":1788331889968,"s":"BTCUSDT","t":6646634470,"p":"77583.85000000","q":"0.00007000","T":1788331889967,"m":true,"M":true}}
{"type":"trade","received_at_ms":1788331889844,"data":{"e":"trade","E":1788331889968,"s":"BTCUSDT","t":6646634471,"p":"77583.85000000","q":"0.00007000","T":1788331889967,"m":true,"M":true}}
{"type":"trade","received_at_ms":1788331889844,"data":{"e":"trade","E":1788331889968,"s":"BTCUSDT","t":6646634472,"p":"77583.85000000","q":"0.00007000","T":1788331889967,"m":true,"M":true}}
{"type":"trade","received_at_ms":1788331889844,"data":{"e":"trade","E":1788331889968,"s":"BTCUSDT","t":6646634473,"p":"77583.85000000","q":"0.00007000","T":1788331889967,"m":true,"M":true}}
{"type":"trade","received_at_ms":1788331889844,"data":{"e":"trade","E":1788331889968,"s":"BTCUSDT","t":6646634474,"p":"77583.84000000","q":"0.00007000","T":1788331889967,"m":true,"M":true}}
{"type":"trade","received_at_ms":1788331889844,"data":{"e":"trade","E":1788331889968,"s":"BTCUSDT","t":6646634475,"p":"77583.84000000","q":"0.00007000","T":1788331889967,"m":true,"M":true}}
{"type":"trade","received_at_ms":1788331889844,"data":{"e":"trade","E":1788331889968,"s":"BTCUSDT","t":6646634476,"p":"77583.84000000","q":"0.00007000","T":1788331889967,"m":true,"M":true}}
{"type":"trade","received_at_ms":1788331889844,"data":{"e":"trade","E":1788331889968,"s":"BTCUSDT","t":6646634477,"p":"77583.84000000","q":"0.00007000","T":1788331889967,"m":true,"M":true}}
{"type":"trade","received_at_ms":1788331889844,"data":{"e":"trade","E":1788331889968,"s":"BTCUSDT","t":6646634478,"p":"77583.84000000","q":"0.00007000","T":1788331889967,"m":true,"M":true}}
{"type":"trade","received_at_ms":1788331889844,"data":{"e":"trade","E":1788331889968,"s":"BTCUSDT","t":6646634479,"p":"77583.80000000","q":"0.00007000","T":1788331889967,"m":true,"M":true}}
{"type":"trade","received_at_ms":1788331889844,"data":{"e":"trade","E":1788331889968,"s":"BTCUSDT","t":6646634480,"p":"77583.80000000","q":"0.00007000","T":1788331889967,"m":true,"M":true}}
{"type":"trade","received_at_ms":1788331889844,"data":{"e":"trade","E":1788331889968,"s":"BTCUSDT","t":6646634481,"p":"77583.46000000","q":"0.00916000","T":1788331889967,"m":true,"M":true}}
{"type":"trade","received_at_ms":1788331889844,"data":{"e":"trade","E":1788331889968,"s":"BTCUSDT","t":6646634482,"p":"77583.46000000","q":"0.07084000","T":1788331889967,"m":true,"M":true}}
{"type":"trade","received_at_ms":1788331889844,"data":{"e":"trade","E":1788331889968,"s":"BTCUSDT","t":6646634483,"p":"77583.35000000","q":"0.00007000","T":1788331889967,"m":true,"M":true}}
{"type":"trade","received_at_ms":1788331889844,"data":{"e":"trade","E":1788331889968,"s":"BTCUSDT","t":6646634484,"p":"77582.83000000","q":"0.00200000","T":1788331889967,"m":true,"M":true}}
{"type":"trade","received_at_ms":1788331889844,"data":{"e":"trade","E":1788331889968,"s":"BTCUSDT","t":6646634485,"p":"77582.83000000","q":"0.00200000","T":1788331889967,"m":true,"M":true}}
{"type":"trade","received_at_ms":1788331889844,"data":{"e":"trade","E":1788331889968,"s":"BTCUSDT","t":6646634486,"p":"77582.83000000","q":"0.00200000","T":1788331889967,"m":true,"M":true}}
{"type":"trade","received_at_ms":1788331889844,"data":{"e":"trade","E":1788331889968,"s":"BTCUSDT","t":6646634487,"p":"77582.83000000","q":"0.00007000","T":1788331889967,"m":true,"M":true}}
{"type":"trade","received_at_ms":1788331889844,"data":{"e":"trade","E":1788331889968,"s":"BTCUSDT","t":6646634488,"p":"77582.83000000","q":"0.00002000","T":1788331889967,"m":true,"M":true}}
{"type":"trade","received_at_ms":1788331889844,"data":{"e":"trade","E":1788331889968,"s":"BTCUSDT","t":6646634489,"p":"77582.54000000","q":"0.00007000","T":1788331889967,"m":true,"M":true}}
{"type":"trade","received_at_ms":1788331889844,"data":{"e":"trade","E":1788331889968,"s":"BTCUSDT","t":6646634490,"p":"77582.53000000","q":"0.00008000","T":1788331889967,"m":true,"M":true}}
{"type":"trade","received_at_ms":1788331889844,"data":{"e":"trade","E":1788331889968,"s":"BTCUSDT","t":6646634491,"p":"77581.76000000","q":"0.00070000","T":1788331889967,"m":true,"M":true}}
{"type":"trade","received_at_ms":1788331889844,"data":{"e":"trade","E":1788331889968,"s":"BTCUSDT","t":6646634492,"p":"77581.32000000","q":"0.00190000","T":1788331889967,"m":true,"M":true}}
{"type":"trade","received_at_ms":1788331889846,"data":{"e":"trade","E":1788331889969,"s":"BTCUSDT","t":6646634493,"p":"77581.14000000","q":"0.00342000","T":1788331889967,"m":true,"M":true}}
{"type":"trade","received_at_ms":1788331889847,"data":{"e":"trade","E":1788331889969,"s":"BTCUSDT","t":6646634494,"p":"77581.14000000","q":"0.00342000","T":1788331889967,"m":true,"M":true}}
{"type":"trade","received_at_ms":1788331889847,"data":{"e":"trade","E":1788331889969,"s":"BTCUSDT","t":6646634495,"p":"77581.14000000","q":"0.00342000","T":1788331889967,"m":true,"M":true}}
{"type":"trade","received_at_ms":1788331889847,"data":{"e":"trade","E":1788331889969,"s":"BTCUSDT","t":6646634496,"p":"77581.14000000","q":"0.00118000","T":1788331889967,"m":true,"M":true}}
{"type":"trade","received_at_ms":1788331889847,"data":{"e":"trade","E":1788331889969,"s":"BTCUSDT","t":6646634497,"p":"77581.14000000","q":"0.00343000","T":1788331889967,"m":true,"M":true}}
{"type":"trade","received_at_ms":1788331889847,"data":{"e":"trade","E":1788331889969,"s":"BTCUSDT","t":6646634498,"p":"77581.14000000","q":"0.00007000","T":1788331889967,"m":true,"M":true}}
{"type":"trade","received_at_ms":1788331889847,"data":{"e":"trade","E":1788331889969,"s":"BTCUSDT","t":6646634499,"p":"77581.14000000","q":"0.00343000","T":1788331889967,"m":true,"M":true}}
{"type":"trade","received_at_ms":1788331889847,"data":{"e":"trade","E":1788331889969,"s":"BTCUSDT","t":6646634500,"p":"77581.14000000","q":"0.00342000","T":1788331889967,"m":true,"M":true}}
{"type":"trade","received_at_ms":1788331889847,"data":{"e":"trade","E":1788331889969,"s":"BTCUSDT","t":6646634501,"p":"77581.14000000","q":"0.00342000","T":1788331889967,"m":true,"M":true}}
{"type":"trade","received_at_ms":1788331889847,"data":{"e":"trade","E":1788331889969,"s":"BTCUSDT","t":6646634502,"p":"77581.14000000","q":"0.00342000","T":1788331889967,"m":true,"M":true}}
{"type":"trade","received_at_ms":1788331889847,"data":{"e":"trade","E":1788331889969,"s":"BTCUSDT","t":6646634503,"p":"77581.14000000","q":"0.00343000","T":1788331889967,"m":true,"M":true}}
{"type":"trade","received_at_ms":1788331889847,"data":{"e":"trade","E":1788331889969,"s":"BTCUSDT","t":6646634504,"p":"77581.14000000","q":"0.00007000","T":1788331889967,"m":true,"M":true}}
{"type":"trade","received_at_ms":1788331889847,"data":{"e":"trade","E":1788331889969,"s":"BTCUSDT","t":6646634505,"p":"77581.14000000","q":"0.00343000","T":1788331889967,"m":true,"M":true}}
{"type":"trade","received_at_ms":1788331889847,"data":{"e":"trade","E":1788331889969,"s":"BTCUSDT","t":6646634506,"p":"77581.14000000","q":"0.00342000","T":1788331889967,"m":true,"M":true}}
{"type":"trade","received_at_ms":1788331889847,"data":{"e":"trade","E":1788331889969,"s":"BTCUSDT","t":6646634507,"p":"77581.14000000","q":"0.00102000","T":1788331889967,"m":true,"M":true}}
{"type":"trade","received_at_ms":1788331889847,"data":{"e":"trade","E":1788331889969,"s":"BTCUSDT","t":6646634508,"p":"77581.14000000","q":"0.00240000","T":1788331889967,"m":true,"M":true}}
{"type":"trade","received_at_ms":1788331889847,"data":{"e":"trade","E":1788331889969,"s":"BTCUSDT","t":6646634509,"p":"77581.14000000","q":"0.00342000","T":1788331889967,"m":true,"M":true}}
{"type":"trade","received_at_ms":1788331889847,"data":{"e":"trade","E":1788331889969,"s":"BTCUSDT","t":6646634510,"p":"77581.14000000","q":"0.00343000","T":1788331889967,"m":true,"M":true}}
{"type":"trade","received_at_ms":1788331889847,"data":{"e":"trade","E":1788331889969,"s":"BTCUSDT","t":6646634511,"p":"77581.14000000","q":"0.00007000","T":1788331889967,"m":true,"M":true}}
{"type":"trade","received_at_ms":1788331889847,"data":{"e":"trade","E":1788331889969,"s":"BTCUSDT","t":6646634512,"p":"77581.14000000","q":"0.00343000","T":1788331889967,"m":true,"M":true}}
{"type":"trade","received_at_ms":1788331889847,"data":{"e":"trade","E":1788331889969,"s":"BTCUSDT","t":6646634513,"p":"77581.14000000","q":"0.00342000","T":1788331889967,"m":true,"M":true}}
{"type":"trade","received_at_ms":1788331889847,"data":{"e":"trade","E":1788331889969,"s":"BTCUSDT","t":6646634514,"p":"77581.14000000","q":"0.00342000","T":1788331889967,"m":true,"M":true}}
{"type":"trade","received_at_ms":1788331889847,"data":{"e":"trade","E":1788331889969,"s":"BTCUSDT","t":6646634515,"p":"77581.14000000","q":"0.00342000","T":1788331889967,"m":true,"M":true}}
{"type":"trade","received_at_ms":1788331889847,"data":{"e":"trade","E":1788331889969,"s":"BTCUSDT","t":6646634516,"p":"77581.14000000","q":"0.00343000","T":1788331889967,"m":true,"M":true}}
{"type":"trade","received_at_ms":1788331889847,"data":{"e":"trade","E":1788331889969,"s":"BTCUSDT","t":6646634517,"p":"77581.14000000","q":"0.00005000","T":1788331889967,"m":true,"M":true}}
{"type":"trade","received_at_ms":1788331889847,"data":{"e":"trade","E":1788331889969,"s":"BTCUSDT","t":6646634518,"p":"77581.14000000","q":"0.00343000","T":1788331889967,"m":true,"M":true}}
{"type":"trade","received_at_ms":1788331889847,"data":{"e":"trade","E":1788331889969,"s":"BTCUSDT","t":6646634519,"p":"77581.14000000","q":"0.00342000","T":1788331889967,"m":true,"M":true}}
{"type":"trade","received_at_ms":1788331889847,"data":{"e":"trade","E":1788331889969,"s":"BTCUSDT","t":6646634520,"p":"77581.14000000","q":"0.00342000","T":1788331889967,"m":true,"M":true}}
{"type":"trade","received_at_ms":1788331889847,"data":{"e":"trade","E":1788331889969,"s":"BTCUSDT","t":6646634521,"p":"77581.14000000","q":"0.00141000","T":1788331889967,"m":true,"M":true}}
{"type":"trade","received_at_ms":1788331889847,"data":{"e":"trade","E":1788331889969,"s":"BTCUSDT","t":6646634522,"p":"77581.14000000","q":"0.00343000","T":1788331889967,"m":true,"M":true}}
{"type":"trade","received_at_ms":1788331889847,"data":{"e":"trade","E":1788331889969,"s":"BTCUSDT","t":6646634523,"p":"77581.14000000","q":"0.00343000","T":1788331889967,"m":true,"M":true}}
{"type":"trade","received_at_ms":1788331889847,"data":{"e":"trade","E":1788331889969,"s":"BTCUSDT","t":6646634524,"p":"77581.14000000","q":"0.00039000","T":1788331889967,"m":true,"M":true}}
{"type":"trade","received_at_ms":1788331889847,"data":{"e":"trade","E":1788331889969,"s":"BTCUSDT","t":6646634525,"p":"77581.14000000","q":"0.00342000","T":1788331889967,"m":true,"M":true}}
{"type":"trade","received_at_ms":1788331889847,"data":{"e":"trade","E":1788331889969,"s":"BTCUSDT","t":6646634526,"p":"77581.14000000","q":"0.00343000","T":1788331889967,"m":true,"M":true}}
{"type":"trade","received_at_ms":1788331889847,"data":{"e":"trade","E":1788331889969,"s":"BTCUSDT","t":6646634527,"p":"77581.14000000","q":"0.00343000","T":1788331889967,"m":true,"M":true}}
{"type":"trade","received_at_ms":1788331889847,"data":{"e":"trade","E":1788331889969,"s":"BTCUSDT","t":6646634528,"p":"77581.14000000","q":"0.00342000","T":1788331889967,"m":true,"M":true}}
{"type":"trade","received_at_ms":1788331889847,"data":{"e":"trade","E":1788331889969,"s":"BTCUSDT","t":6646634529,"p":"77581.14000000","q":"0.00343000","T":1788331889967,"m":true,"M":true}}
{"type":"trade","received_at_ms":1788331889847,"data":{"e":"trade","E":1788331889969,"s":"BTCUSDT","t":6646634530,"p":"77581.14000000","q":"0.00343000","T":1788331889967,"m":true,"M":true}}
{"type":"trade","received_at_ms":1788331889847,"data":{"e":"trade","E":1788331889969,"s":"BTCUSDT","t":6646634531,"p":"77581.14000000","q":"0.00342000","T":1788331889967,"m":true,"M":true}}
{"type":"trade","received_at_ms":1788331889847,"data":{"e":"trade","E":1788331889969,"s":"BTCUSDT","t":6646634532,"p":"77581.14000000","q":"0.00343000","T":1788331889967,"m":true,"M":true}}
{"type":"trade","received_at_ms":1788331889847,"data":{"e":"trade","E":1788331889969,"s":"BTCUSDT","t":6646634533,"p":"77581.14000000","q":"0.00343000","T":1788331889967,"m":true,"M":true}}
{"type":"trade","received_at_ms":1788331889847,"data":{"e":"trade","E":1788331889969,"s":"BTCUSDT","t":6646634534,"p":"77581.14000000","q":"0.00342000","T":1788331889967,"m":true,"M":true}}
{"type":"trade","received_at_ms":1788331889847,"data":{"e":"trade","E":1788331889969,"s":"BTCUSDT","t":6646634535,"p":"77581.14000000","q":"0.00343000","T":1788331889967,"m":true,"M":true}}
{"type":"trade","received_at_ms":1788331889847,"data":{"e":"trade","E":1788331889969,"s":"BTCUSDT","t":6646634536,"p":"77581.14000000","q":"0.00342000","T":1788331889967,"m":true,"M":true}}
{"type":"trade","received_at_ms":1788331889847,"data":{"e":"trade","E":1788331889969,"s":"BTCUSDT","t":6646634537,"p":"77581.14000000","q":"0.00343000","T":1788331889967,"m":true,"M":true}}
{"type":"trade","received_at_ms":1788331889847,"data":{"e":"trade","E":1788331889969,"s":"BTCUSDT","t":6646634538,"p":"77581.14000000","q":"0.00342000","T":1788331889967,"m":true,"M":true}}
{"type":"trade","received_at_ms":1788331889847,"data":{"e":"trade","E":1788331889969,"s":"BTCUSDT","t":6646634539,"p":"77581.14000000","q":"0.00085000","T":1788331889967,"m":true,"M":true}}
{"type":"trade","received_at_ms":1788331889847,"data":{"e":"trade","E":1788331889969,"s":"BTCUSDT","t":6646634540,"p":"77581.14000000","q":"0.00205000","T":1788331889967,"m":true,"M":true}}
{"type":"trade","received_at_ms":1788331889847,"data":{"e":"trade","E":1788331889969,"s":"BTCUSDT","t":6646634541,"p":"77581.13000000","q":"0.00200000","T":1788331889967,"m":true,"M":true}}
{"type":"trade","received_at_ms":1788331889847,"data":{"e":"trade","E":1788331889969,"s":"BTCUSDT","t":6646634542,"p":"77581.13000000","q":"0.00200000","T":1788331889967,"m":true,"M":true}}
{"type":"trade","received_at_ms":1788331889847,"data":{"e":"trade","E":1788331889969,"s":"BTCUSDT","t":6646634543,"p":"77581.13000000","q":"0.00200000","T":1788331889967,"m":true,"M":true}}
{"type":"trade","received_at_ms":1788331889847,"data":{"e":"trade","E":1788331889969,"s":"BTCUSDT","t":6646634544,"p":"77581.13000000","q":"0.00200000","T":1788331889967,"m":true,"M":true}}
{"type":"trade","received_at_ms":1788331889848,"data":{"e":"trade","E":1788331889969,"s":"BTCUSDT","t":6646634545,"p":"77581.13000000","q":"0.00200000","T":1788331889967,"m":true,"M":true}}
{"type":"trade","received_at_ms":1788331889848,"data":{"e":"trade","E":1788331889969,"s":"BTCUSDT","t":6646634546,"p":"77581.13000000","q":"0.00200000","T":1788331889967,"m":true,"M":true}}
{"type":"trade","received_at_ms":1788331889848,"data":{"e":"trade","E":1788331889969,"s":"BTCUSDT","t":6646634547,"p":"77581.13000000","q":"0.00200000","T":1788331889967,"m":true,"M":true}}
{"type":"trade","received_at_ms":1788331889848,"data":{"e":"trade","E":1788331889969,"s":"BTCUSDT","t":6646634548,"p":"77581.13000000","q":"0.00200000","T":1788331889967,"m":true,"M":true}}
{"type":"trade","received_at_ms":1788331889848,"data":{"e":"trade","E":1788331889969,"s":"BTCUSDT","t":6646634549,"p":"77581.13000000","q":"0.00200000","T":1788331889967,"m":true,"M":true}}
{"type":"trade","received_at_ms":1788331889848,"data":{"e":"trade","E":1788331889969,"s":"BTCUSDT","t":6646634550,"p":"77581.13000000","q":"0.00200000","T":1788331889967,"m":true,"M":true}}
{"type":"trade","received_at_ms":1788331889848,"data":{"e":"trade","E":1788331889969,"s":"BTCUSDT","t":6646634551,"p":"77581.13000000","q":"0.00200000","T":1788331889967,"m":true,"M":true}}
{"type":"trade","received_at_ms":1788331889848,"data":{"e":"trade","E":1788331889969,"s":"BTCUSDT","t":6646634552,"p":"77581.13000000","q":"0.00200000","T":1788331889967,"m":true,"M":true}}
{"type":"trade","received_at_ms":1788331889848,"data":{"e":"trade","E":1788331889969,"s":"BTCUSDT","t":6646634553,"p":"77581.13000000","q":"0.00200000","T":1788331889967,"m":true,"M":true}}
{"type":"trade","received_at_ms":1788331889848,"data":{"e":"trade","E":1788331889969,"s":"BTCUSDT","t":6646634554,"p":"77581.13000000","q":"0.00200000","T":1788331889967,"m":true,"M":true}}
{"type":"trade","received_at_ms":1788331889848,"data":{"e":"trade","E":1788331889969,"s":"BTCUSDT","t":6646634555,"p":"77581.13000000","q":"0.00200000","T":1788331889967,"m":true,"M":true}}
{"type":"trade","received_at_ms":1788331889848,"data":{"e":"trade","E":1788331889969,"s":"BTCUSDT","t":6646634556,"p":"77581.13000000","q":"0.00200000","T":1788331889967,"m":true,"M":true}}
{"type":"trade","received_at_ms":1788331889848,"data":{"e":"trade","E":1788331889969,"s":"BTCUSDT","t":6646634557,"p":"77581.13000000","q":"0.00200000","T":1788331889967,"m":true,"M":true}}
{"type":"trade","received_at_ms":1788331889848,"data":{"e":"trade","E":1788331889969,"s":"BTCUSDT","t":6646634558,"p":"77581.13000000","q":"0.00200000","T":1788331889967,"m":true,"M":true}}
{"type":"trade","received_at_ms":1788331889848,"data":{"e":"trade","E":1788331889969,"s":"BTCUSDT","t":6646634559,"p":"77581.13000000","q":"0.00644000","T":1788331889967,"m":true,"M":true}}
{"type":"trade","received_at_ms":1788331889848,"data":{"e":"trade","E":1788331889969,"s":"BTCUSDT","t":6646634560,"p":"77581.13000000","q":"0.00048000","T":1788331889967,"m":true,"M":true}}
{"type":"trade","received_at_ms":1788331889848,"data":{"e":"trade","E":1788331889969,"s":"BTCUSDT","t":6646634561,"p":"77580.80000000","q":"0.00124000","T":1788331889967,"m":true,"M":true}}
{"type":"trade","received_at_ms":1788331889848,"data":{"e":"trade","E":1788331889969,"s":"BTCUSDT","t":6646634562,"p":"77580.69000000","q":"0.00097000","T":1788331889967,"m":true,"M":true}}
{"type":"trade","received_at_ms":1788331889848,"data":{"e":"trade","E":1788331889969,"s":"BTCUSDT","t":6646634563,"p":"77580.61000000","q":"0.00007000","T":1788331889967,"m":true,"M":true}}
{"type":"trade","received_at_ms":1788331889848,"data":{"e":"trade","E":1788331889969,"s":"BTCUSDT","t":6646634564,"p":"77580.56000000","q":"0.00007000","T":1788331889967,"m":true,"M":true}}
{"type":"trade","received_at_ms":1788331889848,"data":{"e":"trade","E":1788331889969,"s":"BTCUSDT","t":6646634565,"p":"77580.17000000","q":"0.00048000","T":1788331889967,"m":true,"M":true}}
{"type":"trade","received_at_ms":1788331889848,"data":{"e":"trade","E":1788331889969,"s":"BTCUSDT","t":6646634566,"p":"77580.11000000","q":"0.00339000","T":1788331889967,"m":true,"M":true}}
{"type":"trade","received_at_ms":1788331889848,"data":{"e":"trade","E":1788331889969,"s":"BTCUSDT","t":6646634567,"p":"77580.00000000","q":"0.01000000","T":1788331889967,"m":true,"M":true}}
{"type":"trade","received_at_ms":1788331889848,"data":{"e":"trade","E":1788331889969,"s":"BTCUSDT","t":6646634568,"p":"77580.00000000","q":"0.00500000","T":1788331889967,"m":true,"M":true}}
{"type":"trade","received_at_ms":1788331889848,"data":{"e":"trade","E":1788331889969,"s":"BTCUSDT","t":6646634569,"p":"77580.00000000","q":"0.00500000","T":1788331889967,"m":true,"M":true}}
{"type":"trade","received_at_ms":1788331889848,"data":{"e":"trade","E":1788331889969,"s":"BTCUSDT","t":6646634570,"p":"77580.00000000","q":"0.01000000","T":1788331889967,"m":true,"M":true}}
{"type":"trade","received_at_ms":1788331889848,"data":{"e":"trade","E":1788331889969,"s":"BTCUSDT","t":6646634571,"p":"77580.00000000","q":"0.00012000","T":1788331889967,"m":true,"M":true}}
{"type":"trade","received_at_ms":1788331889848,"data":{"e":"trade","E":1788331889969,"s":"BTCUSDT","t":6646634572,"p":"77579.88000000","q":"0.00339000","T":1788331889967,"m":true,"M":true}}
{"type":"trade","received_at_ms":1788331889848,"data":{"e":"trade","E":1788331889969,"s":"BTCUSDT","t":6646634573,"p":"77579.87000000","q":"0.00200000","T":1788331889967,"m":true,"M":true}}
{"type":"trade","received_at_ms":1788331889848,"data":{"e":"trade","E":1788331889969,"s":"BTCUSDT","t":6646634574,"p":"77579.67000000","q":"0.00084000","T":1788331889967,"m":true,"M":true}}
{"type":"trade","received_at_ms":1788331889848,"data":{"e":"trade","E":1788331889969,"s":"BTCUSDT","t":6646634575,"p":"77579.54000000","q":"0.00007000","T":1788331889967,"m":true,"M":true}}
{"type":"trade","received_at_ms":1788331889848,"data":{"e":"trade","E":1788331889969,"s":"BTCUSDT","t":6646634576,"p":"77578.60000000","q":"0.00007000","T":1788331889967,"m":true,"M":true}}
{"type":"trade","received_at_ms":1788331889848,"data":{"e":"trade","E":1788331889969,"s":"BTCUSDT","t":6646634577,"p":"77578.21000000","q":"0.00060000","T":1788331889967,"m":true,"M":true}}
{"type":"trade","received_at_ms":1788331889848,"data":{"e":"trade","E":1788331889969,"s":"BTCUSDT","t":6646634578,"p":"77578.20000000","q":"0.02900000","T":1788331889967,"m":true,"M":true}}
{"type":"trade","received_at_ms":1788331889848,"data":{"e":"trade","E":1788331889969,"s":"BTCUSDT","t":6646634579,"p":"77578.00000000","q":"0.01000000","T":1788331889967,"m":true,"M":true}}
{"type":"trade","received_at_ms":1788331889848,"data":{"e":"trade","E":1788331889969,"s":"BTCUSDT","t":6646634580,"p":"77578.00000000","q":"0.00500000","T":1788331889967,"m":true,"M":true}}
{"type":"trade","received_at_ms":1788331889848,"data":{"e":"trade","E":1788331889969,"s":"BTCUSDT","t":6646634581,"p":"77578.00000000","q":"0.00500000","T":1788331889967,"m":true,"M":true}}
{"type":"trade","received_at_ms":1788331889848,"data":{"e":"trade","E":1788331889969,"s":"BTCUSDT","t":6646634582,"p":"77578.00000000","q":"0.01000000","T":1788331889967,"m":true,"M":true}}
{"type":"trade","received_at_ms":1788331889850,"data":{"e":"trade","E":1788331889970,"s":"BTCUSDT","t":6646634583,"p":"77577.76000000","q":"0.00007000","T":1788331889968,"m":true,"M":true}}
{"type":"trade","received_at_ms":1788331889850,"data":{"e":"trade","E":1788331889970,"s":"BTCUSDT","t":6646634584,"p":"77577.71000000","q":"0.00007000","T":1788331889968,"m":true,"M":true}}
{"type":"trade","received_at_ms":1788331889850,"data":{"e":"trade","E":1788331889970,"s":"BTCUSDT","t":6646634585,"p":"77577.65000000","q":"0.00007000","T":1788331889968,"m":true,"M":true}}
{"type":"trade","received_at_ms":1788331889850,"data":{"e":"trade","E":1788331889970,"s":"BTCUSDT","t":6646634586,"p":"77577.39000000","q":"0.00343000","T":1788331889968,"m":true,"M":true}}
{"type":"trade","received_at_ms":1788331889852,"data":{"e":"trade","E":1788331889970,"s":"BTCUSDT","t":6646634587,"p":"77577.36000000","q":"0.00008000","T":1788331889968,"m":true,"M":true}}
{"type":"trade","received_at_ms":1788331889852,"data":{"e":"trade","E":1788331889970,"s":"BTCUSDT","t":6646634588,"p":"77576.86000000","q":"0.01000000","T":1788331889968,"m":true,"M":true}}
{"type":"trade","received_at_ms":1788331889852,"data":{"e":"trade","E":1788331889970,"s":"BTCUSDT","t":6646634589,"p":"77576.86000000","q":"0.00628000","T":1788331889968,"m":true,"M":true}}
{"type":"trade","received_at_ms":1788331889855,"data":{"e":"trade","E":1788331889973,"s":"BTCUSDT","t":6646634590,"p":"77576.86000000","q":"0.00007000","T":1788331889969,"m":true,"M":true}}
{"type":"trade","received_at_ms":1788331889855,"data":{"e":"trade","E":1788331889973,"s":"BTCUSDT","t":6646634591,"p":"77576.86000000","q":"0.00007000","T":1788331889969,"m":true,"M":true}}
{"type":"trade","received_at_ms":1788331889855,"data":{"e":"trade","E":1788331889973,"s":"BTCUSDT","t":6646634592,"p":"77576.86000000","q":"0.00007000","T":1788331889969,"m":true,"M":true}}
{"type":"trade","received_at_ms":1788331889855,"data":{"e":"trade","E":1788331889973,"s":"BTCUSDT","t":6646634593,"p":"77576.86000000","q":"0.00007000","T":1788331889969,"m":true,"M":true}}
{"type":"trade","received_at_ms":1788331889855,"data":{"e":"trade","E":1788331889973,"s":"BTCUSDT","t":6646634594,"p":"77576.86000000","q":"0.00007000","T":1788331889969,"m":true,"M":true}}
{"type":"trade","received_at_ms":1788331889855,"data":{"e":"trade","E":1788331889973,"s":"BTCUSDT","t":6646634595,"p":"77576.86000000","q":"0.00007000","T":1788331889969,"m":true,"M":true}}
{"type":"trade","received_at_ms":1788331889855,"data":{"e":"trade","E":1788331889973,"s":"BTCUSDT","t":6646634596,"p":"77576.86000000","q":"0.00007000","T":1788331889969,"m":true,"M":true}}
{"type":"trade","received_at_ms":1788331889855,"data":{"e":"trade","E":1788331889973,"s":"BTCUSDT","t":6646634597,"p":"77576.86000000","q":"0.00007000","T":1788331889969,"m":true,"M":true}}
{"type":"trade","received_at_ms":1788331889855,"data":{"e":"trade","E":1788331889973,"s":"BTCUSDT","t":6646634598,"p":"77576.72000000","q":"0.00400000","T":1788331889969,"m":true,"M":true}}
{"type":"trade","received_at_ms":1788331889855,"data":{"e":"trade","E":1788331889973,"s":"BTCUSDT","t":6646634599,"p":"77576.44000000","q":"0.00007000","T":1788331889969,"m":true,"M":true}}
{"type":"trade","received_at_ms":1788331889855,"data":{"e":"trade","E":1788331889973,"s":"BTCUSDT","t":6646634600,"p":"77576.27000000","q":"0.02000000","T":1788331889969,"m":true,"M":true}}
{"type":"trade","received_at_ms":1788331889855,"data":{"e":"trade","E":1788331889973,"s":"BTCUSDT","t":6646634601,"p":"77576.00000000","q":"0.01000000","T":1788331889969,"m":true,"M":true}}
{"type":"trade","received_at_ms":1788331889855,"data":{"e":"trade","E":1788331889973,"s":"BTCUSDT","t":6646634602,"p":"77576.00000000","q":"0.00500000","T":1788331889969,"m":true,"M":true}}
{"type":"trade","received_at_ms":1788331889855,"data":{"e":"trade","E":1788331889973,"s":"BTCUSDT","t":6646634603,"p":"77576.00000000","q":"0.00500000","T":1788331889969,"m":true,"M":true}}
{"type":"trade","received_at_ms":1788331889855,"data":{"e":"trade","E":1788331889973,"s":"BTCUSDT","t":6646634604,"p":"77576.00000000","q":"0.01000000","T":1788331889969,"m":true,"M":true}}
{"type":"trade","received_at_ms":1788331889855,"data":{"e":"trade","E":1788331889973,"s":"BTCUSDT","t":6646634605,"p":"77576.00000000","q":"0.00007000","T":1788331889969,"m":true,"M":true}}
{"type":"trade","received_at_ms":1788331889855,"data":{"e":"trade","E":1788331889973,"s":"BTCUSDT","t":6646634606,"p":"77575.96000000","q":"0.00326000","T":1788331889969,"m":true,"M":true}}
{"type":"trade","received_at_ms":1788331889855,"data":{"e":"trade","E":1788331889973,"s":"BTCUSDT","t":6646634607,"p":"77575.94000000","q":"0.02000000","T":1788331889969,"m":true,"M":true}}
{"type":"trade","received_at_ms":1788331889855,"data":{"e":"trade","E":1788331889973,"s":"BTCUSDT","t":6646634608,"p":"77575.86000000","q":"0.00204000","T":1788331889969,"m":true,"M":true}}
{"type":"trade","received_at_ms":1788331889855,"data":{"e":"trade","E":1788331889974,"s":"BTCUSDT","t":6646634609,"p":"77575.86000000","q":"0.00010000","T":1788331889969,"m":true,"M":true}}
{"type":"trade","received_at_ms":1788331889855,"data":{"e":"trade","E":1788331889974,"s":"BTCUSDT","t":6646634610,"p":"77575.86000000","q":"0.00108000","T":1788331889969,"m":true,"M":true}}
{"type":"trade","received_at_ms":1788331889855,"data":{"e":"trade","E":1788331889974,"s":"BTCUSDT","t":6646634611,"p":"77575.86000000","q":"0.00007000","T":1788331889969,"m":true,"M":true}}
{"type":"trade","received_at_ms":1788331889855,"data":{"e":"trade","E":1788331889974,"s":"BTCUSDT","t":6646634612,"p":"77575.86000000","q":"0.00007000","T":1788331889969,"m":true,"M":true}}
{"type":"trade","received_at_ms":1788331889858,"data":{"e":"trade","E":1788331889978,"s":"BTCUSDT","t":6646634613,"p":"77575.07000000","q":"0.02000000","T":1788331889971,"m":true,"M":true}}
{"type":"trade","received_at_ms":1788331889858,"data":{"e":"trade","E":1788331889978,"s":"BTCUSDT","t":6646634614,"p":"77575.07000000","q":"0.00007000","T":1788331889971,"m":true,"M":true}}
{"type":"trade","received_at_ms":1788331889858,"data":{"e":"trade","E":1788331889978,"s":"BTCUSDT","t":6646634615,"p":"77575.07000000","q":"0.00007000","T":1788331889971,"m":true,"M":true}}
{"type":"trade","received_at_ms":1788331889858,"data":{"e":"trade","E":1788331889978,"s":"BTCUSDT","t":6646634616,"p":"77575.07000000","q":"0.00007000","T":1788331889971,"m":true,"M":true}}
{"type":"trade","received_at_ms":1788331889858,"data":{"e":"trade","E":1788331889978,"s":"BTCUSDT","t":6646634617,"p":"77575.07000000","q":"0.00007000","T":1788331889971,"m":true,"M":true}}
{"type":"trade","received_at_ms":1788331889858,"data":{"e":"trade","E":1788331889978,"s":"BTCUSDT","t":6646634618,"p":"77575.07000000","q":"0.00007000","T":1788331889971,"m":true,"M":true}}
{"type":"trade","received_at_ms":1788331889858,"data":{"e":"trade","E":1788331889978,"s":"BTCUSDT","t":6646634619,"p":"77575.07000000","q":"0.00007000","T":1788331889971,"m":true,"M":true}}
{"type":"trade","received_at_ms":1788331889858,"data":{"e":"trade","E":1788331889978,"s":"BTCUSDT","t":6646634620,"p":"77575.07000000","q":"0.00007000","T":1788331889971,"m":true,"M":true}}
{"type":"trade","received_at_ms":1788331889858,"data":{"e":"trade","E":1788331889978,"s":"BTCUSDT","t":6646634621,"p":"77575.07000000","q":"0.00007000","T":1788331889971,"m":true,"M":true}}
{"type":"trade","received_at_ms":1788331889858,"data":{"e":"trade","E":1788331889978,"s":"BTCUSDT","t":6646634622,"p":"77575.05000000","q":"0.02000000","T":1788331889971,"m":true,"M":true}}
{"type":"trade","received_at_ms":1788331889858,"data":{"e":"trade","E":1788331889978,"s":"BTCUSDT","t":6646634623,"p":"77574.97000000","q":"0.00007000","T":1788331889971,"m":true,"M":true}}
{"type":"trade","received_at_ms":1788331889858,"data":{"e":"trade","E":1788331889978,"s":"BTCUSDT","t":6646634624,"p":"77574.97000000","q":"0.02000000","T":1788331889971,"m":true,"M":true}}
{"type":"trade","received_at_ms":1788331889858,"data":{"e":"trade","E":1788331889978,"s":"BTCUSDT","t":6646634625,"p":"77574.93000000","q":"0.02000000","T":1788331889971,"m":true,"M":true}}
{"type":"trade","received_at_ms":1788331889858,"data":{"e":"trade","E":1788331889978,"s":"BTCUSDT","t":6646634626,"p":"77574.92000000","q":"0.00007000","T":1788331889971,"m":true,"M":true}}
{"type":"trade","received_at_ms":1788331889858,"data":{"e":"trade","E":1788331889978,"s":"BTCUSDT","t":6646634627,"p":"77574.92000000","q":"0.00200000","T":1788331889971,"m":true,"M":true}}
{"type":"trade","received_at_ms":1788331889858,"data":{"e":"trade","E":1788331889978,"s":"BTCUSDT","t":6646634628,"p":"77574.88000000","q":"0.00400000","T":1788331889971,"m":true,"M":true}}
{"type":"trade","received_at_ms":1788331889858,"data":{"e":"trade","E":1788331889978,"s":"BTCUSDT","t":6646634629,"p":"77574.87000000","q":"0.00035000","T":1788331889971,"m":true,"M":true}}
{"type":"trade","received_at_ms":1788331889858,"data":{"e":"trade","E":1788331889978,"s":"BTCUSDT","t":6646634630,"p":"77574.66000000","q":"0.00007000","T":1788331889971,"m":true,"M":true}}
{"type":"trade","received_at_ms":1788331889858,"data":{"e":"trade","E":1788331889978,"s":"BTCUSDT","t":6646634631,"p":"77574.48000000","q":"0.00008000","T":1788331889971,"m":true,"M":true}}
{"type":"trade","received_at_ms":1788331889860,"data":{"e":"trade","E":1788331889981,"s":"BTCUSDT","t":6646634632,"p":"77574.00000000","q":"0.00500000","T":1788331889973,"m":true,"M":true}}
{"type":"trade","received_at_ms":1788331889860,"data":{"e":"trade","E":1788331889981,"s":"BTCUSDT","t":6646634633,"p":"77574.00000000","q":"0.00500000","T":1788331889973,"m":true,"M":true}}
{"type":"trade","received_at_ms":1788331889860,"data":{"e":"trade","E":1788331889981,"s":"BTCUSDT","t":6646634634,"p":"77574.00000000","q":"0.01000000","T":1788331889973,"m":true,"M":true}}
{"type":"trade","received_at_ms":1788331889860,"data":{"e":"trade","E":1788331889981,"s":"BTCUSDT","t":6646634635,"p":"77574.00000000","q":"0.01000000","T":1788331889973,"m":true,"M":true}}
{"type":"trade","received_at_ms":1788331889860,"data":{"e":"trade","E":1788331889981,"s":"BTCUSDT","t":6646634636,"p":"77574.00000000","q":"0.00007000","T":1788331889973,"m":true,"M":true}}
{"type":"trade","received_at_ms":1788331889860,"data":{"e":"trade","E":1788331889981,"s":"BTCUSDT","t":6646634637,"p":"77574.00000000","q":"0.00007000","T":1788331889973,"m":true,"M":true}}
{"type":"trade","received_at_ms":1788331889860,"data":{"e":"trade","E":1788331889981,"s":"BTCUSDT","t":6646634638,"p":"77573.58000000","q":"0.02000000","T":1788331889973,"m":true,"M":true}}
{"type":"trade","received_at_ms":1788331889860,"data":{"e":"trade","E":1788331889981,"s":"BTCUSDT","t":6646634639,"p":"77573.10000000","q":"0.02000000","T":1788331889973,"m":true,"M":true}}
{"type":"trade","received_at_ms":1788331889860,"data":{"e":"trade","E":1788331889981,"s":"BTCUSDT","t":6646634640,"p":"77572.62000000","q":"0.00007000","T":1788331889973,"m":true,"M":true}}
{"type":"trade","received_at_ms":1788331889860,"data":{"e":"trade","E":1788331889981,"s":"BTCUSDT","t":6646634641,"p":"77572.48000000","q":"0.00008000","T":1788331889973,"m":true,"M":true}}
{"type":"trade","received_at_ms":1788331889860,"data":{"e":"trade","E":1788331889981,"s":"BTCUSDT","t":6646634642,"p":"77572.33000000","q":"0.02000000","T":1788331889973,"m":true,"M":true}}
{"type":"trade","received_at_ms":1788331889860,"data":{"e":"trade","E":1788331889981,"s":"BTCUSDT","t":6646634643,"p":"77572.18000000","q":"0.00007000","T":1788331889973,"m":true,"M":true}}
{"type":"trade","received_at_ms":1788331889860,"data":{"e":"trade","E":1788331889981,"s":"BTCUSDT","t":6646634644,"p":"77572.18000000","q":"0.00036000","T":1788331889973,"m":true,"M":true}}
{"type":"trade","received_at_ms":1788331889860,"data":{"e":"trade","E":1788331889981,"s":"BTCUSDT","t":6646634645,"p":"77572.01000000","q":"0.00092000","T":1788331889973,"m":true,"M":true}}
{"type":"trade","received_at_ms":1788331889860,"data":{"e":"trade","E":1788331889981,"s":"BTCUSDT","t":6646634646,"p":"77572.00000000","q":"0.00500000","T":1788331889973,"m":true,"M":true}}
{"type":"trade","received_at_ms":1788331889860,"data":{"e":"trade","E":1788331889981,"s":"BTCUSDT","t":6646634647,"p":"77572.00000000","q":"0.00500000","T":1788331889973,"m":true,"M":true}}
{"type":"trade","received_at_ms":1788331889860,"data":{"e":"trade","E":1788331889981,"s":"BTCUSDT","t":6646634648,"p":"77572.00000000","q":"0.01000000","T":1788331889973,"m":true,"M":true}}
{"type":"trade","received_at_ms":1788331889860,"data":{"e":"trade","E":1788331889981,"s":"BTCUSDT","t":6646634649,"p":"77572.00000000","q":"0.01000000","T":1788331889973,"m":true,"M":true}}
{"type":"trade","received_at_ms":1788331889860,"data":{"e":"trade","E":1788331889981,"s":"BTCUSDT","t":6646634650,"p":"77571.92000000","q":"0.00007000","T":1788331889973,"m":true,"M":true}}
{"type":"trade","received_at_ms":1788331889860,"data":{"e":"trade","E":1788331889981,"s":"BTCUSDT","t":6646634651,"p":"77571.89000000","q":"0.00715000","T":1788331889973,"m":true,"M":true}}
{"type":"trade","received_at_ms":1788331889861,"data":{"e":"trade","E":1788331889982,"s":"BTCUSDT","t":6646634652,"p":"77576.75000000","q":"0.00253000","T":1788331889973,"m":false,"M":true}}
{"type":"trade","received_at_ms":1788331889861,"data":{"e":"trade","E":1788331889984,"s":"BTCUSDT","t":6646634653,"p":"77576.56000000","q":"0.00007000","T":1788331889974,"m":true,"M":true}}
{"type":"trade","received_at_ms":1788331889861,"data":{"e":"trade","E":1788331889984,"s":"BTCUSDT","t":6646634654,"p":"77576.56000000","q":"0.00007000","T":1788331889974,"m":true,"M":true}}
{"type":"trade","received_at_ms":1788331889861,"data":{"e":"trade","E":1788331889984,"s":"BTCUSDT","t":6646634655,"p":"77576.56000000","q":"0.00007000","T":1788331889974,"m":true,"M":true}}
{"type":"trade","received_at_ms":1788331889861,"data":{"e":"trade","E":1788331889984,"s":"BTCUSDT","t":6646634656,"p":"77576.55000000","q":"0.00007000","T":1788331889974,"m":true,"M":true}}
{"type":"trade","received_at_ms":1788331889861,"data":{"e":"trade","E":1788331889984,"s":"BTCUSDT","t":6646634657,"p":"77571.89000000","q":"0.01285000","T":1788331889974,"m":true,"M":true}}
{"type":"trade","received_at_ms":1788331889861,"data":{"e":"trade","E":1788331889984,"s":"BTCUSDT","t":6646634658,"p":"77571.76000000","q":"0.00687000","T":1788331889974,"m":true,"M":true}}
{"type":"trade","received_at_ms":1788331889865,"data":{"e":"trade","E":1788331889993,"s":"BTCUSDT","t":6646634659,"p":"77573.59000000","q":"0.00007000","T":1788331889983,"m":true,"M":true}}
{"type":"trade","received_at_ms":1788331889865,"data":{"e":"trade","E":1788331889993,"s":"BTCUSDT","t":6646634660,"p":"77573.59000000","q":"0.00007000","T":1788331889983,"m":true,"M":true}}
{"type":"trade","received_at_ms":1788331889865,"data":{"e":"trade","E":1788331889993,"s":"BTCUSDT","t":6646634661,"p":"77573.59000000","q":"0.00007000","T":1788331889983,"m":true,"M":true}}
{"type":"trade","received_at_ms":1788331889865,"data":{"e":"trade","E":1788331889993,"s":"BTCUSDT","t":6646634662,"p":"77573.11000000","q":"0.00007000","T":1788331889983,"m":true,"M":true}}
{"type":"trade","received_at_ms":1788331889865,"data":{"e":"trade","E":1788331889993,"s":"BTCUSDT","t":6646634663,"p":"77572.94000000","q":"0.00007000","T":1788331889983,"m":true,"M":true}}
{"type":"trade","received_at_ms":1788331889865,"data":{"e":"trade","E":1788331889993,"s":"BTCUSDT","t":6646634664,"p":"77572.94000000","q":"0.00007000","T":1788331889983,"m":true,"M":true}}
{"type":"trade","received_at_ms":1788331889865,"data":{"e":"trade","E":1788331889993,"s":"BTCUSDT","t":6646634665,"p":"77572.94000000","q":"0.00007000","T":1788331889983,"m":true,"M":true}}
{"type":"trade","received_at_ms":1788331889865,"data":{"e":"trade","E":1788331889993,"s":"BTCUSDT","t":6646634666,"p":"77572.92000000","q":"0.00007000","T":1788331889983,"m":true,"M":true}}
{"type":"trade","received_at_ms":1788331889865,"data":{"e":"trade","E":1788331889993,"s":"BTCUSDT","t":6646634667,"p":"77572.82000000","q":"0.00038000","T":1788331889983,"m":true,"M":true}}
{"type":"trade","received_at_ms":1788331889865,"data":{"e":"trade","E":1788331889996,"s":"BTCUSDT","t":6646634668,"p":"77572.82000000","q":"0.00007000","T":1788331889986,"m":true,"M":true}}
{"type":"trade","received_at_ms":1788331889865,"data":{"e":"trade","E":1788331889996,"s":"BTCUSDT","t":6646634669,"p":"77572.82000000","q":"0.00007000","T":1788331889986,"m":true,"M":true}}
{"type":"trade","received_at_ms":1788331889865,"data":{"e":"trade","E":1788331889996,"s":"BTCUSDT","t":6646634670,"p":"77571.89000000","q":"0.00007000","T":1788331889986,"m":true,"M":true}}
{"type":"trade","received_at_ms":1788331889865,"data":{"e":"trade","E":1788331889996,"s":"BTCUSDT","t":6646634671,"p":"77571.89000000","q":"0.00007000","T":1788331889986,"m":true,"M":true}}
{"type":"trade","received_at_ms":1788331889866,"data":{"e":"trade","E":1788331889997,"s":"BTCUSDT","t":6646634672,"p":"77571.77000000","q":"0.00114000","T":1788331889986,"m":false,"M":true}}
{"type":"trade","received_at_ms":1788331889869,"data":{"e":"trade","E":1788331890011,"s":"BTCUSDT","t":6646634673,"p":"77571.77000000","q":"0.00051000","T":1788331890005,"m":false,"M":true}}
{"type":"depth","received_at_ms":1788331889876,"data":{"e":"depthUpdate","E":1788331890015,"s":"BTCUSDT","U":99555826578,"u":99555829130,"b":[["77590.29000000","0.00000000"],["77590.28000000","0.00000000"],["77590.27000000","0.00000000"],["77590.14000000","0.00000000"],["77590.01000000","0.00000000"],["77589.05000000","0.00000000"],["77589.04000000","0.00000000"],["77588.49000000","0.00000000"],["77588.28000000","0.00000000"],["77588.21000000","0.00000000"],["77588.18000000","0.00000000"],["77587.81000000","0.00000000"],["77587.80000000","0.00000000"],["77587.62000000","0.00000000"],["77587.61000000","0.00000000"],["77587.37000000","0.00000000"],["77587.33000000","0.00000000"],["77587.32000000","0.00000000"],["77587.31000000","0.00000000"],["77587.09000000","0.00000000"],["77587.02000000","0.00000000"],["77586.57000000","0.00000000"],["77586.56000000","0.00000000"],["77586.48000000","0.00000000"],["77586.00000000","0.00000000"],["77585.99000000","0.00000000"],["77585.86000000","0.00000000"],["77585.82000000","0.00000000"],["77585.67000000","0.00000000"],["77585.60000000","0.00000000"],["77585.59000000","0.00000000"],["77585.56000000","0.00000000"],["77585.54000000","0.00000000"],["77585.33000000","0.00000000"],["77585.32000000","0.00000000"],["77584.48000000","0.00000000"],["77584.46000000","0.00000000"],["77584.15000000","0.00000000"],["77584.08000000","0.00000000"],["77584.00000000","0.00000000"],["77583.85000000","0.00000000"],["77583.84000000","0.00000000"],["77583.80000000","0.00000000"],["77583.46000000","0.00000000"],["77583.35000000","0.00000000"],["77582.84000000","0.00000000"],["77582.83000000","0.00000000"],["77582.81000000","0.00000000"],["77582.54000000","0.00000000"],["77582.53000000","0.00000000"],["77581.76000000","0.00000000"],["77581.36000000","0.00000000"],["77581.35000000","0.00000000"],["77581.32000000","0.00000000"],["77581.15000000","0.00000000"],["77581.14000000","0.00000000"],["77581.13000000","0.00000000"],["77580.80000000","0.00000000"],["77580.69000000","0.00000000"],["77580.61000000","0.00000000"],["77580.60000000","0.00000000"],["77580.56000000","0.00000000"],["77580.17000000","0.00000000"],["77580.11000000","0.00000000"],["77580.00000000","0.00000000"],["77579.94000000","0.00000000"],["77579.88000000","0.00000000"],["77579.87000000","0.00000000"],["77579.86000000","0.00000000"],["77579.71000000","0.00000000"],["77579.70000000","0.00000000"],["77579.69000000","0.00000000"],["77579.68000000","0.00000000"],["77579.67000000","0.00000000"],["77579.54000000","0.00000000"],["77578.66000000","0.00000000"],["77578.65000000","0.00000000"],["77578.62000000","0.00000000"],["77578.60000000","0.00000000"],["77578.21000000","0.00000000"],["77578.20000000","0.00000000"],["77578.00000000","0.00000000"],["77577.90000000","0.00000000"],["77577.80000000","0.00000000"],["77577.77000000","0.00000000"],["77577.76000000","0.00000000"],["77577.71000000","0.00000000"],["77577.65000000","0.00000000"],["77577.39000000","0.00000000"],["77577.36000000","0.00000000"],["77577.13000000","0.00000000"],["77577.12000000","0.00000000"],["77576.86000000","0.00000000"],["77576.75000000","0.00000000"],["77576.72000000","0.00000000"],["77576.56000000","0.00000000"],["77576.55000000","0.00000000"],["77576.54000000","0.00000000"],["77576.44000000","0.00000000"],["77576.27000000","0.00000000"],["77576.01000000","0.00000000"],["77576.00000000","0.00000000"],["77575.96000000","0.00000000"],["77575.94000000","0.00000000"],["77575.86000000","0.00000000"],["77575.57000000","0.00000000"],["77575.07000000","0.00000000"],["77575.05000000","0.00000000"],["77574.97000000","0.00000000"],["77574.93000000","0.00000000"],["77574.92000000","0.00000000"],["77574.88000000","0.00000000"],["77574.87000000","0.00000000"],["77574.78000000","0.00000000"],["77574.77000000","0.00000000"],["77574.66000000","0.00000000"],["77574.48000000","0.00000000"],["77574.38000000","0.00000000"],["77574.13000000","0.00000000"],["77574.00000000","0.00000000"],["77573.76000000","0.00000000"],["77573.63000000","0.00000000"],["77573.59000000","0.00000000"],["77573.58000000","0.00000000"],["77573.42000000","0.00000000"],["77573.34000000","0.00000000"],["77573.11000000","0.00000000"],["77573.10000000","0.00000000"],["77572.94000000","0.00000000"],["77572.93000000","0.00000000"],["77572.92000000","0.00000000"],["77572.91000000","0.00000000"],["77572.84000000","0.00000000"],["77572.82000000","0.00000000"],["77572.79000000","0.00000000"],["77572.62000000","0.00000000"],["77572.48000000","0.00000000"],["77572.33000000","0.00000000"],["77572.18000000","0.00000000"],["77572.01000000","0.00000000"],["77572.00000000","0.00000000"],["77571.92000000","0.00000000"],["77571.89000000","0.00000000"],["77571.76000000","0.32216000"],["77571.56000000","0.00000000"],["77571.55000000","0.00007000"],["77571.51000000","0.00014000"],["77571.50000000","0.04007000"],["77571.01000000","0.00000000"],["77571.00000000","0.00000000"],["77570.72000000","0.00007000"],["77570.60000000","0.00000000"],["77570.24000000","0.00000000"],["77570.07000000","0.00000000"],["77570.04000000","0.00000000"],["77570.02000000","0.00000000"],["77570.01000000","0.00014000"],["77570.00000000","0.03327000"],["77569.83000000","0.00000000"],["77569.82000000","0.00000000"],["77569.80000000","0.00000000"],["77569.34000000","0.00000000"],["77569.06000000","0.00000000"],["77569.05000000","0.00000000"],["77568.96000000","0.00000000"],["77568.94000000","0.00332000"],["77568.92000000","0.00000000"],["77568.91000000","0.00000000"],["77568.90000000","0.00000000"],["77568.04000000","0.00007000"],["77568.01000000","0.00014000"],["77568.00000000","0.03014000"],["77567.86000000","0.00000000"],["77567.42000000","0.00000000"],["77567.25000000","0.00000000"],["77567.23000000","0.10783000"],["77567.17000000","0.00000000"],["77567.14000000","0.00000000"],["77567.10000000","0.00000000"],["77567.01000000","0.00000000"],["77566.79000000","0.00007000"],["77566.78000000","0.00007000"],["77566.51000000","0.00000000"],["77566.46000000","0.00587000"],["77566.38000000","0.00000000"],["77566.24000000","0.00000000"],["77566.16000000","0.00000000"],["77566.04000000","0.00000000"],["77566.01000000","0.00014000"],["77566.00000000","0.03007000"],["77565.94000000","0.00007000"],["77565.80000000","0.10955000"],["77565.63000000","0.00008000"],["77565.46000000","0.00000000"],["77565.19000000","0.00000000"],["77565.15000000","0.00000000"],["77565.06000000","0.00335000"],["77565.02000000","0.00000000"],["77565.01000000","0.00000000"],["77564.98000000","0.00000000"],["77564.96000000","0.00000000"],["77564.31000000","0.11618000"],["77564.17000000","0.00000000"],["77564.04000000","0.00007000"],["77564.01000000","0.11624000"],["77564.00000000","0.03022000"],["77563.58000000","0.11541000"],["77563.57000000","0.11624000"],["77563.44000000","0.00000000"],["77563.33000000","0.00007000"],["77563.21000000","0.00000000"],["77563.13000000","0.00000000"],["77562.84000000","0.00007000"],["77562.28000000","0.00000000"],["77562.21000000","0.00000000"],["77562.01000000","0.00000000"],["77562.00000000","0.03000000"],["77561.96000000","0.00000000"],["77561.84000000","0.11617000"],["77561.75000000","0.00000000"],["77561.44000000","0.00000000"],["77561.18000000","0.00336000"],["77561.00000000","0.00515000"],["77560.96000000","0.00000000"],["77560.94000000","0.00000000"],["77560.88000000","0.00000000"],["77560.87000000","0.00000000"],["77560.50000000","0.00000000"],["77560.35000000","0.11617000"],["77560.04000000","0.26154000"],["77560.03000000","0.00000000"],["77560.02000000","0.00000000"],["77560.01000000","0.00000000"],["77560.00000000","0.03007000"],["77559.59000000","0.00027000"],["77559.55000000","0.00008000"],["77558.96000000","0.00000000"],["77558.95000000","0.00000000"],["77558.90000000","0.00007000"],["77558.89000000","0.02901000"],["77558.72000000","0.00000000"],["77558.46000000","0.00322000"],["77558.41000000","0.00000000"],["77558.35000000","0.11618000"],["77558.14000000","0.00000000"],["77558.11000000","0.16870000"],["77558.08000000","0.02000000"],["77558.01000000","0.11617000"],["77557.84000000","0.00015000"],["77557.30000000","0.00332000"],["77556.76000000","0.00000000"],["77556.52000000","0.10865000"],["77556.43000000","0.05522000"],["77556.42000000","0.11617000"],["77556.41000000","0.00000000"],["77555.44000000","0.00000000"],["77555.30000000","0.00000000"],["77555.15000000","0.00000000"],["77555.10000000","0.00007000"],["77555.08000000","0.00000000"],["77554.96000000","0.00007000"],["77554.74000000","0.00007000"],["77554.53000000","0.00000000"],["77554.40000000","0.00000000"],["77554.38000000","0.07775000"],["77554.36000000","0.00000000"],["77554.35000000","0.00000000"],["77554.24000000","0.00008000"],["77553.88000000","0.11618000"],["77553.85000000","0.00000000"],["77553.84000000","0.00000000"],["77553.54000000","0.11617000"],["77553.44000000","0.00415000"],["77553.27000000","0.68286000"],["77553.26000000","1.93226000"],["77553.25000000","0.00000000"],["77553.13000000","0.00000000"],["77551.91000000","0.00000000"],["77551.86000000","0.00000000"],["77551.79000000","0.00000000"],["77551.74000000","0.00000000"],["77551.67000000","1.31471000"],["77551.50000000","0.00400000"],["77551.42000000","0.34778000"],["77551.21000000","0.00000000"],["77551.11000000","0.00008000"],["77551.02000000","0.00007000"],["77551.00000000","0.00000000"],["77550.98000000","0.07775000"],["77550.97000000","0.00000000"],["77550.92000000","0.00000000"],["77550.85000000","0.00000000"],["77550.69000000","0.00163000"],["77550.65000000","0.00000000"],["77550.63000000","0.00000000"],["77549.85000000","0.00000000"],["77549.56000000","0.00400000"],["77549.48000000","0.00027000"],["77549.24000000","0.03044000"],["77548.90000000","0.00000000"],["77548.37000000","0.00257000"],["77547.62000000","0.00400000"],["77547.60000000","0.11798000"],["77547.32000000","0.00000000"],["77547.23000000","0.00008000"],["77547.08000000","0.00007000"],["77546.77000000","0.00000000"],["77546.56000000","0.00000000"],["77546.55000000","0.00000000"],["77546.09000000","0.11798000"],["77546.00000000","0.03000000"],["77545.69000000","0.00000000"],["77545.68000000","0.00408000"],["77545.44000000","0.00000000"],["77545.43000000","0.00000000"],["77545.42000000","0.00000000"],["77544.99000000","0.02000000"],["77544.58000000","0.11798000"],["77544.13000000","1.93226000"],["77544.12000000","0.00000000"],["77543.95000000","0.00000000"],["77543.87000000","0.00000000"],["77543.76000000","0.11798000"],["77543.75000000","1.31471000"],["77543.74000000","0.00400000"],["77543.21000000","0.00000000"],["77543.14000000","0.00007000"],["77542.98000000","0.00000000"],["77542.79000000","0.00000000"],["77542.78000000","0.00000000"],["77542.60000000","0.00008000"],["77542.25000000","0.00000000"],["77542.01000000","0.00000000"],["77541.99000000","0.00007000"],["77541.90000000","0.00000000"],["77541.64000000","0.11798000"],["77541.63000000","0.00000000"],["77541.26000000","0.00000000"],["77541.05000000","0.02015000"],["77540.36000000","0.42553000"],["77540.35000000","0.00000000"],["77540.18000000","0.00000000"],["77539.98000000","0.00000000"],["77539.94000000","0.00000000"],["77539.89000000","0.00000000"],["77539.86000000","0.00400000"],["77539.49000000","1.31471000"],["77539.47000000","0.00008000"],["77539.20000000","0.00007000"],["77539.04000000","0.00000000"],["77538.69000000","0.00000000"],["77538.36000000","0.00000000"],["77537.82000000","0.02514000"],["77537.40000000","0.05340000"],["77536.93000000","0.00000000"],["77536.63000000","0.00000000"],["77536.11000000","0.00000000"],["77536.10000000","0.00000000"],["77535.98000000","0.00400000"],["77535.82000000","0.00000000"],["77535.59000000","0.00008000"],["77535.34000000","0.00000000"],["77535.26000000","0.00000000"],["77535.20000000","0.07775000"],["77534.04000000","0.00400000"],["77533.81000000","0.72035000"],["77533.80000000","1.93226000"],["77533.32000000","0.00000000"],["77533.00000000","0.01000000"],["77532.26000000","0.34778000"],["77532.10000000","0.00400000"],["77532.04000000","0.00000000"],["77532.00000000","0.10775000"],["77531.38000000","0.00000000"],["77531.23000000","0.00000000"],["77530.47000000","0.00000000"],["77530.41000000","0.00000000"],["77530.16000000","0.00408000"],["77530.09000000","0.00000000"],["77530.08000000","0.00007000"],["77529.72000000","0.00000000"],["77529.61000000","0.00000000"],["77529.28000000","0.00000000"],["77529.24000000","0.00000000"],["77528.56000000","0.00008000"],["77527.93000000","0.00000000"],["77527.68000000","0.00207000"],["77526.78000000","0.00000000"],["77526.75000000","0.00000000"],["77526.46000000","1.31471000"],["77525.77000000","0.00000000"],["77525.03000000","0.00000000"],["77523.34000000","1.93226000"],["77522.28000000","1.31471000"],["77521.57000000","0.00000000"],["77521.56000000","0.00000000"],["77521.42000000","0.00670000"],["77521.13000000","0.07775000"],["77519.47000000","0.00000000"],["77518.85000000","0.00000000"],["77518.40000000","0.00000000"],["77518.39000000","0.00000000"],["77518.30000000","0.34778000"],["77518.29000000","0.00000000"],["77518.28000000","0.00000000"],["77518.23000000","0.34846000"],["77518.12000000","0.34846000"],["77518.06000000","0.00000000"],["77517.98000000","0.00000000"],["77516.64000000","0.00000000"],["77515.06000000","0.07775000"],["77514.07000000","0.00000000"],["77514.02000000","1.93226000"],["77514.01000000","0.00000000"],["77513.53000000","0.00000000"],["77512.41000000","0.00000000"],["77511.65000000","0.00000000"],["77511.47000000","0.00000000"],["77509.25000000","0.00000000"],["77508.99000000","0.00000000"],["77508.98000000","1.93226000"],["77508.97000000","0.00000000"],["77508.96000000","0.00000000"],["77508.77000000","0.00000000"],["77508.74000000","0.00000000"],["77508.56000000","0.00000000"],["77506.79000000","1.31471000"],["77505.99000000","1.27788000"],["77504.33000000","0.34778000"],["77504.09000000","0.00000000"],["77504.08000000","0.00000000"],["77503.56000000","0.00000000"],["77502.40000000","0.00000000"],["77501.38000000","0.00000000"],["77500.04000000","3.24697000"],["77500.03000000","0.00000000"],["77500.02000000","0.00000000"],["77498.24000000","1.27801000"],["77495.25000000","0.00008000"],["77493.70000000","0.00010000"],["77493.61000000","3.24897000"],["77490.71000000","0.34778000"],["77490.70000000","0.00000000"],["77490.11000000","0.00000000"],["77490.10000000","0.00000000"],["77489.79000000","0.00000000"],["77489.74000000","0.07775000"],["77483.53000000","1.01991000"],["77483.52000000","1.31471000"],["77481.45000000","0.00000000"],["77481.38000000","1.93226000"],["77480.33000000","0.00000000"],["77479.20000000","0.00000000"],["77477.78000000","0.00000000"],["77476.74000000","0.34778000"],["77476.12000000","0.00000000"],["77473.43000000","1.31471000"],["77472.06000000","1.93226000"],["77470.58000000","0.07954000"],["77463.34000000","1.31471000"],["77462.74000000","1.93226000"],["77459.71000000","0.07775000"],["77456.27000000","1.02296000"],["77453.42000000","1.93226000"],["77453.25000000","1.31471000"],["77449.69000000","0.06316000"],["77448.84000000","0.00000000"],["77447.78000000","0.00000000"],["77445.96000000","0.12782000"],["77444.10000000","1.93226000"],["77443.16000000","1.31471000"],["77441.49000000","0.00000000"],["77440.73000000","0.05365000"],["77438.26000000","0.00000000"],["77437.97000000","0.00000000"],["77434.82000000","0.00000000"],["77434.78000000","1.93226000"],["77433.07000000","1.31471000"],["77428.59000000","0.66085000"],["77427.10000000","0.00000000"],["77425.98000000","0.00000000"],["77425.46000000","1.93226000"],["77422.98000000","1.31471000"],["77419.40000000","0.00000000"],["77419.39000000","0.00000000"],["77417.67000000","0.00008000"],["77416.14000000","1.93226000"],["77413.76000000","0.00008000"],["77412.89000000","1.31471000"],["77410.83000000","1.93226000"],["77408.77000000","0.00000000"],["77408.56000000","1.54491000"],["77402.80000000","1.31471000"],["77402.68000000","1.93226000"],["77398.24000000","0.00008000"],["77397.01000000","0.34796000"],["77397.00000000","0.00000000"],["77394.11000000","0.16901000"],["77393.36000000","0.00000000"],["77392.71000000","1.31471000"],["77384.04000000","0.00000000"],["77383.04000000","0.34778000"],["77382.72000000","0.00008000"],["77382.62000000","1.31471000"],["77378.66000000","0.00000000"],["77378.59000000","0.16870000"],["77374.72000000","0.00000000"],["77374.34000000","3.87897000"],["77373.13000000","0.34778000"],["77370.83000000","0.16870000"],["77367.20000000","0.00008000"],["77366.74000000","0.00007000"],["77365.40000000","0.00000000"],["77362.87000000","0.00007000"],["77359.16000000","0.34778000"],["77357.23000000","0.00000000"],["77351.78000000","2.26960000"],["77351.68000000","0.00008000"],["77348.40000000","0.00000000"],["77345.19000000","0.35004000"],["77340.10000000","0.00008000"],["77337.91000000","0.03225000"],["77279.64000000","0.00000000"],["77270.82000000","0.00000000"],["77266.02000000","0.00000000"],["77262.53000000","0.00008000"],["77245.59000000","0.00032000"],["77202.05000000","0.00000000"],["77193.23000000","0.00000000"],["77184.96000000","0.00008000"],["77184.08000000","0.00007000"],["77124.46000000","0.00000000"],["77115.65000000","0.00000000"],["77107.38000000","0.00068000"],["77046.87000000","0.00000000"],["77038.07000000","0.00000000"],["77029.81000000","0.00008000"],["76969.28000000","0.00000000"],["76960.49000000","0.00000000"],["76952.24000000","0.00008000"],["76426.43000000","0.00000000"],["76408.31000000","0.00000000"],["69831.27000000","0.00000000"],["69831.25000000","0.00000000"],["65960.00000000","0.00187000"],["65957.11000000","0.00000000"],["65936.00000000","0.00068000"],["65915.82000000","0.00340000"],["62057.41000000","0.00032000"],["62016.00000000","0.00000000"],["62009.60000000","0.00018000"]],"a":[["77571.77000000","4.49407000"],["77571.78000000","0.00027000"],["77571.79000000","0.00013000"],["77571.90000000","0.00000000"],["77572.81000000","0.00032000"],["77572.83000000","0.27135000"],["77572.84000000","0.00400000"],["77572.91000000","3.10336000"],["77572.92000000","0.28866000"],["77572.94000000","0.00021000"],["77573.11000000","0.00021000"],["77573.39000000","0.00000000"],["77573.59000000","0.05050000"],["77573.60000000","0.00000000"],["77573.64000000","0.00000000"],["77573.76000000","0.00000000"],["77573.77000000","0.00021000"],["77574.00000000","0.34469000"],["77574.01000000","0.12960000"],["77574.38000000","0.07507000"],["77574.39000000","0.00007000"],["77574.66000000","0.00014000"],["77574.78000000","0.00407000"],["77574.79000000","0.00000000"],["77574.80000000","0.00000000"],["77574.87000000","0.00000000"],["77574.88000000","0.46127000"],["77574.93000000","0.00000000"],["77574.98000000","0.00000000"],["77575.06000000","0.00000000"],["77575.08000000","0.00032000"],["77575.57000000","0.00000000"],["77575.58000000","0.28173000"],["77575.87000000","0.00007000"],["77575.99000000","0.02900000"],["77576.43000000","0.00000000"],["77576.55000000","0.00007000"],["77576.56000000","0.00007000"],["77576.57000000","0.00007000"],["77576.72000000","0.00400000"],["77576.74000000","0.34778000"],["77576.75000000","0.04014000"],["77576.76000000","0.00000000"],["77576.86000000","0.07500000"],["77576.87000000","0.00007000"],["77577.13000000","0.00000000"],["77577.37000000","0.00000000"],["77577.38000000","1.29952000"],["77577.39000000","0.00000000"],["77577.40000000","0.00014000"],["77577.76000000","0.00000000"],["77577.77000000","0.08000000"],["77577.78000000","0.00000000"],["77577.79000000","0.00000000"],["77577.91000000","0.00000000"],["77577.99000000","0.00032000"],["77578.01000000","0.12965000"],["77578.03000000","0.00007000"],["77578.17000000","0.00007000"],["77578.60000000","0.00014000"],["77578.65000000","0.00000000"],["77578.66000000","0.00400000"],["77578.81000000","0.00000000"],["77579.35000000","0.00000000"],["77579.53000000","0.00015000"],["77579.54000000","0.00007000"],["77579.55000000","0.00000000"],["77579.70000000","0.09622000"],["77579.71000000","0.00007000"],["77579.72000000","0.00000000"],["77579.85000000","0.00000000"],["77579.88000000","0.00000000"],["77579.95000000","0.00000000"],["77580.01000000","0.00000000"],["77580.60000000","0.00400000"],["77580.61000000","0.00000000"],["77580.70000000","0.00000000"],["77580.80000000","0.00000000"],["77581.12000000","0.27351000"],["77581.13000000","0.00007000"],["77581.14000000","0.30000000"],["77581.15000000","0.13137000"],["77581.16000000","0.00000000"],["77581.23000000","0.00000000"],["77581.24000000","0.00000000"],["77581.32000000","0.04130000"],["77581.33000000","0.00000000"],["77581.36000000","0.00000000"],["77581.54000000","0.00000000"],["77581.68000000","0.00000000"],["77581.82000000","0.00000000"],["77581.96000000","0.00000000"],["77582.05000000","0.00000000"],["77582.10000000","0.00000000"],["77582.18000000","0.00007000"],["77582.24000000","0.00000000"],["77582.38000000","0.00000000"],["77582.53000000","0.00000000"],["77582.54000000","0.00414000"],["77582.56000000","0.00027000"],["77582.61000000","1.93226000"],["77582.64000000","0.00015000"],["77582.82000000","0.00000000"],["77582.83000000","0.00000000"],["77582.84000000","0.00000000"],["77582.85000000","0.00000000"],["77582.97000000","0.00000000"],["77583.34000000","0.00007000"],["77583.36000000","0.00000000"],["77583.42000000","0.00000000"],["77583.46000000","0.00000000"],["77583.47000000","0.00000000"],["77583.56000000","0.00000000"],["77583.70000000","0.00000000"],["77583.80000000","0.00000000"],["77583.81000000","0.00000000"],["77583.83000000","0.25791000"],["77583.84000000","0.00000000"],["77583.85000000","0.00000000"],["77583.86000000","0.00032000"],["77583.91000000","0.00000000"],["77583.92000000","0.00000000"],["77583.99000000","0.00000000"],["77584.01000000","0.00000000"],["77584.09000000","0.00000000"],["77584.29000000","0.00000000"],["77584.47000000","0.00000000"],["77584.48000000","0.00408000"],["77584.74000000","0.00000000"],["77585.09000000","0.64477000"],["77585.10000000","0.00000000"],["77585.19000000","0.00000000"],["77585.26000000","0.00000000"],["77585.33000000","0.00000000"],["77585.34000000","0.00000000"],["77585.53000000","0.00200000"],["77585.55000000","0.00032000"],["77585.57000000","0.12888000"],["77585.58000000","0.10900000"],["77585.59000000","0.01441000"],["77585.60000000","0.00000000"],["77585.61000000","0.00000000"],["77585.62000000","0.00875000"],["77585.74000000","0.00007000"],["77585.78000000","0.00000000"],["77585.83000000","0.00000000"],["77585.92000000","0.00000000"],["77586.00000000","0.00000000"],["77586.01000000","0.00000000"],["77586.06000000","0.00000000"],["77586.13000000","0.00007000"],["77586.20000000","0.00000000"],["77586.34000000","0.00000000"],["77586.35000000","0.00010000"],["77586.42000000","0.00400000"],["77586.48000000","0.00014000"],["77586.49000000","0.00000000"],["77586.53000000","0.00007000"],["77586.57000000","0.00000000"],["77586.58000000","0.00000000"],["77586.62000000","0.00000000"],["77586.73000000","0.00000000"],["77586.76000000","0.00000000"],["77586.90000000","0.00000000"],["77587.03000000","0.00000000"],["77587.04000000","0.00000000"],["77587.10000000","0.00000000"],["77587.12000000","0.00008000"],["77587.18000000","0.00000000"],["77587.32000000","0.00000000"],["77587.33000000","0.41262000"],["77587.34000000","0.00000000"],["77587.38000000","0.00000000"],["77587.44000000","0.00007000"],["77587.60000000","0.00032000"],["77587.61000000","3.59475000"],["77587.62000000","0.00000000"],["77587.63000000","0.00000000"],["77587.77000000","0.00000000"],["77587.81000000","0.00000000"],["77587.82000000","0.00000000"],["77588.19000000","0.00000000"],["77588.22000000","0.00000000"],["77588.23000000","0.00000000"],["77588.29000000","0.01282000"],["77588.32000000","0.00000000"],["77588.36000000","0.00400000"],["77588.50000000","0.00000000"],["77588.52000000","0.00000000"],["77588.57000000","0.00000000"],["77588.67000000","0.00000000"],["77588.84000000","0.00000000"],["77589.02000000","0.00000000"],["77589.04000000","0.00000000"],["77589.05000000","0.00000000"],["77589.06000000","0.16870000"],["77589.11000000","0.00000000"],["77589.12000000","0.00000000"],["77589.36000000","0.00000000"],["77589.47000000","0.00329000"],["77589.48000000","0.00000000"],["77589.49000000","0.24807000"],["77589.57000000","0.00000000"],["77589.62000000","0.00000000"],["77589.65000000","0.24807000"],["77589.68000000","0.00000000"],["77589.70000000","0.00000000"],["77589.88000000","0.89093000"],["77589.89000000","0.34813000"],["77589.94000000","0.00000000"],["77590.02000000","0.00000000"],["77590.06000000","0.00000000"],["77590.15000000","0.00032000"],["77590.16000000","0.00000000"],["77590.23000000","0.00000000"],["77590.28000000","0.38713000"],["77590.29000000","0.07538000"],["77590.30000000","0.74043000"],["77590.31000000","0.00000000"],["77590.32000000","0.00000000"],["77590.34000000","0.30000000"],["77590.39000000","0.00008000"],["77590.52000000","0.03210000"],["77590.53000000","0.00000000"],["77590.57000000","0.00027000"],["77590.84000000","0.00000000"],["77591.00000000","0.00000000"],["77591.57000000","0.00000000"],["77591.58000000","0.00729000"],["77591.63000000","0.00000000"],["77591.64000000","0.00000000"],["77591.65000000","0.00000000"],["77591.78000000","0.00000000"],["77591.80000000","0.00000000"],["77591.81000000","0.00000000"],["77591.82000000","0.13304000"],["77591.90000000","0.00000000"],["77591.94000000","0.00000000"],["77592.00000000","0.00015000"],["77592.04000000","0.00000000"],["77592.24000000","0.00747000"],["77592.31000000","0.00000000"],["77592.32000000","0.10421000"],["77592.83000000","0.01216000"],["77593.00000000","0.00000000"],["77593.04000000","0.00000000"],["77593.27000000","0.00000000"],["77593.28000000","0.00000000"],["77593.35000000","0.00000000"],["77593.40000000","0.00008000"],["77593.41000000","0.00000000"],["77593.80000000","0.00331000"],["77594.06000000","0.00000000"],["77594.11000000","0.00000000"],["77594.12000000","0.00000000"],["77594.26000000","0.10420000"],["77594.31000000","0.00000000"],["77594.77000000","0.00000000"],["77595.04000000","0.00000000"],["77595.49000000","0.00000000"],["77595.50000000","0.00000000"],["77596.10000000","0.00000000"],["77596.11000000","3.59475000"],["77596.12000000","0.00400000"],["77596.13000000","0.00000000"],["77596.53000000","0.00007000"],["77596.62000000","0.00000000"],["77597.01000000","0.00000000"],["77597.04000000","0.00000000"],["77597.05000000","0.00000000"],["77597.07000000","0.44832000"],["77597.53000000","0.00128000"],["77598.06000000","0.17299000"],["77598.14000000","0.00000000"],["77598.15000000","0.00008000"],["77598.21000000","0.00000000"],["77598.72000000","1.27636000"],["77598.89000000","0.00000000"],["77598.92000000","0.00000000"],["77599.01000000","0.00000000"],["77600.00000000","0.09664000"],["77600.51000000","0.00000000"],["77600.56000000","0.00000000"],["77600.81000000","0.00000000"],["77601.11000000","0.00694000"],["77601.24000000","0.00000000"],["77601.88000000","0.00000000"],["77601.89000000","0.00000000"],["77601.93000000","0.00008000"],["77601.94000000","0.00400000"],["77602.05000000","0.00000000"],["77602.20000000","0.00000000"],["77602.57000000","0.00000000"],["77602.65000000","0.00400000"],["77603.70000000","0.00000000"],["77603.88000000","0.00000000"],["77604.15000000","0.00000000"],["77604.51000000","0.00000000"],["77604.86000000","0.00000000"],["77604.99000000","0.00000000"],["77605.04000000","0.00008000"],["77605.82000000","0.00029000"],["77606.10000000","0.00000000"],["77606.83000000","0.00000000"],["77607.76000000","0.00008000"],["77607.77000000","0.34778000"],["77607.78000000","0.00000000"],["77607.79000000","1.22698000"],["77608.05000000","0.00000000"],["77608.58000000","0.00000000"],["77608.59000000","0.00000000"],["77608.87000000","0.00000000"],["77609.04000000","0.00000000"],["77609.27000000","0.00000000"],["77609.70000000","0.00000000"],["77609.79000000","0.00008000"],["77609.96000000","0.00000000"],["77610.00000000","0.03000000"],["77610.94000000","0.00000000"],["77611.64000000","0.00000000"],["77612.04000000","0.00007000"],["77612.49000000","0.79525000"],["77612.74000000","0.00000000"],["77613.27000000","0.00000000"],["77613.29000000","0.00000000"],["77613.58000000","0.00029000"],["77613.67000000","0.00008000"],["77613.84000000","0.00000000"],["77614.06000000","0.00000000"],["77614.21000000","0.04570000"],["77615.14000000","0.00000000"],["77615.41000000","0.02512000"],["77615.52000000","0.00008000"],["77616.00000000","0.03007000"],["77616.38000000","0.34778000"],["77616.39000000","0.00000000"],["77616.62000000","0.00000000"],["77616.65000000","0.00000000"],["77616.78000000","0.00000000"],["77617.46000000","0.00000000"],["77617.55000000","0.00000000"],["77617.56000000","0.00000000"],["77617.92000000","0.00007000"],["77618.00000000","0.03000000"],["77619.40000000","0.00000000"],["77619.46000000","0.00000000"],["77619.51000000","0.23936000"],["77619.79000000","0.00000000"],["77619.95000000","0.00000000"],["77620.01000000","0.02123000"],["77620.50000000","0.00000000"],["77621.34000000","0.00029000"],["77621.94000000","0.00000000"],["77622.24000000","0.00000000"],["77622.77000000","0.00000000"],["77623.53000000","0.00000000"],["77624.38000000","0.00000000"],["77625.03000000","0.35943000"],["77625.22000000","0.00000000"],["77625.67000000","0.00000000"],["77625.68000000","0.79512000"],["77625.88000000","0.00007000"],["77626.26000000","0.00000000"],["77627.55000000","0.00007000"],["77627.57000000","0.34778000"],["77627.58000000","0.00007000"],["77629.10000000","0.00000000"],["77629.35000000","0.00000000"],["77629.99000000","0.00321000"],["77630.89000000","0.00000000"],["77631.53000000","1.00010000"],["77631.79000000","0.00000000"],["77631.90000000","0.00000000"],["77633.55000000","0.00322000"],["77633.56000000","0.00000000"],["77635.44000000","0.00000000"],["77635.92000000","0.00000000"],["77636.42000000","0.00007000"],["77637.99000000","0.00000000"],["77638.98000000","0.00000000"],["77641.06000000","0.34778000"],["77643.32000000","0.00000000"],["77643.33000000","0.00000000"],["77645.43000000","0.00000000"],["77647.12000000","0.00000000"],["77647.13000000","0.00000000"],["77649.64000000","0.00000000"],["77650.49000000","0.00008000"],["77653.11000000","0.00000000"],["77655.03000000","0.34778000"],["77655.09000000","0.00000000"],["77657.11000000","0.00000000"],["77657.34000000","0.00000000"],["77658.73000000","0.00000000"],["77660.29000000","0.00000000"],["77662.92000000","0.90976000"],["77665.80000000","0.34778000"],["77665.81000000","0.00000000"],["77667.17000000","0.00000000"],["77667.35000000","0.00000000"],["77667.44000000","0.00000000"],["77667.89000000","0.00000000"],["77673.60000000","0.34778000"],["77674.42000000","0.00000000"],["77674.81000000","0.00000000"],["77674.82000000","0.00000000"],["77675.69000000","0.00000000"],["77676.99000000","0.00000000"],["77681.85000000","0.00000000"],["77683.46000000","0.00600000"],["77683.99000000","0.00000000"],["77687.02000000","0.34778000"],["77687.03000000","0.99415000"],["77688.11000000","0.00587000"],["77688.89000000","0.00000000"],["77689.07000000","0.00000000"],["77693.63000000","0.00000000"],["77693.64000000","0.00000000"],["77693.99000000","0.00000000"],["77694.85000000","0.00000000"],["77698.30000000","0.02019000"],["77703.26000000","1.54491000"],["77709.88000000","0.00000000"],["77711.35000000","0.00391000"],["77712.13000000","0.00000000"],["77712.64000000","0.00128000"],["77715.99000000","0.00128000"],["77724.99000000","0.00000000"],["77726.91000000","0.00008000"],["77727.26000000","0.00000000"],["77728.33000000","0.06853000"],["77728.34000000","0.00000000"],["77734.87000000","0.00000000"],["77736.12000000","0.00007000"],["77739.68000000","0.00008000"],["77743.50000000","0.00000000"],["77745.22000000","0.00000000"],["77751.63000000","0.00007000"],["77755.20000000","0.00008000"],["77767.14000000","0.00007000"],["77770.72000000","0.00008000"],["77775.15000000","0.34778000"],["77782.65000000","0.05785000"],["77786.24000000","0.00008000"],["77789.12000000","0.34778000"],["77798.16000000","0.00007000"],["77801.76000000","0.00008000"],["77804.49000000","0.00008000"],["77806.65000000","0.03851000"],["77810.47000000","0.00000000"],["77812.45000000","0.00000000"],["77812.74000000","0.00000000"],["77813.67000000","0.00007000"],["77816.69000000","0.00000000"],["77817.28000000","0.00008000"],["77817.67000000","0.00000000"],["77821.08000000","0.00000000"],["77832.80000000","0.00000000"],["77842.64000000","0.00000000"],["77848.32000000","0.00008000"],["77882.06000000","0.00008000"],["77890.03000000","0.00000000"],["77895.81000000","0.00250000"],["77896.59000000","0.00000000"],["77898.67000000","0.00000000"],["77960.78000000","0.00008000"],["77969.06000000","0.00000000"],["77972.88000000","0.00000000"],["77978.25000000","0.00256000"],["78038.36000000","0.00008000"],["78046.64000000","0.00000000"],["78055.84000000","0.00000000"],["78115.93000000","0.00008000"],["78124.22000000","0.00000000"],["78133.43000000","0.00000000"],["78144.00000000","0.00073000"],["78193.50000000","0.00008000"],["78201.80000000","0.00000000"],["78211.02000000","0.00000000"],["78754.16000000","0.00000000"],["81454.21000000","0.00010000"],["81454.68000000","0.00010000"],["81460.21000000","0.00041000"],["81463.08000000","0.00020000"],["81535.66000000","0.00000000"],["81538.21000000","0.00000000"],["81540.94000000","0.00000000"],["81541.86000000","0.00000000"],["81541.98000000","0.00000000"],["86422.88000000","0.20801000"]]}}
{"type":"trade","received_at_ms":1788331889976,"data":{"e":"trade","E":1788331890034,"s":"BTCUSDT","t":6646634674,"p":"77571.76000000","q":"0.00007000","T":1788331890033,"m":true,"M":true}}
{"type":"trade","received_at_ms":1788331889978,"data":{"e":"trade","E":1788331890034,"s":"BTCUSDT","t":6646634675,"p":"77571.76000000","q":"0.00007000","T":1788331890033,"m":true,"M":true}}
{"type":"trade","received_at_ms":1788331889978,"data":{"e":"trade","E":1788331890034,"s":"BTCUSDT","t":6646634676,"p":"77571.76000000","q":"0.00200000","T":1788331890033,"m":true,"M":true}}
{"type":"trade","received_at_ms":1788331889978,"data":{"e":"trade","E":1788331890034,"s":"BTCUSDT","t":6646634677,"p":"77571.76000000","q":"0.00200000","T":1788331890033,"m":true,"M":true}}
{"type":"trade","received_at_ms":1788331889978,"data":{"e":"trade","E":1788331890034,"s":"BTCUSDT","t":6646634678,"p":"77571.76000000","q":"0.00200000","T":1788331890033,"m":true,"M":true}}
{"type":"trade","received_at_ms":1788331889978,"data":{"e":"trade","E":1788331890034,"s":"BTCUSDT","t":6646634679,"p":"77571.76000000","q":"0.00007000","T":1788331890033,"m":true,"M":true}}
{"type":"trade","received_at_ms":1788331889978,"data":{"e":"trade","E":1788331890034,"s":"BTCUSDT","t":6646634680,"p":"77571.76000000","q":"0.00008000","T":1788331890033,"m":true,"M":true}}
{"type":"trade","received_at_ms":1788331889978,"data":{"e":"trade","E":1788331890034,"s":"BTCUSDT","t":6646634681,"p":"77571.76000000","q":"0.00142000","T":1788331890033,"m":true,"M":true}}
{"type":"trade","received_at_ms":1788331889978,"data":{"e":"trade","E":1788331890034,"s":"BTCUSDT","t":6646634682,"p":"77571.76000000","q":"0.00058000","T":1788331890033,"m":true,"M":true}}
{"type":"trade","received_at_ms":1788331889978,"data":{"e":"trade","E":1788331890034,"s":"BTCUSDT","t":6646634683,"p":"77571.76000000","q":"0.00007000","T":1788331890033,"m":true,"M":true}}
{"type":"trade","received_at_ms":1788331889978,"data":{"e":"trade","E":1788331890034,"s":"BTCUSDT","t":6646634684,"p":"77571.76000000","q":"0.00007000","T":1788331890033,"m":true,"M":true}}
{"type":"trade","received_at_ms":1788331889978,"data":{"e":"trade","E":1788331890034,"s":"BTCUSDT","t":6646634685,"p":"77571.76000000","q":"0.00007000","T":1788331890033,"m":true,"M":true}}
{"type":"trade","received_at_ms":1788331889978,"data":{"e":"trade","E":1788331890034,"s":"BTCUSDT","t":6646634686,"p":"77571.75000000","q":"0.00007000","T":1788331890033,"m":true,"M":true}}
{"type":"trade","received_at_ms":1788331889978,"data":{"e":"trade","E":1788331890034,"s":"BTCUSDT","t":6646634687,"p":"77571.75000000","q":"0.00007000","T":1788331890033,"m":true,"M":true}}
{"type":"trade","received_at_ms":1788331889978,"data":{"e":"trade","E":1788331890034,"s":"BTCUSDT","t":6646634688,"p":"77571.55000000","q":"0.00007000","T":1788331890033,"m":true,"M":true}}
{"type":"trade","received_at_ms":1788331889978,"data":{"e":"trade","E":1788331890034,"s":"BTCUSDT","t":6646634689,"p":"77571.55000000","q":"0.00007000","T":1788331890033,"m":true,"M":true}}
{"type":"trade","received_at_ms":1788331889997,"data":{"e":"trade","E":1788331890037,"s":"BTCUSDT","t":6646634690,"p":"77571.50000000","q":"0.00007000","T":1788331890036,"m":true,"M":true}}
{"type":"trade","received_at_ms":1788331889997,"data":{"e":"trade","E":1788331890037,"s":"BTCUSDT","t":6646634691,"p":"77571.50000000","q":"0.00007000","T":1788331890036,"m":true,"M":true}}
{"type":"trade","received_at_ms":1788331889997,"data":{"e":"trade","E":1788331890037,"s":"BTCUSDT","t":6646634692,"p":"77571.50000000","q":"0.00007000","T":1788331890036,"m":true,"M":true}}
{"type":"trade","received_at_ms":1788331889997,"data":{"e":"trade","E":1788331890037,"s":"BTCUSDT","t":6646634693,"p":"77571.50000000","q":"0.00007000","T":1788331890036,"m":true,"M":true}}
{"type":"trade","received_at_ms":1788331889997,"data":{"e":"trade","E":1788331890041,"s":"BTCUSDT","t":6646634694,"p":"77571.50000000","q":"0.00007000","T":1788331890041,"m":true,"M":true}}
{"type":"trade","received_at_ms":1788331889997,"data":{"e":"trade","E":1788331890041,"s":"BTCUSDT","t":6646634695,"p":"77571.50000000","q":"0.00007000","T":1788331890041,"m":true,"M":true}}
{"type":"trade","received_at_ms":1788331889997,"data":{"e":"trade","E":1788331890041,"s":"BTCUSDT","t":6646634696,"p":"77571.50000000","q":"0.00008000","T":1788331890041,"m":true,"M":true}}
{"type":"trade","received_at_ms":1788331889997,"data":{"e":"trade","E":1788331890041,"s":"BTCUSDT","t":6646634697,"p":"77571.50000000","q":"0.00007000","T":1788331890041,"m":true,"M":true}}
{"type":"trade","received_at_ms":1788331889997,"data":{"e":"trade","E":1788331890041,"s":"BTCUSDT","t":6646634698,"p":"77571.49000000","q":"0.00007000","T":1788331890041,"m":true,"M":true}}
{"type":"trade","received_at_ms":1788331889997,"data":{"e":"trade","E":1788331890041,"s":"BTCUSDT","t":6646634699,"p":"77571.49000000","q":"0.00007000","T":1788331890041,"m":true,"M":true}}
{"type":"trade","received_at_ms":1788331889997,"data":{"e":"trade","E":1788331890043,"s":"BTCUSDT","t":6646634700,"p":"77570.90000000","q":"0.00010000","T":1788331890043,"m":true,"M":true}}
{"type":"trade","received_at_ms":1788331889997,"data":{"e":"trade","E":1788331890043,"s":"BTCUSDT","t":6646634701,"p":"77570.90000000","q":"0.00007000","T":1788331890043,"m":true,"M":true}}
{"type":"trade","received_at_ms":1788331889997,"data":{"e":"trade","E":1788331890043,"s":"BTCUSDT","t":6646634702,"p":"77570.90000000","q":"0.00007000","T":1788331890043,"m":true,"M":true}}
{"type":"trade","received_at_ms":1788331889997,"data":{"e":"trade","E":1788331890043,"s":"BTCUSDT","t":6646634703,"p":"77570.90000000","q":"0.00007000","T":1788331890043,"m":true,"M":true}}
{"type":"trade","received_at_ms":1788331889997,"data":{"e":"trade","E":1788331890043,"s":"BTCUSDT","t":6646634704,"p":"77570.90000000","q":"0.00007000","T":1788331890043,"m":true,"M":true}}
{"type":"trade","received_at_ms":1788331889997,"data":{"e":"trade","E":1788331890045,"s":"BTCUSDT","t":6646634705,"p":"77570.44000000","q":"0.00128000","T":1788331890045,"m":true,"M":true}}
{"type":"trade","received_at_ms":1788331889997,"data":{"e":"trade","E":1788331890045,"s":"BTCUSDT","t":6646634706,"p":"77570.44000000","q":"0.00007000","T":1788331890045,"m":true,"M":true}}
{"type":"trade","received_at_ms":1788331889997,"data":{"e":"trade","E":1788331890045,"s":"BTCUSDT","t":6646634707,"p":"77570.44000000","q":"0.00007000","T":1788331890045,"m":true,"M":true}}
{"type":"trade","received_at_ms":1788331889997,"data":{"e":"trade","E":1788331890047,"s":"BTCUSDT","t":6646634708,"p":"77570.01000000","q":"0.00007000","T":1788331890046,"m":true,"M":true}}
{"type":"trade","received_at_ms":1788331889997,"data":{"e":"trade","E":1788331890047,"s":"BTCUSDT","t":6646634709,"p":"77570.01000000","q":"0.00007000","T":1788331890046,"m":true,"M":true}}
{"type":"trade","received_at_ms":1788331889997,"data":{"e":"trade","E":1788331890047,"s":"BTCUSDT","t":6646634710,"p":"77570.01000000","q":"0.00007000","T":1788331890046,"m":true,"M":true}}
{"type":"trade","received_at_ms":1788331889997,"data":{"e":"trade","E":1788331890047,"s":"BTCUSDT","t":6646634711,"p":"77570.01000000","q":"0.00007000","T":1788331890046,"m":true,"M":true}}
{"type":"trade","received_at_ms":1788331889997,"data":{"e":"trade","E":1788331890047,"s":"BTCUSDT","t":6646634712,"p":"77570.01000000","q":"0.00007000","T":1788331890046,"m":true,"M":true}}
{"type":"trade","received_at_ms":1788331889997,"data":{"e":"trade","E":1788331890047,"s":"BTCUSDT","t":6646634713,"p":"77570.00000000","q":"0.00500000","T":1788331890046,"m":true,"M":true}}
{"type":"trade","received_at_ms":1788331889997,"data":{"e":"trade","E":1788331890047,"s":"BTCUSDT","t":6646634714,"p":"77570.00000000","q":"0.00500000","T":1788331890046,"m":true,"M":true}}
{"type":"trade","received_at_ms":1788331889997,"data":{"e":"trade","E":1788331890047,"s":"BTCUSDT","t":6646634715,"p":"77570.00000000","q":"0.01000000","T":1788331890046,"m":true,"M":true}}
{"type":"trade","received_at_ms":1788331889997,"data":{"e":"trade","E":1788331890047,"s":"BTCUSDT","t":6646634716,"p":"77570.00000000","q":"0.01000000","T":1788331890046,"m":true,"M":true}}
{"type":"trade","received_at_ms":1788331889997,"data":{"e":"trade","E":1788331890047,"s":"BTCUSDT","t":6646634717,"p":"77570.00000000","q":"0.00007000","T":1788331890046,"m":true,"M":true}}
{"type":"trade","received_at_ms":1788331889997,"data":{"e":"trade","E":1788331890047,"s":"BTCUSDT","t":6646634718,"p":"77570.00000000","q":"0.00007000","T":1788331890046,"m":true,"M":true}}
{"type":"trade","received_at_ms":1788331889997,"data":{"e":"trade","E":1788331890048,"s":"BTCUSDT","t":6646634719,"p":"77568.98000000","q":"0.00012000","T":1788331890048,"m":true,"M":true}}
{"type":"trade","received_at_ms":1788331889997,"data":{"e":"trade","E":1788331890048,"s":"BTCUSDT","t":6646634720,"p":"77568.50000000","q":"0.00599000","T":1788331890048,"m":true,"M":true}}
{"type":"trade","received_at_ms":1788331889997,"data":{"e":"trade","E":1788331890048,"s":"BTCUSDT","t":6646634721,"p":"77568.04000000","q":"0.00007000","T":1788331890048,"m":true,"M":true}}
{"type":"trade","received_at_ms":1788331889997,"data":{"e":"trade","E":1788331890048,"s":"BTCUSDT","t":6646634722,"p":"77568.04000000","q":"0.00007000","T":1788331890048,"m":true,"M":true}}
{"type":"trade","received_at_ms":1788331889997,"data":{"e":"trade","E":1788331890064,"s":"BTCUSDT","t":6646634723,"p":"77568.00000000","q":"0.00007000","T":1788331890064,"m":true,"M":true}}
{"type":"trade","received_at_ms":1788331889997,"data":{"e":"trade","E":1788331890064,"s":"BTCUSDT","t":6646634724,"p":"77568.00000000","q":"0.00500000","T":1788331890064,"m":true,"M":true}}
{"type":"trade","received_at_ms":1788331889997,"data":{"e":"trade","E":1788331890064,"s":"BTCUSDT","t":6646634725,"p":"77568.00000000","q":"0.00500000","T":1788331890064,"m":true,"M":true}}
{"type":"trade","received_at_ms":1788331889997,"data":{"e":"trade","E":1788331890064,"s":"BTCUSDT","t":6646634726,"p":"77568.00000000","q":"0.01000000","T":1788331890064,"m":true,"M":true}}
{"type":"trade","received_at_ms":1788331889997,"data":{"e":"trade","E":1788331890064,"s":"BTCUSDT","t":6646634727,"p":"77568.00000000","q":"0.01000000","T":1788331890064,"m":true,"M":true}}
{"type":"trade","received_at_ms":1788331889997,"data":{"e":"trade","E":1788331890064,"s":"BTCUSDT","t":6646634728,"p":"77568.00000000","q":"0.00007000","T":1788331890064,"m":true,"M":true}}
{"type":"trade","received_at_ms":1788331889997,"data":{"e":"trade","E":1788331890064,"s":"BTCUSDT","t":6646634729,"p":"77568.00000000","q":"0.00007000","T":1788331890064,"m":true,"M":true}}
{"type":"trade","received_at_ms":1788331889997,"data":{"e":"trade","E":1788331890064,"s":"BTCUSDT","t":6646634730,"p":"77568.00000000","q":"0.00007000","T":1788331890064,"m":true,"M":true}}
{"type":"trade","received_at_ms":1788331889997,"data":{"e":"trade","E":1788331890064,"s":"BTCUSDT","t":6646634731,"p":"77568.00000000","q":"0.00007000","T":1788331890064,"m":true,"M":true}}
{"type":"trade","received_at_ms":1788331889997,"data":{"e":"trade","E":1788331890064,"s":"BTCUSDT","t":6646634732,"p":"77568.00000000","q":"0.00007000","T":1788331890064,"m":true,"M":true}}
{"type":"trade","received_at_ms":1788331889997,"data":{"e":"trade","E":1788331890064,"s":"BTCUSDT","t":6646634733,"p":"77568.00000000","q":"0.00007000","T":1788331890064,"m":true,"M":true}}
{"type":"trade","received_at_ms":1788331889997,"data":{"e":"trade","E":1788331890064,"s":"BTCUSDT","t":6646634734,"p":"77568.00000000","q":"0.00007000","T":1788331890064,"m":true,"M":true}}
{"type":"trade","received_at_ms":1788331889997,"data":{"e":"trade","E":1788331890064,"s":"BTCUSDT","t":6646634735,"p":"77568.00000000","q":"0.00007000","T":1788331890064,"m":true,"M":true}}
{"type":"trade","received_at_ms":1788331889997,"data":{"e":"trade","E":1788331890064,"s":"BTCUSDT","t":6646634736,"p":"77568.00000000","q":"0.00007000","T":1788331890064,"m":true,"M":true}}
{"type":"trade","received_at_ms":1788331889997,"data":{"e":"trade","E":1788331890064,"s":"BTCUSDT","t":6646634737,"p":"77568.00000000","q":"0.00008000","T":1788331890064,"m":true,"M":true}}
{"type":"trade","received_at_ms":1788331889997,"data":{"e":"trade","E":1788331890064,"s":"BTCUSDT","t":6646634738,"p":"77568.00000000","q":"0.00007000","T":1788331890064,"m":true,"M":true}}
{"type":"trade","received_at_ms":1788331889997,"data":{"e":"trade","E":1788331890064,"s":"BTCUSDT","t":6646634739,"p":"77568.00000000","q":"0.00007000","T":1788331890064,"m":true,"M":true}}
{"type":"trade","received_at_ms":1788331889997,"data":{"e":"trade","E":1788331890064,"s":"BTCUSDT","t":6646634740,"p":"77568.00000000","q":"0.00007000","T":1788331890064,"m":true,"M":true}}
{"type":"trade","received_at_ms":1788331889997,"data":{"e":"trade","E":1788331890064,"s":"BTCUSDT","t":6646634741,"p":"77568.00000000","q":"0.00007000","T":1788331890064,"m":true,"M":true}}
{"type":"trade","received_at_ms":1788331889997,"data":{"e":"trade","E":1788331890064,"s":"BTCUSDT","t":6646634742,"p":"77568.00000000","q":"0.00007000","T":1788331890064,"m":true,"M":true}}
{"type":"trade","received_at_ms":1788331889997,"data":{"e":"trade","E":1788331890064,"s":"BTCUSDT","t":6646634743,"p":"77567.99000000","q":"0.00007000","T":1788331890064,"m":true,"M":true}}
{"type":"trade","received_at_ms":1788331889998,"data":{"e":"trade","E":1788331890064,"s":"BTCUSDT","t":6646634744,"p":"77567.99000000","q":"0.00007000","T":1788331890064,"m":true,"M":true}}
{"type":"trade","received_at_ms":1788331889998,"data":{"e":"trade","E":1788331890064,"s":"BTCUSDT","t":6646634745,"p":"77567.60000000","q":"0.00008000","T":1788331890064,"m":true,"M":true}}
{"type":"trade","received_at_ms":1788331889998,"data":{"e":"trade","E":1788331890066,"s":"BTCUSDT","t":6646634746,"p":"77567.26000000","q":"0.00700000","T":1788331890066,"m":true,"M":true}}
{"type":"trade","received_at_ms":1788331889998,"data":{"e":"trade","E":1788331890066,"s":"BTCUSDT","t":6646634747,"p":"77567.26000000","q":"0.00298000","T":1788331890066,"m":true,"M":true}}
{"type":"trade","received_at_ms":1788331889998,"data":{"e":"trade","E":1788331890066,"s":"BTCUSDT","t":6646634748,"p":"77567.26000000","q":"0.00007000","T":1788331890066,"m":true,"M":true}}
{"type":"trade","received_at_ms":1788331889998,"data":{"e":"trade","E":1788331890066,"s":"BTCUSDT","t":6646634749,"p":"77567.26000000","q":"0.00007000","T":1788331890066,"m":true,"M":true}}
{"type":"trade","received_at_ms":1788331889998,"data":{"e":"trade","E":1788331890066,"s":"BTCUSDT","t":6646634750,"p":"77567.26000000","q":"0.00007000","T":1788331890066,"m":true,"M":true}}
{"type":"trade","received_at_ms":1788331889998,"data":{"e":"trade","E":1788331890066,"s":"BTCUSDT","t":6646634751,"p":"77567.26000000","q":"0.00007000","T":1788331890066,"m":true,"M":true}}
{"type":"trade","received_at_ms":1788331889998,"data":{"e":"trade","E":1788331890066,"s":"BTCUSDT","t":6646634752,"p":"77567.26000000","q":"0.00007000","T":1788331890066,"m":true,"M":true}}
{"type":"trade","received_at_ms":1788331889998,"data":{"e":"trade","E":1788331890066,"s":"BTCUSDT","t":6646634753,"p":"77567.26000000","q":"0.00007000","T":1788331890066,"m":true,"M":true}}
{"type":"trade","received_at_ms":1788331889998,"data":{"e":"trade","E":1788331890066,"s":"BTCUSDT","t":6646634754,"p":"77567.23000000","q":"0.00007000","T":1788331890066,"m":true,"M":true}}
{"type":"trade","received_at_ms":1788331889998,"data":{"e":"trade","E":1788331890066,"s":"BTCUSDT","t":6646634755,"p":"77567.23000000","q":"0.00007000","T":1788331890066,"m":true,"M":true}}
{"type":"trade","received_at_ms":1788331889998,"data":{"e":"trade","E":1788331890067,"s":"BTCUSDT","t":6646634756,"p":"77566.79000000","q":"0.00007000","T":1788331890066,"m":true,"M":true}}
{"type":"trade","received_at_ms":1788331889998,"data":{"e":"trade","E":1788331890067,"s":"BTCUSDT","t":6646634757,"p":"77566.79000000","q":"0.00007000","T":1788331890066,"m":true,"M":true}}
{"type":"trade","received_at_ms":1788331889998,"data":{"e":"trade","E":1788331890067,"s":"BTCUSDT","t":6646634758,"p":"77566.79000000","q":"0.00007000","T":1788331890066,"m":true,"M":true}}
{"type":"trade","received_at_ms":1788331889998,"data":{"e":"trade","E":1788331890067,"s":"BTCUSDT","t":6646634759,"p":"77566.79000000","q":"0.00007000","T":1788331890066,"m":true,"M":true}}
{"type":"trade","received_at_ms":1788331889998,"data":{"e":"trade","E":1788331890067,"s":"BTCUSDT","t":6646634760,"p":"77566.79000000","q":"0.00007000","T":1788331890066,"m":true,"M":true}}
{"type":"trade","received_at_ms":1788331889998,"data":{"e":"trade","E":1788331890067,"s":"BTCUSDT","t":6646634761,"p":"77566.78000000","q":"0.00007000","T":1788331890066,"m":true,"M":true}}
{"type":"trade","received_at_ms":1788331889998,"data":{"e":"trade","E":1788331890067,"s":"BTCUSDT","t":6646634762,"p":"77566.46000000","q":"0.00587000","T":1788331890066,"m":true,"M":true}}
{"type":"trade","received_at_ms":1788331889998,"data":{"e":"trade","E":1788331890067,"s":"BTCUSDT","t":6646634763,"p":"77566.46000000","q":"0.00007000","T":1788331890066,"m":true,"M":true}}
{"type":"trade","received_at_ms":1788331889998,"data":{"e":"trade","E":1788331890067,"s":"BTCUSDT","t":6646634764,"p":"77566.46000000","q":"0.00007000","T":1788331890066,"m":true,"M":true}}
{"type":"trade","received_at_ms":1788331889998,"data":{"e":"trade","E":1788331890067,"s":"BTCUSDT","t":6646634765,"p":"77566.46000000","q":"0.00007000","T":1788331890066,"m":true,"M":true}}
{"type":"trade","received_at_ms":1788331889998,"data":{"e":"trade","E":1788331890067,"s":"BTCUSDT","t":6646634766,"p":"77566.46000000","q":"0.00007000","T":1788331890066,"m":true,"M":true}}
{"type":"trade","received_at_ms":1788331889998,"data":{"e":"trade","E":1788331890067,"s":"BTCUSDT","t":6646634767,"p":"77566.03000000","q":"0.00007000","T":1788331890066,"m":true,"M":true}}
{"type":"trade","received_at_ms":1788331889998,"data":{"e":"trade","E":1788331890067,"s":"BTCUSDT","t":6646634768,"p":"77566.03000000","q":"0.00007000","T":1788331890066,"m":true,"M":true}}
{"type":"trade","received_at_ms":1788331889998,"data":{"e":"trade","E":1788331890067,"s":"BTCUSDT","t":6646634769,"p":"77566.03000000","q":"0.00007000","T":1788331890066,"m":true,"M":true}}
{"type":"trade","received_at_ms":1788331889998,"data":{"e":"trade","E":1788331890067,"s":"BTCUSDT","t":6646634770,"p":"77566.02000000","q":"0.01198000","T":1788331890066,"m":true,"M":true}}
{"type":"trade","received_at_ms":1788331889998,"data":{"e":"trade","E":1788331890067,"s":"BTCUSDT","t":6646634771,"p":"77566.01000000","q":"0.00007000","T":1788331890066,"m":true,"M":true}}
{"type":"trade","received_at_ms":1788331889998,"data":{"e":"trade","E":1788331890067,"s":"BTCUSDT","t":6646634772,"p":"77566.01000000","q":"0.00007000","T":1788331890066,"m":true,"M":true}}
{"type":"trade","received_at_ms":1788331889998,"data":{"e":"trade","E":1788331890067,"s":"BTCUSDT","t":6646634773,"p":"77566.01000000","q":"0.00007000","T":1788331890066,"m":true,"M":true}}
{"type":"trade","received_at_ms":1788331889998,"data":{"e":"trade","E":1788331890067,"s":"BTCUSDT","t":6646634774,"p":"77566.00000000","q":"0.00500000","T":1788331890066,"m":true,"M":true}}
{"type":"trade","received_at_ms":1788331889998,"data":{"e":"trade","E":1788331890067,"s":"BTCUSDT","t":6646634775,"p":"77566.00000000","q":"0.00500000","T":1788331890066,"m":true,"M":true}}
{"type":"trade","received_at_ms":1788331889998,"data":{"e":"trade","E":1788331890067,"s":"BTCUSDT","t":6646634776,"p":"77566.00000000","q":"0.01000000","T":1788331890066,"m":true,"M":true}}
{"type":"trade","received_at_ms":1788331889998,"data":{"e":"trade","E":1788331890067,"s":"BTCUSDT","t":6646634777,"p":"77566.00000000","q":"0.01000000","T":1788331890066,"m":true,"M":true}}
{"type":"trade","received_at_ms":1788331889998,"data":{"e":"trade","E":1788331890067,"s":"BTCUSDT","t":6646634778,"p":"77566.00000000","q":"0.00007000","T":1788331890066,"m":true,"M":true}}
{"type":"trade","received_at_ms":1788331889998,"data":{"e":"trade","E":1788331890067,"s":"BTCUSDT","t":6646634779,"p":"77566.00000000","q":"0.00007000","T":1788331890066,"m":true,"M":true}}
{"type":"trade","received_at_ms":1788331889998,"data":{"e":"trade","E":1788331890067,"s":"BTCUSDT","t":6646634780,"p":"77566.00000000","q":"0.00007000","T":1788331890066,"m":true,"M":true}}
{"type":"trade","received_at_ms":1788331889998,"data":{"e":"trade","E":1788331890067,"s":"BTCUSDT","t":6646634781,"p":"77566.00000000","q":"0.00007000","T":1788331890066,"m":true,"M":true}}
{"type":"trade","received_at_ms":1788331889998,"data":{"e":"trade","E":1788331890067,"s":"BTCUSDT","t":6646634782,"p":"77566.00000000","q":"0.00007000","T":1788331890066,"m":true,"M":true}}
{"type":"trade","received_at_ms":1788331889998,"data":{"e":"trade","E":1788331890067,"s":"BTCUSDT","t":6646634783,"p":"77566.00000000","q":"0.00007000","T":1788331890066,"m":true,"M":true}}
{"type":"trade","received_at_ms":1788331889998,"data":{"e":"trade","E":1788331890067,"s":"BTCUSDT","t":6646634784,"p":"77566.00000000","q":"0.00007000","T":1788331890066,"m":true,"M":true}}
{"type":"trade","received_at_ms":1788331889998,"data":{"e":"trade","E":1788331890067,"s":"BTCUSDT","t":6646634785,"p":"77566.00000000","q":"0.00007000","T":1788331890066,"m":true,"M":true}}
{"type":"trade","received_at_ms":1788331889998,"data":{"e":"trade","E":1788331890067,"s":"BTCUSDT","t":6646634786,"p":"77565.95000000","q":"0.00200000","T":1788331890066,"m":true,"M":true}}
{"type":"trade","received_at_ms":1788331889998,"data":{"e":"trade","E":1788331890067,"s":"BTCUSDT","t":6646634787,"p":"77565.94000000","q":"0.00007000","T":1788331890066,"m":true,"M":true}}
{"type":"trade","received_at_ms":1788331889998,"data":{"e":"trade","E":1788331890067,"s":"BTCUSDT","t":6646634788,"p":"77565.94000000","q":"0.00007000","T":1788331890066,"m":true,"M":true}}
{"type":"trade","received_at_ms":1788331889998,"data":{"e":"trade","E":1788331890067,"s":"BTCUSDT","t":6646634789,"p":"77565.80000000","q":"0.00007000","T":1788331890066,"m":true,"M":true}}
{"type":"trade","received_at_ms":1788331889998,"data":{"e":"trade","E":1788331890067,"s":"BTCUSDT","t":6646634790,"p":"77565.80000000","q":"0.00007000","T":1788331890066,"m":true,"M":true}}
{"type":"trade","received_at_ms":1788331889998,"data":{"e":"trade","E":1788331890067,"s":"BTCUSDT","t":6646634791,"p":"77565.80000000","q":"0.00007000","T":1788331890066,"m":true,"M":true}}
{"type":"trade","received_at_ms":1788331889998,"data":{"e":"trade","E":1788331890067,"s":"BTCUSDT","t":6646634792,"p":"77565.80000000","q":"0.00007000","T":1788331890066,"m":true,"M":true}}
{"type":"trade","received_at_ms":1788331889998,"data":{"e":"trade","E":1788331890093,"s":"BTCUSDT","t":6646634793,"p":"77564.79000000","q":"0.00007000","T":1788331890092,"m":true,"M":true}}
{"type":"trade","received_at_ms":1788331889998,"data":{"e":"trade","E":1788331890093,"s":"BTCUSDT","t":6646634794,"p":"77564.79000000","q":"0.00007000","T":1788331890092,"m":true,"M":true}}
{"type":"trade","received_at_ms":1788331889998,"data":{"e":"trade","E":1788331890093,"s":"BTCUSDT","t":6646634795,"p":"77564.79000000","q":"0.00007000","T":1788331890092,"m":true,"M":true}}
{"type":"trade","received_at_ms":1788331889998,"data":{"e":"trade","E":1788331890093,"s":"BTCUSDT","t":6646634796,"p":"77564.79000000","q":"0.00007000","T":1788331890092,"m":true,"M":true}}
{"type":"trade","received_at_ms":1788331889998,"data":{"e":"trade","E":1788331890093,"s":"BTCUSDT","t":6646634797,"p":"77564.79000000","q":"0.00007000","T":1788331890092,"m":true,"M":true}}
{"type":"trade","received_at_ms":1788331889998,"data":{"e":"trade","E":1788331890093,"s":"BTCUSDT","t":6646634798,"p":"77564.79000000","q":"0.00007000","T":1788331890092,"m":true,"M":true}}
{"type":"trade","received_at_ms":1788331889998,"data":{"e":"trade","E":1788331890093,"s":"BTCUSDT","t":6646634799,"p":"77564.79000000","q":"0.00007000","T":1788331890092,"m":true,"M":true}}
{"type":"trade","received_at_ms":1788331889998,"data":{"e":"trade","E":1788331890093,"s":"BTCUSDT","t":6646634800,"p":"77564.79000000","q":"0.00007000","T":1788331890092,"m":true,"M":true}}
{"type":"trade","received_at_ms":1788331889998,"data":{"e":"trade","E":1788331890093,"s":"BTCUSDT","t":6646634801,"p":"77564.79000000","q":"0.00007000","T":1788331890092,"m":true,"M":true}}
{"type":"trade","received_at_ms":1788331889998,"data":{"e":"trade","E":1788331890093,"s":"BTCUSDT","t":6646634802,"p":"77564.79000000","q":"0.00007000","T":1788331890092,"m":true,"M":true}}
{"type":"trade","received_at_ms":1788331889998,"data":{"e":"trade","E":1788331890093,"s":"BTCUSDT","t":6646634803,"p":"77564.79000000","q":"0.00007000","T":1788331890092,"m":true,"M":true}}
{"type":"trade","received_at_ms":1788331889998,"data":{"e":"trade","E":1788331890093,"s":"BTCUSDT","t":6646634804,"p":"77564.79000000","q":"0.00007000","T":1788331890092,"m":true,"M":true}}
{"type":"trade","received_at_ms":1788331889998,"data":{"e":"trade","E":1788331890093,"s":"BTCUSDT","t":6646634805,"p":"77564.79000000","q":"0.00007000","T":1788331890092,"m":true,"M":true}}
{"type":"trade","received_at_ms":1788331889998,"data":{"e":"trade","E":1788331890093,"s":"BTCUSDT","t":6646634806,"p":"77564.79000000","q":"0.00007000","T":1788331890092,"m":true,"M":true}}
{"type":"trade","received_at_ms":1788331889998,"data":{"e":"trade","E":1788331890093,"s":"BTCUSDT","t":6646634807,"p":"77564.79000000","q":"0.00007000","T":1788331890092,"m":true,"M":true}}
{"type":"trade","received_at_ms":1788331889998,"data":{"e":"trade","E":1788331890093,"s":"BTCUSDT","t":6646634808,"p":"77564.79000000","q":"0.00007000","T":1788331890092,"m":true,"M":true}}
{"type":"trade","received_at_ms":1788331889998,"data":{"e":"trade","E":1788331890093,"s":"BTCUSDT","t":6646634809,"p":"77564.79000000","q":"0.00007000","T":1788331890092,"m":true,"M":true}}
{"type":"trade","received_at_ms":1788331889998,"data":{"e":"trade","E":1788331890093,"s":"BTCUSDT","t":6646634810,"p":"77564.79000000","q":"0.00008000","T":1788331890092,"m":true,"M":true}}
{"type":"trade","received_at_ms":1788331889998,"data":{"e":"trade","E":1788331890093,"s":"BTCUSDT","t":6646634811,"p":"77564.79000000","q":"0.00007000","T":1788331890092,"m":true,"M":true}}
{"type":"trade","received_at_ms":1788331889998,"data":{"e":"trade","E":1788331890108,"s":"BTCUSDT","t":6646634812,"p":"77564.79000000","q":"0.00007000","T":1788331890107,"m":true,"M":true}}
{"type":"trade","received_at_ms":1788331889998,"data":{"e":"trade","E":1788331890108,"s":"BTCUSDT","t":6646634813,"p":"77564.79000000","q":"0.00007000","T":1788331890107,"m":true,"M":true}}
{"type":"trade","received_at_ms":1788331889998,"data":{"e":"trade","E":1788331890108,"s":"BTCUSDT","t":6646634814,"p":"77564.79000000","q":"0.00008000","T":1788331890107,"m":true,"M":true}}
{"type":"trade","received_at_ms":1788331889998,"data":{"e":"trade","E":1788331890108,"s":"BTCUSDT","t":6646634815,"p":"77564.79000000","q":"0.00007000","T":1788331890107,"m":true,"M":true}}
{"type":"trade","received_at_ms":1788331889998,"data":{"e":"trade","E":1788331890108,"s":"BTCUSDT","t":6646634816,"p":"77564.79000000","q":"0.00007000","T":1788331890107,"m":true,"M":true}}
{"type":"trade","received_at_ms":1788331889998,"data":{"e":"trade","E":1788331890108,"s":"BTCUSDT","t":6646634817,"p":"77564.79000000","q":"0.00007000","T":1788331890107,"m":true,"M":true}}
{"type":"trade","received_at_ms":1788331889998,"data":{"e":"trade","E":1788331890108,"s":"BTCUSDT","t":6646634818,"p":"77564.79000000","q":"0.00007000","T":1788331890107,"m":true,"M":true}}
{"type":"trade","received_at_ms":1788331889998,"data":{"e":"trade","E":1788331890108,"s":"BTCUSDT","t":6646634819,"p":"77564.79000000","q":"0.00007000","T":1788331890107,"m":true,"M":true}}
{"type":"trade","received_at_ms":1788331889998,"data":{"e":"trade","E":1788331890108,"s":"BTCUSDT","t":6646634820,"p":"77564.79000000","q":"0.00007000","T":1788331890107,"m":true,"M":true}}
{"type":"trade","received_at_ms":1788331889998,"data":{"e":"trade","E":1788331890108,"s":"BTCUSDT","t":6646634821,"p":"77564.79000000","q":"0.00007000","T":1788331890107,"m":true,"M":true}}
{"type":"trade","received_at_ms":1788331889998,"data":{"e":"trade","E":1788331890108,"s":"BTCUSDT","t":6646634822,"p":"77564.79000000","q":"0.00007000","T":1788331890107,"m":true,"M":true}}
{"type":"trade","received_at_ms":1788331889998,"data":{"e":"trade","E":1788331890108,"s":"BTCUSDT","t":6646634823,"p":"77564.79000000","q":"0.00007000","T":1788331890107,"m":true,"M":true}}
{"type":"trade","received_at_ms":1788331889998,"data":{"e":"trade","E":1788331890108,"s":"BTCUSDT","t":6646634824,"p":"77564.79000000","q":"0.00007000","T":1788331890107,"m":true,"M":true}}
{"type":"trade","received_at_ms":1788331889998,"data":{"e":"trade","E":1788331890108,"s":"BTCUSDT","t":6646634825,"p":"77564.79000000","q":"0.00007000","T":1788331890107,"m":true,"M":true}}
{"type":"trade","received_at_ms":1788331889998,"data":{"e":"trade","E":1788331890108,"s":"BTCUSDT","t":6646634826,"p":"77564.79000000","q":"0.00007000","T":1788331890107,"m":true,"M":true}}
{"type":"trade","received_at_ms":1788331889998,"data":{"e":"trade","E":1788331890108,"s":"BTCUSDT","t":6646634827,"p":"77564.79000000","q":"0.00007000","T":1788331890107,"m":true,"M":true}}
{"type":"trade","received_at_ms":1788331889998,"data":{"e":"trade","E":1788331890108,"s":"BTCUSDT","t":6646634828,"p":"77564.79000000","q":"0.00007000","T":1788331890107,"m":true,"M":true}}
{"type":"trade","received_at_ms":1788331889998,"data":{"e":"trade","E":1788331890108,"s":"BTCUSDT","t":6646634829,"p":"77564.79000000","q":"0.00007000","T":1788331890107,"m":true,"M":true}}
{"type":"trade","received_at_ms":1788331889998,"data":{"e":"trade","E":1788331890108,"s":"BTCUSDT","t":6646634830,"p":"77564.79000000","q":"0.00007000","T":1788331890107,"m":true,"M":true}}
{"type":"trade","received_at_ms":1788331889998,"data":{"e":"trade","E":1788331890108,"s":"BTCUSDT","t":6646634831,"p":"77564.79000000","q":"0.00007000","T":1788331890107,"m":true,"M":true}}
{"type":"depth","received_at_ms":1788331889998,"data":{"e":"depthUpdate","E":1788331890114,"s":"BTCUSDT","U":99555829131,"u":99555831418,"b":[["77571.76000000","0.00000000"],["77571.75000000","0.00000000"],["77571.55000000","0.00000000"],["77571.51000000","0.00000000"],["77571.50000000","0.00000000"],["77571.49000000","0.00000000"],["77570.90000000","0.00000000"],["77570.72000000","0.00000000"],["77570.44000000","0.00000000"],["77570.01000000","0.00000000"],["77570.00000000","0.00000000"],["77569.39000000","0.00000000"],["77568.98000000","0.00000000"],["77568.94000000","0.00000000"],["77568.50000000","0.00000000"],["77568.04000000","0.00000000"],["77568.01000000","0.00000000"],["77568.00000000","0.00000000"],["77567.99000000","0.00000000"],["77567.60000000","0.00000000"],["77567.26000000","0.00000000"],["77567.24000000","0.00000000"],["77567.23000000","0.00000000"],["77567.16000000","0.00000000"],["77566.79000000","0.00000000"],["77566.78000000","0.00000000"],["77566.59000000","0.00000000"],["77566.46000000","0.00000000"],["77566.12000000","0.00000000"],["77566.03000000","0.00000000"],["77566.02000000","0.00000000"],["77566.01000000","0.00000000"],["77566.00000000","0.00000000"],["77565.95000000","0.00000000"],["77565.94000000","0.00000000"],["77565.81000000","0.00000000"],["77565.80000000","0.00000000"],["77565.63000000","0.00000000"],["77565.06000000","0.00000000"],["77564.79000000","0.00000000"],["77564.78000000","0.23967000"],["77564.77000000","0.00063000"],["77564.32000000","0.00000000"],["77564.31000000","0.00021000"],["77564.04000000","0.00000000"],["77564.03000000","0.00000000"],["77564.02000000","0.00000000"],["77564.01000000","0.00028000"],["77564.00000000","0.03028000"],["77563.80000000","0.00000000"],["77563.59000000","0.00000000"],["77563.58000000","0.00014000"],["77563.57000000","0.00014000"],["77563.42000000","0.00007000"],["77563.33000000","0.00000000"],["77563.32000000","0.00000000"],["77563.14000000","0.00000000"],["77562.24000000","0.00000000"],["77562.01000000","0.00014000"],["77562.00000000","0.03021000"],["77561.85000000","0.00000000"],["77561.84000000","0.00007000"],["77561.22000000","0.00000000"],["77561.18000000","0.00000000"],["77561.17000000","0.00000000"],["77561.01000000","0.00000000"],["77561.00000000","0.00529000"],["77560.94000000","0.00000000"],["77560.37000000","0.00014000"],["77560.36000000","0.10066000"],["77560.35000000","0.00007000"],["77560.14000000","0.00000000"],["77560.04000000","0.00007000"],["77560.01000000","0.00007000"],["77560.00000000","0.03021000"],["77559.96000000","0.00000000"],["77559.59000000","0.00000000"],["77559.55000000","0.00000000"],["77559.03000000","0.00000000"],["77558.90000000","0.00007000"],["77558.89000000","0.02908000"],["77558.74000000","0.00007000"],["77558.47000000","0.00000000"],["77558.35000000","0.00007000"],["77558.25000000","0.00000000"],["77558.23000000","0.00000000"],["77558.11000000","0.00000000"],["77558.08000000","0.00000000"],["77558.01000000","0.00000000"],["77558.00000000","0.03021000"],["77557.92000000","0.00027000"],["77557.87000000","0.00000000"],["77557.30000000","0.00000000"],["77557.24000000","0.11370000"],["77557.03000000","0.00008000"],["77556.70000000","0.00000000"],["77556.53000000","0.10898000"],["77556.52000000","0.10872000"],["77556.43000000","0.00000000"],["77556.42000000","0.00000000"],["77556.08000000","0.00000000"],["77555.39000000","0.00000000"],["77555.19000000","0.00208000"],["77554.94000000","0.11799000"],["77554.89000000","0.00000000"],["77554.75000000","0.00000000"],["77554.38000000","0.00000000"],["77554.24000000","0.00000000"],["77554.03000000","0.00000000"],["77553.88000000","0.00000000"],["77553.54000000","0.00000000"],["77553.29000000","0.11799000"],["77553.28000000","0.00000000"],["77553.27000000","0.68286000"],["77553.26000000","0.00000000"],["77552.82000000","0.00328000"],["77552.20000000","0.00329000"],["77551.68000000","0.00000000"],["77551.65000000","0.00000000"],["77551.64000000","0.00007000"],["77551.63000000","0.00120000"],["77551.42000000","0.00000000"],["77551.28000000","0.00008000"],["77551.11000000","0.00000000"],["77550.83000000","0.00000000"],["77550.73000000","0.00040000"],["77550.72000000","0.12894000"],["77550.24000000","0.00644000"],["77549.59000000","0.00000000"],["77549.24000000","0.12550000"],["77548.95000000","0.00022000"],["77548.94000000","0.00335000"],["77548.90000000","0.00000000"],["77548.37000000","0.00000000"],["77548.33000000","0.00644000"],["77548.09000000","0.00000000"],["77547.64000000","0.33003000"],["77547.60000000","0.00000000"],["77547.23000000","0.00000000"],["77546.88000000","0.00000000"],["77546.74000000","0.00000000"],["77546.33000000","0.00400000"],["77546.10000000","0.00000000"],["77546.09000000","0.00000000"],["77545.91000000","0.00000000"],["77545.78000000","0.00587000"],["77545.69000000","0.00000000"],["77545.44000000","0.00000000"],["77545.40000000","0.00008000"],["77545.06000000","0.00328000"],["77545.00000000","0.00000000"],["77544.99000000","0.00000000"],["77544.58000000","0.00000000"],["77544.44000000","0.00337000"],["77544.26000000","0.00134000"],["77544.14000000","1.04306000"],["77543.83000000","0.00012000"],["77543.76000000","0.00000000"],["77543.45000000","0.00060000"],["77543.00000000","0.03867000"],["77542.96000000","0.12896000"],["77542.86000000","0.00000000"],["77542.60000000","0.00000000"],["77542.25000000","0.44241000"],["77541.84000000","0.10000000"],["77541.64000000","0.00000000"],["77541.52000000","0.00136000"],["77541.18000000","0.00328000"],["77541.05000000","0.00000000"],["77540.47000000","0.00257000"],["77540.42000000","0.00000000"],["77540.37000000","0.64592000"],["77539.56000000","0.00000000"],["77539.47000000","0.00000000"],["77538.79000000","0.00000000"],["77538.51000000","0.02000000"],["77538.01000000","0.03315000"],["77537.95000000","0.00000000"],["77537.82000000","0.02514000"],["77537.71000000","0.00000000"],["77537.69000000","0.35473000"],["77537.67000000","0.00000000"],["77537.64000000","0.00008000"],["77537.46000000","0.00000000"],["77537.41000000","0.62878000"],["77537.40000000","0.00000000"],["77537.09000000","0.00000000"],["77536.68000000","0.00331000"],["77536.21000000","0.10428000"],["77535.61000000","0.00000000"],["77535.59000000","0.00000000"],["77535.45000000","0.00000000"],["77535.26000000","0.00014000"],["77535.10000000","0.00000000"],["77534.75000000","0.00000000"],["77534.68000000","0.15000000"],["77534.27000000","0.10428000"],["77534.05000000","0.11274000"],["77533.83000000","1.23933000"],["77533.82000000","1.31471000"],["77533.81000000","0.00000000"],["77533.76000000","0.00008000"],["77533.13000000","0.00000000"],["77533.00000000","0.00000000"],["77532.74000000","0.00000000"],["77532.00000000","0.10775000"],["77531.32000000","0.00014000"],["77531.22000000","0.00000000"],["77531.00000000","0.00000000"],["77529.95000000","0.00000000"],["77529.89000000","0.00008000"],["77529.00000000","0.00000000"],["77528.92000000","0.00328000"],["77528.22000000","0.00400000"],["77528.00000000","0.03000000"],["77527.68000000","0.00007000"],["77527.38000000","0.00014000"],["77526.66000000","0.00000000"],["77526.47000000","0.39244000"],["77526.01000000","0.00008000"],["77526.00000000","0.04000000"],["77525.78000000","1.08411000"],["77525.52000000","0.00000000"],["77525.02000000","0.81615000"],["77524.32000000","0.00000000"],["77524.23000000","0.00200000"],["77523.44000000","0.00007000"],["77522.51000000","0.00000000"],["77522.29000000","0.50391000"],["77521.42000000","0.00000000"],["77519.50000000","0.00007000"],["77518.31000000","0.29247000"],["77518.23000000","0.00000000"],["77516.41000000","0.01131000"],["77514.29000000","0.00000000"],["77514.03000000","0.83784000"],["77513.90000000","0.01148000"],["77513.30000000","0.00000000"],["77513.04000000","0.00618000"],["77512.46000000","0.00436000"],["77511.83000000","0.79629000"],["77510.19000000","0.00435000"],["77508.99000000","0.58740000"],["77507.96000000","0.00427000"],["77506.80000000","0.89576000"],["77500.17000000","0.00000000"],["77500.05000000","1.64002000"],["77499.99000000","0.25000000"],["77499.79000000","0.00000000"],["77499.12000000","0.00008000"],["77498.72000000","0.27435000"],["77498.71000000","0.28993000"],["77498.64000000","0.79642000"],["77498.24000000","0.00000000"],["77497.34000000","0.00212000"],["77496.21000000","0.00639000"],["77495.71000000","0.00000000"],["77495.25000000","0.00000000"],["77493.62000000","1.94571000"],["77493.60000000","0.00000000"],["77492.97000000","0.01706000"],["77492.53000000","0.00110000"],["77491.34000000","0.00536000"],["77490.72000000","0.17903000"],["77488.04000000","0.00412000"],["77487.23000000","0.00008000"],["77476.75000000","0.10418000"],["77474.64000000","0.98487000"],["77471.84000000","0.03699000"],["77466.52000000","0.00000000"],["77465.26000000","0.04526000"],["77463.06000000","0.00000000"],["77462.75000000","1.83737000"],["77461.38000000","0.00000000"],["77459.77000000","0.02538000"],["77444.11000000","1.01193000"],["77444.01000000","0.00000000"],["77434.79000000","0.68650000"],["77434.20000000","0.00000000"],["77433.08000000","0.44663000"],["77432.96000000","0.00000000"],["77423.25000000","0.00128000"],["77423.08000000","0.00000000"],["77421.82000000","0.00000000"],["77417.67000000","0.00000000"],["77416.15000000","0.57709000"],["77414.17000000","0.00128000"],["77412.60000000","3.40351000"],["77410.82000000","0.00000000"],["77409.66000000","0.00008000"],["77408.79000000","0.57046000"],["77398.36000000","2.15634000"],["77386.35000000","0.16870000"],["77382.62000000","0.00000000"],["77358.87000000","0.00007000"],["77355.48000000","0.00000000"],["77355.00000000","0.00007000"],["77350.01000000","0.00007000"],["77346.14000000","0.00007000"],["77340.10000000","0.00000000"],["77335.16000000","3.65097000"],["77332.10000000","0.00008000"],["77301.49000000","0.11476000"],["77262.53000000","0.00000000"],["77254.53000000","0.00008000"],["77184.96000000","0.00000000"],["77176.97000000","0.00008000"],["77107.38000000","0.00060000"],["77099.40000000","0.00008000"],["77029.81000000","0.00000000"],["77021.84000000","0.00008000"],["76952.24000000","0.00000000"],["76944.27000000","0.00008000"],["69814.35000000","0.00000000"],["69808.32000000","0.00000000"],["65932.80000000","0.00085000"],["62072.23000000","0.00000000"],["62054.40000000","0.00054000"]],"a":[["77564.79000000","3.88859000"],["77564.80000000","1.43510000"],["77564.81000000","0.00013000"],["77564.82000000","0.00000000"],["77565.51000000","0.00000000"],["77565.52000000","0.00021000"],["77565.64000000","0.00000000"],["77565.81000000","0.00000000"],["77565.96000000","0.00000000"],["77566.01000000","0.00007000"],["77566.02000000","0.00000000"],["77566.03000000","0.00000000"],["77566.04000000","0.00000000"],["77566.47000000","0.00000000"],["77566.60000000","0.00000000"],["77566.78000000","0.00014000"],["77566.79000000","0.00007000"],["77566.80000000","0.12965000"],["77567.05000000","0.00000000"],["77567.06000000","0.00000000"],["77567.17000000","0.00000000"],["77567.22000000","0.00000000"],["77567.24000000","0.10596000"],["77567.26000000","0.07500000"],["77567.27000000","1.24625000"],["77567.28000000","0.00000000"],["77567.29000000","0.00000000"],["77567.59000000","0.30021000"],["77567.61000000","0.00000000"],["77568.00000000","1.39003000"],["77568.01000000","0.73203000"],["77568.02000000","0.00000000"],["77568.03000000","0.00000000"],["77568.05000000","0.00000000"],["77568.94000000","0.00000000"],["77568.95000000","0.00000000"],["77568.96000000","0.00408000"],["77568.99000000","0.30021000"],["77569.00000000","0.00000000"],["77569.40000000","0.00000000"],["77569.97000000","0.34778000"],["77569.98000000","0.00021000"],["77569.99000000","0.00000000"],["77570.00000000","0.00000000"],["77570.01000000","0.13913000"],["77570.02000000","0.61613000"],["77570.21000000","0.02000000"],["77570.25000000","0.00000000"],["77570.43000000","0.00000000"],["77570.44000000","0.00000000"],["77570.45000000","0.24814000"],["77570.46000000","0.00000000"],["77570.67000000","0.00000000"],["77570.72000000","0.00014000"],["77570.73000000","2.36706000"],["77570.74000000","0.00000000"],["77570.75000000","0.00000000"],["77570.85000000","0.00000000"],["77570.90000000","0.00400000"],["77570.91000000","0.44126000"],["77570.92000000","0.00000000"],["77571.10000000","0.00000000"],["77571.11000000","0.00007000"],["77571.48000000","0.00032000"],["77571.50000000","0.00000000"],["77571.51000000","1.02859000"],["77571.52000000","0.16884000"],["77571.53000000","0.00000000"],["77571.55000000","0.09622000"],["77571.56000000","0.00007000"],["77571.76000000","1.93226000"],["77571.77000000","1.11024000"],["77571.78000000","0.00000000"],["77571.79000000","0.00000000"],["77572.40000000","0.00117000"],["77572.81000000","0.00000000"],["77572.82000000","0.00000000"],["77572.83000000","0.16870000"],["77572.90000000","0.00000000"],["77572.91000000","1.31471000"],["77572.92000000","0.00329000"],["77572.94000000","0.00000000"],["77573.11000000","0.00000000"],["77573.28000000","0.00008000"],["77573.34000000","0.00007000"],["77573.49000000","0.00027000"],["77573.59000000","0.00000000"],["77573.77000000","0.00007000"],["77573.99000000","0.00000000"],["77574.00000000","0.00000000"],["77574.01000000","0.00007000"],["77574.03000000","0.38689000"],["77574.38000000","0.00007000"],["77574.47000000","0.00007000"],["77574.78000000","0.00400000"],["77574.87000000","0.23214000"],["77574.88000000","0.12430000"],["77575.08000000","0.00000000"],["77575.20000000","0.00007000"],["77575.21000000","0.00000000"],["77575.58000000","0.14483000"],["77575.77000000","0.00000000"],["77575.87000000","0.00000000"],["77575.93000000","0.00000000"],["77575.98000000","0.54505000"],["77575.99000000","0.02900000"],["77576.00000000","0.00007000"],["77576.44000000","0.00007000"],["77576.55000000","0.00000000"],["77576.56000000","0.00000000"],["77576.57000000","0.00000000"],["77576.72000000","0.00408000"],["77576.73000000","0.82009000"],["77576.74000000","0.00000000"],["77576.75000000","0.00327000"],["77576.76000000","0.00000000"],["77576.86000000","0.00000000"],["77576.87000000","0.00000000"],["77577.22000000","0.00322000"],["77577.33000000","0.00116000"],["77577.37000000","1.93226000"],["77577.38000000","0.00000000"],["77577.40000000","0.00000000"],["77577.68000000","0.00000000"],["77577.76000000","0.64498000"],["77577.77000000","0.12890000"],["77578.01000000","0.00000000"],["77578.03000000","0.00000000"],["77578.17000000","0.00000000"],["77578.22000000","0.34778000"],["77578.42000000","0.00000000"],["77578.49000000","0.00029000"],["77578.63000000","0.00010000"],["77578.76000000","0.00328000"],["77579.37000000","0.00200000"],["77579.53000000","0.00000000"],["77579.69000000","0.00007000"],["77579.70000000","0.00000000"],["77579.71000000","0.00000000"],["77579.77000000","0.00118000"],["77580.43000000","0.00000000"],["77580.60000000","0.00432000"],["77580.61000000","0.00032000"],["77580.88000000","0.10422000"],["77581.02000000","0.00007000"],["77581.03000000","0.00008000"],["77581.11000000","0.38686000"],["77581.12000000","0.00000000"],["77581.13000000","0.00000000"],["77581.14000000","0.00032000"],["77581.31000000","0.00032000"],["77581.32000000","0.65120000"],["77581.92000000","0.00000000"],["77581.97000000","0.00000000"],["77582.18000000","0.00000000"],["77582.64000000","0.00336000"],["77582.82000000","0.10422000"],["77583.56000000","0.00007000"],["77583.83000000","0.00000000"],["77584.00000000","0.00014000"],["77584.51000000","0.00340000"],["77584.91000000","0.00008000"],["77585.09000000","0.00000000"],["77585.53000000","0.00000000"],["77585.57000000","1.24008000"],["77585.74000000","0.00000000"],["77586.25000000","0.00029000"],["77586.42000000","0.00400000"],["77587.44000000","0.00007000"],["77587.62000000","0.34814000"],["77588.79000000","0.00008000"],["77589.37000000","0.00000000"],["77589.41000000","0.00000000"],["77589.47000000","0.00000000"],["77589.48000000","0.52630000"],["77589.88000000","0.00000000"],["77590.15000000","0.00000000"],["77590.28000000","0.38681000"],["77590.29000000","0.00038000"],["77590.30000000","0.20817000"],["77590.34000000","0.00000000"],["77590.39000000","0.00000000"],["77591.22000000","0.00000000"],["77591.58000000","0.00000000"],["77591.61000000","0.00000000"],["77591.99000000","0.00000000"],["77592.00000000","0.00273000"],["77592.32000000","0.00000000"],["77592.67000000","0.00008000"],["77592.83000000","0.00000000"],["77593.26000000","0.00000000"],["77593.40000000","0.00000000"],["77593.64000000","0.00400000"],["77593.80000000","0.00000000"],["77593.84000000","0.00060000"],["77594.01000000","0.00029000"],["77594.07000000","0.00010000"],["77594.10000000","0.00400000"],["77594.18000000","0.00400000"],["77594.26000000","0.00000000"],["77594.51000000","0.00007000"],["77595.31000000","0.00000000"],["77595.39000000","0.00190000"],["77595.91000000","0.00012000"],["77596.10000000","0.78456000"],["77596.55000000","0.00008000"],["77596.75000000","0.00000000"],["77597.69000000","0.00007000"],["77597.88000000","0.00000000"],["77598.06000000","0.17270000"],["77598.15000000","0.00000000"],["77598.45000000","0.00000000"],["77598.51000000","0.00000000"],["77598.90000000","0.00000000"],["77599.45000000","0.00000000"],["77600.00000000","0.09664000"],["77600.25000000","0.00000000"],["77600.42000000","0.00008000"],["77600.74000000","0.00000000"],["77601.05000000","0.00000000"],["77601.11000000","0.10190000"],["77601.34000000","0.79537000"],["77601.76000000","0.00037000"],["77601.93000000","0.00000000"],["77601.94000000","0.00000000"],["77602.65000000","0.00000000"],["77604.30000000","0.00008000"],["77604.38000000","0.00000000"],["77604.39000000","0.00000000"],["77605.04000000","0.00000000"],["77605.07000000","0.00000000"],["77605.35000000","0.24634000"],["77605.82000000","0.00000000"],["77606.18000000","0.00000000"],["77607.37000000","0.35943000"],["77608.00000000","0.03007000"],["77608.04000000","0.00618000"],["77608.72000000","0.00430000"],["77608.90000000","0.00290000"],["77609.70000000","0.00000000"],["77609.79000000","0.00000000"],["77610.12000000","0.00000000"],["77610.40000000","0.00426000"],["77611.00000000","0.01000000"],["77611.06000000","0.03867000"],["77612.49000000","0.00000000"],["77613.17000000","0.00007000"],["77613.29000000","0.00431000"],["77613.58000000","0.00000000"],["77613.67000000","0.00000000"],["77614.53000000","0.79523000"],["77616.27000000","0.06573000"],["77617.38000000","1.27605000"],["77618.20000000","0.00000000"],["77621.34000000","0.00000000"],["77624.07000000","0.00322000"],["77624.52000000","0.00000000"],["77625.00000000","0.00000000"],["77625.03000000","0.00000000"],["77625.68000000","0.00000000"],["77625.88000000","0.00000000"],["77627.71000000","0.79510000"],["77630.00000000","0.03000000"],["77631.38000000","0.00539000"],["77632.98000000","0.01706000"],["77633.46000000","0.00111000"],["77633.55000000","0.00000000"],["77635.29000000","0.01138000"],["77638.85000000","3.47658000"],["77640.30000000","0.25000000"],["77641.15000000","0.09192000"],["77641.16000000","0.00000000"],["77642.36000000","0.00008000"],["77648.02000000","0.00000000"],["77650.49000000","0.00000000"],["77653.19000000","0.00000000"],["77654.19000000","0.00000000"],["77658.79000000","0.00000000"],["77660.01000000","0.00000000"],["77661.72000000","0.00000000"],["77672.41000000","0.00000000"],["77673.99000000","0.02305000"],["77677.98000000","0.00000000"],["77677.99000000","0.02764000"],["77683.46000000","0.06559000"],["77686.70000000","0.00007000"],["77693.65000000","0.06845000"],["77701.99000000","0.49518000"],["77704.52000000","0.00000000"],["77706.87000000","0.00000000"],["77711.62000000","0.00000000"],["77717.38000000","1.00823000"],["77717.87000000","2.62212000"],["77733.03000000","0.00000000"],["77735.88000000","1.30089000"],["77735.96000000","3.86093000"],["77797.67000000","0.00000000"],["77799.78000000","0.00000000"],["77803.65000000","0.00000000"],["77805.63000000","0.00000000"],["77807.18000000","0.02749000"],["77807.64000000","0.00000000"],["77809.21000000","0.01928000"],["77812.31000000","0.01896000"],["77813.24000000","0.01891000"],["77824.18000000","0.00036000"],["77834.90000000","0.02381000"],["77835.28000000","0.07595000"],["77836.22000000","0.00489000"],["77863.57000000","0.00000000"],["77863.79000000","0.00009000"],["77867.68000000","0.00000000"],["77867.94000000","0.00000000"],["77891.88000000","0.00000000"],["77891.95000000","0.00000000"],["77892.45000000","0.00000000"],["77926.61000000","0.00000000"],["77952.62000000","0.00008000"],["77952.98000000","0.00000000"],["77960.78000000","0.00000000"],["77971.85000000","0.00000000"],["78030.19000000","0.00008000"],["78038.36000000","0.00000000"],["78107.75000000","0.00008000"],["78115.93000000","0.00000000"],["78185.32000000","0.00008000"],["78193.50000000","0.00000000"],["81458.43000000","0.00010000"],["86422.88000000","0.22692000"]]}}
{"type":"trade","received_at_ms":1788331890034,"data":{"e":"trade","E":1788331890174,"s":"BTCUSDT","t":6646634832,"p":"77564.78000000","q":"0.00007000","T":1788331890174,"m":true,"M":true}}
{"type":"trade","received_at_ms":1788331890034,"data":{"e":"trade","E":1788331890174,"s":"BTCUSDT","t":6646634833,"p":"77564.78000000","q":"0.00007000","T":1788331890174,"m":true,"M":true}}
{"type":"trade","received_at_ms":1788331890034,"data":{"e":"trade","E":1788331890174,"s":"BTCUSDT","t":6646634834,"p":"77564.78000000","q":"0.00007000","T":1788331890174,"m":true,"M":true}}
{"type":"trade","received_at_ms":1788331890034,"data":{"e":"trade","E":1788331890174,"s":"BTCUSDT","t":6646634835,"p":"77564.78000000","q":"0.00007000","T":1788331890174,"m":true,"M":true}}
{"type":"trade","received_at_ms":1788331890034,"data":{"e":"trade","E":1788331890174,"s":"BTCUSDT","t":6646634836,"p":"77564.78000000","q":"0.00200000","T":1788331890174,"m":true,"M":true}}
{"type":"trade","received_at_ms":1788331890034,"data":{"e":"trade","E":1788331890174,"s":"BTCUSDT","t":6646634837,"p":"77564.78000000","q":"0.00007000","T":1788331890174,"m":true,"M":true}}
{"type":"trade","received_at_ms":1788331890034,"data":{"e":"trade","E":1788331890174,"s":"BTCUSDT","t":6646634838,"p":"77564.78000000","q":"0.00007000","T":1788331890174,"m":true,"M":true}}
{"type":"trade","received_at_ms":1788331890034,"data":{"e":"trade","E":1788331890174,"s":"BTCUSDT","t":6646634839,"p":"77564.78000000","q":"0.00007000","T":1788331890174,"m":true,"M":true}}
{"type":"trade","received_at_ms":1788331890034,"data":{"e":"trade","E":1788331890174,"s":"BTCUSDT","t":6646634840,"p":"77564.78000000","q":"0.00007000","T":1788331890174,"m":true,"M":true}}
{"type":"trade","received_at_ms":1788331890034,"data":{"e":"trade","E":1788331890174,"s":"BTCUSDT","t":6646634841,"p":"77564.78000000","q":"0.00007000","T":1788331890174,"m":true,"M":true}}
{"type":"trade","received_at_ms":1788331890034,"data":{"e":"trade","E":1788331890174,"s":"BTCUSDT","t":6646634842,"p":"77564.78000000","q":"0.00007000","T":1788331890174,"m":true,"M":true}}
{"type":"trade","received_at_ms":1788331890034,"data":{"e":"trade","E":1788331890174,"s":"BTCUSDT","t":6646634843,"p":"77564.78000000","q":"0.00007000","T":1788331890174,"m":true,"M":true}}
{"type":"trade","received_at_ms":1788331890034,"data":{"e":"trade","E":1788331890174,"s":"BTCUSDT","t":6646634844,"p":"77564.78000000","q":"0.00007000","T":1788331890174,"m":true,"M":true}}
{"type":"trade","received_at_ms":1788331890034,"data":{"e":"trade","E":1788331890174,"s":"BTCUSDT","t":6646634845,"p":"77564.78000000","q":"0.00007000","T":1788331890174,"m":true,"M":true}}
{"type":"trade","received_at_ms":1788331890034,"data":{"e":"trade","E":1788331890174,"s":"BTCUSDT","t":6646634846,"p":"77564.78000000","q":"0.00007000","T":1788331890174,"m":true,"M":true}}
{"type":"trade","received_at_ms":1788331890034,"data":{"e":"trade","E":1788331890174,"s":"BTCUSDT","t":6646634847,"p":"77564.78000000","q":"0.00007000","T":1788331890174,"m":true,"M":true}}
{"type":"trade","received_at_ms":1788331890034,"data":{"e":"trade","E":1788331890174,"s":"BTCUSDT","t":6646634848,"p":"77564.78000000","q":"0.00007000","T":1788331890174,"m":true,"M":true}}
{"type":"trade","received_at_ms":1788331890034,"data":{"e":"trade","E":1788331890174,"s":"BTCUSDT","t":6646634849,"p":"77564.78000000","q":"0.00007000","T":1788331890174,"m":true,"M":true}}
{"type":"trade","received_at_ms":1788331890034,"data":{"e":"trade","E":1788331890174,"s":"BTCUSDT","t":6646634850,"p":"77564.78000000","q":"0.00007000","T":1788331890174,"m":true,"M":true}}
{"type":"trade","received_at_ms":1788331890034,"data":{"e":"trade","E":1788331890174,"s":"BTCUSDT","t":6646634851,"p":"77564.78000000","q":"0.00007000","T":1788331890174,"m":true,"M":true}}
{"type":"trade","received_at_ms":1788331890035,"data":{"e":"trade","E":1788331890174,"s":"BTCUSDT","t":6646634852,"p":"77564.78000000","q":"0.00007000","T":1788331890174,"m":true,"M":true}}
{"type":"trade","received_at_ms":1788331890035,"data":{"e":"trade","E":1788331890174,"s":"BTCUSDT","t":6646634853,"p":"77564.78000000","q":"0.00043000","T":1788331890174,"m":true,"M":true}}
{"type":"trade","received_at_ms":1788331890060,"data":{"e":"trade","E":1788331890201,"s":"BTCUSDT","t":6646634854,"p":"77564.78000000","q":"0.00326000","T":1788331890200,"m":true,"M":true}}
{"type":"depth","received_at_ms":1788331890073,"data":{"e":"depthUpdate","E":1788331890214,"s":"BTCUSDT","U":99555831419,"u":99555831880,"b":[["77564.78000000","0.36359000"],["77564.77000000","0.00063000"],["77564.31000000","0.00007000"],["77564.02000000","0.00000000"],["77564.01000000","0.00014000"],["77564.00000000","0.03021000"],["77563.58000000","0.00000000"],["77563.57000000","0.00000000"],["77562.00000000","0.03021000"],["77561.20000000","0.00000000"],["77561.00000000","0.00550000"],["77560.38000000","0.09889000"],["77560.37000000","0.11497000"],["77560.36000000","0.00014000"],["77560.01000000","0.00014000"],["77560.00000000","0.03035000"],["77559.26000000","0.00000000"],["77559.00000000","0.00000000"],["77558.90000000","0.00007000"],["77558.89000000","0.02922000"],["77558.78000000","0.11722000"],["77558.74000000","0.11806000"],["77558.32000000","0.00000000"],["77558.00000000","0.03035000"],["77557.92000000","0.00000000"],["77557.25000000","0.00027000"],["77557.24000000","0.11384000"],["77555.19000000","0.00000000"],["77554.48000000","0.00000000"],["77554.07000000","0.00000000"],["77553.59000000","0.00000000"],["77553.27000000","1.05465000"],["77552.82000000","0.00000000"],["77552.51000000","0.00333000"],["77551.70000000","0.00000000"],["77551.69000000","0.11799000"],["77551.68000000","1.93226000"],["77551.02000000","0.00007000"],["77550.59000000","0.00023000"],["77550.42000000","0.00012000"],["77548.95000000","0.00000000"],["77547.87000000","0.00000000"],["77547.08000000","0.00014000"],["77546.68000000","0.00000000"],["77546.11000000","0.00257000"],["77545.38000000","0.00000000"],["77545.15000000","0.00000000"],["77544.16000000","0.00000000"],["77544.15000000","0.07775000"],["77544.00000000","0.03007000"],["77543.32000000","0.00190000"],["77543.14000000","0.00014000"],["77542.25000000","0.00000000"],["77540.53000000","0.53915000"],["77539.77000000","0.00000000"],["77539.20000000","0.00014000"],["77537.82000000","0.00000000"],["77537.45000000","0.00000000"],["77536.89000000","0.00124000"],["77536.12000000","0.02000000"],["77535.89000000","0.44245000"],["77534.68000000","0.00000000"],["77533.81000000","0.00000000"],["77533.54000000","0.00000000"],["77532.88000000","0.04000000"],["77532.68000000","0.03000000"],["77531.31000000","0.09868000"],["77530.28000000","0.08000000"],["77527.51000000","0.04593000"],["77526.28000000","0.00400000"],["77526.00000000","0.03000000"],["77525.00000000","0.01000000"],["77524.34000000","0.00400000"],["77522.16000000","0.64526000"],["77521.63000000","0.00000000"],["77515.56000000","0.00007000"],["77515.26000000","1.06833000"],["77514.87000000","0.33889000"],["77513.04000000","0.00000000"],["77512.46000000","0.00000000"],["77510.41000000","0.54638000"],["77510.18000000","0.00000000"],["77502.02000000","0.00624000"],["77500.16000000","0.00000000"],["77499.79000000","0.00000000"],["77498.01000000","0.00000000"],["77496.21000000","0.00000000"],["77496.20000000","0.00000000"],["77493.62000000","0.97535000"],["77493.59000000","0.00000000"],["77483.53000000","1.56422000"],["77480.70000000","2.26031000"],["77474.91000000","0.04498000"],["77474.63000000","0.00000000"],["77473.22000000","0.12782000"],["77459.77000000","0.00000000"],["77459.71000000","0.00000000"],["77450.19000000","0.05871000"],["77448.01000000","0.00012000"],["77445.96000000","0.00000000"],["77444.55000000","0.00011000"],["77430.33000000","0.00000000"],["77423.25000000","0.00000000"],["77421.82000000","0.00000000"],["77419.58000000","0.00671000"],["77414.17000000","0.00000000"],["77412.60000000","2.24618000"],["77344.00000000","0.00007000"],["77342.26000000","0.00007000"],["77338.39000000","0.00007000"],["77164.78000000","0.00007000"],["76891.98000000","0.00022000"],["69808.31000000","0.00016000"],["62057.41000000","0.00000000"],["59390.99000000","0.00013000"]],"a":[["77564.79000000","5.18974000"],["77564.80000000","1.46012000"],["77565.03000000","0.00121000"],["77565.08000000","0.00400000"],["77565.51000000","0.00000000"],["77565.52000000","0.00007000"],["77565.95000000","0.00000000"],["77566.00000000","0.00000000"],["77566.04000000","0.01765000"],["77566.79000000","0.00421000"],["77566.80000000","0.12979000"],["77566.82000000","0.00340000"],["77567.02000000","0.00400000"],["77567.23000000","0.00014000"],["77567.24000000","0.10610000"],["77567.26000000","0.07535000"],["77567.27000000","0.83363000"],["77567.28000000","0.02118000"],["77567.58000000","0.00007000"],["77567.59000000","0.30021000"],["77568.00000000","1.69017000"],["77568.01000000","0.73210000"],["77568.37000000","0.00335000"],["77568.52000000","0.02118000"],["77568.99000000","0.00007000"],["77569.96000000","0.34904000"],["77569.97000000","0.00000000"],["77569.98000000","0.00007000"],["77570.01000000","0.13899000"],["77570.02000000","0.31606000"],["77570.21000000","0.00000000"],["77570.47000000","0.00341000"],["77570.73000000","2.19836000"],["77570.91000000","0.68933000"],["77571.51000000","0.78052000"],["77571.52000000","0.41691000"],["77571.75000000","0.00000000"],["77571.77000000","0.69762000"],["77572.87000000","0.00000000"],["77573.77000000","0.00000000"],["77574.01000000","0.00000000"],["77574.02000000","0.36975000"],["77574.14000000","0.00000000"],["77574.38000000","0.00000000"],["77574.39000000","0.00000000"],["77574.87000000","0.00000000"],["77575.87000000","0.00000000"],["77578.22000000","0.00000000"],["77579.59000000","0.34778000"],["77584.70000000","0.00125000"],["77585.55000000","0.00000000"],["77585.59000000","0.00650000"],["77587.14000000","0.00117000"],["77587.60000000","0.00000000"],["77589.48000000","0.34746000"],["77589.49000000","0.00000000"],["77589.65000000","0.00000000"],["77590.93000000","0.04642000"],["77592.00000000","0.00015000"],["77593.64000000","0.00000000"],["77594.10000000","0.00000000"],["77596.12000000","0.00000000"],["77596.80000000","0.00000000"],["77596.95000000","0.00619000"],["77597.15000000","0.00425000"],["77598.06000000","0.16870000"],["77601.11000000","0.00000000"],["77601.79000000","0.00439000"],["77603.17000000","0.33003000"],["77604.00000000","0.04000000"],["77606.30000000","0.02565000"],["77608.04000000","0.00000000"],["77608.72000000","0.00000000"],["77611.00000000","0.00000000"],["77611.19000000","0.00000000"],["77613.29000000","0.00000000"],["77614.21000000","0.00000000"],["77615.41000000","0.00000000"],["77623.37000000","1.06956000"],["77626.84000000","0.00000000"],["77638.84000000","1.74883000"],["77638.99000000","0.00000000"],["77641.95000000","2.39503000"],["77643.96000000","0.00000000"],["77647.15000000","1.32774000"],["77647.20000000","0.00000000"],["77651.99000000","0.01795000"],["77656.44000000","0.00000000"],["77665.99000000","0.03966000"],["77667.60000000","0.00000000"],["77668.63000000","0.00000000"],["77671.41000000","1.12697000"],["77673.61000000","0.00000000"],["77673.77000000","0.03681000"],["77673.78000000","0.04608000"],["77673.99000000","0.00000000"],["77686.50000000","0.00000000"],["77700.68000000","0.00000000"],["77707.70000000","0.00971000"],["77729.05000000","0.00000000"]]}}
{"type":"trade","received_at_ms":1788331890161,"data":{"e":"trade","E":1788331890299,"s":"BTCUSDT","t":6646634855,"p":"77564.78000000","q":"0.00008000","T":1788331890298,"m":true,"M":true}}
{"type":"trade","received_at_ms":1788331890161,"data":{"e":"trade","E":1788331890299,"s":"BTCUSDT","t":6646634856,"p":"77564.78000000","q":"0.00007000","T":1788331890298,"m":true,"M":true}}
{"type":"trade","received_at_ms":1788331890161,"data":{"e":"trade","E":1788331890299,"s":"BTCUSDT","t":6646634857,"p":"77564.78000000","q":"0.00007000","T":1788331890298,"m":true,"M":true}}
{"type":"trade","received_at_ms":1788331890161,"data":{"e":"trade","E":1788331890299,"s":"BTCUSDT","t":6646634858,"p":"77564.78000000","q":"0.00007000","T":1788331890298,"m":true,"M":true}}
{"type":"trade","received_at_ms":1788331890161,"data":{"e":"trade","E":1788331890299,"s":"BTCUSDT","t":6646634859,"p":"77564.78000000","q":"0.00007000","T":1788331890298,"m":true,"M":true}}
{"type":"trade","received_at_ms":1788331890161,"data":{"e":"trade","E":1788331890299,"s":"BTCUSDT","t":6646634860,"p":"77564.78000000","q":"0.00007000","T":1788331890298,"m":true,"M":true}}
{"type":"trade","received_at_ms":1788331890161,"data":{"e":"trade","E":1788331890299,"s":"BTCUSDT","t":6646634861,"p":"77564.78000000","q":"0.00007000","T":1788331890298,"m":true,"M":true}}
{"type":"trade","received_at_ms":1788331890161,"data":{"e":"trade","E":1788331890299,"s":"BTCUSDT","t":6646634862,"p":"77564.78000000","q":"0.00007000","T":1788331890298,"m":true,"M":true}}
{"type":"trade","received_at_ms":1788331890161,"data":{"e":"trade","E":1788331890299,"s":"BTCUSDT","t":6646634863,"p":"77564.78000000","q":"0.00007000","T":1788331890298,"m":true,"M":true}}
{"type":"trade","received_at_ms":1788331890161,"data":{"e":"trade","E":1788331890299,"s":"BTCUSDT","t":6646634864,"p":"77564.78000000","q":"0.00007000","T":1788331890298,"m":true,"M":true}}
{"type":"trade","received_at_ms":1788331890161,"data":{"e":"trade","E":1788331890299,"s":"BTCUSDT","t":6646634865,"p":"77564.78000000","q":"0.00007000","T":1788331890298,"m":true,"M":true}}
{"type":"trade","received_at_ms":1788331890161,"data":{"e":"trade","E":1788331890299,"s":"BTCUSDT","t":6646634866,"p":"77564.78000000","q":"0.00007000","T":1788331890298,"m":true,"M":true}}
{"type":"trade","received_at_ms":1788331890161,"data":{"e":"trade","E":1788331890299,"s":"BTCUSDT","t":6646634867,"p":"77564.78000000","q":"0.00007000","T":1788331890298,"m":true,"M":true}}
{"type":"trade","received_at_ms":1788331890161,"data":{"e":"trade","E":1788331890299,"s":"BTCUSDT","t":6646634868,"p":"77564.78000000","q":"0.00007000","T":1788331890298,"m":true,"M":true}}
{"type":"trade","received_at_ms":1788331890161,"data":{"e":"trade","E":1788331890299,"s":"BTCUSDT","t":6646634869,"p":"77564.78000000","q":"0.00007000","T":1788331890298,"m":true,"M":true}}
{"type":"trade","received_at_ms":1788331890161,"data":{"e":"trade","E":1788331890299,"s":"BTCUSDT","t":6646634870,"p":"77564.78000000","q":"0.00007000","T":1788331890298,"m":true,"M":true}}
{"type":"trade","received_at_ms":1788331890161,"data":{"e":"trade","E":1788331890299,"s":"BTCUSDT","t":6646634871,"p":"77564.78000000","q":"0.00400000","T":1788331890298,"m":true,"M":true}}
{"type":"trade","received_at_ms":1788331890161,"data":{"e":"trade","E":1788331890299,"s":"BTCUSDT","t":6646634872,"p":"77564.78000000","q":"0.02000000","T":1788331890298,"m":true,"M":true}}
{"type":"trade","received_at_ms":1788331890161,"data":{"e":"trade","E":1788331890299,"s":"BTCUSDT","t":6646634873,"p":"77564.78000000","q":"0.00710000","T":1788331890298,"m":true,"M":true}}
{"type":"trade","received_at_ms":1788331890161,"data":{"e":"trade","E":1788331890299,"s":"BTCUSDT","t":6646634874,"p":"77564.78000000","q":"0.02000000","T":1788331890298,"m":true,"M":true}}
{"type":"depth","received_at_ms":1788331890182,"data":{"e":"depthUpdate","E":1788331890314,"s":"BTCUSDT","U":99555831881,"u":99555832084,"b":[["77564.78000000","0.80295000"],["77564.77000000","0.00077000"],["77564.01000000","0.00014000"],["77561.00000000","0.00550000"],["77560.43000000","0.00018000"],["77560.39000000","0.00014000"],["77560.38000000","0.09903000"],["77560.37000000","0.11497000"],["77560.36000000","0.00000000"],["77559.85000000","0.00487000"],["77558.89000000","0.02929000"],["77558.78000000","0.11736000"],["77558.74000000","0.00014000"],["77558.60000000","0.00812000"],["77558.00000000","0.03028000"],["77557.42000000","0.00116000"],["77557.36000000","0.00975000"],["77557.32000000","0.00000000"],["77557.24000000","0.11370000"],["77556.52000000","0.10879000"],["77556.12000000","0.00975000"],["77555.38000000","0.00000000"],["77554.53000000","0.00007000"],["77554.43000000","0.00208000"],["77553.44000000","0.00015000"],["77552.97000000","0.00040000"],["77551.69000000","0.00000000"],["77551.02000000","0.00014000"],["77550.73000000","0.00000000"],["77550.58000000","0.00407000"],["77550.05000000","0.00125000"],["77549.27000000","0.00008000"],["77547.24000000","0.00000000"],["77547.20000000","0.00000000"],["77546.11000000","0.00000000"],["77545.41000000","0.00400000"],["77543.83000000","0.00000000"],["77537.05000000","0.00000000"],["77536.91000000","0.01987000"],["77533.41000000","0.00000000"],["77533.26000000","0.05349000"],["77530.97000000","0.00012000"],["77522.40000000","0.00415000"],["77520.46000000","0.00400000"],["77518.52000000","0.00400000"],["77518.31000000","0.67515000"],["77513.15000000","1.30043000"],["77512.11000000","0.00007000"],["77511.64000000","0.00000000"],["77511.03000000","0.00670000"],["77510.19000000","0.00000000"],["77505.61000000","0.02000000"],["77501.80000000","0.00436000"],["77499.79000000","0.00322000"],["77497.68000000","0.00433000"],["77494.23000000","0.06620000"],["77494.14000000","0.00322000"],["77493.63000000","0.00322000"],["77474.64000000","1.85276000"],["77474.39000000","3.25269000"],["77472.45000000","0.00007000"],["77456.94000000","0.00007000"],["77449.69000000","0.00000000"],["77441.43000000","0.00007000"],["77435.84000000","0.00008000"],["77425.92000000","0.00007000"],["77421.82000000","0.00128000"],["77416.16000000","0.00128000"],["77414.17000000","0.00128000"],["77410.41000000","0.00007000"],["77394.90000000","0.00007000"],["77379.39000000","0.00007000"],["77363.88000000","0.00007000"],["77348.37000000","0.00007000"],["69808.31000000","0.00032000"],["69808.30000000","0.00009000"],["69808.00000000","0.09281000"],["62072.00000000","0.15357000"],["62052.00000000","0.02806000"]],"a":[["77564.79000000","5.32264000"],["77564.80000000","1.29142000"],["77565.95000000","0.00007000"],["77566.00000000","0.00000000"],["77566.04000000","0.01779000"],["77567.00000000","0.05000000"],["77567.05000000","0.05000000"],["77567.23000000","0.00414000"],["77567.25000000","0.00014000"],["77567.27000000","0.83363000"],["77567.28000000","0.02132000"],["77567.58000000","0.00000000"],["77568.00000000","1.69003000"],["77568.01000000","0.56326000"],["77568.52000000","0.02125000"],["77570.02000000","0.14736000"],["77571.51000000","0.77897000"],["77571.77000000","0.69068000"],["77581.31000000","0.00000000"],["77583.10000000","0.00008000"],["77583.58000000","0.03000000"],["77583.86000000","0.00000000"],["77585.59000000","0.00331000"],["77586.58000000","0.01282000"],["77588.29000000","0.00000000"],["77589.16000000","0.73526000"],["77589.17000000","1.29916000"],["77589.48000000","0.00000000"],["77596.66000000","0.00000000"],["77600.74000000","0.00424000"],["77606.67000000","0.00000000"],["77607.10000000","0.00412000"],["77610.40000000","0.00000000"],["77627.60000000","2.11504000"],["77627.96000000","3.29626000"],["77648.00000000","0.03000000"],["77667.95000000","0.00025000"],["77685.95000000","0.00012000"],["77688.31000000","1.27510000"],["77693.06000000","0.00032000"],["77791.02000000","0.00000000"],["84202.54000000","0.01768000"]]}}
{"type":"depth","received_at_ms":1788331890273,"data":{"e":"depthUpdate","E":1788331890414,"s":"BTCUSDT","U":99555832085,"u":99555832158,"b":[["77564.78000000","0.82288000"],["77564.77000000","0.00070000"],["77558.78000000","0.11736000"],["77553.71000000","0.09904000"],["77551.69000000","0.34778000"],["77546.11000000","0.00257000"],["77545.41000000","0.00800000"],["77542.68000000","0.00119000"],["77536.91000000","0.00000000"],["77536.00000000","0.03265000"],["77535.31000000","0.00121000"],["77533.26000000","0.00000000"],["77520.75000000","0.00212000"],["77513.15000000","0.00000000"],["77512.43000000","0.00000000"],["77511.95000000","0.00000000"],["77511.62000000","0.64535000"],["77497.34000000","0.00000000"],["77492.71000000","1.27810000"],["77486.74000000","0.49605000"],["77484.96000000","1.27823000"],["77474.91000000","0.00000000"],["77471.52000000","0.00000000"],["77378.67000000","0.00000000"],["77359.17000000","0.00813000"],["77351.91000000","3.88010000"],["69808.31000000","0.00048000"],["69808.00000000","0.09261000"],["62052.00000000","0.02806000"]],"a":[["77564.79000000","5.32783000"],["77564.80000000","1.34342000"],["77565.95000000","0.00000000"],["77566.80000000","0.12986000"],["77567.00000000","0.00021000"],["77567.05000000","0.00021000"],["77567.23000000","0.00814000"],["77567.28000000","0.02118000"],["77567.59000000","0.30007000"],["77570.72000000","1.47335000"],["77570.91000000","0.52063000"],["77571.52000000","0.24821000"],["77571.77000000","0.69061000"],["77572.83000000","0.00000000"],["77572.90000000","0.76326000"],["77574.02000000","0.00000000"],["77577.36000000","0.00008000"],["77581.14000000","0.00000000"],["77590.30000000","0.20807000"],["77596.14000000","0.65333000"],["77597.04000000","0.12782000"],["77624.21000000","0.05488000"],["77707.70000000","0.00000000"]]}}
{"type":"depth","received_at_ms":1788331890373,"data":{"e":"depthUpdate","E":1788331890514,"s":"BTCUSDT","U":99555832159,"u":99555832283,"b":[["77564.78000000","0.84991000"],["77564.77000000","0.00063000"],["77561.00000000","0.00557000"],["77560.43000000","0.00000000"],["77560.39000000","0.00000000"],["77560.38000000","0.00014000"],["77560.37000000","0.00014000"],["77560.02000000","0.00000000"],["77560.01000000","0.00014000"],["77558.90000000","0.00021000"],["77558.78000000","0.11736000"],["77558.01000000","0.00007000"],["77558.00000000","0.03021000"],["77557.85000000","0.00412000"],["77557.36000000","0.00982000"],["77557.28000000","0.11722000"],["77557.24000000","0.00000000"],["77556.52000000","0.00014000"],["77555.78000000","0.10872000"],["77552.51000000","0.00000000"],["77551.87000000","0.00400000"],["77551.69000000","0.00000000"],["77551.65000000","0.00000000"],["77550.58000000","0.00007000"],["77546.83000000","0.00000000"],["77546.12000000","0.00800000"],["77546.11000000","0.00000000"],["77546.01000000","0.00000000"],["77545.69000000","0.00000000"],["77545.41000000","0.00000000"],["77544.14000000","1.03906000"],["77543.45000000","0.00000000"],["77543.32000000","0.00000000"],["77533.55000000","0.02051000"],["77531.31000000","0.00000000"],["77530.08000000","0.00066000"],["77529.82000000","0.00190000"],["77516.74000000","0.05395000"],["77507.96000000","0.00000000"],["77495.89000000","0.00431000"],["77471.84000000","0.00000000"],["77471.83000000","0.00000000"],["77470.59000000","0.02397000"],["77465.18000000","0.03999000"],["77451.71000000","0.00000000"],["77450.85000000","0.04636000"],["77419.80000000","0.01581000"],["77417.71000000","0.02020000"],["69808.31000000","0.00080000"],["62051.83000000","0.00032000"]],"a":[["77564.79000000","5.32800000"],["77564.80000000","1.34142000"],["77566.79000000","0.00407000"],["77566.80000000","0.12986000"],["77567.00000000","0.00007000"],["77567.05000000","0.00007000"],["77567.23000000","0.00814000"],["77567.25000000","0.00000000"],["77567.26000000","0.07521000"],["77567.28000000","0.02132000"],["77570.73000000","2.19805000"],["77572.55000000","0.00029000"],["77578.49000000","0.00000000"],["77582.42000000","0.00190000"],["77582.58000000","0.00012000"],["77586.25000000","0.00000000"],["77593.54000000","0.00000000"],["77594.01000000","0.00000000"],["77595.39000000","0.00000000"],["77595.91000000","0.00000000"],["77601.76000000","0.00008000"],["77602.54000000","0.01159000"],["77623.68000000","0.00000000"],["77697.94000000","0.00978000"]]}}
{"type":"depth","received_at_ms":1788331890473,"data":{"e":"depthUpdate","E":1788331890614,"s":"BTCUSDT","U":99555832284,"u":99555832412,"b":[["77564.78000000","0.86005000"],["77564.77000000","0.00077000"],["77563.18000000","0.00000000"],["77563.08000000","0.00000000"],["77561.00000000","0.00543000"],["77560.38000000","0.00000000"],["77560.37000000","0.00000000"],["77558.91000000","0.00014000"],["77558.90000000","0.06104000"],["77558.79000000","0.00000000"],["77558.60000000","0.00826000"],["77558.01000000","0.00000000"],["77558.00000000","0.03035000"],["77556.00000000","0.03007000"],["77553.30000000","0.00000000"],["77551.59000000","0.00339000"],["77549.61000000","0.02000000"],["77549.56000000","0.02400000"],["77548.83000000","0.04000000"],["77548.79000000","0.04000000"],["77546.81000000","0.00000000"],["77546.80000000","0.00257000"],["77546.12000000","0.00000000"],["77546.01000000","0.00800000"],["77545.73000000","0.02000000"],["77541.54000000","0.00000000"],["77536.16000000","0.00000000"],["77514.58000000","0.34847000"],["77506.15000000","0.02000000"],["77503.52000000","1.30059000"],["77502.74000000","0.02000000"],["77502.55000000","0.02000000"],["77501.99000000","0.34853000"],["77501.88000000","0.00000000"],["77501.00000000","0.02000000"],["77498.57000000","0.02000000"],["77498.32000000","0.02000000"],["77497.45000000","0.00000000"],["77497.35000000","0.02000000"],["77497.31000000","0.02000000"],["77479.86000000","1.61625000"],["77448.01000000","0.00000000"],["77419.80000000","0.00000000"],["77417.71000000","0.00000000"],["77372.63000000","0.02020000"],["71383.07000000","0.00015000"],["62072.00000000","0.15357000"],["62051.83000000","0.00000000"]],"a":[["77564.79000000","5.32814000"],["77564.80000000","1.66387000"],["77565.07000000","0.00000000"],["77565.51000000","0.00000000"],["77566.79000000","0.00421000"],["77567.23000000","0.00828000"],["77567.25000000","0.00000000"],["77567.26000000","0.07528000"],["77570.02000000","0.14743000"],["77570.29000000","0.02007000"],["77570.32000000","0.02600000"],["77570.91000000","0.52070000"],["77571.05000000","0.03200000"],["77571.06000000","0.02600000"],["77571.10000000","0.02600000"],["77571.11000000","0.03207000"],["77571.52000000","0.24814000"],["77571.56000000","0.00000000"],["77573.39000000","0.03000000"],["77574.16000000","0.02600000"],["77574.94000000","0.04600000"],["77580.22000000","0.34818000"],["77580.31000000","0.00029000"],["77588.06000000","0.00029000"],["77595.82000000","0.00029000"],["77608.00000000","0.03000000"],["77625.38000000","0.00012000"],["77640.03000000","0.00000000"],["77640.13000000","0.00000000"],["77644.25000000","0.00000000"],["77661.54000000","0.00000000"],["77685.95000000","0.00000000"],["77688.31000000","1.27491000"],["77693.06000000","0.00000000"]]}}
{"type":"trade","received_at_ms":1788331890509,"data":{"e":"trade","E":1788331890649,"s":"BTCUSDT","t":6646634875,"p":"77564.79000000","q":"0.00159000","T":1788331890649,"m":false,"M":true}}
{"type":"depth","received_at_ms":1788331890574,"data":{"e":"depthUpdate","E":1788331890714,"s":"BTCUSDT","U":99555832413,"u":99555832464,"b":[["77564.78000000","0.86013000"],["77560.00000000","0.03035000"],["77558.90000000","0.06118000"],["77558.00000000","0.03021000"],["77552.20000000","0.00000000"],["77551.69000000","0.34778000"],["77551.59000000","0.00000000"],["77546.33000000","0.00800000"],["77540.68000000","0.00000000"],["77537.37000000","0.00000000"],["77537.13000000","0.00000000"],["77536.25000000","0.00000000"],["77519.07000000","0.00412000"],["77518.80000000","0.00008000"],["77501.61000000","0.02000000"],["77483.53000000","2.35865000"],["77482.40000000","1.27827000"],["77437.58000000","0.00011000"],["69808.31000000","0.00112000"],["69808.30000000","0.00000000"],["69808.29000000","0.00009000"],["62051.82000000","0.00000000"]],"a":[["77564.79000000","5.33000000"],["77565.73000000","0.00007000"],["77567.23000000","0.01228000"],["77567.26000000","0.07535000"],["77567.28000000","0.02139000"],["77567.51000000","0.01282000"],["77567.58000000","0.00007000"],["77574.18000000","0.02800000"],["77582.24000000","0.00008000"],["77582.64000000","0.00000000"],["77586.58000000","0.00000000"],["77589.16000000","1.02238000"],["77590.54000000","1.27649000"],["77597.06000000","0.00000000"],["77617.38000000","0.00000000"],["77626.16000000","0.00000000"],["77648.14000000","0.00000000"],["77678.96000000","0.00012000"],["77681.32000000","0.00019000"],["78728.27000000","0.00030000"]]}}
{"type":"trade","received_at_ms":1788331890608,"data":{"e":"trade","E":1788331890748,"s":"BTCUSDT","t":6646634876,"p":"77564.78000000","q":"0.00257000","T":1788331890748,"m":true,"M":true}}
{"type":"depth","received_at_ms":1788331890674,"data":{"e":"depthUpdate","E":1788331890814,"s":"BTCUSDT","U":99555832465,"u":99555832498,"b":[["77564.78000000","0.85756000"],["77553.71000000","0.00000000"],["77553.30000000","0.01200000"],["77551.50000000","0.00742000"],["77547.57000000","0.00257000"],["77546.80000000","0.00000000"],["77546.33000000","0.00400000"],["77546.01000000","0.00000000"],["77536.12000000","0.00000000"],["77529.83000000","0.00335000"],["77515.56000000","0.00000000"],["77503.43000000","0.02000000"],["77412.59000000","0.00000000"],["77346.11000000","0.00000000"],["69808.31000000","0.00128000"]],"a":[["77567.27000000","0.83363000"],["77567.28000000","0.02139000"],["77568.00000000","1.68971000"],["77571.48000000","0.00000000"],["77571.51000000","0.77865000"],["77574.62000000","0.02200000"],["77577.99000000","0.00000000"],["77580.60000000","0.00400000"],["77580.61000000","0.00000000"],["77583.49000000","0.00007000"],["77647.36000000","0.00000000"],["77686.07000000","0.00032000"]]}}
{"type":"trade","received_at_ms":1788331890758,"data":{"e":"trade","E":1788331890899,"s":"BTCUSDT","t":6646634877,"p":"77564.79000000","q":"0.00037000","T":1788331890899,"m":false,"M":true}}
{"type":"depth","received_at_ms":1788331890775,"data":{"e":"depthUpdate","E":1788331890914,"s":"BTCUSDT","U":99555832499,"u":99555832516,"b":[["77551.70000000","0.11178000"],["77550.59000000","0.00000000"],["77547.57000000","0.00000000"],["77412.60000000","0.00000000"],["69808.31000000","0.00128000"]],"a":[["77564.79000000","5.33077000"],["77564.80000000","1.66387000"],["77581.15000000","0.00179000"],["77592.19000000","0.49207000"],["77639.39000000","0.00000000"],["77640.06000000","0.00000000"],["77643.82000000","0.00000000"],["77648.50000000","0.00000000"],["77676.95000000","0.00412000"]]}}
{"type":"trade","received_at_ms":1788331890805,"data":{"e":"trade","E":1788331890944,"s":"BTCUSDT","t":6646634878,"p":"77564.79000000","q":"0.00138000","T":1788331890944,"m":false,"M":true}}
{"type":"trade","received_at_ms":1788331890805,"data":{"e":"trade","E":1788331890946,"s":"BTCUSDT","t":6646634879,"p":"77564.79000000","q":"0.03224000","T":1788331890945,"m":false,"M":true}}
{"type":"depth","received_at_ms":1788331890874,"data":{"e":"depthUpdate","E":1788331891014,"s":"BTCUSDT","U":99555832517,"u":99555832700,"b":[["77564.78000000","1.21511000"],["77564.77000000","0.00104000"],["77564.76000000","0.00013000"],["77564.00000000","0.03028000"],["77563.25000000","0.00020000"],["77562.02000000","0.00014000"],["77562.01000000","0.04421000"],["77562.00000000","0.03028000"],["77561.79000000","0.00014000"],["77561.78000000","0.11719000"],["77561.50000000","0.00000000"],["77561.00000000","0.00550000"],["77560.30000000","0.00007000"],["77560.29000000","0.13671000"],["77560.28000000","0.11719000"],["77560.01000000","0.00000000"],["77558.91000000","0.00000000"],["77558.90000000","0.00021000"],["77558.00000000","0.04318000"],["77557.99000000","0.00000000"],["77557.40000000","0.00000000"],["77557.28000000","0.11729000"],["77556.54000000","0.11719000"],["77556.53000000","0.42535000"],["77556.24000000","1.31471000"],["77556.23000000","0.00042000"],["77556.00000000","0.03000000"],["77555.78000000","0.00000000"],["77555.14000000","0.00000000"],["77555.10000000","0.00000000"],["77554.97000000","0.00644000"],["77554.96000000","0.00014000"],["77554.94000000","0.00000000"],["77554.55000000","0.00000000"],["77554.48000000","0.00400000"],["77554.43000000","0.00000000"],["77554.23000000","0.07775000"],["77553.45000000","0.00644000"],["77553.44000000","0.00415000"],["77553.29000000","0.00000000"],["77552.97000000","0.00000000"],["77552.00000000","0.06217000"],["77551.87000000","0.00000000"],["77551.71000000","0.34778000"],["77551.70000000","0.00000000"],["77551.69000000","0.00000000"],["77550.24000000","0.00000000"],["77548.33000000","0.00000000"],["77547.58000000","0.00000000"],["77544.16000000","0.05338000"],["77541.80000000","0.00400000"],["77540.54000000","0.11808000"],["77538.01000000","0.00000000"],["77537.92000000","0.00415000"],["77533.83000000","1.15974000"],["77527.90000000","0.09714000"],["77522.40000000","0.00015000"],["77522.29000000","0.84030000"],["77521.00000000","0.70000000"],["77520.75000000","0.00000000"],["77520.46000000","0.00000000"],["77519.50000000","0.00000000"],["77519.47000000","0.00007000"],["77518.52000000","0.00000000"],["77511.84000000","1.31471000"],["77485.98000000","0.00010000"],["77479.86000000","0.00000000"],["77473.51000000","0.00197000"],["77402.80000000","0.00000000"],["77392.71000000","0.00000000"],["76401.30000000","0.00030000"],["69808.31000000","0.00144000"],["69808.29000000","0.00000000"],["62052.00000000","0.02806000"],["62051.83000000","0.00032000"]],"a":[["77564.79000000","4.39210000"],["77565.00000000","0.00000000"],["77565.72000000","0.00000000"],["77566.00000000","0.00644000"],["77566.04000000","0.01786000"],["77566.15000000","0.00400000"],["77566.31000000","0.00257000"],["77566.77000000","0.00048000"],["77566.79000000","0.00007000"],["77566.80000000","0.00028000"],["77567.22000000","0.01200000"],["77567.23000000","0.00414000"],["77567.24000000","0.00028000"],["77567.25000000","0.00000000"],["77567.27000000","0.71283000"],["77567.58000000","0.00014000"],["77567.59000000","0.30014000"],["77567.99000000","0.00665000"],["77568.00000000","0.37507000"],["77569.96000000","0.00126000"],["77570.91000000","0.52063000"],["77571.11000000","0.03200000"],["77571.51000000","0.64953000"],["77571.52000000","0.24807000"],["77571.75000000","0.34778000"],["77572.45000000","0.12891000"],["77574.96000000","0.00007000"],["77575.98000000","0.00000000"],["77577.75000000","0.00007000"],["77577.76000000","0.00000000"],["77579.37000000","0.00000000"],["77579.58000000","0.38567000"],["77581.10000000","0.25799000"],["77582.60000000","0.64499000"],["77582.74000000","0.00200000"],["77586.53000000","0.00000000"],["77647.72000000","0.00000000"],["77685.36000000","0.00000000"]]}}
{"type":"trade","received_at_ms":1788331890922,"data":{"e":"trade","E":1788331891063,"s":"BTCUSDT","t":6646634880,"p":"77564.79000000","q":"0.00100000","T":1788331891063,"m":false,"M":true}}
{"type":"depth","received_at_ms":1788331890975,"data":{"e":"depthUpdate","E":1788331891114,"s":"BTCUSDT","U":99555832701,"u":99555832836,"b":[["77564.78000000","1.23471000"],["77564.77000000","0.00104000"],["77564.00000000","0.03028000"],["77562.01000000","0.04435000"],["77562.00000000","0.03028000"],["77561.78000000","0.11733000"],["77561.00000000","0.00557000"],["77560.32000000","0.00007000"],["77560.31000000","0.50277000"],["77560.30000000","1.31471000"],["77560.29000000","0.00014000"],["77560.28000000","0.00014000"],["77560.00000000","0.03035000"],["77558.90000000","0.00014000"],["77558.89000000","0.02908000"],["77558.78000000","0.00000000"],["77558.60000000","0.00812000"],["77557.36000000","0.00975000"],["77557.28000000","0.00000000"],["77556.54000000","0.00000000"],["77554.97000000","0.00000000"],["77553.45000000","0.01288000"],["77553.30000000","0.00000000"],["77551.72000000","0.01200000"],["77545.51000000","0.00007000"],["77537.61000000","0.12896000"],["77514.03000000","1.31808000"],["77505.62000000","0.02000000"],["77465.18000000","0.00000000"],["77454.06000000","0.14812000"],["77444.55000000","0.00000000"],["77437.58000000","0.00022000"],["77412.89000000","0.00000000"],["77378.60000000","4.69310000"],["69808.31000000","0.00160000"],["62051.82000000","0.00000000"]],"a":[["77564.79000000","4.63975000"],["77564.80000000","1.66387000"],["77566.00000000","0.00658000"],["77566.04000000","0.01786000"],["77566.13000000","0.00333000"],["77566.31000000","0.00000000"],["77566.77000000","0.00200000"],["77566.80000000","0.00007000"],["77567.00000000","0.00000000"],["77567.05000000","0.00000000"],["77567.18000000","0.00257000"],["77567.22000000","0.00014000"],["77567.23000000","0.00000000"],["77567.24000000","0.00014000"],["77567.27000000","0.71290000"],["77567.51000000","0.01296000"],["77570.45000000","0.00007000"],["77570.71000000","0.01600000"],["77570.91000000","0.27256000"],["77571.52000000","0.00000000"],["77575.05000000","0.02800000"],["77576.54000000","0.00007000"],["77646.96000000","0.00000000"],["77661.46000000","0.00000000"],["77686.78000000","0.00971000"],["77697.94000000","0.00007000"]]}}
{"type":"depth","received_at_ms":1788331891073,"data":{"e":"depthUpdate","E":1788331891214,"s":"BTCUSDT","U":99555832837,"u":99555832896,"b":[["77564.78000000","1.35864000"],["77564.77000000","0.00111000"],["77564.18000000","0.00021000"],["77563.42000000","0.00000000"],["77563.25000000","0.00000000"],["77561.00000000","0.00550000"],["77560.33000000","0.00007000"],["77560.32000000","0.07782000"],["77560.31000000","0.50284000"],["77560.30000000","1.31485000"],["77560.29000000","0.00000000"],["77560.28000000","0.00000000"],["77551.72000000","0.00000000"],["77548.09000000","0.01200000"],["77540.54000000","0.00000000"],["77537.70000000","0.07619000"],["77470.59000000","0.00000000"],["77470.58000000","0.00179000"],["76866.70000000","0.00010000"],["71383.07000000","0.00000000"],["69808.31000000","0.00176000"],["69808.30000000","0.00027000"],["62051.83000000","0.00000000"]],"a":[["77564.85000000","0.05000000"],["77566.04000000","0.01779000"],["77566.50000000","0.00007000"],["77567.22000000","0.00000000"],["77567.59000000","0.30028000"],["77588.00000000","0.01000000"],["77590.00000000","0.01000000"],["77592.00000000","0.01015000"],["77594.00000000","0.01000000"],["77596.00000000","0.01000000"],["77598.00000000","0.01000000"],["77600.00000000","0.10664000"],["77602.00000000","0.01000000"],["77661.09000000","0.00000000"]]}}
{"type":"depth","received_at_ms":1788331891173,"data":{"e":"depthUpdate","E":1788331891314,"s":"BTCUSDT","U":99555832897,"u":99555832923,"b":[["77564.78000000","1.36264000"],["77561.00000000","0.00550000"],["77560.32000000","0.07796000"],["77560.00000000","0.03021000"],["77558.90000000","0.00007000"],["77551.77000000","0.00342000"],["77519.50000000","0.00007000"],["77519.47000000","0.00000000"],["77511.07000000","0.00000000"],["77454.06000000","0.00000000"]],"a":[["77564.79000000","4.63982000"],["77564.80000000","1.66387000"],["77564.85000000","0.05014000"],["77567.18000000","0.00000000"],["77567.59000000","0.30014000"],["77686.78000000","0.00000000"]]}}
{"type":"depth","received_at_ms":1788331891273,"data":{"e":"depthUpdate","E":1788331891414,"s":"BTCUSDT","U":99555832924,"u":99555832942,"b":[["77564.78000000","1.23878000"],["77554.48000000","0.00000000"],["77553.77000000","0.00400000"],["77548.74000000","0.00007000"],["77519.50000000","0.00000000"],["77519.47000000","0.00007000"],["77466.92000000","0.03998000"],["77466.15000000","0.00000000"],["69808.31000000","0.00192000"],["62052.00000000","0.02806000"]],"a":[["77564.79000000","4.64636000"],["77565.91000000","0.00000000"],["77566.00000000","0.00014000"],["77584.00000000","0.00272000"],["77699.68000000","0.00971000"]]}}
{"type":"depth","received_at_ms":1788331891373,"data":{"e":"depthUpdate","E":1788331891514,"s":"BTCUSDT","U":99555832943,"u":99555832967,"b":[["77359.17000000","0.00000000"],["77351.92000000","0.00813000"],["69808.31000000","0.00192000"],["62052.00000000","0.03006000"],["62051.83000000","0.00032000"]],"a":[["77564.79000000","4.64629000"],["77564.85000000","0.05014000"],["77566.00000000","0.00000000"],["77566.71000000","0.00257000"],["77567.59000000","0.30028000"],["77588.00000000","0.01500000"],["77590.00000000","0.01500000"],["77592.00000000","0.01515000"],["77594.00000000","0.01500000"],["77596.00000000","0.01500000"],["77598.00000000","0.01500000"],["77600.00000000","0.11164000"],["77659.40000000","0.00000000"]]}}
{"type":"trade","received_at_ms":1788331891410,"data":{"e":"trade","E":1788331891549,"s":"BTCUSDT","t":6646634881,"p":"77564.79000000","q":"0.00096000","T":1788331891548,"m":false,"M":true}}
{"type":"trade","received_at_ms":1788331891449,"data":{"e":"trade","E":1788331891590,"s":"BTCUSDT","t":6646634882,"p":"77564.79000000","q":"0.00037000","T":1788331891589,"m":false,"M":true}}
{"type":"depth","received_at_ms":1788331891472,"data":{"e":"depthUpdate","E":1788331891614,"s":"BTCUSDT","U":99555832968,"u":99555832987,"b":[["77556.23000000","0.00000000"],["77555.47000000","0.00041000"],["77544.16000000","0.00000000"],["77541.85000000","0.03328000"],["77510.85000000","0.34849000"],["77501.88000000","0.02000000"],["77497.45000000","0.02000000"],["77496.79000000","0.00195000"],["77473.51000000","0.00000000"],["69808.31000000","0.00217000"],["69808.00000000","0.09261000"],["62051.83000000","0.00000000"]],"a":[["77564.79000000","4.64496000"],["77567.27000000","0.71283000"],["77583.91000000","0.32237000"],["77597.12000000","0.34810000"],["77602.00000000","0.01500000"],["77667.15000000","0.00000000"],["77674.90000000","0.00000000"]]}}
{"type":"depth","received_at_ms":1788331891574,"data":{"e":"depthUpdate","E":1788331891714,"s":"BTCUSDT","U":99555832988,"u":99555832999,"b":[["77557.12000000","0.00330000"],["77553.24000000","0.00335000"],["77530.01000000","0.68265000"],["77530.00000000","0.73000000"],["77526.47000000","0.00000000"],["77427.41000000","0.00000000"],["69808.31000000","0.00217000"],["62051.82000000","0.00000000"]],"a":[["78728.27000000","0.00030000"]]}}
{"type":"trade","received_at_ms":1788331891608,"data":{"e":"trade","E":1788331891748,"s":"BTCUSDT","t":6646634883,"p":"77564.79000000","q":"0.00058000","T":1788331891748,"m":false,"M":true}}
{"type":"depth","received_at_ms":1788331891677,"data":{"e":"depthUpdate","E":1788331891814,"s":"BTCUSDT","U":99555833000,"u":99555833011,"b":[["77558.90000000","0.00014000"],["77558.67000000","0.00341000"],["69808.31000000","0.00233000"]],"a":[["77564.79000000","4.64438000"],["77566.71000000","0.00000000"],["77567.62000000","0.00257000"],["77588.00000000","0.02500000"],["77590.00000000","0.02500000"],["77592.00000000","0.02515000"],["77730.77000000","0.01543000"],["77761.40000000","0.00000000"]]}}
{"type":"depth","received_at_ms":1788331891774,"data":{"e":"depthUpdate","E":1788331891915,"s":"BTCUSDT","U":99555833012,"u":99555833020,"b":[["77564.78000000","1.23885000"],["77510.69000000","0.00000000"]],"a":[["77594.00000000","0.02500000"],["77596.00000000","0.02500000"],["77598.00000000","0.02500000"],["77600.00000000","0.12164000"],["77602.00000000","0.02500000"],["77714.43000000","0.00000000"]]}}
{"type":"trade","received_at_ms":1788331891807,"data":{"e":"trade","E":1788331891947,"s":"BTCUSDT","t":6646634884,"p":"77564.79000000","q":"0.00035000","T":1788331891947,"m":false,"M":true}}
{"type":"depth","received_at_ms":1788331891875,"data":{"e":"depthUpdate","E":1788331892014,"s":"BTCUSDT","U":99555833021,"u":99555833043,"b":[["77564.78000000","1.23878000"],["77558.97000000","0.00013000"],["77558.67000000","0.00000000"],["77557.12000000","0.00000000"],["77552.84000000","0.00257000"],["77545.78000000","0.00000000"],["77510.57000000","0.12898000"],["77510.56000000","0.00587000"],["77510.49000000","0.00000000"],["76401.30000000","0.00030000"],["69808.31000000","0.00240000"],["69808.30000000","0.00036000"],["62051.83000000","0.00032000"]],"a":[["77564.79000000","4.64403000"],["77570.60000000","0.00013000"],["77572.17000000","0.00007000"],["77580.55000000","0.00007000"],["77605.92000000","0.01344000"],["77622.00000000","0.03000000"],["77632.12000000","0.00587000"],["77688.11000000","0.00000000"]]}}
{"type":"trade","received_at_ms":1788331891928,"data":{"e":"trade","E":1788331892069,"s":"BTCUSDT","t":6646634885,"p":"77564.79000000","q":"0.00037000","T":1788331892068,"m":false,"M":true}}
{"type":"trade","received_at_ms":1788331891957,"data":{"e":"trade","E":1788331892094,"s":"BTCUSDT","t":6646634886,"p":"77564.78000000","q":"0.00100000","T":1788331892094,"m":true,"M":true}}
{"type":"depth","received_at_ms":1788331891976,"data":{"e":"depthUpdate","E":1788331892114,"s":"BTCUSDT","U":99555833044,"u":99555833067,"b":[["77564.78000000","1.23771000"],["77558.60000000","0.01142000"],["77557.85000000","0.00000000"],["77557.04000000","0.00341000"],["77552.84000000","0.00000000"],["77545.51000000","0.00007000"],["77519.07000000","0.00000000"],["77510.57000000","0.00000000"],["77510.15000000","0.12898000"],["77488.04000000","0.00000000"],["69808.31000000","0.00240000"],["62051.82000000","0.00000000"]],"a":[["77564.79000000","4.64366000"],["77576.54000000","0.00007000"],["77607.10000000","0.00000000"],["77645.91000000","0.00000000"],["77660.96000000","0.00025000"],["77667.95000000","0.00000000"],["77676.95000000","0.00000000"]]}}
{"type":"trade","received_at_ms":1788331892014,"data":{"e":"trade","E":1788331892155,"s":"BTCUSDT","t":6646634887,"p":"77564.79000000","q":"0.00022000","T":1788331892154,"m":false,"M":true}}
{"type":"depth","received_at_ms":1788331892072,"data":{"e":"depthUpdate","E":1788331892214,"s":"BTCUSDT","U":99555833068,"u":99555833075,"b":[["77552.82000000","0.00257000"],["77510.17000000","0.12898000"],["77510.15000000","0.00000000"],["69808.31000000","0.00240000"],["62051.83000000","0.00000000"]],"a":[["77564.79000000","4.64344000"],["77753.28000000","0.00000000"]]}}
{"type":"trade","received_at_ms":1788331892085,"data":{"e":"trade","E":1788331892226,"s":"BTCUSDT","t":6646634888,"p":"77564.79000000","q":"0.00037000","T":1788331892225,"m":false,"M":true}}
{"type":"depth","received_at_ms":1788331892173,"data":{"e":"depthUpdate","E":1788331892315,"s":"BTCUSDT","U":99555833076,"u":99555833110,"b":[["77564.78000000","1.23785000"],["77564.77000000","0.00125000"],["77561.78000000","0.11740000"],["77561.07000000","0.00215000"],["77561.06000000","0.09908000"],["77560.32000000","0.07789000"],["77553.45000000","0.00644000"],["77552.82000000","0.00000000"],["77552.79000000","0.00257000"],["77552.01000000","0.00644000"],["77540.53000000","0.00000000"],["77527.90000000","0.00000000"],["77524.86000000","0.09647000"],["77518.31000000","0.29247000"],["77515.26000000","0.00000000"],["77510.48000000","0.00000000"],["77510.32000000","0.00000000"],["77510.17000000","0.00000000"],["77494.32000000","0.00412000"],["77479.86000000","1.61678000"],["69808.31000000","0.00256000"],["69808.30000000","0.00027000"],["62052.00000000","0.03006000"]],"a":[["77564.79000000","4.64307000"],["77600.00000000","0.02515000"],["77624.53000000","0.09469000"],["77630.02000000","0.00000000"]]}}
{"type":"trade","received_at_ms":1788331892213,"data":{"e":"trade","E":1788331892354,"s":"BTCUSDT","t":6646634889,"p":"77564.79000000","q":"0.00012000","T":1788331892354,"m":false,"M":true}}
{"type":"depth","received_at_ms":1788331892273,"data":{"e":"depthUpdate","E":1788331892414,"s":"BTCUSDT","U":99555833111,"u":99555833130,"b":[["77561.78000000","0.11740000"],["77561.06000000","0.09922000"],["77560.30000000","1.31471000"],["77552.79000000","0.00000000"],["77552.76000000","0.00000000"],["77509.88000000","0.12898000"],["69808.31000000","0.00272000"],["69808.30000000","0.00000000"]],"a":[["77564.79000000","4.64295000"],["77574.89000000","0.03210000"],["77585.58000000","0.10725000"],["77585.62000000","0.00000000"]]}}
{"type":"trade","received_at_ms":1788331892355,"data":{"e":"trade","E":1788331892491,"s":"BTCUSDT","t":6646634890,"p":"77564.79000000","q":"0.00010000","T":1788331892491,"m":false,"M":true}}
{"type":"depth","received_at_ms":1788331892373,"data":{"e":"depthUpdate","E":1788331892514,"s":"BTCUSDT","U":99555833131,"u":99555833138,"b":[["77552.74000000","0.00257000"],["77509.88000000","0.00000000"],["69808.31000000","0.00265000"],["62051.83000000","0.00032000"]],"a":[["77564.79000000","4.64285000"],["77570.00000000","0.00200000"],["77652.16000000","0.00412000"]]}}
{"type":"depth","received_at_ms":1788331892473,"data":{"e":"depthUpdate","E":1788331892614,"s":"BTCUSDT","U":99555833139,"u":99555833151,"b":[["77552.74000000","0.00000000"],["77552.71000000","0.00257000"],["77506.80000000","1.29738000"],["77503.97000000","0.34852000"],["69808.31000000","0.00297000"],["69808.00000000","0.09261000"],["62052.00000000","0.03006000"],["62051.83000000","0.00000000"]],"a":[]}}
{"type":"depth","received_at_ms":1788331892573,"data":{"e":"depthUpdate","E":1788331892714,"s":"BTCUSDT","U":99555833152,"u":99555833168,"b":[["77562.72000000","0.00092000"],["77561.84000000","0.00057000"],["77560.35000000","0.00109000"],["77552.71000000","0.00000000"],["77552.66000000","0.00257000"],["77532.94000000","0.52900000"],["77508.99000000","0.82481000"],["77507.16000000","1.05119000"],["69808.31000000","0.00313000"],["62051.82000000","0.00000000"]],"a":[["77564.79000000","4.64378000"],["78728.27000000","0.00030000"]]}}
{"type":"depth","received_at_ms":1788331892672,"data":{"e":"depthUpdate","E":1788331892814,"s":"BTCUSDT","U":99555833169,"u":99555833174,"b":[["77552.66000000","0.00000000"],["77552.54000000","0.00000000"],["69808.31000000","0.00313000"]],"a":[["77564.79000000","4.64278000"]]}}
{"type":"depth","received_at_ms":1788331892776,"data":{"e":"depthUpdate","E":1788331892914,"s":"BTCUSDT","U":99555833175,"u":99555833178,"b":[["77552.51000000","0.00000000"],["69808.31000000","0.00329000"]],"a":[["77582.33000000","0.00412000"]]}}
{"type":"depth","received_at_ms":1788331892874,"data":{"e":"depthUpdate","E":1788331893014,"s":"BTCUSDT","U":99555833179,"u":99555833190,"b":[["77564.78000000","1.23914000"],["77552.49000000","0.00000000"],["77509.34000000","0.12898000"],["77477.18000000","0.00396000"],["76401.30000000","0.00030000"],["69808.31000000","0.00329000"],["62051.83000000","0.00032000"]],"a":[["77624.53000000","0.00000000"]]}}
{"type":"depth","received_at_ms":1788331892976,"data":{"e":"depthUpdate","E":1788331893114,"s":"BTCUSDT","U":99555833191,"u":99555833204,"b":[["77552.47000000","0.00000000"],["77545.51000000","0.00007000"],["77532.94000000","0.00000000"],["77509.34000000","0.00000000"],["69808.31000000","0.00345000"],["62051.82000000","0.00000000"]],"a":[["77569.38000000","0.00007000"],["77576.54000000","0.00007000"],["77588.93000000","0.00007000"]]}}
{"type":"depth","received_at_ms":1788331893073,"data":{"e":"depthUpdate","E":1788331893214,"s":"BTCUSDT","U":99555833205,"u":99555833217,"b":[["77552.44000000","0.00257000"],["77510.26000000","0.00000000"],["77510.02000000","0.16870000"],["77509.71000000","0.00000000"],["62051.83000000","0.00000000"]],"a":[["77588.00000000","0.03000000"],["77590.00000000","0.03000000"],["77592.00000000","0.03015000"],["77594.00000000","0.03000000"],["77596.00000000","0.03000000"]]}}
{"type":"depth","received_at_ms":1788331893176,"data":{"e":"depthUpdate","E":1788331893314,"s":"BTCUSDT","U":99555833218,"u":99555833228,"b":[["77564.18000000","0.00000000"],["77552.44000000","0.00000000"],["77509.94000000","0.00000000"],["69808.31000000","0.00361000"]],"a":[["77570.91000000","0.27249000"],["77598.00000000","0.03000000"],["77600.00000000","0.03015000"],["77602.00000000","0.03000000"]]}}
{"type":"trade","received_at_ms":1788331893253,"data":{"e":"trade","E":1788331893391,"s":"BTCUSDT","t":6646634891,"p":"77564.79000000","q":"0.00012000","T":1788331893391,"m":false,"M":true}}
{"type":"depth","received_at_ms":1788331893273,"data":{"e":"depthUpdate","E":1788331893414,"s":"BTCUSDT","U":99555833229,"u":99555833245,"b":[["77533.11000000","0.53669000"],["77520.11000000","0.00195000"],["77509.55000000","0.00000000"],["77509.49000000","0.00000000"],["77496.79000000","0.00000000"],["77440.68000000","0.00083000"],["69808.31000000","0.00352000"],["69808.30000000","0.00009000"]],"a":[["77564.79000000","4.64266000"],["77661.14000000","2.15391000"],["77687.03000000","0.41562000"],["77687.04000000","0.00000000"]]}}
{"type":"depth","received_at_ms":1788331893379,"data":{"e":"depthUpdate","E":1788331893514,"s":"BTCUSDT","U":99555833246,"u":99555833263,"b":[["77564.78000000","1.11431000"],["77553.77000000","0.00000000"],["77553.64000000","0.00000000"],["77553.49000000","0.00400000"],["77548.09000000","0.00400000"],["77547.32000000","0.00800000"],["77509.41000000","0.00000000"],["69808.31000000","0.00368000"],["62051.83000000","0.00032000"]],"a":[["77614.37000000","0.09493000"]]}}
{"type":"depth","received_at_ms":1788331893552,"data":{"e":"depthUpdate","E":1788331893614,"s":"BTCUSDT","U":99555833264,"u":99555833270,"b":[["77564.78000000","1.24065000"],["77401.95000000","0.00083000"],["69808.31000000","0.00368000"],["62052.00000000","0.03206000"],["62051.83000000","0.00000000"]],"a":[]}}
{"type":"trade","received_at_ms":1788331893552,"data":{"e":"trade","E":1788331893682,"s":"BTCUSDT","t":6646634892,"p":"77564.79000000","q":"0.07577000","T":1788331893682,"m":false,"M":true}}
{"type":"trade","received_at_ms":1788331893552,"data":{"e":"trade","E":1788331893682,"s":"BTCUSDT","t":6646634893,"p":"77564.79000000","q":"0.10803000","T":1788331893682,"m":false,"M":true}}
{"type":"depth","received_at_ms":1788331893574,"data":{"e":"depthUpdate","E":1788331893714,"s":"BTCUSDT","U":99555833271,"u":99555833287,"b":[["77563.60000000","0.00021000"],["77562.01000000","0.07369000"],["77562.00000000","0.03035000"],["77561.81000000","0.00014000"],["77561.80000000","0.11641000"],["77561.07000000","0.00208000"],["77560.33000000","0.00000000"],["69808.31000000","0.00384000"],["69808.30000000","0.00000000"],["69808.00000000","0.09281000"],["62052.00000000","0.03006000"]],"a":[["77564.79000000","4.45886000"],["78728.27000000","0.00030000"]]}}
{"type":"depth","received_at_ms":1788331893674,"data":{"e":"depthUpdate","E":1788331893814,"s":"BTCUSDT","U":99555833288,"u":99555833307,"b":[["77564.78000000","1.24072000"],["77564.77000000","0.00132000"],["77562.00000000","0.03035000"],["77561.80000000","0.11655000"],["77560.31000000","0.50270000"],["77509.67000000","0.00000000"],["77508.79000000","0.12898000"],["75557.06000000","0.00000000"],["69808.31000000","0.00368000"],["69808.00000000","0.09261000"],["62051.82000000","0.00000000"]],"a":[["77567.62000000","0.00000000"],["77597.50000000","0.00000000"],["81001.06000000","0.00000000"]]}}
{"type":"depth","received_at_ms":1788331893775,"data":{"e":"depthUpdate","E":1788331893914,"s":"BTCUSDT","U":99555833308,"u":99555833314,"b":[["77564.78000000","1.36654000"],["69808.31000000","0.00400000"]],"a":[["77571.80000000","0.00249000"],["77621.13000000","0.00412000"],["77688.88000000","0.00083000"]]}}
{"type":"depth","received_at_ms":1788331893875,"data":{"e":"depthUpdate","E":1788331894014,"s":"BTCUSDT","U":99555833315,"u":99555833324,"b":[["77564.78000000","1.36674000"],["76401.30000000","0.00030000"],["69808.31000000","0.00400000"],["62052.00000000","0.03006000"],["62051.83000000","0.00032000"]],"a":[]}}
{"type":"depth","received_at_ms":1788331893973,"data":{"e":"depthUpdate","E":1788331894114,"s":"BTCUSDT","U":99555833325,"u":99555833337,"b":[["77564.78000000","1.24100000"],["77563.60000000","0.00000000"],["77545.51000000","0.00000000"],["77541.18000000","0.00000000"],["77485.66000000","0.00007000"],["77480.08000000","0.00007000"],["77454.56000000","0.00000000"],["76684.59000000","0.00019000"],["76218.90000000","0.00000000"],["75753.20000000","0.00000000"],["75287.51000000","0.00000000"],["74821.81000000","0.00000000"],["74356.11000000","0.00000000"],["73890.42000000","0.00000000"],["73424.72000000","0.00000000"],["72959.03000000","0.00000000"],["72493.33000000","0.00000000"],["69808.31000000","0.00400000"],["62051.82000000","0.00000000"]],"a":[["77576.54000000","0.00000000"],["77727.72000000","0.00076000"]]}}
{"type":"depth","received_at_ms":1788331894073,"data":{"e":"depthUpdate","E":1788331894214,"s":"BTCUSDT","U":99555833338,"u":99555833357,"b":[["77564.78000000","1.38404000"],["77559.37000000","0.00332000"],["77545.51000000","0.00007000"],["77485.12000000","0.00000000"],["77391.43000000","0.00000000"],["69808.31000000","0.00448000"],["62051.83000000","0.00000000"]],"a":[["77564.80000000","1.34422000"],["77567.25000000","0.00014000"],["77567.27000000","0.30021000"],["77568.00000000","0.37500000"],["77576.54000000","0.00007000"],["77669.65000000","0.00000000"],["77846.99000000","0.00000000"]]}}
{"type":"depth","received_at_ms":1788331894172,"data":{"e":"depthUpdate","E":1788331894314,"s":"BTCUSDT","U":99555833358,"u":99555833373,"b":[["77564.78000000","1.24092000"],["77463.31000000","0.00412000"],["69808.31000000","0.00448000"],["62052.00000000","0.03006000"]],"a":[]}}
{"type":"depth","received_at_ms":1788331894273,"data":{"e":"depthUpdate","E":1788331894414,"s":"BTCUSDT","U":99555833374,"u":99555833380,"b":[["77551.12000000","0.00257000"],["77369.72000000","0.02020000"],["69808.31000000","0.00464000"]],"a":[["77687.03000000","0.38094000"],["77761.33000000","0.02020000"]]}}
{"type":"depth","received_at_ms":1788331894374,"data":{"e":"depthUpdate","E":1788331894514,"s":"BTCUSDT","U":99555833381,"u":99555833391,"b":[["77564.78000000","1.37013000"],["77533.11000000","0.00000000"],["77358.32000000","0.00813000"],["77351.92000000","0.00000000"],["69808.31000000","0.00448000"],["62052.00000000","0.03206000"],["62051.83000000","0.00032000"]],"a":[["77647.38000000","0.01680000"],["77655.13000000","0.01799000"],["77662.88000000","0.01360000"]]}}
{"type":"depth","received_at_ms":1788331894473,"data":{"e":"depthUpdate","E":1788331894614,"s":"BTCUSDT","U":99555833392,"u":99555833401,"b":[["77564.78000000","1.24100000"],["77555.47000000","0.00000000"],["75557.06000000","0.00010000"],["69808.31000000","0.00464000"],["62051.83000000","0.00000000"]],"a":[["77564.79000000","4.45927000"],["77614.37000000","0.00000000"]]}}
{"type":"trade","received_at_ms":1788331894531,"data":{"e":"trade","E":1788331894672,"s":"BTCUSDT","t":6646634894,"p":"77564.79000000","q":"0.00100000","T":1788331894672,"m":false,"M":true}}
{"type":"depth","received_at_ms":1788331894573,"data":{"e":"depthUpdate","E":1788331894714,"s":"BTCUSDT","U":99555833402,"u":99555833414,"b":[["77564.78000000","1.38454000"],["77533.10000000","0.51900000"],["69808.31000000","0.00457000"]],"a":[["77564.79000000","4.45827000"],["78728.27000000","0.00030000"]]}}
{"type":"depth","received_at_ms":1788331894673,"data":{"e":"depthUpdate","E":1788331894814,"s":"BTCUSDT","U":99555833415,"u":99555833421,"b":[["77564.78000000","1.38446000"],["69808.31000000","0.00473000"],["69808.00000000","0.09281000"],["62051.82000000","0.00000000"]],"a":[["77565.80000000","0.00257000"],["81001.06000000","0.00010000"]]}}
{"type":"depth","received_at_ms":1788331894773,"data":{"e":"depthUpdate","E":1788331894914,"s":"BTCUSDT","U":99555833422,"u":99555833428,"b":[["77564.78000000","1.24100000"],["69808.31000000","0.00457000"],["69808.00000000","0.09261000"]],"a":[["77570.73000000","2.19798000"]]}}
{"type":"depth","received_at_ms":1788331894874,"data":{"e":"depthUpdate","E":1788331895014,"s":"BTCUSDT","U":99555833429,"u":99555833440,"b":[["77564.78000000","1.24100000"],["76401.30000000","0.00030000"],["69808.31000000","0.00473000"],["62072.00000000","0.14957000"],["62051.83000000","0.00032000"]],"a":[]}}
{"type":"depth","received_at_ms":1788331894973,"data":{"e":"depthUpdate","E":1788331895114,"s":"BTCUSDT","U":99555833441,"u":99555833445,"b":[["77491.24000000","0.00007000"],["77476.78000000","0.00007000"],["69808.31000000","0.00457000"],["62051.82000000","0.00020000"]],"a":[["77595.71000000","0.09592000"]]}}
{"type":"depth","received_at_ms":1788331895072,"data":{"e":"depthUpdate","E":1788331895214,"s":"BTCUSDT","U":99555833446,"u":99555833456,"b":[["77545.51000000","0.00007000"],["69808.31000000","0.00457000"],["62052.00000000","0.03206000"],["62051.83000000","0.00000000"],["62051.82000000","0.00000000"]],"a":[["77576.54000000","0.00007000"]]}}
{"type":"trade","received_at_ms":1788331895174,"data":{"e":"trade","E":1788331895313,"s":"BTCUSDT","t":6646634895,"p":"77564.78000000","q":"0.00009000","T":1788331895313,"m":true,"M":true}}
{"type":"depth","received_at_ms":1788331895174,"data":{"e":"depthUpdate","E":1788331895314,"s":"BTCUSDT","U":99555833457,"u":99555833476,"b":[["77564.78000000","1.37415000"],["77551.72000000","0.00000000"],["77548.09000000","0.01200000"],["77547.32000000","0.00000000"],["77542.01000000","0.00750000"],["77541.85000000","0.00000000"],["77538.52000000","0.02280000"],["77537.70000000","0.01529000"],["77534.05000000","0.00000000"],["69808.31000000","0.00457000"]],"a":[]}}
{"type":"trade","received_at_ms":1788331895209,"data":{"e":"trade","E":1788331895350,"s":"BTCUSDT","t":6646634896,"p":"77564.78000000","q":"0.00037000","T":1788331895350,"m":true,"M":true}}
{"type":"depth","received_at_ms":1788331895273,"data":{"e":"depthUpdate","E":1788331895414,"s":"BTCUSDT","U":99555833477,"u":99555833491,"b":[["77564.78000000","1.37386000"],["77561.07000000","0.00000000"],["77561.06000000","0.00014000"],["77558.90000000","0.00007000"],["77551.12000000","0.00000000"],["77549.30000000","0.00257000"],["77519.50000000","0.00007000"],["77519.47000000","0.00000000"],["69808.31000000","0.00448000"],["69808.30000000","0.00009000"]],"a":[["77564.79000000","4.46084000"],["77565.80000000","0.00000000"]]}}
{"type":"depth","received_at_ms":1788331895374,"data":{"e":"depthUpdate","E":1788331895514,"s":"BTCUSDT","U":99555833492,"u":99555833524,"b":[["77564.78000000","1.24040000"],["77564.77000000","0.00118000"],["77561.78000000","0.11733000"],["77561.06000000","0.00000000"],["77560.31000000","0.50284000"],["77559.37000000","0.00000000"],["77558.60000000","0.00812000"],["77557.04000000","0.00000000"],["77555.77000000","0.00332000"],["77550.06000000","0.00257000"],["77549.30000000","0.00000000"],["77533.09000000","0.00000000"],["77494.32000000","0.00000000"],["77463.31000000","0.00000000"],["76634.00000000","0.00043000"],["69808.31000000","0.00448000"],["62051.83000000","0.00032000"]],"a":[["77582.33000000","0.00000000"],["77621.13000000","0.00000000"],["77652.16000000","0.00000000"]]}}
{"type":"depth","received_at_ms":1788331895473,"data":{"e":"depthUpdate","E":1788331895614,"s":"BTCUSDT","U":99555833525,"u":99555833540,"b":[["77550.06000000","0.00000000"],["77550.05000000","0.00382000"],["77358.32000000","0.00000000"],["77351.92000000","0.00813000"],["69808.31000000","0.00448000"],["62052.00000000","0.03206000"],["62051.83000000","0.00000000"]],"a":[]}}
{"type":"trade","received_at_ms":1788331895562,"data":{"e":"trade","E":1788331895703,"s":"BTCUSDT","t":6646634897,"p":"77564.78000000","q":"0.00100000","T":1788331895702,"m":true,"M":true}}
{"type":"depth","received_at_ms":1788331895575,"data":{"e":"depthUpdate","E":1788331895714,"s":"BTCUSDT","U":99555833541,"u":99555833554,"b":[["77564.78000000","1.37662000"],["77555.77000000","0.00000000"],["77555.35000000","0.00000000"],["77550.06000000","0.00257000"],["77550.05000000","0.00125000"],["77463.32000000","0.00412000"],["69808.31000000","0.00448000"],["69808.30000000","0.00000000"]],"a":[["78728.27000000","0.00030000"]]}}
{"type":"depth","received_at_ms":1788331895674,"data":{"e":"depthUpdate","E":1788331895814,"s":"BTCUSDT","U":99555833555,"u":99555833590,"b":[["77564.78000000","1.37669000"],["77558.85000000","0.00208000"],["77558.60000000","0.00819000"],["77558.50000000","0.09908000"],["77555.57000000","0.00340000"],["77551.72000000","0.00000000"],["77550.06000000","0.00000000"],["77550.01000000","0.00257000"],["77548.09000000","0.00000000"],["77548.01000000","0.01200000"],["77367.13000000","0.00095000"],["76168.61000000","0.00043000"],["69808.31000000","0.00448000"],["62051.82000000","0.00000000"]],"a":[["77630.43000000","0.25786000"],["77654.32000000","0.00231000"],["77661.22000000","0.00000000"],["77726.12000000","0.00000000"]]}}
{"type":"depth","received_at_ms":1788331895773,"data":{"e":"depthUpdate","E":1788331895914,"s":"BTCUSDT","U":99555833591,"u":99555833599,"b":[["77564.78000000","1.23947000"],["77533.10000000","0.52312000"],["69808.31000000","0.00464000"],["69808.00000000","0.09261000"]],"a":[["77564.79000000","4.46184000"]]}}
{"type":"trade","received_at_ms":1788331895873,"data":{"e":"trade","E":1788331896013,"s":"BTCUSDT","t":6646634898,"p":"77564.79000000","q":"0.00037000","T":1788331896013,"m":false,"M":true}}
{"type":"depth","received_at_ms":1788331895874,"data":{"e":"depthUpdate","E":1788331896014,"s":"BTCUSDT","U":99555833600,"u":99555833609,"b":[["77564.78000000","1.37467000"],["77550.02000000","0.00257000"],["77550.01000000","0.00000000"],["76401.30000000","0.00030000"],["69808.31000000","0.00432000"],["62051.83000000","0.00032000"]],"a":[["77564.79000000","4.46147000"]]}}
{"type":"depth","received_at_ms":1788331895974,"data":{"e":"depthUpdate","E":1788331896114,"s":"BTCUSDT","U":99555833610,"u":99555833629,"b":[["77564.78000000","1.23947000"],["77551.72000000","0.00000000"],["77548.01000000","0.01200000"],["77494.03000000","0.00007000"],["77279.63000000","0.00007000"],["75703.23000000","0.00063000"],["69808.31000000","0.00473000"]],"a":[]}}
{"type":"depth","received_at_ms":1788331896078,"data":{"e":"depthUpdate","E":1788331896214,"s":"BTCUSDT","U":99555833630,"u":99555833641,"b":[["77550.03000000","0.00257000"],["77550.02000000","0.00000000"],["77545.51000000","0.00007000"],["71383.07000000","0.00015000"],["69808.31000000","0.00457000"],["62051.83000000","0.00000000"],["62051.82000000","0.00000000"]],"a":[["77576.54000000","0.00007000"]]}}
{"type":"depth","received_at_ms":1788331896173,"data":{"e":"depthUpdate","E":1788331896314,"s":"BTCUSDT","U":99555833642,"u":99555833662,"b":[["77564.78000000","1.23947000"],["77564.77000000","0.00118000"],["77562.01000000","0.04435000"],["77561.79000000","0.00000000"],["77561.78000000","0.00014000"],["77561.00000000","0.00557000"],["77560.34000000","0.00007000"],["77560.33000000","0.11709000"],["69808.31000000","0.00473000"],["62052.00000000","0.03206000"]],"a":[["77564.79000000","4.45829000"],["77566.01000000","0.00693000"]]}}
{"type":"depth","received_at_ms":1788331896275,"data":{"e":"depthUpdate","E":1788331896414,"s":"BTCUSDT","U":99555833663,"u":99555833690,"b":[["77562.00000000","0.03028000"],["77561.80000000","0.11655000"],["77561.78000000","0.00000000"],["77561.00000000","0.00557000"],["77560.33000000","0.11723000"],["77555.36000000","0.00335000"],["77550.04000000","0.00257000"],["77550.03000000","0.00000000"],["75237.84000000","0.00044000"],["69808.31000000","0.00457000"],["62052.00000000","0.03206000"]],"a":[["77564.85000000","0.05014000"],["77566.01000000","0.00707000"],["77567.59000000","0.30014000"]]}}
{"type":"depth","received_at_ms":1788331896373,"data":{"e":"depthUpdate","E":1788331896514,"s":"BTCUSDT","U":99555833691,"u":99555833696,"b":[["77555.36000000","0.00000000"],["69808.31000000","0.00473000"],["62051.83000000","0.00032000"]],"a":[["77621.14000000","0.00412000"]]}}
{"type":"depth","received_at_ms":1788331896472,"data":{"e":"depthUpdate","E":1788331896614,"s":"BTCUSDT","U":99555833697,"u":99555833704,"b":[["77550.05000000","0.00382000"],["77550.04000000","0.00000000"],["69808.31000000","0.00457000"],["62052.00000000","0.03206000"],["62051.83000000","0.00000000"]],"a":[]}}
{"type":"depth","received_at_ms":1788331896572,"data":{"e":"depthUpdate","E":1788331896714,"s":"BTCUSDT","U":99555833705,"u":99555833709,"b":[["69808.31000000","0.00457000"]],"a":[["77652.17000000","0.00412000"],["78728.27000000","0.00030000"]]}}
{"type":"depth","received_at_ms":1788331896672,"data":{"e":"depthUpdate","E":1788331896814,"s":"BTCUSDT","U":99555833710,"u":99555833719,"b":[["77550.06000000","0.00257000"],["77550.05000000","0.00125000"],["74772.45000000","0.00044000"],["71383.07000000","0.00000000"],["69808.31000000","0.00457000"],["62051.82000000","0.00000000"]],"a":[["77597.27000000","0.00670000"],["77621.28000000","0.00008000"]]}}
{"type":"depth","received_at_ms":1788331896775,"data":{"e":"depthUpdate","E":1788331896914,"s":"BTCUSDT","U":99555833720,"u":99555833724,"b":[["77494.33000000","0.00412000"],["69808.31000000","0.00457000"]],"a":[]}}
{"type":"depth","received_at_ms":1788331896872,"data":{"e":"depthUpdate","E":1788331897014,"s":"BTCUSDT","U":99555833725,"u":99555833736,"b":[["77564.78000000","1.37374000"],["77521.74000000","0.34844000"],["77501.99000000","0.00000000"],["76401.30000000","0.00030000"],["69808.31000000","0.00473000"],["69808.00000000","0.09261000"],["62052.00000000","0.03206000"],["62051.83000000","0.00032000"]],"a":[]}}
{"type":"depth","received_at_ms":1788331896972,"data":{"e":"depthUpdate","E":1788331897114,"s":"BTCUSDT","U":99555833737,"u":99555833755,"b":[["77564.78000000","1.23947000"],["77551.72000000","0.00000000"],["77548.01000000","0.00400000"],["77499.61000000","0.00007000"],["77429.10000000","0.00020000"],["77272.60000000","0.00007000"],["74307.06000000","0.00044000"],["69808.31000000","0.00457000"]],"a":[["77564.79000000","4.45927000"],["77700.57000000","0.00020000"],["77839.21000000","0.00000000"]]}}
{"type":"trade","received_at_ms":1788331897045,"data":{"e":"trade","E":1788331897186,"s":"BTCUSDT","t":6646634899,"p":"77564.79000000","q":"0.00257000","T":1788331897186,"m":false,"M":true}}
{"type":"trade","received_at_ms":1788331897051,"data":{"e":"trade","E":1788331897191,"s":"BTCUSDT","t":6646634900,"p":"77564.79000000","q":"0.00037000","T":1788331897191,"m":false,"M":true}}
{"type":"depth","received_at_ms":1788331897072,"data":{"e":"depthUpdate","E":1788331897214,"s":"BTCUSDT","U":99555833756,"u":99555833765,"b":[["77545.51000000","0.00000000"],["69808.31000000","0.00464000"],["69808.30000000","0.00009000"],["62051.83000000","0.00000000"],["62051.82000000","0.00000000"]],"a":[["77564.79000000","4.45633000"],["77576.54000000","0.00000000"]]}}
{"type":"depth","received_at_ms":1788331897172,"data":{"e":"depthUpdate","E":1788331897314,"s":"BTCUSDT","U":99555833766,"u":99555833769,"b":[["77545.51000000","0.00007000"],["69808.31000000","0.00432000"]],"a":[["77576.54000000","0.00007000"]]}}
