{"type":"snapshot","received_at_ms":1788331803671,"data":{"lastUpdateId":99555803695,"bids":[["77597.06000000","1.25958000"],["77597.05000000","0.00118000"],["77597.04000000","0.00013000"],["77596.88000000","0.00008000"],["77596.80000000","0.00007000"],["77596.48000000","0.00665000"],["77596.45000000","0.00014000"],["77596.44000000","0.03234000"],["77596.11000000","0.00007000"],["77596.01000000","0.00014000"],["77596.00000000","0.03035000"],["77595.87000000","0.00007000"],["77595.82000000","0.00007000"],["77595.62000000","0.00014000"],["77595.61000000","0.28645000"],["77595.60000000","0.00021000"],["77595.23000000","0.00014000"],["77595.22000000","0.25810000"],["77595.19000000","0.00014000"],["77595.09000000","0.00007000"],["77594.54000000","0.00007000"],["77594.53000000","0.38698000"],["77594.52000000","0.00007000"],["77594.41000000","0.00339000"],["77594.36000000","0.01318000"],["77594.15000000","0.00027000"],["77594.00000000","0.03014000"],["77593.97000000","0.00007000"],["77593.55000000","0.00007000"],["77593.28000000","0.00007000"],["77592.95000000","0.00007000"],["77592.84000000","0.00341000"],["77592.80000000","0.00538000"],["77592.73000000","0.00007000"],["77592.69000000","0.11335000"],["77592.54000000","0.00007000"],["77592.27000000","0.00007000"],["77592.24000000","0.00008000"],["77592.00000000","0.03029000"],["77591.97000000","0.00013000"],["77591.94000000","0.00007000"],["77591.81000000","0.00012000"],["77591.80000000","0.01400000"],["77591.79000000","0.11412000"],["77591.78000000","1.17083000"],["77591.77000000","0.00007000"],["77591.73000000","0.00007000"],["77591.55000000","0.00886000"],["77590.96000000","1.93226000"],["77590.77000000","0.02899000"],["77590.75000000","0.00330000"],["77590.42000000","0.00098000"],["77590.31000000","0.01070000"],["77590.30000000","0.00400000"],["77590.21000000","0.00333000"],["77590.02000000","0.00008000"],["77590.00000000","0.03000000"],["77589.59000000","0.00257000"],["77589.31000000","0.00125000"],["77589.30000000","0.00020000"],["77589.07000000","0.01063000"],["77589.03000000","1.31471000"],["77588.94000000","0.00007000"],["77588.84000000","0.00007000"],["77588.79000000","0.00322000"],["77588.65000000","0.00338000"],["77588.52000000","0.00118000"],["77588.36000000","0.00400000"],["77588.31000000","0.03873000"],["77588.18000000","0.00120000"],["77588.07000000","0.00007000"],["77588.01000000","0.00192000"],["77588.00000000","0.03000000"],["77587.78000000","0.00175000"],["77587.77000000","1.18295000"],["77587.66000000","0.00644000"],["77587.65000000","0.00048000"],["77587.50000000","0.00048000"],["77587.32000000","0.00644000"],["77587.31000000","0.00048000"],["77587.12000000","0.00008000"],["77586.96000000","0.03000000"],["77586.83000000","0.00400000"],["77586.60000000","0.00400000"],["77586.53000000","0.00329000"],["77586.48000000","0.00014000"],["77586.34000000","0.00010000"],["77586.26000000","0.00007000"],["77586.14000000","0.00007000"],["77586.01000000","1.93226000"],["77586.00000000","0.03000000"],["77585.80000000","0.00027000"],["77585.74000000","0.00007000"],["77585.33000000","0.00332000"],["77585.13000000","1.31471000"],["77584.71000000","0.12889000"],["77584.65000000","0.00400000"],["77584.48000000","0.00015000"],["77584.31000000","0.00069000"],["77584.22000000","0.34778000"],["77584.20000000","1.05647000"],["77584.05000000","0.16870000"],["77584.00000000","0.03007000"],["77583.92000000","0.00163000"],["77583.77000000","0.00333000"],["77583.50000000","0.00007000"],["77583.35000000","0.00007000"],["77582.70000000","0.00400000"],["77582.54000000","0.00014000"],["77582.26000000","0.00008000"],["77582.24000000","0.00008000"],["77582.06000000","0.12000000"],["77582.00000000","0.03000000"],["77581.96000000","0.00007000"],["77581.84000000","0.32996000"],["77581.80000000","0.00104000"],["77581.75000000","0.00056000"],["77581.54000000","0.00028000"],["77581.27000000","1.93226000"],["77581.25000000","1.31471000"],["77581.14000000","0.00213000"],["77580.84000000","0.00341000"],["77580.80000000","0.00115000"],["77580.75000000","0.00400000"],["77580.56000000","0.00007000"],["77580.01000000","0.45361000"],["77580.00000000","0.03000000"],["77579.15000000","0.04000000"],["77579.00000000","0.00012000"],["77578.84000000","0.00007000"],["77578.80000000","0.00400000"],["77578.75000000","0.02000000"],["77578.62000000","0.00010000"],["77578.60000000","0.00014000"],["77578.38000000","0.04000000"],["77578.34000000","0.02000000"],["77578.32000000","0.02000000"],["77578.00000000","0.03000000"],["77577.85000000","0.00027000"],["77577.78000000","0.00007000"],["77577.76000000","0.00333000"],["77577.71000000","0.00007000"],["77577.66000000","0.00008000"],["77577.39000000","0.10000000"],["77577.36000000","0.00008000"],["77577.34000000","0.12890000"],["77577.30000000","1.31471000"],["77576.88000000","0.00007000"],["77576.85000000","0.00400000"],["77576.72000000","0.00008000"],["77576.54000000","1.08811000"],["77576.30000000","0.00128000"],["77576.04000000","0.02000000"],["77576.00000000","0.03265000"],["77575.45000000","0.34778000"],["77575.27000000","0.04000000"],["77574.97000000","0.00007000"],["77574.92000000","0.00207000"],["77574.90000000","0.00400000"],["77574.87000000","0.00035000"],["77574.86000000","0.02000000"],["77574.68000000","0.02000000"],["77574.66000000","0.00014000"],["77574.60000000","0.10422000"],["77574.51000000","0.03210000"],["77574.50000000","0.04000000"],["77574.48000000","0.62857000"],["77574.47000000","0.02000000"],["77574.46000000","1.93226000"],["77574.17000000","0.16870000"],["77574.00000000","0.03000000"],["77573.78000000","0.00156000"],["77573.76000000","0.00124000"],["77573.71000000","0.10422000"],["77573.42000000","0.00126000"],["77572.95000000","0.00400000"],["77572.86000000","1.31471000"],["77572.64000000","0.12891000"],["77572.62000000","0.00007000"],["77572.48000000","0.00008000"],["77572.18000000","0.00043000"],["77572.07000000","0.00257000"],["77572.01000000","0.88423000"],["77572.00000000","0.03000000"],["77571.88000000","0.25000000"],["77571.71000000","0.01996000"],["77571.00000000","0.00400000"],["77570.90000000","0.00010000"],["77570.72000000","0.00014000"],["77570.02000000","0.00027000"],["77570.00000000","0.03327000"],["77569.90000000","0.00008000"],["77569.78000000","1.93226000"],["77569.39000000","0.00007000"],["77569.34000000","0.00007000"],["77569.05000000","0.00400000"],["77568.96000000","0.00015000"],["77568.91000000","0.58848000"],["77568.90000000","1.31471000"],["77568.06000000","0.05301000"],["77568.00000000","0.03265000"],["77567.61000000","0.44226000"],["77567.60000000","0.00008000"],["77567.59000000","0.04523000"],["77567.26000000","0.00400000"],["77567.25000000","0.00586000"],["77567.20000000","0.00400000"],["77567.10000000","0.00400000"],["77567.07000000","0.00335000"],["77567.00000000","0.70000000"],["77566.78000000","0.00014000"],["77566.59000000","0.00007000"],["77566.51000000","0.00007000"],["77566.38000000","0.00125000"],["77566.27000000","0.51859000"],["77566.24000000","0.09627000"],["77566.20000000","0.00200000"],["77566.04000000","0.00123000"],["77566.02000000","0.00028000"],["77566.00000000","0.03000000"],["77565.95000000","0.00200000"],["77565.94000000","0.16870000"],["77565.46000000","0.03210000"],["77565.21000000","0.00212000"],["77565.15000000","0.00400000"],["77565.13000000","0.00412000"],["77565.01000000","1.50449000"],["77565.00000000","0.34778000"],["77564.98000000","1.93226000"],["77564.96000000","1.08358000"],["77564.45000000","0.00059000"],["77564.03000000","0.00007000"],["77564.00000000","0.03000000"],["77563.80000000","0.00007000"],["77563.60000000","0.00012000"],["77563.49000000","0.00193000"],["77563.35000000","0.64493000"],["77563.20000000","0.00400000"],["77563.18000000","0.00010000"],["77563.08000000","0.00010000"],["77562.84000000","0.00014000"],["77562.72000000","0.00008000"],["77562.24000000","0.00329000"],["77562.21000000","0.00027000"],["77562.14000000","0.00008000"],["77562.00000000","0.73000000"],["77561.75000000","0.00360000"],["77561.20000000","0.00408000"],["77561.17000000","0.00007000"],["77561.01000000","0.00007000"],["77561.00000000","0.00515000"],["77560.95000000","0.02000000"],["77560.24000000","0.02531000"],["77560.14000000","0.00007000"],["77560.09000000","0.02000000"],["77560.01000000","1.28059000"],["77560.00000000","1.96226000"],["77559.72000000","0.79555000"],["77558.90000000","0.00014000"],["77558.73000000","0.34828000"],["77558.72000000","1.08358000"],["77558.32000000","0.00007000"],["77558.26000000","0.00008000"],["77558.22000000","0.00007000"],["77558.14000000","0.16870000"],["77558.00000000","0.04000000"],["77557.84000000","0.00008000"],["77556.82000000","0.00007000"],["77556.78000000","0.02000000"],["77556.76000000","0.34778000"],["77556.59000000","0.54625000"],["77556.41000000","0.95884000"],["77556.22000000","0.00007000"],["77556.07000000","0.33882000"],["77556.00000000","0.03000000"],["77555.46000000","0.00010000"],["77555.43000000","0.00007000"],["77555.30000000","1.93226000"],["77554.40000000","0.00027000"],["77554.35000000","0.11557000"],["77554.02000000","0.00007000"],["77554.00000000","0.03000000"],["77553.99000000","0.00007000"],["77553.84000000","1.08358000"],["77553.44000000","0.34845000"],["77553.25000000","1.51703000"],["77553.24000000","1.29976000"],["77553.10000000","0.64501000"],["77552.96000000","0.00008000"],["77552.63000000","0.00007000"],["77552.00000000","0.03007000"],["77551.83000000","0.00021000"],["77551.60000000","0.34831000"],["77550.63000000","1.93226000"],["77550.58000000","0.00007000"],["77550.23000000","0.16870000"],["77550.00000000","0.03007000"],["77549.85000000","1.08358000"],["77549.84000000","0.00007000"],["77549.24000000","0.50408000"],["77549.23000000","0.25775000"],["77548.90000000","0.34778000"],["77548.74000000","0.64505000"],["77548.32000000","0.00007000"],["77548.14000000","0.02000000"],["77548.13000000","0.02000000"],["77548.00000000","0.03000000"],["77547.85000000","0.00200000"],["77547.74000000","0.00010000"],["77547.48000000","0.02000000"],["77547.31000000","0.00007000"],["77546.88000000","0.01141000"],["77546.55000000","0.00027000"],["77546.32000000","0.00007000"],["77546.00000000","0.03000000"],["77545.68000000","0.00008000"],["77545.43000000","1.61625000"],["77545.42000000","1.93226000"],["77544.42000000","0.04000000"],["77544.37000000","0.00007000"],["77544.26000000","0.00007000"],["77544.12000000","1.08358000"],["77544.00000000","0.03000000"],["77543.67000000","0.34835000"],["77543.59000000","0.34835000"],["77543.20000000","0.00008000"],["77542.61000000","0.79573000"],["77542.24000000","0.02000000"],["77542.03000000","1.06425000"],["77542.00000000","0.03000000"],["77541.99000000","0.12848000"],["77541.91000000","0.06463000"],["77541.63000000","1.07078000"],["77541.54000000","0.02000000"],["77541.47000000","0.00007000"],["77541.36000000","0.02000000"],["77541.29000000","0.00007000"],["77541.23000000","0.00644000"],["77540.68000000","0.02000000"],["77540.41000000","0.02000000"],["77540.33000000","0.02000000"],["77540.22000000","0.79575000"],["77540.18000000","1.43136000"],["77540.06000000","1.27735000"],["77540.02000000","0.00010000"],["77540.00000000","0.03007000"],["77539.81000000","0.02000000"],["77539.63000000","0.16870000"],["77539.51000000","0.02000000"],["77539.04000000","0.00007000"],["77538.68000000","0.00007000"],["77538.47000000","0.00027000"],["77538.00000000","0.03007000"],["77537.96000000","0.00632000"],["77537.92000000","0.00015000"],["77537.72000000","1.61357000"],["77537.71000000","2.22998000"],["77537.68000000","0.12841000"],["77537.55000000","0.00432000"],["77537.37000000","0.02000000"],["77536.62000000","0.12782000"],["77536.10000000","1.93226000"],["77536.00000000","0.03007000"],["77535.88000000","0.00007000"],["77535.81000000","0.00010000"],["77535.45000000","0.01130000"],["77535.34000000","1.08358000"],["77534.80000000","0.00100000"],["77534.49000000","0.00007000"],["77534.13000000","0.00007000"],["77534.00000000","0.03000000"],["77533.44000000","0.00008000"],["77533.20000000","0.00007000"],["77532.31000000","0.54836000"],["77532.30000000","1.27758000"],["77532.29000000","0.00507000"],["77532.17000000","0.00007000"],["77532.05000000","0.00321000"],["77532.04000000","0.34778000"],["77532.00000000","0.03000000"],["77531.17000000","0.16870000"],["77530.66000000","0.00027000"],["77530.59000000","0.00423000"],["77530.30000000","0.00007000"],["77530.16000000","0.00008000"],["77530.08000000","0.00007000"],["77530.00000000","0.03000000"],["77529.41000000","0.00424000"],["77529.08000000","0.59534000"],["77528.73000000","0.02000000"],["77528.72000000","0.02000000"],["77528.07000000","0.02000000"],["77528.00000000","0.03000000"],["77527.68000000","0.00007000"],["77527.51000000","0.00007000"],["77527.48000000","0.03210000"],["77526.78000000","1.93226000"],["77526.35000000","0.00321000"],["77526.00000000","0.03000000"],["77525.79000000","0.00322000"],["77525.78000000","0.40959000"],["77525.77000000","1.08358000"],["77525.68000000","0.00456000"],["77525.02000000","0.02000000"],["77525.01000000","0.02000000"],["77524.76000000","0.00007000"],["77524.72000000","0.00007000"],["77524.58000000","0.00010000"],["77524.49000000","0.00010000"],["77524.00000000","0.03000000"],["77523.89000000","0.00008000"],["77523.87000000","0.07410000"],["77523.68000000","0.00008000"],["77522.83000000","0.02000000"],["77522.66000000","0.00027000"],["77522.50000000","0.16877000"],["77522.40000000","0.00015000"],["77522.09000000","1.27764000"],["77522.00000000","0.03000000"],["77521.95000000","0.02000000"],["77521.93000000","0.00007000"],["77521.77000000","1.34118000"],["77521.76000000","3.25071000"],["77521.56000000","1.08358000"],["77521.30000000","0.12841000"],["77521.00000000","0.02000000"],["77520.93000000","0.02000000"],["77520.40000000","0.02000000"],["77520.27000000","0.00007000"],["77520.10000000","0.02000000"],["77520.00000000","0.03007000"],["77519.47000000","0.00007000"],["77519.14000000","0.00007000"],["77519.09000000","0.00007000"],["77518.98000000","0.00007000"],["77518.29000000","0.70976000"],["77518.28000000","1.93226000"],["77518.06000000","0.34778000"],["77518.00000000","0.03000000"],["77517.79000000","0.00007000"],["77517.12000000","0.00181000"],["77516.86000000","0.00010000"],["77516.00000000","0.03000000"],["77514.94000000","0.03210000"],["77514.86000000","0.00007000"],["77514.80000000","0.00027000"],["77514.64000000","0.00008000"],["77514.60000000","0.00310000"],["77514.29000000","0.00540000"],["77514.07000000","0.01720000"],["77514.01000000","0.50071000"],["77514.00000000","0.03395000"],["77513.92000000","0.00008000"],["77513.56000000","0.00007000"],["77513.52000000","0.00010000"],["77513.30000000","0.00111000"],["77512.78000000","0.00515000"],["77512.11000000","0.00007000"],["77512.04000000","0.00007000"],["77512.00000000","0.03000000"],["77511.66000000","0.00200000"],["77511.65000000","0.00128000"],["77510.94000000","1.61611000"],["77510.89000000","0.00011000"],["77510.88000000","0.00008000"],["77510.63000000","0.00023000"],["77510.03000000","0.69225000"],["77510.02000000","0.16870000"],["77510.00000000","0.03000000"],["77509.98000000","0.03210000"],["77509.91000000","0.00007000"],["77509.57000000","0.20000000"],["77509.14000000","0.00010000"],["77508.96000000","1.93226000"],["77508.00000000","0.03000000"],["77507.98000000","0.00007000"],["77507.84000000","0.00007000"],["77507.18000000","0.00102000"],["77506.88000000","0.00015000"],["77506.82000000","0.00027000"],["77506.00000000","0.03000000"],["77505.87000000","0.00007000"],["77504.16000000","0.00008000"],["77504.09000000","0.11283000"],["77504.08000000","0.34778000"],["77504.00000000","0.03007000"],["77503.47000000","0.00007000"],["77503.24000000","0.00007000"],["77502.40000000","0.00007000"],["77502.18000000","0.16870000"],["77502.00000000","0.03000000"],["77501.42000000","0.00010000"],["77501.30000000","0.00007000"],["77500.16000000","0.07670000"],["77500.03000000","1.24758000"],["77500.02000000","1.93226000"],["77500.00000000","1.44548000"],["77499.78000000","0.80000000"],["77499.70000000","0.00163000"],["77499.65000000","0.03997000"],["77499.60000000","0.00007000"],["77499.31000000","0.00007000"],["77498.72000000","0.03162000"],["77498.71000000","0.03210000"],["77498.38000000","0.00051000"],["77498.01000000","0.07280000"],["77496.77000000","0.00007000"],["77496.51000000","0.00027000"],["77496.43000000","0.00007000"],["77495.71000000","0.04565000"],["77494.41000000","0.00007000"],["77494.40000000","0.00008000"],["77494.39000000","0.00387000"],["77494.34000000","0.00774000"],["77494.14000000","0.01424000"],["77494.13000000","0.00100000"],["77494.03000000","0.00007000"],["77493.63000000","0.04625000"],["77493.58000000","0.00011000"],["77491.93000000","0.00011000"],["77491.36000000","0.00015000"],["77491.20000000","0.00516000"],["77490.70000000","1.93226000"],["77490.54000000","0.00007000"],["77490.11000000","1.29097000"],["77490.10000000","0.34778000"],["77490.00000000","0.00061000"],["77489.79000000","3.87323000"],["77489.00000000","0.00026000"],["77488.45000000","0.00007000"],["77488.06000000","0.16870000"],["77488.03000000","0.00007000"],["77487.96000000","0.00007000"],["77487.50000000","0.00027000"],["77486.74000000","0.13128000"],["77486.73000000","0.38251000"],["77485.99000000","0.03210000"],["77485.90000000","0.00010000"],["77485.44000000","0.00169000"],["77485.28000000","0.00010000"],["77485.21000000","0.00128000"],["77485.12000000","0.02153000"],["77484.73000000","0.00035000"],["77484.64000000","0.00008000"],["77484.16000000","0.00007000"],["77483.33000000","0.00020000"],["77482.87000000","0.00007000"],["77481.75000000","0.00108000"],["77481.13000000","0.00011000"],["77480.66000000","0.00011000"],["77480.33000000","0.05055000"],["77480.32000000","0.16877000"],["77480.06000000","0.00007000"],["77480.00000000","0.00050000"],["77479.60000000","0.00027000"],["77478.63000000","0.00109000"],["77478.37000000","0.00007000"],["77478.04000000","0.00051000"],["77477.78000000","0.10988000"],["77476.12000000","0.34778000"],["77475.84000000","0.00015000"],["77475.74000000","0.00007000"],["77475.43000000","0.00011000"],["77475.42000000","0.00011000"],["77474.88000000","0.00008000"],["77474.64000000","0.01794000"],["77474.63000000","0.05893000"],["77474.50000000","0.00007000"],["77473.46000000","0.00011000"],["77473.21000000","0.00007000"],["77472.14000000","0.00097000"],["77472.00000000","0.00007000"],["77471.52000000","0.00482000"],["77471.01000000","0.00027000"],["77470.65000000","0.00007000"],["77470.58000000","0.00179000"],["77470.00000000","0.00050000"],["77469.84000000","0.00020000"],["77469.81000000","0.00011000"],["77468.92000000","0.00007000"],["77468.46000000","0.00012000"],["77468.35000000","0.00007000"],["77467.52000000","0.00010000"],["77467.13000000","0.05058000"],["77467.12000000","0.16870000"],["77466.65000000","0.00013000"],["77466.44000000","0.00010000"],["77466.12000000","0.00007000"],["77466.04000000","0.00010000"],["77465.57000000","0.00011000"],["77465.52000000","0.00015000"],["77465.12000000","0.00008000"],["77465.06000000","0.01787000"],["77464.05000000","0.00007000"],["77463.87000000","0.12841000"],["77463.40000000","0.00021000"],["77463.25000000","0.00027000"],["77463.11000000","0.00100000"],["77462.14000000","0.34778000"],["77462.06000000","0.00009000"],["77461.89000000","0.00007000"],["77461.38000000","1.15673000"],["77461.15000000","3.87467000"],["77460.38000000","0.00012000"],["77460.32000000","0.00035000"],["77460.16000000","0.00007000"],["77460.02000000","0.00053000"],["77460.00000000","0.01671000"],["77459.76000000","0.00502000"],["77459.68000000","0.00018000"],["77459.66000000","0.00011000"],["77459.31000000","0.00007000"],["77459.11000000","0.00010000"],["77458.68000000","0.00031000"],["77458.33000000","0.00033000"],["77458.01000000","0.00007000"],["77457.77000000","0.00007000"],["77457.63000000","0.00007000"],["77457.60000000","0.00019000"],["77457.56000000","0.00040000"],["77457.53000000","0.00007000"],["77457.14000000","0.00008000"],["77456.77000000","0.00020000"],["77456.27000000","0.08999000"],["77456.26000000","0.16870000"],["77456.15000000","0.01547000"],["77455.88000000","0.01546000"],["77455.73000000","0.00022000"],["77455.49000000","0.00027000"],["77455.46000000","0.00007000"],["77455.36000000","0.00008000"],["77454.98000000","0.00007000"],["77454.84000000","0.00046000"],["77454.55000000","0.00128000"],["77454.54000000","0.00085000"],["77454.16000000","0.03210000"],["77453.95000000","0.09188000"],["77453.72000000","0.00543000"],["77453.24000000","0.00007000"],["77452.32000000","0.00265000"],["77452.16000000","0.00007000"],["77451.69000000","0.00391000"],["77451.28000000","0.00009000"],["77450.01000000","0.29897000"],["77450.00000000","1.00122000"],["77449.36000000","0.00007000"],["77449.28000000","0.00011000"],["77449.24000000","0.00009000"],["77448.97000000","0.00007000"],["77448.68000000","0.00128000"],["77448.67000000","0.00071000"],["77448.49000000","0.16870000"],["77448.17000000","0.00128000"],["77448.16000000","0.34778000"],["77448.00000000","0.00014000"],["77447.77000000","0.00039000"],["77447.51000000","0.00011000"],["77447.32000000","0.77132000"],["77447.31000000","0.00010000"],["77447.29000000","2.15567000"],["77447.27000000","0.00672000"],["77447.04000000","0.00013000"],["77446.96000000","0.00069000"],["77446.76000000","0.10000000"],["77446.62000000","0.00007000"],["77446.53000000","0.00007000"],["77446.29000000","0.00008000"],["77446.15000000","0.00046000"],["77446.00000000","0.00013000"],["77445.60000000","0.00008000"],["77444.80000000","0.00015000"],["77444.61000000","0.03210000"],["77444.44000000","0.00008000"],["77444.01000000","0.04271000"],["77444.00000000","0.10000000"],["77443.85000000","0.00025000"],["77443.78000000","0.04000000"],["77443.71000000","0.00047000"],["77443.53000000","0.00009000"],["77443.35000000","0.00007000"],["77443.34000000","0.00019000"],["77443.20000000","0.00027000"],["77442.85000000","0.00021000"],["77442.65000000","0.00007000"],["77442.62000000","0.00021000"],["77441.83000000","0.00010000"],["77441.48000000","0.00021000"],["77441.17000000","0.00078000"],["77441.04000000","0.00007000"],["77440.95000000","0.00008000"],["77440.73000000","0.51412000"],["77440.72000000","0.16870000"],["77440.65000000","0.00007000"],["77440.48000000","0.00008000"],["77440.30000000","0.00007000"],["77440.26000000","0.00592000"],["77440.00000000","0.00246000"],["77439.90000000","0.00013000"],["77439.41000000","0.02019000"],["77438.37000000","0.00007000"],["77438.26000000","1.54466000"],["77437.80000000","0.00061000"],["77437.66000000","0.00007000"],["77437.51000000","0.00083000"],["77437.50000000","0.00053000"],["77437.40000000","0.00011000"],["77437.11000000","0.00007000"],["77436.46000000","0.00065000"],["77436.42000000","0.00007000"],["77435.34000000","0.00027000"],["77435.12000000","0.00008000"],["77434.39000000","0.00049000"],["77434.38000000","0.00016000"],["77434.19000000","0.34778000"],["77434.00000000","0.00007000"],["77433.72000000","0.00013000"],["77433.33000000","0.00330000"],["77433.24000000","0.00016000"],["77433.01000000","0.00043000"],["77432.95000000","0.16870000"],["77432.91000000","0.00128000"],["77432.68000000","0.00007000"],["77432.52000000","0.00007000"],["77431.63000000","0.00007000"],["77431.00000000","0.00064000"],["77430.79000000","0.00009000"],["77430.77000000","1.20000000"],["77430.62000000","0.00016000"],["77430.57000000","0.00043000"],["77430.20000000","0.00133000"],["77430.12000000","0.00007000"],["77430.00000000","0.00078000"],["77429.81000000","0.00007000"],["77429.60000000","0.00041000"],["77429.50000000","0.00008000"],["77429.28000000","0.00015000"],["77428.58000000","0.07670000"],["77428.57000000","0.00064000"],["77428.50000000","0.00016000"],["77428.46000000","0.00010000"],["77428.00000000","0.11557000"],["77427.73000000","0.00015000"],["77427.61000000","0.00044000"],["77427.60000000","0.00218000"],["77427.55000000","0.00007000"],["77427.53000000","0.00027000"],["77426.93000000","0.00007000"],["77426.76000000","0.03523000"],["77426.43000000","0.00039000"],["77426.29000000","0.00032000"],["77426.12000000","0.00035000"],["77425.86000000","0.00020000"],["77425.18000000","0.16870000"],["77425.00000000","0.00409000"],["77424.80000000","0.00017000"],["77424.74000000","0.00049000"],["77424.54000000","0.00007000"],["77424.31000000","0.00007000"],["77424.24000000","0.00037000"],["77424.23000000","0.00296000"],["77423.79000000","0.05113000"],["77423.50000000","0.00190000"],["77423.24000000","0.00039000"],["77423.15000000","0.00011000"],["77423.07000000","0.00054000"],["77422.73000000","0.00260000"],["77422.60000000","0.34778000"],["77422.58000000","3.87660000"],["77422.57000000","0.00062000"],["77422.22000000","0.00046000"],["77422.08000000","0.00007000"],["77421.81000000","0.00042000"],["77421.46000000","0.00516000"],["77421.11000000","0.00008000"],["77420.72000000","0.00007000"],["77420.66000000","0.00007000"],["77420.53000000","0.00009000"],["77420.02000000","0.00011000"],["77420.00000000","0.00556000"],["77419.61000000","0.00007000"],["77419.60000000","0.00027000"],["77419.35000000","0.00105000"],["77419.34000000","0.00008000"],["77418.74000000","0.00012000"],["77418.49000000","0.00007000"],["77418.48000000","0.00144000"],["77418.41000000","0.00575000"],["77418.28000000","0.00023000"],["77417.65000000","0.00042000"],["77417.64000000","0.00109000"],["77417.41000000","0.16870000"],["77416.80000000","0.00008000"],["77416.78000000","0.00007000"],["77416.72000000","0.00010000"],["77416.66000000","0.00014000"],["77416.42000000","0.00334000"],["77416.38000000","0.11557000"],["77416.32000000","0.00008000"],["77416.28000000","0.00941000"],["77416.04000000","0.00008000"],["77415.95000000","0.00007000"],["77415.69000000","4.47824000"],["77415.27000000","0.00010000"],["77415.00000000","0.00007000"],["77414.48000000","0.00017000"],["77414.18000000","0.00007000"],["77414.16000000","0.00030000"],["77413.89000000","0.00011000"],["77413.76000000","0.00015000"],["77413.46000000","0.00380000"],["77413.03000000","0.00010000"],["77412.91000000","0.00268000"],["77412.90000000","0.00039000"],["77412.03000000","0.00007000"],["77411.76000000","0.00095000"],["77411.66000000","0.00019000"],["77411.52000000","0.00572000"],["77411.44000000","0.00007000"],["77411.32000000","0.00033000"],["77411.16000000","0.00027000"],["77410.82000000","3.87718000"],["77410.38000000","0.00007000"],["77410.21000000","0.00008000"],["77410.05000000","0.00010000"],["77410.00000000","0.00050000"],["77409.79000000","0.00027000"],["77409.64000000","0.16870000"],["77409.22000000","0.00007000"],["77409.10000000","0.00774000"],["77409.09000000","0.00065000"],["77408.96000000","0.00010000"],["77408.78000000","0.34778000"],["77408.77000000","2.23342000"],["77408.72000000","0.00010000"],["77408.68000000","0.00011000"],["77408.66000000","0.00007000"],["77408.45000000","0.01091000"],["77408.13000000","0.00179000"],["77408.05000000","0.00085000"],["77408.00000000","0.00007000"],["77407.06000000","0.00291000"],["77406.97000000","0.00094000"],["77406.80000000","0.00033000"],["77406.75000000","0.00024000"],["77406.25000000","0.00007000"],["77405.72000000","0.00066000"],["77405.69000000","0.00017000"],["77405.40000000","0.00160000"],["77405.16000000","0.00010000"],["77404.76000000","0.11557000"],["77404.02000000","0.00176000"],["77404.01000000","0.00007000"],["77403.73000000","0.00007000"],["77403.72000000","0.00010000"],["77403.48000000","0.00011000"],["77403.33000000","0.00037000"],["77403.26000000","0.00027000"],["77403.00000000","0.00019000"],["77402.85000000","0.00009000"],["77402.67000000","3.87763000"],["77402.64000000","0.00436000"],["77402.31000000","0.00126000"],["77402.02000000","0.00007000"],["77401.87000000","0.16880000"],["77401.76000000","0.00061000"],["77401.73000000","0.00007000"],["77401.37000000","0.00007000"],["77401.24000000","0.00007000"],["77400.95000000","0.00017000"],["77400.00000000","1.68082000"],["77399.92000000","0.00056000"],["77399.69000000","0.00007000"],["77399.64000000","0.00018000"],["77399.34000000","0.00012000"],["77399.30000000","0.00491000"],["77399.24000000","0.00258000"],["77399.00000000","0.00010000"],["77398.88000000","0.00007000"],["77398.60000000","0.00009000"],["77398.34000000","0.00018000"],["77398.24000000","0.00015000"],["77397.40000000","0.00028000"],["77397.38000000","0.00007000"],["77397.26000000","0.00008000"],["77397.01000000","0.00018000"],["77397.00000000","3.67873000"],["77396.45000000","0.00007000"],["77396.30000000","0.00007000"],["77395.67000000","0.00013000"],["77395.63000000","0.00007000"],["77394.26000000","0.00027000"],["77394.21000000","0.00129000"],["77394.11000000","0.00031000"],["77394.10000000","0.16870000"],["77393.86000000","0.00007000"],["77393.14000000","0.11557000"],["77392.73000000","0.00007000"],["77392.59000000","0.00026000"],["77392.21000000","0.00048000"],["77391.43000000","0.00771000"],["77391.30000000","0.00009000"],["77391.27000000","0.00008000"],["77390.93000000","0.00018000"],["77390.42000000","0.00010000"],["77390.30000000","0.00007000"],["77390.00000000","0.00050000"],["77389.45000000","0.00007000"],["77389.17000000","0.00010000"],["77389.16000000","0.00008000"],["77389.00000000","0.00129000"],["77388.88000000","0.00033000"],["77388.70000000","0.00018000"],["77388.39000000","0.00007000"],["77388.27000000","0.00559000"],["77388.23000000","0.00030000"],["77388.19000000","0.00007000"],["77388.09000000","0.00007000"],["77388.00000000","0.00011000"],["77387.72000000","0.00165000"],["77387.67000000","0.00059000"],["77387.38000000","0.00122000"],["77387.25000000","0.00093000"],["77387.04000000","0.00008000"],["77386.90000000","0.00012000"],["77386.66000000","0.00958000"],["77386.39000000","0.00007000"],["77386.36000000","0.00035000"],["77385.75000000","0.00007000"],["77385.71000000","0.00049000"],["77385.54000000","0.00023000"],["77385.34000000","0.00010000"],["77385.00000000","0.00018000"],["77384.74000000","0.00022000"],["77384.61000000","0.00007000"],["77384.60000000","0.00050000"],["77384.36000000","0.00007000"],["77384.00000000","0.10011000"],["77383.93000000","0.00008000"],["77383.91000000","0.00020000"],["77383.37000000","0.00008000"],["77383.33000000","0.00040000"],["77383.23000000","0.00129000"],["77383.00000000","0.00007000"],["77382.72000000","0.00015000"],["77382.40000000","0.00113000"],["77382.35000000","0.00011000"],["77382.16000000","0.00043000"],["77381.88000000","0.00035000"],["77381.66000000","0.00813000"],["77381.65000000","1.38347000"],["77381.53000000","0.11557000"],["77381.28000000","0.00007000"],["77381.01000000","0.00516000"],["77380.95000000","0.00025000"],["77380.67000000","0.00007000"],["77380.08000000","0.00027000"],["77380.00000000","0.00078000"],["77379.92000000","0.00012000"],["77379.73000000","0.00007000"],["77379.46000000","0.00030000"],["77379.35000000","0.00007000"],["77378.75000000","0.00470000"],["77378.66000000","0.03224000"],["77378.37000000","0.00007000"],["77378.15000000","0.00387000"],["77377.75000000","0.00010000"],["77377.11000000","0.00011000"],["77376.82000000","0.00027000"],["77376.00000000","0.00007000"],["77375.79000000","0.00008000"],["77375.62000000","0.00022000"],["77375.61000000","0.00033000"],["77375.49000000","0.00025000"],["77375.01000000","0.01271000"],["77375.00000000","0.00081000"],["77374.91000000","0.00009000"],["77374.78000000","0.00009000"],["77373.45000000","0.00016000"],["77373.39000000","0.00019000"],["77373.18000000","0.00007000"],["77373.15000000","0.00007000"],["77373.12000000","7.75831000"],["77371.86000000","0.00068000"],["77371.66000000","0.00045000"],["77371.31000000","0.00018000"],["77371.10000000","0.00016000"],["77371.02000000","0.00075000"],["77370.60000000","0.00038000"],["77370.54000000","0.03512000"],["77370.40000000","0.00007000"],["77370.13000000","0.00010000"],["77370.00000000","0.00057000"],["77369.92000000","0.11557000"],["77369.56000000","0.00026000"],["77369.36000000","0.00228000"],["77369.03000000","0.00027000"],["77368.99000000","0.00009000"],["77368.69000000","0.00008000"],["77368.60000000","0.00021000"],["77368.42000000","0.00021000"]],"asks":[["77597.07000000","6.17896000"],["77597.08000000","0.01090000"],["77597.09000000","0.00013000"],["77597.77000000","0.00014000"],["77597.78000000","0.23295000"],["77597.79000000","0.35681000"],["77597.81000000","0.00014000"],["77597.82000000","0.32253000"],["77597.83000000","0.00007000"],["77598.01000000","0.00007000"],["77598.29000000","0.00014000"],["77598.30000000","0.00414000"],["77598.32000000","0.01711000"],["77598.95000000","0.00007000"],["77599.15000000","0.00644000"],["77599.16000000","0.00407000"],["77599.17000000","0.04159000"],["77599.45000000","0.00122000"],["77599.56000000","0.02042000"],["77599.79000000","0.01302000"],["77600.24000000","0.80241000"],["77600.25000000","0.00400000"],["77600.27000000","0.07500000"],["77600.28000000","0.46877000"],["77600.31000000","0.71269000"],["77600.72000000","0.30007000"],["77600.73000000","0.14100000"],["77600.74000000","0.00342000"],["77600.80000000","0.02028000"],["77601.04000000","0.14289000"],["77601.05000000","0.14280000"],["77601.18000000","0.00014000"],["77601.28000000","0.00007000"],["77601.50000000","0.12559000"],["77601.88000000","0.00644000"],["77601.89000000","0.00117000"],["77601.98000000","0.00007000"],["77602.20000000","0.00400000"],["77602.24000000","0.00014000"],["77602.89000000","0.00007000"],["77603.07000000","0.00007000"],["77603.50000000","0.00200000"],["77603.51000000","0.15000000"],["77603.60000000","0.00013000"],["77604.01000000","0.00400000"],["77604.02000000","0.00340000"],["77604.15000000","0.00400000"],["77604.20000000","0.04000000"],["77604.39000000","0.00400000"],["77604.40000000","0.00167000"],["77604.53000000","0.03210000"],["77604.57000000","0.00257000"],["77604.63000000","0.02000000"],["77604.72000000","0.02600000"],["77604.91000000","0.00800000"],["77604.92000000","0.00150000"],["77605.07000000","0.00335000"],["77605.24000000","0.02899000"],["77605.40000000","0.05400000"],["77605.44000000","0.02400000"],["77605.45000000","0.03000000"],["77605.49000000","0.66835000"],["77605.50000000","0.34778000"],["77605.51000000","1.31471000"],["77605.52000000","0.00007000"],["77605.56000000","0.26136000"],["77605.59000000","0.20515000"],["77605.60000000","0.00038000"],["77605.69000000","0.00007000"],["77606.10000000","0.00400000"],["77606.18000000","0.00014000"],["77606.63000000","0.00339000"],["77606.82000000","0.00322000"],["77606.83000000","0.00120000"],["77607.42000000","0.00027000"],["77607.44000000","0.00007000"],["77607.71000000","0.00007000"],["77607.73000000","0.02800000"],["77607.76000000","0.00008000"],["77608.00000000","0.00007000"],["77608.05000000","0.00400000"],["77608.38000000","0.46545000"],["77608.39000000","0.12885000"],["77608.48000000","0.00007000"],["77608.51000000","0.05000000"],["77608.70000000","0.00128000"],["77608.82000000","0.00007000"],["77608.94000000","0.02000000"],["77609.04000000","0.00337000"],["77609.27000000","0.00122000"],["77609.29000000","0.04600000"],["77609.30000000","0.03000000"],["77609.32000000","0.02800000"],["77609.51000000","0.00010000"],["77609.64000000","0.10417000"],["77609.97000000","0.09622000"],["77609.99000000","0.38672000"],["77610.00000000","0.00400000"],["77610.12000000","0.00014000"],["77610.25000000","0.00332000"],["77610.42000000","0.00007000"],["77610.54000000","0.00007000"],["77610.93000000","0.37616000"],["77610.94000000","0.34805000"],["77611.19000000","0.04400000"],["77611.27000000","0.00007000"],["77611.52000000","0.00008000"],["77611.58000000","0.10417000"],["77611.79000000","0.03210000"],["77611.87000000","1.05149000"],["77611.95000000","0.00400000"],["77612.27000000","0.00336000"],["77612.47000000","0.00007000"],["77612.59000000","0.12900000"],["77612.76000000","1.93226000"],["77612.84000000","0.00290000"],["77613.26000000","0.64471000"],["77613.28000000","0.00327000"],["77613.37000000","0.16870000"],["77613.64000000","0.00007000"],["77613.79000000","1.31471000"],["77613.89000000","0.25788000"],["77613.90000000","0.00400000"],["77614.06000000","0.00014000"],["77614.07000000","0.00007000"],["77614.21000000","0.00120000"],["77614.50000000","0.64450000"],["77615.29000000","0.00007000"],["77615.52000000","0.00015000"],["77615.84000000","0.00038000"],["77615.85000000","0.00400000"],["77616.00000000","0.00265000"],["77616.16000000","0.00193000"],["77616.29000000","0.00039000"],["77616.40000000","0.00008000"],["77616.47000000","0.00008000"],["77616.65000000","0.00120000"],["77616.86000000","0.00007000"],["77617.15000000","0.00060000"],["77617.23000000","0.00010000"],["77617.68000000","1.20987000"],["77617.69000000","3.24697000"],["77617.70000000","0.34778000"],["77617.76000000","0.00014000"],["77617.80000000","0.00400000"],["77618.00000000","0.00014000"],["77618.20000000","0.21686000"],["77618.25000000","0.00200000"],["77618.59000000","0.34801000"],["77618.75000000","0.12958000"],["77619.51000000","0.46815000"],["77619.61000000","0.34801000"],["77619.66000000","0.12890000"],["77619.75000000","0.00400000"],["77619.91000000","0.41262000"],["77619.95000000","0.10883000"],["77619.99000000","0.00600000"],["77620.00000000","0.03000000"],["77620.01000000","0.12841000"],["77620.35000000","0.00008000"],["77621.18000000","0.00007000"],["77621.28000000","0.00008000"],["77621.38000000","0.00329000"],["77621.59000000","0.00119000"],["77621.70000000","0.00400000"],["77621.94000000","0.00014000"],["77622.00000000","0.03000000"],["77622.40000000","0.04747000"],["77622.45000000","0.00007000"],["77623.13000000","0.00007000"],["77623.28000000","0.00008000"],["77623.37000000","1.52774000"],["77623.38000000","1.31471000"],["77623.40000000","1.93226000"],["77623.65000000","0.00400000"],["77624.00000000","0.03007000"],["77624.03000000","0.00127000"],["77624.08000000","0.02000000"],["77624.13000000","0.02600000"],["77624.23000000","0.00008000"],["77624.33000000","0.03210000"],["77624.85000000","0.02600000"],["77624.86000000","0.03000000"],["77624.95000000","0.00010000"],["77625.06000000","0.38665000"],["77625.25000000","0.00007000"],["77625.29000000","0.00027000"],["77625.31000000","0.00007000"],["77625.60000000","0.00400000"],["77625.88000000","0.00014000"],["77626.00000000","0.03000000"],["77626.04000000","0.00339000"],["77626.16000000","0.00008000"],["77626.67000000","0.34798000"],["77626.77000000","0.34797000"],["77627.16000000","0.00400000"],["77627.18000000","0.02800000"],["77627.48000000","0.00424000"],["77627.58000000","0.34785000"],["77627.60000000","1.26986000"],["77627.61000000","1.31471000"],["77627.96000000","0.05000000"],["77628.00000000","0.03000000"],["77628.04000000","0.00007000"],["77628.11000000","0.00008000"],["77628.22000000","0.48067000"],["77628.24000000","1.93226000"],["77628.74000000","0.04600000"],["77629.30000000","1.29848000"],["77629.34000000","0.00128000"],["77629.55000000","0.16870000"],["77629.57000000","0.00007000"],["77629.82000000","0.00014000"],["77630.00000000","0.03000000"],["77630.02000000","0.01278000"],["77630.83000000","0.00007000"],["77631.04000000","0.00023000"],["77631.38000000","0.09442000"],["77631.53000000","1.46596000"],["77631.54000000","1.31471000"],["77631.63000000","0.00007000"],["77631.99000000","0.00008000"],["77632.00000000","0.03007000"],["77632.61000000","0.03210000"],["77632.67000000","0.00010000"],["77633.09000000","0.00027000"],["77633.56000000","1.27581000"],["77633.63000000","0.00007000"],["77633.76000000","0.00014000"],["77633.88000000","0.02400000"],["77633.93000000","0.02800000"],["77633.97000000","0.25000000"],["77634.00000000","0.03000000"],["77634.06000000","1.93226000"],["77634.61000000","0.00007000"],["77635.27000000","0.00634000"],["77635.45000000","1.08293000"],["77635.48000000","1.31471000"],["77635.87000000","0.00008000"],["77635.92000000","0.00008000"],["77636.00000000","0.04000000"],["77636.01000000","0.00032000"],["77636.22000000","0.00100000"],["77636.42000000","0.79483000"],["77637.58000000","0.00007000"],["77637.64000000","0.05210000"],["77637.65000000","0.02559000"],["77637.70000000","0.00007000"],["77638.00000000","0.03000000"],["77638.11000000","0.00200000"],["77638.63000000","0.00430000"],["77638.74000000","1.93226000"],["77638.80000000","0.00008000"],["77638.98000000","0.34778000"],["77638.99000000","0.85753000"],["77639.22000000","0.00007000"],["77639.54000000","0.00429000"],["77640.00000000","0.03000000"],["77640.01000000","0.00007000"],["77640.27000000","0.00010000"],["77640.39000000","0.00010000"],["77640.80000000","0.00008000"],["77641.07000000","1.31471000"],["77641.10000000","0.12890000"],["77641.42000000","1.27568000"],["77641.68000000","0.02000000"],["77642.00000000","0.03000000"],["77642.01000000","0.00007000"],["77642.05000000","0.02800000"],["77642.13000000","0.03000000"],["77642.26000000","0.00027000"],["77643.06000000","0.00007000"],["77643.10000000","0.00007000"],["77643.43000000","0.35935000"],["77643.53000000","0.02600000"],["77643.68000000","1.21924000"],["77643.69000000","1.93226000"],["77643.78000000","0.16870000"],["77644.00000000","0.03000000"],["77644.10000000","0.00386000"],["77644.27000000","0.03000000"],["77644.81000000","0.00007000"],["77645.01000000","0.00018000"],["77645.02000000","0.03210000"],["77645.68000000","0.00008000"],["77645.70000000","0.00007000"],["77645.73000000","0.52161000"],["77645.84000000","0.32993000"],["77646.00000000","0.03000000"],["77646.10000000","1.31471000"],["77646.56000000","0.00015000"],["77647.13000000","0.34778000"],["77647.15000000","1.41925000"],["77647.60000000","0.00007000"],["77647.77000000","0.00021000"],["77648.00000000","0.03007000"],["77648.11000000","0.00010000"],["77648.45000000","0.01278000"],["77648.74000000","0.00007000"],["77649.61000000","0.79463000"],["77649.65000000","1.27555000"],["77650.00000000","0.03000000"],["77650.16000000","0.00027000"],["77650.19000000","1.08358000"],["77650.22000000","1.93226000"],["77650.40000000","0.00007000"],["77650.56000000","0.00008000"],["77650.96000000","0.00007000"],["77651.42000000","0.47635000"],["77651.43000000","0.12782000"],["77651.86000000","0.01535000"],["77652.00000000","0.03000000"],["77652.89000000","0.02011000"],["77653.19000000","0.00007000"],["77653.29000000","0.02400000"],["77653.34000000","0.02800000"],["77653.48000000","1.27547000"],["77653.70000000","0.00007000"],["77653.76000000","0.01740000"],["77653.84000000","0.00322000"],["77653.85000000","0.00111000"],["77653.99000000","0.00012000"],["77654.00000000","0.03000000"],["77654.19000000","0.06534000"],["77654.32000000","0.00008000"],["77654.69000000","0.00541000"],["77655.00000000","0.03210000"],["77655.09000000","0.34778000"],["77655.27000000","0.50256000"],["77655.32000000","1.10125000"],["77655.33000000","1.93226000"],["77655.44000000","0.00008000"],["77655.83000000","1.08368000"],["77655.99000000","0.00007000"],["77656.00000000","0.03000000"],["77656.04000000","0.00200000"],["77656.05000000","0.00380000"],["77656.43000000","0.00321000"],["77656.44000000","0.41262000"],["77656.49000000","0.02600000"],["77656.54000000","0.05400000"],["77656.78000000","0.01278000"],["77656.93000000","0.79455000"],["77657.22000000","0.00007000"],["77657.36000000","0.00007000"],["77658.00000000","0.03000000"],["77658.01000000","0.00027000"],["77658.57000000","0.00007000"],["77658.64000000","0.02000000"],["77658.79000000","0.00007000"],["77659.42000000","0.02600000"],["77660.00000000","1.48501000"],["77660.01000000","0.41262000"],["77660.16000000","1.93226000"],["77660.29000000","0.00007000"],["77660.32000000","0.00008000"],["77661.10000000","0.00007000"],["77661.35000000","0.00673000"],["77661.54000000","0.03000000"],["77661.72000000","0.01159000"],["77661.73000000","1.08358000"],["77661.74000000","0.02800000"],["77661.91000000","2.38875000"],["77662.00000000","0.03000000"],["77662.08000000","0.00015000"],["77662.52000000","0.02400000"],["77662.92000000","1.33050000"],["77663.28000000","0.02400000"],["77663.29000000","0.02200000"],["77663.54000000","0.00007000"],["77663.55000000","0.00010000"],["77664.00000000","0.03007000"],["77664.38000000","0.00007000"],["77665.25000000","0.00128000"],["77665.70000000","0.00007000"],["77665.81000000","0.34778000"],["77665.82000000","3.01611000"],["77666.00000000","0.03000000"],["77667.17000000","0.00007000"],["77667.35000000","0.00007000"],["77667.60000000","0.13707000"],["77668.00000000","0.03000000"],["77668.20000000","0.00007000"],["77668.63000000","0.41262000"],["77669.65000000","0.00912000"],["77669.84000000","0.00008000"],["77670.00000000","0.03000000"],["77670.08000000","0.00008000"],["77671.10000000","0.00007000"],["77671.27000000","0.00010000"],["77671.41000000","1.12697000"],["77671.42000000","3.01584000"],["77671.67000000","0.03210000"],["77672.00000000","0.03000000"],["77672.41000000","0.41262000"],["77672.77000000","0.00007000"],["77673.11000000","0.02000000"],["77673.17000000","0.00007000"],["77673.50000000","0.02800000"],["77673.55000000","0.09282000"],["77674.00000000","0.03000000"],["77674.07000000","0.00200000"],["77674.08000000","0.00007000"],["77674.42000000","0.00007000"],["77674.81000000","2.51955000"],["77674.82000000","3.47577000"],["77674.89000000","0.00027000"],["77675.42000000","3.24427000"],["77675.69000000","0.60553000"],["77675.85000000","0.00100000"],["77676.00000000","0.03000000"],["77676.08000000","0.00007000"],["77676.99000000","1.08358000"],["77677.11000000","0.00007000"],["77677.60000000","0.00015000"],["77677.98000000","0.61047000"],["77677.99000000","1.93226000"],["77678.00000000","0.03000000"],["77678.28000000","0.03210000"],["77678.36000000","0.00007000"],["77678.86000000","0.00010000"],["77678.99000000","0.00010000"],["77679.10000000","0.00008000"],["77679.53000000","0.00007000"],["77679.84000000","0.00008000"],["77680.00000000","0.03007000"],["77681.15000000","0.00007000"],["77681.49000000","0.00007000"],["77681.85000000","2.11121000"],["77682.00000000","0.03000000"],["77682.61000000","1.08358000"],["77683.46000000","1.93826000"],["77683.47000000","0.16884000"],["77683.59000000","0.00008000"],["77683.87000000","3.86359000"],["77683.99000000","0.34778000"],["77684.00000000","0.03000000"],["77684.03000000","0.00044000"],["77684.25000000","0.00027000"],["77685.36000000","0.00008000"],["77686.00000000","0.03000000"],["77686.29000000","0.00017000"],["77686.66000000","0.00016000"],["77686.71000000","0.00010000"],["77686.75000000","0.00007000"],["77687.03000000","0.91573000"],["77687.11000000","0.00007000"],["77687.27000000","0.03210000"],["77687.56000000","0.00515000"],["77688.00000000","0.08000000"],["77688.31000000","1.27491000"],["77688.67000000","0.00007000"],["77688.88000000","0.00007000"],["77688.89000000","0.00586000"],["77689.07000000","1.93226000"],["77689.33000000","0.34873000"],["77689.34000000","1.08358000"],["77689.59000000","0.00007000"],["77689.60000000","0.00008000"],["77690.00000000","0.03050000"],["77690.26000000","0.00008000"],["77691.06000000","0.00007000"],["77691.32000000","0.04625000"],["77692.00000000","0.03000000"],["77692.33000000","0.00200000"],["77692.34000000","0.00007000"],["77692.37000000","0.00147000"],["77692.38000000","0.00027000"],["77692.49000000","0.00007000"],["77693.12000000","0.00015000"],["77693.14000000","0.00007000"],["77693.28000000","0.00025000"],["77693.64000000","0.34778000"],["77693.66000000","0.16870000"],["77693.99000000","1.19898000"],["77694.00000000","0.03000000"],["77694.07000000","0.00008000"],["77694.43000000","0.00010000"],["77694.81000000","2.15391000"],["77694.85000000","1.93226000"],["77695.11000000","0.00007000"],["77695.48000000","0.00021000"],["77696.00000000","0.03007000"],["77696.80000000","0.00007000"],["77696.90000000","0.14298000"],["77697.60000000","0.70727000"],["77697.72000000","0.05153000"],["77697.94000000","0.00007000"],["77698.00000000","0.03000000"],["77698.09000000","0.00087000"],["77698.50000000","0.03210000"],["77698.69000000","0.00008000"],["77698.98000000","0.00007000"],["77699.36000000","0.00008000"],["77700.00000000","0.32881000"],["77700.03000000","1.93226000"],["77701.55000000","0.75035000"],["77701.91000000","0.00007000"],["77702.00000000","0.03000000"],["77702.15000000","0.00010000"],["77702.80000000","0.00027000"],["77703.20000000","0.00390000"],["77703.22000000","0.06500000"],["77703.95000000","2.38312000"],["77703.99000000","0.00128000"],["77704.00000000","0.03000000"],["77704.77000000","0.00012000"],["77704.78000000","0.00014000"],["77704.87000000","0.20178000"],["77704.88000000","0.18799000"],["77705.10000000","0.00007000"],["77705.28000000","0.00100000"],["77705.78000000","0.00007000"],["77705.88000000","0.00193000"],["77706.00000000","0.03000000"],["77706.53000000","0.00022000"],["77707.26000000","0.00007000"],["77707.29000000","0.34778000"],["77707.36000000","0.00008000"],["77707.74000000","0.00007000"],["77708.00000000","0.04000000"],["77708.20000000","0.00011000"],["77708.33000000","0.00062000"],["77708.38000000","0.00036000"],["77708.42000000","0.00007000"],["77708.64000000","0.00015000"],["77709.12000000","0.00008000"],["77709.26000000","0.00007000"],["77709.77000000","0.00007000"],["77709.87000000","0.00010000"],["77709.99000000","0.02239000"],["77710.00000000","0.03850000"],["77710.07000000","0.00200000"],["77710.08000000","0.00009000"],["77710.75000000","0.00011000"],["77710.84000000","0.00013000"],["77711.74000000","0.00027000"],["77712.00000000","0.03000000"],["77712.13000000","0.00391000"],["77712.65000000","0.03209000"],["77712.91000000","0.00008000"],["77712.93000000","0.08245000"],["77713.13000000","0.00007000"],["77713.34000000","0.00042000"],["77713.93000000","0.00011000"],["77713.96000000","0.16870000"],["77714.00000000","0.03000000"],["77714.28000000","0.00010000"],["77714.68000000","0.00007000"],["77714.72000000","0.00007000"],["77714.92000000","0.00077000"],["77714.95000000","0.00012000"],["77715.37000000","0.00008000"],["77716.00000000","0.03000000"],["77716.52000000","0.00007000"],["77716.61000000","0.00007000"],["77716.66000000","0.00010000"],["77716.73000000","0.00007000"],["77717.31000000","0.00019000"],["77717.37000000","0.34778000"],["77717.38000000","0.25903000"],["77717.39000000","0.00026000"],["77717.45000000","0.00010000"],["77717.52000000","0.00007000"],["77717.59000000","0.00010000"],["77717.64000000","0.00010000"],["77717.83000000","0.00022000"],["77718.00000000","0.03000000"],["77718.73000000","0.00041000"],["77718.88000000","0.00008000"],["77719.27000000","0.80000000"],["77719.35000000","0.00381000"],["77719.75000000","0.00027000"],["77720.00000000","0.03107000"],["77720.48000000","0.00007000"],["77720.52000000","0.00011000"],["77720.61000000","0.00007000"],["77720.70000000","0.45012000"],["77720.88000000","0.00046000"],["77721.30000000","0.00008000"],["77721.50000000","0.00007000"],["77721.74000000","0.16870000"],["77721.85000000","0.00386000"],["77722.00000000","0.03000000"],["77722.06000000","0.00032000"],["77722.54000000","0.00007000"],["77722.99000000","0.00011000"],["77723.57000000","0.00686000"],["77723.66000000","1.27432000"],["77724.00000000","0.03000000"],["77724.16000000","0.00015000"],["77724.31000000","0.03775000"],["77724.42000000","0.00108000"],["77725.00000000","0.00024000"],["77725.19000000","0.05955000"],["77725.31000000","0.00010000"],["77725.36000000","0.00034000"],["77725.50000000","0.00007000"],["77725.53000000","0.12382000"],["77725.54000000","0.34778000"],["77725.91000000","0.00007000"],["77726.00000000","0.03000000"],["77726.02000000","0.00019000"],["77726.10000000","0.00090000"],["77726.42000000","0.00011000"],["77726.49000000","0.00060000"],["77726.98000000","0.00128000"],["77727.24000000","0.00010000"],["77727.27000000","0.00157000"],["77727.60000000","0.00007000"],["77728.00000000","0.03007000"],["77728.64000000","0.00008000"],["77728.71000000","0.00027000"],["77729.11000000","0.00008000"],["77729.37000000","0.00007000"],["77729.49000000","0.53080000"],["77729.50000000","1.71336000"],["77729.60000000","0.00386000"],["77729.70000000","0.04550000"],["77729.72000000","0.00160000"],["77730.00000000","0.03050000"],["77730.43000000","0.01278000"],["77730.45000000","0.00085000"],["77731.19000000","0.00008000"],["77731.32000000","0.00051000"],["77731.33000000","0.00024000"],["77731.36000000","0.00010000"],["77731.63000000","0.00007000"],["77731.92000000","0.00007000"],["77731.98000000","0.00128000"],["77731.99000000","0.02729000"],["77732.00000000","0.03100000"],["77732.51000000","0.00971000"],["77732.75000000","0.00007000"],["77733.03000000","0.00010000"],["77733.33000000","0.00251000"],["77733.34000000","0.00007000"],["77733.50000000","0.00163000"],["77733.99000000","0.00128000"],["77734.00000000","0.03000000"],["77734.20000000","0.00007000"],["77734.22000000","0.00007000"],["77734.31000000","0.00007000"],["77734.74000000","0.00334000"],["77735.80000000","0.00191000"],["77735.88000000","0.15832000"],["77735.89000000","0.34778000"],["77735.94000000","0.00007000"],["77735.97000000","0.11557000"],["77736.00000000","0.03000000"],["77736.24000000","0.00007000"],["77736.48000000","0.00027000"],["77736.69000000","0.00095000"],["77737.13000000","0.00007000"],["77737.37000000","0.00386000"],["77737.45000000","0.00007000"],["77737.81000000","0.00020000"],["77737.96000000","0.00041000"],["77738.00000000","0.03000000"],["77738.40000000","0.00008000"],["77739.68000000","0.00015000"],["77739.78000000","0.07023000"],["77739.79000000","0.16870000"],["77739.91000000","0.00007000"],["77739.97000000","0.00008000"],["77740.00000000","0.03250000"],["77740.28000000","0.00018000"],["77740.69000000","0.00012000"],["77740.74000000","0.00026000"],["77741.45000000","0.00020000"],["77741.85000000","0.00022000"],["77741.93000000","0.00105000"],["77742.00000000","0.03000000"],["77742.59000000","0.00007000"],["77742.70000000","0.00007000"],["77742.90000000","0.00007000"],["77743.17000000","0.00128000"],["77743.52000000","0.00023000"],["77743.58000000","0.00007000"],["77743.91000000","0.06373000"],["77744.00000000","0.03000000"],["77744.02000000","0.00009000"],["77744.21000000","0.00007000"],["77744.25000000","0.00027000"],["77744.26000000","0.00220000"],["77744.44000000","0.00029000"],["77744.62000000","0.01458000"],["77745.00000000","0.15000000"],["77745.18000000","0.00041000"],["77745.35000000","0.00007000"],["77746.00000000","0.03000000"],["77746.97000000","0.00010000"],["77747.51000000","0.00008000"],["77747.64000000","0.04495000"],["77747.74000000","0.00122000"],["77747.78000000","0.20271000"],["77747.79000000","0.16870000"],["77747.99000000","0.00049000"],["77748.00000000","0.03000000"],["77748.10000000","0.00515000"],["77748.16000000","0.00008000"],["77748.17000000","0.00019000"],["77748.30000000","0.00007000"],["77748.55000000","0.07280000"],["77749.22000000","0.00007000"],["77749.75000000","0.00008000"],["77749.87000000","0.34778000"],["77750.00000000","0.05097000"],["77750.58000000","0.00256000"],["77751.22000000","0.00007000"],["77751.59000000","0.00100000"],["77752.00000000","0.03000000"],["77752.26000000","0.00008000"],["77752.29000000","0.00100000"],["77752.37000000","0.00160000"],["77752.80000000","1.16160000"],["77753.42000000","0.00016000"],["77753.67000000","0.00021000"],["77753.72000000","0.00007000"],["77753.90000000","0.00019000"],["77754.00000000","0.03000000"],["77754.31000000","0.00018000"],["77754.44000000","0.00014000"],["77754.84000000","3.86003000"],["77755.00000000","0.00010000"],["77755.10000000","0.00023000"],["77755.20000000","0.00015000"],["77755.38000000","0.00027000"],["77755.65000000","0.00035000"],["77755.81000000","0.00094000"],["77755.90000000","0.00064000"],["77755.93000000","0.00007000"],["77756.00000000","0.03000000"],["77756.04000000","0.00010000"],["77756.45000000","0.06193000"],["77756.46000000","0.16870000"],["77756.50000000","0.00260000"],["77756.66000000","0.00007000"],["77756.70000000","0.00007000"],["77756.75000000","0.00007000"],["77757.10000000","0.00044000"],["77757.54000000","0.00514000"],["77758.00000000","0.03000000"],["77758.19000000","0.00023000"],["77758.39000000","0.00007000"],["77758.67000000","0.00007000"],["77759.28000000","0.00456000"],["77759.30000000","0.09863000"],["77759.31000000","0.09849000"],["77759.67000000","0.03224000"],["77759.90000000","0.00008000"],["77760.00000000","0.05907000"],["77760.21000000","0.00054000"],["77761.05000000","0.01543000"],["77761.19000000","0.00051000"],["77761.55000000","0.00010000"],["77761.82000000","0.00117000"],["77761.93000000","0.10000000"],["77761.95000000","0.00008000"],["77761.98000000","0.00600000"],["77762.00000000","0.03000000"],["77762.02000000","0.00183000"],["77762.29000000","0.00007000"],["77762.54000000","0.00007000"],["77762.88000000","0.00010000"],["77763.10000000","0.00007000"],["77763.23000000","0.02000000"],["77763.55000000","0.00030000"],["77763.57000000","0.00027000"],["77763.74000000","0.00083000"],["77763.84000000","0.17302000"],["77763.85000000","0.34778000"],["77764.00000000","0.03000000"],["77764.01000000","0.00177000"],["77764.37000000","0.00113000"],["77764.47000000","0.00013000"],["77764.56000000","0.00049000"],["77764.70000000","0.01767000"],["77765.41000000","0.00012000"],["77765.56000000","0.00025000"],["77765.80000000","0.01378000"],["77765.99000000","0.13504000"],["77766.00000000","0.03000000"],["77766.23000000","0.00069000"],["77766.41000000","0.00007000"],["77766.45000000","0.00046000"],["77766.52000000","0.00011000"],["77766.66000000","0.00015000"],["77766.92000000","0.00034000"],["77766.98000000","0.00007000"],["77767.02000000","2.62177000"],["77767.08000000","0.00034000"],["77767.12000000","0.00009000"],["77767.44000000","0.00029000"],["77767.68000000","0.00008000"],["77767.89000000","0.00014000"],["77768.00000000","0.03000000"],["77768.09000000","0.00118000"],["77768.10000000","0.00007000"],["77768.42000000","0.00014000"],["77768.57000000","0.00034000"],["77768.83000000","0.00030000"],["77769.23000000","0.00147000"],["77769.30000000","0.00973000"],["77769.48000000","0.16870000"],["77769.60000000","0.00067000"],["77769.63000000","0.00061000"],["77769.64000000","0.00007000"],["77769.82000000","0.00010000"],["77770.00000000","0.03059000"],["77770.04000000","0.00011000"],["77770.07000000","0.00007000"],["77770.41000000","0.00007000"],["77770.53000000","0.00107000"],["77770.69000000","0.00007000"],["77770.72000000","0.00015000"],["77770.77000000","0.00007000"],["77770.80000000","0.00059000"],["77770.98000000","0.03211000"],["77771.34000000","0.00009000"],["77771.42000000","0.00026000"],["77771.60000000","0.00026000"],["77771.74000000","0.00052000"],["77772.00000000","0.03000000"],["77772.10000000","0.00072000"],["77772.30000000","0.00027000"],["77772.40000000","0.00053000"],["77772.55000000","0.00049000"],["77772.58000000","0.00097000"],["77772.78000000","0.00007000"],["77772.79000000","0.00026000"],["77772.85000000","0.00063000"],["77773.69000000","0.00015000"],["77773.88000000","0.00021000"],["77774.00000000","0.03000000"],["77774.36000000","0.00007000"],["77774.64000000","0.00009000"],["77775.00000000","0.01505000"],["77775.14000000","0.00012000"],["77775.26000000","0.02621000"],["77775.44000000","0.00024000"],["77775.48000000","0.00027000"],["77775.68000000","0.00007000"],["77775.87000000","0.11377000"],["77776.00000000","0.03000000"],["77776.05000000","0.00008000"],["77776.07000000","3.85898000"],["77776.29000000","0.00007000"],["77776.46000000","0.00390000"],["77776.65000000","0.00007000"],["77776.72000000","0.00231000"],["77776.73000000","0.00010000"],["77776.81000000","0.00033000"],["77776.83000000","0.00018000"],["77776.97000000","0.00010000"],["77777.00000000","0.12555000"],["77777.06000000","0.02019000"],["77777.24000000","0.16870000"],["77777.50000000","0.00007000"],["77777.64000000","0.00013000"],["77777.75000000","0.00013000"],["77777.77000000","0.00158000"],["77777.78000000","0.00010000"],["77778.00000000","0.03000000"],["77778.10000000","0.01271000"],["77778.58000000","0.00020000"],["77778.66000000","0.00007000"],["77778.74000000","0.00253000"],["77778.96000000","0.00009000"],["77779.20000000","0.00010000"],["77779.35000000","0.00023000"],["77779.41000000","0.00022000"],["77779.43000000","0.00109000"],["77779.49000000","0.00016000"],["77779.84000000","0.00011000"],["77779.95000000","0.00009000"],["77780.00000000","0.03687000"],["77780.19000000","0.01457000"],["77780.29000000","0.00010000"],["77780.58000000","0.00036000"],["77780.61000000","0.00010000"],["77780.68000000","0.00007000"],["77780.77000000","0.00159000"],["77780.81000000","0.00018000"],["77781.33000000","0.00016000"],["77781.74000000","0.00025000"],["77781.78000000","0.00007000"],["77781.99000000","0.00128000"],["77782.00000000","0.03000000"],["77782.05000000","0.00011000"],["77782.30000000","0.00014000"],["77782.35000000","0.00009000"],["77782.42000000","0.00009000"],["77782.65000000","0.05778000"],["77783.35000000","0.00045000"],["77784.00000000","0.03000000"],["77784.02000000","0.00007000"],["77784.56000000","0.00007000"],["77784.69000000","0.00007000"],["77784.77000000","0.00126000"],["77784.87000000","0.00018000"],["77784.99000000","0.05843000"],["77785.00000000","0.18496000"],["77785.29000000","0.00017000"],["77785.50000000","0.00021000"],["77785.54000000","0.00041000"],["77785.55000000","0.00012000"],["77785.71000000","0.00068000"],["77785.74000000","0.01542000"],["77785.92000000","0.00021000"],["77786.00000000","0.03000000"],["77786.04000000","0.00121000"],["77786.24000000","0.00015000"],["77786.45000000","0.00104000"],["77786.66000000","0.00007000"],["77786.70000000","0.00647000"],["77786.80000000","0.00013000"],["77787.37000000","0.00009000"],["77787.39000000","0.00020000"],["77787.54000000","0.01917000"],["77787.75000000","0.00035000"],["77787.90000000","0.00034000"],["77788.00000000","0.03000000"],["77788.13000000","0.00011000"],["77788.22000000","0.00009000"],["77788.27000000","0.00014000"],["77788.29000000","0.00008000"],["77788.53000000","0.00010000"],["77788.57000000","0.00008000"],["77788.60000000","0.00017000"],["77788.76000000","0.00007000"],["77788.91000000","0.00009000"],["77789.00000000","0.11077000"],["77789.09000000","0.00073000"],["77789.16000000","0.00290000"],["77789.47000000","0.00007000"],["77789.51000000","0.00034000"],["77790.00000000","0.03282000"],["77790.10000000","0.00681000"],["77790.27000000","0.00007000"],["77790.62000000","0.00020000"],["77791.12000000","0.00022000"],["77791.60000000","0.00007000"],["77791.99000000","0.00031000"],["77792.00000000","0.03007000"],["77792.03000000","0.00009000"],["77792.09000000","0.00008000"],["77792.67000000","0.00010000"],["77792.77000000","0.16870000"],["77792.98000000","0.00012000"],["77793.05000000","0.00034000"],["77793.08000000","0.00008000"],["77793.13000000","0.00024000"],["77793.27000000","0.00012000"],["77793.54000000","0.00009000"],["77793.80000000","0.00023000"],["77794.00000000","0.03000000"],["77794.03000000","0.00032000"],["77794.11000000","0.00377000"],["77794.16000000","0.00019000"],["77794.32000000","0.03211000"],["77794.41000000","0.00023000"],["77794.63000000","0.00010000"],["77794.67000000","0.00007000"],["77794.68000000","0.00007000"],["77795.02000000","0.00043000"],["77795.34000000","0.00021000"],["77795.47000000","0.00015000"],["77795.52000000","0.00646000"],["77795.64000000","0.00015000"],["77795.78000000","0.00017000"],["77795.81000000","0.00076000"],["77795.89000000","0.00007000"],["77796.00000000","0.03000000"],["77796.11000000","0.00007000"],["77796.30000000","0.00020000"],["77796.40000000","0.00378000"],["77796.54000000","0.00013000"],["77796.96000000","0.00008000"],["77797.26000000","0.00027000"],["77797.35000000","0.00228000"],["77797.48000000","0.00032000"],["77797.67000000","0.00007000"],["77798.00000000","0.03000000"],["77798.10000000","0.00109000"],["77798.29000000","0.00025000"],["77798.52000000","0.00016000"],["77798.59000000","0.00057000"],["77798.64000000","0.00168000"],["77798.83000000","0.00089000"],["77798.85000000","0.00010000"],["77799.00000000","1.00000000"],["77799.30000000","0.00012000"],["77799.48000000","0.00029000"],["77799.78000000","0.00007000"],["77799.87000000","0.00014000"],["77799.91000000","0.00100000"],["77799.96000000","0.00011000"],["77800.00000000","1.78458000"],["77800.14000000","0.00018000"]]}}
{"type":"depth","received_at_ms":1788331803671,"data":{"e":"depthUpdate","E":1788331803814,"s":"BTCUSDT","U":99555803696,"u":99555803741,"b":[["77597.06000000","1.25951000"],["77597.05000000","0.00111000"],["77595.61000000","0.28645000"],["77595.60000000","0.00007000"],["77594.41000000","0.00000000"],["77594.36000000","0.01325000"],["77594.00000000","0.03021000"],["77592.84000000","0.00000000"],["77589.59000000","0.00000000"],["77589.58000000","0.00257000"],["69837.36000000","0.00448000"],["69837.00000000","0.00000000"]],"a":[["77597.82000000","0.32246000"],["77598.29000000","0.00000000"],["77598.32000000","0.01711000"],["77598.69000000","0.00000000"],["77598.70000000","0.00000000"],["77598.75000000","0.00000000"],["77599.15000000","0.00658000"],["77599.16000000","0.00407000"],["78500.00000000","12.09954000"]]}}
{"type":"depth","received_at_ms":1788331803772,"data":{"e":"depthUpdate","E":1788331803914,"s":"BTCUSDT","U":99555803742,"u":99555803758,"b":[["77589.58000000","0.00000000"],["69837.36000000","0.00464000"]],"a":[["77597.07000000","6.17910000"],["77597.08000000","0.01097000"],["77598.32000000","0.01718000"],["77598.69000000","0.00007000"],["77598.70000000","0.05007000"],["77598.75000000","0.05000000"],["77599.16000000","0.00400000"],["77615.04000000","0.00412000"],["77692.22000000","2.15391000"],["77693.99000000","0.63755000"],["77694.81000000","0.00000000"]]}}
{"type":"trade","received_at_ms":1788331803856,"data":{"e":"trade","E":1788331803998,"s":"BTCUSDT","t":6646633248,"p":"77597.06000000","q":"0.00070000","T":1788331803998,"m":true,"M":true}}
{"type":"depth","received_at_ms":1788331803872,"data":{"e":"depthUpdate","E":1788331804014,"s":"BTCUSDT","U":99555803759,"u":99555803802,"b":[["77597.06000000","1.25881000"],["77589.56000000","0.00000000"],["77577.40000000","0.62855000"],["77574.48000000","0.00000000"],["69837.36000000","0.00448000"],["69837.35000000","0.00009000"],["62078.00000000","0.00400000"],["62077.65000000","0.00032000"]],"a":[["77597.07000000","6.17903000"],["77597.08000000","0.01097000"],["77598.32000000","0.01725000"],["77598.45000000","0.00400000"],["77598.64000000","0.00007000"],["77598.65000000","0.05000000"],["77598.69000000","0.00000000"],["77598.70000000","0.00021000"],["77598.75000000","0.00014000"],["77599.16000000","0.00000000"],["77599.17000000","0.04145000"],["77599.56000000","0.02028000"],["77604.62000000","0.00800000"],["77604.91000000","0.00000000"],["77609.98000000","0.25861000"],["77610.93000000","0.00000000"],["77615.84000000","0.00000000"],["77617.75000000","0.00038000"],["78761.03000000","0.00030000"]]}}
{"type":"depth","received_at_ms":1788331803974,"data":{"e":"depthUpdate","E":1788331804115,"s":"BTCUSDT","U":99555803803,"u":99555803825,"b":[["77580.01000000","0.65382000"],["77577.78000000","0.00007000"],["77495.41000000","0.00412000"],["71800.00000000","2.80885000"],["69837.36000000","0.00464000"]],"a":[["77598.32000000","0.01725000"],["77598.65000000","0.05014000"],["77598.70000000","0.05000000"],["77598.75000000","0.00000000"],["77599.17000000","0.04159000"],["77608.82000000","0.00007000"]]}}
{"type":"depth","received_at_ms":1788331804072,"data":{"e":"depthUpdate","E":1788331804214,"s":"BTCUSDT","U":99555803826,"u":99555803867,"b":[["77597.06000000","1.26525000"],["77597.05000000","0.00104000"],["77597.03000000","0.00014000"],["77597.02000000","0.03220000"],["77596.48000000","0.00021000"],["77596.45000000","0.00000000"],["77596.44000000","0.00014000"],["76433.10000000","0.00030000"],["69837.36000000","0.00448000"],["62077.65000000","0.00000000"]],"a":[["77597.07000000","6.17903000"],["77597.08000000","0.01097000"],["77597.83000000","0.00606000"],["77598.64000000","0.00000000"],["77598.65000000","0.00014000"],["77598.69000000","0.00007000"],["77598.70000000","0.05021000"],["77598.75000000","0.05000000"],["77599.17000000","0.04145000"],["77609.98000000","0.00000000"],["77610.93000000","0.37601000"]]}}
{"type":"trade","received_at_ms":1788331804135,"data":{"e":"trade","E":1788331804277,"s":"BTCUSDT","t":6646633249,"p":"77597.07000000","q":"0.00100000","T":1788331804277,"m":false,"M":true}}
{"type":"depth","received_at_ms":1788331804172,"data":{"e":"depthUpdate","E":1788331804314,"s":"BTCUSDT","U":99555803868,"u":99555803927,"b":[["77597.06000000","1.36629000"],["77597.02000000","0.03234000"],["77596.48000000","0.00000000"],["77596.44000000","0.00000000"],["77594.00000000","0.03028000"],["77592.80000000","0.00545000"],["77592.00000000","0.03036000"],["77588.32000000","0.00161000"],["77587.78000000","0.00000000"],["77546.53000000","0.00000000"],["69837.36000000","0.00464000"],["69837.35000000","0.00000000"],["69837.34000000","0.00009000"],["62078.00000000","0.00400000"],["62077.65000000","0.00000000"]],"a":[["77597.07000000","6.17810000"],["77597.82000000","0.32246000"],["77597.83000000","0.00620000"],["77598.32000000","0.01718000"],["77598.65000000","0.00000000"],["77598.69000000","0.00000000"],["77598.70000000","0.00021000"],["77598.75000000","0.00014000"],["77599.15000000","0.00644000"],["77599.16000000","0.00007000"],["77761.40000000","0.01543000"],["77763.74000000","0.00000000"],["77785.74000000","0.00000000"]]}}
{"type":"depth","received_at_ms":1788331804272,"data":{"e":"depthUpdate","E":1788331804414,"s":"BTCUSDT","U":99555803928,"u":99555803946,"b":[["77591.80000000","0.01200000"],["77581.28000000","0.00200000"],["69837.36000000","0.00448000"]],"a":[["77598.32000000","0.01711000"],["77598.70000000","0.00000000"],["77598.75000000","0.00000000"],["77599.15000000","0.00658000"],["77599.17000000","0.04159000"]]}}
{"type":"depth","received_at_ms":1788331804372,"data":{"e":"depthUpdate","E":1788331804514,"s":"BTCUSDT","U":99555803947,"u":99555803964,"b":[["69837.36000000","0.00464000"],["62078.00000000","0.00400000"],["62077.65000000","0.00032000"]],"a":[["77597.07000000","6.18396000"],["77598.45000000","0.00400000"],["77604.62000000","0.00800000"],["77653.85000000","0.00523000"]]}}
{"type":"depth","received_at_ms":1788331804472,"data":{"e":"depthUpdate","E":1788331804614,"s":"BTCUSDT","U":99555803965,"u":99555803978,"b":[["77597.06000000","1.36630000"],["77589.31000000","0.00000000"],["77589.30000000","0.00019000"],["77589.08000000","0.00134000"],["77581.54000000","0.00027000"],["77573.78000000","0.00155000"],["77566.02000000","0.00027000"],["69837.36000000","0.00432000"],["62077.65000000","0.00000000"]],"a":[]}}
{"type":"depth","received_at_ms":1788331804573,"data":{"e":"depthUpdate","E":1788331804714,"s":"BTCUSDT","U":99555803979,"u":99555803999,"b":[["77597.06000000","1.36623000"],["77592.00000000","0.03029000"],["77591.80000000","0.00000000"],["77581.28000000","0.01400000"],["69837.36000000","0.00448000"],["62078.00000000","0.00400000"],["62077.65000000","0.00000000"]],"a":[["77597.07000000","6.18496000"],["77684.90000000","0.00412000"]]}}
{"type":"depth","received_at_ms":1788331804672,"data":{"e":"depthUpdate","E":1788331804814,"s":"BTCUSDT","U":99555804000,"u":99555804018,"b":[["77587.32000000","0.01044000"],["77586.83000000","0.00000000"],["77581.28000000","0.00600000"],["77568.91000000","0.96118000"],["69837.36000000","0.00432000"],["69837.00000000","0.00000000"]],"a":[["77597.07000000","6.18510000"],["77598.32000000","0.01718000"],["77598.79000000","0.00007000"],["77598.80000000","0.05007000"],["77598.85000000","0.05000000"],["77599.16000000","0.00000000"],["77689.33000000","0.95496000"]]}}
{"type":"depth","received_at_ms":1788331804770,"data":{"e":"depthUpdate","E":1788331804914,"s":"BTCUSDT","U":99555804019,"u":99555804050,"b":[["77565.13000000","0.00000000"],["77543.98000000","0.12892000"],["77526.43000000","0.00412000"],["77495.41000000","0.00000000"],["69837.36000000","0.00416000"]],"a":[["77597.07000000","6.18503000"],["77598.32000000","0.01718000"],["77598.79000000","0.00000000"],["77598.80000000","0.00021000"],["77598.84000000","0.00007000"],["77598.85000000","0.00021000"],["77598.90000000","0.05000000"],["77599.15000000","0.00644000"],["77599.17000000","0.04145000"],["77615.04000000","0.00000000"],["77653.85000000","0.00111000"],["77684.90000000","0.00000000"],["77689.33000000","0.34873000"],["77692.22000000","0.00000000"],["77694.81000000","2.15391000"]]}}
{"type":"depth","received_at_ms":1788331804872,"data":{"e":"depthUpdate","E":1788331805014,"s":"BTCUSDT","U":99555804051,"u":99555804074,"b":[["69837.36000000","0.00448000"],["62077.65000000","0.00032000"]],"a":[["77597.07000000","6.18503000"],["77598.32000000","0.01718000"],["77598.80000000","0.00007000"],["77598.84000000","0.00000000"],["77598.85000000","0.00007000"],["77598.89000000","0.00007000"],["77598.90000000","0.05021000"],["77598.95000000","0.05007000"],["77599.15000000","0.00658000"],["78761.03000000","0.00030000"],["79750.00000000","1.24296000"],["80750.00000000","0.66347000"]]}}
{"type":"depth","received_at_ms":1788331804972,"data":{"e":"depthUpdate","E":1788331805114,"s":"BTCUSDT","U":99555804075,"u":99555804098,"b":[["77589.34000000","0.00257000"],["77577.78000000","0.00007000"],["69837.36000000","0.00432000"]],"a":[["77597.07000000","6.18510000"],["77598.89000000","0.00000000"],["77598.90000000","0.00021000"],["77598.95000000","0.00021000"],["77599.15000000","0.00644000"],["77599.16000000","0.00007000"],["77599.56000000","0.02035000"],["77599.70000000","0.05000000"],["77599.75000000","0.05000000"],["77608.82000000","0.00007000"],["77615.07000000","0.00412000"]]}}
{"type":"trade","received_at_ms":1788331805022,"data":{"e":"trade","E":1788331805164,"s":"BTCUSDT","t":6646633250,"p":"77597.07000000","q":"0.00070000","T":1788331805163,"m":false,"M":true}}
{"type":"depth","received_at_ms":1788331805074,"data":{"e":"depthUpdate","E":1788331805214,"s":"BTCUSDT","U":99555804099,"u":99555804128,"b":[["76433.10000000","0.00030000"],["69837.36000000","0.00448000"],["69837.34000000","0.00000000"],["62077.65000000","0.00000000"]],"a":[["77597.07000000","6.18426000"],["77598.32000000","0.01725000"],["77598.90000000","0.00007000"],["77598.95000000","0.00007000"],["77599.09000000","0.00007000"],["77599.10000000","0.05000000"],["77599.15000000","0.00658000"],["77599.17000000","0.04159000"],["77599.56000000","0.02028000"],["77599.70000000","0.00000000"],["77599.75000000","0.00000000"]]}}
{"type":"trade","received_at_ms":1788331805167,"data":{"e":"trade","E":1788331805307,"s":"BTCUSDT","t":6646633251,"p":"77597.06000000","q":"0.00100000","T":1788331805307,"m":true,"M":true}}
{"type":"depth","received_at_ms":1788331805172,"data":{"e":"depthUpdate","E":1788331805314,"s":"BTCUSDT","U":99555804129,"u":99555804148,"b":[["77597.06000000","1.36523000"],["77589.34000000","0.00000000"],["77589.32000000","0.00257000"],["69837.36000000","0.00432000"],["62077.65000000","0.00000000"]],"a":[["77598.32000000","0.01725000"],["77599.09000000","0.00000000"],["77599.10000000","0.00014000"],["77599.17000000","0.04145000"],["77684.93000000","0.00412000"],["77692.22000000","2.15391000"],["77694.81000000","0.00000000"],["77833.83000000","0.00000000"]]}}
{"type":"depth","received_at_ms":1788331805273,"data":{"e":"depthUpdate","E":1788331805415,"s":"BTCUSDT","U":99555804149,"u":99555804189,"b":[["77597.06000000","1.35879000"],["77597.05000000","0.00097000"],["77597.03000000","0.00000000"],["77597.02000000","0.00014000"],["77595.61000000","0.04747000"],["77595.23000000","0.00000000"],["77595.22000000","0.00021000"],["77594.54000000","0.00000000"],["77594.53000000","0.00014000"],["77594.01000000","0.00014000"],["77592.70000000","0.00014000"],["77592.01000000","0.00007000"],["77589.32000000","0.00000000"],["77587.66000000","0.00000000"],["77587.33000000","0.00644000"],["77577.40000000","0.00000000"],["77576.30000000","0.00000000"],["77575.56000000","0.00128000"],["77575.46000000","0.62856000"],["77472.90000000","0.00053000"],["69837.36000000","0.00448000"]],"a":[["77597.83000000","0.00627000"],["77598.31000000","0.00644000"],["77598.32000000","0.01718000"],["77599.10000000","0.00000000"],["77599.15000000","0.00014000"],["77599.17000000","0.04159000"]]}}
{"type":"depth","received_at_ms":1788331805372,"data":{"e":"depthUpdate","E":1788331805514,"s":"BTCUSDT","U":99555804190,"u":99555804245,"b":[["77597.06000000","1.35879000"],["77597.05000000","0.00090000"],["77597.02000000","0.00000000"],["77596.00000000","0.03028000"],["77595.61000000","0.04747000"],["77595.60000000","0.00000000"],["77595.22000000","0.00000000"],["77594.53000000","0.00000000"],["77594.37000000","0.00014000"],["77592.80000000","0.00552000"],["77592.69000000","0.11349000"],["77592.01000000","0.00000000"],["77592.00000000","0.03043000"],["77591.80000000","0.00600000"],["77589.31000000","0.00257000"],["77581.28000000","0.00000000"],["77341.63000000","0.00000000"],["75557.06000000","0.00000000"],["69837.36000000","0.00432000"],["62077.65000000","0.00032000"]],"a":[["77597.07000000","6.18419000"],["77597.08000000","0.01090000"],["77597.83000000","0.00627000"],["77598.31000000","0.00658000"],["77598.32000000","0.01711000"],["77599.15000000","0.00000000"],["81001.05000000","0.00000000"]]}}
{"type":"depth","received_at_ms":1788331805471,"data":{"e":"depthUpdate","E":1788331805614,"s":"BTCUSDT","U":99555804246,"u":99555804288,"b":[["77597.06000000","1.35907000"],["77597.05000000","0.00104000"],["77596.95000000","0.00014000"],["77596.94000000","0.25076000"],["77596.93000000","0.25793000"],["77596.16000000","0.00014000"],["77596.15000000","0.38680000"],["77596.01000000","0.00000000"],["77595.62000000","0.00000000"],["77595.61000000","0.00014000"],["77594.37000000","0.00000000"],["77594.01000000","0.00000000"],["77592.00000000","0.03043000"],["77591.80000000","0.00607000"],["77589.31000000","0.00000000"],["77589.29000000","0.00257000"],["69837.36000000","0.00448000"],["62078.00000000","0.00400000"],["62077.65000000","0.00000000"]],"a":[["77942.93000000","0.00000000"]]}}
{"type":"depth","received_at_ms":1788331805572,"data":{"e":"depthUpdate","E":1788331805714,"s":"BTCUSDT","U":99555804289,"u":99555804323,"b":[["77597.06000000","1.35914000"],["77597.05000000","0.00104000"],["77596.94000000","0.25090000"],["77596.93000000","0.25800000"],["77596.00000000","0.03007000"],["77595.61000000","0.00000000"],["77592.00000000","0.03036000"],["77591.80000000","0.00007000"],["77589.29000000","0.00000000"],["77589.28000000","0.00257000"],["77581.28000000","0.00400000"],["77566.20000000","0.00000000"],["77434.16000000","0.00053000"],["77193.02000000","0.00000000"],["69837.36000000","0.00432000"],["62077.65000000","0.00000000"]],"a":[["77603.50000000","0.00000000"],["77618.25000000","0.00000000"],["77692.22000000","0.00000000"],["77694.81000000","2.15391000"]]}}
{"type":"depth","received_at_ms":1788331805671,"data":{"e":"depthUpdate","E":1788331805814,"s":"BTCUSDT","U":99555804324,"u":99555804346,"b":[["77597.06000000","1.35921000"],["77591.80000000","0.00407000"],["77589.28000000","0.00000000"],["77589.27000000","0.00257000"],["77581.28000000","0.00200000"],["77565.50000000","0.00200000"],["77024.65000000","0.00000000"],["69837.36000000","0.00448000"],["69837.00000000","0.00000000"]],"a":[["77597.07000000","6.18333000"],["77599.17000000","0.04166000"],["77599.20000000","0.05007000"],["77599.25000000","0.05000000"],["77618.45000000","0.00200000"],["77693.99000000","1.19898000"],["78094.90000000","0.00000000"]]}}
{"type":"depth","received_at_ms":1788331805772,"data":{"e":"depthUpdate","E":1788331805914,"s":"BTCUSDT","U":99555804347,"u":99555804360,"b":[["77595.09000000","0.00000000"],["77589.27000000","0.00000000"],["69837.36000000","0.00432000"]],"a":[["77597.07000000","6.18326000"],["77599.17000000","0.04166000"],["77599.20000000","0.05000000"],["77599.25000000","0.00000000"],["77604.01000000","0.00600000"],["77653.88000000","0.00412000"],["77721.22000000","0.00106000"],["78242.14000000","0.00000000"]]}}
{"type":"trade","received_at_ms":1788331805853,"data":{"e":"trade","E":1788331805993,"s":"BTCUSDT","t":6646633252,"p":"77597.07000000","q":"0.00382000","T":1788331805993,"m":false,"M":true}}
{"type":"depth","received_at_ms":1788331805872,"data":{"e":"depthUpdate","E":1788331806014,"s":"BTCUSDT","U":99555804361,"u":99555804385,"b":[["77597.06000000","1.35893000"],["77596.93000000","0.25807000"],["77596.15000000","0.38694000"],["77596.00000000","0.03014000"],["77589.26000000","0.00000000"],["77569.00000000","0.70000000"],["77567.00000000","0.00000000"],["69837.36000000","0.00457000"],["62077.65000000","0.00032000"]],"a":[["77597.07000000","6.17951000"],["77598.32000000","0.01718000"],["77599.14000000","0.00007000"],["77599.15000000","0.05000000"],["78399.48000000","0.00000000"],["78761.03000000","0.00030000"]]}}
{"type":"depth","received_at_ms":1788331805972,"data":{"e":"depthUpdate","E":1788331806114,"s":"BTCUSDT","U":99555804386,"u":99555804410,"b":[["77589.25000000","0.00000000"],["77577.78000000","0.00000000"],["77572.96000000","0.44223000"],["77568.91000000","0.58848000"],["77567.61000000","0.00000000"],["69837.36000000","0.00441000"]],"a":[["77597.07000000","6.17944000"],["77598.31000000","0.00014000"],["77598.32000000","0.01725000"],["77598.79000000","0.00644000"],["77599.09000000","0.00007000"],["77599.10000000","0.05000000"],["77599.15000000","0.05014000"],["77599.16000000","0.00000000"],["77599.17000000","0.04145000"],["77599.20000000","0.00000000"],["77608.82000000","0.00000000"],["78952.82000000","0.00000000"]]}}
{"type":"depth","received_at_ms":1788331806071,"data":{"e":"depthUpdate","E":1788331806214,"s":"BTCUSDT","U":99555804411,"u":99555804436,"b":[["77589.24000000","0.00257000"],["77577.78000000","0.00007000"],["76433.10000000","0.00030000"],["75557.06000000","0.00010000"],["69837.36000000","0.00441000"],["62077.65000000","0.00000000"]],"a":[["77597.83000000","0.00620000"],["77598.31000000","0.00000000"],["77598.32000000","0.01725000"],["77598.79000000","0.00658000"],["77599.10000000","0.05014000"],["77599.15000000","0.05000000"],["77608.82000000","0.00007000"]]}}
{"type":"depth","received_at_ms":1788331806175,"data":{"e":"depthUpdate","E":1788331806314,"s":"BTCUSDT","U":99555804437,"u":99555804452,"b":[["77589.24000000","0.00000000"],["77589.23000000","0.00257000"],["77565.25000000","0.00412000"],["77543.98000000","0.00000000"],["77543.13000000","0.12892000"],["76256.04000000","0.00000000"],["69837.36000000","0.00441000"],["62078.00000000","0.00400000"]],"a":[["77597.07000000","6.17958000"],["77598.32000000","0.01732000"],["80559.42000000","0.00000000"]]}}
{"type":"trade","received_at_ms":1788331806271,"data":{"e":"trade","E":1788331806410,"s":"BTCUSDT","t":6646633253,"p":"77597.06000000","q":"0.00070000","T":1788331806409,"m":true,"M":true}}
{"type":"depth","received_at_ms":1788331806274,"data":{"e":"depthUpdate","E":1788331806414,"s":"BTCUSDT","U":99555804453,"u":99555804466,"b":[["77597.06000000","1.35822000"],["77589.23000000","0.00000000"],["69837.36000000","0.00432000"],["69837.35000000","0.00009000"],["62078.00000000","0.00400000"],["62077.65000000","0.00000000"]],"a":[["87336.63000000","0.00000000"]]}}
{"type":"depth","received_at_ms":1788331806375,"data":{"e":"depthUpdate","E":1788331806514,"s":"BTCUSDT","U":99555804467,"u":99555804482,"b":[["69837.36000000","0.00432000"],["62077.65000000","0.00032000"]],"a":[["77597.07000000","6.17951000"],["77598.32000000","0.01725000"],["77599.09000000","0.00000000"],["77599.10000000","0.00014000"],["77599.14000000","0.00000000"],["77599.15000000","0.00000000"],["77599.16000000","0.00007000"],["77599.17000000","0.04152000"],["77599.30000000","0.05000000"],["77599.35000000","0.05000000"],["81001.05000000","0.00010000"]]}}
{"type":"depth","received_at_ms":1788331806475,"data":{"e":"depthUpdate","E":1788331806614,"s":"BTCUSDT","U":99555804483,"u":99555804506,"b":[["69837.36000000","0.00432000"],["62078.00000000","0.00400000"],["62077.65000000","0.00000000"]],"a":[["77597.07000000","6.18271000"],["77598.32000000","0.01718000"],["77598.79000000","0.00665000"],["77599.09000000","0.00007000"],["77599.10000000","0.05000000"],["77599.17000000","0.04159000"],["77599.30000000","0.00000000"],["77599.35000000","0.00000000"]]}}
{"type":"depth","received_at_ms":1788331806574,"data":{"e":"depthUpdate","E":1788331806714,"s":"BTCUSDT","U":99555804507,"u":99555804520,"b":[["71397.14000000","0.00015000"],["69837.36000000","0.00448000"]],"a":[["77598.79000000","0.00665000"],["77599.09000000","0.00000000"],["77599.10000000","0.00014000"],["77599.17000000","0.04145000"]]}}
{"type":"trade","received_at_ms":1788331806673,"data":{"e":"trade","E":1788331806809,"s":"BTCUSDT","t":6646633254,"p":"77597.06000000","q":"0.00529000","T":1788331806809,"m":true,"M":true}}
{"type":"trade","received_at_ms":1788331806673,"data":{"e":"trade","E":1788331806809,"s":"BTCUSDT","t":6646633255,"p":"77597.06000000","q":"0.00007000","T":1788331806809,"m":true,"M":true}}
{"type":"trade","received_at_ms":1788331806673,"data":{"e":"trade","E":1788331806809,"s":"BTCUSDT","t":6646633256,"p":"77597.06000000","q":"0.00008000","T":1788331806809,"m":true,"M":true}}
{"type":"trade","received_at_ms":1788331806673,"data":{"e":"trade","E":1788331806809,"s":"BTCUSDT","t":6646633257,"p":"77597.06000000","q":"0.00007000","T":1788331806809,"m":true,"M":true}}
{"type":"trade","received_at_ms":1788331806673,"data":{"e":"trade","E":1788331806809,"s":"BTCUSDT","t":6646633258,"p":"77597.06000000","q":"0.00007000","T":1788331806809,"m":true,"M":true}}
{"type":"trade","received_at_ms":1788331806673,"data":{"e":"trade","E":1788331806809,"s":"BTCUSDT","t":6646633259,"p":"77597.06000000","q":"0.00007000","T":1788331806809,"m":true,"M":true}}
{"type":"trade","received_at_ms":1788331806673,"data":{"e":"trade","E":1788331806809,"s":"BTCUSDT","t":6646633260,"p":"77597.06000000","q":"0.00007000","T":1788331806809,"m":true,"M":true}}
{"type":"trade","received_at_ms":1788331806673,"data":{"e":"trade","E":1788331806809,"s":"BTCUSDT","t":6646633261,"p":"77597.06000000","q":"0.00007000","T":1788331806809,"m":true,"M":true}}
{"type":"trade","received_at_ms":1788331806673,"data":{"e":"trade","E":1788331806809,"s":"BTCUSDT","t":6646633262,"p":"77597.06000000","q":"0.00007000","T":1788331806809,"m":true,"M":true}}
{"type":"trade","received_at_ms":1788331806673,"data":{"e":"trade","E":1788331806809,"s":"BTCUSDT","t":6646633263,"p":"77597.06000000","q":"0.00007000","T":1788331806809,"m":true,"M":true}}
{"type":"trade","received_at_ms":1788331806673,"data":{"e":"trade","E":1788331806809,"s":"BTCUSDT","t":6646633264,"p":"77597.06000000","q":"0.02000000","T":1788331806809,"m":true,"M":true}}
{"type":"trade","received_at_ms":1788331806673,"data":{"e":"trade","E":1788331806809,"s":"BTCUSDT","t":6646633265,"p":"77597.06000000","q":"0.00007000","T":1788331806809,"m":true,"M":true}}
{"type":"trade","received_at_ms":1788331806673,"data":{"e":"trade","E":1788331806809,"s":"BTCUSDT","t":6646633266,"p":"77597.06000000","q":"0.00007000","T":1788331806809,"m":true,"M":true}}
{"type":"trade","received_at_ms":1788331806673,"data":{"e":"trade","E":1788331806809,"s":"BTCUSDT","t":6646633267,"p":"77597.06000000","q":"0.00200000","T":1788331806809,"m":true,"M":true}}
{"type":"trade","received_at_ms":1788331806673,"data":{"e":"trade","E":1788331806809,"s":"BTCUSDT","t":6646633268,"p":"77597.06000000","q":"0.00200000","T":1788331806809,"m":true,"M":true}}
{"type":"trade","received_at_ms":1788331806673,"data":{"e":"trade","E":1788331806809,"s":"BTCUSDT","t":6646633269,"p":"77597.06000000","q":"0.00200000","T":1788331806809,"m":true,"M":true}}
{"type":"trade","received_at_ms":1788331806673,"data":{"e":"trade","E":1788331806809,"s":"BTCUSDT","t":6646633270,"p":"77597.06000000","q":"0.00200000","T":1788331806809,"m":true,"M":true}}
{"type":"trade","received_at_ms":1788331806673,"data":{"e":"trade","E":1788331806809,"s":"BTCUSDT","t":6646633271,"p":"77597.06000000","q":"0.00007000","T":1788331806809,"m":true,"M":true}}
{"type":"trade","received_at_ms":1788331806674,"data":{"e":"trade","E":1788331806809,"s":"BTCUSDT","t":6646633272,"p":"77597.06000000","q":"0.00007000","T":1788331806809,"m":true,"M":true}}
{"type":"trade","received_at_ms":1788331806674,"data":{"e":"trade","E":1788331806809,"s":"BTCUSDT","t":6646633273,"p":"77597.06000000","q":"0.00007000","T":1788331806809,"m":true,"M":true}}
{"type":"trade","received_at_ms":1788331806674,"data":{"e":"trade","E":1788331806809,"s":"BTCUSDT","t":6646633274,"p":"77597.06000000","q":"0.02000000","T":1788331806809,"m":true,"M":true}}
{"type":"trade","received_at_ms":1788331806674,"data":{"e":"trade","E":1788331806809,"s":"BTCUSDT","t":6646633275,"p":"77597.06000000","q":"0.00007000","T":1788331806809,"m":true,"M":true}}
{"type":"trade","received_at_ms":1788331806674,"data":{"e":"trade","E":1788331806809,"s":"BTCUSDT","t":6646633276,"p":"77597.06000000","q":"0.00013000","T":1788331806809,"m":true,"M":true}}
{"type":"trade","received_at_ms":1788331806674,"data":{"e":"trade","E":1788331806809,"s":"BTCUSDT","t":6646633277,"p":"77597.06000000","q":"0.00200000","T":1788331806809,"m":true,"M":true}}
{"type":"trade","received_at_ms":1788331806674,"data":{"e":"trade","E":1788331806809,"s":"BTCUSDT","t":6646633278,"p":"77597.06000000","q":"0.00065000","T":1788331806809,"m":true,"M":true}}
{"type":"trade","received_at_ms":1788331806674,"data":{"e":"trade","E":1788331806809,"s":"BTCUSDT","t":6646633279,"p":"77597.06000000","q":"0.00064000","T":1788331806809,"m":true,"M":true}}
{"type":"trade","received_at_ms":1788331806674,"data":{"e":"trade","E":1788331806809,"s":"BTCUSDT","t":6646633280,"p":"77597.06000000","q":"0.00848000","T":1788331806809,"m":true,"M":true}}
{"type":"trade","received_at_ms":1788331806674,"data":{"e":"trade","E":1788331806809,"s":"BTCUSDT","t":6646633281,"p":"77597.06000000","q":"0.02000000","T":1788331806809,"m":true,"M":true}}
{"type":"trade","received_at_ms":1788331806674,"data":{"e":"trade","E":1788331806809,"s":"BTCUSDT","t":6646633282,"p":"77597.06000000","q":"0.02000000","T":1788331806809,"m":true,"M":true}}
{"type":"depth","received_at_ms":1788331806674,"data":{"e":"depthUpdate","E":1788331806814,"s":"BTCUSDT","U":99555804521,"u":99555804646,"b":[["77597.06000000","0.22871000"],["77597.02000000","0.03220000"],["77596.94000000","0.00028000"],["77594.36000000","0.01318000"],["77594.15000000","0.00000000"],["77591.80000000","0.00007000"],["77590.96000000","0.00000000"],["77590.75000000","0.00000000"],["77590.42000000","0.00091000"],["77589.08000000","0.00000000"],["77588.53000000","0.00134000"],["77588.32000000","0.00000000"],["77587.57000000","0.00000000"],["77587.51000000","0.00168000"],["77587.33000000","0.00000000"],["77587.32000000","0.00000000"],["77586.48000000","0.00007000"],["77586.35000000","0.01288000"],["77581.28000000","0.00600000"],["77575.46000000","0.00000000"],["69837.36000000","0.00416000"],["69837.35000000","0.00000000"],["62077.65000000","0.00000000"]],"a":[["77597.07000000","6.18752000"],["77597.08000000","0.01055000"],["77598.79000000","0.00014000"],["77599.10000000","0.00000000"],["77599.15000000","0.05000000"],["77599.17000000","0.04159000"],["77599.20000000","0.05000000"],["77600.23000000","1.31471000"],["77600.71000000","0.00644000"],["77601.88000000","0.00000000"],["77602.88000000","0.00400000"],["77604.39000000","0.00000000"],["77604.62000000","0.00000000"],["77605.39000000","1.93226000"],["77689.33000000","0.95496000"],["77692.22000000","2.15391000"],["77693.99000000","0.63755000"],["77694.81000000","0.00000000"]]}}
{"type":"trade","received_at_ms":1788331806674,"data":{"e":"trade","E":1788331806814,"s":"BTCUSDT","t":6646633283,"p":"77597.06000000","q":"0.12885000","T":1788331806813,"m":true,"M":true}}
{"type":"depth","received_at_ms":1788331806775,"data":{"e":"depthUpdate","E":1788331806914,"s":"BTCUSDT","U":99555804647,"u":99555804739,"b":[["77597.06000000","0.36370000"],["77597.05000000","0.00104000"],["77597.03000000","0.00014000"],["77596.95000000","0.00014000"],["77596.94000000","0.25064000"],["77596.01000000","0.00000000"],["77594.36000000","0.01325000"],["77594.01000000","0.00000000"],["77592.70000000","0.00007000"],["77592.00000000","0.03029000"],["77591.80000000","0.00000000"],["77591.78000000","0.41285000"],["77590.42000000","0.00098000"],["77589.76000000","0.11335000"],["77589.08000000","0.11335000"],["77589.04000000","0.00600000"],["77586.48000000","0.00014000"],["77581.28000000","0.00000000"],["77574.52000000","0.62855000"],["69837.36000000","0.00448000"],["69837.00000000","0.00000000"]],"a":[["77597.07000000","5.65910000"],["77597.78000000","0.26523000"],["77598.32000000","0.01718000"],["77598.79000000","0.00000000"],["77598.90000000","0.00034000"],["77599.14000000","0.00000000"],["77599.15000000","0.00014000"],["77599.16000000","0.00007000"],["77599.17000000","0.04166000"],["77600.22000000","0.00000000"],["77600.31000000","0.71276000"],["77601.50000000","0.12552000"],["77602.67000000","0.00257000"],["77602.88000000","0.00000000"],["77604.01000000","0.00400000"],["77604.46000000","0.00000000"],["77604.57000000","0.00000000"],["77605.38000000","1.25875000"],["77605.49000000","0.00000000"],["77612.59000000","0.00016000"],["77618.45000000","0.00000000"],["77620.47000000","0.00200000"]]}}
{"type":"depth","received_at_ms":1788331806874,"data":{"e":"depthUpdate","E":1788331807014,"s":"BTCUSDT","U":99555804740,"u":99555804773,"b":[["77597.06000000","0.38369000"],["77597.05000000","0.00111000"],["77597.02000000","0.03234000"],["77592.69000000","0.11335000"],["77587.51000000","0.00000000"],["77587.13000000","0.00172000"],["69837.36000000","0.00432000"],["62078.00000000","0.00400000"],["62077.65000000","0.00032000"]],"a":[["77597.07000000","5.65266000"],["77597.76000000","0.00644000"],["77598.32000000","0.01711000"],["77598.90000000","0.00007000"],["77599.15000000","0.05000000"],["77599.20000000","0.00014000"],["77605.37000000","0.09622000"],["77609.28000000","0.29779000"],["77609.97000000","0.00000000"],["77610.93000000","0.00000000"],["77760.08000000","0.00106000"],["77802.46000000","0.00183000"],["78761.03000000","0.00030000"]]}}
{"type":"depth","received_at_ms":1788331806975,"data":{"e":"depthUpdate","E":1788331807114,"s":"BTCUSDT","U":99555804774,"u":99555804832,"b":[["77597.06000000","0.55247000"],["77593.58000000","0.00027000"],["77341.61000000","0.00119000"],["69837.36000000","0.00448000"]],"a":[["77597.07000000","5.65329000"],["77597.08000000","0.01097000"],["77597.76000000","0.00658000"],["77597.82000000","0.32895000"],["77597.83000000","0.00021000"],["77598.32000000","0.01725000"],["77598.59000000","0.00007000"],["77598.60000000","0.00000000"],["77599.14000000","0.00000000"],["77599.15000000","0.00014000"],["77599.16000000","0.00000000"],["77599.17000000","0.04145000"],["77599.20000000","0.00000000"],["77605.36000000","0.00000000"],["77605.37000000","0.00000000"],["77609.63000000","0.09622000"]]}}
{"type":"depth","received_at_ms":1788331807075,"data":{"e":"depthUpdate","E":1788331807214,"s":"BTCUSDT","U":99555804833,"u":99555804861,"b":[["77589.04000000","0.00720000"],["77588.53000000","0.00000000"],["77577.78000000","0.00007000"],["71397.14000000","0.00000000"],["69837.36000000","0.00432000"],["62077.65000000","0.00000000"]],"a":[["77597.07000000","5.65329000"],["77597.82000000","0.32895000"],["77597.83000000","0.00007000"],["77598.32000000","0.01711000"],["77598.59000000","0.00000000"],["77599.15000000","0.00000000"],["77599.16000000","0.00007000"],["77599.17000000","0.04159000"],["77599.56000000","0.02042000"],["77608.82000000","0.00007000"]]}}
{"type":"trade","received_at_ms":1788331807110,"data":{"e":"trade","E":1788331807248,"s":"BTCUSDT","t":6646633284,"p":"77597.07000000","q":"0.00199000","T":1788331807248,"m":false,"M":true}}
{"type":"trade","received_at_ms":1788331807119,"data":{"e":"trade","E":1788331807257,"s":"BTCUSDT","t":6646633285,"p":"77597.07000000","q":"0.03222000","T":1788331807257,"m":false,"M":true}}
{"type":"depth","received_at_ms":1788331807173,"data":{"e":"depthUpdate","E":1788331807314,"s":"BTCUSDT","U":99555804862,"u":99555804914,"b":[["77597.06000000","1.18960000"],["77596.94000000","0.25078000"],["77592.69000000","0.11342000"],["77592.01000000","0.34778000"],["77590.03000000","0.00119000"],["77589.04000000","0.00600000"],["77588.37000000","0.00644000"],["77588.02000000","0.00816000"],["77587.13000000","0.00000000"],["77586.58000000","0.03210000"],["77586.35000000","0.00000000"],["77560.61000000","0.34827000"],["77543.59000000","0.00000000"],["76433.10000000","0.00030000"],["69837.36000000","0.00457000"]],"a":[["77597.07000000","4.98002000"],["77597.08000000","0.01097000"],["77597.76000000","0.00014000"],["77598.32000000","0.01718000"],["77598.45000000","0.00000000"],["77598.79000000","0.00644000"],["77600.23000000","0.00000000"],["77600.31000000","0.71269000"],["77600.71000000","0.00000000"],["77601.05000000","0.14280000"],["77601.27000000","0.00000000"],["77602.19000000","0.00000000"],["77602.67000000","0.00000000"],["77603.06000000","0.00644000"],["77603.64000000","0.00257000"],["77604.53000000","0.00000000"],["77605.38000000","0.57816000"],["77605.39000000","0.00000000"],["77605.50000000","0.00000000"],["77609.28000000","0.00000000"],["77610.93000000","0.33983000"]]}}
{"type":"depth","received_at_ms":1788331807275,"data":{"e":"depthUpdate","E":1788331807414,"s":"BTCUSDT","U":99555804915,"u":99555804950,"b":[["77597.06000000","1.19168000"],["77591.20000000","0.00335000"],["77589.09000000","0.00200000"],["77589.04000000","0.00400000"],["77581.28000000","0.00000000"],["77549.24000000","0.30971000"],["77549.23000000","0.00000000"],["77537.06000000","0.25778000"],["69837.36000000","0.00441000"],["62077.65000000","0.00000000"]],"a":[["77597.08000000","0.01090000"],["77597.76000000","0.00000000"],["77597.82000000","0.32246000"],["77598.32000000","0.01718000"],["77598.79000000","0.00658000"],["77604.91000000","0.00400000"],["77689.33000000","0.34873000"],["77692.22000000","0.00000000"],["77694.81000000","2.15391000"],["77929.68000000","0.50005000"]]}}
{"type":"trade","received_at_ms":1788331807368,"data":{"e":"trade","E":1788331807507,"s":"BTCUSDT","t":6646633286,"p":"77597.06000000","q":"0.00025000","T":1788331807506,"m":true,"M":true}}
{"type":"depth","received_at_ms":1788331807374,"data":{"e":"depthUpdate","E":1788331807514,"s":"BTCUSDT","U":99555804951,"u":99555804973,"b":[["77597.06000000","1.29038000"],["77589.76000000","0.00000000"],["77589.24000000","0.00257000"],["77589.08000000","0.00000000"],["69837.36000000","0.00448000"],["69837.35000000","0.00009000"],["62078.00000000","0.00400000"],["62077.65000000","0.00032000"]],"a":[["77598.79000000","0.00665000"],["77599.04000000","0.00007000"],["77599.05000000","0.05000000"],["77599.16000000","0.00000000"],["77599.17000000","0.04166000"],["77599.35000000","0.05000000"],["77603.64000000","0.00000000"],["77603.97000000","0.00257000"],["77729.49000000","0.53080000"],["77729.50000000","0.16870000"],["77729.68000000","1.54467000"]]}}
{"type":"depth","received_at_ms":1788331807474,"data":{"e":"depthUpdate","E":1788331807614,"s":"BTCUSDT","U":99555804974,"u":99555805005,"b":[["77597.06000000","1.29046000"],["77589.67000000","0.00400000"],["77589.09000000","0.00000000"],["77589.04000000","0.00000000"],["77586.02000000","0.00200000"],["77193.02000000","0.00044000"],["69837.36000000","0.00432000"],["62077.65000000","0.00000000"]],"a":[["77597.07000000","5.00082000"],["77597.83000000","0.00594000"],["77598.79000000","0.00665000"],["77598.84000000","0.00007000"],["77598.85000000","0.05007000"],["77599.04000000","0.00000000"],["77599.05000000","0.00014000"],["77599.17000000","0.04159000"],["77599.35000000","0.00000000"],["77599.56000000","0.02028000"],["77600.54000000","0.00400000"]]}}
{"type":"depth","received_at_ms":1788331807574,"data":{"e":"depthUpdate","E":1788331807714,"s":"BTCUSDT","U":99555805006,"u":99555805043,"b":[["77597.06000000","1.31046000"],["69837.36000000","0.00432000"]],"a":[["77597.07000000","5.00290000"],["77597.08000000","0.01097000"],["77597.82000000","0.32246000"],["77597.83000000","0.00608000"],["77598.79000000","0.00658000"],["77598.84000000","0.00000000"],["77598.85000000","0.00021000"],["77599.05000000","0.00000000"],["77599.16000000","0.00007000"],["77599.17000000","0.04145000"],["77603.97000000","0.00000000"],["77603.98000000","0.00257000"],["77729.49000000","0.07306000"],["77729.68000000","0.00000000"],["77729.69000000","1.54467000"],["78084.24000000","0.00033000"]]}}
{"type":"trade","received_at_ms":1788331807655,"data":{"e":"trade","E":1788331807793,"s":"BTCUSDT","t":6646633287,"p":"77597.07000000","q":"0.00070000","T":1788331807792,"m":false,"M":true}}
{"type":"depth","received_at_ms":1788331807675,"data":{"e":"depthUpdate","E":1788331807814,"s":"BTCUSDT","U":99555805044,"u":99555805058,"b":[["77597.06000000","1.31039000"],["77591.79000000","0.00077000"],["69837.35000000","0.00000000"],["62077.65000000","0.00000000"]],"a":[["77597.07000000","5.00220000"],["77598.79000000","0.00658000"],["77598.85000000","0.00007000"],["77599.17000000","0.04159000"],["77693.99000000","1.19898000"]]}}
{"type":"trade","received_at_ms":1788331807752,"data":{"e":"trade","E":1788331807891,"s":"BTCUSDT","t":6646633288,"p":"77597.07000000","q":"0.00100000","T":1788331807891,"m":false,"M":true}}
{"type":"depth","received_at_ms":1788331807774,"data":{"e":"depthUpdate","E":1788331807914,"s":"BTCUSDT","U":99555805059,"u":99555805083,"b":[["77589.04000000","0.00200000"],["77586.02000000","0.00000000"],["77579.00000000","0.00140000"],["77575.56000000","0.00000000"],["77565.25000000","0.00000000"],["77526.43000000","0.00000000"],["77495.44000000","0.00412000"],["77024.65000000","0.00014000"],["69837.36000000","0.00432000"]],"a":[["77597.07000000","4.99825000"],["77598.32000000","0.01725000"],["77598.64000000","0.00007000"],["77598.65000000","0.05000000"],["77598.80000000","0.00007000"],["77599.16000000","0.00000000"],["77612.50000000","0.12884000"],["77615.07000000","0.00000000"],["77653.88000000","0.00000000"],["77684.93000000","0.00000000"]]}}
{"type":"depth","received_at_ms":1788331807874,"data":{"e":"depthUpdate","E":1788331808014,"s":"BTCUSDT","U":99555805084,"u":99555805105,"b":[["77588.66000000","0.00170000"],["77588.02000000","0.00644000"],["69837.36000000","0.00448000"],["69837.00000000","0.00000000"],["62077.65000000","0.00032000"]],"a":[["77598.32000000","0.01718000"],["77598.64000000","0.00000000"],["77598.65000000","0.00014000"],["77599.16000000","0.00007000"],["77599.17000000","0.04145000"],["78242.14000000","0.00767000"],["78761.03000000","0.00030000"]]}}
{"type":"depth","received_at_ms":1788331807974,"data":{"e":"depthUpdate","E":1788331808114,"s":"BTCUSDT","U":99555805106,"u":99555805119,"b":[["77565.20000000","0.00412000"],["69837.36000000","0.00416000"]],"a":[["77598.32000000","0.01718000"],["77598.65000000","0.00000000"],["77598.79000000","0.00665000"],["77598.80000000","0.05007000"],["77599.16000000","0.00000000"],["77599.17000000","0.04159000"]]}}
{"type":"depth","received_at_ms":1788331808075,"data":{"e":"depthUpdate","E":1788331808214,"s":"BTCUSDT","U":99555805120,"u":99555805150,"b":[["77597.06000000","1.36270000"],["77592.24000000","0.00408000"],["77589.04000000","0.00000000"],["77581.28000000","0.00200000"],["77577.78000000","0.00007000"],["77561.20000000","0.00008000"],["77499.65000000","0.00000000"],["69837.36000000","0.00448000"],["62077.65000000","0.00000000"]],"a":[["77597.78000000","0.00028000"],["77598.30000000","0.00014000"],["77598.79000000","0.00658000"],["77598.80000000","0.00021000"],["77598.85000000","0.00007000"],["77599.16000000","0.00007000"],["77599.17000000","0.04145000"],["77600.27000000","0.00000000"],["77608.82000000","0.00007000"],["77632.98000000","0.00400000"],["77732.51000000","0.00000000"]]}}
{"type":"depth","received_at_ms":1788331808174,"data":{"e":"depthUpdate","E":1788331808314,"s":"BTCUSDT","U":99555805151,"u":99555805205,"b":[["77597.06000000","1.36277000"],["77586.02000000","0.00200000"],["77581.28000000","0.00000000"],["77518.29000000","1.10047000"],["77516.12000000","1.61611000"],["77514.01000000","0.02058000"],["77510.94000000","0.00000000"],["77488.03000000","0.04891000"],["77400.74000000","0.02019000"],["77365.24000000","0.00000000"],["76433.10000000","0.00030000"],["69837.36000000","0.00432000"],["62078.00000000","0.00400000"]],"a":[["77597.07000000","4.99818000"],["77597.08000000","0.01090000"],["77597.77000000","0.00000000"],["77597.78000000","0.00014000"],["77597.82000000","0.32253000"],["77597.83000000","0.00014000"],["77598.01000000","0.00000000"],["77598.30000000","0.00652000"],["77598.79000000","0.00658000"],["77598.80000000","0.00007000"],["77599.16000000","0.00014000"],["77599.17000000","0.04159000"],["77599.56000000","0.02042000"],["77600.23000000","0.00007000"],["77684.87000000","0.00412000"],["77720.86000000","0.00971000"],["78399.48000000","0.00064000"]]}}
{"type":"depth","received_at_ms":1788331808274,"data":{"e":"depthUpdate","E":1788331808414,"s":"BTCUSDT","U":99555805206,"u":99555805233,"b":[["77597.06000000","1.36284000"],["77593.93000000","0.00340000"],["77591.14000000","0.04000000"],["77439.41000000","0.00000000"],["69837.36000000","0.00432000"],["62077.65000000","0.00000000"]],"a":[["77597.77000000","0.00014000"],["77597.78000000","0.23493000"],["77597.79000000","0.35674000"],["77597.82000000","0.32253000"],["77597.83000000","0.00000000"],["77598.30000000","0.00666000"],["77600.23000000","0.00000000"],["77601.50000000","0.12559000"],["77678.43000000","0.01680000"],["77686.19000000","0.01799000"],["77693.94000000","0.01360000"],["77715.89000000","0.02019000"],["77717.20000000","0.01360000"],["77777.06000000","0.00000000"]]}}
{"type":"depth","received_at_ms":1788331808375,"data":{"e":"depthUpdate","E":1788331808514,"s":"BTCUSDT","U":99555805234,"u":99555805247,"b":[["77452.09000000","0.02019000"],["77400.74000000","0.00000000"],["77374.22000000","0.02019000"],["69837.36000000","0.00432000"],["62077.65000000","0.00032000"]],"a":[["77597.08000000","0.01090000"],["77597.78000000","0.23507000"],["77599.56000000","0.02028000"]]}}
{"type":"depth","received_at_ms":1788331808474,"data":{"e":"depthUpdate","E":1788331808614,"s":"BTCUSDT","U":99555805248,"u":99555805255,"b":[["69837.36000000","0.00448000"],["62078.00000000","0.00400000"],["62077.65000000","0.00000000"]],"a":[]}}
{"type":"depth","received_at_ms":1788331808574,"data":{"e":"depthUpdate","E":1788331808714,"s":"BTCUSDT","U":99555805256,"u":99555805261,"b":[["77589.67000000","0.00000000"],["69837.36000000","0.00432000"]],"a":[["77613.89000000","0.00000000"],["77615.84000000","0.25788000"],["78952.82000000","0.00013000"]]}}
{"type":"depth","received_at_ms":1788331808676,"data":{"e":"depthUpdate","E":1788331808814,"s":"BTCUSDT","U":99555805262,"u":99555805271,"b":[["77590.18000000","0.00000000"],["77590.09000000","0.00400000"],["76256.04000000","0.00013000"],["69837.36000000","0.00448000"],["62077.65000000","0.00000000"]],"a":[["77619.64000000","0.04538000"],["77622.40000000","0.00000000"],["77729.49000000","0.53080000"]]}}
{"type":"depth","received_at_ms":1788331808775,"data":{"e":"depthUpdate","E":1788331808914,"s":"BTCUSDT","U":99555805272,"u":99555805274,"b":[["69837.36000000","0.00432000"]],"a":[]}}
{"type":"trade","received_at_ms":1788331808784,"data":{"e":"trade","E":1788331808921,"s":"BTCUSDT","t":6646633289,"p":"77597.06000000","q":"0.00100000","T":1788331808921,"m":true,"M":true}}
{"type":"trade","received_at_ms":1788331808872,"data":{"e":"trade","E":1788331809010,"s":"BTCUSDT","t":6646633290,"p":"77597.06000000","q":"0.00070000","T":1788331809010,"m":true,"M":true}}
{"type":"depth","received_at_ms":1788331808875,"data":{"e":"depthUpdate","E":1788331809014,"s":"BTCUSDT","U":99555805275,"u":99555805285,"b":[["77597.06000000","1.30875000"],["69837.36000000","0.00448000"],["69837.35000000","0.00009000"],["62077.65000000","0.00032000"]],"a":[["78761.03000000","0.00030000"],["80559.42000000","0.00012000"]]}}
{"type":"depth","received_at_ms":1788331808974,"data":{"e":"depthUpdate","E":1788331809114,"s":"BTCUSDT","U":99555805286,"u":99555805291,"b":[["77469.84000000","0.00000000"],["69837.36000000","0.00432000"],["69837.00000000","0.00000000"]],"a":[["77653.82000000","0.00412000"],["77741.45000000","0.00000000"]]}}
{"type":"depth","received_at_ms":1788331809074,"data":{"e":"depthUpdate","E":1788331809214,"s":"BTCUSDT","U":99555805292,"u":99555805300,"b":[["77586.02000000","0.00000000"],["77581.28000000","0.00200000"],["77577.78000000","0.00000000"],["69837.36000000","0.00432000"],["62077.65000000","0.00000000"]],"a":[["77608.82000000","0.00000000"],["87336.63000000","0.00011000"]]}}
{"type":"depth","received_at_ms":1788331809175,"data":{"e":"depthUpdate","E":1788331809314,"s":"BTCUSDT","U":99555805301,"u":99555805307,"b":[["77577.78000000","0.00007000"],["76433.10000000","0.00030000"],["69837.36000000","0.00432000"]],"a":[["77608.82000000","0.00007000"],["77615.01000000","0.00412000"]]}}
{"type":"depth","received_at_ms":1788331809275,"data":{"e":"depthUpdate","E":1788331809414,"s":"BTCUSDT","U":99555805308,"u":99555805311,"b":[["69837.36000000","0.00432000"],["62077.65000000","0.00000000"]],"a":[]}}
{"type":"depth","received_at_ms":1788331809374,"data":{"e":"depthUpdate","E":1788331809514,"s":"BTCUSDT","U":99555805312,"u":99555805316,"b":[["77543.13000000","0.00000000"],["69837.36000000","0.00448000"],["62077.65000000","0.00032000"]],"a":[]}}
{"type":"depth","received_at_ms":1788331809474,"data":{"e":"depthUpdate","E":1788331809614,"s":"BTCUSDT","U":99555805317,"u":99555805385,"b":[["77597.06000000","1.30225000"],["77597.05000000","0.00090000"],["77597.03000000","0.00000000"],["77597.02000000","0.00014000"],["77596.94000000","0.08685000"],["77596.93000000","0.00021000"],["77596.16000000","0.00000000"],["77596.15000000","0.00014000"],["77596.01000000","0.00014000"],["77594.37000000","0.00014000"],["77594.36000000","0.01332000"],["77594.15000000","0.00014000"],["77594.14000000","0.11335000"],["77594.01000000","0.00014000"],["77592.70000000","0.00000000"],["77592.69000000","0.11349000"],["77592.02000000","0.73573000"],["77591.78000000","0.00014000"],["77589.76000000","0.10860000"],["77589.04000000","0.11335000"],["77588.66000000","0.00000000"],["77588.38000000","0.00170000"],["77539.72000000","0.00000000"],["69837.36000000","0.00432000"],["62078.00000000","0.00400000"],["62077.65000000","0.00000000"]],"a":[["77597.07000000","5.00462000"],["77597.08000000","0.01097000"],["77597.10000000","0.00014000"],["77597.11000000","0.03220000"],["77597.82000000","0.32849000"],["77598.30000000","0.00028000"],["77599.16000000","0.00000000"]]}}
{"type":"depth","received_at_ms":1788331809576,"data":{"e":"depthUpdate","E":1788331809714,"s":"BTCUSDT","U":99555805386,"u":99555805429,"b":[["77597.06000000","1.30232000"],["77597.05000000","0.00097000"],["77597.02000000","0.00000000"],["77596.94000000","0.08685000"],["77596.93000000","0.00000000"],["77596.15000000","0.00000000"],["77596.00000000","0.03021000"],["77595.48000000","0.00341000"],["77594.36000000","0.01332000"],["77594.14000000","0.11349000"],["77592.69000000","0.11356000"],["77589.05000000","0.00200000"],["77581.28000000","0.00000000"],["77539.81000000","0.14892000"],["69837.36000000","0.00432000"]],"a":[["77597.07000000","5.00562000"],["77597.08000000","0.01097000"],["77597.11000000","0.03234000"],["77597.82000000","0.32849000"],["77598.30000000","0.00014000"]]}}
{"type":"depth","received_at_ms":1788331809675,"data":{"e":"depthUpdate","E":1788331809814,"s":"BTCUSDT","U":99555805430,"u":99555805437,"b":[["77597.06000000","1.30239000"],["77597.05000000","0.00104000"],["69837.36000000","0.00432000"],["62077.65000000","0.00000000"]],"a":[["77597.07000000","5.00995000"]]}}
{"type":"depth","received_at_ms":1788331809775,"data":{"e":"depthUpdate","E":1788331809915,"s":"BTCUSDT","U":99555805438,"u":99555805448,"b":[["77565.20000000","0.00000000"],["77539.81000000","0.02000000"],["77526.41000000","0.00412000"],["77495.44000000","0.00000000"],["69837.36000000","0.00464000"]],"a":[["77615.01000000","0.00000000"],["77653.82000000","0.00000000"],["77684.87000000","0.00000000"]]}}
{"type":"trade","received_at_ms":1788331809842,"data":{"e":"trade","E":1788331809979,"s":"BTCUSDT","t":6646633291,"p":"77597.06000000","q":"0.00015000","T":1788331809978,"m":true,"M":true}}
{"type":"depth","received_at_ms":1788331809875,"data":{"e":"depthUpdate","E":1788331810014,"s":"BTCUSDT","U":99555805449,"u":99555805462,"b":[["77597.06000000","1.30224000"],["69837.36000000","0.00432000"],["69837.35000000","0.00000000"],["69837.34000000","0.00009000"],["62078.00000000","0.00400000"],["62077.65000000","0.00032000"]],"a":[["77597.79000000","0.35681000"],["77597.81000000","0.00629000"],["77597.82000000","0.32253000"],["78761.03000000","0.00030000"]]}}
{"type":"depth","received_at_ms":1788331809974,"data":{"e":"depthUpdate","E":1788331810114,"s":"BTCUSDT","U":99555805463,"u":99555805476,"b":[["69837.36000000","0.00464000"]],"a":[["77597.07000000","5.01002000"],["77597.08000000","0.01104000"],["77597.79000000","0.35681000"],["77597.81000000","0.00643000"],["77599.17000000","0.04145000"],["77690.19000000","0.00087000"],["77698.09000000","0.00000000"]]}}
{"type":"trade","received_at_ms":1788331810046,"data":{"e":"trade","E":1788331810185,"s":"BTCUSDT","t":6646633292,"p":"77597.07000000","q":"0.00070000","T":1788331810185,"m":false,"M":true}}
{"type":"depth","received_at_ms":1788331810075,"data":{"e":"depthUpdate","E":1788331810214,"s":"BTCUSDT","U":99555805477,"u":99555805530,"b":[["77597.06000000","0.49622000"],["77597.05000000","0.00097000"],["77595.48000000","0.00000000"],["77593.93000000","0.00000000"],["77592.69000000","0.11363000"],["77592.02000000","0.73580000"],["77591.20000000","0.00000000"],["77590.09000000","0.00000000"],["77590.03000000","0.00000000"],["77589.77000000","0.00000000"],["77589.31000000","0.00123000"],["77588.76000000","0.00000000"],["77588.38000000","0.00000000"],["77588.37000000","0.00000000"],["77588.02000000","0.00000000"],["77587.98000000","0.00400000"],["77587.78000000","0.00171000"],["77587.32000000","0.00644000"],["77587.13000000","0.00644000"],["77518.29000000","0.70976000"],["77516.12000000","0.00000000"],["77514.01000000","0.50189000"],["77513.53000000","1.61611000"],["69837.36000000","0.00448000"],["62077.65000000","0.00000000"]],"a":[["77597.07000000","5.00848000"],["77597.08000000","0.01062000"],["77598.58000000","0.00400000"],["77600.31000000","0.71276000"],["77600.53000000","0.00644000"],["77600.54000000","0.00000000"],["77601.50000000","0.12552000"],["77603.06000000","0.00000000"],["77613.25000000","0.25788000"],["77615.84000000","0.00000000"]]}}
{"type":"trade","received_at_ms":1788331810084,"data":{"e":"trade","E":1788331810222,"s":"BTCUSDT","t":6646633293,"p":"77597.06000000","q":"0.00382000","T":1788331810221,"m":true,"M":true}}
{"type":"depth","received_at_ms":1788331810174,"data":{"e":"depthUpdate","E":1788331810314,"s":"BTCUSDT","U":99555805531,"u":99555805553,"b":[["77597.06000000","0.49240000"],["77597.05000000","0.00090000"],["77589.05000000","0.00600000"],["77587.78000000","0.00000000"],["77587.32000000","0.00000000"],["77587.14000000","0.00172000"],["77586.71000000","0.00400000"],["77586.35000000","0.00644000"],["77577.78000000","0.00007000"],["76433.10000000","0.00030000"],["69837.36000000","0.00448000"],["69837.00000000","0.00020000"],["62078.00000000","0.00400000"]],"a":[["77597.58000000","0.00400000"],["77603.50000000","0.00400000"],["77608.82000000","0.00007000"],["77615.03000000","0.00412000"]]}}
{"type":"depth","received_at_ms":1788331810275,"data":{"e":"depthUpdate","E":1788331810414,"s":"BTCUSDT","U":99555805554,"u":99555805588,"b":[["77597.06000000","0.65902000"],["77589.05000000","0.01000000"],["77588.08000000","0.00173000"],["77587.14000000","0.00000000"],["77540.43000000","0.12892000"],["69837.36000000","0.00448000"],["69837.00000000","0.00000000"],["62077.65000000","0.00000000"]],"a":[["77597.07000000","5.00724000"],["77597.08000000","0.01097000"],["77597.79000000","0.25778000"],["77597.81000000","0.00028000"],["77598.30000000","0.00007000"],["77598.58000000","0.00000000"],["77599.50000000","0.00400000"],["77604.19000000","0.00400000"]]}}
{"type":"depth","received_at_ms":1788331810382,"data":{"e":"depthUpdate","E":1788331810514,"s":"BTCUSDT","U":99555805589,"u":99555805615,"b":[["77540.43000000","0.00000000"],["69837.36000000","0.00464000"],["62078.00000000","0.00800000"],["62077.65000000","0.00032000"]],"a":[["77597.07000000","5.00717000"],["77597.08000000","0.01097000"],["77597.79000000","0.25778000"],["77597.81000000","0.00014000"],["77598.30000000","0.00014000"],["77599.17000000","0.04159000"],["77600.31000000","0.71269000"],["77600.53000000","0.00000000"],["77601.50000000","0.12559000"],["77601.88000000","0.00644000"],["77653.84000000","0.00734000"]]}}
{"type":"depth","received_at_ms":1788331810474,"data":{"e":"depthUpdate","E":1788331810614,"s":"BTCUSDT","U":99555805616,"u":99555805619,"b":[["69837.36000000","0.00448000"],["62077.65000000","0.00000000"]],"a":[]}}
{"type":"depth","received_at_ms":1788331810575,"data":{"e":"depthUpdate","E":1788331810714,"s":"BTCUSDT","U":99555805620,"u":99555805628,"b":[["77597.06000000","0.66110000"],["77589.06000000","0.00400000"],["77495.40000000","0.00412000"],["69837.36000000","0.00448000"]],"a":[["77597.07000000","5.10724000"],["77604.01000000","0.00800000"]]}}
{"type":"depth","received_at_ms":1788331810675,"data":{"e":"depthUpdate","E":1788331810814,"s":"BTCUSDT","U":99555805629,"u":99555805644,"b":[["77589.24000000","0.00000000"],["77588.96000000","0.00000000"],["77588.95000000","0.00257000"],["77540.31000000","0.12892000"],["69837.36000000","0.00448000"],["62077.65000000","0.00000000"]],"a":[["77597.07000000","5.10713000"],["77599.50000000","0.00000000"],["77600.33000000","0.00400000"]]}}
{"type":"depth","received_at_ms":1788331810775,"data":{"e":"depthUpdate","E":1788331810914,"s":"BTCUSDT","U":99555805645,"u":99555805654,"b":[["77540.60000000","0.00000000"],["77540.40000000","0.00000000"],["77540.31000000","0.00000000"],["69837.36000000","0.00448000"]],"a":[["77597.79000000","0.26423000"]]}}
{"type":"depth","received_at_ms":1788331810874,"data":{"e":"depthUpdate","E":1788331811014,"s":"BTCUSDT","U":99555805655,"u":99555805663,"b":[["77597.06000000","0.66117000"],["77592.46000000","0.00329000"],["77588.08000000","0.00000000"],["77587.66000000","0.00172000"],["77540.86000000","0.00000000"],["77540.76000000","0.00000000"],["69837.36000000","0.00464000"],["62077.65000000","0.00032000"]],"a":[]}}
{"type":"depth","received_at_ms":1788331810974,"data":{"e":"depthUpdate","E":1788331811114,"s":"BTCUSDT","U":99555805664,"u":99555805683,"b":[["77597.06000000","0.55990000"],["77595.45000000","0.00335000"],["77594.36000000","0.01325000"],["77589.31000000","0.00000000"],["77588.95000000","0.00123000"],["77588.94000000","0.00264000"],["77540.66000000","0.12892000"],["69837.36000000","0.00448000"],["40840.60000000","0.00037000"]],"a":[["77597.07000000","5.10520000"],["77597.58000000","0.00000000"],["77598.38000000","0.00400000"],["78761.03000000","0.00030000"],["85356.77000000","0.00383000"]]}}
{"type":"depth","received_at_ms":1788331811079,"data":{"e":"depthUpdate","E":1788331811214,"s":"BTCUSDT","U":99555805684,"u":99555805697,"b":[["77587.66000000","0.00000000"],["77587.14000000","0.00173000"],["77540.66000000","0.00000000"],["69837.36000000","0.00464000"],["62078.00000000","0.00800000"],["62077.65000000","0.00000000"]],"a":[["77597.07000000","5.11164000"],["77597.79000000","0.25778000"],["77597.81000000","0.00654000"],["77598.79000000","0.00014000"],["77602.88000000","0.00200000"],["77605.38000000","0.57616000"],["85356.77000000","0.00000000"]]}}
{"type":"depth","received_at_ms":1788331811175,"data":{"e":"depthUpdate","E":1788331811314,"s":"BTCUSDT","U":99555805698,"u":99555805734,"b":[["77597.06000000","0.56018000"],["77597.05000000","0.00097000"],["77595.09000000","0.00007000"],["77594.36000000","0.01332000"],["77588.94000000","0.00007000"],["77588.93000000","0.00257000"],["77577.78000000","0.00007000"],["77541.12000000","0.00000000"],["76433.10000000","0.00030000"],["75557.06000000","0.00000000"],["69837.36000000","0.00448000"]],"a":[["77597.07000000","5.11164000"],["77597.08000000","0.01097000"],["77597.79000000","0.25778000"],["77597.81000000","0.00668000"],["77598.32000000","0.01711000"],["77598.79000000","0.00000000"],["77600.23000000","0.00200000"],["77602.88000000","0.00000000"],["77608.82000000","0.00007000"],["81001.05000000","0.00000000"]]}}
{"type":"trade","received_at_ms":1788331811180,"data":{"e":"trade","E":1788331811320,"s":"BTCUSDT","t":6646633294,"p":"77597.06000000","q":"0.00070000","T":1788331811320,"m":true,"M":true}}
{"type":"depth","received_at_ms":1788331811275,"data":{"e":"depthUpdate","E":1788331811414,"s":"BTCUSDT","U":99555805735,"u":99555805785,"b":[["77597.06000000","0.39078000"],["77595.45000000","0.00000000"],["77592.46000000","0.00000000"],["77588.95000000","0.00000000"],["77588.93000000","0.00000000"],["77588.92000000","0.00257000"],["77588.19000000","0.00125000"],["77587.98000000","0.00000000"],["77587.13000000","0.00400000"],["77586.71000000","0.00000000"],["77586.07000000","0.00400000"],["77585.81000000","0.00644000"],["69837.36000000","0.00464000"],["69837.34000000","0.00000000"],["69837.00000000","0.00000000"],["62078.00000000","0.00800000"],["62077.65000000","0.00000000"]],"a":[["77597.07000000","5.11087000"],["77597.08000000","0.01062000"],["77598.40000000","0.00400000"],["77599.79000000","0.01309000"],["77600.23000000","0.01800000"],["77600.33000000","0.00000000"],["77603.50000000","0.00000000"],["77604.01000000","0.00400000"],["77604.19000000","0.00000000"],["77604.91000000","0.00000000"],["77631.04000000","0.00423000"],["77632.98000000","0.00000000"]]}}
{"type":"trade","received_at_ms":1788331811373,"data":{"e":"trade","E":1788331811511,"s":"BTCUSDT","t":6646633295,"p":"77597.07000000","q":"0.00100000","T":1788331811511,"m":false,"M":true}}
{"type":"depth","received_at_ms":1788331811375,"data":{"e":"depthUpdate","E":1788331811514,"s":"BTCUSDT","U":99555805786,"u":99555805806,"b":[["77597.06000000","0.39071000"],["77597.05000000","0.00090000"],["77591.31000000","0.00335000"],["77589.05000000","0.00800000"],["77588.92000000","0.00000000"],["77588.91000000","0.00257000"],["77587.14000000","0.00000000"],["77586.35000000","0.00000000"],["77586.15000000","0.00174000"],["77586.07000000","0.00000000"],["77585.19000000","0.00400000"],["77585.14000000","0.00644000"],["77577.40000000","0.00200000"],["77565.50000000","0.00000000"],["77561.97000000","0.00200000"],["69837.36000000","0.00448000"],["62077.65000000","0.00032000"]],"a":[["77597.07000000","5.10987000"],["77620.47000000","0.00000000"]]}}
{"type":"depth","received_at_ms":1788331811475,"data":{"e":"depthUpdate","E":1788331811614,"s":"BTCUSDT","U":99555805807,"u":99555805827,"b":[["77589.08000000","0.00000000"],["77588.91000000","0.00000000"],["77588.90000000","0.00257000"],["77577.40000000","0.00000000"],["77541.21000000","0.00000000"],["77541.13000000","0.12892000"],["77138.24000000","0.03240000"],["69837.36000000","0.00448000"],["62078.00000000","0.00800000"],["62077.65000000","0.00000000"]],"a":[["77615.19000000","0.00200000"]]}}
{"type":"depth","received_at_ms":1788331811575,"data":{"e":"depthUpdate","E":1788331811714,"s":"BTCUSDT","U":99555805828,"u":99555805834,"b":[["77588.90000000","0.00000000"],["77577.40000000","0.00200000"],["77565.21000000","0.00624000"],["77541.13000000","0.00000000"],["77540.86000000","0.12892000"],["69837.36000000","0.00448000"]],"a":[]}}
{"type":"depth","received_at_ms":1788331811675,"data":{"e":"depthUpdate","E":1788331811814,"s":"BTCUSDT","U":99555805835,"u":99555805842,"b":[["77567.59000000","0.00000000"],["77567.43000000","0.04561000"],["77540.86000000","0.00000000"],["69837.36000000","0.00464000"],["62077.65000000","0.00000000"]],"a":[]}}
{"type":"depth","received_at_ms":1788331811775,"data":{"e":"depthUpdate","E":1788331811914,"s":"BTCUSDT","U":99555805843,"u":99555805862,"b":[["77595.09000000","0.00000000"],["77589.08000000","0.00200000"],["77577.40000000","0.00000000"],["69837.36000000","0.00432000"]],"a":[["77600.23000000","0.00200000"],["77602.88000000","0.01600000"],["77607.84000000","1.09735000"],["77607.85000000","1.93226000"],["77608.38000000","0.00000000"],["77689.33000000","0.95522000"],["77692.22000000","2.15391000"],["77693.99000000","0.63755000"],["77694.81000000","0.00000000"]]}}
{"type":"depth","received_at_ms":1788331811875,"data":{"e":"depthUpdate","E":1788331812014,"s":"BTCUSDT","U":99555805863,"u":99555805871,"b":[["77461.32000000","0.00020000"],["69837.36000000","0.00448000"],["62077.65000000","0.00032000"],["40840.60000000","0.00000000"]],"a":[["77607.83000000","0.34778000"],["77608.50000000","0.26790000"],["77610.93000000","0.00000000"],["77732.91000000","0.00020000"]]}}
{"type":"depth","received_at_ms":1788331811975,"data":{"e":"depthUpdate","E":1788331812114,"s":"BTCUSDT","U":99555805872,"u":99555805888,"b":[["77597.06000000","0.39064000"],["77591.14000000","0.00000000"],["77565.21000000","0.00212000"],["77540.65000000","0.00000000"],["77540.24000000","0.12892000"],["77526.41000000","0.00000000"],["77495.40000000","0.00000000"],["69837.36000000","0.00448000"]],"a":[["77600.23000000","0.00000000"],["77615.03000000","0.00000000"],["77615.19000000","0.00000000"],["77653.84000000","0.00322000"],["77684.89000000","0.00412000"],["78761.03000000","0.00030000"]]}}
{"type":"depth","received_at_ms":1788331812075,"data":{"e":"depthUpdate","E":1788331812214,"s":"BTCUSDT","U":99555805889,"u":99555805904,"b":[["77587.14000000","0.00174000"],["77586.15000000","0.00000000"],["77540.40000000","0.00000000"],["77540.24000000","0.00000000"],["69837.36000000","0.00448000"],["62077.65000000","0.00000000"]],"a":[["77599.79000000","0.01302000"],["77600.23000000","0.00200000"],["77602.87000000","0.00000000"],["77617.27000000","0.00200000"],["77632.83000000","0.32997000"],["77645.84000000","0.00000000"]]}}
{"type":"depth","received_at_ms":1788331812175,"data":{"e":"depthUpdate","E":1788331812314,"s":"BTCUSDT","U":99555805905,"u":99555805921,"b":[["77587.14000000","0.00000000"],["77586.61000000","0.00174000"],["77577.78000000","0.00000000"],["77539.75000000","0.00000000"],["76433.10000000","0.00030000"],["75557.06000000","0.00010000"],["71389.30000000","0.00015000"],["62078.00000000","0.00800000"]],"a":[["77598.40000000","0.00000000"],["77599.48000000","0.00400000"],["77600.23000000","0.00200000"],["77608.82000000","0.00000000"],["77653.84000000","0.00734000"]]}}
{"type":"depth","received_at_ms":1788331812275,"data":{"e":"depthUpdate","E":1788331812414,"s":"BTCUSDT","U":99555805922,"u":99555805934,"b":[["77577.78000000","0.00007000"],["77540.03000000","0.00000000"],["69837.36000000","0.00448000"],["62078.00000000","0.00800000"]],"a":[["77608.82000000","0.00007000"],["77689.33000000","0.34873000"],["77692.22000000","0.00000000"],["77694.81000000","2.15391000"]]}}
{"type":"trade","received_at_ms":1788331812330,"data":{"e":"trade","E":1788331812469,"s":"BTCUSDT","t":6646633296,"p":"77597.07000000","q":"0.00071000","T":1788331812468,"m":false,"M":true}}
{"type":"depth","received_at_ms":1788331812376,"data":{"e":"depthUpdate","E":1788331812514,"s":"BTCUSDT","U":99555805935,"u":99555805948,"b":[["77539.91000000","0.12892000"],["77539.89000000","0.00000000"],["69837.36000000","0.00473000"],["69837.00000000","0.00000000"],["62077.65000000","0.00032000"]],"a":[["77597.07000000","5.10916000"],["81001.05000000","0.00010000"]]}}
{"type":"trade","received_at_ms":1788331812407,"data":{"e":"trade","E":1788331812545,"s":"BTCUSDT","t":6646633297,"p":"77597.06000000","q":"0.00100000","T":1788331812544,"m":true,"M":true}}
{"type":"depth","received_at_ms":1788331812477,"data":{"e":"depthUpdate","E":1788331812614,"s":"BTCUSDT","U":99555805949,"u":99555805956,"b":[["77597.06000000","0.38964000"],["77539.91000000","0.00000000"],["77539.79000000","0.12892000"],["69837.36000000","0.00457000"],["62078.00000000","0.00800000"],["62077.65000000","0.00000000"],["40840.60000000","0.00037000"]],"a":[]}}
{"type":"depth","received_at_ms":1788331812575,"data":{"e":"depthUpdate","E":1788331812714,"s":"BTCUSDT","U":99555805957,"u":99555805962,"b":[["77588.84000000","0.00264000"],["77539.79000000","0.00000000"],["77526.42000000","0.00412000"],["69837.36000000","0.00473000"]],"a":[]}}
{"type":"depth","received_at_ms":1788331812674,"data":{"e":"depthUpdate","E":1788331812814,"s":"BTCUSDT","U":99555805963,"u":99555805969,"b":[["77540.47000000","0.00000000"],["77539.76000000","0.12892000"],["69837.36000000","0.00457000"],["62077.65000000","0.00020000"]],"a":[]}}
{"type":"depth","received_at_ms":1788331812775,"data":{"e":"depthUpdate","E":1788331812914,"s":"BTCUSDT","U":99555805970,"u":99555805980,"b":[["77588.84000000","0.00007000"],["77565.21000000","0.00624000"],["77539.84000000","0.00000000"],["77539.80000000","0.00000000"],["77539.76000000","0.00000000"],["77539.05000000","0.12892000"],["71389.30000000","0.00000000"],["69837.36000000","0.00473000"],["62077.65000000","0.00000000"]],"a":[]}}
{"type":"depth","received_at_ms":1788331812875,"data":{"e":"depthUpdate","E":1788331813014,"s":"BTCUSDT","U":99555805981,"u":99555805987,"b":[["77588.82000000","0.00257000"],["69837.36000000","0.00457000"],["62078.00000000","0.00800000"],["62077.65000000","0.00032000"]],"a":[]}}
{"type":"depth","received_at_ms":1788331812974,"data":{"e":"depthUpdate","E":1788331813114,"s":"BTCUSDT","U":99555805988,"u":99555806005,"b":[["77597.06000000","0.38971000"],["77597.05000000","0.00097000"],["77594.73000000","0.00330000"],["77588.82000000","0.00000000"],["77588.81000000","0.00257000"],["77539.82000000","0.12892000"],["77539.42000000","0.00000000"],["77539.05000000","0.00000000"],["75900.00000000","6.79065000"],["69837.36000000","0.00473000"]],"a":[["77597.07000000","5.11218000"],["77597.81000000","0.00028000"],["77615.03000000","0.00412000"],["78761.03000000","0.00030000"]]}}
{"type":"depth","received_at_ms":1788331813074,"data":{"e":"depthUpdate","E":1788331813214,"s":"BTCUSDT","U":99555806006,"u":99555806022,"b":[["77539.82000000","0.00000000"],["77539.59000000","0.12892000"],["69837.36000000","0.00425000"],["62077.65000000","0.00000000"]],"a":[["77597.79000000","0.25778000"],["77597.81000000","0.00014000"],["77599.56000000","0.02042000"],["77600.23000000","0.00000000"],["77603.50000000","0.00200000"],["77620.00000000","0.03200000"]]}}
{"type":"depth","received_at_ms":1788331813174,"data":{"e":"depthUpdate","E":1788331813314,"s":"BTCUSDT","U":99555806023,"u":99555806029,"b":[["77588.81000000","0.00000000"],["77588.79000000","0.00579000"],["77539.59000000","0.00000000"],["76433.10000000","0.00030000"],["69837.36000000","0.00457000"]],"a":[]}}
{"type":"depth","received_at_ms":1788331813278,"data":{"e":"depthUpdate","E":1788331813414,"s":"BTCUSDT","U":99555806030,"u":99555806036,"b":[["77588.79000000","0.00322000"],["77577.78000000","0.00007000"],["69837.36000000","0.00441000"]],"a":[["77608.82000000","0.00007000"]]}}
{"type":"depth","received_at_ms":1788331813377,"data":{"e":"depthUpdate","E":1788331813514,"s":"BTCUSDT","U":99555806037,"u":99555806055,"b":[["77588.78000000","0.00257000"],["77565.21000000","0.00212000"],["77539.79000000","0.00000000"],["77526.42000000","0.00000000"],["77495.40000000","0.00412000"],["69837.36000000","0.00425000"],["65146.32000000","0.00000000"],["62078.00000000","0.00800000"],["62077.65000000","0.00032000"],["40840.60000000","0.00000000"]],"a":[["77615.03000000","0.00000000"],["77653.84000000","0.00322000"],["77684.89000000","0.00000000"]]}}
{"type":"depth","received_at_ms":1788331813475,"data":{"e":"depthUpdate","E":1788331813614,"s":"BTCUSDT","U":99555806056,"u":99555806061,"b":[["77588.78000000","0.00000000"],["77588.77000000","0.00257000"],["69837.36000000","0.00441000"],["69837.00000000","0.00000000"],["62077.65000000","0.00000000"]],"a":[]}}
{"type":"depth","received_at_ms":1788331813576,"data":{"e":"depthUpdate","E":1788331813714,"s":"BTCUSDT","U":99555806062,"u":99555806068,"b":[["77588.77000000","0.00000000"],["77588.76000000","0.00257000"],["69837.36000000","0.00441000"]],"a":[["77615.01000000","0.00412000"]]}}
{"type":"depth","received_at_ms":1788331813676,"data":{"e":"depthUpdate","E":1788331813815,"s":"BTCUSDT","U":99555806069,"u":99555806097,"b":[["77597.06000000","0.39193000"],["77597.05000000","0.00111000"],["77596.94000000","0.14678000"],["77596.83000000","0.00014000"],["77596.82000000","0.09903000"],["77596.00000000","0.03028000"],["77595.61000000","0.00014000"],["77595.60000000","0.11335000"],["77594.37000000","0.00000000"],["77594.01000000","0.00000000"],["77588.76000000","0.00000000"],["77588.75000000","0.00257000"],["69837.36000000","0.00441000"],["65146.32000000","0.01188000"]],"a":[["77597.07000000","5.11426000"]]}}
{"type":"depth","received_at_ms":1788331813775,"data":{"e":"depthUpdate","E":1788331813914,"s":"BTCUSDT","U":99555806098,"u":99555806136,"b":[["77597.06000000","0.56063000"],["77596.94000000","0.14678000"],["77596.82000000","0.09917000"],["77596.00000000","0.03028000"],["77595.60000000","0.11342000"],["77592.69000000","0.11349000"],["77592.02000000","0.73573000"],["69837.36000000","0.00441000"],["62077.65000000","0.00000000"]],"a":[["77597.07000000","5.11503000"],["77597.08000000","0.01097000"],["77653.82000000","0.00412000"],["77693.99000000","1.19898000"]]}}
{"type":"trade","received_at_ms":1788331813832,"data":{"e":"trade","E":1788331813969,"s":"BTCUSDT","t":6646633298,"p":"77597.06000000","q":"0.00070000","T":1788331813969,"m":true,"M":true}}
{"type":"depth","received_at_ms":1788331813875,"data":{"e":"depthUpdate","E":1788331814014,"s":"BTCUSDT","U":99555806137,"u":99555806143,"b":[["77597.06000000","0.55993000"],["77588.75000000","0.00000000"],["69837.36000000","0.00448000"],["69837.35000000","0.00009000"],["62077.65000000","0.00032000"]],"a":[]}}
{"type":"depth","received_at_ms":1788331813975,"data":{"e":"depthUpdate","E":1788331814114,"s":"BTCUSDT","U":99555806144,"u":99555806152,"b":[["77595.09000000","0.00007000"],["77588.74000000","0.00257000"],["69837.36000000","0.00432000"],["40840.60000000","0.00037000"]],"a":[["77684.87000000","0.00412000"],["78761.03000000","0.00030000"]]}}
{"type":"depth","received_at_ms":1788331814074,"data":{"e":"depthUpdate","E":1788331814214,"s":"BTCUSDT","U":99555806153,"u":99555806155,"b":[["77415.69000000","0.00000000"],["69837.36000000","0.00448000"],["62077.65000000","0.00000000"]],"a":[]}}
{"type":"depth","received_at_ms":1788331814176,"data":{"e":"depthUpdate","E":1788331814314,"s":"BTCUSDT","U":99555806156,"u":99555806165,"b":[["77565.19000000","0.00412000"],["76433.10000000","0.00030000"],["69837.36000000","0.00432000"],["62078.00000000","0.00800000"]],"a":[]}}
{"type":"depth","received_at_ms":1788331814275,"data":{"e":"depthUpdate","E":1788331814414,"s":"BTCUSDT","U":99555806166,"u":99555806183,"b":[["77589.09000000","0.00124000"],["77588.74000000","0.00000000"],["77588.19000000","0.00000000"],["77587.66000000","0.00172000"],["77586.61000000","0.00000000"],["77577.78000000","0.00007000"],["77539.46000000","0.00000000"],["69837.36000000","0.00448000"]],"a":[["77597.07000000","5.10866000"],["77597.08000000","0.01104000"],["77597.82000000","0.32260000"],["77598.29000000","0.00644000"],["77603.50000000","0.00000000"],["77604.71000000","0.00200000"],["77608.50000000","0.00000000"],["77608.82000000","0.00007000"],["77609.62000000","0.29434000"]]}}
{"type":"depth","received_at_ms":1788331814374,"data":{"e":"depthUpdate","E":1788331814514,"s":"BTCUSDT","U":99555806184,"u":99555806197,"b":[["77588.73000000","0.00257000"],["77417.06000000","4.45738000"],["69837.36000000","0.00432000"],["62077.65000000","0.00032000"]],"a":[["77597.82000000","0.32260000"],["77598.29000000","0.00658000"],["77599.56000000","0.02028000"]]}}
{"type":"depth","received_at_ms":1788331814474,"data":{"e":"depthUpdate","E":1788331814614,"s":"BTCUSDT","U":99555806198,"u":99555806208,"b":[["69837.36000000","0.00448000"],["69837.00000000","0.00000000"],["62078.00000000","0.01000000"],["62077.65000000","0.00000000"]],"a":[["77687.56000000","0.00602000"],["77690.19000000","0.00000000"]]}}
{"type":"depth","received_at_ms":1788331814576,"data":{"e":"depthUpdate","E":1788331814714,"s":"BTCUSDT","U":99555806209,"u":99555806218,"b":[["77565.19000000","0.00000000"],["77526.40000000","0.00412000"],["77495.40000000","0.00000000"],["69837.36000000","0.00432000"],["62078.00000000","0.00800000"]],"a":[["77615.01000000","0.00000000"],["77653.82000000","0.00000000"],["77684.87000000","0.00000000"]]}}
{"type":"depth","received_at_ms":1788331814674,"data":{"e":"depthUpdate","E":1788331814814,"s":"BTCUSDT","U":99555806219,"u":99555806221,"b":[["77588.73000000","0.00000000"],["77588.72000000","0.00257000"],["69837.36000000","0.00448000"]],"a":[]}}
{"type":"depth","received_at_ms":1788331814776,"data":{"e":"depthUpdate","E":1788331814914,"s":"BTCUSDT","U":99555806222,"u":99555806226,"b":[["69837.36000000","0.00432000"],["62077.65000000","0.00000000"]],"a":[]}}
{"type":"depth","received_at_ms":1788331814874,"data":{"e":"depthUpdate","E":1788331815014,"s":"BTCUSDT","U":99555806227,"u":99555806235,"b":[["77566.27000000","0.00000000"],["77542.03000000","0.00000000"],["69837.36000000","0.00432000"],["62078.00000000","0.00600000"],["62077.65000000","0.00032000"],["40840.60000000","0.00000000"]],"a":[]}}
{"type":"depth","received_at_ms":1788331814975,"data":{"e":"depthUpdate","E":1788331815114,"s":"BTCUSDT","U":99555806236,"u":99555806239,"b":[["77495.45000000","0.00412000"],["69837.36000000","0.00416000"]],"a":[["78761.03000000","0.00030000"]]}}
{"type":"trade","received_at_ms":1788331814984,"data":{"e":"trade","E":1788331815123,"s":"BTCUSDT","t":6646633299,"p":"77597.07000000","q":"0.00382000","T":1788331815122,"m":false,"M":true}}
{"type":"trade","received_at_ms":1788331814988,"data":{"e":"trade","E":1788331815126,"s":"BTCUSDT","t":6646633300,"p":"77597.07000000","q":"0.00100000","T":1788331815126,"m":false,"M":true}}
{"type":"depth","received_at_ms":1788331815075,"data":{"e":"depthUpdate","E":1788331815214,"s":"BTCUSDT","U":99555806240,"u":99555806248,"b":[["69837.36000000","0.00432000"],["69837.35000000","0.00000000"],["62077.65000000","0.00000000"]],"a":[["77597.07000000","5.10384000"],["77617.27000000","0.00000000"],["77619.32000000","0.00200000"]]}}
{"type":"depth","received_at_ms":1788331815176,"data":{"e":"depthUpdate","E":1788331815314,"s":"BTCUSDT","U":99555806249,"u":99555806259,"b":[["77588.72000000","0.00000000"],["77588.71000000","0.00257000"],["77540.36000000","0.00000000"],["76433.10000000","0.00030000"],["69837.36000000","0.00432000"]],"a":[["77597.07000000","5.10484000"]]}}
{"type":"depth","received_at_ms":1788331815276,"data":{"e":"depthUpdate","E":1788331815415,"s":"BTCUSDT","U":99555806260,"u":99555806287,"b":[["77597.06000000","0.56122000"],["77587.37000000","0.00400000"],["77585.19000000","0.00000000"],["77577.78000000","0.00000000"],["77570.13000000","0.51116000"],["77549.24000000","0.60086000"],["77546.86000000","1.01868000"],["77540.40000000","0.00000000"],["77540.29000000","0.00000000"],["69837.36000000","0.00416000"]],"a":[["77597.07000000","5.09840000"],["77597.10000000","0.00000000"],["77597.11000000","0.00014000"],["77599.16000000","0.00007000"],["77602.88000000","0.00000000"],["77604.39000000","0.01600000"],["77608.82000000","0.00000000"],["77851.55000000","0.00000000"]]}}
{"type":"depth","received_at_ms":1788331815374,"data":{"e":"depthUpdate","E":1788331815514,"s":"BTCUSDT","U":99555806288,"u":99555806307,"b":[["77597.06000000","0.55993000"],["77577.78000000","0.00007000"],["69837.36000000","0.00448000"],["62077.65000000","0.00032000"]],"a":[["77597.07000000","5.09833000"],["77597.08000000","0.01090000"],["77597.11000000","0.00000000"],["77599.56000000","0.02042000"],["77608.82000000","0.00007000"],["77684.94000000","0.00412000"]]}}
{"type":"depth","received_at_ms":1788331815478,"data":{"e":"depthUpdate","E":1788331815614,"s":"BTCUSDT","U":99555806308,"u":99555806314,"b":[["77587.37000000","0.00000000"],["77586.59000000","0.00400000"],["69837.36000000","0.00432000"],["62078.00000000","0.00800000"],["62077.65000000","0.00000000"]],"a":[]}}
{"type":"depth","received_at_ms":1788331815575,"data":{"e":"depthUpdate","E":1788331815714,"s":"BTCUSDT","U":99555806315,"u":99555806324,"b":[["77588.71000000","0.00000000"],["77588.70000000","0.00257000"],["69837.36000000","0.00448000"],["69837.00000000","0.00000000"],["62078.00000000","0.00600000"],["40840.60000000","0.00037000"]],"a":[["77615.08000000","0.00412000"]]}}
{"type":"depth","received_at_ms":1788331815675,"data":{"e":"depthUpdate","E":1788331815814,"s":"BTCUSDT","U":99555806325,"u":99555806326,"b":[["77539.26000000","0.12892000"],["69837.36000000","0.00432000"]],"a":[]}}
{"type":"depth","received_at_ms":1788331815774,"data":{"e":"depthUpdate","E":1788331815914,"s":"BTCUSDT","U":99555806327,"u":99555806332,"b":[["77587.66000000","0.00000000"],["77587.14000000","0.00154000"],["69837.36000000","0.00448000"],["62077.65000000","0.00000000"]],"a":[]}}
{"type":"depth","received_at_ms":1788331815875,"data":{"e":"depthUpdate","E":1788331816014,"s":"BTCUSDT","U":99555806333,"u":99555806343,"b":[["77589.09000000","0.00000000"],["77588.71000000","0.00130000"],["69837.36000000","0.00432000"],["62078.00000000","0.00600000"],["62077.65000000","0.00032000"]],"a":[["77597.07000000","5.09585000"]]}}
{"type":"depth","received_at_ms":1788331815974,"data":{"e":"depthUpdate","E":1788331816114,"s":"BTCUSDT","U":99555806344,"u":99555806349,"b":[["69837.36000000","0.00448000"]],"a":[["77602.88000000","0.00200000"],["77604.71000000","0.00000000"],["77653.89000000","0.00412000"],["78761.03000000","0.00030000"]]}}
{"type":"trade","received_at_ms":1788331816024,"data":{"e":"trade","E":1788331816162,"s":"BTCUSDT","t":6646633301,"p":"77597.06000000","q":"0.00100000","T":1788331816162,"m":true,"M":true}}
{"type":"depth","received_at_ms":1788331816075,"data":{"e":"depthUpdate","E":1788331816214,"s":"BTCUSDT","U":99555806350,"u":99555806357,"b":[["77597.06000000","0.55893000"],["69837.36000000","0.00432000"],["69837.35000000","0.00009000"],["62077.65000000","0.00000000"]],"a":[["77600.23000000","0.00200000"],["77602.88000000","0.00000000"]]}}
{"type":"depth","received_at_ms":1788331816175,"data":{"e":"depthUpdate","E":1788331816314,"s":"BTCUSDT","U":99555806358,"u":99555806386,"b":[["77597.06000000","0.55886000"],["77597.05000000","0.00104000"],["77596.83000000","0.00000000"],["77596.82000000","0.00014000"],["77594.01000000","0.00007000"],["77588.70000000","0.00000000"],["77588.69000000","0.00257000"],["77565.26000000","0.00412000"],["77539.26000000","0.00000000"],["77526.40000000","0.00000000"],["77495.45000000","0.00000000"],["77488.03000000","0.00007000"],["76433.10000000","0.00030000"],["69837.36000000","0.00448000"],["62078.00000000","0.00600000"]],"a":[["77597.07000000","4.99682000"],["77600.23000000","0.00000000"],["77602.88000000","0.00200000"],["77615.08000000","0.00000000"],["77653.89000000","0.00000000"],["77684.94000000","0.00000000"],["77720.86000000","0.00000000"]]}}
{"type":"depth","received_at_ms":1788331816275,"data":{"e":"depthUpdate","E":1788331816414,"s":"BTCUSDT","U":99555806387,"u":99555806400,"b":[["77596.94000000","0.14671000"],["77596.82000000","0.00000000"],["77595.60000000","0.11349000"],["77592.69000000","0.11356000"],["77539.65000000","0.00000000"],["77499.65000000","0.03997000"],["69837.36000000","0.00432000"]],"a":[["77732.51000000","0.00971000"]]}}
{"type":"depth","received_at_ms":1788331816375,"data":{"e":"depthUpdate","E":1788331816514,"s":"BTCUSDT","U":99555806401,"u":99555806419,"b":[["77577.78000000","0.00007000"],["77539.94000000","0.00000000"],["69837.36000000","0.00432000"],["62078.00000000","0.00600000"],["62077.65000000","0.00032000"]],"a":[["77600.23000000","0.00000000"],["77602.88000000","0.00200000"],["77608.82000000","0.00007000"],["77684.88000000","0.00412000"]]}}
{"type":"depth","received_at_ms":1788331816477,"data":{"e":"depthUpdate","E":1788331816614,"s":"BTCUSDT","U":99555806420,"u":99555806423,"b":[["69837.36000000","0.00432000"],["62077.65000000","0.00000000"],["40840.60000000","0.00000000"]],"a":[]}}
{"type":"depth","received_at_ms":1788331816575,"data":{"e":"depthUpdate","E":1788331816714,"s":"BTCUSDT","U":99555806424,"u":99555806445,"b":[["77597.06000000","0.55866000"],["77589.30000000","0.00000000"],["77581.54000000","0.00008000"],["77573.78000000","0.00136000"],["77566.02000000","0.00008000"],["77539.59000000","0.00000000"],["77539.40000000","0.00000000"],["69837.36000000","0.00416000"],["62078.00000000","0.00600000"]],"a":[["77597.07000000","4.99692000"],["77600.23000000","0.00200000"],["77602.88000000","0.00000000"],["77604.83000000","0.00007000"]]}}
{"type":"trade","received_at_ms":1788331816602,"data":{"e":"trade","E":1788331816740,"s":"BTCUSDT","t":6646633302,"p":"77597.07000000","q":"0.00052000","T":1788331816739,"m":false,"M":true}}
{"type":"trade","received_at_ms":1788331816642,"data":{"e":"trade","E":1788331816779,"s":"BTCUSDT","t":6646633303,"p":"77597.06000000","q":"0.00022000","T":1788331816778,"m":true,"M":true}}
{"type":"depth","received_at_ms":1788331816676,"data":{"e":"depthUpdate","E":1788331816814,"s":"BTCUSDT","U":99555806446,"u":99555806467,"b":[["77597.06000000","0.55844000"],["77596.94000000","0.14678000"],["77596.76000000","0.00014000"],["77596.75000000","0.08219000"],["77594.01000000","0.00000000"],["77588.69000000","0.00000000"],["77588.68000000","0.00257000"],["77539.41000000","0.12892000"],["73418.00000000","0.00274000"],["69837.36000000","0.00432000"],["69837.35000000","0.00000000"],["69837.34000000","0.00009000"],["69837.00000000","0.00000000"]],"a":[["77597.07000000","5.07759000"],["77600.23000000","0.00000000"],["77602.88000000","0.00200000"],["77612.59000000","0.00023000"],["77620.35000000","0.00015000"],["77628.11000000","0.00015000"]]}}
{"type":"depth","received_at_ms":1788331816775,"data":{"e":"depthUpdate","E":1788331816914,"s":"BTCUSDT","U":99555806468,"u":99555806483,"b":[["77597.06000000","0.55851000"],["77597.05000000","0.00111000"],["77596.94000000","0.14678000"],["77596.75000000","0.08226000"],["77592.69000000","0.11349000"],["69837.36000000","0.00432000"],["62077.65000000","0.00000000"]],"a":[["77653.83000000","0.00412000"],["77713.46000000","0.00011000"]]}}
{"type":"depth","received_at_ms":1788331816877,"data":{"e":"depthUpdate","E":1788331817014,"s":"BTCUSDT","U":99555806484,"u":99555806496,"b":[["77539.41000000","0.00000000"],["77538.51000000","0.12892000"],["69837.36000000","0.00432000"],["62096.00000000","0.00000000"],["62084.00000000","0.00400000"],["62078.00000000","0.00400000"],["62077.65000000","0.00032000"]],"a":[["77600.23000000","0.00200000"],["77602.88000000","0.00000000"],["77665.06000000","0.25779000"],["77675.69000000","0.34778000"]]}}
{"type":"depth","received_at_ms":1788331816975,"data":{"e":"depthUpdate","E":1788331817114,"s":"BTCUSDT","U":99555806497,"u":99555806504,"b":[["77538.51000000","0.00000000"],["77495.39000000","0.00412000"],["69837.36000000","0.00432000"]],"a":[["77600.23000000","0.00000000"],["77602.88000000","0.00200000"],["78761.03000000","0.00030000"]]}}
{"type":"depth","received_at_ms":1788331817076,"data":{"e":"depthUpdate","E":1788331817215,"s":"BTCUSDT","U":99555806505,"u":99555806520,"b":[["77002.15000000","0.00000000"],["75557.06000000","0.00000000"],["69837.36000000","0.00448000"],["62077.65000000","0.00000000"]],"a":[["77597.07000000","5.07761000"],["77604.83000000","0.00009000"],["77612.59000000","0.00025000"],["77620.35000000","0.00017000"],["77628.11000000","0.00017000"],["81001.05000000","0.00000000"]]}}
{"type":"depth","received_at_ms":1788331817175,"data":{"e":"depthUpdate","E":1788331817314,"s":"BTCUSDT","U":99555806521,"u":99555806528,"b":[["77588.68000000","0.00000000"],["77588.67000000","0.00257000"],["77526.41000000","0.00412000"],["76433.10000000","0.00030000"],["69837.36000000","0.00432000"]],"a":[]}}
{"type":"depth","received_at_ms":1788331817275,"data":{"e":"depthUpdate","E":1788331817414,"s":"BTCUSDT","U":99555806529,"u":99555806529,"b":[["69837.36000000","0.00448000"]],"a":[]}}
{"type":"depth","received_at_ms":1788331817374,"data":{"e":"depthUpdate","E":1788331817514,"s":"BTCUSDT","U":99555806530,"u":99555806548,"b":[["77592.03000000","0.07775000"],["77588.67000000","0.00000000"],["77588.66000000","0.00257000"],["77586.02000000","0.07775000"],["77581.28000000","0.07775000"],["77577.78000000","0.00007000"],["77577.40000000","0.07775000"],["77572.97000000","0.00000000"],["69837.36000000","0.00432000"],["62077.65000000","0.00032000"],["40840.60000000","0.00037000"]],"a":[["77608.82000000","0.00007000"],["77839.21000000","0.00257000"]]}}
{"type":"depth","received_at_ms":1788331817479,"data":{"e":"depthUpdate","E":1788331817614,"s":"BTCUSDT","U":99555806549,"u":99555806622,"b":[["77597.06000000","0.55858000"],["77592.69000000","0.11349000"],["77592.04000000","1.35815000"],["77592.03000000","2.01001000"],["77592.02000000","0.00000000"],["77589.76000000","0.00000000"],["77589.04000000","0.00000000"],["69837.36000000","0.00448000"],["62078.00000000","0.00400000"],["62077.65000000","0.00000000"]],"a":[["77597.31000000","0.00000000"],["77597.39000000","0.00400000"],["77598.38000000","0.00000000"],["77598.48000000","0.00000000"],["77598.51000000","0.00400000"],["77599.48000000","0.00000000"],["77603.50000000","0.01200000"],["77604.39000000","0.00400000"]]}}
{"type":"trade","received_at_ms":1788331817505,"data":{"e":"trade","E":1788331817644,"s":"BTCUSDT","t":6646633304,"p":"77597.06000000","q":"0.00709000","T":1788331817643,"m":true,"M":true}}
{"type":"trade","received_at_ms":1788331817508,"data":{"e":"trade","E":1788331817647,"s":"BTCUSDT","t":6646633305,"p":"77597.07000000","q":"0.00434000","T":1788331817647,"m":false,"M":true}}
{"type":"depth","received_at_ms":1788331817574,"data":{"e":"depthUpdate","E":1788331817714,"s":"BTCUSDT","U":99555806623,"u":99555806670,"b":[["77597.06000000","0.55156000"],["77592.69000000","0.11356000"],["77592.05000000","0.01400000"],["77589.08000000","0.00000000"],["77589.06000000","0.00000000"],["77589.05000000","0.00000000"],["77588.66000000","0.00000000"],["77588.64000000","0.00257000"],["77581.29000000","0.00000000"],["77565.26000000","0.00000000"],["77526.41000000","0.00000000"],["77495.39000000","0.00000000"],["69837.36000000","0.00432000"],["69837.34000000","0.00000000"]],"a":[["77597.07000000","5.07327000"],["77597.08000000","0.01090000"],["77615.02000000","0.00412000"],["77653.83000000","0.00000000"],["77684.88000000","0.00000000"]]}}
{"type":"trade","received_at_ms":1788331817614,"data":{"e":"trade","E":1788331817753,"s":"BTCUSDT","t":6646633306,"p":"77597.06000000","q":"0.00100000","T":1788331817752,"m":true,"M":true}}
{"type":"depth","received_at_ms":1788331817674,"data":{"e":"depthUpdate","E":1788331817814,"s":"BTCUSDT","U":99555806671,"u":99555806693,"b":[["77597.06000000","0.55056000"],["77592.06000000","0.01200000"],["77592.05000000","0.00200000"],["77588.64000000","0.00000000"],["77588.63000000","0.00257000"],["77581.29000000","0.00000000"],["77539.11000000","0.00000000"],["69837.36000000","0.00448000"]],"a":[["77602.88000000","0.00000000"],["77603.06000000","0.00000000"]]}}
{"type":"trade","received_at_ms":1788331817705,"data":{"e":"trade","E":1788331817843,"s":"BTCUSDT","t":6646633307,"p":"77597.07000000","q":"0.00069000","T":1788331817842,"m":false,"M":true}}
{"type":"depth","received_at_ms":1788331817775,"data":{"e":"depthUpdate","E":1788331817914,"s":"BTCUSDT","U":99555806694,"u":99555806711,"b":[["77597.06000000","0.55063000"],["77592.69000000","0.11363000"],["77591.78000000","0.00007000"],["77591.77000000","0.00000000"],["77539.25000000","0.00000000"],["77019.54000000","0.00443000"],["71389.30000000","0.00015000"],["69837.36000000","0.00432000"],["69837.00000000","0.00000000"],["62077.65000000","0.00000000"]],"a":[["77597.07000000","5.07258000"],["77604.01000000","0.00600000"],["77653.86000000","0.00412000"]]}}
{"type":"depth","received_at_ms":1788331817875,"data":{"e":"depthUpdate","E":1788331818014,"s":"BTCUSDT","U":99555806712,"u":99555806721,"b":[["77572.97000000","0.07775000"],["69837.36000000","0.00432000"],["62077.65000000","0.00032000"]],"a":[["77597.07000000","5.07902000"],["77597.08000000","0.01097000"],["77597.10000000","0.00014000"],["77597.11000000","0.03220000"],["77599.16000000","0.00000000"]]}}
{"type":"depth","received_at_ms":1788331817974,"data":{"e":"depthUpdate","E":1788331818114,"s":"BTCUSDT","U":99555806722,"u":99555806736,"b":[["77495.42000000","0.00412000"],["69837.36000000","0.00432000"]],"a":[["77597.07000000","5.07909000"],["77597.08000000","0.01104000"],["77597.11000000","0.03234000"],["77599.56000000","0.02028000"],["78761.03000000","0.00030000"]]}}
{"type":"depth","received_at_ms":1788331818075,"data":{"e":"depthUpdate","E":1788331818214,"s":"BTCUSDT","U":99555806737,"u":99555806742,"b":[["75557.06000000","0.00010000"],["69837.36000000","0.00432000"],["62077.65000000","0.00000000"]],"a":[]}}
{"type":"depth","received_at_ms":1788331818174,"data":{"e":"depthUpdate","E":1788331818314,"s":"BTCUSDT","U":99555806743,"u":99555806751,"b":[["76433.10000000","0.00030000"],["69837.36000000","0.00448000"],["62078.00000000","0.00400000"]],"a":[]}}
{"type":"depth","received_at_ms":1788331818276,"data":{"e":"depthUpdate","E":1788331818414,"s":"BTCUSDT","U":99555806752,"u":99555806759,"b":[["77538.93000000","0.00000000"],["77538.48000000","0.12892000"],["69837.36000000","0.00448000"],["62078.00000000","0.00400000"],["40840.60000000","0.00000000"]],"a":[]}}
{"type":"depth","received_at_ms":1788331818377,"data":{"e":"depthUpdate","E":1788331818514,"s":"BTCUSDT","U":99555806760,"u":99555806773,"b":[["77577.78000000","0.00007000"],["77526.44000000","0.00412000"],["77460.01000000","0.01318000"],["77459.70000000","0.02019000"],["77452.09000000","0.00000000"],["71389.30000000","0.00000000"],["69837.36000000","0.00464000"],["62077.65000000","0.00052000"]],"a":[["77608.82000000","0.00007000"],["81001.05000000","0.00010000"]]}}
{"type":"depth","received_at_ms":1788331818476,"data":{"e":"depthUpdate","E":1788331818614,"s":"BTCUSDT","U":99555806774,"u":99555806781,"b":[["77406.13000000","0.02019000"],["77374.22000000","0.00000000"],["69837.36000000","0.00432000"],["62078.00000000","0.00400000"],["62077.65000000","0.00000000"]],"a":[]}}
{"type":"depth","received_at_ms":1788331818574,"data":{"e":"depthUpdate","E":1788331818714,"s":"BTCUSDT","U":99555806782,"u":99555806784,"b":[["69837.36000000","0.00464000"]],"a":[["77684.91000000","0.00412000"]]}}
{"type":"trade","received_at_ms":1788331818606,"data":{"e":"trade","E":1788331818745,"s":"BTCUSDT","t":6646633308,"p":"77597.07000000","q":"0.00100000","T":1788331818745,"m":false,"M":true}}
{"type":"depth","received_at_ms":1788331818675,"data":{"e":"depthUpdate","E":1788331818814,"s":"BTCUSDT","U":99555806785,"u":99555806803,"b":[["77597.06000000","0.55049000"],["77592.69000000","0.11349000"],["77592.06000000","0.00000000"],["77592.05000000","0.00000000"],["77581.29000000","0.01400000"],["69837.36000000","0.00457000"]],"a":[["77597.07000000","5.08014000"]]}}
{"type":"depth","received_at_ms":1788331818775,"data":{"e":"depthUpdate","E":1788331818914,"s":"BTCUSDT","U":99555806804,"u":99555806820,"b":[["77597.06000000","0.55056000"],["77593.79000000","0.00327000"],["77587.70000000","0.00400000"],["77587.13000000","0.00000000"],["77586.59000000","0.00000000"],["77586.57000000","0.00400000"],["77581.68000000","0.10287000"],["77581.29000000","0.01400000"],["69837.36000000","0.00473000"],["69837.00000000","0.00020000"],["62077.65000000","0.00000000"]],"a":[]}}
{"type":"depth","received_at_ms":1788331818876,"data":{"e":"depthUpdate","E":1788331819014,"s":"BTCUSDT","U":99555806821,"u":99555806825,"b":[["69837.36000000","0.00457000"],["69837.00000000","0.00000000"],["62078.00000000","0.00400000"],["62077.65000000","0.00032000"]],"a":[]}}
{"type":"depth","received_at_ms":1788331818975,"data":{"e":"depthUpdate","E":1788331819114,"s":"BTCUSDT","U":99555806826,"u":99555806836,"b":[["77565.23000000","0.00412000"],["77526.44000000","0.00000000"],["77495.42000000","0.00000000"],["69837.36000000","0.00473000"]],"a":[["77615.02000000","0.00000000"],["77653.86000000","0.00000000"],["77684.91000000","0.00000000"],["78761.03000000","0.00030000"]]}}
{"type":"depth","received_at_ms":1788331819077,"data":{"e":"depthUpdate","E":1788331819215,"s":"BTCUSDT","U":99555806837,"u":99555806840,"b":[["69837.36000000","0.00457000"],["62077.65000000","0.00000000"]],"a":[]}}
{"type":"trade","received_at_ms":1788331819114,"data":{"e":"trade","E":1788331819253,"s":"BTCUSDT","t":6646633309,"p":"77597.06000000","q":"0.00323000","T":1788331819253,"m":true,"M":true}}
{"type":"trade","received_at_ms":1788331819115,"data":{"e":"trade","E":1788331819253,"s":"BTCUSDT","t":6646633310,"p":"77597.06000000","q":"0.00007000","T":1788331819253,"m":true,"M":true}}
{"type":"trade","received_at_ms":1788331819115,"data":{"e":"trade","E":1788331819253,"s":"BTCUSDT","t":6646633311,"p":"77597.06000000","q":"0.00007000","T":1788331819253,"m":true,"M":true}}
{"type":"trade","received_at_ms":1788331819115,"data":{"e":"trade","E":1788331819253,"s":"BTCUSDT","t":6646633312,"p":"77597.06000000","q":"0.00125000","T":1788331819253,"m":true,"M":true}}
{"type":"trade","received_at_ms":1788331819116,"data":{"e":"trade","E":1788331819255,"s":"BTCUSDT","t":6646633313,"p":"77597.06000000","q":"0.00070000","T":1788331819255,"m":true,"M":true}}
{"type":"depth","received_at_ms":1788331819175,"data":{"e":"depthUpdate","E":1788331819314,"s":"BTCUSDT","U":99555806841,"u":99555806857,"b":[["77597.06000000","0.78869000"],["77592.69000000","0.11356000"],["77592.05000000","0.01200000"],["77581.29000000","0.00200000"],["77526.39000000","0.00412000"],["76433.10000000","0.00030000"],["69837.36000000","0.00464000"],["69837.35000000","0.00009000"]],"a":[]}}
{"type":"trade","received_at_ms":1788331819214,"data":{"e":"trade","E":1788331819353,"s":"BTCUSDT","t":6646633314,"p":"77597.06000000","q":"0.00328000","T":1788331819353,"m":true,"M":true}}
{"type":"trade","received_at_ms":1788331819237,"data":{"e":"trade","E":1788331819375,"s":"BTCUSDT","t":6646633315,"p":"77597.07000000","q":"0.00039000","T":1788331819375,"m":false,"M":true}}
{"type":"depth","received_at_ms":1788331819276,"data":{"e":"depthUpdate","E":1788331819414,"s":"BTCUSDT","U":99555806858,"u":99555806865,"b":[["77597.06000000","0.78541000"],["77592.06000000","0.00200000"],["77581.29000000","0.00000000"],["77538.48000000","0.00000000"],["69837.36000000","0.00448000"]],"a":[["77597.07000000","5.07975000"]]}}
{"type":"depth","received_at_ms":1788331819375,"data":{"e":"depthUpdate","E":1788331819514,"s":"BTCUSDT","U":99555806866,"u":99555806877,"b":[["77597.06000000","0.78548000"],["77577.78000000","0.00000000"],["77539.95000000","0.00000000"],["69837.36000000","0.00448000"],["62078.00000000","0.00400000"],["62077.65000000","0.00032000"]],"a":[["77608.82000000","0.00000000"],["77615.00000000","0.00412000"]]}}
{"type":"depth","received_at_ms":1788331819475,"data":{"e":"depthUpdate","E":1788331819614,"s":"BTCUSDT","U":99555806878,"u":99555806885,"b":[["77577.78000000","0.00007000"],["77539.76000000","0.12892000"],["77539.41000000","0.00000000"],["62077.65000000","0.00000000"]],"a":[["77608.82000000","0.00007000"]]}}
{"type":"depth","received_at_ms":1788331819575,"data":{"e":"depthUpdate","E":1788331819714,"s":"BTCUSDT","U":99555806886,"u":99555806892,"b":[["77539.76000000","0.00000000"],["77495.37000000","0.00412000"],["69837.36000000","0.00448000"],["40840.60000000","0.00037000"]],"a":[]}}
{"type":"trade","received_at_ms":1788331819639,"data":{"e":"trade","E":1788331819777,"s":"BTCUSDT","t":6646633316,"p":"77597.06000000","q":"0.00100000","T":1788331819777,"m":true,"M":true}}
{"type":"depth","received_at_ms":1788331819676,"data":{"e":"depthUpdate","E":1788331819814,"s":"BTCUSDT","U":99555806893,"u":99555806904,"b":[["77597.06000000","0.78441000"],["77592.06000000","0.00000000"],["77581.29000000","0.00200000"],["77539.71000000","0.00000000"],["69837.36000000","0.00464000"],["69837.35000000","0.00000000"]],"a":[["77619.64000000","0.04703000"]]}}
{"type":"depth","received_at_ms":1788331819775,"data":{"e":"depthUpdate","E":1788331819914,"s":"BTCUSDT","U":99555806905,"u":99555806909,"b":[["77540.03000000","0.00000000"],["69837.36000000","0.00448000"]],"a":[["77605.60000000","0.00000000"],["77653.81000000","0.00412000"]]}}
{"type":"depth","received_at_ms":1788331819875,"data":{"e":"depthUpdate","E":1788331820014,"s":"BTCUSDT","U":99555806910,"u":99555806918,"b":[["77593.79000000","0.00000000"],["69837.36000000","0.00464000"],["69837.00000000","0.00000000"],["62077.65000000","0.00032000"]],"a":[]}}
{"type":"depth","received_at_ms":1788331819974,"data":{"e":"depthUpdate","E":1788331820114,"s":"BTCUSDT","U":99555806919,"u":99555806927,"b":[["77597.06000000","0.78441000"],["77592.06000000","0.00200000"],["77581.29000000","0.00000000"],["69837.36000000","0.00448000"]],"a":[["78761.03000000","0.00030000"]]}}
{"type":"depth","received_at_ms":1788331820075,"data":{"e":"depthUpdate","E":1788331820214,"s":"BTCUSDT","U":99555806928,"u":99555806932,"b":[["77597.06000000","0.78448000"],["77593.73000000","0.00337000"],["69837.36000000","0.00448000"],["62077.65000000","0.00000000"]],"a":[]}}
{"type":"depth","received_at_ms":1788331820175,"data":{"e":"depthUpdate","E":1788331820314,"s":"BTCUSDT","U":99555806933,"u":99555806948,"b":[["77597.06000000","0.78449000"],["77592.06000000","0.00000000"],["77590.28000000","0.00322000"],["77588.79000000","0.00000000"],["77581.29000000","0.00200000"],["76433.10000000","0.00030000"],["69837.36000000","0.00448000"],["62078.00000000","0.00400000"]],"a":[["77597.07000000","5.08075000"],["78788.00000000","0.00200000"]]}}
{"type":"depth","received_at_ms":1788331820276,"data":{"e":"depthUpdate","E":1788331820414,"s":"BTCUSDT","U":99555806949,"u":99555806951,"b":[["69837.36000000","0.00464000"]],"a":[]}}
{"type":"depth","received_at_ms":1788331820375,"data":{"e":"depthUpdate","E":1788331820514,"s":"BTCUSDT","U":99555806952,"u":99555806965,"b":[["77597.06000000","0.78456000"],["77592.06000000","0.00200000"],["77581.29000000","0.00000000"],["77565.23000000","0.00000000"],["77539.72000000","0.12892000"],["77526.39000000","0.00000000"],["77495.37000000","0.00000000"],["69837.36000000","0.00432000"],["62077.65000000","0.00032000"],["40840.60000000","0.00000000"]],"a":[["77615.00000000","0.00000000"],["77653.81000000","0.00000000"],["77684.86000000","0.00412000"]]}}
{"type":"trade","received_at_ms":1788331820408,"data":{"e":"trade","E":1788331820543,"s":"BTCUSDT","t":6646633317,"p":"77597.07000000","q":"0.00071000","T":1788331820543,"m":false,"M":true}}
{"type":"depth","received_at_ms":1788331820474,"data":{"e":"depthUpdate","E":1788331820614,"s":"BTCUSDT","U":99555806966,"u":99555806989,"b":[["77597.06000000","0.78449000"],["77593.73000000","0.00000000"],["77593.48000000","0.00334000"],["77592.06000000","0.00200000"],["77581.29000000","0.00000000"],["77577.78000000","0.00007000"],["77539.72000000","0.00000000"],["69837.36000000","0.00473000"],["62078.00000000","0.00400000"],["62077.65000000","0.00000000"]],"a":[["77597.07000000","5.08004000"],["77608.82000000","0.00007000"]]}}
{"type":"trade","received_at_ms":1788331820500,"data":{"e":"trade","E":1788331820639,"s":"BTCUSDT","t":6646633318,"p":"77597.07000000","q":"0.00011000","T":1788331820639,"m":false,"M":true}}
{"type":"depth","received_at_ms":1788331820575,"data":{"e":"depthUpdate","E":1788331820715,"s":"BTCUSDT","U":99555806990,"u":99555806998,"b":[["77597.06000000","0.78449000"],["77592.06000000","0.00000000"],["77581.29000000","0.00200000"],["77565.18000000","0.00412000"],["69837.36000000","0.00457000"]],"a":[["77597.07000000","5.07993000"]]}}
{"type":"depth","received_at_ms":1788331820674,"data":{"e":"depthUpdate","E":1788331820814,"s":"BTCUSDT","U":99555806999,"u":99555807072,"b":[["77597.06000000","1.42159000"],["77592.06000000","0.00200000"],["77588.32000000","0.00152000"],["77587.14000000","0.00000000"],["77586.79000000","0.02000000"],["77581.29000000","0.00000000"],["77578.75000000","0.00000000"],["77568.17000000","0.34823000"],["77543.67000000","0.00000000"],["77540.16000000","0.00000000"],["69837.36000000","0.00473000"]],"a":[["77597.07000000","5.05920000"],["77597.39000000","0.00000000"],["77597.77000000","0.00000000"],["77597.78000000","0.00028000"],["77597.79000000","0.25435000"],["77598.34000000","0.00000000"],["77598.38000000","0.00400000"],["77598.51000000","0.00000000"],["77598.61000000","0.00000000"],["77598.63000000","0.00000000"],["77599.16000000","0.00007000"],["77599.44000000","0.00400000"],["77599.47000000","0.00000000"],["77599.59000000","0.00000000"],["77600.24000000","0.54064000"],["77600.31000000","0.30007000"],["77603.50000000","0.00000000"],["77604.20000000","0.00000000"],["77604.39000000","0.00800000"],["77604.62000000","0.00800000"],["77604.71000000","0.00000000"],["77604.82000000","0.00000000"],["77606.02000000","0.04000000"],["77609.62000000","0.00000000"],["77610.93000000","0.37555000"],["77616.00000000","0.00007000"],["77624.00000000","0.03265000"]]}}
{"type":"depth","received_at_ms":1788331820774,"data":{"e":"depthUpdate","E":1788331820914,"s":"BTCUSDT","U":99555807073,"u":99555807104,"b":[["77597.06000000","1.44299000"],["77590.01000000","0.00128000"],["77588.71000000","0.00000000"],["77581.52000000","0.00128000"],["77579.00000000","0.00012000"],["77540.23000000","0.12892000"],["77526.39000000","0.00412000"],["77499.65000000","0.00000000"],["69837.36000000","0.00457000"],["62078.00000000","0.00400000"]],"a":[["77597.07000000","4.81198000"],["77597.08000000","0.01104000"],["77597.11000000","0.03234000"],["77597.77000000","0.00014000"],["77597.78000000","0.20477000"],["77599.16000000","0.00000000"],["77599.56000000","0.02042000"],["77608.70000000","0.00000000"],["77613.54000000","0.00128000"],["77732.51000000","0.00000000"]]}}
{"type":"depth","received_at_ms":1788331820875,"data":{"e":"depthUpdate","E":1788331821014,"s":"BTCUSDT","U":99555807105,"u":99555807159,"b":[["77597.06000000","1.55786000"],["77597.05000000","0.00104000"],["77595.61000000","0.00000000"],["77595.60000000","0.00014000"],["77594.73000000","0.00000000"],["77594.01000000","0.00007000"],["77593.48000000","0.00000000"],["77592.69000000","0.11356000"],["77592.06000000","0.01400000"],["77592.05000000","0.00000000"],["77591.31000000","0.00000000"],["77581.29000000","0.00000000"],["77540.23000000","0.00000000"],["77501.91000000","0.03997000"],["69837.36000000","0.00457000"],["69837.00000000","0.00000000"],["62077.65000000","0.00032000"]],"a":[["77597.07000000","4.54260000"],["77597.11000000","0.03234000"],["77597.78000000","0.20491000"],["77599.56000000","0.02028000"],["77600.24000000","0.36154000"],["77600.28000000","0.16877000"],["77600.31000000","0.00007000"],["77734.78000000","0.00971000"]]}}
{"type":"depth","received_at_ms":1788331820974,"data":{"e":"depthUpdate","E":1788331821114,"s":"BTCUSDT","U":99555807160,"u":99555807180,"b":[["77597.06000000","1.55779000"],["77597.05000000","0.00097000"],["77596.75000000","0.08233000"],["77596.00000000","0.03021000"],["77595.60000000","0.00000000"],["77595.09000000","0.00000000"],["77592.69000000","0.11363000"],["77540.04000000","0.00000000"],["69837.36000000","0.00457000"]],"a":[["77598.38000000","0.00000000"],["77599.01000000","0.00400000"],["77613.25000000","0.00000000"],["77615.84000000","0.25788000"],["78761.03000000","0.00030000"]]}}
{"type":"depth","received_at_ms":1788331821075,"data":{"e":"depthUpdate","E":1788331821214,"s":"BTCUSDT","U":99555807181,"u":99555807193,"b":[["77597.06000000","1.55786000"],["77597.05000000","0.00104000"],["77594.10000000","0.00335000"],["77590.22000000","0.00343000"],["77540.66000000","0.00000000"],["77540.15000000","0.12892000"],["69837.36000000","0.00457000"],["62077.65000000","0.00000000"]],"a":[["77597.07000000","4.54260000"],["77597.08000000","0.01097000"]]}}
{"type":"depth","received_at_ms":1788331821176,"data":{"e":"depthUpdate","E":1788331821314,"s":"BTCUSDT","U":99555807194,"u":99555807199,"b":[["77540.15000000","0.00000000"],["76433.10000000","0.00030000"],["69837.36000000","0.00473000"]],"a":[]}}
{"type":"depth","received_at_ms":1788331821276,"data":{"e":"depthUpdate","E":1788331821415,"s":"BTCUSDT","U":99555807200,"u":99555807206,"b":[["77597.06000000","1.55793000"],["77594.41000000","0.00329000"],["77594.10000000","0.00000000"],["77592.85000000","0.00328000"],["69837.36000000","0.00457000"]],"a":[]}}
{"type":"depth","received_at_ms":1788331821376,"data":{"e":"depthUpdate","E":1788331821514,"s":"BTCUSDT","U":99555807207,"u":99555807209,"b":[["69837.36000000","0.00473000"],["62077.65000000","0.00032000"]],"a":[["77615.00000000","0.00412000"]]}}
{"type":"depth","received_at_ms":1788331821475,"data":{"e":"depthUpdate","E":1788331821614,"s":"BTCUSDT","U":99555807210,"u":99555807232,"b":[["77597.06000000","1.55793000"],["77597.05000000","0.00104000"],["77577.78000000","0.00007000"],["77577.39000000","0.00000000"],["77572.96000000","0.54223000"],["77540.24000000","0.00000000"],["77518.29000000","1.10047000"],["77516.12000000","1.61611000"],["77514.01000000","0.02058000"],["77513.53000000","0.00000000"],["69837.36000000","0.00457000"],["62078.00000000","0.00400000"],["62077.65000000","0.00000000"]],"a":[["77608.82000000","0.00007000"]]}}
{"type":"trade","received_at_ms":1788331821508,"data":{"e":"trade","E":1788331821646,"s":"BTCUSDT","t":6646633319,"p":"77597.07000000","q":"0.01915000","T":1788331821646,"m":false,"M":true}}
{"type":"depth","received_at_ms":1788331821574,"data":{"e":"depthUpdate","E":1788331821714,"s":"BTCUSDT","U":99555807233,"u":99555807242,"b":[["77540.32000000","0.00000000"],["77540.12000000","0.00000000"],["69837.36000000","0.00448000"],["69837.35000000","0.00009000"]],"a":[["77597.07000000","4.52345000"]]}}
{"type":"trade","received_at_ms":1788331821654,"data":{"e":"trade","E":1788331821790,"s":"BTCUSDT","t":6646633320,"p":"77597.06000000","q":"0.00071000","T":1788331821790,"m":true,"M":true}}
{"type":"depth","received_at_ms":1788331821674,"data":{"e":"depthUpdate","E":1788331821814,"s":"BTCUSDT","U":99555807243,"u":99555807248,"b":[["77597.06000000","1.55722000"],["77539.89000000","0.00000000"],["69837.36000000","0.00416000"]],"a":[["77597.07000000","4.52245000"]]}}
{"type":"depth","received_at_ms":1788331821774,"data":{"e":"depthUpdate","E":1788331821914,"s":"BTCUSDT","U":99555807249,"u":99555807251,"b":[["77495.37000000","0.00412000"],["69837.36000000","0.00448000"]],"a":[]}}
{"type":"depth","received_at_ms":1788331821875,"data":{"e":"depthUpdate","E":1788331822014,"s":"BTCUSDT","U":99555807252,"u":99555807261,"b":[["69837.36000000","0.00432000"],["62078.00000000","0.00400000"],["62077.65000000","0.00032000"]],"a":[]}}
{"type":"depth","received_at_ms":1788331821975,"data":{"e":"depthUpdate","E":1788331822114,"s":"BTCUSDT","U":99555807262,"u":99555807267,"b":[["69837.36000000","0.00432000"],["69837.00000000","0.00000000"]],"a":[["78761.03000000","0.00030000"]]}}
{"type":"depth","received_at_ms":1788331822074,"data":{"e":"depthUpdate","E":1788331822214,"s":"BTCUSDT","U":99555807268,"u":99555807272,"b":[["77538.03000000","0.12892000"],["69837.36000000","0.00432000"],["62077.65000000","0.00000000"],["40840.60000000","0.00037000"]],"a":[]}}
{"type":"depth","received_at_ms":1788331822175,"data":{"e":"depthUpdate","E":1788331822314,"s":"BTCUSDT","U":99555807273,"u":99555807281,"b":[["77538.03000000","0.00000000"],["76433.10000000","0.00000000"],["69837.36000000","0.00448000"],["62078.00000000","0.00400000"]],"a":[]}}
{"type":"trade","received_at_ms":1788331822226,"data":{"e":"trade","E":1788331822364,"s":"BTCUSDT","t":6646633321,"p":"77597.07000000","q":"0.00100000","T":1788331822364,"m":false,"M":true}}
{"type":"depth","received_at_ms":1788331822274,"data":{"e":"depthUpdate","E":1788331822414,"s":"BTCUSDT","U":99555807282,"u":99555807290,"b":[["77538.65000000","0.12892000"],["76433.10000000","0.00030000"],["69837.36000000","0.00432000"],["69837.35000000","0.00000000"],["62078.00000000","0.00400000"]],"a":[["77597.07000000","4.52145000"]]}}
{"type":"depth","received_at_ms":1788331822375,"data":{"e":"depthUpdate","E":1788331822514,"s":"BTCUSDT","U":99555807291,"u":99555807296,"b":[["69837.36000000","0.00432000"],["62078.00000000","0.00600000"],["62077.65000000","0.00032000"]],"a":[]}}
{"type":"depth","received_at_ms":1788331822475,"data":{"e":"depthUpdate","E":1788331822614,"s":"BTCUSDT","U":99555807297,"u":99555807304,"b":[["77577.78000000","0.00007000"],["69837.36000000","0.00432000"],["62077.65000000","0.00000000"]],"a":[["77608.82000000","0.00007000"]]}}
{"type":"trade","received_at_ms":1788331822497,"data":{"e":"trade","E":1788331822635,"s":"BTCUSDT","t":6646633322,"p":"77597.06000000","q":"0.00132000","T":1788331822635,"m":true,"M":true}}
{"type":"trade","received_at_ms":1788331822498,"data":{"e":"trade","E":1788331822637,"s":"BTCUSDT","t":6646633323,"p":"77597.07000000","q":"0.03162000","T":1788331822637,"m":false,"M":true}}
{"type":"depth","received_at_ms":1788331822575,"data":{"e":"depthUpdate","E":1788331822714,"s":"BTCUSDT","U":99555807305,"u":99555807317,"b":[["77597.06000000","1.55590000"],["77565.18000000","0.00000000"],["77526.39000000","0.00000000"],["77495.37000000","0.00000000"],["69837.36000000","0.00432000"],["69837.35000000","0.00009000"]],"a":[["77597.07000000","4.48983000"],["77615.00000000","0.00000000"],["77653.81000000","0.00412000"],["77684.86000000","0.00000000"]]}}
{"type":"depth","received_at_ms":1788331822676,"data":{"e":"depthUpdate","E":1788331822815,"s":"BTCUSDT","U":99555807318,"u":99555807323,"b":[["77597.06000000","1.55598000"],["77568.74000000","0.04708000"],["77567.43000000","0.00000000"],["69837.36000000","0.00448000"]],"a":[["77597.07000000","4.48759000"]]}}
{"type":"depth","received_at_ms":1788331822775,"data":{"e":"depthUpdate","E":1788331822914,"s":"BTCUSDT","U":99555807324,"u":99555807328,"b":[["77581.68000000","0.00000000"],["69837.36000000","0.00432000"]],"a":[["77684.92000000","0.00412000"]]}}
{"type":"depth","received_at_ms":1788331822875,"data":{"e":"depthUpdate","E":1788331823014,"s":"BTCUSDT","U":99555807329,"u":99555807339,"b":[["77580.84000000","0.00000000"],["77501.91000000","0.00000000"],["77491.43000000","0.04883000"],["69837.36000000","0.00448000"],["62077.65000000","0.00032000"]],"a":[["77724.26000000","0.00971000"],["77734.78000000","0.00000000"]]}}
{"type":"depth","received_at_ms":1788331822976,"data":{"e":"depthUpdate","E":1788331823114,"s":"BTCUSDT","U":99555807340,"u":99555807350,"b":[["77594.87000000","0.00333000"],["77565.25000000","0.00412000"],["77494.14000000","0.00000000"],["77493.64000000","0.02849000"],["75557.06000000","0.00000000"],["69837.36000000","0.00432000"],["69837.00000000","0.00000000"],["40840.60000000","0.00000000"]],"a":[["78761.03000000","0.00030000"],["81001.05000000","0.00000000"]]}}
{"type":"depth","received_at_ms":1788331823075,"data":{"e":"depthUpdate","E":1788331823214,"s":"BTCUSDT","U":99555807351,"u":99555807358,"b":[["77538.65000000","0.00000000"],["77538.49000000","0.12892000"],["69837.36000000","0.00448000"],["62078.00000000","0.00600000"],["62077.65000000","0.00000000"]],"a":[]}}
{"type":"trade","received_at_ms":1788331823076,"data":{"e":"trade","E":1788331823215,"s":"BTCUSDT","t":6646633324,"p":"77597.07000000","q":"0.00023000","T":1788331823215,"m":false,"M":true}}
{"type":"depth","received_at_ms":1788331823177,"data":{"e":"depthUpdate","E":1788331823315,"s":"BTCUSDT","U":99555807359,"u":99555807366,"b":[["77597.06000000","1.55605000"],["77597.05000000","0.00111000"],["77495.44000000","0.00412000"],["69837.36000000","0.00432000"],["69837.35000000","0.00000000"],["69837.34000000","0.00009000"]],"a":[["77597.07000000","4.48736000"]]}}
{"type":"trade","received_at_ms":1788331823260,"data":{"e":"trade","E":1788331823399,"s":"BTCUSDT","t":6646633325,"p":"77597.06000000","q":"0.00100000","T":1788331823398,"m":true,"M":true}}
{"type":"trade","received_at_ms":1788331823264,"data":{"e":"trade","E":1788331823403,"s":"BTCUSDT","t":6646633326,"p":"77597.07000000","q":"0.00071000","T":1788331823403,"m":false,"M":true}}
{"type":"depth","received_at_ms":1788331823273,"data":{"e":"depthUpdate","E":1788331823414,"s":"BTCUSDT","U":99555807367,"u":99555807376,"b":[["77597.06000000","1.55505000"],["77588.46000000","0.00400000"],["77586.57000000","0.00000000"],["76433.10000000","0.00030000"],["69837.36000000","0.00432000"]],"a":[["77597.07000000","4.48665000"],["77604.01000000","0.00400000"],["77604.91000000","0.00200000"]]}}
{"type":"depth","received_at_ms":1788331823376,"data":{"e":"depthUpdate","E":1788331823515,"s":"BTCUSDT","U":99555807377,"u":99555807381,"b":[["71389.30000000","0.00015000"],["69837.36000000","0.00432000"],["62077.65000000","0.00032000"]],"a":[["77615.06000000","0.00412000"]]}}
{"type":"depth","received_at_ms":1788331823475,"data":{"e":"depthUpdate","E":1788331823614,"s":"BTCUSDT","U":99555807382,"u":99555807399,"b":[["77577.78000000","0.00000000"],["77406.13000000","0.00000000"],["77377.21000000","0.02019000"],["69837.36000000","0.00448000"],["62078.00000000","0.00600000"],["62077.65000000","0.00020000"]],"a":[["77602.65000000","0.02899000"],["77605.24000000","0.00000000"],["77608.82000000","0.00000000"]]}}
{"type":"depth","received_at_ms":1788331823575,"data":{"e":"depthUpdate","E":1788331823714,"s":"BTCUSDT","U":99555807400,"u":99555807410,"b":[["77577.78000000","0.00007000"],["77565.25000000","0.00000000"],["77526.46000000","0.00412000"],["77495.44000000","0.00000000"],["69837.36000000","0.00416000"],["62077.65000000","0.00000000"]],"a":[["77608.82000000","0.00007000"],["77615.06000000","0.00000000"],["77653.81000000","0.00000000"],["77684.92000000","0.00000000"]]}}
{"type":"depth","received_at_ms":1788331823675,"data":{"e":"depthUpdate","E":1788331823814,"s":"BTCUSDT","U":99555807411,"u":99555807413,"b":[["69837.36000000","0.00448000"]],"a":[["77600.72000000","0.00007000"]]}}
{"type":"depth","received_at_ms":1788331823776,"data":{"e":"depthUpdate","E":1788331823914,"s":"BTCUSDT","U":99555807414,"u":99555807418,"b":[["69837.36000000","0.00432000"],["62078.00000000","0.00600000"]],"a":[]}}
{"type":"depth","received_at_ms":1788331823874,"data":{"e":"depthUpdate","E":1788331824014,"s":"BTCUSDT","U":99555807419,"u":99555807430,"b":[["77588.08000000","0.00644000"],["77586.80000000","0.00644000"],["77585.81000000","0.00000000"],["77585.14000000","0.00000000"],["77526.47000000","0.00322000"],["77526.35000000","0.00000000"],["71389.30000000","0.00000000"],["69837.36000000","0.00416000"],["62077.65000000","0.00032000"]],"a":[["77598.29000000","0.00014000"],["77599.16000000","0.00644000"],["77601.03000000","0.00644000"],["77601.88000000","0.00000000"]]}}
{"type":"trade","received_at_ms":1788331823909,"data":{"e":"trade","E":1788331824046,"s":"BTCUSDT","t":6646633327,"p":"77597.06000000","q":"0.00382000","T":1788331824046,"m":true,"M":true}}
{"type":"depth","received_at_ms":1788331823974,"data":{"e":"depthUpdate","E":1788331824114,"s":"BTCUSDT","U":99555807431,"u":99555807455,"b":[["77597.06000000","1.55123000"],["77495.38000000","0.00412000"],["75557.06000000","0.00010000"],["69837.36000000","0.00432000"],["69837.34000000","0.00000000"]],"a":[["77597.82000000","0.32253000"],["77598.29000000","0.00000000"],["77598.32000000","0.01718000"],["77599.16000000","0.00658000"],["77600.80000000","0.02035000"],["77601.50000000","0.12552000"],["77603.26000000","0.00322000"],["77606.82000000","0.00000000"],["78761.03000000","0.00030000"]]}}
{"type":"depth","received_at_ms":1788331824075,"data":{"e":"depthUpdate","E":1788331824214,"s":"BTCUSDT","U":99555807456,"u":99555807467,"b":[["77538.49000000","0.00000000"],["69837.36000000","0.00432000"],["69837.00000000","0.00000000"],["62077.65000000","0.00000000"]],"a":[["77597.07000000","4.48665000"],["77597.08000000","0.01097000"]]}}
{"type":"depth","received_at_ms":1788331824176,"data":{"e":"depthUpdate","E":1788331824314,"s":"BTCUSDT","U":99555807468,"u":99555807478,"b":[["77594.87000000","0.00000000"],["69837.36000000","0.00448000"],["62078.00000000","0.00600000"],["40840.60000000","0.00037000"]],"a":[["77615.00000000","0.00412000"],["81001.05000000","0.00010000"]]}}
{"type":"depth","received_at_ms":1788331824274,"data":{"e":"depthUpdate","E":1788331824414,"s":"BTCUSDT","U":99555807479,"u":99555807487,"b":[["77597.06000000","1.55116000"],["77597.05000000","0.00104000"],["77516.12000000","0.00000000"],["77513.53000000","1.61611000"],["76433.10000000","0.00030000"],["69837.36000000","0.00432000"],["62078.00000000","0.00600000"]],"a":[]}}
{"type":"depth","received_at_ms":1788331824375,"data":{"e":"depthUpdate","E":1788331824514,"s":"BTCUSDT","U":99555807488,"u":99555807496,"b":[["77518.29000000","0.70976000"],["77514.01000000","0.50189000"],["69837.36000000","0.00448000"],["62077.65000000","0.00032000"]],"a":[["77597.07000000","4.49210000"],["77653.81000000","0.00412000"]]}}
{"type":"trade","received_at_ms":1788331824442,"data":{"e":"trade","E":1788331824580,"s":"BTCUSDT","t":6646633328,"p":"77597.06000000","q":"0.00070000","T":1788331824580,"m":true,"M":true}}
{"type":"depth","received_at_ms":1788331824475,"data":{"e":"depthUpdate","E":1788331824614,"s":"BTCUSDT","U":99555807497,"u":99555807504,"b":[["77597.06000000","1.55046000"],["69837.36000000","0.00432000"],["69837.35000000","0.00009000"],["62078.00000000","0.00600000"],["62077.65000000","0.00000000"]],"a":[]}}
{"type":"depth","received_at_ms":1788331824576,"data":{"e":"depthUpdate","E":1788331824714,"s":"BTCUSDT","U":99555807505,"u":99555807510,"b":[["77577.78000000","0.00007000"],["69837.36000000","0.00448000"],["62077.65000000","0.00000000"]],"a":[["77608.82000000","0.00007000"]]}}
{"type":"depth","received_at_ms":1788331824675,"data":{"e":"depthUpdate","E":1788331824814,"s":"BTCUSDT","U":99555807511,"u":99555807514,"b":[["77417.06000000","0.00000000"],["69837.36000000","0.00432000"]],"a":[]}}
{"type":"depth","received_at_ms":1788331824775,"data":{"e":"depthUpdate","E":1788331824914,"s":"BTCUSDT","U":99555807515,"u":99555807519,"b":[["77595.27000000","0.00328000"],["69837.36000000","0.00448000"]],"a":[["77684.86000000","0.00412000"]]}}
{"type":"depth","received_at_ms":1788331824874,"data":{"e":"depthUpdate","E":1788331825014,"s":"BTCUSDT","U":99555807520,"u":99555807530,"b":[["77597.06000000","1.55053000"],["77597.05000000","0.00111000"],["77595.09000000","0.00007000"],["77586.80000000","0.00000000"],["77586.61000000","0.00644000"],["69837.36000000","0.00432000"],["62078.00000000","0.00600000"],["62077.65000000","0.00032000"]],"a":[["77597.07000000","4.51308000"]]}}
{"type":"depth","received_at_ms":1788331824975,"data":{"e":"depthUpdate","E":1788331825114,"s":"BTCUSDT","U":99555807531,"u":99555807543,"b":[["77565.19000000","0.00412000"],["77526.47000000","0.00000000"],["77526.46000000","0.00000000"],["77526.01000000","0.00321000"],["77495.38000000","0.00000000"],["77418.74000000","4.45551000"],["69837.36000000","0.00448000"]],"a":[["77615.00000000","0.00000000"],["77653.81000000","0.00000000"],["77684.86000000","0.00000000"],["78761.03000000","0.00030000"]]}}
{"type":"depth","received_at_ms":1788331825082,"data":{"e":"depthUpdate","E":1788331825222,"s":"BTCUSDT","U":99555807544,"u":99555807548,"b":[["69837.36000000","0.00432000"],["62077.65000000","0.00000000"],["40840.60000000","0.00000000"]],"a":[]}}
{"type":"depth","received_at_ms":1788331825175,"data":{"e":"depthUpdate","E":1788331825314,"s":"BTCUSDT","U":99555807549,"u":99555807554,"b":[["77595.27000000","0.00000000"],["69837.36000000","0.00432000"],["69837.00000000","0.00000000"]],"a":[["77653.83000000","0.00412000"]]}}
{"type":"depth","received_at_ms":1788331825274,"data":{"e":"depthUpdate","E":1788331825414,"s":"BTCUSDT","U":99555807555,"u":99555807572,"b":[["77595.11000000","0.00341000"],["77540.16000000","0.00000000"],["77516.12000000","1.61611000"],["77514.01000000","0.02058000"],["77513.53000000","0.00000000"],["76433.10000000","0.00030000"],["69837.36000000","0.00432000"]],"a":[["77597.77000000","0.00014000"],["77597.78000000","0.20487000"],["77599.16000000","0.00658000"]]}}
{"type":"depth","received_at_ms":1788331825375,"data":{"e":"depthUpdate","E":1788331825514,"s":"BTCUSDT","U":99555807573,"u":99555807586,"b":[["77597.06000000","1.55053000"],["77597.05000000","0.00111000"],["77540.36000000","0.00000000"],["77495.39000000","0.00412000"],["69837.36000000","0.00432000"],["62078.00000000","0.00600000"],["62077.65000000","0.00032000"]],"a":[]}}
{"type":"depth","received_at_ms":1788331825476,"data":{"e":"depthUpdate","E":1788331825614,"s":"BTCUSDT","U":99555807587,"u":99555807593,"b":[["77597.06000000","1.55046000"],["77595.11000000","0.00000000"],["77594.41000000","0.00000000"],["77592.85000000","0.00000000"],["77578.38000000","0.02000000"],["77548.13000000","0.00000000"],["77528.72000000","0.00000000"],["69837.36000000","0.00416000"],["62077.65000000","0.00000000"]],"a":[["77605.40000000","0.02600000"],["77633.93000000","0.00000000"],["77653.34000000","0.00000000"]]}}
{"type":"depth","received_at_ms":1788331825574,"data":{"e":"depthUpdate","E":1788331825714,"s":"BTCUSDT","U":99555807594,"u":99555807609,"b":[["77597.06000000","1.55032000"],["77597.05000000","0.00097000"],["77592.07000000","0.00200000"],["77592.06000000","0.01200000"],["77581.29000000","0.00000000"],["77577.78000000","0.00007000"],["69837.36000000","0.00432000"],["62077.65000000","0.00000000"]],"a":[["77608.82000000","0.00007000"]]}}
{"type":"trade","received_at_ms":1788331825651,"data":{"e":"trade","E":1788331825790,"s":"BTCUSDT","t":6646633329,"p":"77597.07000000","q":"0.00070000","T":1788331825790,"m":false,"M":true}}
{"type":"depth","received_at_ms":1788331825675,"data":{"e":"depthUpdate","E":1788331825815,"s":"BTCUSDT","U":99555807610,"u":99555807615,"b":[["77597.06000000","1.55039000"],["69837.36000000","0.00448000"],["69837.35000000","0.00000000"],["69837.34000000","0.00009000"]],"a":[["77597.07000000","4.51238000"]]}}
{"type":"trade","received_at_ms":1788331825712,"data":{"e":"trade","E":1788331825851,"s":"BTCUSDT","t":6646633330,"p":"77597.06000000","q":"0.06931000","T":1788331825851,"m":true,"M":true}}
{"type":"depth","received_at_ms":1788331825775,"data":{"e":"depthUpdate","E":1788331825914,"s":"BTCUSDT","U":99555807616,"u":99555807627,"b":[["77597.06000000","1.48101000"],["77592.07000000","0.00000000"],["77588.08000000","0.00000000"],["77587.78000000","0.00644000"],["77581.29000000","0.00200000"],["77541.09000000","0.00000000"],["69837.36000000","0.00432000"]],"a":[["77602.88000000","0.00200000"],["77604.91000000","0.00000000"]]}}
{"type":"trade","received_at_ms":1788331825845,"data":{"e":"trade","E":1788331825981,"s":"BTCUSDT","t":6646633331,"p":"77597.07000000","q":"0.00100000","T":1788331825981,"m":false,"M":true}}
{"type":"depth","received_at_ms":1788331825875,"data":{"e":"depthUpdate","E":1788331826014,"s":"BTCUSDT","U":99555807628,"u":99555807636,"b":[["77588.46000000","0.00000000"],["77587.54000000","0.00400000"],["77586.61000000","0.00000000"],["77586.35000000","0.00644000"],["77516.12000000","0.00000000"],["77513.53000000","1.61611000"],["69837.36000000","0.00448000"],["62077.65000000","0.00052000"]],"a":[["77597.07000000","4.51138000"]]}}
{"type":"depth","received_at_ms":1788331825975,"data":{"e":"depthUpdate","E":1788331826114,"s":"BTCUSDT","U":99555807637,"u":99555807648,"b":[["77595.09000000","0.00000000"],["73717.21000000","0.00020000"],["69837.36000000","0.00432000"],["62077.65000000","0.00032000"]],"a":[["77597.07000000","4.50843000"],["77597.08000000","0.01104000"],["77597.81000000","0.00641000"],["78761.03000000","0.00030000"]]}}
{"type":"trade","received_at_ms":1788331826011,"data":{"e":"trade","E":1788331826148,"s":"BTCUSDT","t":6646633332,"p":"77597.07000000","q":"0.00013000","T":1788331826148,"m":false,"M":true}}
{"type":"depth","received_at_ms":1788331826074,"data":{"e":"depthUpdate","E":1788331826214,"s":"BTCUSDT","U":99555807649,"u":99555807663,"b":[["73717.21000000","0.00040000"],["69837.36000000","0.00448000"],["69837.34000000","0.00000000"],["62077.65000000","0.00000000"]],"a":[["77597.07000000","4.50830000"],["77597.79000000","0.25435000"],["77597.81000000","0.00655000"],["77599.17000000","0.04145000"]]}}
{"type":"depth","received_at_ms":1788331826175,"data":{"e":"depthUpdate","E":1788331826314,"s":"BTCUSDT","U":99555807664,"u":99555807674,"b":[["77592.07000000","0.00200000"],["77581.29000000","0.00000000"],["77526.41000000","0.00412000"],["77514.01000000","0.50189000"],["69837.36000000","0.00432000"],["62078.00000000","0.00600000"]],"a":[["77602.88000000","0.00000000"],["77603.50000000","0.00200000"]]}}
{"type":"depth","received_at_ms":1788331826274,"data":{"e":"depthUpdate","E":1788331826414,"s":"BTCUSDT","U":99555807675,"u":99555807684,"b":[["77597.06000000","1.48108000"],["77540.45000000","0.00000000"],["76433.10000000","0.00030000"],["69837.36000000","0.00448000"],["69837.00000000","0.00000000"]],"a":[]}}
{"type":"depth","received_at_ms":1788331826374,"data":{"e":"depthUpdate","E":1788331826514,"s":"BTCUSDT","U":99555807685,"u":99555807700,"b":[["77581.23000000","0.02000000"],["77578.34000000","0.00000000"],["77548.14000000","0.00000000"],["77542.42000000","0.02000000"],["77540.36000000","0.00000000"],["77528.73000000","0.00000000"],["77516.12000000","1.61611000"],["77514.01000000","0.02058000"],["77513.53000000","0.00000000"],["69837.36000000","0.00432000"],["62077.65000000","0.00032000"]],"a":[["77605.44000000","0.00000000"],["77605.67000000","0.02800000"],["77615.02000000","0.00412000"],["77625.08000000","0.02800000"],["77633.88000000","0.00000000"],["77644.49000000","0.02800000"],["77653.29000000","0.00000000"]]}}
{"type":"depth","received_at_ms":1788331826474,"data":{"e":"depthUpdate","E":1788331826614,"s":"BTCUSDT","U":99555807701,"u":99555807709,"b":[["77597.06000000","1.48101000"],["77592.07000000","0.00000000"],["77581.29000000","0.00200000"],["69837.36000000","0.00448000"],["62078.00000000","0.00600000"],["62077.65000000","0.00000000"]],"a":[]}}
{"type":"trade","received_at_ms":1788331826512,"data":{"e":"trade","E":1788331826650,"s":"BTCUSDT","t":6646633333,"p":"77597.07000000","q":"0.00034000","T":1788331826650,"m":false,"M":true}}
{"type":"depth","received_at_ms":1788331826575,"data":{"e":"depthUpdate","E":1788331826714,"s":"BTCUSDT","U":99555807710,"u":99555807751,"b":[["77597.06000000","1.48108000"],["77592.07000000","0.00200000"],["77589.08000000","0.00644000"],["77587.78000000","0.00000000"],["77581.29000000","0.00000000"],["77577.78000000","0.00000000"],["69837.36000000","0.00457000"],["62077.65000000","0.00000000"]],"a":[["77597.07000000","4.50789000"],["77597.08000000","0.01097000"],["77598.59000000","0.00400000"],["77599.01000000","0.00000000"],["77599.16000000","0.00014000"],["77599.44000000","0.00000000"],["77599.56000000","0.02428000"],["77599.79000000","0.01309000"],["77600.00000000","0.00000000"],["77600.23000000","0.00644000"],["77601.50000000","0.12559000"],["77603.50000000","0.00000000"],["77604.39000000","0.00400000"],["77604.62000000","0.00000000"],["77605.37000000","0.01400000"],["77607.82000000","0.34778000"],["77607.83000000","0.00000000"],["77608.82000000","0.00000000"],["77609.63000000","0.00000000"],["77611.86000000","0.09622000"],["77613.26000000","0.00000000"],["77615.83000000","0.64470000"],["77619.64000000","0.00000000"],["77620.89000000","0.04654000"],["77687.56000000","0.00515000"],["77690.19000000","0.00087000"]]}}
{"type":"depth","received_at_ms":1788331826674,"data":{"e":"depthUpdate","E":1788331826814,"s":"BTCUSDT","U":99555807752,"u":99555807779,"b":[["77594.18000000","0.00400000"],["77589.08000000","0.00000000"],["77588.19000000","0.00644000"],["77577.78000000","0.00007000"],["77569.08000000","0.00000000"],["77565.81000000","0.00200000"],["77563.20000000","0.00000000"],["77561.97000000","0.00000000"],["77541.06000000","0.00000000"],["77540.55000000","0.00000000"],["77540.53000000","0.12892000"],["69837.36000000","0.00473000"]],"a":[["77598.32000000","0.01711000"],["77599.16000000","0.00000000"],["77599.17000000","0.04159000"],["77599.51000000","0.00400000"],["77599.56000000","0.02028000"],["77608.82000000","0.00007000"]]}}
{"type":"depth","received_at_ms":1788331826775,"data":{"e":"depthUpdate","E":1788331826914,"s":"BTCUSDT","U":99555807780,"u":99555807790,"b":[["77597.06000000","1.36592000"],["77526.41000000","0.00000000"],["69837.36000000","0.00441000"]],"a":[["77597.07000000","4.75581000"],["77603.97000000","0.00200000"],["77605.37000000","0.01200000"],["77607.81000000","0.09622000"],["77611.86000000","0.00000000"],["77615.02000000","0.00000000"],["77684.88000000","0.00412000"]]}}
{"type":"trade","received_at_ms":1788331826872,"data":{"e":"trade","E":1788331827010,"s":"BTCUSDT","t":6646633334,"p":"77597.06000000","q":"0.00100000","T":1788331827010,"m":true,"M":true}}
{"type":"depth","received_at_ms":1788331826875,"data":{"e":"depthUpdate","E":1788331827014,"s":"BTCUSDT","U":99555807791,"u":99555807836,"b":[["77597.06000000","0.70656000"],["77597.05000000","0.00104000"],["77592.69000000","0.11363000"],["77592.07000000","0.00000000"],["77592.06000000","0.00000000"],["77590.01000000","0.00000000"],["77589.08000000","0.00132000"],["77588.32000000","0.00000000"],["77588.19000000","0.00000000"],["77587.78000000","0.00157000"],["77587.70000000","0.00000000"],["77587.54000000","0.00000000"],["77586.97000000","0.00644000"],["77586.84000000","0.00400000"],["77586.68000000","0.00000000"],["77586.35000000","0.00000000"],["77585.85000000","0.00400000"],["77584.72000000","0.00000000"],["77584.32000000","0.00644000"],["77581.29000000","0.00200000"],["69837.36000000","0.00448000"],["69837.35000000","0.00009000"],["62077.65000000","0.00032000"]],"a":[["77597.07000000","4.75596000"],["77597.53000000","0.00400000"],["77597.76000000","0.00644000"],["77597.79000000","0.26032000"],["77597.81000000","0.00028000"],["77598.31000000","0.00644000"],["77599.51000000","0.00000000"],["77600.23000000","0.00000000"],["77601.03000000","0.00000000"]]}}
{"type":"trade","received_at_ms":1788331826930,"data":{"e":"trade","E":1788331827068,"s":"BTCUSDT","t":6646633335,"p":"77597.06000000","q":"0.00071000","T":1788331827068,"m":true,"M":true}}
{"type":"depth","received_at_ms":1788331826975,"data":{"e":"depthUpdate","E":1788331827114,"s":"BTCUSDT","U":99555807837,"u":99555807891,"b":[["77597.06000000","0.70585000"],["77593.58000000","0.00000000"],["77592.69000000","0.11363000"],["77592.07000000","0.01200000"],["77588.63000000","0.00000000"],["77587.19000000","0.00257000"],["77541.06000000","0.00000000"],["77540.53000000","0.00000000"],["69837.36000000","0.00448000"],["62077.65000000","0.00032000"]],"a":[["77597.07000000","4.75596000"],["77597.08000000","0.01104000"],["77597.11000000","0.03241000"],["77597.76000000","0.00658000"],["77597.79000000","0.26032000"],["77597.81000000","0.00014000"],["77597.82000000","0.32260000"],["77598.31000000","0.00658000"],["77599.17000000","0.04145000"],["77599.54000000","0.00027000"],["77599.79000000","0.01302000"],["77600.80000000","0.02028000"],["77602.70000000","0.00257000"],["77603.98000000","0.00000000"],["77615.11000000","0.00412000"]]}}
{"type":"trade","received_at_ms":1788331827059,"data":{"e":"trade","E":1788331827199,"s":"BTCUSDT","t":6646633336,"p":"77597.06000000","q":"0.00038000","T":1788331827199,"m":true,"M":true}}
{"type":"depth","received_at_ms":1788331827074,"data":{"e":"depthUpdate","E":1788331827214,"s":"BTCUSDT","U":99555807892,"u":99555807908,"b":[["77597.06000000","0.70554000"],["77592.69000000","0.11363000"],["77592.07000000","0.00800000"],["77592.05000000","0.00400000"],["77491.43000000","0.00000000"],["69837.36000000","0.00432000"],["62077.65000000","0.00000000"]],"a":[["77597.07000000","4.75603000"],["77598.31000000","0.00014000"],["77598.32000000","0.01718000"],["77598.84000000","0.00644000"],["77724.26000000","0.00000000"],["78761.03000000","0.00030000"]]}}
{"type":"depth","received_at_ms":1788331827174,"data":{"e":"depthUpdate","E":1788331827314,"s":"BTCUSDT","U":99555807909,"u":99555807940,"b":[["77592.07000000","0.00807000"],["77592.05000000","0.00400000"],["77585.86000000","0.00644000"],["77584.32000000","0.00000000"],["77581.29000000","0.00200000"],["77526.50000000","0.00412000"],["77518.29000000","1.10047000"],["77501.91000000","0.03997000"],["77494.14000000","0.01424000"],["77493.64000000","0.00000000"],["69837.36000000","0.00464000"]],"a":[["77597.07000000","4.75596000"],["77597.82000000","0.32253000"],["77598.31000000","0.00000000"],["77598.32000000","0.01718000"],["77598.84000000","0.00014000"],["77599.54000000","0.00000000"],["77600.23000000","0.00644000"],["77615.11000000","0.00000000"],["77684.88000000","0.00000000"],["77734.78000000","0.00971000"]]}}
{"type":"trade","received_at_ms":1788331827250,"data":{"e":"trade","E":1788331827389,"s":"BTCUSDT","t":6646633337,"p":"77597.07000000","q":"0.00257000","T":1788331827389,"m":false,"M":true}}
{"type":"depth","received_at_ms":1788331827275,"data":{"e":"depthUpdate","E":1788331827415,"s":"BTCUSDT","U":99555807941,"u":99555807967,"b":[["77597.06000000","0.70547000"],["77592.07000000","0.00007000"],["77592.05000000","0.01200000"],["77585.86000000","0.00000000"],["77584.72000000","0.00644000"],["77581.52000000","0.00000000"],["77579.00000000","0.00140000"],["76433.10000000","0.00030000"],["69837.36000000","0.00448000"],["69837.35000000","0.00000000"]],"a":[["77597.07000000","4.75339000"],["77597.78000000","0.21127000"],["77597.79000000","0.25435000"],["77598.32000000","0.01711000"],["77598.84000000","0.00000000"],["77599.17000000","0.04159000"],["77599.79000000","0.01309000"]]}}
{"type":"trade","received_at_ms":1788331827339,"data":{"e":"trade","E":1788331827477,"s":"BTCUSDT","t":6646633338,"p":"77597.07000000","q":"0.01295000","T":1788331827477,"m":false,"M":true}}
{"type":"depth","received_at_ms":1788331827375,"data":{"e":"depthUpdate","E":1788331827514,"s":"BTCUSDT","U":99555807968,"u":99555807983,"b":[["77592.69000000","0.11363000"],["77583.80000000","0.02000000"],["77578.32000000","0.00000000"],["77544.98000000","0.02000000"],["77539.51000000","0.00000000"],["77523.01000000","0.02000000"],["77520.10000000","0.00000000"],["69837.36000000","0.00464000"],["69837.00000000","0.00020000"],["62077.65000000","0.00032000"]],"a":[["77597.07000000","4.74044000"],["77605.45000000","0.00000000"],["77605.76000000","0.02400000"],["77624.86000000","0.00000000"],["77625.17000000","0.02400000"],["77644.27000000","0.00000000"],["77644.57000000","0.02400000"],["77684.87000000","0.00412000"]]}}
{"type":"depth","received_at_ms":1788331827475,"data":{"e":"depthUpdate","E":1788331827614,"s":"BTCUSDT","U":99555807984,"u":99555807992,"b":[["77597.06000000","0.70554000"],["77592.06000000","0.00200000"],["77581.29000000","0.00000000"],["69837.36000000","0.00448000"],["69837.00000000","0.00000000"],["62078.00000000","0.00800000"],["62077.65000000","0.00000000"]],"a":[["77607.82000000","0.00000000"],["77607.84000000","1.44513000"]]}}
{"type":"depth","received_at_ms":1788331827574,"data":{"e":"depthUpdate","E":1788331827714,"s":"BTCUSDT","U":99555807993,"u":99555808009,"b":[["77597.06000000","0.70547000"],["77592.07000000","0.00000000"],["77592.06000000","0.01400000"],["77592.05000000","0.00000000"],["77541.32000000","0.00000000"],["77540.99000000","0.12892000"],["69837.36000000","0.00464000"],["62078.00000000","0.00600000"],["62077.65000000","0.00000000"]],"a":[]}}
{"type":"depth","received_at_ms":1788331827674,"data":{"e":"depthUpdate","E":1788331827814,"s":"BTCUSDT","U":99555808010,"u":99555808023,"b":[["77594.36000000","0.01325000"],["77592.69000000","0.11363000"],["77577.78000000","0.00007000"],["77540.99000000","0.00000000"],["77540.52000000","0.12892000"],["69837.36000000","0.00448000"],["69837.35000000","0.00027000"]],"a":[["77608.82000000","0.00007000"]]}}
