{"type":"depth","received_at_ms":1788333167248,"data":{"e":"depthUpdate","E":1788333167414,"s":"BTCUSDT","U":99556322536,"u":99556322552,"b":[["77723.99000000","1.02890000"],["77721.11000000","0.10619000"],["77721.10000000","1.00000000"],["77720.25000000","0.02133000"],["77719.35000000","0.00000000"],["77715.77000000","0.11199000"],["77714.81000000","0.11378000"],["77712.31000000","0.00000000"],["69951.60000000","0.00432000"]],"a":[["77728.72000000","0.00600000"]]}}
{"type":"depth","received_at_ms":1788333167357,"data":{"e":"depthUpdate","E":1788333167514,"s":"BTCUSDT","U":99556322553,"u":99556322555,"b":[["69951.60000000","0.00464000"],["62179.20000000","0.00032000"]],"a":[]}}
{"type":"depth","received_at_ms":1788333167448,"data":{"e":"depthUpdate","E":1788333167614,"s":"BTCUSDT","U":99556322556,"u":99556322574,"b":[["77713.72000000","0.00400000"],["77522.01000000","0.00811000"],["77520.01000000","0.00000000"],["69951.60000000","0.00448000"],["69951.00000000","0.00068000"],["62179.20000000","0.00000000"],["62179.19000000","0.00000000"],["62179.00000000","0.00000000"]],"a":[["77724.61000000","0.00400000"]]}}
{"type":"depth","received_at_ms":1788333167548,"data":{"e":"depthUpdate","E":1788333167714,"s":"BTCUSDT","U":99556322575,"u":99556322607,"b":[["77723.99000000","1.93967000"],["77722.62000000","0.00014000"],["77719.35000000","0.26970000"],["77716.12000000","0.00400000"],["77715.77000000","0.00008000"],["77714.83000000","0.66827000"],["77714.82000000","1.31471000"],["77714.81000000","0.00187000"],["77714.80000000","0.00000000"],["77714.31000000","0.00643000"],["77713.72000000","0.00000000"],["77711.64000000","0.00000000"],["77710.48000000","1.93226000"],["77710.47000000","0.00000000"],["76558.13000000","0.00030000"],["69951.60000000","0.00448000"]],"a":[["77724.00000000","4.34728000"],["77724.01000000","0.00090000"],["77724.61000000","0.00000000"],["77726.23000000","0.00000000"],["77726.75000000","0.00014000"],["77727.39000000","0.00400000"],["77728.63000000","0.00643000"],["78889.86000000","0.00030000"],["79262.58000000","0.00025000"]]}}
{"type":"depth","received_at_ms":1788333167648,"data":{"e":"depthUpdate","E":1788333167814,"s":"BTCUSDT","U":99556322608,"u":99556322656,"b":[["77723.99000000","2.10852000"],["77722.74000000","0.01786000"],["77722.63000000","0.00000000"],["77722.62000000","0.00000000"],["77721.33000000","0.00014000"],["77721.25000000","0.10633000"],["77721.12000000","0.34251000"],["77721.11000000","0.00021000"],["77720.25000000","0.02140000"],["77718.18000000","0.00257000"],["77716.29000000","0.00000000"],["77712.30000000","1.08472000"],["77710.49000000","0.00000000"],["77706.35000000","0.00200000"],["77533.22000000","0.00000000"]],"a":[["77724.00000000","2.41502000"],["77725.98000000","0.00014000"],["77726.18000000","0.32193000"],["77726.75000000","0.00000000"],["77726.76000000","0.01281000"],["77726.99000000","0.00643000"],["77727.39000000","0.00000000"],["77728.63000000","0.00000000"],["77728.84000000","0.03600000"],["77730.44000000","0.00643000"],["77731.05000000","0.00000000"],["77732.94000000","0.00257000"]]}}
{"type":"depth","received_at_ms":1788333167748,"data":{"e":"depthUpdate","E":1788333167914,"s":"BTCUSDT","U":99556322657,"u":99556322697,"b":[["77723.99000000","2.10831000"],["77723.98000000","0.00083000"],["77721.25000000","0.10633000"],["77721.12000000","0.34265000"],["77721.11000000","0.00007000"],["77716.21000000","0.00000000"],["77708.44000000","0.00000000"],["77700.67000000","0.00000000"],["77692.90000000","0.00000000"],["77623.69000000","0.00000000"],["69951.60000000","0.00448000"],["62179.00000000","0.00000000"]],"a":[["77724.00000000","2.41488000"],["77724.01000000","0.00076000"],["77724.74000000","0.08219000"],["77725.98000000","0.00000000"],["77726.76000000","0.01281000"],["77726.99000000","0.00657000"],["77817.11000000","0.00411000"]]}}
{"type":"trade","received_at_ms":1788333167841,"data":{"e":"trade","E":1788333168007,"s":"BTCUSDT","t":6646665711,"p":"77724.00000000","q":"0.02187000","T":1788333168006,"m":false,"M":true}}
{"type":"depth","received_at_ms":1788333167847,"data":{"e":"depthUpdate","E":1788333168014,"s":"BTCUSDT","U":99556322698,"u":99556322731,"b":[["77723.99000000","2.38186000"],["77722.60000000","0.00000000"],["77722.55000000","0.00000000"],["77721.10000000","1.00014000"],["77720.87000000","0.04105000"],["77718.73000000","0.00222000"],["77717.54000000","0.00257000"],["77714.30000000","0.00000000"],["77713.61000000","0.00000000"],["77713.59000000","0.00000000"],["77712.83000000","0.00000000"],["77681.04000000","0.00000000"],["77677.11000000","0.00007000"],["77540.56000000","4.65641000"],["69951.60000000","0.00464000"],["69951.59000000","0.00000000"],["69951.58000000","0.00009000"],["62179.20000000","0.00032000"],["62179.19000000","0.00000000"]],"a":[["77724.00000000","2.12013000"],["77732.94000000","0.00000000"]]}}
{"type":"trade","received_at_ms":1788333167941,"data":{"e":"trade","E":1788333168107,"s":"BTCUSDT","t":6646665712,"p":"77724.00000000","q":"0.01500000","T":1788333168107,"m":false,"M":true}}
{"type":"depth","received_at_ms":1788333167948,"data":{"e":"depthUpdate","E":1788333168114,"s":"BTCUSDT","U":99556322732,"u":99556322742,"b":[["77721.30000000","0.00000000"],["77721.25000000","0.10633000"],["77637.05000000","3.04529000"],["77619.19000000","0.00000000"],["69951.60000000","0.00448000"]],"a":[["77724.00000000","2.10513000"],["77733.43000000","0.00000000"],["77733.45000000","0.00257000"]]}}
{"type":"trade","received_at_ms":1788333167963,"data":{"e":"trade","E":1788333168129,"s":"BTCUSDT","t":6646665713,"p":"77724.00000000","q":"0.02015000","T":1788333168129,"m":false,"M":true}}
{"type":"depth","received_at_ms":1788333168048,"data":{"e":"depthUpdate","E":1788333168214,"s":"BTCUSDT","U":99556322743,"u":99556322759,"b":[["77723.99000000","2.38193000"],["77721.32000000","0.01342000"],["77721.31000000","0.00007000"],["77721.30000000","0.05000000"],["77721.26000000","0.00007000"],["77721.25000000","0.10633000"],["77705.37000000","0.00007000"],["69951.60000000","0.00464000"],["62179.20000000","0.00000000"]],"a":[["77724.00000000","2.08498000"],["77736.47000000","0.00007000"],["77813.95000000","2.15325000"],["77816.54000000","0.00000000"]]}}
{"type":"depth","received_at_ms":1788333168147,"data":{"e":"depthUpdate","E":1788333168314,"s":"BTCUSDT","U":99556322760,"u":99556322796,"b":[["77723.99000000","2.38193000"],["77723.98000000","0.00090000"],["77721.50000000","0.02147000"],["77721.36000000","0.00014000"],["77721.35000000","0.00000000"],["77721.33000000","0.00000000"],["77721.32000000","0.01342000"],["77721.31000000","0.00000000"],["77721.30000000","0.00014000"],["77720.87000000","0.04091000"],["77717.09000000","0.00400000"],["77717.08000000","0.00000000"],["77716.12000000","0.00000000"],["69951.60000000","0.00448000"],["62179.00000000","0.00000000"]],"a":[["77733.45000000","0.00000000"],["77733.49000000","0.00257000"]]}}
{"type":"depth","received_at_ms":1788333168248,"data":{"e":"depthUpdate","E":1788333168415,"s":"BTCUSDT","U":99556322797,"u":99556322819,"b":[["77723.99000000","2.38186000"],["77723.98000000","0.00083000"],["77721.50000000","0.02140000"],["77721.36000000","0.00000000"],["77721.33000000","0.00014000"],["77721.32000000","0.01335000"],["77721.30000000","0.00000000"],["77720.87000000","0.04105000"],["77710.49000000","0.00200000"],["77706.35000000","0.00000000"],["69951.60000000","0.00464000"],["62179.00000000","0.00000000"]],"a":[["77733.49000000","0.00000000"],["77733.52000000","0.00265000"]]}}
{"type":"trade","received_at_ms":1788333168305,"data":{"e":"trade","E":1788333168471,"s":"BTCUSDT","t":6646665714,"p":"77723.99000000","q":"0.00154000","T":1788333168470,"m":true,"M":true}}
{"type":"depth","received_at_ms":1788333168347,"data":{"e":"depthUpdate","E":1788333168514,"s":"BTCUSDT","U":99556322820,"u":99556322844,"b":[["77723.99000000","2.38358000"],["77710.49000000","0.00000000"],["77708.87000000","0.00000000"],["77706.58000000","0.00200000"],["77706.46000000","0.00000000"],["77670.01000000","0.00000000"],["77639.14000000","0.00000000"],["77636.50000000","0.02000000"],["77627.11000000","1.28708000"],["77584.84000000","0.02016000"],["77579.38000000","0.00000000"],["69951.60000000","0.00448000"],["69951.58000000","0.00000000"],["62179.20000000","0.00032000"]],"a":[["77733.52000000","0.00008000"],["77733.54000000","0.00257000"],["77747.13000000","0.00000000"],["77786.01000000","0.00411000"],["77817.11000000","0.00000000"]]}}
{"type":"depth","received_at_ms":1788333168449,"data":{"e":"depthUpdate","E":1788333168614,"s":"BTCUSDT","U":99556322845,"u":99556322862,"b":[["77721.10000000","2.50014000"],["77698.00000000","0.03000000"],["77487.79000000","0.00000000"],["77434.50000000","0.00000000"],["77355.08000000","0.00000000"],["77275.66000000","0.00000000"],["69951.60000000","0.00464000"],["69951.00000000","0.00068000"],["62179.20000000","0.00000000"],["62179.19000000","0.00000000"],["62179.00000000","0.00000000"]],"a":[["77733.54000000","0.00000000"],["77733.57000000","0.00257000"]]}}
{"type":"depth","received_at_ms":1788333168547,"data":{"e":"depthUpdate","E":1788333168714,"s":"BTCUSDT","U":99556322863,"u":99556322905,"b":[["77723.99000000","2.38351000"],["77721.12000000","0.00014000"],["77721.10000000","0.00014000"],["77720.44000000","0.00014000"],["77720.25000000","0.02147000"],["77719.36000000","0.10961000"],["77719.32000000","0.00257000"],["77718.18000000","0.00000000"],["77717.45000000","0.00400000"],["77717.36000000","0.00000000"],["77717.26000000","0.00000000"],["77717.09000000","0.00000000"],["77714.84000000","0.11191000"],["77710.49000000","0.00200000"],["77706.58000000","0.00000000"],["77705.45000000","0.00000000"],["77681.04000000","0.00000000"],["77677.11000000","0.00007000"],["77524.01000000","0.00811000"],["77523.69000000","0.02016000"],["77522.01000000","0.00000000"],["76558.13000000","0.00030000"],["69951.60000000","0.00448000"]],"a":[["77724.00000000","2.08491000"],["77726.99000000","0.00014000"],["77728.25000000","0.00400000"],["77728.31000000","0.00643000"],["77728.84000000","0.03200000"],["77733.57000000","0.00000000"],["77734.32000000","0.00000000"],["77734.85000000","0.00257000"],["77735.12000000","0.00128000"],["77750.69000000","0.00000000"],["77754.34000000","0.00000000"],["78889.86000000","0.00030000"]]}}
{"type":"trade","received_at_ms":1788333168603,"data":{"e":"trade","E":1788333168769,"s":"BTCUSDT","t":6646665715,"p":"77723.99000000","q":"0.00260000","T":1788333168769,"m":true,"M":true}}
{"type":"depth","received_at_ms":1788333168647,"data":{"e":"depthUpdate","E":1788333168814,"s":"BTCUSDT","U":99556322906,"u":99556322944,"b":[["77723.99000000","2.38280000"],["77721.25000000","0.10619000"],["77721.12000000","0.00000000"],["77721.11000000","0.00000000"],["77721.10000000","0.00000000"],["77720.44000000","0.00014000"],["77720.25000000","0.02161000"],["77719.36000000","0.10975000"],["77719.32000000","0.00000000"],["77719.18000000","0.00257000"],["77714.81000000","0.00000000"],["77523.69000000","0.00000000"],["69951.60000000","0.00464000"],["69951.59000000","0.00009000"]],"a":[["77724.00000000","2.08303000"],["77726.76000000","0.01281000"],["77726.99000000","0.00000000"],["77727.98000000","0.02814000"],["77733.15000000","0.00189000"],["77734.71000000","0.00257000"],["77734.85000000","0.00000000"]]}}
{"type":"depth","received_at_ms":1788333168748,"data":{"e":"depthUpdate","E":1788333168914,"s":"BTCUSDT","U":99556322945,"u":99556322967,"b":[["77723.99000000","2.10977000"],["77723.98000000","0.00076000"],["77721.26000000","0.00000000"],["77721.25000000","0.00014000"],["77720.88000000","0.00007000"],["77719.88000000","0.11191000"],["77717.45000000","0.00000000"],["77716.65000000","0.00400000"],["77671.08000000","0.00411000"],["77503.75000000","0.02016000"],["69951.60000000","0.00448000"]],"a":[["77724.00000000","2.08490000"],["77733.15000000","0.00000000"],["77734.08000000","0.04595000"],["77748.56000000","0.00000000"]]}}
{"type":"trade","received_at_ms":1788333168834,"data":{"e":"trade","E":1788333168995,"s":"BTCUSDT","t":6646665716,"p":"77724.00000000","q":"0.07741000","T":1788333168994,"m":false,"M":true}}
{"type":"depth","received_at_ms":1788333168848,"data":{"e":"depthUpdate","E":1788333169014,"s":"BTCUSDT","U":99556322968,"u":99556322989,"b":[["77723.99000000","2.10984000"],["77721.32000000","0.01328000"],["77721.25000000","0.00000000"],["77720.25000000","0.02168000"],["77719.88000000","0.11205000"],["69951.60000000","0.00464000"],["62179.20000000","0.00032000"],["62179.19000000","0.00000000"],["62179.00000000","0.00000000"]],"a":[["77724.00000000","2.00749000"]]}}
{"type":"depth","received_at_ms":1788333168948,"data":{"e":"depthUpdate","E":1788333169114,"s":"BTCUSDT","U":99556322990,"u":99556323000,"b":[["77723.99000000","2.10795000"],["77721.40000000","0.00000000"],["77721.35000000","0.00000000"],["77714.83000000","0.67016000"],["77699.00000000","0.70000000"],["77434.50000000","2.50000000"],["69951.60000000","0.00464000"]],"a":[["77817.14000000","0.00411000"]]}}
{"type":"trade","received_at_ms":1788333168971,"data":{"e":"trade","E":1788333169138,"s":"BTCUSDT","t":6646665717,"p":"77723.99000000","q":"0.01500000","T":1788333169137,"m":true,"M":true}}
{"type":"depth","received_at_ms":1788333169047,"data":{"e":"depthUpdate","E":1788333169214,"s":"BTCUSDT","U":99556323001,"u":99556323032,"b":[["77723.99000000","2.09295000"],["77722.74000000","0.01800000"],["77721.96000000","0.00014000"],["77721.95000000","0.05000000"],["77721.86000000","0.00014000"],["77721.85000000","0.05000000"],["77721.81000000","0.00000000"],["77721.80000000","0.00000000"],["77721.33000000","0.00000000"],["77720.88000000","0.00000000"],["77705.37000000","0.00000000"],["77524.01000000","0.00000000"],["77522.01000000","0.00811000"],["69951.60000000","0.00464000"],["69951.59000000","0.00000000"],["69951.58000000","0.00009000"],["62179.20000000","0.00000000"]],"a":[["77736.47000000","0.00000000"],["77750.97000000","0.02008000"],["77754.62000000","0.05386000"]]}}
{"type":"depth","received_at_ms":1788333169147,"data":{"e":"depthUpdate","E":1788333169314,"s":"BTCUSDT","U":99556323033,"u":99556323076,"b":[["77723.99000000","2.09317000"],["77723.98000000","0.00090000"],["77722.74000000","0.01807000"],["77722.01000000","0.00014000"],["77722.00000000","0.05007000"],["77721.96000000","0.00000000"],["77721.95000000","0.00014000"],["77721.86000000","0.00000000"],["77721.85000000","0.00014000"],["77721.76000000","0.00014000"],["77721.75000000","0.05000000"],["77720.88000000","0.00000000"],["77719.88000000","0.11191000"],["77719.36000000","0.10961000"],["77705.37000000","0.00007000"],["77640.44000000","1.61347000"],["77640.00000000","0.03411000"],["77635.26000000","0.00000000"],["69951.60000000","0.00448000"]],"a":[["77736.47000000","0.00007000"],["77813.95000000","0.00000000"]]}}
{"type":"depth","received_at_ms":1788333169249,"data":{"e":"depthUpdate","E":1788333169415,"s":"BTCUSDT","U":99556323077,"u":99556323099,"b":[["77723.99000000","2.09310000"],["77723.98000000","0.00083000"],["77722.74000000","0.01793000"],["77722.01000000","0.00000000"],["77722.00000000","0.00021000"],["77721.95000000","0.00000000"],["77721.85000000","0.00000000"],["77721.75000000","0.05014000"],["77720.88000000","0.00007000"],["69951.60000000","0.00464000"]],"a":[]}}
{"type":"depth","received_at_ms":1788333169348,"data":{"e":"depthUpdate","E":1788333169514,"s":"BTCUSDT","U":99556323100,"u":99556323119,"b":[["77722.74000000","0.01793000"],["77722.00000000","0.00007000"],["77721.75000000","0.00014000"],["77719.88000000","0.11205000"],["77524.01000000","0.00811000"],["77522.01000000","0.00000000"],["69951.60000000","0.00480000"],["62179.20000000","0.00032000"],["62179.00000000","0.00200000"]],"a":[["77747.16000000","0.00411000"],["77833.66000000","0.00000000"],["77848.26000000","0.00108000"]]}}
{"type":"depth","received_at_ms":1788333169448,"data":{"e":"depthUpdate","E":1788333169614,"s":"BTCUSDT","U":99556323120,"u":99556323144,"b":[["77723.99000000","1.92433000"],["77723.98000000","0.00076000"],["77722.74000000","0.01786000"],["77722.00000000","0.00000000"],["77721.76000000","0.00000000"],["77721.75000000","0.00000000"],["77721.33000000","0.00014000"],["77719.36000000","0.10975000"],["77355.08000000","2.50000000"],["75557.14000000","0.00000000"],["69951.60000000","0.00464000"],["62179.20000000","0.00000000"],["62179.19000000","0.00000000"]],"a":[["81001.14000000","0.00000000"]]}}
{"type":"depth","received_at_ms":1788333169547,"data":{"e":"depthUpdate","E":1788333169714,"s":"BTCUSDT","U":99556323145,"u":99556323157,"b":[["77709.94000000","0.00411000"],["77671.08000000","0.00000000"],["77640.00000000","0.03000000"],["76558.13000000","0.00030000"],["69951.60000000","0.00480000"],["69951.00000000","0.00068000"]],"a":[["77747.16000000","0.00000000"],["77786.01000000","0.00000000"],["77817.14000000","0.00000000"],["78889.86000000","0.00030000"]]}}
{"type":"depth","received_at_ms":1788333169647,"data":{"e":"depthUpdate","E":1788333169814,"s":"BTCUSDT","U":99556323158,"u":99556323159,"b":[["69951.60000000","0.00448000"]],"a":[]}}
{"type":"depth","received_at_ms":1788333169747,"data":{"e":"depthUpdate","E":1788333169914,"s":"BTCUSDT","U":99556323160,"u":99556323163,"b":[["77723.99000000","1.92759000"],["69951.60000000","0.00464000"]],"a":[]}}
{"type":"depth","received_at_ms":1788333169848,"data":{"e":"depthUpdate","E":1788333170014,"s":"BTCUSDT","U":99556323164,"u":99556323169,"b":[["69951.60000000","0.00448000"],["69951.00000000","0.00068000"],["62179.20000000","0.00032000"],["62179.19000000","0.00000000"]],"a":[]}}
{"type":"depth","received_at_ms":1788333169947,"data":{"e":"depthUpdate","E":1788333170114,"s":"BTCUSDT","U":99556323170,"u":99556323189,"b":[["77723.99000000","2.09621000"],["77722.74000000","0.01793000"],["77721.76000000","0.00014000"],["77721.75000000","0.05007000"],["77721.71000000","0.00014000"],["77721.70000000","0.05000000"],["77721.33000000","0.00000000"],["77720.88000000","0.00000000"],["77275.66000000","2.50000000"],["69951.60000000","0.00464000"],["69951.00000000","0.00068000"]],"a":[["77786.10000000","0.00411000"]]}}
{"type":"depth","received_at_ms":1788333170048,"data":{"e":"depthUpdate","E":1788333170215,"s":"BTCUSDT","U":99556323190,"u":99556323225,"b":[["77723.99000000","2.09643000"],["77723.98000000","0.00090000"],["77722.74000000","0.01800000"],["77721.96000000","0.00014000"],["77721.95000000","0.05007000"],["77721.91000000","0.00014000"],["77721.90000000","0.05000000"],["77721.76000000","0.00000000"],["77721.75000000","0.00021000"],["77721.71000000","0.00000000"],["77721.70000000","0.00014000"],["77719.88000000","0.11191000"],["77719.36000000","0.10961000"],["77343.27000000","0.00000000"],["69951.60000000","0.00448000"],["62179.20000000","0.00000000"]],"a":[]}}
{"type":"trade","received_at_ms":1788333170078,"data":{"e":"trade","E":1788333170241,"s":"BTCUSDT","t":6646665718,"p":"77723.99000000","q":"0.05784000","T":1788333170240,"m":true,"M":true}}
{"type":"trade","received_at_ms":1788333170078,"data":{"e":"trade","E":1788333170241,"s":"BTCUSDT","t":6646665719,"p":"77723.99000000","q":"0.00007000","T":1788333170240,"m":true,"M":true}}
{"type":"trade","received_at_ms":1788333170078,"data":{"e":"trade","E":1788333170241,"s":"BTCUSDT","t":6646665720,"p":"77723.99000000","q":"0.00048000","T":1788333170240,"m":true,"M":true}}
{"type":"trade","received_at_ms":1788333170078,"data":{"e":"trade","E":1788333170241,"s":"BTCUSDT","t":6646665721,"p":"77723.99000000","q":"0.00200000","T":1788333170240,"m":true,"M":true}}
{"type":"trade","received_at_ms":1788333170078,"data":{"e":"trade","E":1788333170241,"s":"BTCUSDT","t":6646665722,"p":"77723.99000000","q":"0.00200000","T":1788333170240,"m":true,"M":true}}
{"type":"trade","received_at_ms":1788333170078,"data":{"e":"trade","E":1788333170241,"s":"BTCUSDT","t":6646665723,"p":"77723.99000000","q":"0.00200000","T":1788333170240,"m":true,"M":true}}
{"type":"trade","received_at_ms":1788333170078,"data":{"e":"trade","E":1788333170241,"s":"BTCUSDT","t":6646665724,"p":"77723.99000000","q":"0.01000000","T":1788333170240,"m":true,"M":true}}
{"type":"trade","received_at_ms":1788333170078,"data":{"e":"trade","E":1788333170241,"s":"BTCUSDT","t":6646665725,"p":"77723.99000000","q":"0.00007000","T":1788333170240,"m":true,"M":true}}
{"type":"trade","received_at_ms":1788333170078,"data":{"e":"trade","E":1788333170241,"s":"BTCUSDT","t":6646665726,"p":"77723.99000000","q":"0.00007000","T":1788333170240,"m":true,"M":true}}
{"type":"trade","received_at_ms":1788333170079,"data":{"e":"trade","E":1788333170241,"s":"BTCUSDT","t":6646665727,"p":"77723.99000000","q":"0.00007000","T":1788333170240,"m":true,"M":true}}
{"type":"trade","received_at_ms":1788333170079,"data":{"e":"trade","E":1788333170241,"s":"BTCUSDT","t":6646665728,"p":"77723.99000000","q":"0.00007000","T":1788333170240,"m":true,"M":true}}
{"type":"trade","received_at_ms":1788333170079,"data":{"e":"trade","E":1788333170241,"s":"BTCUSDT","t":6646665729,"p":"77723.99000000","q":"0.00007000","T":1788333170240,"m":true,"M":true}}
{"type":"trade","received_at_ms":1788333170079,"data":{"e":"trade","E":1788333170241,"s":"BTCUSDT","t":6646665730,"p":"77723.99000000","q":"0.01063000","T":1788333170240,"m":true,"M":true}}
{"type":"trade","received_at_ms":1788333170079,"data":{"e":"trade","E":1788333170241,"s":"BTCUSDT","t":6646665731,"p":"77723.99000000","q":"0.02000000","T":1788333170240,"m":true,"M":true}}
{"type":"trade","received_at_ms":1788333170079,"data":{"e":"trade","E":1788333170241,"s":"BTCUSDT","t":6646665732,"p":"77723.99000000","q":"0.00007000","T":1788333170240,"m":true,"M":true}}
{"type":"trade","received_at_ms":1788333170079,"data":{"e":"trade","E":1788333170241,"s":"BTCUSDT","t":6646665733,"p":"77723.99000000","q":"0.00026000","T":1788333170240,"m":true,"M":true}}
{"type":"trade","received_at_ms":1788333170079,"data":{"e":"trade","E":1788333170241,"s":"BTCUSDT","t":6646665734,"p":"77723.99000000","q":"0.00007000","T":1788333170240,"m":true,"M":true}}
{"type":"trade","received_at_ms":1788333170079,"data":{"e":"trade","E":1788333170241,"s":"BTCUSDT","t":6646665735,"p":"77723.99000000","q":"0.00007000","T":1788333170240,"m":true,"M":true}}
{"type":"trade","received_at_ms":1788333170079,"data":{"e":"trade","E":1788333170241,"s":"BTCUSDT","t":6646665736,"p":"77723.99000000","q":"0.02000000","T":1788333170240,"m":true,"M":true}}
{"type":"trade","received_at_ms":1788333170079,"data":{"e":"trade","E":1788333170241,"s":"BTCUSDT","t":6646665737,"p":"77723.99000000","q":"0.00069000","T":1788333170240,"m":true,"M":true}}
{"type":"trade","received_at_ms":1788333170079,"data":{"e":"trade","E":1788333170241,"s":"BTCUSDT","t":6646665738,"p":"77723.99000000","q":"0.00600000","T":1788333170240,"m":true,"M":true}}
{"type":"trade","received_at_ms":1788333170079,"data":{"e":"trade","E":1788333170241,"s":"BTCUSDT","t":6646665739,"p":"77723.99000000","q":"0.00326000","T":1788333170240,"m":true,"M":true}}
{"type":"trade","received_at_ms":1788333170079,"data":{"e":"trade","E":1788333170241,"s":"BTCUSDT","t":6646665740,"p":"77723.99000000","q":"0.00200000","T":1788333170240,"m":true,"M":true}}
{"type":"trade","received_at_ms":1788333170079,"data":{"e":"trade","E":1788333170241,"s":"BTCUSDT","t":6646665741,"p":"77723.99000000","q":"0.02000000","T":1788333170240,"m":true,"M":true}}
{"type":"trade","received_at_ms":1788333170079,"data":{"e":"trade","E":1788333170241,"s":"BTCUSDT","t":6646665742,"p":"77723.99000000","q":"0.00007000","T":1788333170240,"m":true,"M":true}}
{"type":"trade","received_at_ms":1788333170079,"data":{"e":"trade","E":1788333170241,"s":"BTCUSDT","t":6646665743,"p":"77723.99000000","q":"0.00007000","T":1788333170240,"m":true,"M":true}}
{"type":"trade","received_at_ms":1788333170079,"data":{"e":"trade","E":1788333170241,"s":"BTCUSDT","t":6646665744,"p":"77723.99000000","q":"0.05634000","T":1788333170240,"m":true,"M":true}}
{"type":"trade","received_at_ms":1788333170079,"data":{"e":"trade","E":1788333170241,"s":"BTCUSDT","t":6646665745,"p":"77723.99000000","q":"0.00007000","T":1788333170240,"m":true,"M":true}}
{"type":"trade","received_at_ms":1788333170079,"data":{"e":"trade","E":1788333170241,"s":"BTCUSDT","t":6646665746,"p":"77723.99000000","q":"0.00007000","T":1788333170240,"m":true,"M":true}}
{"type":"trade","received_at_ms":1788333170079,"data":{"e":"trade","E":1788333170241,"s":"BTCUSDT","t":6646665747,"p":"77723.99000000","q":"0.00007000","T":1788333170240,"m":true,"M":true}}
{"type":"trade","received_at_ms":1788333170079,"data":{"e":"trade","E":1788333170241,"s":"BTCUSDT","t":6646665748,"p":"77723.99000000","q":"0.00008000","T":1788333170240,"m":true,"M":true}}
{"type":"trade","received_at_ms":1788333170079,"data":{"e":"trade","E":1788333170241,"s":"BTCUSDT","t":6646665749,"p":"77723.99000000","q":"0.00063000","T":1788333170240,"m":true,"M":true}}
{"type":"trade","received_at_ms":1788333170079,"data":{"e":"trade","E":1788333170241,"s":"BTCUSDT","t":6646665750,"p":"77723.99000000","q":"0.00065000","T":1788333170240,"m":true,"M":true}}
{"type":"trade","received_at_ms":1788333170079,"data":{"e":"trade","E":1788333170241,"s":"BTCUSDT","t":6646665751,"p":"77723.99000000","q":"0.00013000","T":1788333170240,"m":true,"M":true}}
{"type":"trade","received_at_ms":1788333170079,"data":{"e":"trade","E":1788333170241,"s":"BTCUSDT","t":6646665752,"p":"77723.99000000","q":"0.00007000","T":1788333170240,"m":true,"M":true}}
{"type":"trade","received_at_ms":1788333170079,"data":{"e":"trade","E":1788333170241,"s":"BTCUSDT","t":6646665753,"p":"77723.99000000","q":"0.00007000","T":1788333170240,"m":true,"M":true}}
{"type":"trade","received_at_ms":1788333170079,"data":{"e":"trade","E":1788333170241,"s":"BTCUSDT","t":6646665754,"p":"77723.99000000","q":"0.03875000","T":1788333170240,"m":true,"M":true}}
{"type":"trade","received_at_ms":1788333170079,"data":{"e":"trade","E":1788333170241,"s":"BTCUSDT","t":6646665755,"p":"77723.99000000","q":"0.01000000","T":1788333170240,"m":true,"M":true}}
{"type":"trade","received_at_ms":1788333170079,"data":{"e":"trade","E":1788333170241,"s":"BTCUSDT","t":6646665756,"p":"77723.99000000","q":"0.02000000","T":1788333170240,"m":true,"M":true}}
{"type":"trade","received_at_ms":1788333170079,"data":{"e":"trade","E":1788333170241,"s":"BTCUSDT","t":6646665757,"p":"77723.99000000","q":"0.02000000","T":1788333170240,"m":true,"M":true}}
{"type":"trade","received_at_ms":1788333170079,"data":{"e":"trade","E":1788333170241,"s":"BTCUSDT","t":6646665758,"p":"77723.99000000","q":"0.02000000","T":1788333170240,"m":true,"M":true}}
{"type":"trade","received_at_ms":1788333170080,"data":{"e":"trade","E":1788333170245,"s":"BTCUSDT","t":6646665759,"p":"77723.99000000","q":"0.08305000","T":1788333170245,"m":true,"M":true}}
{"type":"trade","received_at_ms":1788333170080,"data":{"e":"trade","E":1788333170245,"s":"BTCUSDT","t":6646665760,"p":"77723.99000000","q":"0.01320000","T":1788333170245,"m":true,"M":true}}
{"type":"trade","received_at_ms":1788333170080,"data":{"e":"trade","E":1788333170245,"s":"BTCUSDT","t":6646665761,"p":"77723.99000000","q":"0.00200000","T":1788333170245,"m":true,"M":true}}
{"type":"trade","received_at_ms":1788333170080,"data":{"e":"trade","E":1788333170245,"s":"BTCUSDT","t":6646665762,"p":"77723.99000000","q":"0.00007000","T":1788333170245,"m":true,"M":true}}
{"type":"trade","received_at_ms":1788333170080,"data":{"e":"trade","E":1788333170245,"s":"BTCUSDT","t":6646665763,"p":"77723.99000000","q":"0.00007000","T":1788333170245,"m":true,"M":true}}
{"type":"trade","received_at_ms":1788333170080,"data":{"e":"trade","E":1788333170245,"s":"BTCUSDT","t":6646665764,"p":"77723.99000000","q":"0.00007000","T":1788333170245,"m":true,"M":true}}
{"type":"trade","received_at_ms":1788333170080,"data":{"e":"trade","E":1788333170245,"s":"BTCUSDT","t":6646665765,"p":"77723.99000000","q":"0.00007000","T":1788333170245,"m":true,"M":true}}
{"type":"trade","received_at_ms":1788333170080,"data":{"e":"trade","E":1788333170245,"s":"BTCUSDT","t":6646665766,"p":"77723.99000000","q":"0.00007000","T":1788333170245,"m":true,"M":true}}
{"type":"trade","received_at_ms":1788333170080,"data":{"e":"trade","E":1788333170245,"s":"BTCUSDT","t":6646665767,"p":"77723.99000000","q":"0.00150000","T":1788333170245,"m":true,"M":true}}
{"type":"trade","received_at_ms":1788333170080,"data":{"e":"trade","E":1788333170245,"s":"BTCUSDT","t":6646665768,"p":"77723.99000000","q":"0.02854000","T":1788333170245,"m":true,"M":true}}
{"type":"depth","received_at_ms":1788333170148,"data":{"e":"depthUpdate","E":1788333170314,"s":"BTCUSDT","U":99556323226,"u":99556323344,"b":[["77723.99000000","0.61494000"],["77723.98000000","0.00083000"],["77723.24000000","0.00000000"],["77723.22000000","0.00000000"],["77723.21000000","0.00014000"],["77722.74000000","0.01793000"],["77721.96000000","0.00000000"],["77721.95000000","0.00021000"],["77721.90000000","0.05021000"],["77721.86000000","0.00014000"],["77721.85000000","0.05000000"],["77721.75000000","0.00000000"],["77721.70000000","0.00000000"],["77720.88000000","0.00007000"],["77720.44000000","0.00007000"],["77719.18000000","0.00000000"],["77717.00000000","0.00000000"],["77716.65000000","0.00000000"],["77716.50000000","0.00007000"],["77716.24000000","0.00000000"],["77716.00000000","0.00000000"],["77715.77000000","0.10778000"],["77715.25000000","0.00400000"],["77714.83000000","0.66373000"],["77714.31000000","0.00000000"],["77712.56000000","0.00007000"],["77710.48000000","0.00000000"],["77708.62000000","0.00007000"],["77705.43000000","1.31471000"],["77705.42000000","0.00000000"],["77705.37000000","0.00007000"],["77704.68000000","0.00007000"],["77702.92000000","0.00000000"],["69951.60000000","0.00464000"],["69951.58000000","0.00000000"],["62179.00000000","0.00200000"]],"a":[["77724.00000000","4.40344000"],["77727.89000000","0.00400000"],["77728.99000000","0.00600000"],["77736.47000000","0.00007000"]]}}
{"type":"depth","received_at_ms":1788333170249,"data":{"e":"depthUpdate","E":1788333170414,"s":"BTCUSDT","U":99556323345,"u":99556323500,"b":[["77723.99000000","0.41141000"],["77723.98000000","0.00076000"],["77723.21000000","0.00000000"],["77722.74000000","0.01793000"],["77721.95000000","0.00007000"],["77721.90000000","0.05021000"],["77721.85000000","0.05014000"],["77721.32000000","0.01335000"],["77721.26000000","0.00007000"],["77721.25000000","0.11191000"],["77720.25000000","0.02161000"],["77719.35000000","0.00000000"],["77719.34000000","0.35400000"],["77718.73000000","0.00000000"],["77718.00000000","0.11191000"],["77717.54000000","0.00000000"],["77717.27000000","0.00257000"],["77716.50000000","0.00014000"],["77715.31000000","0.00250000"],["77715.25000000","0.00000000"],["77715.08000000","0.00000000"],["77714.85000000","0.00000000"],["77714.83000000","0.23516000"],["77714.82000000","0.00000000"],["77714.76000000","1.31471000"],["77714.62000000","0.00048000"],["77714.53000000","0.00047000"],["77713.36000000","0.00257000"],["77712.62000000","0.00000000"],["77712.56000000","0.00014000"],["77712.54000000","0.00400000"],["77712.38000000","0.00000000"],["77712.30000000","0.58328000"],["77712.16000000","0.00400000"],["77712.11000000","0.00000000"],["77712.02000000","0.00643000"],["77712.01000000","0.00000000"],["77711.80000000","0.00000000"],["77710.82000000","0.00000000"],["77710.49000000","0.00000000"],["77709.59000000","0.00643000"],["77708.62000000","0.00014000"],["77706.37000000","0.00800000"],["77706.35000000","0.00400000"],["77705.45000000","0.37938000"],["77704.68000000","0.00014000"],["77704.32000000","0.22820000"],["77700.74000000","0.00021000"],["77681.04000000","0.00007000"],["77677.11000000","0.00000000"],["77640.44000000","0.00000000"],["77627.11000000","1.33197000"],["77593.63000000","0.00000000"],["69951.60000000","0.00448000"]],"a":[["77724.00000000","4.42531000"],["77724.01000000","0.00027000"],["77724.37000000","0.00000000"],["77726.15000000","0.12249000"],["77727.29000000","0.00000000"],["77727.88000000","0.00000000"],["77727.89000000","0.00000000"],["77728.25000000","0.00000000"],["77728.31000000","0.00000000"],["77728.47000000","0.00200000"],["77728.72000000","0.01200000"],["77730.44000000","0.00000000"],["77732.02000000","0.00257000"],["77734.71000000","0.00000000"]]}}
{"type":"depth","received_at_ms":1788333170347,"data":{"e":"depthUpdate","E":1788333170514,"s":"BTCUSDT","U":99556323501,"u":99556323533,"b":[["77723.99000000","0.48399000"],["77723.98000000","0.00090000"],["77722.74000000","0.01800000"],["77721.91000000","0.00000000"],["77721.90000000","0.00021000"],["77721.86000000","0.00000000"],["77721.85000000","0.00014000"],["77721.81000000","0.00014000"],["77721.80000000","0.05007000"],["77721.76000000","0.00014000"],["77721.75000000","0.05000000"],["77721.32000000","0.01335000"],["77714.83000000","0.59928000"],["75557.14000000","0.00010000"],["69951.60000000","0.00480000"],["69951.00000000","0.00078000"],["62179.20000000","0.00032000"]],"a":[["77724.00000000","4.41888000"],["77725.98000000","0.00643000"],["77762.51000000","0.00000000"],["77817.20000000","0.00411000"]]}}
{"type":"trade","received_at_ms":1788333170391,"data":{"e":"trade","E":1788333170551,"s":"BTCUSDT","t":6646665769,"p":"77724.00000000","q":"0.00050000","T":1788333170551,"m":false,"M":true}}
{"type":"depth","received_at_ms":1788333170446,"data":{"e":"depthUpdate","E":1788333170614,"s":"BTCUSDT","U":99556323534,"u":99556323610,"b":[["77723.99000000","0.48364000"],["77723.98000000","0.00076000"],["77722.74000000","0.01800000"],["77722.63000000","0.00014000"],["77722.62000000","0.11191000"],["77721.95000000","0.00000000"],["77721.90000000","0.00000000"],["77721.85000000","0.00000000"],["77721.81000000","0.00000000"],["77721.80000000","0.00021000"],["77721.76000000","0.00000000"],["77721.75000000","0.00014000"],["77721.33000000","0.00000000"],["77721.26000000","0.00014000"],["77721.25000000","0.11205000"],["77717.27000000","0.00000000"],["77717.26000000","0.00257000"],["77706.64000000","0.00200000"],["77705.45000000","0.37738000"],["77524.01000000","0.00000000"],["77520.01000000","0.00811000"],["69951.60000000","0.00457000"],["69951.00000000","0.00068000"],["62179.20000000","0.00000000"],["62179.19000000","0.00000000"],["62179.00000000","0.00200000"]],"a":[["77724.00000000","4.41438000"],["77724.70000000","0.00400000"],["77724.74000000","0.08219000"],["77725.98000000","0.00657000"],["77727.98000000","0.02800000"]]}}
{"type":"depth","received_at_ms":1788333170547,"data":{"e":"depthUpdate","E":1788333170714,"s":"BTCUSDT","U":99556323611,"u":99556323682,"b":[["77723.99000000","0.69530000"],["77722.74000000","0.01793000"],["77722.62000000","0.11205000"],["77721.80000000","0.00000000"],["77721.75000000","0.00000000"],["77719.88000000","0.11205000"],["77717.26000000","0.00000000"],["77717.25000000","0.00657000"],["77714.20000000","0.00000000"],["77713.95000000","0.00000000"],["77713.94000000","0.00400000"],["77712.54000000","0.00000000"],["77712.30000000","1.08873000"],["77712.16000000","0.00000000"],["77710.47000000","1.93226000"],["77708.42000000","0.01200000"],["77706.37000000","0.00000000"],["77554.83000000","0.00000000"],["76558.13000000","0.00030000"],["69951.60000000","0.00473000"],["69951.00000000","0.00088000"]],"a":[["77724.00000000","4.41136000"],["77724.01000000","0.00076000"],["77724.69000000","0.00400000"],["77724.70000000","0.00000000"],["78889.86000000","0.00030000"],["81001.14000000","0.00010000"]]}}
{"type":"depth","received_at_ms":1788333170647,"data":{"e":"depthUpdate","E":1788333170814,"s":"BTCUSDT","U":99556323683,"u":99556323708,"b":[["77723.99000000","1.41454000"],["77714.85000000","0.01400000"],["77714.62000000","0.00000000"],["77708.42000000","0.00000000"],["77706.64000000","0.00000000"],["77635.26000000","1.61347000"],["69951.60000000","0.00457000"],["69951.00000000","0.00068000"]],"a":[["77724.69000000","0.00000000"],["77725.86000000","0.00400000"],["77725.98000000","0.00014000"],["77728.31000000","0.00643000"],["77732.02000000","0.00000000"],["77732.51000000","0.00257000"],["77760.88000000","0.00000000"],["77761.25000000","0.12872000"]]}}
{"type":"depth","received_at_ms":1788333170748,"data":{"e":"depthUpdate","E":1788333170914,"s":"BTCUSDT","U":99556323709,"u":99556323741,"b":[["77723.99000000","1.42556000"],["77719.36000000","0.10968000"],["77719.35000000","0.30389000"],["77714.85000000","0.00000000"],["77714.53000000","0.00000000"],["77710.48000000","0.01400000"],["77697.24000000","0.00000000"],["77685.05000000","0.00000000"],["77520.01000000","0.00000000"],["77518.01000000","0.00811000"],["75765.70000000","0.00026000"],["71506.08000000","0.00014000"],["69951.60000000","0.00441000"],["69951.00000000","0.00078000"]],"a":[["77724.74000000","0.08219000"],["77725.98000000","0.00000000"],["77727.98000000","0.02814000"],["77842.33000000","0.00000000"]]}}
{"type":"depth","received_at_ms":1788333170854,"data":{"e":"depthUpdate","E":1788333171014,"s":"BTCUSDT","U":99556323742,"u":99556323758,"b":[["77723.99000000","1.21598000"],["69951.60000000","0.00473000"],["69951.00000000","0.00068000"],["62179.20000000","0.00032000"],["62179.19000000","0.00020000"]],"a":[["77724.00000000","4.40493000"],["77724.01000000","0.00076000"],["77725.85000000","0.00643000"]]}}
{"type":"depth","received_at_ms":1788333170953,"data":{"e":"depthUpdate","E":1788333171114,"s":"BTCUSDT","U":99556323759,"u":99556323788,"b":[["77723.99000000","1.21612000"],["77723.98000000","0.00090000"],["77722.62000000","0.11212000"],["77721.86000000","0.00014000"],["77721.85000000","0.05007000"],["77721.81000000","0.00014000"],["77721.80000000","0.05000000"],["77721.26000000","0.00000000"],["77720.88000000","0.00000000"],["77572.45000000","0.00000000"],["69951.60000000","0.00457000"],["62179.19000000","0.00000000"]],"a":[["77724.00000000","4.40500000"],["77724.01000000","0.00083000"],["77724.74000000","0.08219000"],["77725.85000000","0.00657000"],["77727.98000000","0.02800000"]]}}
{"type":"depth","received_at_ms":1788333171047,"data":{"e":"depthUpdate","E":1788333171214,"s":"BTCUSDT","U":99556323789,"u":99556323828,"b":[["77723.99000000","1.21612000"],["77723.98000000","0.00090000"],["77722.62000000","0.11219000"],["77721.86000000","0.00000000"],["77721.85000000","0.00021000"],["77721.81000000","0.00000000"],["77721.80000000","0.00014000"],["77721.76000000","0.00014000"],["77721.75000000","0.05007000"],["77721.71000000","0.00014000"],["77721.70000000","0.05000000"],["77721.26000000","0.00000000"],["77720.25000000","0.02147000"],["77719.88000000","0.11191000"],["69951.60000000","0.00457000"],["62179.20000000","0.00000000"]],"a":[["77881.25000000","0.00000000"]]}}
{"type":"depth","received_at_ms":1788333171148,"data":{"e":"depthUpdate","E":1788333171314,"s":"BTCUSDT","U":99556323829,"u":99556323865,"b":[["77723.99000000","1.21605000"],["77723.98000000","0.00083000"],["77722.62000000","0.11219000"],["77721.96000000","0.00014000"],["77721.95000000","0.05000000"],["77721.85000000","0.00000000"],["77721.80000000","0.00000000"],["77721.76000000","0.00000000"],["77721.75000000","0.00021000"],["77721.71000000","0.00000000"],["77721.70000000","0.00014000"],["77721.26000000","0.00007000"],["77705.37000000","0.00007000"],["77693.08000000","0.51995000"],["77668.29000000","1.03890000"],["69951.60000000","0.00441000"]],"a":[["77736.47000000","0.00007000"]]}}
{"type":"depth","received_at_ms":1788333171248,"data":{"e":"depthUpdate","E":1788333171414,"s":"BTCUSDT","U":99556323866,"u":99556323892,"b":[["77723.99000000","1.21598000"],["77723.98000000","0.00076000"],["77722.62000000","0.11212000"],["77721.96000000","0.00000000"],["77721.95000000","0.00014000"],["77721.75000000","0.00000000"],["77721.70000000","0.00000000"],["77721.26000000","0.00014000"],["77720.88000000","0.00007000"],["77720.25000000","0.02161000"],["71506.08000000","0.00000000"],["69951.60000000","0.00457000"],["62179.00000000","0.00200000"]],"a":[]}}
{"type":"depth","received_at_ms":1788333171349,"data":{"e":"depthUpdate","E":1788333171514,"s":"BTCUSDT","U":99556323893,"u":99556323925,"b":[["77723.99000000","1.21690000"],["77723.98000000","0.00090000"],["77722.62000000","0.11212000"],["77721.95000000","0.00000000"],["77721.91000000","0.00014000"],["77721.90000000","0.05007000"],["77721.86000000","0.00014000"],["77721.85000000","0.05000000"],["77721.26000000","0.00000000"],["77720.88000000","0.00000000"],["77719.88000000","0.11205000"],["69951.60000000","0.00441000"],["62179.20000000","0.00032000"]],"a":[]}}
{"type":"depth","received_at_ms":1788333171448,"data":{"e":"depthUpdate","E":1788333171614,"s":"BTCUSDT","U":99556323926,"u":99556324001,"b":[["77723.99000000","1.58484000"],["77722.62000000","0.11212000"],["77721.91000000","0.00000000"],["77721.90000000","0.00021000"],["77721.86000000","0.00000000"],["77721.85000000","0.00014000"],["77721.26000000","0.00007000"],["77720.25000000","0.02147000"],["77719.88000000","0.11191000"],["77719.34000000","0.35393000"],["77718.00000000","0.00000000"],["77715.14000000","0.00400000"],["77713.94000000","0.00000000"],["77710.48000000","0.01200000"],["77705.46000000","0.00000000"],["69951.60000000","0.00457000"],["62179.20000000","0.00000000"],["62179.19000000","0.00000000"],["62179.00000000","0.00400000"]],"a":[["77724.00000000","4.40500000"],["77724.01000000","0.00083000"],["77725.33000000","0.00000000"],["77725.86000000","0.00000000"],["77725.90000000","0.00000000"],["77726.01000000","0.00400000"],["77728.71000000","0.01634000"],["77728.72000000","0.00000000"],["77728.73000000","0.37338000"],["77732.51000000","0.00000000"],["77732.52000000","0.00257000"],["77750.97000000","0.00000000"],["77754.62000000","0.00000000"],["77761.25000000","0.00000000"]]}}
{"type":"depth","received_at_ms":1788333171547,"data":{"e":"depthUpdate","E":1788333171714,"s":"BTCUSDT","U":99556324002,"u":99556324036,"b":[["77723.99000000","1.58470000"],["77723.98000000","0.00076000"],["77722.62000000","0.11205000"],["77721.90000000","0.00000000"],["77721.85000000","0.00000000"],["77721.26000000","0.00014000"],["77720.88000000","0.00007000"],["77720.25000000","0.02161000"],["77719.88000000","0.11205000"],["77715.14000000","0.00000000"],["77710.49000000","0.00200000"],["77710.48000000","0.00400000"],["77671.08000000","0.00411000"],["76558.13000000","0.00030000"],["69951.60000000","0.00441000"],["62179.00000000","0.00200000"]],"a":[["77732.52000000","0.00000000"],["77732.56000000","0.00257000"],["78889.86000000","0.00030000"]]}}
{"type":"trade","received_at_ms":1788333171551,"data":{"e":"trade","E":1788333171717,"s":"BTCUSDT","t":6646665770,"p":"77724.00000000","q":"0.01500000","T":1788333171717,"m":false,"M":true}}
{"type":"depth","received_at_ms":1788333171647,"data":{"e":"depthUpdate","E":1788333171814,"s":"BTCUSDT","U":99556324037,"u":99556324046,"b":[["77710.48000000","0.01200000"],["69951.60000000","0.00448000"],["69951.59000000","0.00009000"]],"a":[["77724.00000000","4.38900000"],["77732.56000000","0.00000000"],["77732.57000000","0.00257000"]]}}
{"type":"depth","received_at_ms":1788333171747,"data":{"e":"depthUpdate","E":1788333171914,"s":"BTCUSDT","U":99556324047,"u":99556324085,"b":[["77723.99000000","1.84307000"],["77721.15000000","0.00400000"],["77719.34000000","0.35400000"],["77718.00000000","0.11191000"],["77717.25000000","0.00400000"],["77716.51000000","0.01286000"],["77714.83000000","0.59739000"],["77712.02000000","0.00000000"],["77709.59000000","0.00000000"],["77689.95000000","0.00000000"],["77681.04000000","0.00000000"],["77677.11000000","0.00007000"],["69951.60000000","0.00432000"],["69951.00000000","0.00068000"]],"a":[["77724.00000000","2.18386000"],["77724.01000000","0.00076000"],["77725.85000000","0.00014000"],["77726.01000000","0.00000000"],["77727.00000000","0.00000000"],["77727.23000000","0.00643000"],["77728.31000000","0.00000000"],["77731.07000000","0.00643000"],["77732.57000000","0.00000000"],["77751.04000000","0.00000000"],["77754.69000000","0.00000000"],["77764.05000000","0.00400000"]]}}
{"type":"depth","received_at_ms":1788333171847,"data":{"e":"depthUpdate","E":1788333172014,"s":"BTCUSDT","U":99556324086,"u":99556324128,"b":[["77723.99000000","1.84498000"],["77718.81000000","0.00257000"],["77717.26000000","0.00257000"],["77714.85000000","0.00000000"],["77713.36000000","0.00000000"],["77710.49000000","0.01400000"],["77710.48000000","0.00000000"],["77642.87000000","0.00401000"],["77624.46000000","0.00000000"],["77522.01000000","0.00811000"],["77518.01000000","0.00000000"],["69951.60000000","0.00464000"],["62179.20000000","0.00032000"],["62179.00000000","0.00200000"]],"a":[["77724.74000000","0.08219000"],["77725.85000000","0.00000000"],["77726.76000000","0.01281000"],["77727.23000000","0.00657000"],["77734.35000000","0.00257000"],["77761.50000000","0.00000000"],["77761.65000000","0.00000000"],["77761.82000000","0.12989000"]]}}
{"type":"depth","received_at_ms":1788333171948,"data":{"e":"depthUpdate","E":1788333172114,"s":"BTCUSDT","U":99556324129,"u":99556324163,"b":[["77723.99000000","1.84718000"],["77723.98000000","0.00090000"],["77722.62000000","0.11212000"],["77721.81000000","0.00014000"],["77721.80000000","0.00007000"],["77721.76000000","0.00014000"],["77721.75000000","0.00000000"],["77721.26000000","0.00000000"],["77720.88000000","0.00000000"],["77715.77000000","0.00008000"],["69951.60000000","0.00448000"],["62179.19000000","0.00000000"]],"a":[["77724.00000000","2.18199000"],["77733.13000000","0.00189000"],["77747.22000000","0.00411000"],["77761.72000000","0.00000000"],["77761.82000000","0.00117000"],["77762.10000000","0.00400000"],["77762.15000000","0.12872000"],["77764.05000000","0.00000000"],["77816.54000000","2.15325000"]]}}
{"type":"depth","received_at_ms":1788333172047,"data":{"e":"depthUpdate","E":1788333172214,"s":"BTCUSDT","U":99556324164,"u":99556324198,"b":[["77723.99000000","1.84718000"],["77723.98000000","0.00090000"],["77722.62000000","0.11212000"],["77721.91000000","0.00014000"],["77721.90000000","0.00007000"],["77721.86000000","0.00014000"],["77721.85000000","0.00000000"],["77721.81000000","0.00000000"],["77721.80000000","0.00000000"],["77721.76000000","0.00000000"],["77721.26000000","0.00000000"],["77720.88000000","0.00000000"],["77413.10000000","0.00129000"],["69951.60000000","0.00448000"],["62179.20000000","0.00000000"]],"a":[["77762.15000000","0.00000000"]]}}
{"type":"depth","received_at_ms":1788333172147,"data":{"e":"depthUpdate","E":1788333172314,"s":"BTCUSDT","U":99556324199,"u":99556324235,"b":[["77723.99000000","1.84704000"],["77723.98000000","0.00076000"],["77722.62000000","0.11212000"],["77721.91000000","0.00000000"],["77721.90000000","0.00000000"],["77721.86000000","0.00000000"],["77721.81000000","0.00014000"],["77721.80000000","0.00000000"],["77721.26000000","0.00014000"],["77720.88000000","0.00000000"],["77709.94000000","0.00000000"],["77705.37000000","0.00000000"],["77671.08000000","0.00000000"],["77640.00000000","0.03411000"],["77576.46000000","0.01544000"],["77555.27000000","0.00000000"],["69951.60000000","0.00448000"],["62179.00000000","0.00200000"]],"a":[["77736.47000000","0.00000000"],["77747.22000000","0.00000000"],["77760.15000000","0.00400000"],["77762.10000000","0.00000000"],["77786.10000000","0.00000000"],["77817.20000000","0.00000000"],["77844.43000000","0.00000000"],["77919.87000000","0.00000000"]]}}
{"type":"depth","received_at_ms":1788333172260,"data":{"e":"depthUpdate","E":1788333172414,"s":"BTCUSDT","U":99556324236,"u":99556324385,"b":[["77723.99000000","2.16659000"],["77723.98000000","0.00083000"],["77722.74000000","0.01800000"],["77722.64000000","0.00014000"],["77722.63000000","0.09170000"],["77722.62000000","0.11205000"],["77721.81000000","0.00000000"],["77721.34000000","0.00257000"],["77720.88000000","0.00000000"],["77720.44000000","0.00014000"],["77719.88000000","0.11212000"],["77719.62000000","0.00248000"],["77719.61000000","0.00000000"],["77719.38000000","0.73291000"],["77719.37000000","1.31471000"],["77719.36000000","0.00000000"],["77719.35000000","0.00000000"],["77719.34000000","0.35393000"],["77718.81000000","0.00000000"],["77718.00000000","0.00000000"],["77715.31000000","0.00000000"],["77714.85000000","0.38538000"],["77714.84000000","0.00000000"],["77710.49000000","0.00200000"],["77705.37000000","0.00007000"],["77699.20000000","0.34765000"],["77697.85000000","0.34766000"],["77684.99000000","1.27498000"],["77681.68000000","0.00000000"],["77678.19000000","0.00000000"],["77646.05000000","0.41353000"],["77644.87000000","0.00000000"],["77625.65000000","0.00000000"],["77599.63000000","0.00070000"],["69951.60000000","0.00448000"]],"a":[["77724.00000000","1.85737000"],["77724.01000000","0.00076000"],["77724.43000000","0.00000000"],["77724.44000000","0.00014000"],["77724.52000000","0.00000000"],["77724.53000000","0.00014000"],["77724.73000000","0.00000000"],["77724.74000000","0.00014000"],["77726.14000000","0.00000000"],["77726.15000000","0.00014000"],["77726.17000000","0.00014000"],["77727.97000000","0.00014000"],["77727.99000000","0.00014000"],["77728.70000000","0.01200000"],["77728.71000000","0.00434000"],["77728.72000000","0.00000000"],["77728.73000000","0.00000000"],["77728.74000000","0.00000000"],["77728.75000000","0.00000000"],["77728.81000000","0.00000000"],["77728.83000000","0.00007000"],["77728.98000000","0.13686000"],["77731.35000000","0.10128000"],["77731.92000000","1.06581000"],["77731.93000000","1.93226000"],["77732.73000000","0.00000000"],["77734.35000000","0.00000000"],["77735.12000000","0.00000000"],["77735.14000000","0.00000000"],["77736.47000000","0.00007000"],["77736.87000000","0.00257000"],["77739.75000000","0.00000000"],["77740.75000000","0.00128000"],["77743.45000000","0.00000000"],["77745.58000000","0.00200000"],["77746.43000000","0.00000000"],["77749.99000000","0.51310000"],["77751.13000000","0.01969000"],["77752.00000000","0.03000000"],["77754.78000000","0.05524000"],["77755.80000000","0.00000000"],["77759.72000000","0.64331000"],["77772.00000000","0.37733000"],["77776.24000000","0.41324000"],["77789.88000000","1.27326000"],["77852.98000000","0.02016000"]]}}
{"type":"depth","received_at_ms":1788333172347,"data":{"e":"depthUpdate","E":1788333172514,"s":"BTCUSDT","U":99556324386,"u":99556324504,"b":[["77723.99000000","2.18804000"],["77723.98000000","0.00083000"],["77723.64000000","0.00000000"],["77722.74000000","0.01800000"],["77722.62000000","0.11212000"],["77722.45000000","0.00257000"],["77721.91000000","0.00014000"],["77721.90000000","0.00007000"],["77721.86000000","0.00007000"],["77721.85000000","0.00000000"],["77721.51000000","0.00007000"],["77721.34000000","0.00000000"],["77721.26000000","0.00000000"],["77720.25000000","0.02154000"],["77719.88000000","0.11198000"],["77714.86000000","0.01200000"],["77714.85000000","0.37338000"],["77710.48000000","0.00000000"],["77684.98000000","0.00000000"],["69951.60000000","0.00448000"],["62179.20000000","0.00032000"],["62179.00000000","0.00200000"]],"a":[["77724.00000000","1.85751000"],["77724.01000000","0.00076000"],["77724.38000000","0.00014000"],["77724.44000000","0.00000000"],["77724.53000000","0.00000000"],["77724.74000000","0.00000000"],["77726.00000000","0.03014000"],["77726.15000000","0.00000000"],["77727.86000000","0.00206000"],["77727.97000000","0.00014000"],["77727.98000000","0.02814000"],["77728.00000000","0.03021000"],["77728.47000000","0.00000000"],["77728.70000000","0.00014000"],["77728.71000000","0.00034000"],["77728.84000000","0.03214000"],["77728.98000000","0.00000000"],["77729.53000000","0.08205000"],["77729.99000000","0.16748000"],["77730.98000000","0.00200000"],["77731.77000000","0.01608000"],["77731.92000000","0.47462000"],["77731.93000000","0.00000000"],["77733.56000000","0.00048000"],["77733.68000000","0.00048000"],["77736.87000000","0.00000000"],["77737.98000000","0.00257000"],["77739.18000000","0.00000000"],["77763.78000000","0.00000000"]]}}
{"type":"depth","received_at_ms":1788333172447,"data":{"e":"depthUpdate","E":1788333172614,"s":"BTCUSDT","U":99556324505,"u":99556324565,"b":[["77723.99000000","2.18811000"],["77723.98000000","0.00090000"],["77722.62000000","0.11205000"],["77721.91000000","0.00000000"],["77721.90000000","0.00000000"],["77721.86000000","0.00000000"],["77721.51000000","0.00014000"],["77721.26000000","0.00007000"],["77719.88000000","0.11205000"],["77719.39000000","0.11191000"],["77710.49000000","0.00000000"],["77710.48000000","0.00200000"],["77696.25000000","0.64383000"],["77689.62000000","0.00000000"],["69951.60000000","0.00448000"],["62179.20000000","0.00000000"]],"a":[["77724.00000000","1.69195000"],["77724.01000000","0.00076000"],["77726.92000000","0.00014000"],["77726.93000000","0.12792000"],["77727.23000000","0.00014000"],["77728.00000000","0.03021000"],["77728.70000000","0.00000000"],["77728.83000000","0.00000000"],["77728.93000000","0.00643000"],["77728.94000000","0.02414000"],["77730.98000000","0.00000000"],["77731.77000000","0.00008000"],["77733.12000000","0.00200000"],["77734.18000000","0.01600000"],["77737.68000000","0.00000000"],["77741.37000000","0.33958000"],["77762.09000000","0.00000000"],["77762.57000000","0.12872000"]]}}
{"type":"depth","received_at_ms":1788333172547,"data":{"e":"depthUpdate","E":1788333172714,"s":"BTCUSDT","U":99556324566,"u":99556324621,"b":[["77722.45000000","0.00000000"],["77721.61000000","0.00257000"],["77709.94000000","0.00411000"],["77694.15000000","0.00200000"],["77684.98000000","0.00007000"],["77560.83000000","0.00070000"],["76558.13000000","0.00030000"],["69951.60000000","0.00448000"],["62179.19000000","0.00000000"],["62179.00000000","0.00200000"]],"a":[["77724.00000000","1.69202000"],["77724.01000000","0.00083000"],["77726.16000000","0.00014000"],["77726.17000000","0.15911000"],["77726.76000000","0.01281000"],["77726.93000000","0.12806000"],["77727.23000000","0.00000000"],["77727.97000000","0.00000000"],["77728.84000000","0.03214000"],["77728.93000000","0.00657000"],["77728.94000000","0.02400000"],["77729.53000000","0.00000000"],["77731.92000000","0.45723000"],["77737.14000000","0.00257000"],["77737.98000000","0.00000000"],["77762.42000000","0.00000000"],["77762.57000000","0.00000000"],["77762.73000000","0.00000000"],["77852.98000000","0.00000000"],["78889.86000000","0.00030000"]]}}
{"type":"trade","received_at_ms":1788333172582,"data":{"e":"trade","E":1788333172747,"s":"BTCUSDT","t":6646665771,"p":"77723.99000000","q":"0.00065000","T":1788333172747,"m":true,"M":true}}
{"type":"trade","received_at_ms":1788333172582,"data":{"e":"trade","E":1788333172747,"s":"BTCUSDT","t":6646665772,"p":"77723.99000000","q":"0.00326000","T":1788333172747,"m":true,"M":true}}
{"type":"trade","received_at_ms":1788333172582,"data":{"e":"trade","E":1788333172747,"s":"BTCUSDT","t":6646665773,"p":"77723.99000000","q":"0.00007000","T":1788333172747,"m":true,"M":true}}
{"type":"trade","received_at_ms":1788333172582,"data":{"e":"trade","E":1788333172747,"s":"BTCUSDT","t":6646665774,"p":"77723.99000000","q":"0.00326000","T":1788333172747,"m":true,"M":true}}
{"type":"trade","received_at_ms":1788333172582,"data":{"e":"trade","E":1788333172747,"s":"BTCUSDT","t":6646665775,"p":"77723.99000000","q":"0.00326000","T":1788333172747,"m":true,"M":true}}
{"type":"trade","received_at_ms":1788333172583,"data":{"e":"trade","E":1788333172747,"s":"BTCUSDT","t":6646665776,"p":"77723.99000000","q":"0.00007000","T":1788333172747,"m":true,"M":true}}
{"type":"trade","received_at_ms":1788333172583,"data":{"e":"trade","E":1788333172747,"s":"BTCUSDT","t":6646665777,"p":"77723.99000000","q":"0.00007000","T":1788333172747,"m":true,"M":true}}
{"type":"trade","received_at_ms":1788333172583,"data":{"e":"trade","E":1788333172747,"s":"BTCUSDT","t":6646665778,"p":"77723.99000000","q":"0.00008000","T":1788333172747,"m":true,"M":true}}
{"type":"trade","received_at_ms":1788333172583,"data":{"e":"trade","E":1788333172747,"s":"BTCUSDT","t":6646665779,"p":"77723.99000000","q":"0.00064000","T":1788333172747,"m":true,"M":true}}
{"type":"trade","received_at_ms":1788333172583,"data":{"e":"trade","E":1788333172747,"s":"BTCUSDT","t":6646665780,"p":"77723.99000000","q":"0.00013000","T":1788333172747,"m":true,"M":true}}
{"type":"trade","received_at_ms":1788333172583,"data":{"e":"trade","E":1788333172747,"s":"BTCUSDT","t":6646665781,"p":"77723.99000000","q":"0.00007000","T":1788333172747,"m":true,"M":true}}
{"type":"trade","received_at_ms":1788333172583,"data":{"e":"trade","E":1788333172747,"s":"BTCUSDT","t":6646665782,"p":"77723.99000000","q":"0.00007000","T":1788333172747,"m":true,"M":true}}
{"type":"trade","received_at_ms":1788333172583,"data":{"e":"trade","E":1788333172747,"s":"BTCUSDT","t":6646665783,"p":"77723.99000000","q":"0.00007000","T":1788333172747,"m":true,"M":true}}
{"type":"trade","received_at_ms":1788333172583,"data":{"e":"trade","E":1788333172747,"s":"BTCUSDT","t":6646665784,"p":"77723.99000000","q":"0.00007000","T":1788333172747,"m":true,"M":true}}
{"type":"trade","received_at_ms":1788333172583,"data":{"e":"trade","E":1788333172747,"s":"BTCUSDT","t":6646665785,"p":"77723.99000000","q":"0.00007000","T":1788333172747,"m":true,"M":true}}
{"type":"trade","received_at_ms":1788333172583,"data":{"e":"trade","E":1788333172747,"s":"BTCUSDT","t":6646665786,"p":"77723.99000000","q":"0.00007000","T":1788333172747,"m":true,"M":true}}
{"type":"trade","received_at_ms":1788333172583,"data":{"e":"trade","E":1788333172747,"s":"BTCUSDT","t":6646665787,"p":"77723.99000000","q":"0.00065000","T":1788333172747,"m":true,"M":true}}
{"type":"trade","received_at_ms":1788333172583,"data":{"e":"trade","E":1788333172747,"s":"BTCUSDT","t":6646665788,"p":"77723.99000000","q":"0.00244000","T":1788333172747,"m":true,"M":true}}
{"type":"depth","received_at_ms":1788333172647,"data":{"e":"depthUpdate","E":1788333172814,"s":"BTCUSDT","U":99556324622,"u":99556324670,"b":[["77723.99000000","2.18502000"],["77723.98000000","0.00090000"],["77722.63000000","0.09184000"],["69951.60000000","0.00416000"],["69951.59000000","0.00000000"]],"a":[["77724.00000000","1.82247000"],["77724.01000000","0.00083000"],["77725.29000000","0.00014000"],["77725.30000000","0.11693000"],["77726.00000000","0.03014000"],["77726.17000000","0.15925000"],["77726.92000000","0.00000000"],["77726.93000000","0.00014000"],["77727.89000000","0.00136000"],["77727.97000000","0.00007000"],["77727.99000000","0.00007000"],["77728.93000000","0.00643000"],["77861.99000000","0.02016000"]]}}
{"type":"depth","received_at_ms":1788333172762,"data":{"e":"depthUpdate","E":1788333172914,"s":"BTCUSDT","U":99556324671,"u":99556324697,"b":[["77721.61000000","0.00000000"],["77720.76000000","0.00257000"],["69951.60000000","0.00448000"]],"a":[["77724.00000000","1.82255000"],["77725.30000000","0.11707000"],["77726.76000000","0.01281000"],["77726.93000000","0.00000000"],["77729.99000000","0.71747000"],["77731.35000000","0.00000000"],["77731.91000000","1.93226000"],["77731.92000000","0.42867000"],["77736.30000000","0.00257000"],["77737.14000000","0.00000000"],["77765.74000000","0.00672000"],["77817.18000000","0.00411000"],["77848.35000000","0.00089000"]]}}
{"type":"depth","received_at_ms":1788333172848,"data":{"e":"depthUpdate","E":1788333173014,"s":"BTCUSDT","U":99556324698,"u":99556324719,"b":[["77723.99000000","2.18495000"],["77723.98000000","0.00083000"],["77721.78000000","0.00257000"],["77720.76000000","0.00000000"],["71506.08000000","0.00009000"],["69951.60000000","0.00432000"],["69951.00000000","0.00068000"],["62179.20000000","0.00032000"]],"a":[["77724.00000000","1.69325000"],["77729.97000000","1.10112000"],["77729.98000000","1.31471000"],["77729.99000000","0.00000000"],["77736.30000000","0.00000000"],["77737.31000000","0.00257000"]]}}
{"type":"depth","received_at_ms":1788333172947,"data":{"e":"depthUpdate","E":1788333173114,"s":"BTCUSDT","U":99556324720,"u":99556324741,"b":[["77723.99000000","2.20509000"],["77723.98000000","0.00090000"],["77722.15000000","0.05007000"],["77722.10000000","0.05000000"],["77524.01000000","0.00811000"],["77522.01000000","0.00000000"],["69951.60000000","0.00448000"],["62179.19000000","0.00000000"]],"a":[["77729.96000000","0.01800000"],["77733.12000000","0.00000000"],["77734.18000000","0.00000000"]]}}
{"type":"depth","received_at_ms":1788333173048,"data":{"e":"depthUpdate","E":1788333173214,"s":"BTCUSDT","U":99556324742,"u":99556324771,"b":[["77722.62000000","0.11205000"],["77722.16000000","0.00000000"],["77722.15000000","0.00028000"],["77722.11000000","0.00000000"],["77722.10000000","0.00014000"],["77721.95000000","0.05000000"],["77721.90000000","0.05000000"],["77721.51000000","0.00014000"],["77721.26000000","0.00007000"],["77720.87000000","0.04091000"],["77720.25000000","0.02140000"],["69951.60000000","0.00432000"],["62179.20000000","0.00000000"]],"a":[["77887.27000000","0.00089000"]]}}
{"type":"trade","received_at_ms":1788333173078,"data":{"e":"trade","E":1788333173243,"s":"BTCUSDT","t":6646665789,"p":"77724.00000000","q":"0.00027000","T":1788333173243,"m":false,"M":true}}
{"type":"depth","received_at_ms":1788333173148,"data":{"e":"depthUpdate","E":1788333173314,"s":"BTCUSDT","U":99556324772,"u":99556324802,"b":[["77723.99000000","2.20523000"],["77723.98000000","0.00104000"],["77722.62000000","0.11212000"],["77722.15000000","0.00007000"],["77722.10000000","0.00000000"],["77721.96000000","0.00014000"],["77721.95000000","0.05021000"],["77721.91000000","0.00007000"],["77721.90000000","0.05014000"],["77721.51000000","0.00007000"],["77721.26000000","0.00000000"],["77708.00000000","0.70000000"],["69951.60000000","0.00457000"]],"a":[["77724.00000000","1.69298000"],["77786.08000000","0.00411000"]]}}
{"type":"depth","received_at_ms":1788333173249,"data":{"e":"depthUpdate","E":1788333173415,"s":"BTCUSDT","U":99556324803,"u":99556324821,"b":[["77723.99000000","2.20509000"],["77723.98000000","0.00090000"],["77721.96000000","0.00000000"],["77721.95000000","0.00021000"],["77721.91000000","0.00000000"],["77721.90000000","0.00014000"],["77721.51000000","0.00014000"],["77721.50000000","0.07140000"],["77721.26000000","0.00007000"],["77705.37000000","0.00007000"],["69951.60000000","0.00457000"]],"a":[["77736.47000000","0.00007000"],["77745.58000000","0.00000000"],["77747.66000000","0.00200000"]]}}
{"type":"depth","received_at_ms":1788333173347,"data":{"e":"depthUpdate","E":1788333173514,"s":"BTCUSDT","U":99556324822,"u":99556324838,"b":[["77722.62000000","0.11205000"],["77721.95000000","0.00000000"],["77721.90000000","0.00000000"],["77721.50000000","0.02140000"],["77720.87000000","0.04105000"],["77720.25000000","0.02154000"],["69951.60000000","0.00473000"],["62179.20000000","0.00032000"]],"a":[]}}
{"type":"depth","received_at_ms":1788333173453,"data":{"e":"depthUpdate","E":1788333173614,"s":"BTCUSDT","U":99556324839,"u":99556324863,"b":[["77723.99000000","2.20523000"],["77723.98000000","0.00104000"],["77722.62000000","0.11212000"],["77722.21000000","0.00014000"],["77722.20000000","0.05000000"],["77722.16000000","0.00007000"],["77722.15000000","0.05007000"],["77721.51000000","0.00007000"],["77721.26000000","0.00000000"],["69951.60000000","0.00457000"],["62179.20000000","0.00000000"],["62179.00000000","0.00200000"]],"a":[["79651.12000000","0.00025000"]]}}
{"type":"depth","received_at_ms":1788333173547,"data":{"e":"depthUpdate","E":1788333173714,"s":"BTCUSDT","U":99556324864,"u":99556324897,"b":[["77722.62000000","0.11212000"],["77722.21000000","0.00000000"],["77722.20000000","0.00014000"],["77722.16000000","0.00000000"],["77722.15000000","0.00021000"],["77721.51000000","0.00014000"],["77721.26000000","0.00007000"],["77720.87000000","0.04091000"],["77720.25000000","0.02140000"],["77714.86000000","0.00400000"],["77671.08000000","0.00411000"],["76558.13000000","0.00030000"],["69951.60000000","0.00457000"],["62179.19000000","0.00000000"]],"a":[["77724.00000000","1.83768000"],["78889.86000000","0.00030000"]]}}
{"type":"depth","received_at_ms":1788333173647,"data":{"e":"depthUpdate","E":1788333173814,"s":"BTCUSDT","U":99556324898,"u":99556324915,"b":[["77723.99000000","2.20509000"],["77723.98000000","0.00090000"],["77722.62000000","0.11205000"],["77722.20000000","0.00000000"],["77722.15000000","0.00007000"],["77720.87000000","0.04105000"],["77720.25000000","0.02154000"]],"a":[["77762.86000000","0.12872000"]]}}
{"type":"depth","received_at_ms":1788333173748,"data":{"e":"depthUpdate","E":1788333173914,"s":"BTCUSDT","U":99556324916,"u":99556324930,"b":[["77643.03000000","1.61347000"],["77635.26000000","0.00000000"],["69951.60000000","0.00457000"]],"a":[["77762.74000000","0.00000000"],["77762.84000000","0.00000000"],["77762.86000000","0.00000000"],["77763.15000000","0.00000000"],["77763.23000000","0.12872000"],["77816.54000000","0.00000000"]]}}
{"type":"depth","received_at_ms":1788333173852,"data":{"e":"depthUpdate","E":1788333174014,"s":"BTCUSDT","U":99556324931,"u":99556324980,"b":[["77723.99000000","2.20502000"],["77723.98000000","0.00083000"],["77722.63000000","0.05904000"],["77722.62000000","0.00014000"],["77722.13000000","0.00257000"],["77721.78000000","0.00000000"],["77721.33000000","0.00014000"],["77684.98000000","0.00007000"],["77588.03000000","0.00020000"],["69951.60000000","0.00473000"],["62179.20000000","0.00032000"]],"a":[["77724.00000000","1.69291000"],["77724.01000000","0.00076000"],["77724.38000000","0.00014000"],["77725.29000000","0.00000000"],["77725.30000000","0.00014000"],["77727.86000000","0.00000000"],["77727.94000000","0.00000000"],["77727.95000000","0.00000000"],["77727.97000000","0.00014000"],["77727.98000000","0.02821000"],["77727.99000000","0.08418000"],["77731.07000000","0.00000000"],["77733.12000000","0.00643000"],["77737.31000000","0.00000000"],["77737.67000000","0.00257000"],["77763.78000000","0.00000000"],["77860.06000000","0.00020000"]]}}
{"type":"depth","received_at_ms":1788333173947,"data":{"e":"depthUpdate","E":1788333174114,"s":"BTCUSDT","U":99556324981,"u":99556325012,"b":[["77723.99000000","2.20502000"],["77723.98000000","0.00083000"],["77722.74000000","0.01793000"],["77722.63000000","0.05904000"],["77722.62000000","0.00000000"],["77722.20000000","0.05000000"],["77722.15000000","0.05007000"],["69951.60000000","0.00441000"],["69951.00000000","0.00068000"],["62179.19000000","0.00000000"]],"a":[["77724.00000000","1.83137000"],["77725.30000000","0.00000000"],["77727.98000000","0.02821000"],["77727.99000000","0.08432000"],["77860.05000000","0.00128000"],["77863.05000000","0.00128000"]]}}
{"type":"depth","received_at_ms":1788333174047,"data":{"e":"depthUpdate","E":1788333174214,"s":"BTCUSDT","U":99556325013,"u":99556325090,"b":[["77723.99000000","2.20758000"],["77723.98000000","0.00090000"],["77722.74000000","0.01800000"],["77722.64000000","0.00000000"],["77722.63000000","0.00021000"],["77722.22000000","0.00014000"],["77722.21000000","0.08885000"],["77722.20000000","0.00014000"],["77722.16000000","0.00000000"],["77722.15000000","0.00007000"],["77722.13000000","0.00000000"],["77722.10000000","0.05000000"],["77722.00000000","0.05000000"],["77721.33000000","0.00000000"],["77721.26000000","0.00007000"],["77720.25000000","0.02140000"],["77714.86000000","0.00600000"],["77710.48000000","0.00000000"],["77701.69000000","0.03210000"],["77684.98000000","0.00000000"],["77646.05000000","0.84228000"],["69951.60000000","0.00457000"],["62179.20000000","0.00000000"]],"a":[["77724.00000000","1.69291000"],["77724.38000000","0.00007000"],["77725.36000000","0.00014000"],["77725.37000000","0.14353000"],["77726.16000000","0.00000000"],["77726.17000000","0.00028000"],["77727.98000000","0.02814000"],["77727.99000000","0.00021000"],["77728.71000000","0.00007000"],["77728.93000000","0.00000000"],["77729.95000000","0.00400000"],["77729.96000000","0.00600000"],["77730.72000000","0.00643000"],["77734.08000000","0.00000000"],["77737.67000000","0.00000000"],["77738.12000000","0.37338000"],["77738.13000000","0.00000000"],["77738.77000000","0.00257000"],["77743.52000000","0.04532000"],["77751.13000000","0.00000000"],["77754.78000000","0.00000000"],["77763.78000000","0.00007000"]]}}
{"type":"depth","received_at_ms":1788333174148,"data":{"e":"depthUpdate","E":1788333174314,"s":"BTCUSDT","U":99556325091,"u":99556325164,"b":[["77723.99000000","2.20759000"],["77723.98000000","0.00083000"],["77722.74000000","0.01793000"],["77722.63000000","0.00000000"],["77722.21000000","0.08892000"],["77722.20000000","0.00000000"],["77722.11000000","0.00014000"],["77722.10000000","0.00000000"],["77722.01000000","0.00000000"],["77722.00000000","0.00000000"],["77721.26000000","0.00007000"],["77613.46000000","0.00108000"],["77597.82000000","0.00000000"],["69951.60000000","0.00441000"],["62179.00000000","0.00200000"]],"a":[["77724.00000000","1.69305000"],["77724.01000000","0.00076000"],["77725.37000000","0.14367000"],["77726.00000000","0.03014000"],["77726.17000000","0.00014000"],["77727.98000000","0.02814000"],["77727.99000000","0.00007000"],["77728.56000000","0.00027000"],["77728.84000000","0.03214000"],["77728.94000000","0.02414000"]]}}
{"type":"depth","received_at_ms":1788333174248,"data":{"e":"depthUpdate","E":1788333174414,"s":"BTCUSDT","U":99556325165,"u":99556325216,"b":[["77723.99000000","2.20516000"],["77723.98000000","0.00090000"],["77722.21000000","0.05844000"],["77722.20000000","0.00000000"],["77722.11000000","0.00000000"],["77722.07000000","0.00257000"],["77721.33000000","0.00000000"],["77714.86000000","0.00400000"],["77710.48000000","0.00200000"],["77705.37000000","0.00007000"],["77684.98000000","0.00007000"],["69951.60000000","0.00441000"],["62179.00000000","0.00200000"]],"a":[["77724.00000000","1.69312000"],["77724.38000000","0.00014000"],["77727.95000000","0.00014000"],["77727.96000000","0.08205000"],["77727.99000000","0.00000000"],["77736.47000000","0.00007000"],["77737.61000000","0.00257000"],["77738.77000000","0.00000000"],["77763.23000000","0.00000000"],["77763.76000000","0.12872000"],["77763.78000000","0.00000000"]]}}
{"type":"depth","received_at_ms":1788333174346,"data":{"e":"depthUpdate","E":1788333174514,"s":"BTCUSDT","U":99556325217,"u":99556325246,"b":[["77723.99000000","2.20509000"],["77723.98000000","0.00083000"],["77722.21000000","0.05823000"],["77721.33000000","0.00014000"],["69951.60000000","0.00441000"],["62179.20000000","0.00032000"]],"a":[["77724.00000000","1.69305000"],["77726.76000000","0.01281000"],["77727.96000000","0.08219000"],["77727.97000000","0.00000000"],["77727.98000000","0.00014000"],["77727.99000000","0.00007000"],["77728.84000000","0.00014000"],["77728.94000000","0.00000000"],["77728.96000000","0.00010000"]]}}
{"type":"depth","received_at_ms":1788333174448,"data":{"e":"depthUpdate","E":1788333174614,"s":"BTCUSDT","U":99556325247,"u":99556325292,"b":[["77723.99000000","2.20523000"],["77723.98000000","0.00097000"],["77722.21000000","0.08163000"],["77722.20000000","0.05000000"],["77722.16000000","0.00000000"],["77722.15000000","0.00007000"],["77721.33000000","0.00000000"],["77721.26000000","0.00007000"],["77708.65000000","0.16978000"],["69951.60000000","0.00457000"],["62179.20000000","0.00000000"],["62179.00000000","0.00200000"]],"a":[["77727.96000000","0.08219000"],["77727.98000000","0.00000000"],["77728.00000000","0.03021000"],["77728.84000000","0.00000000"],["77728.99000000","0.00614000"],["77729.96000000","0.00614000"],["77737.95000000","0.02800000"],["77738.73000000","0.03200000"],["77786.33000000","0.02800000"],["77787.20000000","0.03208000"]]}}
{"type":"depth","received_at_ms":1788333174547,"data":{"e":"depthUpdate","E":1788333174714,"s":"BTCUSDT","U":99556325293,"u":99556325330,"b":[["77723.99000000","2.20509000"],["77723.98000000","0.00083000"],["77722.21000000","0.05823000"],["77722.20000000","0.00000000"],["77721.33000000","0.00014000"],["76558.13000000","0.00030000"],["69951.60000000","0.00441000"],["62179.19000000","0.00000000"]],"a":[["77724.00000000","1.81958000"],["77727.88000000","0.00000000"],["77738.65000000","0.03000000"],["77738.73000000","0.05600000"],["77747.43000000","0.00000000"],["77748.41000000","0.00000000"],["77751.73000000","0.02021000"],["77755.38000000","0.05524000"],["77787.30000000","0.02400000"],["77787.31000000","0.03000000"],["78889.86000000","0.00030000"]]}}
{"type":"depth","received_at_ms":1788333174649,"data":{"e":"depthUpdate","E":1788333174814,"s":"BTCUSDT","U":99556325331,"u":99556325375,"b":[["77723.99000000","2.20509000"],["77723.98000000","0.00083000"],["77723.10000000","0.00400000"],["77723.04000000","0.00257000"],["77722.21000000","0.05823000"],["77722.07000000","0.00000000"],["77719.41000000","0.11191000"],["77719.40000000","1.27693000"],["77719.39000000","1.93226000"],["77719.38000000","0.00000000"],["77691.90000000","0.00000000"],["77684.98000000","0.00000000"],["69951.60000000","0.00457000"]],"a":[["77724.00000000","1.69305000"],["77724.38000000","0.00007000"],["77727.86000000","0.00000000"],["77728.95000000","0.00000000"],["77729.97000000","0.49927000"],["77731.91000000","0.00000000"],["77737.61000000","0.00000000"],["77738.58000000","0.00257000"],["77748.29000000","0.00000000"],["77748.39000000","0.00000000"],["77751.73000000","0.00000000"],["77752.43000000","0.02015000"],["77755.38000000","0.00027000"],["77756.08000000","0.05266000"],["77760.00000000","0.06158000"],["77764.05000000","0.00400000"],["77816.43000000","0.00000000"]]}}
{"type":"depth","received_at_ms":1788333174748,"data":{"e":"depthUpdate","E":1788333174914,"s":"BTCUSDT","U":99556325376,"u":99556325400,"b":[["77723.99000000","2.20516000"],["77723.98000000","0.00090000"],["77719.88000000","0.11212000"],["77719.42000000","0.00600000"],["77714.86000000","0.00000000"],["77712.00000000","0.00265000"],["77710.48000000","0.00000000"],["77709.94000000","0.00000000"],["77671.08000000","0.00000000"],["77640.00000000","0.03000000"],["69951.60000000","0.00457000"]],"a":[["77729.95000000","0.00000000"],["77729.96000000","0.00214000"],["77734.18000000","0.00800000"],["77740.75000000","0.00000000"],["77743.12000000","0.00128000"],["77747.20000000","0.00000000"],["77786.08000000","0.00000000"],["77817.18000000","0.00000000"]]}}
{"type":"depth","received_at_ms":1788333174848,"data":{"e":"depthUpdate","E":1788333175014,"s":"BTCUSDT","U":99556325401,"u":99556325418,"b":[["71506.08000000","0.00000000"],["69951.60000000","0.00473000"],["69951.00000000","0.00068000"],["62179.20000000","0.00032000"],["62179.00000000","0.00200000"]],"a":[["77728.99000000","0.00614000"],["77729.96000000","0.00200000"],["77729.97000000","0.49941000"],["77740.64000000","0.00000000"],["77746.22000000","0.00038000"]]}}
{"type":"depth","received_at_ms":1788333174948,"data":{"e":"depthUpdate","E":1788333175114,"s":"BTCUSDT","U":99556325419,"u":99556325432,"b":[["77723.99000000","2.20553000"],["77722.10000000","0.05000000"],["77722.05000000","0.05000000"],["77716.21000000","0.00037000"],["77708.44000000","0.00037000"],["77700.67000000","0.00037000"],["77692.90000000","0.00037000"],["77627.11000000","0.04489000"],["77525.65000000","0.00811000"],["77524.01000000","0.00000000"],["69951.60000000","0.00457000"],["69951.00000000","0.00068000"],["62179.19000000","0.00000000"]],"a":[]}}
{"type":"depth","received_at_ms":1788333175048,"data":{"e":"depthUpdate","E":1788333175214,"s":"BTCUSDT","U":99556325433,"u":99556325536,"b":[["77723.99000000","2.20347000"],["77723.83000000","0.00257000"],["77723.04000000","0.00000000"],["77722.74000000","0.01800000"],["77722.63000000","0.00014000"],["77722.62000000","0.11191000"],["77722.21000000","0.08073000"],["77722.11000000","0.00000000"],["77722.10000000","0.00007000"],["77722.06000000","0.00014000"],["77721.33000000","0.00000000"],["77721.26000000","0.00000000"],["69951.60000000","0.00457000"],["62179.20000000","0.00000000"]],"a":[["77724.00000000","0.79425000"],["77724.16000000","0.00000000"],["77725.36000000","0.00000000"],["77725.37000000","0.00014000"],["77726.17000000","0.00000000"],["77726.18000000","0.00014000"],["77726.75000000","0.00014000"],["77727.95000000","0.00000000"],["77727.96000000","0.00014000"],["77727.99000000","0.00014000"],["77728.11000000","0.11191000"],["77728.32000000","0.00007000"],["77729.47000000","0.00014000"],["77729.48000000","0.11191000"],["77729.95000000","0.00007000"],["77729.96000000","0.11398000"],["77729.97000000","0.13566000"],["77729.98000000","0.00000000"],["77733.12000000","0.00000000"],["77733.87000000","0.32176000"],["77734.18000000","0.00000000"],["77735.79000000","0.00643000"],["77736.19000000","0.00000000"],["77736.42000000","0.00000000"],["77736.47000000","0.00407000"],["77736.55000000","0.00000000"],["77736.62000000","0.00400000"],["77738.58000000","0.00000000"],["77739.37000000","0.00257000"],["77743.12000000","0.00000000"],["77747.16000000","0.00128000"],["77763.78000000","0.00007000"]]}}
{"type":"depth","received_at_ms":1788333175149,"data":{"e":"depthUpdate","E":1788333175314,"s":"BTCUSDT","U":99556325537,"u":99556325647,"b":[["77723.99000000","2.20361000"],["77723.98000000","0.00104000"],["77722.74000000","0.01807000"],["77722.64000000","0.00014000"],["77722.63000000","0.12164000"],["77722.62000000","0.11212000"],["77722.22000000","0.00000000"],["77722.21000000","0.00021000"],["77722.20000000","0.05000000"],["77722.10000000","0.00000000"],["77722.06000000","0.00000000"],["77722.05000000","0.00000000"],["77721.96000000","0.00000000"],["77721.95000000","0.00000000"],["77721.51000000","0.00007000"],["77719.34000000","0.35386000"],["77718.72000000","0.00000000"],["77717.99000000","0.38298000"],["77649.06000000","0.00112000"],["77633.45000000","0.00000000"],["69951.60000000","0.00457000"],["69951.00000000","0.00068000"]],"a":[["77724.00000000","0.98597000"],["77724.01000000","0.00076000"],["77725.37000000","0.00000000"],["77726.00000000","0.03014000"],["77726.18000000","0.00000000"],["77726.76000000","0.01281000"],["77727.96000000","0.00000000"],["77728.00000000","0.03021000"],["77728.10000000","0.00014000"],["77728.11000000","0.11205000"],["77728.32000000","0.00014000"],["77728.99000000","0.00614000"],["77729.46000000","0.00007000"],["77729.47000000","0.23400000"],["77729.48000000","0.11205000"],["77729.95000000","0.00000000"],["77729.96000000","0.11205000"],["77729.97000000","0.00014000"],["77731.35000000","0.11191000"],["77733.33000000","0.00451000"],["77751.09000000","0.00411000"]]}}
{"type":"trade","received_at_ms":1788333175158,"data":{"e":"trade","E":1788333175323,"s":"BTCUSDT","t":6646665790,"p":"77724.00000000","q":"0.00007000","T":1788333175323,"m":false,"M":true}}
{"type":"trade","received_at_ms":1788333175158,"data":{"e":"trade","E":1788333175323,"s":"BTCUSDT","t":6646665791,"p":"77724.00000000","q":"0.00528000","T":1788333175323,"m":false,"M":true}}
{"type":"trade","received_at_ms":1788333175158,"data":{"e":"trade","E":1788333175323,"s":"BTCUSDT","t":6646665792,"p":"77724.00000000","q":"0.00007000","T":1788333175323,"m":false,"M":true}}
{"type":"trade","received_at_ms":1788333175158,"data":{"e":"trade","E":1788333175323,"s":"BTCUSDT","t":6646665793,"p":"77724.00000000","q":"0.00007000","T":1788333175323,"m":false,"M":true}}
{"type":"trade","received_at_ms":1788333175158,"data":{"e":"trade","E":1788333175323,"s":"BTCUSDT","t":6646665794,"p":"77724.00000000","q":"0.00007000","T":1788333175323,"m":false,"M":true}}
{"type":"trade","received_at_ms":1788333175158,"data":{"e":"trade","E":1788333175323,"s":"BTCUSDT","t":6646665795,"p":"77724.00000000","q":"0.00944000","T":1788333175323,"m":false,"M":true}}
{"type":"depth","received_at_ms":1788333175247,"data":{"e":"depthUpdate","E":1788333175414,"s":"BTCUSDT","U":99556325648,"u":99556325690,"b":[["77723.99000000","2.20882000"],["77723.98000000","0.00097000"],["77722.74000000","0.01800000"],["77722.63000000","0.12178000"],["77722.62000000","0.11198000"],["77722.21000000","0.00000000"],["77722.20000000","0.00000000"],["77722.01000000","0.00014000"],["77722.00000000","0.05000000"],["77721.51000000","0.00014000"],["77721.26000000","0.00000000"],["77710.00000000","0.70000000"],["77705.37000000","0.00000000"],["69951.60000000","0.00448000"],["69951.59000000","0.00009000"]],"a":[["77724.00000000","0.97105000"],["77728.99000000","0.00614000"],["77729.47000000","0.23414000"],["77729.96000000","0.11205000"],["77729.97000000","0.00000000"],["77736.47000000","0.00400000"]]}}
{"type":"depth","received_at_ms":1788333175348,"data":{"e":"depthUpdate","E":1788333175514,"s":"BTCUSDT","U":99556325691,"u":99556325711,"b":[["77723.99000000","2.21088000"],["77722.62000000","0.11191000"],["77722.01000000","0.00000000"],["77722.00000000","0.00000000"],["77721.26000000","0.00007000"],["77705.37000000","0.00007000"],["75557.14000000","0.00000000"],["69951.60000000","0.00464000"],["69951.00000000","0.00078000"],["62179.20000000","0.00032000"],["62179.00000000","0.00200000"]],"a":[["77724.00000000","0.97112000"],["77728.85000000","0.00206000"],["77729.61000000","0.08205000"],["77736.47000000","0.00407000"],["81001.14000000","0.00000000"]]}}
{"type":"depth","received_at_ms":1788333175448,"data":{"e":"depthUpdate","E":1788333175614,"s":"BTCUSDT","U":99556325712,"u":99556325747,"b":[["77723.99000000","2.21095000"],["77722.62000000","0.11198000"],["77721.81000000","0.00000000"],["77721.80000000","0.00007000"],["77721.76000000","0.00014000"],["77721.75000000","0.05000000"],["77721.51000000","0.00007000"],["77721.26000000","0.00000000"],["77706.44000000","0.00000000"],["77686.93000000","0.00000000"],["77658.86000000","0.00000000"],["69951.60000000","0.00432000"],["69951.00000000","0.00068000"],["62179.20000000","0.00000000"]],"a":[["77729.48000000","0.11205000"],["77729.61000000","0.08219000"],["77729.96000000","0.11191000"],["77738.65000000","0.00000000"],["77747.66000000","0.00000000"],["77748.27000000","0.00200000"],["77767.86000000","0.00000000"],["77787.31000000","0.00000000"]]}}
{"type":"depth","received_at_ms":1788333175547,"data":{"e":"depthUpdate","E":1788333175714,"s":"BTCUSDT","U":99556325748,"u":99556325774,"b":[["77723.99000000","2.21088000"],["77722.62000000","0.11191000"],["77721.80000000","0.00000000"],["77721.76000000","0.00000000"],["77721.75000000","0.00000000"],["77721.51000000","0.00014000"],["77721.26000000","0.00007000"],["77708.04000000","0.02000000"],["77670.09000000","0.00411000"],["77669.13000000","0.02000000"],["76558.13000000","0.00030000"],["69951.60000000","0.00432000"],["62179.19000000","0.00000000"]],"a":[["77724.00000000","1.12029000"],["77725.73000000","0.14471000"],["77738.62000000","0.03000000"],["77758.08000000","0.03000000"],["77758.20000000","0.00400000"],["77764.05000000","0.00000000"],["77777.54000000","0.03000000"],["78889.86000000","0.00030000"]]}}
{"type":"depth","received_at_ms":1788333175648,"data":{"e":"depthUpdate","E":1788333175814,"s":"BTCUSDT","U":99556325775,"u":99556325785,"b":[["69951.60000000","0.00432000"]],"a":[["77724.00000000","1.12043000"],["77725.72000000","0.00014000"],["77726.75000000","0.00000000"],["77729.61000000","0.08205000"],["77819.13000000","2.15325000"]]}}
{"type":"trade","received_at_ms":1788333175686,"data":{"e":"trade","E":1788333175851,"s":"BTCUSDT","t":6646665796,"p":"77724.00000000","q":"0.00018000","T":1788333175851,"m":false,"M":true}}
{"type":"depth","received_at_ms":1788333175747,"data":{"e":"depthUpdate","E":1788333175914,"s":"BTCUSDT","U":99556325786,"u":99556325817,"b":[["77723.99000000","2.21095000"],["77722.63000000","0.37475000"],["77721.51000000","0.00000000"],["77721.26000000","0.00014000"],["77721.25000000","0.11219000"],["77721.12000000","0.00007000"],["77721.11000000","0.11198000"],["77721.10000000","1.00000000"],["77719.88000000","0.00014000"],["77719.41000000","0.00000000"],["69951.60000000","0.00464000"],["69951.59000000","0.00000000"],["69951.00000000","0.00078000"]],"a":[["77724.00000000","1.12025000"],["77724.01000000","0.00083000"],["77728.10000000","0.00000000"],["77728.11000000","0.00014000"],["77729.46000000","0.00014000"],["77729.96000000","0.00000000"],["77730.85000000","0.11191000"]]}}
{"type":"depth","received_at_ms":1788333175848,"data":{"e":"depthUpdate","E":1788333176014,"s":"BTCUSDT","U":99556325818,"u":99556325843,"b":[["77722.62000000","0.11205000"],["77721.25000000","0.11205000"],["77720.87000000","0.04091000"],["77719.42000000","0.00400000"],["77710.48000000","0.00200000"],["69951.60000000","0.00432000"],["69951.00000000","0.00068000"],["62179.20000000","0.00032000"]],"a":[["77724.00000000","1.11875000"],["77725.73000000","0.14485000"],["77728.00000000","0.03021000"],["77728.11000000","0.00000000"],["77729.61000000","0.08219000"],["82938.65000000","0.00000000"]]}}
{"type":"depth","received_at_ms":1788333175948,"data":{"e":"depthUpdate","E":1788333176114,"s":"BTCUSDT","U":99556325844,"u":99556325849,"b":[["77639.01000000","0.00411000"],["76398.49000000","0.00000000"],["69951.60000000","0.00464000"],["62179.19000000","0.00000000"]],"a":[]}}
{"type":"depth","received_at_ms":1788333176061,"data":{"e":"depthUpdate","E":1788333176214,"s":"BTCUSDT","U":99556325850,"u":99556325892,"b":[["77723.99000000","2.21102000"],["77723.98000000","0.00104000"],["77722.62000000","0.11212000"],["77722.06000000","0.00014000"],["77722.05000000","0.05007000"],["77722.01000000","0.00007000"],["77722.00000000","0.05000000"],["77721.26000000","0.00007000"],["77721.25000000","0.11198000"],["77721.12000000","0.00000000"],["77721.11000000","0.00000000"],["77526.01000000","0.00811000"],["77525.65000000","0.00000000"],["69951.60000000","0.00448000"],["62179.20000000","0.00000000"]],"a":[["77724.00000000","1.12033000"],["77724.01000000","0.00076000"],["77725.72000000","0.00000000"],["77725.73000000","0.00014000"],["77726.75000000","0.00014000"],["77728.10000000","0.00014000"],["77728.11000000","0.11191000"],["77729.47000000","0.23407000"],["77736.03000000","0.00400000"],["77736.47000000","0.00007000"],["77736.62000000","0.00400000"]]}}
{"type":"trade","received_at_ms":1788333176142,"data":{"e":"trade","E":1788333176308,"s":"BTCUSDT","t":6646665797,"p":"77723.99000000","q":"0.00032000","T":1788333176308,"m":true,"M":true}}
{"type":"depth","received_at_ms":1788333176149,"data":{"e":"depthUpdate","E":1788333176314,"s":"BTCUSDT","U":99556325893,"u":99556325945,"b":[["77723.99000000","2.21070000"],["77723.98000000","0.00097000"],["77722.62000000","0.11212000"],["77722.06000000","0.00000000"],["77722.05000000","0.00014000"],["77722.01000000","0.00000000"],["77722.00000000","0.00014000"],["77721.91000000","0.00014000"],["77721.90000000","0.05007000"],["77721.86000000","0.00007000"],["77721.85000000","0.05000000"],["77721.25000000","0.11212000"],["77708.95000000","0.00411000"],["75557.14000000","0.00010000"],["69951.60000000","0.00480000"],["69951.59000000","0.00009000"],["62179.00000000","0.00200000"]],"a":[["77724.00000000","1.11991000"],["77725.73000000","0.00000000"],["77728.00000000","0.03021000"],["77728.11000000","0.11205000"]]}}
{"type":"trade","received_at_ms":1788333176196,"data":{"e":"trade","E":1788333176361,"s":"BTCUSDT","t":6646665798,"p":"77723.99000000","q":"0.01029000","T":1788333176361,"m":true,"M":true}}
{"type":"trade","received_at_ms":1788333176196,"data":{"e":"trade","E":1788333176361,"s":"BTCUSDT","t":6646665799,"p":"77723.99000000","q":"0.00007000","T":1788333176361,"m":true,"M":true}}
{"type":"trade","received_at_ms":1788333176196,"data":{"e":"trade","E":1788333176361,"s":"BTCUSDT","t":6646665800,"p":"77723.99000000","q":"0.00007000","T":1788333176361,"m":true,"M":true}}
{"type":"trade","received_at_ms":1788333176196,"data":{"e":"trade","E":1788333176361,"s":"BTCUSDT","t":6646665801,"p":"77723.99000000","q":"0.00007000","T":1788333176361,"m":true,"M":true}}
{"type":"trade","received_at_ms":1788333176196,"data":{"e":"trade","E":1788333176361,"s":"BTCUSDT","t":6646665802,"p":"77723.99000000","q":"0.00200000","T":1788333176361,"m":true,"M":true}}
{"type":"trade","received_at_ms":1788333176196,"data":{"e":"trade","E":1788333176361,"s":"BTCUSDT","t":6646665803,"p":"77723.99000000","q":"0.00200000","T":1788333176361,"m":true,"M":true}}
{"type":"trade","received_at_ms":1788333176196,"data":{"e":"trade","E":1788333176361,"s":"BTCUSDT","t":6646665804,"p":"77723.99000000","q":"0.00050000","T":1788333176361,"m":true,"M":true}}
{"type":"depth","received_at_ms":1788333176247,"data":{"e":"depthUpdate","E":1788333176414,"s":"BTCUSDT","U":99556325946,"u":99556325996,"b":[["77723.99000000","2.20039000"],["77723.98000000","0.00097000"],["77722.63000000","0.37461000"],["77722.62000000","0.00021000"],["77722.05000000","0.00000000"],["77722.00000000","0.00000000"],["77721.91000000","0.00000000"],["77721.90000000","0.00021000"],["77721.86000000","0.00014000"],["77721.85000000","0.05021000"],["77721.81000000","0.00014000"],["77721.80000000","0.05000000"],["77721.26000000","0.00014000"],["77721.11000000","0.00000000"],["71506.08000000","0.00014000"],["69951.60000000","0.00464000"],["69951.00000000","0.00088000"]],"a":[["77724.00000000","1.11998000"],["77724.01000000","0.00083000"],["77725.45000000","0.00014000"],["77725.46000000","0.12758000"],["77726.75000000","0.00000000"]]}}
{"type":"depth","received_at_ms":1788333176349,"data":{"e":"depthUpdate","E":1788333176516,"s":"BTCUSDT","U":99556325997,"u":99556326031,"b":[["77722.63000000","0.37461000"],["77722.62000000","0.00007000"],["77721.90000000","0.00007000"],["77721.85000000","0.05021000"],["77721.80000000","0.05014000"],["77721.10000000","1.00014000"],["77708.65000000","0.00000000"],["77706.36000000","0.00000000"],["77705.37000000","0.00007000"],["77686.85000000","0.00000000"],["77658.76000000","0.00000000"],["69951.60000000","0.00480000"],["69951.00000000","0.00068000"],["62179.20000000","0.00032000"]],"a":[["77724.00000000","1.11998000"],["77725.46000000","0.12772000"],["77729.61000000","0.08205000"],["77736.47000000","0.00007000"],["77738.73000000","0.03200000"],["77767.84000000","0.00000000"],["77787.30000000","0.00000000"],["77789.97000000","0.00411000"]]}}
{"type":"depth","received_at_ms":1788333176448,"data":{"e":"depthUpdate","E":1788333176614,"s":"BTCUSDT","U":99556326032,"u":99556326051,"b":[["77723.99000000","2.20039000"],["77723.98000000","0.00104000"],["77721.91000000","0.00014000"],["77721.90000000","0.05007000"],["77721.81000000","0.00000000"],["77721.80000000","0.00014000"],["77721.11000000","0.00000000"],["69951.60000000","0.00464000"],["62179.20000000","0.00000000"],["62179.00000000","0.00200000"]],"a":[["81001.14000000","0.00010000"]]}}
{"type":"trade","received_at_ms":1788333176499,"data":{"e":"trade","E":1788333176666,"s":"BTCUSDT","t":6646665805,"p":"77724.00000000","q":"0.00050000","T":1788333176665,"m":false,"M":true}}
{"type":"depth","received_at_ms":1788333176547,"data":{"e":"depthUpdate","E":1788333176714,"s":"BTCUSDT","U":99556326052,"u":99556326097,"b":[["77723.99000000","2.20039000"],["77723.98000000","0.00097000"],["77722.63000000","0.37461000"],["77721.90000000","0.05028000"],["77721.86000000","0.00000000"],["77721.85000000","0.00014000"],["77721.80000000","0.00000000"],["77721.76000000","0.00014000"],["77721.75000000","0.05000000"],["77721.11000000","0.00000000"],["77708.95000000","0.00000000"],["77707.96000000","0.02000000"],["77669.05000000","0.02007000"],["77649.67000000","0.02000000"],["77639.01000000","0.00000000"],["76558.13000000","0.00030000"],["69951.60000000","0.00464000"],["69951.59000000","0.00000000"],["69951.58000000","0.00009000"],["62179.19000000","0.00000000"]],"a":[["77724.00000000","1.11798000"],["77738.68000000","0.02400000"],["77758.13000000","0.02400000"],["77777.59000000","0.02400000"],["77789.97000000","0.00000000"],["77821.07000000","0.00411000"],["78889.86000000","0.00030000"]]}}
{"type":"depth","received_at_ms":1788333176647,"data":{"e":"depthUpdate","E":1788333176814,"s":"BTCUSDT","U":99556326098,"u":99556326120,"b":[["77723.99000000","2.20025000"],["77723.98000000","0.00090000"],["77721.91000000","0.00000000"],["77721.90000000","0.00021000"],["77721.85000000","0.00000000"],["77721.76000000","0.00000000"],["77721.75000000","0.00014000"],["77721.51000000","0.00014000"],["77721.11000000","0.00007000"],["69951.60000000","0.00464000"]],"a":[]}}
{"type":"depth","received_at_ms":1788333176748,"data":{"e":"depthUpdate","E":1788333176914,"s":"BTCUSDT","U":99556326121,"u":99556326143,"b":[["77722.74000000","0.01793000"],["77722.63000000","0.37461000"],["77722.62000000","0.00000000"],["77721.90000000","0.00000000"],["77721.75000000","0.00000000"],["77720.87000000","0.04105000"],["77720.25000000","0.02154000"],["77694.09000000","0.04745000"],["77693.06000000","0.00000000"],["69951.60000000","0.00464000"]],"a":[["77736.03000000","0.00400000"]]}}
{"type":"depth","received_at_ms":1788333176847,"data":{"e":"depthUpdate","E":1788333177014,"s":"BTCUSDT","U":99556326144,"u":99556326147,"b":[["71506.08000000","0.00000000"],["69951.60000000","0.00480000"],["62179.20000000","0.00032000"]],"a":[["81938.65000000","0.00000000"]]}}
{"type":"depth","received_at_ms":1788333176949,"data":{"e":"depthUpdate","E":1788333177114,"s":"BTCUSDT","U":99556326148,"u":99556326153,"b":[["77717.98000000","0.15370000"],["69951.60000000","0.00448000"],["62179.19000000","0.00000000"]],"a":[["77789.96000000","0.00411000"]]}}
{"type":"trade","received_at_ms":1788333177040,"data":{"e":"trade","E":1788333177206,"s":"BTCUSDT","t":6646665806,"p":"77724.00000000","q":"0.00080000","T":1788333177206,"m":false,"M":true}}
{"type":"depth","received_at_ms":1788333177047,"data":{"e":"depthUpdate","E":1788333177214,"s":"BTCUSDT","U":99556326154,"u":99556326180,"b":[["77723.99000000","2.20032000"],["77723.98000000","0.00097000"],["77722.63000000","0.37468000"],["77721.91000000","0.00014000"],["77721.90000000","0.05000000"],["77721.86000000","0.00000000"],["77721.85000000","0.00000000"],["77721.51000000","0.00000000"],["77721.11000000","0.00007000"],["69951.60000000","0.00464000"],["69951.58000000","0.00000000"],["62179.20000000","0.00000000"]],"a":[["77724.00000000","1.11868000"]]}}
{"type":"trade","received_at_ms":1788333177098,"data":{"e":"trade","E":1788333177264,"s":"BTCUSDT","t":6646665807,"p":"77724.00000000","q":"0.00016000","T":1788333177264,"m":false,"M":true}}
{"type":"depth","received_at_ms":1788333177147,"data":{"e":"depthUpdate","E":1788333177314,"s":"BTCUSDT","U":99556326181,"u":99556326199,"b":[["77722.63000000","0.37468000"],["77721.90000000","0.05014000"],["77721.51000000","0.00000000"],["77721.50000000","0.02140000"],["77721.11000000","0.00007000"],["77720.25000000","0.02140000"],["69951.60000000","0.00448000"]],"a":[["77724.00000000","1.11702000"]]}}
{"type":"depth","received_at_ms":1788333177248,"data":{"e":"depthUpdate","E":1788333177414,"s":"BTCUSDT","U":99556326200,"u":99556326209,"b":[["77722.63000000","0.37475000"],["77721.96000000","0.00014000"],["77721.95000000","0.05000000"],["77721.11000000","0.00000000"],["69951.60000000","0.00464000"]],"a":[["77763.76000000","0.00000000"],["77816.43000000","0.00087000"]]}}
{"type":"depth","received_at_ms":1788333177348,"data":{"e":"depthUpdate","E":1788333177514,"s":"BTCUSDT","U":99556326210,"u":99556326245,"b":[["77723.99000000","2.20032000"],["77723.98000000","0.00097000"],["77722.63000000","0.37482000"],["77722.01000000","0.00014000"],["77722.00000000","0.05000000"],["77721.96000000","0.00000000"],["77721.95000000","0.00014000"],["77721.91000000","0.00000000"],["77721.90000000","0.00014000"],["77721.11000000","0.00007000"],["77720.87000000","0.04091000"],["77708.94000000","0.00411000"],["77706.38000000","0.00000000"],["77705.37000000","0.00007000"],["77686.86000000","0.00000000"],["77668.29000000","0.00000000"],["77658.71000000","0.00000000"],["77562.54000000","0.01767000"],["77252.59000000","0.02384000"],["69951.60000000","0.00448000"],["62179.20000000","0.00032000"]],"a":[["77724.00000000","1.12902000"],["77736.47000000","0.00007000"],["77738.73000000","0.00000000"],["77767.74000000","0.00000000"],["77787.20000000","0.00008000"]]}}
{"type":"depth","received_at_ms":1788333177447,"data":{"e":"depthUpdate","E":1788333177614,"s":"BTCUSDT","U":99556326246,"u":99556326285,"b":[["77723.99000000","2.20039000"],["77723.98000000","0.00097000"],["77722.63000000","0.37475000"],["77722.35000000","0.00400000"],["77722.01000000","0.00000000"],["77722.00000000","0.00014000"],["77721.96000000","0.00014000"],["77721.95000000","0.05000000"],["77721.90000000","0.00000000"],["77721.51000000","0.00000000"],["77720.87000000","0.04105000"],["77712.48000000","0.08652000"],["76330.16000000","0.01118000"],["69951.60000000","0.00448000"],["69951.00000000","0.00068000"],["62179.20000000","0.00000000"],["62179.00000000","0.00400000"]],"a":[["77733.25000000","0.00400000"]]}}
{"type":"trade","received_at_ms":1788333177470,"data":{"e":"trade","E":1788333177636,"s":"BTCUSDT","t":6646665808,"p":"77724.00000000","q":"0.03315000","T":1788333177636,"m":false,"M":true}}
{"type":"depth","received_at_ms":1788333177547,"data":{"e":"depthUpdate","E":1788333177714,"s":"BTCUSDT","U":99556326286,"u":99556326319,"b":[["77723.99000000","2.20046000"],["77723.98000000","0.00104000"],["77722.63000000","0.37475000"],["77722.01000000","0.00014000"],["77722.00000000","0.05000000"],["77721.95000000","0.05014000"],["77721.11000000","0.00000000"],["77707.89000000","0.02000000"],["77668.98000000","0.02000000"],["77649.60000000","0.02000000"],["76558.13000000","0.00030000"],["76177.49000000","0.02060000"],["69951.60000000","0.00457000"],["62179.19000000","0.00000000"],["62179.00000000","0.00200000"]],"a":[["77724.00000000","1.09587000"],["77738.58000000","0.03200000"],["77758.03000000","0.03200000"],["77777.49000000","0.03200000"],["78889.86000000","0.00030000"]]}}
{"type":"depth","received_at_ms":1788333177648,"data":{"e":"depthUpdate","E":1788333177815,"s":"BTCUSDT","U":99556326320,"u":99556326342,"b":[["77722.63000000","0.37475000"],["77722.00000000","0.00014000"],["77721.95000000","0.00014000"],["77720.87000000","0.04091000"],["77701.51000000","0.48935000"],["77645.62000000","1.61347000"],["77643.03000000","0.00000000"],["76025.13000000","0.01394000"],["69951.60000000","0.00489000"]],"a":[["77724.00000000","1.09580000"],["77724.01000000","0.00076000"],["77725.45000000","0.00000000"],["77725.46000000","0.00014000"],["77726.75000000","0.00014000"]]}}
{"type":"depth","received_at_ms":1788333177747,"data":{"e":"depthUpdate","E":1788333177914,"s":"BTCUSDT","U":99556326343,"u":99556326371,"b":[["77723.99000000","2.20039000"],["77722.63000000","0.37461000"],["77722.01000000","0.00000000"],["77722.00000000","0.00000000"],["77721.96000000","0.00000000"],["77721.95000000","0.00000000"],["77721.51000000","0.00014000"],["77721.11000000","0.00007000"],["77720.87000000","0.04105000"],["77704.32000000","0.35468000"],["69951.60000000","0.00457000"]],"a":[["77724.00000000","1.09594000"],["77725.46000000","0.00000000"],["77729.61000000","0.08219000"]]}}
{"type":"depth","received_at_ms":1788333177848,"data":{"e":"depthUpdate","E":1788333178014,"s":"BTCUSDT","U":99556326372,"u":99556326382,"b":[["77723.99000000","2.20032000"],["77723.98000000","0.00097000"],["75873.07000000","0.01606000"],["69951.60000000","0.00489000"],["62179.20000000","0.00032000"],["62179.00000000","0.00200000"]],"a":[["77762.94000000","0.12872000"]]}}
{"type":"depth","received_at_ms":1788333177963,"data":{"e":"depthUpdate","E":1788333178115,"s":"BTCUSDT","U":99556326383,"u":99556326386,"b":[["75721.32000000","0.01828000"],["69951.60000000","0.00473000"]],"a":[]}}
{"type":"depth","received_at_ms":1788333178048,"data":{"e":"depthUpdate","E":1788333178214,"s":"BTCUSDT","U":99556326387,"u":99556326406,"b":[["77723.99000000","2.20046000"],["77722.63000000","0.37468000"],["77721.96000000","0.00014000"],["77721.95000000","0.05007000"],["77721.81000000","0.00014000"],["77721.80000000","0.05000000"],["77721.51000000","0.00000000"],["77721.11000000","0.00000000"],["69951.60000000","0.00473000"],["62179.20000000","0.00000000"],["62179.19000000","0.00000000"]],"a":[]}}
{"type":"depth","received_at_ms":1788333178149,"data":{"e":"depthUpdate","E":1788333178314,"s":"BTCUSDT","U":99556326407,"u":99556326433,"b":[["77723.99000000","2.20046000"],["77722.63000000","0.37468000"],["77721.95000000","0.05021000"],["77721.91000000","0.00014000"],["77721.90000000","0.05000000"],["77721.81000000","0.00000000"],["77721.80000000","0.00000000"],["77721.26000000","0.00007000"],["77720.87000000","0.04091000"],["77708.94000000","0.00000000"],["77639.00000000","0.00411000"],["62179.00000000","0.00200000"]],"a":[["77789.96000000","0.00000000"],["77821.07000000","0.00000000"]]}}
{"type":"trade","received_at_ms":1788333178208,"data":{"e":"trade","E":1788333178374,"s":"BTCUSDT","t":6646665809,"p":"77724.00000000","q":"0.00257000","T":1788333178374,"m":false,"M":true}}
{"type":"depth","received_at_ms":1788333178248,"data":{"e":"depthUpdate","E":1788333178414,"s":"BTCUSDT","U":99556326434,"u":99556326443,"b":[["77721.95000000","0.05021000"],["69951.60000000","0.00464000"],["69951.59000000","0.00009000"]],"a":[["77724.00000000","1.09337000"]]}}
{"type":"depth","received_at_ms":1788333178348,"data":{"e":"depthUpdate","E":1788333178514,"s":"BTCUSDT","U":99556326444,"u":99556326459,"b":[["77723.99000000","2.20039000"],["77721.96000000","0.00000000"],["77721.95000000","0.00021000"],["77721.85000000","0.05000000"],["77721.26000000","0.00014000"],["77721.11000000","0.00007000"],["77707.16000000","0.00000000"],["77705.37000000","0.00007000"],["77687.64000000","0.00000000"],["77659.46000000","0.00000000"],["69951.60000000","0.00464000"],["62179.20000000","0.00032000"],["62179.00000000","0.00200000"]],"a":[["77736.47000000","0.00007000"],["77737.95000000","0.00000000"],["77766.88000000","0.00000000"],["77786.33000000","0.00000000"]]}}
{"type":"trade","received_at_ms":1788333178378,"data":{"e":"trade","E":1788333178543,"s":"BTCUSDT","t":6646665810,"p":"77724.00000000","q":"0.00200000","T":1788333178543,"m":false,"M":true}}
{"type":"trade","received_at_ms":1788333178378,"data":{"e":"trade","E":1788333178543,"s":"BTCUSDT","t":6646665811,"p":"77724.00000000","q":"0.00200000","T":1788333178543,"m":false,"M":true}}
{"type":"trade","received_at_ms":1788333178378,"data":{"e":"trade","E":1788333178543,"s":"BTCUSDT","t":6646665812,"p":"77724.00000000","q":"0.00200000","T":1788333178543,"m":false,"M":true}}
{"type":"trade","received_at_ms":1788333178378,"data":{"e":"trade","E":1788333178543,"s":"BTCUSDT","t":6646665813,"p":"77724.00000000","q":"0.00200000","T":1788333178543,"m":false,"M":true}}
{"type":"trade","received_at_ms":1788333178378,"data":{"e":"trade","E":1788333178543,"s":"BTCUSDT","t":6646665814,"p":"77724.00000000","q":"0.00200000","T":1788333178543,"m":false,"M":true}}
{"type":"trade","received_at_ms":1788333178378,"data":{"e":"trade","E":1788333178544,"s":"BTCUSDT","t":6646665815,"p":"77724.00000000","q":"0.00200000","T":1788333178543,"m":false,"M":true}}
{"type":"trade","received_at_ms":1788333178378,"data":{"e":"trade","E":1788333178544,"s":"BTCUSDT","t":6646665816,"p":"77724.00000000","q":"0.00200000","T":1788333178544,"m":false,"M":true}}
{"type":"trade","received_at_ms":1788333178379,"data":{"e":"trade","E":1788333178545,"s":"BTCUSDT","t":6646665817,"p":"77724.00000000","q":"0.00200000","T":1788333178545,"m":false,"M":true}}
{"type":"trade","received_at_ms":1788333178379,"data":{"e":"trade","E":1788333178545,"s":"BTCUSDT","t":6646665818,"p":"77724.00000000","q":"0.00200000","T":1788333178545,"m":false,"M":true}}
{"type":"trade","received_at_ms":1788333178379,"data":{"e":"trade","E":1788333178546,"s":"BTCUSDT","t":6646665819,"p":"77724.00000000","q":"0.00200000","T":1788333178545,"m":false,"M":true}}
{"type":"depth","received_at_ms":1788333178449,"data":{"e":"depthUpdate","E":1788333178614,"s":"BTCUSDT","U":99556326460,"u":99556326511,"b":[["77723.99000000","2.19983000"],["77723.98000000","0.00090000"],["77722.63000000","0.37468000"],["77721.95000000","0.05007000"],["77721.90000000","0.05014000"],["77721.86000000","0.00000000"],["77721.85000000","0.00000000"],["77721.11000000","0.00007000"],["77719.20000000","0.30400000"],["77718.20000000","0.30500000"],["77591.31000000","0.02015000"],["77584.84000000","0.00000000"],["69951.60000000","0.00448000"],["62179.20000000","0.00000000"]],"a":[["77724.00000000","1.07337000"],["77733.25000000","0.00000000"],["77733.94000000","0.00400000"],["77760.40000000","0.00000000"],["77761.45000000","0.00000000"],["77762.94000000","0.00000000"]]}}
{"type":"trade","received_at_ms":1788333178478,"data":{"e":"trade","E":1788333178644,"s":"BTCUSDT","t":6646665820,"p":"77724.00000000","q":"0.00029000","T":1788333178644,"m":false,"M":true}}
{"type":"depth","received_at_ms":1788333178547,"data":{"e":"depthUpdate","E":1788333178714,"s":"BTCUSDT","U":99556326512,"u":99556326570,"b":[["77723.99000000","2.20254000"],["77723.98000000","0.00090000"],["77723.83000000","0.00000000"],["77722.63000000","0.37468000"],["77721.96000000","0.00000000"],["77721.95000000","0.00021000"],["77721.90000000","0.05000000"],["77721.85000000","0.05000000"],["77721.11000000","0.00007000"],["77719.41000000","0.00000000"],["77710.48000000","0.00000000"],["77708.68000000","0.02000000"],["77669.76000000","0.02000000"],["77649.53000000","0.02000000"],["76558.13000000","0.00030000"],["69951.60000000","0.00464000"],["69951.59000000","0.00000000"],["69951.00000000","0.00088000"]],"a":[["77724.00000000","1.07301000"],["77726.25000000","0.00014000"],["77726.26000000","0.14849000"],["77726.75000000","0.00000000"],["77728.85000000","0.00000000"],["77733.33000000","0.00251000"],["77737.73000000","0.02800000"],["77738.95000000","0.00257000"],["77739.37000000","0.00000000"],["77748.08000000","0.00200000"],["77748.27000000","0.00000000"],["77757.07000000","0.03861000"],["77757.18000000","0.02800000"],["77757.36000000","0.32945000"],["77776.64000000","0.02800000"],["77789.98000000","0.00411000"],["78889.86000000","0.00030000"]]}}
{"type":"depth","received_at_ms":1788333178649,"data":{"e":"depthUpdate","E":1788333178815,"s":"BTCUSDT","U":99556326571,"u":99556326611,"b":[["77723.99000000","2.20254000"],["77723.98000000","0.00090000"],["77722.63000000","0.37468000"],["77721.95000000","0.00007000"],["77721.90000000","0.05021000"],["77721.86000000","0.00014000"],["77721.11000000","0.00000000"],["77719.41000000","0.00000000"],["77710.48000000","0.00200000"],["77540.56000000","0.00000000"],["69951.60000000","0.00448000"],["69951.00000000","0.00068000"],["62179.19000000","0.00000000"]],"a":[["77724.00000000","1.07308000"],["77724.01000000","0.00083000"],["77726.00000000","0.03014000"],["77726.26000000","0.14863000"],["77729.61000000","0.08205000"],["77733.79000000","0.00200000"],["77738.95000000","0.00000000"],["77738.96000000","0.00257000"]]}}
{"type":"depth","received_at_ms":1788333178748,"data":{"e":"depthUpdate","E":1788333178914,"s":"BTCUSDT","U":99556326612,"u":99556326636,"b":[["77723.99000000","2.20247000"],["77723.98000000","0.00090000"],["77722.63000000","0.37475000"],["77722.21000000","0.00014000"],["77722.20000000","0.05000000"],["77721.91000000","0.00000000"],["77721.90000000","0.00014000"],["77721.86000000","0.00000000"],["77721.85000000","0.00000000"],["77721.26000000","0.00014000"],["77721.11000000","0.00007000"],["77534.46000000","0.02016000"],["77503.75000000","0.00000000"],["69951.60000000","0.00464000"]],"a":[["77738.96000000","0.00000000"]]}}
{"type":"trade","received_at_ms":1788333178781,"data":{"e":"trade","E":1788333178945,"s":"BTCUSDT","t":6646665821,"p":"77724.00000000","q":"0.01500000","T":1788333178945,"m":false,"M":true}}
{"type":"trade","received_at_ms":1788333178824,"data":{"e":"trade","E":1788333178990,"s":"BTCUSDT","t":6646665822,"p":"77723.99000000","q":"0.00007000","T":1788333178989,"m":true,"M":true}}
{"type":"trade","received_at_ms":1788333178838,"data":{"e":"trade","E":1788333179003,"s":"BTCUSDT","t":6646665823,"p":"77724.00000000","q":"0.00200000","T":1788333179002,"m":false,"M":true}}
{"type":"trade","received_at_ms":1788333178838,"data":{"e":"trade","E":1788333179003,"s":"BTCUSDT","t":6646665824,"p":"77724.00000000","q":"0.00200000","T":1788333179002,"m":false,"M":true}}
{"type":"trade","received_at_ms":1788333178838,"data":{"e":"trade","E":1788333179003,"s":"BTCUSDT","t":6646665825,"p":"77724.00000000","q":"0.00200000","T":1788333179003,"m":false,"M":true}}
{"type":"trade","received_at_ms":1788333178838,"data":{"e":"trade","E":1788333179003,"s":"BTCUSDT","t":6646665826,"p":"77724.00000000","q":"0.00200000","T":1788333179003,"m":false,"M":true}}
{"type":"trade","received_at_ms":1788333178838,"data":{"e":"trade","E":1788333179003,"s":"BTCUSDT","t":6646665827,"p":"77724.00000000","q":"0.00200000","T":1788333179003,"m":false,"M":true}}
{"type":"trade","received_at_ms":1788333178838,"data":{"e":"trade","E":1788333179003,"s":"BTCUSDT","t":6646665828,"p":"77724.00000000","q":"0.00200000","T":1788333179003,"m":false,"M":true}}
{"type":"trade","received_at_ms":1788333178838,"data":{"e":"trade","E":1788333179004,"s":"BTCUSDT","t":6646665829,"p":"77724.00000000","q":"0.00200000","T":1788333179003,"m":false,"M":true}}
{"type":"trade","received_at_ms":1788333178838,"data":{"e":"trade","E":1788333179004,"s":"BTCUSDT","t":6646665830,"p":"77724.00000000","q":"0.00200000","T":1788333179003,"m":false,"M":true}}
{"type":"trade","received_at_ms":1788333178838,"data":{"e":"trade","E":1788333179004,"s":"BTCUSDT","t":6646665831,"p":"77724.00000000","q":"0.00200000","T":1788333179003,"m":false,"M":true}}
{"type":"trade","received_at_ms":1788333178838,"data":{"e":"trade","E":1788333179004,"s":"BTCUSDT","t":6646665832,"p":"77724.00000000","q":"0.00200000","T":1788333179004,"m":false,"M":true}}
{"type":"trade","received_at_ms":1788333178839,"data":{"e":"trade","E":1788333179005,"s":"BTCUSDT","t":6646665833,"p":"77724.00000000","q":"0.00200000","T":1788333179005,"m":false,"M":true}}
{"type":"trade","received_at_ms":1788333178839,"data":{"e":"trade","E":1788333179005,"s":"BTCUSDT","t":6646665834,"p":"77724.00000000","q":"0.00200000","T":1788333179005,"m":false,"M":true}}
{"type":"trade","received_at_ms":1788333178839,"data":{"e":"trade","E":1788333179005,"s":"BTCUSDT","t":6646665835,"p":"77724.00000000","q":"0.00284000","T":1788333179005,"m":false,"M":true}}
{"type":"trade","received_at_ms":1788333178839,"data":{"e":"trade","E":1788333179006,"s":"BTCUSDT","t":6646665836,"p":"77724.00000000","q":"0.00200000","T":1788333179005,"m":false,"M":true}}
{"type":"depth","received_at_ms":1788333178848,"data":{"e":"depthUpdate","E":1788333179014,"s":"BTCUSDT","U":99556326637,"u":99556326834,"b":[["77723.99000000","2.67242000"],["77723.98000000","0.00041000"],["77722.81000000","0.00000000"],["77722.71000000","0.00000000"],["77722.64000000","0.47511000"],["77722.63000000","0.37468000"],["77722.35000000","0.00000000"],["77722.21000000","0.00000000"],["77722.20000000","0.00014000"],["77722.00000000","0.00257000"],["77721.95000000","0.00000000"],["77721.90000000","0.00000000"],["77721.51000000","0.00000000"],["77721.26000000","0.00000000"],["77721.11000000","0.11191000"],["77720.87000000","0.04105000"],["77719.83000000","0.00118000"],["77719.62000000","0.00000000"],["77719.41000000","0.00000000"],["77717.26000000","0.00000000"],["77717.21000000","0.01000000"],["77716.91000000","0.02000000"],["77714.75000000","0.26543000"],["77710.48000000","0.00000000"],["77708.51000000","0.08000000"],["77707.84000000","0.34762000"],["77706.67000000","0.34762000"],["77706.38000000","0.64375000"],["77694.51000000","1.27482000"],["77694.15000000","0.00000000"],["77693.80000000","0.00335000"],["77690.27000000","0.00000000"],["77690.14000000","1.31471000"],["77684.99000000","0.00000000"],["77684.61000000","0.02057000"],["77682.67000000","0.00000000"],["77657.52000000","0.00000000"],["77626.60000000","0.00000000"],["69951.60000000","0.00457000"],["62179.20000000","0.00032000"]],"a":[["77724.00000000","0.68246000"],["77726.26000000","0.00014000"],["77728.11000000","0.00014000"],["77728.32000000","0.00007000"],["77728.56000000","0.00000000"],["77729.47000000","0.00014000"],["77729.48000000","0.00014000"],["77729.61000000","0.00000000"],["77730.72000000","0.00000000"],["77730.73000000","0.00000000"],["77730.85000000","0.00000000"],["77731.35000000","0.00000000"],["77731.36000000","0.00010000"],["77731.78000000","0.00000000"],["77731.92000000","0.00008000"],["77732.66000000","0.04000000"],["77732.74000000","0.00643000"],["77733.67000000","0.00000000"],["77733.79000000","0.00000000"],["77733.94000000","0.00000000"],["77734.19000000","0.00000000"],["77734.37000000","0.11000000"],["77736.03000000","0.00000000"],["77736.04000000","0.01278000"],["77736.56000000","0.00000000"],["77736.63000000","0.93619000"],["77736.64000000","0.00000000"],["77738.11000000","1.31471000"],["77738.12000000","0.00000000"],["77738.14000000","0.02200000"],["77738.97000000","0.00000000"],["77739.27000000","0.02000000"],["77741.36000000","1.93226000"],["77741.39000000","0.00000000"],["77741.44000000","0.00000000"],["77742.04000000","0.00000000"],["77743.99000000","0.00000000"],["77746.95000000","0.00000000"],["77748.08000000","0.00000000"],["77749.98000000","0.25744000"],["77750.65000000","0.00000000"],["77752.43000000","0.00000000"],["77753.30000000","0.00000000"],["77753.65000000","0.00000000"],["77753.70000000","0.01983000"],["77754.82000000","0.09532000"],["77755.39000000","0.00000000"],["77755.89000000","0.00000000"],["77756.08000000","0.00000000"],["77756.96000000","0.00000000"],["77757.07000000","0.00000000"],["77757.36000000","0.05405000"],["77768.26000000","0.00007000"],["77769.37000000","0.64323000"],["77771.52000000","0.34733000"],["77779.98000000","0.34729000"],["77799.46000000","1.27310000"],["77816.43000000","0.00000000"],["77819.13000000","0.00000000"],["77821.72000000","2.15325000"],["77844.61000000","0.00000000"],["78018.05000000","0.16870000"]]}}
{"type":"trade","received_at_ms":1788333178852,"data":{"e":"trade","E":1788333179017,"s":"BTCUSDT","t":6646665837,"p":"77724.00000000","q":"0.00009000","T":1788333179016,"m":false,"M":true}}
{"type":"depth","received_at_ms":1788333178949,"data":{"e":"depthUpdate","E":1788333179114,"s":"BTCUSDT","U":99556326835,"u":99556327053,"b":[["77723.99000000","2.70911000"],["77723.98000000","0.00034000"],["77723.55000000","0.00000000"],["77722.74000000","0.01800000"],["77722.65000000","0.00014000"],["77722.64000000","0.47525000"],["77722.63000000","0.37461000"],["77722.20000000","0.00000000"],["77721.26000000","0.00643000"],["77721.25000000","0.00028000"],["77721.11000000","0.00028000"],["77720.87000000","0.04091000"],["77720.72000000","0.00151000"],["77719.41000000","0.00200000"],["77719.34000000","0.35393000"],["77716.51000000","0.00643000"],["77715.85000000","0.02000000"],["77712.74000000","0.00000000"],["77708.96000000","0.00411000"],["77708.41000000","1.62403000"],["77707.55000000","0.00000000"],["77704.00000000","0.00007000"],["77703.71000000","0.00000000"],["77700.96000000","0.00200000"],["77685.80000000","0.00000000"],["77685.06000000","0.00000000"],["77677.09000000","1.29768000"],["77670.99000000","0.00000000"],["77670.98000000","0.00000000"],["77658.09000000","0.14299000"],["77651.16000000","0.00528000"],["77650.64000000","0.01721000"],["77634.21000000","0.00000000"],["77634.05000000","0.00000000"],["77548.18000000","4.51260000"],["77534.46000000","0.00000000"],["77526.01000000","0.00000000"],["77524.01000000","0.00811000"],["77511.73000000","0.02016000"],["69951.60000000","0.00473000"]],"a":[["77724.00000000","0.68112000"],["77724.01000000","0.00076000"],["77726.00000000","0.03014000"],["77726.25000000","0.00000000"],["77726.26000000","0.00000000"],["77726.75000000","0.00014000"],["77728.00000000","0.03021000"],["77728.10000000","0.00000000"],["77728.11000000","0.00000000"],["77728.99000000","0.00614000"],["77729.46000000","0.00000000"],["77729.47000000","0.00014000"],["77729.48000000","0.11191000"],["77729.99000000","0.00014000"],["77730.00000000","0.03064000"],["77730.21000000","0.00000000"],["77730.22000000","0.02908000"],["77730.85000000","0.11191000"],["77730.90000000","0.00000000"],["77731.78000000","0.16870000"],["77731.93000000","0.11191000"],["77731.99000000","0.18858000"],["77732.26000000","0.00014000"],["77732.74000000","0.00000000"],["77733.07000000","0.00069000"],["77733.59000000","0.11191000"],["77733.69000000","0.00048000"],["77733.80000000","0.00000000"],["77733.86000000","0.11191000"],["77734.57000000","0.00000000"],["77734.79000000","0.00643000"],["77735.79000000","0.00000000"],["77736.20000000","0.00014000"],["77736.33000000","0.11191000"],["77736.37000000","0.00400000"],["77736.61000000","0.11191000"],["77736.62000000","0.01000000"],["77736.63000000","0.50954000"],["77736.93000000","0.00000000"],["77737.69000000","0.00000000"],["77737.70000000","0.00000000"],["77737.99000000","0.00643000"],["77738.10000000","0.11191000"],["77738.14000000","0.00000000"],["77738.47000000","0.00007000"],["77738.48000000","0.00000000"],["77738.49000000","0.00000000"],["77739.78000000","0.00000000"],["77741.37000000","0.00000000"],["77741.90000000","0.14162000"],["77744.97000000","0.00257000"],["77745.12000000","0.00000000"],["77745.60000000","0.28759000"],["77746.20000000","0.00000000"],["77746.22000000","0.09660000"],["77747.15000000","0.00000000"],["77747.94000000","0.00000000"],["77753.27000000","1.29641000"],["77755.79000000","0.34535000"],["77755.89000000","0.00200000"],["77762.23000000","0.00000000"],["77766.00000000","0.03400000"],["77767.72000000","0.00007000"],["77768.25000000","0.25624000"],["77770.19000000","0.03861000"],["77770.37000000","0.32946000"],["77771.66000000","0.00000000"],["78116.37000000","0.00000000"],["78215.25000000","0.20733000"]]}}
{"type":"trade","received_at_ms":1788333179018,"data":{"e":"trade","E":1788333179184,"s":"BTCUSDT","t":6646665838,"p":"77723.99000000","q":"0.00009000","T":1788333179184,"m":true,"M":true}}
{"type":"depth","received_at_ms":1788333179048,"data":{"e":"depthUpdate","E":1788333179214,"s":"BTCUSDT","U":99556327054,"u":99556327176,"b":[["77723.99000000","2.71187000"],["77723.98000000","0.00062000"],["77722.00000000","0.00000000"],["77721.32000000","0.01342000"],["77721.26000000","0.00657000"],["77721.25000000","0.00014000"],["77721.11000000","0.00014000"],["77720.87000000","0.04105000"],["77719.41000000","0.00207000"],["77696.21000000","1.49207000"],["77460.66000000","0.11435000"],["77407.74000000","0.00000000"],["69951.60000000","0.00441000"],["62179.20000000","0.00000000"],["62179.19000000","0.00000000"],["62179.00000000","0.00200000"]],"a":[["77724.00000000","0.87291000"],["77725.54000000","0.12386000"],["77728.10000000","0.00014000"],["77728.11000000","0.10086000"],["77728.68000000","0.00027000"],["77728.99000000","0.00614000"],["77729.47000000","0.00014000"],["77729.48000000","0.11205000"],["77729.99000000","0.00000000"],["77730.28000000","0.00814000"],["77731.93000000","0.41250000"],["77731.99000000","0.00000000"],["77735.21000000","0.08205000"],["77736.61000000","1.18042000"],["77736.62000000","1.93626000"],["77736.63000000","0.00000000"],["77738.09000000","0.00000000"],["77738.10000000","0.00000000"],["77740.67000000","0.00600000"],["77744.11000000","0.00257000"],["77744.97000000","0.00000000"],["77747.16000000","0.00000000"],["77749.76000000","0.00128000"],["77753.70000000","0.00000000"],["77754.06000000","0.01988000"],["77754.82000000","0.00000000"],["77757.36000000","0.00000000"],["77763.44000000","0.00000000"],["77764.18000000","0.12871000"],["77764.28000000","0.00000000"],["77942.42000000","0.00000000"]]}}
{"type":"trade","received_at_ms":1788333179147,"data":{"e":"trade","E":1788333179310,"s":"BTCUSDT","t":6646665839,"p":"77724.00000000","q":"0.00718000","T":1788333179310,"m":false,"M":true}}
{"type":"trade","received_at_ms":1788333179154,"data":{"e":"trade","E":1788333179314,"s":"BTCUSDT","t":6646665840,"p":"77724.00000000","q":"0.00454000","T":1788333179313,"m":false,"M":true}}
{"type":"depth","received_at_ms":1788333179154,"data":{"e":"depthUpdate","E":1788333179314,"s":"BTCUSDT","U":99556327177,"u":99556327230,"b":[["77723.99000000","2.71173000"],["77723.98000000","0.00048000"],["77722.63000000","0.37468000"],["77722.21000000","0.00014000"],["77722.20000000","0.05000000"],["77721.90000000","0.00000000"],["77719.41000000","0.00200000"],["69951.60000000","0.00464000"],["69951.59000000","0.00009000"]],"a":[["77724.00000000","0.86141000"],["77724.01000000","0.00083000"],["77725.53000000","0.00014000"],["77725.54000000","0.00014000"],["77726.75000000","0.00000000"],["77728.00000000","0.03021000"],["77728.11000000","0.10100000"],["77729.46000000","0.00007000"],["77729.47000000","0.14316000"],["77730.22000000","0.02894000"],["77730.28000000","0.00800000"],["77736.60000000","0.00600000"],["77740.67000000","0.00000000"],["77744.11000000","0.00000000"],["77744.18000000","0.00000000"],["77744.25000000","0.00284000"],["77764.18000000","0.00000000"],["77996.36000000","0.02364000"]]}}
{"type":"trade","received_at_ms":1788333179154,"data":{"e":"trade","E":1788333179316,"s":"BTCUSDT","t":6646665841,"p":"77724.00000000","q":"0.01287000","T":1788333179315,"m":false,"M":true}}
{"type":"trade","received_at_ms":1788333179237,"data":{"e":"trade","E":1788333179402,"s":"BTCUSDT","t":6646665842,"p":"77724.00000000","q":"0.00200000","T":1788333179402,"m":false,"M":true}}
{"type":"trade","received_at_ms":1788333179237,"data":{"e":"trade","E":1788333179402,"s":"BTCUSDT","t":6646665843,"p":"77724.00000000","q":"0.00200000","T":1788333179402,"m":false,"M":true}}
{"type":"trade","received_at_ms":1788333179237,"data":{"e":"trade","E":1788333179402,"s":"BTCUSDT","t":6646665844,"p":"77724.00000000","q":"0.00200000","T":1788333179402,"m":false,"M":true}}
{"type":"trade","received_at_ms":1788333179237,"data":{"e":"trade","E":1788333179403,"s":"BTCUSDT","t":6646665845,"p":"77724.00000000","q":"0.00200000","T":1788333179402,"m":false,"M":true}}
{"type":"trade","received_at_ms":1788333179237,"data":{"e":"trade","E":1788333179403,"s":"BTCUSDT","t":6646665846,"p":"77724.00000000","q":"0.00200000","T":1788333179402,"m":false,"M":true}}
{"type":"trade","received_at_ms":1788333179237,"data":{"e":"trade","E":1788333179403,"s":"BTCUSDT","t":6646665847,"p":"77724.00000000","q":"0.00200000","T":1788333179402,"m":false,"M":true}}
{"type":"trade","received_at_ms":1788333179238,"data":{"e":"trade","E":1788333179403,"s":"BTCUSDT","t":6646665848,"p":"77724.00000000","q":"0.00200000","T":1788333179403,"m":false,"M":true}}
{"type":"trade","received_at_ms":1788333179238,"data":{"e":"trade","E":1788333179403,"s":"BTCUSDT","t":6646665849,"p":"77724.00000000","q":"0.00200000","T":1788333179403,"m":false,"M":true}}
{"type":"trade","received_at_ms":1788333179238,"data":{"e":"trade","E":1788333179403,"s":"BTCUSDT","t":6646665850,"p":"77724.00000000","q":"0.00200000","T":1788333179403,"m":false,"M":true}}
{"type":"trade","received_at_ms":1788333179238,"data":{"e":"trade","E":1788333179403,"s":"BTCUSDT","t":6646665851,"p":"77724.00000000","q":"0.00200000","T":1788333179403,"m":false,"M":true}}
{"type":"trade","received_at_ms":1788333179238,"data":{"e":"trade","E":1788333179403,"s":"BTCUSDT","t":6646665852,"p":"77724.00000000","q":"0.00200000","T":1788333179403,"m":false,"M":true}}
{"type":"trade","received_at_ms":1788333179238,"data":{"e":"trade","E":1788333179403,"s":"BTCUSDT","t":6646665853,"p":"77724.00000000","q":"0.00200000","T":1788333179403,"m":false,"M":true}}
{"type":"trade","received_at_ms":1788333179238,"data":{"e":"trade","E":1788333179403,"s":"BTCUSDT","t":6646665854,"p":"77724.00000000","q":"0.00200000","T":1788333179403,"m":false,"M":true}}
{"type":"trade","received_at_ms":1788333179238,"data":{"e":"trade","E":1788333179403,"s":"BTCUSDT","t":6646665855,"p":"77724.00000000","q":"0.00200000","T":1788333179403,"m":false,"M":true}}
{"type":"trade","received_at_ms":1788333179238,"data":{"e":"trade","E":1788333179404,"s":"BTCUSDT","t":6646665856,"p":"77724.00000000","q":"0.00200000","T":1788333179403,"m":false,"M":true}}
{"type":"trade","received_at_ms":1788333179239,"data":{"e":"trade","E":1788333179405,"s":"BTCUSDT","t":6646665857,"p":"77724.00000000","q":"0.00200000","T":1788333179404,"m":false,"M":true}}
{"type":"trade","received_at_ms":1788333179239,"data":{"e":"trade","E":1788333179405,"s":"BTCUSDT","t":6646665858,"p":"77724.00000000","q":"0.00200000","T":1788333179405,"m":false,"M":true}}
{"type":"trade","received_at_ms":1788333179239,"data":{"e":"trade","E":1788333179405,"s":"BTCUSDT","t":6646665859,"p":"77724.00000000","q":"0.00200000","T":1788333179405,"m":false,"M":true}}
{"type":"depth","received_at_ms":1788333179247,"data":{"e":"depthUpdate","E":1788333179414,"s":"BTCUSDT","U":99556327231,"u":99556327346,"b":[["77723.99000000","2.70152000"],["77723.98000000","0.00027000"],["77723.96000000","0.00014000"],["77723.95000000","0.05000000"],["77722.63000000","0.37461000"],["77722.21000000","0.00000000"],["77722.20000000","0.00000000"],["77721.41000000","0.00117000"],["77720.87000000","0.04091000"],["77712.48000000","0.00000000"],["77709.00000000","0.01300000"],["77691.85000000","0.00000000"],["75569.87000000","0.00429000"],["69951.60000000","0.00448000"]],"a":[["77724.00000000","0.62074000"],["77724.01000000","0.00076000"],["77725.53000000","0.00000000"],["77725.54000000","0.00000000"],["77726.75000000","0.00014000"],["77728.99000000","0.00614000"],["77729.46000000","0.00000000"],["77729.47000000","0.00021000"],["77735.12000000","0.00400000"],["77735.18000000","0.00000000"],["77735.20000000","0.00206000"],["77735.42000000","0.00000000"],["77735.63000000","0.00000000"],["77735.82000000","0.00000000"],["77736.37000000","0.00000000"],["77736.60000000","0.00600000"],["77736.62000000","0.00400000"],["77744.15000000","0.00000000"],["77744.25000000","0.00027000"],["77754.06000000","0.00000000"],["77755.89000000","0.10054000"],["77758.51000000","0.05319000"]]}}
{"type":"depth","received_at_ms":1788333179348,"data":{"e":"depthUpdate","E":1788333179514,"s":"BTCUSDT","U":99556327347,"u":99556327434,"b":[["77723.99000000","2.71235000"],["77723.98000000","0.00076000"],["77723.95000000","0.05014000"],["77722.63000000","0.37447000"],["77710.25000000","0.02000000"],["77708.96000000","0.00000000"],["77705.37000000","0.00000000"],["77687.53000000","0.02568000"],["77683.12000000","0.00000000"],["77639.00000000","0.00000000"],["77394.54000000","0.00000000"],["69951.60000000","0.00448000"],["62179.20000000","0.00032000"]],"a":[["77724.00000000","0.81254000"],["77728.99000000","0.00614000"],["77729.47000000","0.00007000"],["77730.22000000","0.02908000"],["77735.12000000","0.00000000"],["77735.52000000","0.00400000"],["77735.53000000","0.00000000"],["77735.54000000","0.00000000"],["77736.47000000","0.00000000"],["77736.59000000","1.03630000"],["77736.60000000","1.93626000"],["77736.61000000","0.00000000"],["77740.46000000","0.00000000"],["77740.67000000","0.00200000"],["77744.14000000","0.00257000"],["77760.86000000","0.00000000"],["77789.98000000","0.00000000"],["77821.08000000","0.00411000"]]}}
{"type":"depth","received_at_ms":1788333179448,"data":{"e":"depthUpdate","E":1788333179614,"s":"BTCUSDT","U":99556327435,"u":99556327476,"b":[["77723.99000000","2.71249000"],["77723.98000000","0.00083000"],["77723.95000000","0.05021000"],["77723.91000000","0.00014000"],["77723.90000000","0.05000000"],["77722.64000000","0.37366000"],["77721.25000000","0.00007000"],["77721.11000000","0.00000000"],["77705.37000000","0.00007000"],["77704.32000000","0.22820000"],["77701.51000000","0.00000000"],["77693.08000000","0.00000000"],["77636.50000000","0.00000000"],["77405.00000000","0.00028000"],["69951.60000000","0.00448000"],["62179.20000000","0.00000000"],["62179.00000000","0.00200000"]],"a":[["77724.00000000","0.81261000"],["77724.01000000","0.00083000"],["77727.65000000","0.00014000"],["77727.66000000","0.12288000"],["77729.47000000","0.00000000"],["77736.47000000","0.00007000"],["77736.58000000","0.00200000"],["77740.67000000","0.00000000"],["77744.14000000","0.00000000"],["77744.17000000","0.00257000"],["77764.66000000","0.00000000"],["77764.84000000","0.12871000"]]}}
{"type":"depth","received_at_ms":1788333179552,"data":{"e":"depthUpdate","E":1788333179714,"s":"BTCUSDT","U":99556327477,"u":99556327526,"b":[["77723.95000000","0.05021000"],["77723.90000000","0.05014000"],["77721.10000000","1.00000000"],["77712.00000000","0.70265000"],["77710.33000000","0.02000000"],["77710.22000000","0.02000000"],["77710.00000000","0.00000000"],["77702.55000000","0.00000000"],["77702.41000000","0.00000000"],["77702.31000000","0.00000000"],["77650.31000000","0.02000000"],["76558.13000000","0.00000000"],["69951.60000000","0.00448000"]],"a":[["77726.76000000","0.01281000"],["77727.66000000","0.12302000"],["77730.22000000","0.02894000"],["77743.46000000","0.02400000"],["77744.17000000","0.00000000"],["77744.18000000","0.00257000"],["77744.23000000","0.03000000"],["77746.56000000","0.03000000"],["77747.34000000","0.02800000"],["77747.35000000","0.02600000"],["77748.12000000","0.04600000"],["77748.20000000","0.03000000"],["77759.91000000","0.00000000"],["77790.63000000","0.00411000"],["77798.82000000","0.03000000"],["77799.59000000","0.02400000"],["77800.37000000","0.03000000"],["77803.47000000","0.02800000"],["77803.48000000","0.02600000"],["77804.25000000","0.02200000"],["77804.26000000","0.02400000"],["77804.31000000","0.03000000"],["78889.86000000","0.00000000"]]}}
{"type":"depth","received_at_ms":1788333179661,"data":{"e":"depthUpdate","E":1788333179814,"s":"BTCUSDT","U":99556327527,"u":99556327554,"b":[["77723.99000000","2.71208000"],["77723.98000000","0.00076000"],["76558.13000000","0.00030000"],["69951.60000000","0.00448000"],["62179.19000000","0.00000000"]],"a":[["77724.00000000","0.62081000"],["77727.66000000","0.00014000"],["77742.83000000","0.00000000"],["77742.85000000","0.00257000"],["77744.18000000","0.00000000"],["77747.79000000","0.19070000"],["77764.15000000","0.00000000"],["77764.84000000","0.00000000"],["77800.09000000","0.02200000"],["77804.25000000","0.00000000"],["77804.26000000","0.00000000"],["78889.86000000","0.00030000"]]}}
{"type":"depth","received_at_ms":1788333179751,"data":{"e":"depthUpdate","E":1788333179914,"s":"BTCUSDT","U":99556327555,"u":99556327591,"b":[["77723.99000000","2.41250000"],["77709.62000000","0.00411000"],["77704.79000000","0.50603000"],["77681.48000000","1.00231000"],["69951.60000000","0.00448000"],["69951.00000000","0.00088000"]],"a":[["77724.00000000","0.81254000"],["77724.01000000","0.00076000"],["77726.76000000","0.01281000"],["77727.65000000","0.00000000"],["77727.66000000","0.00000000"],["77729.47000000","0.14312000"],["77730.22000000","0.02908000"],["77736.58000000","0.11391000"],["77736.59000000","0.89321000"],["77742.85000000","0.00000000"],["77751.23000000","0.38602000"],["77754.86000000","0.01964000"],["77759.72000000","0.00000000"],["77765.26000000","0.02553000"]]}}
{"type":"trade","received_at_ms":1788333179824,"data":{"e":"trade","E":1788333179989,"s":"BTCUSDT","t":6646665860,"p":"77723.99000000","q":"0.01500000","T":1788333179989,"m":true,"M":true}}
{"type":"trade","received_at_ms":1788333179829,"data":{"e":"trade","E":1788333179995,"s":"BTCUSDT","t":6646665861,"p":"77724.00000000","q":"0.02548000","T":1788333179995,"m":false,"M":true}}
{"type":"depth","received_at_ms":1788333179848,"data":{"e":"depthUpdate","E":1788333180014,"s":"BTCUSDT","U":99556327592,"u":99556327644,"b":[["77723.99000000","2.39451000"],["77723.40000000","0.00257000"],["77723.11000000","0.00000000"],["77722.63000000","0.37461000"],["77719.41000000","0.62947000"],["77703.36000000","0.44148000"],["77694.49000000","0.00000000"],["69951.60000000","0.00448000"],["69951.59000000","0.00000000"],["69951.00000000","0.00068000"],["62179.20000000","0.00032000"]],"a":[["77724.00000000","0.59512000"],["77728.99000000","0.00614000"],["77729.46000000","0.00000000"],["77729.47000000","0.00021000"],["77730.22000000","0.02894000"],["77736.57000000","0.00200000"],["77736.58000000","0.11191000"],["77742.84000000","0.00257000"],["77744.52000000","0.09622000"],["77746.22000000","0.00000000"],["77746.23000000","0.00200000"],["77749.04000000","0.00000000"],["77749.74000000","0.00038000"],["77749.97000000","0.64359000"],["77749.98000000","0.25743000"],["77761.18000000","0.00000000"],["77799.59000000","0.00000000"],["77804.31000000","0.00000000"],["86422.88000000","0.20801000"]]}}
{"type":"trade","received_at_ms":1788333179870,"data":{"e":"trade","E":1788333180037,"s":"BTCUSDT","t":6646665862,"p":"77723.99000000","q":"0.00632000","T":1788333180036,"m":true,"M":true}}
{"type":"depth","received_at_ms":1788333179948,"data":{"e":"depthUpdate","E":1788333180114,"s":"BTCUSDT","U":99556327645,"u":99556327687,"b":[["77723.99000000","2.38861000"],["77723.98000000","0.00083000"],["77719.42000000","0.00600000"],["77719.41000000","0.62747000"],["69951.60000000","0.00432000"],["69951.00000000","0.00068000"]],"a":[["77724.00000000","0.59519000"],["77728.08000000","0.00014000"],["77728.09000000","0.13985000"],["77728.99000000","0.00614000"],["77729.47000000","0.00000000"],["77730.22000000","0.02908000"],["77742.84000000","0.00000000"],["77749.96000000","1.01556000"],["77749.99000000","0.00000000"],["77764.45000000","0.00000000"],["77764.93000000","0.00000000"],["77800.37000000","0.00000000"],["77803.48000000","0.00000000"],["86422.88000000","0.22692000"]]}}
{"type":"depth","received_at_ms":1788333180047,"data":{"e":"depthUpdate","E":1788333180214,"s":"BTCUSDT","U":99556327688,"u":99556327702,"b":[["77528.01000000","0.00811000"],["77524.01000000","0.00000000"],["69951.60000000","0.00448000"],["62179.20000000","0.00000000"],["62179.19000000","0.00000000"]],"a":[["77728.00000000","0.03021000"],["77728.09000000","0.13999000"],["77730.22000000","0.02894000"],["77742.85000000","0.00257000"],["77803.47000000","0.00000000"]]}}
{"type":"depth","received_at_ms":1788333180147,"data":{"e":"depthUpdate","E":1788333180314,"s":"BTCUSDT","U":99556327703,"u":99556327731,"b":[["77723.99000000","2.38868000"],["77723.98000000","0.00090000"],["77722.99000000","0.00400000"],["77704.32000000","0.32231000"],["77672.90000000","0.02852000"],["69951.60000000","0.00432000"],["62179.00000000","0.00200000"]],"a":[["77724.00000000","0.78698000"],["77724.01000000","0.00083000"],["77727.08000000","0.00014000"],["77727.09000000","0.10539000"],["77728.08000000","0.00000000"],["77728.09000000","0.00014000"],["77729.47000000","0.14301000"],["77733.88000000","0.00400000"],["77752.14000000","0.73829000"],["84202.54000000","0.01768000"]]}}
{"type":"depth","received_at_ms":1788333180247,"data":{"e":"depthUpdate","E":1788333180414,"s":"BTCUSDT","U":99556327732,"u":99556327771,"b":[["77723.99000000","2.38833000"],["77719.42000000","0.01400000"],["69951.60000000","0.00448000"],["62179.00000000","0.00200000"]],"a":[["77726.76000000","0.01281000"],["77727.09000000","0.10553000"],["77728.00000000","0.03021000"],["77728.09000000","0.00000000"],["77728.99000000","0.00614000"],["77729.47000000","0.00014000"],["77730.00000000","0.03050000"],["77736.57000000","0.01000000"],["77749.96000000","0.87247000"],["77764.58000000","0.00000000"],["77764.67000000","0.00000000"]]}}
{"type":"trade","received_at_ms":1788333180341,"data":{"e":"trade","E":1788333180508,"s":"BTCUSDT","t":6646665863,"p":"77723.99000000","q":"0.00027000","T":1788333180508,"m":true,"M":true}}
{"type":"depth","received_at_ms":1788333180347,"data":{"e":"depthUpdate","E":1788333180514,"s":"BTCUSDT","U":99556327772,"u":99556327802,"b":[["77723.99000000","2.38600000"],["77719.43000000","0.00200000"],["77719.42000000","0.01200000"],["77714.62000000","0.10937000"],["77690.74000000","0.02000000"],["77636.50000000","0.02000000"],["69951.60000000","0.00432000"],["69951.59000000","0.00009000"],["69951.00000000","0.00078000"],["62179.20000000","0.00032000"]],"a":[["77724.00000000","0.78691000"],["77728.99000000","0.00614000"],["77729.47000000","0.00000000"],["77730.00000000","0.03064000"],["77732.26000000","0.00007000"],["77735.20000000","0.00000000"],["77735.21000000","0.00000000"],["77736.56000000","0.00200000"],["77736.57000000","0.00800000"],["77764.58000000","0.00000000"],["77764.94000000","0.12871000"]]}}
{"type":"depth","received_at_ms":1788333180447,"data":{"e":"depthUpdate","E":1788333180614,"s":"BTCUSDT","U":99556327803,"u":99556327828,"b":[["77705.37000000","0.00007000"],["77636.50000000","0.00000000"],["69951.60000000","0.00448000"],["69951.00000000","0.00068000"],["62179.20000000","0.00000000"],["62179.00000000","0.00200000"]],"a":[["77724.00000000","0.79089000"],["77732.26000000","0.00014000"],["77736.47000000","0.00007000"],["77764.94000000","0.00000000"]]}}
{"type":"depth","received_at_ms":1788333180548,"data":{"e":"depthUpdate","E":1788333180714,"s":"BTCUSDT","U":99556327829,"u":99556327832,"b":[["69951.60000000","0.00432000"]],"a":[["77736.56000000","0.00600000"]]}}
{"type":"depth","received_at_ms":1788333180648,"data":{"e":"depthUpdate","E":1788333180814,"s":"BTCUSDT","U":99556327833,"u":99556327848,"b":[["77723.99000000","2.38572000"],["77723.98000000","0.00062000"],["76558.13000000","0.00030000"],["69951.60000000","0.00432000"],["62179.19000000","0.00000000"]],"a":[["78889.86000000","0.00030000"]]}}
{"type":"depth","received_at_ms":1788333180749,"data":{"e":"depthUpdate","E":1788333180915,"s":"BTCUSDT","U":99556327849,"u":99556327854,"b":[["69951.60000000","0.00432000"],["69951.00000000","0.00078000"]],"a":[["77742.85000000","0.00000000"],["77764.03000000","0.00000000"]]}}
{"type":"depth","received_at_ms":1788333180848,"data":{"e":"depthUpdate","E":1788333181014,"s":"BTCUSDT","U":99556327855,"u":99556327871,"b":[["77723.99000000","2.38572000"],["77723.98000000","0.00062000"],["77723.40000000","0.00000000"],["77723.11000000","0.00257000"],["69951.60000000","0.00432000"],["69951.00000000","0.00068000"],["62179.20000000","0.00032000"],["62179.00000000","0.00200000"]],"a":[["77742.86000000","0.00257000"],["77749.04000000","0.25743000"],["77749.98000000","0.00000000"]]}}
{"type":"depth","received_at_ms":1788333180948,"data":{"e":"depthUpdate","E":1788333181114,"s":"BTCUSDT","U":99556327872,"u":99556327885,"b":[["77723.99000000","2.38572000"],["77723.98000000","0.00062000"],["69951.60000000","0.00416000"],["69951.00000000","0.00068000"]],"a":[["77724.00000000","0.79355000"],["77749.03000000","0.64359000"],["77749.97000000","0.00000000"],["77764.62000000","0.00000000"]]}}
{"type":"trade","received_at_ms":1788333180974,"data":{"e":"trade","E":1788333181139,"s":"BTCUSDT","t":6646665864,"p":"77724.00000000","q":"0.00019000","T":1788333181139,"m":false,"M":true}}
{"type":"depth","received_at_ms":1788333181047,"data":{"e":"depthUpdate","E":1788333181214,"s":"BTCUSDT","U":99556327886,"u":99556327919,"b":[["77723.99000000","2.21417000"],["77723.98000000","0.00076000"],["77719.44000000","0.62748000"],["77719.43000000","0.00200000"],["77719.41000000","0.00000000"],["77710.48000000","0.00000000"],["77703.36000000","0.00000000"],["77700.89000000","0.44150000"],["69951.60000000","0.00432000"],["69951.59000000","0.00000000"],["69951.58000000","0.00009000"],["62179.20000000","0.00000000"],["62179.19000000","0.00000000"]],"a":[["77724.00000000","0.79336000"],["77726.21000000","0.00014000"],["77726.22000000","0.14456000"],["77726.75000000","0.00000000"],["77727.08000000","0.00000000"],["77727.09000000","0.00014000"],["77729.47000000","0.00007000"],["77744.99000000","0.26110000"],["77745.60000000","0.00000000"]]}}
{"type":"depth","received_at_ms":1788333181148,"data":{"e":"depthUpdate","E":1788333181314,"s":"BTCUSDT","U":99556327920,"u":99556327947,"b":[["77723.99000000","2.21410000"],["77719.44000000","0.00000000"],["77710.48000000","0.62748000"],["77709.62000000","0.00000000"],["77682.17000000","0.75094000"],["77653.39000000","1.61347000"],["77646.05000000","0.41353000"],["77645.62000000","0.00000000"],["77639.68000000","0.00411000"],["75557.14000000","0.00000000"],["69951.60000000","0.00432000"]],"a":[["77724.00000000","0.79343000"],["77726.00000000","0.03014000"],["77726.22000000","0.14470000"],["77726.76000000","0.01281000"],["77727.09000000","0.00000000"],["77729.46000000","0.00007000"],["77729.47000000","0.14308000"],["77790.63000000","0.00000000"],["77821.08000000","0.00000000"],["81001.14000000","0.00000000"]]}}
{"type":"depth","received_at_ms":1788333181248,"data":{"e":"depthUpdate","E":1788333181414,"s":"BTCUSDT","U":99556327948,"u":99556327960,"b":[["77685.53000000","0.00000000"],["76030.04000000","0.00000000"],["69951.60000000","0.00416000"]],"a":[["77728.99000000","0.00614000"],["77729.47000000","0.14322000"],["77730.00000000","0.03050000"]]}}
{"type":"depth","received_at_ms":1788333181347,"data":{"e":"depthUpdate","E":1788333181514,"s":"BTCUSDT","U":99556327961,"u":99556327981,"b":[["77723.99000000","2.21017000"],["77723.98000000","0.00076000"],["77723.33000000","0.00400000"],["77722.99000000","0.00000000"],["77722.27000000","0.00400000"],["69951.60000000","0.00448000"],["62179.20000000","0.00032000"],["62179.00000000","0.00400000"]],"a":[["77724.00000000","0.79343000"],["77724.01000000","0.00083000"],["77764.71000000","0.00000000"]]}}
{"type":"depth","received_at_ms":1788333181448,"data":{"e":"depthUpdate","E":1788333181615,"s":"BTCUSDT","U":99556327982,"u":99556328020,"b":[["77723.99000000","2.21024000"],["77723.98000000","0.00076000"],["77723.33000000","0.00000000"],["77723.11000000","0.00000000"],["77722.76000000","0.00257000"],["77722.60000000","0.00400000"],["77705.37000000","0.00007000"],["76546.89000000","0.00032000"],["69951.60000000","0.00432000"],["62179.20000000","0.00000000"]],"a":[["77724.00000000","0.93847000"],["77724.01000000","0.00090000"],["77724.90000000","0.00014000"],["77724.91000000","0.14283000"],["77726.21000000","0.00000000"],["77726.22000000","0.00014000"],["77726.73000000","0.00014000"],["77726.74000000","0.11191000"],["77729.46000000","0.00000000"],["77729.47000000","0.14315000"],["77736.47000000","0.00007000"],["77755.45000000","0.34740000"],["77779.98000000","0.00000000"]]}}
{"type":"depth","received_at_ms":1788333181551,"data":{"e":"depthUpdate","E":1788333181714,"s":"BTCUSDT","U":99556328021,"u":99556328044,"b":[["77723.99000000","2.21230000"],["69951.60000000","0.00448000"]],"a":[["77724.00000000","0.93861000"],["77724.91000000","0.14297000"],["77726.00000000","0.03014000"],["77726.22000000","0.00000000"],["77729.48000000","0.11191000"],["77733.95000000","0.08205000"],["77734.23000000","0.00206000"],["77742.83000000","0.00257000"],["77742.86000000","0.00000000"],["77764.05000000","0.00400000"],["77766.00000000","0.03000000"]]}}
{"type":"depth","received_at_ms":1788333181651,"data":{"e":"depthUpdate","E":1788333181814,"s":"BTCUSDT","U":99556328045,"u":99556328126,"b":[["77723.99000000","2.21424000"],["77723.98000000","0.00062000"],["77723.33000000","0.00400000"],["77722.76000000","0.00000000"],["77722.27000000","0.00000000"],["77721.29000000","0.00000000"],["77693.72000000","0.09761000"],["76558.13000000","0.00030000"],["69951.60000000","0.00432000"],["62179.19000000","0.00000000"]],"a":[["77724.00000000","0.60170000"],["77724.01000000","0.00083000"],["77724.90000000","0.00000000"],["77724.91000000","0.00014000"],["77728.68000000","0.00000000"],["77729.47000000","0.00021000"],["77731.93000000","0.76951000"],["77732.66000000","0.04000000"],["77733.11000000","0.00000000"],["77733.85000000","1.31471000"],["77733.86000000","0.00000000"],["77733.88000000","0.00000000"],["77734.22000000","0.00407000"],["77735.19000000","0.00400000"],["77735.52000000","0.00000000"],["77736.33000000","0.00000000"],["77736.56000000","0.01800000"],["77736.57000000","0.00000000"],["77736.58000000","0.00000000"],["77736.60000000","1.93226000"],["77742.15000000","0.00257000"],["77742.83000000","0.00000000"],["77742.84000000","0.00000000"],["77743.52000000","0.00023000"],["77744.99000000","0.00000000"],["77745.60000000","0.26056000"],["77746.23000000","0.37538000"],["77746.24000000","0.00000000"],["77748.03000000","0.00128000"],["77749.74000000","0.00000000"],["77749.76000000","0.00000000"],["77749.92000000","0.04699000"],["77752.83000000","0.00038000"],["77754.86000000","0.00000000"],["77755.89000000","0.00200000"],["77758.51000000","0.00000000"],["77767.72000000","0.00000000"],["78889.86000000","0.00030000"]]}}
{"type":"depth","received_at_ms":1788333181748,"data":{"e":"depthUpdate","E":1788333181914,"s":"BTCUSDT","U":99556328127,"u":99556328175,"b":[["77723.99000000","2.21487000"],["77723.98000000","0.00076000"],["77723.33000000","0.00000000"],["77722.49000000","0.00400000"],["77709.64000000","0.00411000"],["77690.55000000","0.00012000"],["77682.46000000","0.00000000"],["69951.60000000","0.00448000"]],"a":[["77724.00000000","0.79349000"],["77724.91000000","0.00000000"],["77726.74000000","0.11205000"],["77728.70000000","0.00027000"],["77728.99000000","0.00614000"],["77729.46000000","0.00007000"],["77729.47000000","0.14300000"],["77729.48000000","0.11205000"],["77731.77000000","0.01808000"],["77736.56000000","0.00000000"],["77742.15000000","0.00000000"],["77757.53000000","0.00000000"]]}}
{"type":"trade","received_at_ms":1788333181754,"data":{"e":"trade","E":1788333181919,"s":"BTCUSDT","t":6646665865,"p":"77724.00000000","q":"0.00200000","T":1788333181918,"m":false,"M":true}}
{"type":"trade","received_at_ms":1788333181754,"data":{"e":"trade","E":1788333181919,"s":"BTCUSDT","t":6646665866,"p":"77724.00000000","q":"0.00200000","T":1788333181918,"m":false,"M":true}}
{"type":"trade","received_at_ms":1788333181754,"data":{"e":"trade","E":1788333181919,"s":"BTCUSDT","t":6646665867,"p":"77724.00000000","q":"0.00200000","T":1788333181918,"m":false,"M":true}}
{"type":"trade","received_at_ms":1788333181754,"data":{"e":"trade","E":1788333181919,"s":"BTCUSDT","t":6646665868,"p":"77724.00000000","q":"0.00200000","T":1788333181918,"m":false,"M":true}}
{"type":"trade","received_at_ms":1788333181754,"data":{"e":"trade","E":1788333181919,"s":"BTCUSDT","t":6646665869,"p":"77724.00000000","q":"0.00200000","T":1788333181918,"m":false,"M":true}}
{"type":"trade","received_at_ms":1788333181755,"data":{"e":"trade","E":1788333181919,"s":"BTCUSDT","t":6646665870,"p":"77724.00000000","q":"0.00200000","T":1788333181919,"m":false,"M":true}}
{"type":"trade","received_at_ms":1788333181755,"data":{"e":"trade","E":1788333181919,"s":"BTCUSDT","t":6646665871,"p":"77724.00000000","q":"0.00200000","T":1788333181919,"m":false,"M":true}}
{"type":"trade","received_at_ms":1788333181755,"data":{"e":"trade","E":1788333181920,"s":"BTCUSDT","t":6646665872,"p":"77724.00000000","q":"0.00200000","T":1788333181919,"m":false,"M":true}}
{"type":"trade","received_at_ms":1788333181755,"data":{"e":"trade","E":1788333181920,"s":"BTCUSDT","t":6646665873,"p":"77724.00000000","q":"0.00200000","T":1788333181919,"m":false,"M":true}}
{"type":"trade","received_at_ms":1788333181755,"data":{"e":"trade","E":1788333181920,"s":"BTCUSDT","t":6646665874,"p":"77724.00000000","q":"0.00200000","T":1788333181919,"m":false,"M":true}}
{"type":"trade","received_at_ms":1788333181755,"data":{"e":"trade","E":1788333181920,"s":"BTCUSDT","t":6646665875,"p":"77724.00000000","q":"0.00200000","T":1788333181919,"m":false,"M":true}}
{"type":"trade","received_at_ms":1788333181755,"data":{"e":"trade","E":1788333181920,"s":"BTCUSDT","t":6646665876,"p":"77724.00000000","q":"0.00200000","T":1788333181920,"m":false,"M":true}}
{"type":"trade","received_at_ms":1788333181755,"data":{"e":"trade","E":1788333181920,"s":"BTCUSDT","t":6646665877,"p":"77724.00000000","q":"0.00200000","T":1788333181920,"m":false,"M":true}}
{"type":"trade","received_at_ms":1788333181755,"data":{"e":"trade","E":1788333181921,"s":"BTCUSDT","t":6646665878,"p":"77724.00000000","q":"0.00200000","T":1788333181920,"m":false,"M":true}}
{"type":"trade","received_at_ms":1788333181755,"data":{"e":"trade","E":1788333181921,"s":"BTCUSDT","t":6646665879,"p":"77724.00000000","q":"0.00200000","T":1788333181920,"m":false,"M":true}}
{"type":"trade","received_at_ms":1788333181756,"data":{"e":"trade","E":1788333181921,"s":"BTCUSDT","t":6646665880,"p":"77724.00000000","q":"0.00200000","T":1788333181921,"m":false,"M":true}}
{"type":"trade","received_at_ms":1788333181756,"data":{"e":"trade","E":1788333181922,"s":"BTCUSDT","t":6646665881,"p":"77724.00000000","q":"0.00009000","T":1788333181921,"m":false,"M":true}}
{"type":"trade","received_at_ms":1788333181756,"data":{"e":"trade","E":1788333181922,"s":"BTCUSDT","t":6646665882,"p":"77724.00000000","q":"0.00200000","T":1788333181921,"m":false,"M":true}}
{"type":"trade","received_at_ms":1788333181756,"data":{"e":"trade","E":1788333181922,"s":"BTCUSDT","t":6646665883,"p":"77724.00000000","q":"0.00200000","T":1788333181922,"m":false,"M":true}}
{"type":"trade","received_at_ms":1788333181756,"data":{"e":"trade","E":1788333181923,"s":"BTCUSDT","t":6646665884,"p":"77724.00000000","q":"0.02100000","T":1788333181923,"m":false,"M":true}}
{"type":"trade","received_at_ms":1788333181758,"data":{"e":"trade","E":1788333181923,"s":"BTCUSDT","t":6646665885,"p":"77724.00000000","q":"0.02100000","T":1788333181923,"m":false,"M":true}}
{"type":"trade","received_at_ms":1788333181758,"data":{"e":"trade","E":1788333181923,"s":"BTCUSDT","t":6646665886,"p":"77724.00000000","q":"0.02100000","T":1788333181923,"m":false,"M":true}}
{"type":"trade","received_at_ms":1788333181758,"data":{"e":"trade","E":1788333181924,"s":"BTCUSDT","t":6646665887,"p":"77724.00000000","q":"0.02100000","T":1788333181923,"m":false,"M":true}}
{"type":"trade","received_at_ms":1788333181758,"data":{"e":"trade","E":1788333181924,"s":"BTCUSDT","t":6646665888,"p":"77724.00000000","q":"0.02100000","T":1788333181923,"m":false,"M":true}}
{"type":"trade","received_at_ms":1788333181758,"data":{"e":"trade","E":1788333181924,"s":"BTCUSDT","t":6646665889,"p":"77724.00000000","q":"0.02100000","T":1788333181924,"m":false,"M":true}}
{"type":"trade","received_at_ms":1788333181758,"data":{"e":"trade","E":1788333181924,"s":"BTCUSDT","t":6646665890,"p":"77724.00000000","q":"0.02100000","T":1788333181924,"m":false,"M":true}}
{"type":"trade","received_at_ms":1788333181765,"data":{"e":"trade","E":1788333181925,"s":"BTCUSDT","t":6646665891,"p":"77724.00000000","q":"0.02100000","T":1788333181924,"m":false,"M":true}}
{"type":"depth","received_at_ms":1788333181852,"data":{"e":"depthUpdate","E":1788333182014,"s":"BTCUSDT","U":99556328176,"u":99556328462,"b":[["77723.99000000","4.14763000"],["77723.98000000","0.00076000"],["77723.96000000","0.00014000"],["77723.91000000","0.00014000"],["77722.75000000","0.00014000"],["77722.65000000","0.00014000"],["77722.64000000","0.37359000"],["77722.60000000","0.00000000"],["77721.26000000","0.00014000"],["77721.25000000","0.00007000"],["77721.11000000","0.00000000"],["77719.43000000","0.00200000"],["77712.31000000","0.62747000"],["77710.48000000","0.00000000"],["77708.19000000","0.00000000"],["77704.79000000","0.00000000"],["77698.71000000","0.00000000"],["77691.30000000","0.54184000"],["77682.17000000","0.00000000"],["77681.48000000","0.00000000"],["77674.71000000","0.00000000"],["77619.18000000","0.00000000"],["71506.08000000","0.00014000"],["69951.60000000","0.00432000"],["69951.58000000","0.00000000"],["62179.20000000","0.00032000"],["62167.00000000","0.00050000"]],"a":[["77724.00000000","0.58675000"],["77724.01000000","0.00076000"],["77726.73000000","0.00014000"],["77726.74000000","0.11108000"],["77726.75000000","0.00000000"],["77728.06000000","0.00027000"],["77728.09000000","0.00014000"],["77728.10000000","0.11191000"],["77728.11000000","0.00021000"],["77728.12000000","0.13071000"],["77728.70000000","0.00000000"],["77728.99000000","0.00614000"],["77729.45000000","0.00007000"],["77729.46000000","0.10078000"],["77729.47000000","0.00000000"],["77729.48000000","0.00014000"],["77730.84000000","0.11191000"],["77730.85000000","0.00000000"],["77731.76000000","0.11191000"],["77731.77000000","0.00008000"],["77731.78000000","0.16870000"],["77731.93000000","0.17643000"],["77732.26000000","0.00007000"],["77733.59000000","0.11191000"],["77733.85000000","0.00000000"],["77733.95000000","0.00000000"],["77734.22000000","0.00007000"],["77734.23000000","0.00000000"],["77734.37000000","0.00000000"],["77734.96000000","0.11191000"],["77735.19000000","0.00000000"],["77735.84000000","0.00400000"],["77736.27000000","0.00000000"],["77736.29000000","0.00000000"],["77736.33000000","0.11191000"],["77736.56000000","0.09622000"],["77736.57000000","1.10091000"],["77736.58000000","3.26497000"],["77736.59000000","0.00000000"],["77736.60000000","0.00000000"],["77736.87000000","0.03000000"],["77738.11000000","0.00000000"],["77739.77000000","0.08000000"],["77741.35000000","3.24697000"],["77741.36000000","0.00000000"],["77742.98000000","0.00000000"],["77743.79000000","0.00257000"],["77744.52000000","0.00000000"],["77745.33000000","0.00000000"],["77745.60000000","0.00000000"],["77745.96000000","0.26037000"],["77747.33000000","0.00000000"],["77749.03000000","0.00000000"],["77749.04000000","0.00000000"],["77749.91000000","0.25743000"],["77749.95000000","0.64358000"],["77751.11000000","0.00000000"],["77756.01000000","0.00000000"],["77757.22000000","0.00000000"],["77757.82000000","0.09850000"],["77759.66000000","0.00000000"],["77761.66000000","0.00000000"],["77762.24000000","0.00000000"],["77764.55000000","0.00000000"],["77765.64000000","0.00012000"],["77765.66000000","0.00000000"],["77767.72000000","0.00007000"],["77771.28000000","0.00433000"],["77782.64000000","0.25373000"],["77785.27000000","0.35870000"]]}}
{"type":"depth","received_at_ms":1788333181948,"data":{"e":"depthUpdate","E":1788333182114,"s":"BTCUSDT","U":99556328463,"u":99556328517,"b":[["77723.99000000","4.15763000"],["77721.32000000","0.01335000"],["77721.26000000","0.00000000"],["69951.60000000","0.00448000"]],"a":[["77724.00000000","0.58689000"],["77724.01000000","0.00090000"],["77726.52000000","0.00014000"],["77726.53000000","0.12285000"],["77728.00000000","0.03021000"],["77728.10000000","0.11205000"],["77728.11000000","0.00000000"],["77728.12000000","0.00014000"],["77728.99000000","0.00614000"],["77729.45000000","0.17305000"],["77729.46000000","0.10092000"],["77729.48000000","0.00000000"],["77732.26000000","0.00014000"],["77736.57000000","0.90840000"],["77743.79000000","0.00000000"],["77743.80000000","0.00257000"],["77765.47000000","0.00000000"],["77765.78000000","0.00000000"],["77766.02000000","0.00000000"],["77770.63000000","0.00630000"]]}}
{"type":"depth","received_at_ms":1788333182048,"data":{"e":"depthUpdate","E":1788333182214,"s":"BTCUSDT","U":99556328518,"u":99556328554,"b":[["77263.73000000","0.00000000"],["75557.14000000","0.00010000"],["69951.60000000","0.00432000"],["62179.20000000","0.00000000"],["62179.19000000","0.00000000"]],"a":[["77725.49000000","0.00014000"],["77725.50000000","0.14752000"],["77726.00000000","0.03014000"],["77726.52000000","0.00000000"],["77726.53000000","0.00014000"],["77728.10000000","0.11205000"],["77728.12000000","0.00000000"],["77728.99000000","0.00614000"],["77729.45000000","0.17319000"],["77729.46000000","0.10078000"],["77743.79000000","0.00257000"],["77743.80000000","0.00000000"],["77965.76000000","0.00000000"]]}}
{"type":"depth","received_at_ms":1788333182147,"data":{"e":"depthUpdate","E":1788333182314,"s":"BTCUSDT","U":99556328555,"u":99556328581,"b":[["77683.85000000","0.49720000"],["69951.60000000","0.00448000"],["62179.00000000","0.00400000"]],"a":[["77724.00000000","0.58703000"],["77724.01000000","0.00090000"],["77725.50000000","0.00014000"],["77726.00000000","0.03000000"],["77726.53000000","0.00000000"],["77742.82000000","0.00257000"],["77743.79000000","0.00000000"],["77745.96000000","0.00000000"],["77746.55000000","0.28920000"],["77781.42000000","0.00000000"],["77804.73000000","0.25738000"],["81001.14000000","0.00010000"]]}}
{"type":"depth","received_at_ms":1788333182248,"data":{"e":"depthUpdate","E":1788333182414,"s":"BTCUSDT","U":99556328582,"u":99556328604,"b":[["77723.99000000","2.21880000"],["77723.11000000","0.00257000"],["77712.31000000","0.00000000"],["77710.48000000","0.62748000"],["77704.46000000","0.49867000"],["77681.15000000","0.97855000"],["69951.60000000","0.00432000"]],"a":[["77724.00000000","0.58703000"],["77725.49000000","0.00000000"],["77725.50000000","0.00000000"],["77726.00000000","0.03014000"],["77729.44000000","0.00007000"],["77733.67000000","0.00400000"],["77735.84000000","0.00000000"],["77742.82000000","0.00000000"],["77821.72000000","0.00000000"],["77824.31000000","4.08551000"]]}}
{"type":"depth","received_at_ms":1788333182347,"data":{"e":"depthUpdate","E":1788333182514,"s":"BTCUSDT","U":99556328605,"u":99556328630,"b":[["77723.99000000","2.21251000"],["77723.98000000","0.00083000"],["77722.63000000","0.37468000"],["77721.80000000","0.00643000"],["77719.41000000","0.00000000"],["77710.49000000","0.62748000"],["77710.48000000","0.00000000"],["69951.60000000","0.00432000"],["69951.00000000","0.00068000"],["62179.20000000","0.00032000"]],"a":[["77724.00000000","0.73493000"],["77724.01000000","0.00083000"],["77731.93000000","0.24639000"],["77732.90000000","0.08205000"],["77756.52000000","0.01964000"],["77760.17000000","0.05497000"],["77767.72000000","0.00000000"],["77772.74000000","1.27354000"],["77799.46000000","0.00000000"]]}}
{"type":"trade","received_at_ms":1788333182406,"data":{"e":"trade","E":1788333182568,"s":"BTCUSDT","t":6646665892,"p":"77724.00000000","q":"0.01500000","T":1788333182568,"m":false,"M":true}}
{"type":"depth","received_at_ms":1788333182449,"data":{"e":"depthUpdate","E":1788333182614,"s":"BTCUSDT","U":99556328631,"u":99556328676,"b":[["77723.99000000","2.22144000"],["77723.11000000","0.00000000"],["77722.74000000","0.01807000"],["77722.66000000","0.00014000"],["77722.65000000","0.11205000"],["77722.64000000","0.37352000"],["77722.63000000","0.37447000"],["77721.80000000","0.00000000"],["77705.37000000","0.00000000"],["71506.08000000","0.00000000"],["69951.60000000","0.00441000"],["62179.20000000","0.00000000"],["62179.00000000","0.00400000"]],"a":[["77724.00000000","0.57596000"],["77724.01000000","0.00090000"],["77726.74000000","0.00014000"],["77727.65000000","0.00014000"],["77727.66000000","0.12930000"],["77728.10000000","0.00014000"],["77729.44000000","0.00000000"],["77729.45000000","0.00014000"],["77729.46000000","0.10092000"],["77733.67000000","0.00000000"],["77734.44000000","0.00400000"],["77736.47000000","0.00000000"],["77736.57000000","0.79649000"],["77756.52000000","0.00000000"],["77760.17000000","0.00000000"],["77765.62000000","0.00000000"],["77765.85000000","0.12871000"],["77977.24000000","0.00000000"]]}}
{"type":"depth","received_at_ms":1788333182548,"data":{"e":"depthUpdate","E":1788333182714,"s":"BTCUSDT","U":99556328677,"u":99556328796,"b":[["77723.99000000","2.40064000"],["77723.98000000","0.00027000"],["77722.74000000","0.01807000"],["77716.97000000","0.02000000"],["77716.89000000","0.02000000"],["77716.20000000","0.04000000"],["77716.13000000","0.02000000"],["77716.11000000","0.02000000"],["77713.89000000","0.02000000"],["77713.10000000","0.02000000"],["77713.09000000","0.02000000"],["77712.33000000","0.02000000"],["77708.68000000","0.00000000"],["77708.04000000","0.00000000"],["77707.23000000","0.00000000"],["77706.45000000","0.00008000"],["77705.37000000","0.00007000"],["77704.11000000","0.00000000"],["77703.35000000","0.00000000"],["77703.33000000","0.00000000"],["77673.72000000","0.06324000"],["77634.54000000","0.00000000"],["69951.60000000","0.00425000"]],"a":[["77724.00000000","0.38416000"],["77724.01000000","0.00090000"],["77726.00000000","0.03014000"],["77726.73000000","0.00000000"],["77726.74000000","0.00000000"],["77726.75000000","0.00000000"],["77726.76000000","0.00014000"],["77727.64000000","0.00014000"],["77727.65000000","0.10108000"],["77727.66000000","0.12944000"],["77728.00000000","0.03021000"],["77728.09000000","0.00000000"],["77728.10000000","0.00000000"],["77728.42000000","0.01267000"],["77728.99000000","0.00614000"],["77729.45000000","0.00014000"],["77729.99000000","0.00000000"],["77730.00000000","0.03064000"],["77730.22000000","0.02908000"],["77732.90000000","0.08411000"],["77734.08000000","0.00000000"],["77734.44000000","0.00000000"],["77734.93000000","0.00400000"],["77736.47000000","0.00007000"],["77736.55000000","0.11191000"],["77746.55000000","0.00000000"],["77747.33000000","0.33496000"],["77765.85000000","0.00000000"],["77790.65000000","0.00411000"],["77986.87000000","0.00030000"]]}}
{"type":"depth","received_at_ms":1788333182649,"data":{"e":"depthUpdate","E":1788333182814,"s":"BTCUSDT","U":99556328797,"u":99556328827,"b":[["77714.62000000","0.00000000"],["77712.60000000","0.02000000"],["77707.96000000","0.00000000"],["77707.89000000","0.00000000"],["77704.46000000","0.00000000"],["77702.56000000","0.00008000"],["77661.51000000","0.02000000"],["76558.13000000","0.00030000"],["69951.60000000","0.00441000"],["62179.19000000","0.00000000"]],"a":[["77726.00000000","0.03014000"],["77726.76000000","0.00000000"],["77727.65000000","0.10122000"],["77728.00000000","0.03021000"],["77728.42000000","0.01281000"],["77730.22000000","0.02894000"],["77766.38000000","0.12871000"],["78889.86000000","0.00030000"]]}}
{"type":"depth","received_at_ms":1788333182748,"data":{"e":"depthUpdate","E":1788333182914,"s":"BTCUSDT","U":99556328828,"u":99556328837,"b":[["77709.64000000","0.00000000"],["77639.68000000","0.00000000"],["69951.60000000","0.00441000"]],"a":[["77724.00000000","0.38409000"],["77724.01000000","0.00083000"],["77790.65000000","0.00000000"],["77821.75000000","0.00411000"]]}}
{"type":"depth","received_at_ms":1788333182848,"data":{"e":"depthUpdate","E":1788333183014,"s":"BTCUSDT","U":99556328838,"u":99556328850,"b":[["77723.99000000","2.40072000"],["77721.10000000","1.50000000"],["77719.41000000","0.62746000"],["77714.61000000","0.10910000"],["77710.49000000","0.00000000"],["77702.86000000","0.00000000"],["77699.19000000","0.12870000"],["77653.39000000","0.00000000"],["69951.60000000","0.00441000"],["62179.20000000","0.00032000"]],"a":[["77724.00000000","0.37809000"],["77726.42000000","0.00611000"],["77746.22000000","0.27079000"],["77747.33000000","0.00000000"],["77749.91000000","0.00000000"],["77750.34000000","0.25743000"]]}}
{"type":"depth","received_at_ms":1788333182948,"data":{"e":"depthUpdate","E":1788333183114,"s":"BTCUSDT","U":99556328851,"u":99556328874,"b":[["77723.99000000","2.40230000"],["77723.95000000","0.05811000"],["77722.74000000","0.01800000"],["77722.65000000","0.69785000"],["77722.63000000","0.00000000"],["77721.32000000","0.01342000"],["77721.11000000","0.62746000"],["77719.41000000","0.00000000"],["77705.57000000","0.51329000"],["77640.49000000","0.00411000"],["69951.60000000","0.00441000"]],"a":[["77724.00000000","0.37816000"],["77724.01000000","0.00090000"],["77726.00000000","0.03014000"],["77726.42000000","0.00625000"],["77730.00000000","0.03050000"],["77756.74000000","0.02026000"],["77760.40000000","0.05397000"]]}}
{"type":"depth","received_at_ms":1788333183048,"data":{"e":"depthUpdate","E":1788333183214,"s":"BTCUSDT","U":99556328875,"u":99556328905,"b":[["77723.99000000","2.40072000"],["77723.95000000","0.05021000"],["77722.74000000","0.01807000"],["77722.67000000","0.00014000"],["77722.66000000","0.01414000"],["77722.65000000","0.69785000"],["77722.64000000","0.37352000"],["77721.32000000","0.01328000"],["77719.88000000","0.00007000"],["77719.43000000","0.00000000"],["77719.42000000","0.00000000"],["69951.60000000","0.00457000"],["62179.20000000","0.00000000"],["62179.19000000","0.00000000"]],"a":[["77766.38000000","0.00000000"]]}}
{"type":"depth","received_at_ms":1788333183147,"data":{"e":"depthUpdate","E":1788333183314,"s":"BTCUSDT","U":99556328906,"u":99556328915,"b":[["77722.74000000","0.01807000"],["69951.60000000","0.00441000"]],"a":[["77770.96000000","1.67717000"],["77791.44000000","0.00411000"]]}}
{"type":"depth","received_at_ms":1788333183248,"data":{"e":"depthUpdate","E":1788333183414,"s":"BTCUSDT","U":99556328916,"u":99556328916,"b":[["69951.60000000","0.00457000"]],"a":[]}}
{"type":"trade","received_at_ms":1788333183286,"data":{"e":"trade","E":1788333183451,"s":"BTCUSDT","t":6646665893,"p":"77724.00000000","q":"0.00260000","T":1788333183451,"m":false,"M":true}}
{"type":"depth","received_at_ms":1788333183348,"data":{"e":"depthUpdate","E":1788333183514,"s":"BTCUSDT","U":99556328917,"u":99556328947,"b":[["77723.99000000","2.40170000"],["77723.98000000","0.00076000"],["69951.60000000","0.00432000"],["69951.59000000","0.00009000"],["62179.20000000","0.00032000"]],"a":[["77724.00000000","0.56736000"],["77742.05000000","0.00257000"]]}}
{"type":"trade","received_at_ms":1788333183434,"data":{"e":"trade","E":1788333183600,"s":"BTCUSDT","t":6646665894,"p":"77723.99000000","q":"0.01500000","T":1788333183599,"m":true,"M":true}}
{"type":"depth","received_at_ms":1788333183447,"data":{"e":"depthUpdate","E":1788333183614,"s":"BTCUSDT","U":99556328948,"u":99556329100,"b":[["77723.99000000","4.32441000"],["77723.98000000","0.00027000"],["77722.66000000","0.01428000"],["77722.65000000","0.58594000"],["77721.32000000","0.01335000"],["77721.11000000","0.00000000"],["77716.51000000","0.00000000"],["77712.45000000","0.62745000"],["77707.51000000","0.44146000"],["77704.32000000","0.22820000"],["77700.89000000","0.00000000"],["69951.60000000","0.00448000"],["69951.00000000","0.00088000"],["62179.20000000","0.00000000"],["62179.00000000","0.00600000"]],"a":[["77724.00000000","0.56959000"],["77724.01000000","0.00083000"],["77727.65000000","0.10108000"],["77727.66000000","0.00014000"],["77728.06000000","0.00000000"],["77728.67000000","0.00027000"],["77729.99000000","0.00007000"],["77731.93000000","0.00000000"],["77733.97000000","0.00000000"],["77734.91000000","0.00000000"],["77734.93000000","0.00000000"],["77734.96000000","0.10250000"],["77734.98000000","0.00000000"],["77735.24000000","0.00000000"],["77735.26000000","0.00000000"],["77735.28000000","0.00000000"],["77735.29000000","0.00000000"],["77736.54000000","0.51047000"],["77736.55000000","1.42662000"],["77736.56000000","0.00000000"],["77736.57000000","0.00000000"],["77736.58000000","0.00600000"],["77740.67000000","0.09622000"],["77742.05000000","0.00000000"],["77743.20000000","0.00257000"],["77746.22000000","0.00000000"],["77747.33000000","0.32664000"],["77767.72000000","0.00007000"],["77770.96000000","1.50412000"],["77773.21000000","0.51268000"],["78125.76000000","0.00000000"]]}}
{"type":"depth","received_at_ms":1788333183547,"data":{"e":"depthUpdate","E":1788333183714,"s":"BTCUSDT","U":99556329101,"u":99556329215,"b":[["77723.99000000","4.31604000"],["77723.98000000","0.00076000"],["77723.11000000","0.00257000"],["77722.67000000","0.00000000"],["77722.66000000","0.00028000"],["77722.65000000","0.58601000"],["77722.64000000","0.37359000"],["77722.49000000","0.00000000"],["77721.80000000","0.00643000"],["77721.32000000","0.01335000"],["77720.25000000","0.02147000"],["77719.41000000","0.01400000"],["77710.43000000","0.00411000"],["77707.51000000","0.00000000"],["77705.37000000","0.00007000"],["77703.61000000","0.44148000"],["77697.39000000","0.02000000"],["77696.70000000","0.02000000"],["77696.62000000","0.02000000"],["77696.60000000","0.02000000"],["77663.60000000","0.02000000"],["77650.80000000","1.61347000"],["77650.31000000","0.00000000"],["77640.49000000","0.00000000"],["69951.60000000","0.00432000"],["69951.00000000","0.00068000"],["62179.00000000","0.00400000"]],"a":[["77724.00000000","0.56974000"],["77724.01000000","0.00090000"],["77726.73000000","0.00014000"],["77726.74000000","0.11191000"],["77727.65000000","0.10108000"],["77727.66000000","0.00000000"],["77728.96000000","0.00000000"],["77729.99000000","0.00000000"],["77730.00000000","0.03064000"],["77732.65000000","0.21785000"],["77736.47000000","0.00007000"],["77736.52000000","1.19355000"],["77736.53000000","1.93226000"],["77736.54000000","0.00000000"],["77736.55000000","1.31471000"],["77736.58000000","0.00000000"],["77739.47000000","0.01200000"],["77739.76000000","0.00200000"],["77740.66000000","0.00000000"],["77743.20000000","0.00000000"],["77743.22000000","0.00257000"],["77744.52000000","0.26006000"],["77744.53000000","1.21016000"],["77747.33000000","0.00000000"],["77756.74000000","0.00000000"],["77757.82000000","0.00000000"],["77760.40000000","0.00000000"],["77791.44000000","0.00000000"],["77821.75000000","0.00000000"],["78222.45000000","0.21198000"]]}}
{"type":"depth","received_at_ms":1788333183648,"data":{"e":"depthUpdate","E":1788333183814,"s":"BTCUSDT","U":99556329216,"u":99556329259,"b":[["77722.74000000","0.01807000"],["77722.66000000","0.00014000"],["77722.64000000","0.37359000"],["77721.80000000","0.00657000"],["77528.01000000","0.00000000"],["77526.01000000","0.00811000"],["76558.13000000","0.00030000"],["69951.60000000","0.00448000"]],"a":[["77724.00000000","0.56981000"],["77726.42000000","0.00625000"],["77726.74000000","0.11205000"],["77728.23000000","0.00007000"],["77728.24000000","0.12273000"],["77729.45000000","0.00007000"],["77730.00000000","0.03050000"],["77736.51000000","0.01400000"],["77739.47000000","0.00000000"],["77739.76000000","0.00000000"],["77743.22000000","0.00000000"],["77743.24000000","0.00257000"],["77744.52000000","0.00000000"],["77745.96000000","0.30086000"],["77766.94000000","0.12871000"],["78889.86000000","0.00030000"]]}}
{"type":"trade","received_at_ms":1788333183720,"data":{"e":"trade","E":1788333183886,"s":"BTCUSDT","t":6646665895,"p":"77724.00000000","q":"0.00200000","T":1788333183886,"m":false,"M":true}}
{"type":"trade","received_at_ms":1788333183721,"data":{"e":"trade","E":1788333183886,"s":"BTCUSDT","t":6646665896,"p":"77724.00000000","q":"0.00200000","T":1788333183886,"m":false,"M":true}}
{"type":"trade","received_at_ms":1788333183721,"data":{"e":"trade","E":1788333183886,"s":"BTCUSDT","t":6646665897,"p":"77724.00000000","q":"0.00200000","T":1788333183886,"m":false,"M":true}}
{"type":"trade","received_at_ms":1788333183721,"data":{"e":"trade","E":1788333183886,"s":"BTCUSDT","t":6646665898,"p":"77724.00000000","q":"0.00200000","T":1788333183886,"m":false,"M":true}}
{"type":"depth","received_at_ms":1788333183747,"data":{"e":"depthUpdate","E":1788333183914,"s":"BTCUSDT","U":99556329260,"u":99556329289,"b":[["77723.99000000","4.31861000"],["77723.98000000","0.00076000"],["77723.11000000","0.00000000"],["77649.60000000","0.00000000"],["69951.60000000","0.00432000"],["69951.59000000","0.00000000"],["62179.19000000","0.00000000"]],"a":[["77724.00000000","0.56181000"],["77728.00000000","0.03021000"],["77728.24000000","0.12287000"],["77729.46000000","0.10078000"],["77743.24000000","0.00000000"],["77743.25000000","0.00257000"],["77766.94000000","0.00000000"],["77822.56000000","0.00411000"]]}}
{"type":"depth","received_at_ms":1788333183848,"data":{"e":"depthUpdate","E":1788333184014,"s":"BTCUSDT","U":99556329290,"u":99556329305,"b":[["77723.99000000","4.31854000"],["77723.98000000","0.00076000"],["69951.60000000","0.00432000"],["62179.20000000","0.00032000"],["62179.00000000","0.00400000"]],"a":[["77732.66000000","0.00000000"],["77736.50000000","0.09622000"],["77740.67000000","0.00000000"],["77743.25000000","0.00000000"],["77743.26000000","0.00257000"],["77766.94000000","0.00000000"]]}}
{"type":"depth","received_at_ms":1788333183947,"data":{"e":"depthUpdate","E":1788333184114,"s":"BTCUSDT","U":99556329306,"u":99556329314,"b":[["77649.53000000","0.00000000"],["69951.60000000","0.00432000"]],"a":[["77726.95000000","0.13846000"],["77728.24000000","0.00014000"],["77736.87000000","0.07000000"],["77743.26000000","0.00000000"],["77743.27000000","0.00257000"],["77791.46000000","0.00411000"]]}}
{"type":"depth","received_at_ms":1788333184048,"data":{"e":"depthUpdate","E":1788333184214,"s":"BTCUSDT","U":99556329315,"u":99556329343,"b":[["77649.67000000","0.00000000"],["77335.38000000","0.00129000"],["69951.60000000","0.00432000"],["62179.20000000","0.00000000"]],"a":[["77724.00000000","0.56174000"],["77726.74000000","0.11205000"],["77726.94000000","0.00014000"],["77726.95000000","0.13860000"],["77728.00000000","0.03021000"],["77728.23000000","0.00000000"],["77728.24000000","0.00000000"],["77729.45000000","0.00000000"],["77743.27000000","0.00000000"],["77743.28000000","0.00265000"],["77756.76000000","0.01980000"],["77757.84000000","0.09766000"],["77760.41000000","0.05313000"]]}}
{"type":"depth","received_at_ms":1788333184147,"data":{"e":"depthUpdate","E":1788333184314,"s":"BTCUSDT","U":99556329344,"u":99556329358,"b":[["69951.60000000","0.00432000"],["62179.19000000","0.00000000"],["62179.00000000","0.00400000"]],"a":[["77724.00000000","0.56181000"],["77724.01000000","0.00097000"],["77743.28000000","0.00008000"],["77743.30000000","0.00257000"],["77747.18000000","0.00128000"],["77748.03000000","0.00000000"],["78034.89000000","0.00128000"]]}}
{"type":"trade","received_at_ms":1788333184164,"data":{"e":"trade","E":1788333184329,"s":"BTCUSDT","t":6646665899,"p":"77724.00000000","q":"0.02100000","T":1788333184329,"m":false,"M":true}}
{"type":"depth","received_at_ms":1788333184247,"data":{"e":"depthUpdate","E":1788333184414,"s":"BTCUSDT","U":99556329359,"u":99556329367,"b":[["69951.60000000","0.00457000"]],"a":[["77724.00000000","0.54081000"],["77743.30000000","0.00000000"],["77745.96000000","0.00000000"],["77746.55000000","0.29287000"],["77767.45000000","0.12871000"],["77821.69000000","0.00087000"]]}}
{"type":"trade","received_at_ms":1788333184309,"data":{"e":"trade","E":1788333184476,"s":"BTCUSDT","t":6646665900,"p":"77723.99000000","q":"0.00348000","T":1788333184475,"m":true,"M":true}}
{"type":"depth","received_at_ms":1788333184348,"data":{"e":"depthUpdate","E":1788333184514,"s":"BTCUSDT","U":99556329368,"u":99556329381,"b":[["77723.99000000","4.31506000"],["77710.43000000","0.00000000"],["77640.51000000","0.00411000"],["69951.60000000","0.00473000"],["62179.20000000","0.00032000"],["62179.00000000","0.00400000"]],"a":[["77743.31000000","0.00000000"],["77743.32000000","0.00257000"],["77791.46000000","0.00000000"],["77822.56000000","0.00000000"]]}}
{"type":"trade","received_at_ms":1788333184438,"data":{"e":"trade","E":1788333184604,"s":"BTCUSDT","t":6646665901,"p":"77724.00000000","q":"0.00349000","T":1788333184604,"m":false,"M":true}}
{"type":"depth","received_at_ms":1788333184447,"data":{"e":"depthUpdate","E":1788333184614,"s":"BTCUSDT","U":99556329382,"u":99556329390,"b":[["77723.99000000","4.13473000"],["69951.60000000","0.00432000"],["69951.59000000","0.00009000"],["62179.20000000","0.00000000"]],"a":[["77724.00000000","0.53732000"],["77743.32000000","0.00000000"],["77743.33000000","0.00257000"],["77767.45000000","0.00000000"]]}}
{"type":"depth","received_at_ms":1788333184547,"data":{"e":"depthUpdate","E":1788333184714,"s":"BTCUSDT","U":99556329391,"u":99556329408,"b":[["77719.42000000","0.00800000"],["77719.41000000","0.00600000"],["77705.37000000","0.00007000"],["69951.60000000","0.00464000"],["62179.00000000","0.00400000"]],"a":[["77736.47000000","0.00007000"],["77743.33000000","0.00000000"],["77766.83000000","0.00000000"]]}}
{"type":"depth","received_at_ms":1788333184652,"data":{"e":"depthUpdate","E":1788333184814,"s":"BTCUSDT","U":99556329409,"u":99556329425,"b":[["77723.99000000","4.12830000"],["77723.55000000","0.00643000"],["77722.47000000","0.00643000"],["77721.80000000","0.00014000"],["77720.25000000","0.02154000"],["77652.47000000","0.00319000"],["77652.45000000","0.00000000"],["76558.13000000","0.00030000"],["69951.60000000","0.00448000"],["69951.00000000","0.00068000"]],"a":[["77736.47000000","0.00650000"],["77737.99000000","0.00000000"],["77766.24000000","0.00000000"],["77861.98000000","0.00128000"],["77863.05000000","0.00000000"],["78889.86000000","0.00030000"]]}}
{"type":"depth","received_at_ms":1788333184747,"data":{"e":"depthUpdate","E":1788333184914,"s":"BTCUSDT","U":99556329426,"u":99556329454,"b":[["77723.99000000","4.12837000"],["77723.98000000","0.00083000"],["77723.90000000","0.05021000"],["77723.55000000","0.00657000"],["77722.64000000","0.37359000"],["77722.47000000","0.00657000"],["77721.80000000","0.00000000"],["77721.32000000","0.01321000"],["77710.40000000","0.00411000"],["69951.60000000","0.00464000"],["62179.19000000","0.00000000"]],"a":[["77766.07000000","0.00000000"]]}}
{"type":"trade","received_at_ms":1788333184824,"data":{"e":"trade","E":1788333184987,"s":"BTCUSDT","t":6646665902,"p":"77724.00000000","q":"0.02100000","T":1788333184987,"m":false,"M":true}}
{"type":"trade","received_at_ms":1788333184824,"data":{"e":"trade","E":1788333184988,"s":"BTCUSDT","t":6646665903,"p":"77724.00000000","q":"0.02100000","T":1788333184987,"m":false,"M":true}}
{"type":"trade","received_at_ms":1788333184824,"data":{"e":"trade","E":1788333184989,"s":"BTCUSDT","t":6646665904,"p":"77724.00000000","q":"0.00654000","T":1788333184989,"m":false,"M":true}}
{"type":"trade","received_at_ms":1788333184824,"data":{"e":"trade","E":1788333184989,"s":"BTCUSDT","t":6646665905,"p":"77724.00000000","q":"0.00007000","T":1788333184989,"m":false,"M":true}}
{"type":"trade","received_at_ms":1788333184824,"data":{"e":"trade","E":1788333184989,"s":"BTCUSDT","t":6646665906,"p":"77724.00000000","q":"0.00008000","T":1788333184989,"m":false,"M":true}}
{"type":"trade","received_at_ms":1788333184824,"data":{"e":"trade","E":1788333184989,"s":"BTCUSDT","t":6646665907,"p":"77724.00000000","q":"0.00014000","T":1788333184989,"m":false,"M":true}}
{"type":"trade","received_at_ms":1788333184824,"data":{"e":"trade","E":1788333184989,"s":"BTCUSDT","t":6646665908,"p":"77724.00000000","q":"0.00007000","T":1788333184989,"m":false,"M":true}}
{"type":"trade","received_at_ms":1788333184824,"data":{"e":"trade","E":1788333184989,"s":"BTCUSDT","t":6646665909,"p":"77724.00000000","q":"0.01410000","T":1788333184989,"m":false,"M":true}}
{"type":"depth","received_at_ms":1788333184851,"data":{"e":"depthUpdate","E":1788333185014,"s":"BTCUSDT","U":99556329455,"u":99556329486,"b":[["77723.99000000","4.12774000"],["77723.98000000","0.00027000"],["77722.47000000","0.00014000"],["77722.16000000","0.00643000"],["77528.01000000","0.00811000"],["77526.01000000","0.00000000"],["69951.60000000","0.00448000"],["69951.59000000","0.00000000"],["69951.00000000","0.00068000"],["62179.20000000","0.00032000"]],"a":[["77724.00000000","0.47440000"],["77757.84000000","0.00000000"],["77758.11000000","0.09749000"]]}}
{"type":"depth","received_at_ms":1788333184952,"data":{"e":"depthUpdate","E":1788333185114,"s":"BTCUSDT","U":99556329487,"u":99556329502,"b":[["77722.64000000","0.37359000"],["77722.47000000","0.00000000"],["77722.16000000","0.00657000"],["69951.60000000","0.00464000"],["69951.00000000","0.00068000"]],"a":[["77822.51000000","0.00411000"]]}}
{"type":"trade","received_at_ms":1788333184988,"data":{"e":"trade","E":1788333185155,"s":"BTCUSDT","t":6646665910,"p":"77724.00000000","q":"0.00200000","T":1788333185154,"m":false,"M":true}}
{"type":"trade","received_at_ms":1788333184988,"data":{"e":"trade","E":1788333185155,"s":"BTCUSDT","t":6646665911,"p":"77724.00000000","q":"0.00200000","T":1788333185154,"m":false,"M":true}}
{"type":"trade","received_at_ms":1788333184989,"data":{"e":"trade","E":1788333185155,"s":"BTCUSDT","t":6646665912,"p":"77724.00000000","q":"0.00200000","T":1788333185155,"m":false,"M":true}}
{"type":"trade","received_at_ms":1788333184989,"data":{"e":"trade","E":1788333185155,"s":"BTCUSDT","t":6646665913,"p":"77724.00000000","q":"0.00200000","T":1788333185155,"m":false,"M":true}}
{"type":"trade","received_at_ms":1788333184989,"data":{"e":"trade","E":1788333185156,"s":"BTCUSDT","t":6646665914,"p":"77724.00000000","q":"0.00200000","T":1788333185155,"m":false,"M":true}}
{"type":"trade","received_at_ms":1788333184989,"data":{"e":"trade","E":1788333185156,"s":"BTCUSDT","t":6646665915,"p":"77724.00000000","q":"0.00200000","T":1788333185155,"m":false,"M":true}}
{"type":"trade","received_at_ms":1788333184989,"data":{"e":"trade","E":1788333185156,"s":"BTCUSDT","t":6646665916,"p":"77724.00000000","q":"0.00200000","T":1788333185155,"m":false,"M":true}}
{"type":"trade","received_at_ms":1788333184989,"data":{"e":"trade","E":1788333185156,"s":"BTCUSDT","t":6646665917,"p":"77724.00000000","q":"0.00200000","T":1788333185155,"m":false,"M":true}}
{"type":"trade","received_at_ms":1788333184990,"data":{"e":"trade","E":1788333185156,"s":"BTCUSDT","t":6646665918,"p":"77724.00000000","q":"0.00200000","T":1788333185156,"m":false,"M":true}}
{"type":"trade","received_at_ms":1788333184990,"data":{"e":"trade","E":1788333185156,"s":"BTCUSDT","t":6646665919,"p":"77724.00000000","q":"0.00200000","T":1788333185156,"m":false,"M":true}}
{"type":"trade","received_at_ms":1788333184990,"data":{"e":"trade","E":1788333185156,"s":"BTCUSDT","t":6646665920,"p":"77724.00000000","q":"0.00200000","T":1788333185156,"m":false,"M":true}}
{"type":"trade","received_at_ms":1788333184991,"data":{"e":"trade","E":1788333185157,"s":"BTCUSDT","t":6646665921,"p":"77724.00000000","q":"0.00200000","T":1788333185157,"m":false,"M":true}}
{"type":"trade","received_at_ms":1788333184991,"data":{"e":"trade","E":1788333185158,"s":"BTCUSDT","t":6646665922,"p":"77724.00000000","q":"0.02100000","T":1788333185158,"m":false,"M":true}}
{"type":"trade","received_at_ms":1788333184992,"data":{"e":"trade","E":1788333185158,"s":"BTCUSDT","t":6646665923,"p":"77724.00000000","q":"0.00200000","T":1788333185158,"m":false,"M":true}}
{"type":"trade","received_at_ms":1788333184992,"data":{"e":"trade","E":1788333185158,"s":"BTCUSDT","t":6646665924,"p":"77724.00000000","q":"0.00200000","T":1788333185158,"m":false,"M":true}}
{"type":"trade","received_at_ms":1788333184992,"data":{"e":"trade","E":1788333185159,"s":"BTCUSDT","t":6646665925,"p":"77724.00000000","q":"0.02000000","T":1788333185158,"m":false,"M":true}}
{"type":"trade","received_at_ms":1788333184994,"data":{"e":"trade","E":1788333185159,"s":"BTCUSDT","t":6646665926,"p":"77724.00000000","q":"0.02100000","T":1788333185159,"m":false,"M":true}}
{"type":"trade","received_at_ms":1788333184994,"data":{"e":"trade","E":1788333185160,"s":"BTCUSDT","t":6646665927,"p":"77724.00000000","q":"0.02100000","T":1788333185159,"m":false,"M":true}}
{"type":"trade","received_at_ms":1788333184994,"data":{"e":"trade","E":1788333185160,"s":"BTCUSDT","t":6646665928,"p":"77724.00000000","q":"0.02100000","T":1788333185160,"m":false,"M":true}}
{"type":"trade","received_at_ms":1788333184994,"data":{"e":"trade","E":1788333185160,"s":"BTCUSDT","t":6646665929,"p":"77724.00000000","q":"0.02100000","T":1788333185160,"m":false,"M":true}}
{"type":"depth","received_at_ms":1788333185047,"data":{"e":"depthUpdate","E":1788333185214,"s":"BTCUSDT","U":99556329503,"u":99556329541,"b":[["77723.99000000","4.43417000"],["77723.55000000","0.00021000"],["77723.11000000","0.00643000"],["77722.16000000","0.00014000"],["69951.60000000","0.00448000"],["62179.20000000","0.00000000"]],"a":[["77724.00000000","0.32133000"],["77724.01000000","0.00090000"],["77726.94000000","0.00000000"],["77726.95000000","0.00014000"],["77729.45000000","0.00007000"],["77736.47000000","0.00007000"],["77737.36000000","0.00643000"],["77746.55000000","0.00000000"],["77747.33000000","0.35236000"],["77750.34000000","0.00000000"],["77751.08000000","0.25743000"]]}}
{"type":"trade","received_at_ms":1788333185109,"data":{"e":"trade","E":1788333185275,"s":"BTCUSDT","t":6646665930,"p":"77723.99000000","q":"0.00013000","T":1788333185275,"m":true,"M":true}}
{"type":"depth","received_at_ms":1788333185149,"data":{"e":"depthUpdate","E":1788333185314,"s":"BTCUSDT","U":99556329542,"u":99556329574,"b":[["77723.99000000","4.43404000"],["77723.90000000","0.05021000"],["77723.55000000","0.00007000"],["77723.11000000","0.00657000"],["77722.64000000","0.37352000"],["77722.16000000","0.00000000"],["77721.32000000","0.01335000"],["69951.60000000","0.00464000"],["69951.59000000","0.00009000"],["62179.19000000","0.00000000"]],"a":[["77726.74000000","0.11205000"],["77726.95000000","0.00000000"],["77729.46000000","0.10092000"],["77734.79000000","0.00000000"],["77735.79000000","0.00643000"],["77766.56000000","0.00000000"]]}}
{"type":"depth","received_at_ms":1788333185247,"data":{"e":"depthUpdate","E":1788333185414,"s":"BTCUSDT","U":99556329575,"u":99556329581,"b":[["69951.60000000","0.00448000"]],"a":[["77727.28000000","0.00014000"],["77727.29000000","0.11058000"],["77729.45000000","0.00000000"]]}}
{"type":"depth","received_at_ms":1788333185346,"data":{"e":"depthUpdate","E":1788333185514,"s":"BTCUSDT","U":99556329582,"u":99556329597,"b":[["69951.60000000","0.00448000"],["69951.00000000","0.00078000"],["62179.20000000","0.00032000"]],"a":[["77724.00000000","0.32140000"],["77724.01000000","0.00097000"],["77726.74000000","0.11205000"],["77727.29000000","0.11072000"],["77729.46000000","0.10078000"]]}}
{"type":"depth","received_at_ms":1788333185446,"data":{"e":"depthUpdate","E":1788333185614,"s":"BTCUSDT","U":99556329598,"u":99556329634,"b":[["77723.99000000","2.50178000"],["77723.11000000","0.00014000"],["77722.64000000","0.37359000"],["77722.16000000","0.00643000"],["77721.32000000","0.01342000"],["77721.11000000","0.62746000"],["77712.45000000","0.00000000"],["69951.00000000","0.00068000"],["62179.20000000","0.00000000"],["62179.00000000","0.00400000"]],"a":[["77724.00000000","0.32147000"],["77724.01000000","0.00104000"],["77725.36000000","0.00014000"],["77725.37000000","0.11191000"],["77726.43000000","0.00014000"],["77726.44000000","0.12305000"],["77727.28000000","0.00000000"],["77727.29000000","0.00014000"],["77727.99000000","0.00000000"]]}}
{"type":"depth","received_at_ms":1788333185548,"data":{"e":"depthUpdate","E":1788333185714,"s":"BTCUSDT","U":99556329635,"u":99556329683,"b":[["77723.90000000","0.05014000"],["77723.55000000","0.00000000"],["77723.11000000","0.00000000"],["77722.64000000","0.37359000"],["77722.16000000","0.00657000"],["77721.32000000","0.01342000"],["77710.40000000","0.00000000"],["77705.37000000","0.00007000"],["77640.51000000","0.00000000"],["69951.60000000","0.00448000"]],"a":[["77724.00000000","0.32147000"],["77725.37000000","0.11205000"],["77726.42000000","0.00625000"],["77726.44000000","0.12319000"],["77726.74000000","0.11205000"],["77727.29000000","0.00000000"],["77728.99000000","0.00600000"],["77736.47000000","0.00007000"],["77791.41000000","0.00411000"],["77822.51000000","0.00000000"]]}}
{"type":"depth","received_at_ms":1788333185650,"data":{"e":"depthUpdate","E":1788333185814,"s":"BTCUSDT","U":99556329684,"u":99556329692,"b":[["76558.13000000","0.00030000"],["69951.60000000","0.00448000"]],"a":[["77736.51000000","0.00600000"],["77742.56000000","0.00257000"],["78889.86000000","0.00030000"]]}}
{"type":"depth","received_at_ms":1788333185747,"data":{"e":"depthUpdate","E":1788333185914,"s":"BTCUSDT","U":99556329693,"u":99556329700,"b":[["69951.60000000","0.00448000"],["69951.00000000","0.00078000"],["62179.19000000","0.00000000"],["62179.00000000","0.00400000"]],"a":[["77742.56000000","0.00000000"]]}}
{"type":"depth","received_at_ms":1788333185848,"data":{"e":"depthUpdate","E":1788333186014,"s":"BTCUSDT","U":99556329701,"u":99556329715,"b":[["77723.99000000","2.49535000"],["77723.55000000","0.00643000"],["77653.39000000","1.61347000"],["77650.80000000","0.00000000"],["69951.60000000","0.00464000"],["69951.00000000","0.00078000"],["62179.20000000","0.00032000"]],"a":[["77734.66000000","0.00643000"],["77735.79000000","0.00000000"],["77742.57000000","0.00000000"],["77742.58000000","0.00257000"]]}}
{"type":"trade","received_at_ms":1788333185921,"data":{"e":"trade","E":1788333186084,"s":"BTCUSDT","t":6646665931,"p":"77724.00000000","q":"0.00500000","T":1788333186083,"m":false,"M":true}}
{"type":"depth","received_at_ms":1788333185947,"data":{"e":"depthUpdate","E":1788333186114,"s":"BTCUSDT","U":99556329716,"u":99556329742,"b":[["77723.90000000","0.05021000"],["77723.55000000","0.00657000"],["77721.32000000","0.01328000"],["77718.20000000","0.30000000"],["69951.60000000","0.00448000"],["69951.59000000","0.00000000"],["69951.58000000","0.00009000"],["69951.00000000","0.00068000"]],"a":[["77724.00000000","0.31647000"],["77724.01000000","0.00111000"],["77726.02000000","0.00619000"],["77726.42000000","0.00025000"],["77726.49000000","0.00660000"],["77728.99000000","0.00000000"],["77729.59000000","0.14290000"],["77767.00000000","0.12871000"]]}}
{"type":"trade","received_at_ms":1788333186017,"data":{"e":"trade","E":1788333186183,"s":"BTCUSDT","t":6646665932,"p":"77724.00000000","q":"0.01500000","T":1788333186182,"m":false,"M":true}}
{"type":"depth","received_at_ms":1788333186047,"data":{"e":"depthUpdate","E":1788333186214,"s":"BTCUSDT","U":99556329743,"u":99556329768,"b":[["77653.39000000","0.00000000"],["69951.60000000","0.00448000"],["62179.20000000","0.00000000"]],"a":[["77724.00000000","0.30147000"],["77726.00000000","0.03014000"],["77726.02000000","0.00633000"],["77726.42000000","0.00011000"],["77726.44000000","0.12319000"],["77726.49000000","0.00674000"],["77728.42000000","0.01267000"],["77729.59000000","0.00000000"],["77736.52000000","1.04246000"],["77766.94000000","0.00000000"],["77767.00000000","0.00000000"]]}}
{"type":"depth","received_at_ms":1788333186147,"data":{"e":"depthUpdate","E":1788333186314,"s":"BTCUSDT","U":99556329769,"u":99556329785,"b":[["77710.44000000","0.00411000"],["69951.60000000","0.00448000"],["62179.19000000","0.00000000"],["62179.00000000","0.00400000"]],"a":[["77724.00000000","0.30140000"],["77724.01000000","0.00104000"],["77726.43000000","0.00000000"],["77726.44000000","0.00014000"],["77727.99000000","0.00007000"],["77742.58000000","0.00000000"],["77742.60000000","0.00657000"]]}}
{"type":"depth","received_at_ms":1788333186247,"data":{"e":"depthUpdate","E":1788333186414,"s":"BTCUSDT","U":99556329786,"u":99556329823,"b":[["77723.99000000","4.43404000"],["77723.90000000","0.05028000"],["77723.55000000","0.00014000"],["77723.11000000","0.00643000"],["77722.66000000","0.00014000"],["77722.16000000","0.00014000"],["77721.32000000","0.01321000"],["77721.11000000","0.00000000"],["77712.83000000","0.62745000"],["77650.80000000","1.61347000"],["69951.60000000","0.00464000"],["62179.00000000","0.00400000"]],"a":[["77724.00000000","0.10960000"],["77726.02000000","0.00633000"],["77726.44000000","0.00000000"],["77728.42000000","0.01281000"],["77728.48000000","0.00000000"],["77734.66000000","0.00000000"],["77735.79000000","0.00643000"],["77736.50000000","0.00000000"],["77736.52000000","0.59113000"],["77736.53000000","0.00000000"],["77737.36000000","0.00000000"],["77738.05000000","0.00643000"],["77742.60000000","0.00400000"],["77742.61000000","0.00257000"],["77746.22000000","0.09622000"],["77749.95000000","0.00000000"],["77751.07000000","0.64358000"],["77936.50000000","0.00007000"]]}}
{"type":"depth","received_at_ms":1788333186347,"data":{"e":"depthUpdate","E":1788333186514,"s":"BTCUSDT","U":99556329824,"u":99556329864,"b":[["77723.90000000","0.05021000"],["77723.55000000","0.00000000"],["77723.11000000","0.00657000"],["77722.64000000","0.37352000"],["77722.16000000","0.00000000"],["77721.32000000","0.01335000"],["77705.57000000","0.00000000"],["77681.15000000","0.00000000"],["77640.50000000","0.00411000"],["77528.01000000","0.00000000"],["77526.01000000","0.00811000"],["69951.60000000","0.00432000"],["62179.20000000","0.00032000"]],"a":[["77729.18000000","0.10654000"],["77736.50000000","1.26413000"],["77736.51000000","1.93226000"],["77736.52000000","0.00000000"],["77740.67000000","0.00600000"],["77741.53000000","0.00000000"],["77742.61000000","0.00000000"],["77743.35000000","0.00257000"],["77746.22000000","0.00000000"]]}}
{"type":"trade","received_at_ms":1788333186421,"data":{"e":"trade","E":1788333186588,"s":"BTCUSDT","t":6646665933,"p":"77724.00000000","q":"0.02548000","T":1788333186588,"m":false,"M":true}}
{"type":"depth","received_at_ms":1788333186447,"data":{"e":"depthUpdate","E":1788333186614,"s":"BTCUSDT","U":99556329865,"u":99556329883,"b":[["69951.60000000","0.00464000"],["69951.58000000","0.00000000"],["62179.20000000","0.00000000"],["62179.00000000","0.00400000"]],"a":[["77724.00000000","0.08412000"],["77724.10000000","0.00007000"],["77728.42000000","0.01281000"],["77734.14000000","0.00000000"],["77736.32000000","0.00600000"],["77740.67000000","0.00000000"],["77743.35000000","0.00000000"],["77743.37000000","0.00257000"]]}}
{"type":"depth","received_at_ms":1788333186548,"data":{"e":"depthUpdate","E":1788333186714,"s":"BTCUSDT","U":99556329884,"u":99556329889,"b":[["77705.37000000","0.00000000"],["69951.60000000","0.00448000"]],"a":[["77736.47000000","0.00000000"],["77743.37000000","0.00000000"],["77743.39000000","0.00257000"]]}}
{"type":"depth","received_at_ms":1788333186647,"data":{"e":"depthUpdate","E":1788333186814,"s":"BTCUSDT","U":99556329890,"u":99556329905,"b":[["77705.37000000","0.00007000"],["77696.69000000","0.10000000"],["77681.11000000","0.00000000"],["77528.01000000","0.00811000"],["77526.01000000","0.00000000"],["76558.13000000","0.00030000"],["69951.60000000","0.00464000"]],"a":[["77728.40000000","0.11326000"],["77729.18000000","0.00000000"],["77736.47000000","0.00007000"],["77743.39000000","0.00000000"],["77743.40000000","0.00257000"],["78889.86000000","0.00030000"]]}}
{"type":"depth","received_at_ms":1788333186747,"data":{"e":"depthUpdate","E":1788333186914,"s":"BTCUSDT","U":99556329906,"u":99556329934,"b":[["77723.99000000","2.50178000"],["77723.11000000","0.00014000"],["77722.64000000","0.37359000"],["77722.00000000","0.00643000"],["77721.32000000","0.01342000"],["77721.11000000","0.62746000"],["77712.83000000","0.00000000"],["77710.44000000","0.00000000"],["77705.56000000","0.50307000"],["77683.85000000","0.73269000"],["77682.25000000","1.00188000"],["77640.50000000","0.00000000"],["69951.60000000","0.00448000"],["62179.19000000","0.00000000"]],"a":[["77724.00000000","0.27599000"],["77728.00000000","0.03021000"],["77728.40000000","0.11340000"],["77728.42000000","0.01267000"],["77742.62000000","0.00257000"],["77743.40000000","0.00000000"],["77791.41000000","0.00000000"],["77822.55000000","0.00411000"]]}}
{"type":"depth","received_at_ms":1788333186847,"data":{"e":"depthUpdate","E":1788333187014,"s":"BTCUSDT","U":99556329935,"u":99556329968,"b":[["77723.90000000","0.05014000"],["77723.11000000","0.00000000"],["77722.64000000","0.37359000"],["77722.00000000","0.00657000"],["77721.32000000","0.01342000"],["69951.60000000","0.00448000"],["62179.20000000","0.00032000"],["62179.00000000","0.00400000"]],"a":[["77724.00000000","0.27592000"],["77726.57000000","0.00014000"],["77726.58000000","0.11542000"],["77727.99000000","0.00000000"],["77728.40000000","0.00014000"],["77742.62000000","0.00000000"],["77742.64000000","0.00257000"]]}}
{"type":"trade","received_at_ms":1788333186857,"data":{"e":"trade","E":1788333187023,"s":"BTCUSDT","t":6646665934,"p":"77724.00000000","q":"0.00032000","T":1788333187022,"m":false,"M":true}}
{"type":"depth","received_at_ms":1788333186947,"data":{"e":"depthUpdate","E":1788333187114,"s":"BTCUSDT","U":99556329969,"u":99556329994,"b":[["77674.61000000","0.25738000"],["77652.43000000","0.00000000"],["69951.60000000","0.00457000"],["69951.00000000","0.00068000"]],"a":[["77724.00000000","0.27560000"],["77724.01000000","0.00104000"],["77726.00000000","0.03614000"],["77726.02000000","0.00033000"],["77726.49000000","0.00674000"],["77726.58000000","0.11556000"],["77728.00000000","0.03021000"],["77728.40000000","0.00000000"],["77742.64000000","0.00000000"]]}}
{"type":"depth","received_at_ms":1788333187048,"data":{"e":"depthUpdate","E":1788333187214,"s":"BTCUSDT","U":99556329995,"u":99556330012,"b":[["75557.14000000","0.00000000"],["69951.60000000","0.00457000"],["62179.20000000","0.00000000"]],"a":[["77724.10000000","0.00000000"],["77726.00000000","0.03614000"],["77726.02000000","0.00019000"],["77728.42000000","0.01281000"],["77742.66000000","0.00257000"],["77765.85000000","0.00000000"],["77821.72000000","2.15325000"],["77824.31000000","1.93226000"],["81001.14000000","0.00000000"]]}}
{"type":"trade","received_at_ms":1788333187049,"data":{"e":"trade","E":1788333187215,"s":"BTCUSDT","t":6646665935,"p":"77723.99000000","q":"0.01500000","T":1788333187215,"m":true,"M":true}}
{"type":"depth","received_at_ms":1788333187148,"data":{"e":"depthUpdate","E":1788333187314,"s":"BTCUSDT","U":99556330013,"u":99556330025,"b":[["77723.99000000","2.48678000"],["69951.60000000","0.00457000"],["62179.19000000","0.00000000"]],"a":[["77742.66000000","0.00000000"],["77742.67000000","0.00257000"],["77765.90000000","0.00000000"],["77766.00000000","0.15871000"],["77766.07000000","0.00000000"],["80000.00000000","84.36766000"]]}}
{"type":"depth","received_at_ms":1788333187248,"data":{"e":"depthUpdate","E":1788333187414,"s":"BTCUSDT","U":99556330026,"u":99556330038,"b":[["69951.60000000","0.00457000"],["62179.00000000","0.00400000"]],"a":[["77736.32000000","0.01000000"],["77742.67000000","0.00000000"],["77742.68000000","0.00000000"],["77742.70000000","0.00264000"],["77766.00000000","0.03000000"],["77766.13000000","0.12871000"]]}}
{"type":"depth","received_at_ms":1788333187347,"data":{"e":"depthUpdate","E":1788333187514,"s":"BTCUSDT","U":99556330039,"u":99556330045,"b":[["69951.60000000","0.00473000"],["62179.20000000","0.00032000"],["62179.00000000","0.00600000"]],"a":[["77734.53000000","0.00643000"],["77735.79000000","0.00000000"],["77766.13000000","0.00000000"]]}}
{"type":"trade","received_at_ms":1788333187399,"data":{"e":"trade","E":1788333187565,"s":"BTCUSDT","t":6646665936,"p":"77723.99000000","q":"0.11000000","T":1788333187564,"m":true,"M":true}}
{"type":"trade","received_at_ms":1788333187437,"data":{"e":"trade","E":1788333187602,"s":"BTCUSDT","t":6646665937,"p":"77724.00000000","q":"0.00692000","T":1788333187602,"m":false,"M":true}}
{"type":"depth","received_at_ms":1788333187448,"data":{"e":"depthUpdate","E":1788333187614,"s":"BTCUSDT","U":99556330046,"u":99556330066,"b":[["77723.99000000","2.38078000"],["71506.08000000","0.00014000"],["69951.60000000","0.00448000"],["69951.59000000","0.00009000"],["62179.20000000","0.00000000"]],"a":[["77724.00000000","0.26860000"],["77725.67000000","0.00014000"],["77725.68000000","0.12913000"],["77726.57000000","0.00000000"],["77726.58000000","0.00014000"],["77735.00000000","0.00400000"],["77742.70000000","0.00007000"],["77742.71000000","0.00257000"]]}}
{"type":"trade","received_at_ms":1788333187473,"data":{"e":"trade","E":1788333187639,"s":"BTCUSDT","t":6646665938,"p":"77724.00000000","q":"0.00342000","T":1788333187639,"m":false,"M":true}}
{"type":"depth","received_at_ms":1788333187548,"data":{"e":"depthUpdate","E":1788333187714,"s":"BTCUSDT","U":99556330067,"u":99556330096,"b":[["77710.42000000","0.00411000"],["77650.80000000","0.00000000"],["77648.21000000","1.61347000"],["69951.60000000","0.00448000"]],"a":[["77724.00000000","0.40944000"],["77724.01000000","0.00104000"],["77725.37000000","0.11205000"],["77725.68000000","0.12927000"],["77726.49000000","0.00674000"],["77726.58000000","0.00000000"],["77734.14000000","0.00007000"],["77736.19000000","0.00643000"],["77738.05000000","0.00000000"],["77742.71000000","0.00000000"],["77742.73000000","0.00257000"]]}}
{"type":"depth","received_at_ms":1788333187646,"data":{"e":"depthUpdate","E":1788333187814,"s":"BTCUSDT","U":99556330097,"u":99556330110,"b":[["77705.37000000","0.00007000"],["77653.90000000","0.97917000"],["77650.02000000","1.41437000"],["76558.13000000","0.00030000"],["69951.60000000","0.00416000"]],"a":[["77736.47000000","0.00007000"],["77742.72000000","0.00000000"],["77742.73000000","0.00000000"],["78889.86000000","0.00030000"]]}}
{"type":"depth","received_at_ms":1788333187747,"data":{"e":"depthUpdate","E":1788333187914,"s":"BTCUSDT","U":99556330111,"u":99556330157,"b":[["77723.99000000","2.06834000"],["77723.98000000","0.00076000"],["77723.55000000","0.00257000"],["77722.99000000","0.00000000"],["77722.76000000","0.00643000"],["77722.00000000","0.00014000"],["77720.88000000","0.00643000"],["77719.42000000","0.00000000"],["77700.49000000","0.04728000"],["77694.09000000","0.00000000"],["69951.60000000","0.00448000"],["62179.19000000","0.00000000"]],"a":[["77724.00000000","0.53779000"],["77724.63000000","0.00014000"],["77724.64000000","0.11953000"],["77725.67000000","0.00000000"],["77725.68000000","0.00014000"],["77735.00000000","0.00000000"],["77736.32000000","0.00600000"],["77742.73000000","0.00000000"],["77791.43000000","0.00411000"]]}}
{"type":"trade","received_at_ms":1788333187800,"data":{"e":"trade","E":1788333187966,"s":"BTCUSDT","t":6646665939,"p":"77724.00000000","q":"0.00200000","T":1788333187966,"m":false,"M":true}}
