{"type":"depth","received_at_ms":1788407327110,"data":{"e":"depthUpdate","E":1788407327314,"s":"BTCUSDT","U":99603294634,"u":99603294642,"b":[["77669.39000000","0.00000000"],["77668.77000000","0.00257000"],["69902.88000000","0.00457000"],["62136.00000000","0.00015000"]],"a":[["77670.91000000","0.00021000"],["77672.84000000","0.00311000"]]}}
{"type":"depth","received_at_ms":1788407327212,"data":{"e":"depthUpdate","E":1788407327414,"s":"BTCUSDT","U":99603294643,"u":99603294658,"b":[["76970.83000000","0.00010000"],["69902.88000000","0.00441000"]],"a":[["77669.87000000","0.99452000"],["77669.88000000","0.00084000"],["77670.54000000","0.10275000"],["77670.91000000","0.00007000"],["77674.00000000","0.03021000"],["78058.22000000","0.00041000"]]}}
{"type":"depth","received_at_ms":1788407327311,"data":{"e":"depthUpdate","E":1788407327514,"s":"BTCUSDT","U":99603294659,"u":99603294663,"b":[["69902.88000000","0.00441000"],["62135.89000000","0.00032000"]],"a":[["77669.87000000","0.99462000"],["77707.90000000","0.09723000"]]}}
{"type":"depth","received_at_ms":1788407327410,"data":{"e":"depthUpdate","E":1788407327614,"s":"BTCUSDT","U":99603294664,"u":99603294676,"b":[["77669.86000000","9.27969000"],["69902.88000000","0.00432000"],["69902.87000000","0.00073000"],["62136.00000000","0.00015000"],["62135.89000000","0.00000000"]],"a":[]}}
{"type":"depth","received_at_ms":1788407327510,"data":{"e":"depthUpdate","E":1788407327714,"s":"BTCUSDT","U":99603294677,"u":99603294686,"b":[["69902.88000000","0.00448000"]],"a":[["77669.87000000","0.92970000"]]}}
{"type":"depth","received_at_ms":1788407327611,"data":{"e":"depthUpdate","E":1788407327814,"s":"BTCUSDT","U":99603294687,"u":99603294695,"b":[["77662.82000000","0.00321000"],["77655.55000000","0.00000000"],["77651.64000000","0.00000000"],["71456.28000000","0.00014000"],["69902.88000000","0.00432000"]],"a":[["77686.62000000","0.00000000"],["77699.34000000","0.00000000"],["77708.40000000","0.00000000"]]}}
{"type":"depth","received_at_ms":1788407327710,"data":{"e":"depthUpdate","E":1788407327914,"s":"BTCUSDT","U":99603294696,"u":99603294708,"b":[["77655.55000000","0.00007000"],["77588.86000000","0.72120000"],["77588.24000000","0.35842000"],["77586.31000000","0.00000000"],["69902.88000000","0.00464000"]],"a":[["77678.78000000","0.00523000"],["77686.62000000","0.00007000"],["77722.08000000","0.00000000"],["77722.09000000","0.00000000"],["77722.18000000","0.12879000"]]}}
{"type":"depth","received_at_ms":1788407327810,"data":{"e":"depthUpdate","E":1788407328014,"s":"BTCUSDT","U":99603294709,"u":99603294719,"b":[["69902.88000000","0.00448000"],["62136.00000000","0.00015000"],["62135.89000000","0.00032000"]],"a":[["77722.18000000","0.00000000"],["77722.34000000","0.01278000"],["77722.43000000","0.00000000"]]}}
{"type":"depth","received_at_ms":1788407327911,"data":{"e":"depthUpdate","E":1788407328115,"s":"BTCUSDT","U":99603294720,"u":99603294732,"b":[["76504.81000000","0.00030000"],["69902.88000000","0.00464000"]],"a":[["77669.87000000","0.93982000"],["77722.43000000","0.00000000"],["77723.20000000","0.12879000"],["78834.92000000","0.00030000"]]}}
{"type":"depth","received_at_ms":1788407328010,"data":{"e":"depthUpdate","E":1788407328214,"s":"BTCUSDT","U":99603294733,"u":99603294742,"b":[["69902.88000000","0.00448000"],["62135.89000000","0.00000000"]],"a":[["77669.87000000","0.79372000"],["77697.27000000","0.65080000"],["77697.29000000","0.00000000"],["77723.20000000","0.00000000"],["77723.29000000","0.12879000"],["77774.98000000","0.91197000"],["77775.10000000","0.00000000"]]}}
{"type":"depth","received_at_ms":1788407328111,"data":{"e":"depthUpdate","E":1788407328314,"s":"BTCUSDT","U":99603294743,"u":99603294751,"b":[["69902.88000000","0.00448000"],["62136.00000000","0.00015000"]],"a":[["77669.87000000","0.93162000"],["77723.29000000","0.00000000"]]}}
{"type":"depth","received_at_ms":1788407328210,"data":{"e":"depthUpdate","E":1788407328414,"s":"BTCUSDT","U":99603294752,"u":99603294763,"b":[["71456.28000000","0.00000000"],["69902.88000000","0.00448000"],["69902.87000000","0.00064000"]],"a":[["77669.87000000","0.79251000"],["78058.22000000","0.00034000"]]}}
{"type":"depth","received_at_ms":1788407328313,"data":{"e":"depthUpdate","E":1788407328515,"s":"BTCUSDT","U":99603294764,"u":99603294770,"b":[["69902.88000000","0.00448000"],["62135.89000000","0.00032000"]],"a":[["77669.87000000","0.91715000"],["77682.20000000","0.00200000"],["77683.48000000","0.00000000"]]}}
{"type":"depth","received_at_ms":1788407328410,"data":{"e":"depthUpdate","E":1788407328614,"s":"BTCUSDT","U":99603294771,"u":99603294786,"b":[["77658.49000000","0.08000000"],["77642.34000000","0.00000000"],["69902.88000000","0.00448000"],["62135.89000000","0.00000000"]],"a":[["77669.87000000","0.77962000"],["77670.52000000","0.00000000"],["77670.53000000","0.00678000"]]}}
{"type":"depth","received_at_ms":1788407328510,"data":{"e":"depthUpdate","E":1788407328714,"s":"BTCUSDT","U":99603294787,"u":99603294800,"b":[["77669.86000000","9.14169000"],["75561.73000000","0.00000000"],["69902.88000000","0.00448000"],["69902.87000000","0.00073000"],["62136.00000000","0.00015000"]],"a":[["77669.87000000","0.93581000"],["77672.67000000","0.00007000"],["81006.07000000","0.00000000"]]}}
{"type":"depth","received_at_ms":1788407328610,"data":{"e":"depthUpdate","E":1788407328814,"s":"BTCUSDT","U":99603294801,"u":99603294803,"b":[["77669.86000000","9.14147000"],["69902.88000000","0.00464000"]],"a":[["77669.87000000","0.78992000"]]}}
{"type":"depth","received_at_ms":1788407328711,"data":{"e":"depthUpdate","E":1788407328914,"s":"BTCUSDT","U":99603294804,"u":99603294820,"b":[["77669.86000000","9.14108000"],["77655.55000000","0.00007000"],["69902.88000000","0.00448000"]],"a":[["77669.87000000","0.92154000"],["77680.20000000","0.00400000"],["77686.62000000","0.00007000"],["77711.40000000","0.00000000"]]}}
{"type":"depth","received_at_ms":1788407328811,"data":{"e":"depthUpdate","E":1788407329014,"s":"BTCUSDT","U":99603294821,"u":99603294827,"b":[["69902.88000000","0.00464000"],["62135.89000000","0.00032000"]],"a":[["77669.87000000","0.92261000"],["77723.44000000","0.00000000"]]}}
{"type":"depth","received_at_ms":1788407328910,"data":{"e":"depthUpdate","E":1788407329114,"s":"BTCUSDT","U":99603294828,"u":99603294833,"b":[["76504.81000000","0.00030000"],["69902.88000000","0.00432000"]],"a":[["78834.92000000","0.00030000"]]}}
{"type":"depth","received_at_ms":1788407329010,"data":{"e":"depthUpdate","E":1788407329214,"s":"BTCUSDT","U":99603294834,"u":99603294846,"b":[["69902.88000000","0.00464000"],["62135.89000000","0.00000000"]],"a":[["77669.87000000","0.79084000"],["77709.10000000","1.85009000"],["77723.42000000","0.00000000"],["77723.59000000","0.00000000"]]}}
{"type":"depth","received_at_ms":1788407329111,"data":{"e":"depthUpdate","E":1788407329314,"s":"BTCUSDT","U":99603294847,"u":99603294853,"b":[["69902.88000000","0.00448000"],["62136.00000000","0.00015000"]],"a":[["77723.50000000","0.00000000"]]}}
{"type":"depth","received_at_ms":1788407329210,"data":{"e":"depthUpdate","E":1788407329414,"s":"BTCUSDT","U":99603294854,"u":99603294873,"b":[["77669.86000000","9.13900000"],["77627.02000000","0.00000000"],["69902.88000000","0.00448000"]],"a":[["77669.87000000","0.78061000"],["77674.78000000","0.00007000"],["77675.60000000","0.00000000"],["77675.77000000","0.00000000"],["77678.78000000","0.00000000"],["77680.94000000","0.10022000"],["77682.20000000","0.00600000"],["77771.99000000","0.79435000"],["77772.44000000","2.60865000"],["77774.98000000","0.00000000"],["77774.99000000","0.00000000"]]}}
{"type":"depth","received_at_ms":1788407329310,"data":{"e":"depthUpdate","E":1788407329514,"s":"BTCUSDT","U":99603294874,"u":99603294960,"b":[["77669.86000000","9.14804000"],["77668.77000000","0.00000000"],["77668.74000000","0.00000000"],["77668.62000000","0.00000000"],["77665.91000000","0.00000000"],["77665.56000000","0.03224000"],["77665.38000000","0.00000000"],["77665.14000000","0.00000000"],["77665.13000000","0.12875000"],["77664.74000000","0.00200000"],["77664.27000000","0.00800000"],["77663.19000000","0.00000000"],["77663.18000000","0.00800000"],["77660.89000000","0.00000000"],["77656.00000000","0.00272000"],["77649.28000000","0.00200000"],["77645.53000000","0.00000000"],["77623.56000000","0.00425000"],["77611.68000000","0.00496000"],["69902.88000000","0.00448000"],["69902.87000000","0.00064000"],["69902.86000000","0.00009000"],["62136.00000000","0.00015000"],["62135.89000000","0.00032000"]],"a":[["77669.87000000","0.24575000"],["77674.78000000","0.00007000"],["77676.10000000","0.00208000"],["77676.41000000","0.09989000"],["77680.01000000","0.00000000"],["77681.09000000","0.00000000"],["77682.23000000","0.46350000"],["77682.39000000","0.00400000"],["77683.15000000","0.00000000"],["77683.69000000","0.00000000"],["77683.97000000","0.10022000"],["77684.20000000","0.00000000"],["77684.33000000","0.00000000"],["77684.46000000","0.00000000"],["77684.87000000","0.00000000"],["77685.71000000","0.00000000"],["77686.21000000","0.00400000"],["77687.64000000","0.00643000"],["77688.20000000","0.10022000"],["77689.35000000","0.00000000"],["77689.53000000","0.10022000"],["77690.76000000","0.00000000"],["77702.93000000","0.00060000"],["77704.44000000","0.00190000"],["77707.90000000","0.00000000"],["77713.38000000","0.00007000"],["77713.79000000","0.00000000"],["77724.17000000","0.00000000"],["77726.93000000","0.00000000"],["77728.05000000","0.00000000"],["77771.99000000","0.01846000"],["77772.44000000","0.00000000"]]}}
{"type":"depth","received_at_ms":1788407329410,"data":{"e":"depthUpdate","E":1788407329614,"s":"BTCUSDT","U":99603294961,"u":99603294996,"b":[["77669.86000000","9.15061000"],["77669.53000000","0.53388000"],["77665.91000000","0.00014000"],["77665.56000000","0.03217000"],["77665.13000000","0.12882000"],["77651.76000000","0.00183000"],["77627.71000000","0.00000000"],["75561.73000000","0.00010000"],["69902.88000000","0.00464000"],["62135.89000000","0.00000000"]],"a":[["77680.98000000","0.00400000"],["77682.20000000","0.00400000"],["77682.21000000","0.00000000"],["77682.39000000","0.00000000"],["77684.72000000","0.00000000"],["77685.07000000","0.01808000"],["77740.50000000","0.00534000"],["77741.72000000","0.01739000"]]}}
{"type":"depth","received_at_ms":1788407329510,"data":{"e":"depthUpdate","E":1788407329714,"s":"BTCUSDT","U":99603294997,"u":99603295001,"b":[["69902.88000000","0.00448000"]],"a":[["77684.74000000","0.00000000"]]}}
{"type":"depth","received_at_ms":1788407329610,"data":{"e":"depthUpdate","E":1788407329814,"s":"BTCUSDT","U":99603295002,"u":99603295010,"b":[["77664.74000000","0.00000000"],["77663.18000000","0.01000000"],["69902.88000000","0.00448000"],["62136.00000000","0.00015000"]],"a":[["77684.75000000","0.00000000"],["81006.07000000","0.00010000"]]}}
{"type":"depth","received_at_ms":1788407329710,"data":{"e":"depthUpdate","E":1788407329914,"s":"BTCUSDT","U":99603295011,"u":99603295018,"b":[["77669.86000000","9.14804000"],["77655.55000000","0.00007000"],["69902.88000000","0.00448000"]],"a":[["77674.78000000","0.00014000"],["77686.62000000","0.00007000"],["77713.38000000","0.00000000"]]}}
{"type":"depth","received_at_ms":1788407329811,"data":{"e":"depthUpdate","E":1788407330014,"s":"BTCUSDT","U":99603295019,"u":99603295050,"b":[["77669.05000000","0.00257000"],["77665.14000000","0.00007000"],["77664.27000000","0.01000000"],["77663.18000000","0.00800000"],["69902.88000000","0.00448000"],["62135.89000000","0.00032000"]],"a":[["77669.87000000","0.24582000"],["77672.89000000","0.12067000"],["77680.98000000","0.00000000"],["77681.49000000","0.00400000"],["77682.20000000","0.00000000"],["77685.06000000","0.01600000"],["77685.07000000","0.00208000"],["77687.64000000","0.01043000"],["77714.06000000","0.00834000"]]}}
{"type":"depth","received_at_ms":1788407329910,"data":{"e":"depthUpdate","E":1788407330114,"s":"BTCUSDT","U":99603295051,"u":99603295061,"b":[["76504.81000000","0.00000000"],["62136.00000000","0.00215000"]],"a":[["77672.68000000","0.09204000"],["77672.89000000","0.12081000"],["77674.00000000","0.03007000"],["78834.92000000","0.00000000"]]}}
{"type":"depth","received_at_ms":1788407330010,"data":{"e":"depthUpdate","E":1788407330214,"s":"BTCUSDT","U":99603295062,"u":99603295071,"b":[["77636.00000000","0.73000000"],["77635.00000000","0.00000000"],["76504.81000000","0.00030000"],["69902.88000000","0.00448000"],["62136.00000000","0.00015000"],["62135.89000000","0.00000000"]],"a":[["78834.92000000","0.00030000"]]}}
{"type":"depth","received_at_ms":1788407330110,"data":{"e":"depthUpdate","E":1788407330314,"s":"BTCUSDT","U":99603295072,"u":99603295083,"b":[["77669.86000000","9.15061000"],["77669.05000000","0.00000000"],["69902.88000000","0.00464000"],["62136.00000000","0.00015000"]],"a":[["77674.78000000","0.00007000"],["77713.38000000","0.00007000"],["77714.45000000","1.25645000"],["77722.99000000","0.00000000"]]}}
{"type":"depth","received_at_ms":1788407330210,"data":{"e":"depthUpdate","E":1788407330414,"s":"BTCUSDT","U":99603295084,"u":99603295089,"b":[["77664.27000000","0.00800000"],["77663.21000000","0.00200000"],["69902.88000000","0.00448000"],["62136.00000000","0.00015000"]],"a":[["77723.87000000","0.12879000"]]}}
{"type":"depth","received_at_ms":1788407330310,"data":{"e":"depthUpdate","E":1788407330514,"s":"BTCUSDT","U":99603295090,"u":99603295100,"b":[["77664.27000000","0.00800000"],["77663.22000000","0.00200000"],["77663.21000000","0.00000000"],["69902.88000000","0.00464000"],["62135.89000000","0.00032000"]],"a":[["77685.36000000","0.13620000"],["77686.79000000","0.09317000"],["77723.87000000","0.00000000"]]}}
{"type":"depth","received_at_ms":1788407330410,"data":{"e":"depthUpdate","E":1788407330614,"s":"BTCUSDT","U":99603295101,"u":99603295114,"b":[["69902.88000000","0.00448000"],["62136.00000000","0.00015000"],["62135.89000000","0.00040000"]],"a":[]}}
{"type":"depth","received_at_ms":1788407330511,"data":{"e":"depthUpdate","E":1788407330714,"s":"BTCUSDT","U":99603295115,"u":99603295123,"b":[["77669.86000000","9.14802000"],["77664.27000000","0.01000000"],["77663.22000000","0.00000000"],["77651.76000000","0.00000000"],["69902.88000000","0.00448000"],["69902.86000000","0.00000000"],["62135.89000000","0.00000000"]],"a":[]}}
{"type":"depth","received_at_ms":1788407330611,"data":{"e":"depthUpdate","E":1788407330814,"s":"BTCUSDT","U":99603295124,"u":99603295125,"b":[["69902.88000000","0.00448000"]],"a":[]}}
{"type":"depth","received_at_ms":1788407330711,"data":{"e":"depthUpdate","E":1788407330914,"s":"BTCUSDT","U":99603295126,"u":99603295526,"b":[["77670.53000000","13.82818000"],["77670.52000000","0.00014000"],["77670.45000000","0.00400000"],["77669.99000000","2.86283000"],["77669.98000000","0.41262000"],["77669.87000000","1.39552000"],["77669.86000000","5.12199000"],["77669.85000000","0.00000000"],["77669.55000000","0.00000000"],["77669.54000000","0.00028000"],["77669.53000000","0.08315000"],["77668.73000000","0.00000000"],["77668.61000000","0.01705000"],["77668.48000000","0.00000000"],["77667.85000000","0.03259000"],["77666.89000000","0.00000000"],["77666.85000000","0.00021000"],["77665.91000000","0.00000000"],["77665.14000000","0.00000000"],["77659.35000000","0.00007000"],["77658.68000000","0.00000000"],["77655.55000000","0.00000000"],["77649.28000000","0.00000000"],["77647.74000000","0.00200000"],["77639.25000000","0.00000000"],["77615.14000000","0.54562000"],["77612.71000000","0.00000000"],["77602.78000000","0.23067000"],["77258.67000000","0.00250000"],["69903.48000000","0.00032000"],["69902.88000000","0.00000000"]],"a":[["77669.87000000","0.00000000"],["77669.88000000","0.00000000"],["77669.99000000","0.00000000"],["77670.00000000","0.00000000"],["77670.53000000","0.00000000"],["77670.54000000","0.16416000"],["77670.55000000","0.00063000"],["77672.61000000","0.00000000"],["77672.62000000","0.00028000"],["77672.67000000","0.00000000"],["77672.68000000","0.00021000"],["77672.88000000","0.00000000"],["77672.89000000","0.00014000"],["77673.28000000","0.00014000"],["77673.29000000","0.03179000"],["77673.99000000","0.00014000"],["77674.00000000","0.03021000"],["77674.08000000","0.00021000"],["77674.09000000","0.00548000"],["77674.76000000","0.00014000"],["77674.77000000","0.10022000"],["77675.33000000","0.00014000"],["77675.50000000","0.00000000"],["77675.98000000","0.00007000"],["77675.99000000","0.19962000"],["77676.18000000","0.10022000"],["77677.37000000","0.00000000"],["77680.41000000","0.10022000"],["77680.93000000","0.00000000"],["77681.49000000","0.00000000"],["77684.59000000","0.00000000"],["77685.05000000","0.00800000"],["77685.06000000","0.00000000"],["77685.07000000","0.00008000"],["77685.21000000","0.00000000"],["77685.28000000","1.15151000"],["77685.36000000","0.19935000"],["77685.81000000","0.00000000"],["77686.21000000","0.00000000"],["77686.53000000","0.02000000"],["77686.62000000","0.00000000"],["77686.79000000","0.00000000"],["77687.63000000","0.00200000"],["77687.64000000","0.00643000"],["77687.99000000","0.00400000"],["77688.19000000","0.00000000"],["77688.46000000","0.30866000"],["77709.00000000","0.00000000"],["77710.00000000","0.04200000"],["77714.06000000","0.00000000"],["77723.63000000","0.00000000"],["77724.54000000","0.12879000"],["77774.99000000","2.60865000"],["78070.47000000","0.00250000"],["78834.92000000","0.00000000"]]}}
{"type":"depth","received_at_ms":1788407330810,"data":{"e":"depthUpdate","E":1788407331014,"s":"BTCUSDT","U":99603295527,"u":99603295614,"b":[["77670.53000000","13.82839000"],["77670.52000000","0.00414000"],["77670.00000000","0.01800000"],["77669.99000000","2.86297000"],["77669.98000000","0.41276000"],["77669.87000000","1.39566000"],["77669.86000000","4.95329000"],["77669.54000000","0.00014000"],["77668.61000000","0.01705000"],["77667.37000000","0.02021000"],["77666.88000000","0.49823000"],["77666.85000000","0.00007000"],["77665.13000000","0.12875000"],["77664.27000000","0.00000000"],["77663.18000000","0.00000000"],["77656.22000000","0.00007000"],["62136.43000000","0.00032000"],["62136.00000000","0.00215000"]],"a":[["77670.54000000","0.16416000"],["77672.00000000","0.03028000"],["77672.62000000","0.00007000"],["77672.68000000","0.00000000"],["77672.89000000","0.00000000"],["77673.29000000","0.03193000"],["77674.00000000","0.03021000"],["77674.08000000","0.00007000"],["77674.09000000","0.00555000"],["77674.77000000","0.10036000"],["77675.33000000","0.00000000"],["77675.34000000","0.00904000"],["77675.99000000","0.19976000"],["77676.00000000","0.03014000"],["77676.10000000","0.00000000"],["77685.05000000","0.00000000"],["77686.58000000","0.00400000"],["77687.29000000","0.00007000"],["77687.62000000","0.00800000"],["77724.54000000","0.00000000"]]}}
{"type":"depth","received_at_ms":1788407330910,"data":{"e":"depthUpdate","E":1788407331114,"s":"BTCUSDT","U":99603295615,"u":99603295658,"b":[["77670.53000000","13.82839000"],["77670.01000000","0.00014000"],["77670.00000000","0.01828000"],["77669.99000000","2.86311000"],["77669.88000000","0.00014000"],["77667.71000000","0.02903000"],["69903.48000000","0.00064000"],["62136.00000000","0.00015000"]],"a":[["77670.54000000","0.34427000"],["77670.55000000","0.00077000"],["77673.37000000","0.00014000"],["77673.38000000","0.09884000"],["77674.31000000","0.00014000"],["77674.32000000","0.14308000"],["77674.76000000","0.00000000"],["77675.98000000","0.00000000"],["77675.99000000","0.19969000"],["77681.65000000","0.00400000"],["77687.58000000","0.10093000"],["77687.64000000","0.01443000"],["77723.98000000","0.00000000"],["77766.17000000","0.00000000"],["77766.84000000","0.00025000"],["77769.10000000","0.00089000"]]}}
{"type":"depth","received_at_ms":1788407331010,"data":{"e":"depthUpdate","E":1788407331214,"s":"BTCUSDT","U":99603295659,"u":99603295680,"b":[["76504.81000000","0.00000000"],["69903.48000000","0.00080000"],["62136.43000000","0.00000000"]],"a":[["77670.68000000","0.00000000"],["77672.23000000","0.00007000"],["77673.29000000","0.03193000"],["77673.38000000","0.09898000"],["77674.09000000","0.00555000"],["77674.32000000","0.14322000"],["77675.99000000","0.19955000"],["77676.00000000","0.03000000"],["78835.60000000","0.00030000"]]}}
{"type":"depth","received_at_ms":1788407331111,"data":{"e":"depthUpdate","E":1788407331314,"s":"BTCUSDT","U":99603295681,"u":99603295684,"b":[["69903.48000000","0.00096000"],["62136.00000000","0.00015000"]],"a":[["77673.77000000","0.00007000"]]}}
{"type":"depth","received_at_ms":1788407331209,"data":{"e":"depthUpdate","E":1788407331414,"s":"BTCUSDT","U":99603295685,"u":99603295708,"b":[["77670.53000000","13.81909000"],["76970.83000000","0.00000000"],["69903.48000000","0.00112000"],["69903.47000000","0.00009000"],["62136.00000000","0.00015000"]],"a":[["77670.54000000","0.34427000"],["77670.55000000","0.00077000"],["77673.32000000","0.00014000"],["77673.33000000","0.10693000"],["77674.31000000","0.00000000"],["77674.32000000","0.00014000"],["77678.03000000","0.00794000"],["77714.16000000","0.00844000"],["77718.30000000","0.64402000"],["77724.20000000","0.00000000"],["77774.98000000","0.91197000"]]}}
{"type":"depth","received_at_ms":1788407331310,"data":{"e":"depthUpdate","E":1788407331514,"s":"BTCUSDT","U":99603295709,"u":99603295727,"b":[["77670.00000000","0.01628000"],["77663.21000000","0.00200000"],["69903.48000000","0.00144000"],["62136.43000000","0.00032000"]],"a":[["77673.29000000","0.03193000"],["77673.33000000","0.10707000"],["77674.09000000","0.00555000"],["77674.32000000","0.00000000"],["77742.23000000","0.00000000"],["77747.28000000","0.25755000"]]}}
{"type":"depth","received_at_ms":1788407331410,"data":{"e":"depthUpdate","E":1788407331614,"s":"BTCUSDT","U":99603295728,"u":99603295735,"b":[["77670.01000000","0.00014000"],["77663.21000000","0.00000000"],["77648.00000000","0.00765000"],["69903.48000000","0.00144000"],["62136.43000000","0.00000000"]],"a":[["77724.94000000","0.12879000"]]}}
{"type":"depth","received_at_ms":1788407331510,"data":{"e":"depthUpdate","E":1788407331714,"s":"BTCUSDT","U":99603295736,"u":99603295745,"b":[["77670.53000000","13.81917000"],["77663.18000000","0.00000000"],["69903.48000000","0.00160000"],["62136.42000000","0.00000000"]],"a":[["77670.54000000","0.48531000"]]}}
{"type":"depth","received_at_ms":1788407331610,"data":{"e":"depthUpdate","E":1788407331814,"s":"BTCUSDT","U":99603295746,"u":99603295752,"b":[["77670.53000000","13.85946000"],["77670.01000000","0.00014000"],["77665.90000000","0.14971000"],["69903.48000000","0.00176000"]],"a":[]}}
{"type":"depth","received_at_ms":1788407331711,"data":{"e":"depthUpdate","E":1788407331914,"s":"BTCUSDT","U":99603295753,"u":99603295758,"b":[["77663.18000000","0.00200000"],["69903.48000000","0.00176000"]],"a":[["77671.73000000","0.10822000"],["77673.33000000","0.00014000"],["77673.77000000","0.00000000"]]}}
{"type":"depth","received_at_ms":1788407331817,"data":{"e":"depthUpdate","E":1788407332015,"s":"BTCUSDT","U":99603295759,"u":99603295786,"b":[["77670.53000000","13.86188000"],["77656.22000000","0.00007000"],["77591.41000000","0.72120000"],["77588.86000000","0.00000000"],["69903.48000000","0.00192000"],["69903.47000000","0.00000000"],["69903.46000000","0.00009000"],["62136.43000000","0.00032000"]],"a":[["77670.54000000","0.48531000"],["77671.72000000","0.00014000"],["77671.73000000","0.10836000"],["77673.29000000","0.03193000"],["77673.32000000","0.00000000"],["77673.33000000","0.00000000"],["77685.07000000","0.10243000"],["77685.39000000","0.00257000"],["77687.29000000","0.00007000"]]}}
{"type":"depth","received_at_ms":1788407331910,"data":{"e":"depthUpdate","E":1788407332114,"s":"BTCUSDT","U":99603295787,"u":99603295790,"b":[["69903.48000000","0.00192000"]],"a":[["77685.39000000","0.00000000"],["77685.40000000","0.00257000"]]}}
{"type":"depth","received_at_ms":1788407332011,"data":{"e":"depthUpdate","E":1788407332214,"s":"BTCUSDT","U":99603295791,"u":99603295799,"b":[["77670.01000000","0.00214000"],["77663.18000000","0.00000000"],["76505.47000000","0.00030000"],["69903.48000000","0.00208000"],["62136.43000000","0.00000000"]],"a":[["78835.60000000","0.00030000"]]}}
{"type":"depth","received_at_ms":1788407332111,"data":{"e":"depthUpdate","E":1788407332314,"s":"BTCUSDT","U":99603295800,"u":99603295808,"b":[["62136.00000000","0.00015000"]],"a":[["77670.54000000","0.48531000"],["77670.55000000","0.00077000"],["77672.23000000","0.00000000"],["77685.40000000","0.00000000"],["77685.41000000","0.00257000"]]}}
{"type":"depth","received_at_ms":1788407332210,"data":{"e":"depthUpdate","E":1788407332414,"s":"BTCUSDT","U":99603295809,"u":99603295817,"b":[["77545.59000000","0.00000000"],["76971.50000000","0.00010000"],["69903.48000000","0.00224000"],["62136.00000000","0.00015000"]],"a":[["77670.54000000","0.34442000"],["77673.77000000","0.00007000"]]}}
{"type":"depth","received_at_ms":1788407332310,"data":{"e":"depthUpdate","E":1788407332514,"s":"BTCUSDT","U":99603295818,"u":99603295830,"b":[["77670.52000000","0.00014000"],["77670.02000000","0.00400000"],["69903.48000000","0.00224000"],["62136.43000000","0.00032000"]],"a":[["77670.54000000","0.48989000"],["77685.06000000","0.01200000"],["77687.62000000","0.00400000"],["77687.64000000","0.00643000"]]}}
{"type":"depth","received_at_ms":1788407332411,"data":{"e":"depthUpdate","E":1788407332614,"s":"BTCUSDT","U":99603295831,"u":99603295844,"b":[["77648.00000000","0.01765000"],["69903.48000000","0.00224000"],["62136.43000000","0.00000000"]],"a":[["77685.06000000","0.00000000"],["77685.41000000","0.00000000"],["77685.42000000","0.00257000"],["77687.57000000","0.01600000"],["77687.62000000","0.00000000"]]}}
{"type":"depth","received_at_ms":1788407332510,"data":{"e":"depthUpdate","E":1788407332714,"s":"BTCUSDT","U":99603295845,"u":99603295853,"b":[["77591.41000000","0.00000000"],["77588.86000000","0.72120000"],["77482.01000000","0.02017000"],["77452.89000000","0.00000000"],["69903.48000000","0.00240000"],["62136.42000000","0.00000000"]],"a":[]}}
{"type":"depth","received_at_ms":1788407332610,"data":{"e":"depthUpdate","E":1788407332814,"s":"BTCUSDT","U":99603295854,"u":99603295860,"b":[["77670.53000000","13.82159000"],["77670.47000000","0.04024000"],["69903.48000000","0.00256000"],["62136.00000000","0.00015000"]],"a":[]}}
{"type":"depth","received_at_ms":1788407332710,"data":{"e":"depthUpdate","E":1788407332914,"s":"BTCUSDT","U":99603295861,"u":99603295869,"b":[["77670.53000000","13.82151000"],["77482.01000000","0.00000000"],["77454.88000000","0.02017000"],["76762.68000000","0.00007000"],["69903.48000000","0.00240000"]],"a":[["77708.33000000","0.09689000"],["77719.90000000","0.10000000"]]}}
{"type":"depth","received_at_ms":1788407332810,"data":{"e":"depthUpdate","E":1788407333014,"s":"BTCUSDT","U":99603295870,"u":99603295880,"b":[["77670.53000000","13.82159000"],["77656.22000000","0.00007000"],["77648.00000000","0.02265000"],["69903.48000000","0.00272000"],["62136.43000000","0.00032000"]],"a":[["77670.54000000","0.49000000"],["77685.42000000","0.00000000"],["77685.44000000","0.00257000"],["77687.29000000","0.00007000"]]}}
{"type":"depth","received_at_ms":1788407332910,"data":{"e":"depthUpdate","E":1788407333114,"s":"BTCUSDT","U":99603295881,"u":99603295898,"b":[["77670.53000000","13.82159000"],["69903.48000000","0.00272000"],["69903.46000000","0.00000000"],["62136.00000000","0.00215000"]],"a":[["77670.54000000","0.48983000"],["77685.06000000","0.01200000"],["77685.44000000","0.00000000"],["77685.45000000","0.00257000"],["77687.57000000","0.00400000"],["77769.10000000","0.00000000"]]}}
{"type":"depth","received_at_ms":1788407333010,"data":{"e":"depthUpdate","E":1788407333214,"s":"BTCUSDT","U":99603295899,"u":99603295909,"b":[["76505.47000000","0.00030000"],["69903.48000000","0.00288000"],["62136.43000000","0.00000000"],["62136.00000000","0.00015000"]],"a":[["77685.45000000","0.00000000"],["77685.46000000","0.00257000"],["78835.60000000","0.00030000"]]}}
{"type":"depth","received_at_ms":1788407333110,"data":{"e":"depthUpdate","E":1788407333314,"s":"BTCUSDT","U":99603295910,"u":99603295922,"b":[["77591.41000000","0.72120000"],["77588.86000000","0.00000000"],["69903.48000000","0.00304000"],["62136.00000000","0.00015000"]],"a":[["77685.06000000","0.00000000"],["77685.46000000","0.00000000"],["77685.47000000","0.00257000"],["77687.28000000","0.01200000"]]}}
{"type":"depth","received_at_ms":1788407333210,"data":{"e":"depthUpdate","E":1788407333414,"s":"BTCUSDT","U":99603295923,"u":99603295942,"b":[["77648.00000000","0.03265000"],["77638.00000000","0.73000000"],["77636.00000000","0.03000000"],["71456.28000000","0.00014000"],["69903.48000000","0.00304000"]],"a":[["77685.06000000","0.00000000"],["77685.47000000","0.00000000"],["77685.48000000","0.00257000"],["77687.27000000","0.01200000"],["77687.28000000","0.00000000"]]}}
{"type":"depth","received_at_ms":1788407333310,"data":{"e":"depthUpdate","E":1788407333514,"s":"BTCUSDT","U":99603295943,"u":99603295954,"b":[["77670.01000000","0.00014000"],["77647.74000000","0.00000000"],["77506.81000000","0.00000000"],["69903.48000000","0.00320000"],["62136.43000000","0.00032000"]],"a":[["77685.48000000","0.00000000"],["77685.49000000","0.00257000"],["77687.63000000","0.00000000"],["77794.13000000","0.00000000"],["77833.02000000","0.00140000"]]}}
{"type":"depth","received_at_ms":1788407333410,"data":{"e":"depthUpdate","E":1788407333614,"s":"BTCUSDT","U":99603295955,"u":99603295961,"b":[["62136.43000000","0.00000000"],["62136.00000000","0.00015000"]],"a":[["77685.49000000","0.00000000"],["77685.50000000","0.00257000"]]}}
{"type":"depth","received_at_ms":1788407333510,"data":{"e":"depthUpdate","E":1788407333715,"s":"BTCUSDT","U":99603295962,"u":99603295979,"b":[["77670.48000000","0.00007000"],["69903.48000000","0.00336000"],["62136.42000000","0.00000000"]],"a":[["77670.54000000","0.34439000"],["77670.55000000","0.00070000"],["77671.72000000","0.00000000"],["77671.73000000","0.00014000"],["77674.76000000","0.00007000"],["77685.50000000","0.00000000"],["77685.51000000","0.00257000"],["77724.94000000","0.00000000"]]}}
{"type":"depth","received_at_ms":1788407333610,"data":{"e":"depthUpdate","E":1788407333814,"s":"BTCUSDT","U":99603295980,"u":99603295989,"b":[["77662.41000000","0.00200000"],["77647.37000000","0.00200000"],["69903.48000000","0.00336000"]],"a":[["77670.54000000","0.34453000"],["77671.73000000","0.00000000"],["77685.51000000","0.00000000"],["77685.52000000","0.00257000"]]}}
{"type":"depth","received_at_ms":1788407333713,"data":{"e":"depthUpdate","E":1788407333917,"s":"BTCUSDT","U":99603295990,"u":99603295994,"b":[["69903.48000000","0.00352000"],["62136.00000000","0.00015000"]],"a":[["77685.06000000","0.00200000"],["77685.52000000","0.00000000"]]}}
{"type":"depth","received_at_ms":1788407333810,"data":{"e":"depthUpdate","E":1788407334014,"s":"BTCUSDT","U":99603295995,"u":99603296004,"b":[["77656.22000000","0.00000000"],["77652.24000000","0.00183000"],["71456.28000000","0.00000000"],["69903.48000000","0.00352000"],["62136.43000000","0.00032000"],["62136.00000000","0.00015000"]],"a":[["77672.23000000","0.00007000"],["77685.54000000","0.00257000"],["77687.29000000","0.00000000"]]}}
{"type":"depth","received_at_ms":1788407333911,"data":{"e":"depthUpdate","E":1788407334114,"s":"BTCUSDT","U":99603296005,"u":99603296019,"b":[["77670.01000000","0.00014000"],["77662.41000000","0.00000000"],["77656.22000000","0.00007000"],["69903.48000000","0.00368000"]],"a":[["77670.54000000","0.34460000"],["77670.55000000","0.00077000"],["77674.08000000","0.11270000"],["77677.05000000","0.00208000"],["77685.54000000","0.00000000"],["77685.55000000","0.00257000"],["77687.29000000","0.00007000"]]}}
{"type":"depth","received_at_ms":1788407334012,"data":{"e":"depthUpdate","E":1788407334216,"s":"BTCUSDT","U":99603296020,"u":99603296034,"b":[["77663.18000000","0.00200000"],["76505.47000000","0.00030000"],["69903.48000000","0.00352000"],["62136.43000000","0.00000000"]],"a":[["77674.00000000","0.03021000"],["77685.55000000","0.00000000"],["77685.56000000","0.00257000"],["77723.70000000","0.00000000"],["78835.60000000","0.00030000"]]}}
{"type":"depth","received_at_ms":1788407334110,"data":{"e":"depthUpdate","E":1788407334314,"s":"BTCUSDT","U":99603296035,"u":99603296046,"b":[["77670.01000000","0.00014000"],["77663.18000000","0.00200000"],["69903.48000000","0.00384000"],["62136.00000000","0.00015000"]],"a":[["77685.56000000","0.00000000"],["77685.57000000","0.00257000"]]}}
{"type":"depth","received_at_ms":1788407334211,"data":{"e":"depthUpdate","E":1788407334414,"s":"BTCUSDT","U":99603296047,"u":99603296053,"b":[["77670.01000000","0.00014000"],["77663.18000000","0.00000000"],["69903.48000000","0.00384000"]],"a":[["77685.57000000","0.00000000"],["77693.20000000","0.02000000"]]}}
{"type":"depth","received_at_ms":1788407334311,"data":{"e":"depthUpdate","E":1788407334514,"s":"BTCUSDT","U":99603296054,"u":99603296060,"b":[["77663.18000000","0.00200000"],["69903.48000000","0.00393000"],["62136.43000000","0.00032000"]],"a":[["77670.54000000","0.34201000"],["77724.63000000","0.12879000"]]}}
{"type":"depth","received_at_ms":1788407334410,"data":{"e":"depthUpdate","E":1788407334615,"s":"BTCUSDT","U":99603296061,"u":99603296067,"b":[["77670.01000000","0.00214000"],["77663.18000000","0.00000000"],["69903.48000000","0.00425000"],["62136.43000000","0.00000000"],["62136.00000000","0.00215000"]],"a":[["77700.98000000","0.00000000"]]}}
{"type":"depth","received_at_ms":1788407334510,"data":{"e":"depthUpdate","E":1788407334714,"s":"BTCUSDT","U":99603296068,"u":99603296079,"b":[["75561.73000000","0.00000000"],["69903.48000000","0.00425000"],["62136.42000000","0.00000000"],["62136.00000000","0.00015000"]],"a":[["81006.07000000","0.00000000"]]}}
{"type":"depth","received_at_ms":1788407334610,"data":{"e":"depthUpdate","E":1788407334814,"s":"BTCUSDT","U":99603296080,"u":99603296097,"b":[["77667.81000000","0.02896000"],["77667.71000000","0.00007000"],["77546.26000000","0.00073000"],["76277.83000000","0.00300000"],["69903.48000000","0.00441000"]],"a":[["77670.54000000","0.16211000"],["77681.65000000","0.00000000"],["77682.16000000","0.00400000"],["77685.06000000","0.00000000"],["77687.27000000","0.00000000"],["77687.57000000","0.00600000"],["77688.19000000","0.01200000"]]}}
{"type":"depth","received_at_ms":1788407334710,"data":{"e":"depthUpdate","E":1788407334914,"s":"BTCUSDT","U":99603296098,"u":99603296101,"b":[["77670.53000000","13.82151000"],["77668.00000000","0.02576000"],["77660.00000000","0.00000000"]],"a":[]}}
{"type":"depth","received_at_ms":1788407334811,"data":{"e":"depthUpdate","E":1788407335014,"s":"BTCUSDT","U":99603296102,"u":99603296114,"b":[["77668.61000000","0.01691000"],["77507.48000000","0.00073000"],["69903.48000000","0.00457000"],["62136.43000000","0.00032000"]],"a":[["77674.08000000","0.11284000"],["77685.06000000","0.00000000"],["77687.28000000","0.00200000"],["77687.57000000","0.00400000"]]}}
{"type":"depth","received_at_ms":1788407334910,"data":{"e":"depthUpdate","E":1788407335114,"s":"BTCUSDT","U":99603296115,"u":99603296142,"b":[["77670.53000000","13.82559000"],["77670.48000000","0.00014000"],["77670.02000000","0.00000000"],["77670.01000000","0.00600000"],["77670.00000000","0.01228000"],["77669.86000000","4.95341000"],["77656.22000000","0.00007000"],["77650.20000000","0.00200000"],["77647.37000000","0.00000000"],["77631.71000000","0.07061000"],["69903.48000000","0.00441000"]],"a":[["77670.68000000","0.00007000"],["77674.07000000","0.00207000"],["77687.29000000","0.00007000"],["77688.18000000","0.01200000"],["77688.19000000","0.00000000"]]}}
{"type":"depth","received_at_ms":1788407335010,"data":{"e":"depthUpdate","E":1788407335214,"s":"BTCUSDT","U":99603296143,"u":99603296153,"b":[["77650.20000000","0.00000000"],["77648.83000000","0.00200000"],["76505.47000000","0.00030000"],["69903.48000000","0.00457000"],["62136.43000000","0.00000000"]],"a":[["77723.82000000","0.00000000"],["77724.63000000","0.00000000"],["78835.60000000","0.00030000"]]}}
{"type":"depth","received_at_ms":1788407335110,"data":{"e":"depthUpdate","E":1788407335314,"s":"BTCUSDT","U":99603296154,"u":99603296173,"b":[["77670.53000000","13.82530000"],["77670.47000000","0.04038000"],["69903.48000000","0.00432000"],["69903.47000000","0.00009000"],["62136.00000000","0.00015000"]],"a":[["77670.54000000","0.16205000"],["77687.28000000","0.00000000"],["77688.36000000","0.00000000"],["77724.03000000","0.00000000"],["77724.18000000","0.00000000"],["77794.80000000","0.00106000"]]}}
{"type":"depth","received_at_ms":1788407335210,"data":{"e":"depthUpdate","E":1788407335414,"s":"BTCUSDT","U":99603296174,"u":99603296188,"b":[["77645.23000000","0.00000000"],["77621.94000000","0.00000000"],["77575.78000000","0.04015000"],["77566.49000000","0.00000000"],["72500.00000000","46.94107000"],["69903.48000000","0.00448000"],["62136.00000000","0.00015000"]],"a":[["77685.06000000","0.00200000"],["77702.74000000","0.00000000"],["77726.62000000","0.00000000"],["77799.55000000","0.00000000"],["77808.86000000","0.00971000"]]}}
{"type":"depth","received_at_ms":1788407335310,"data":{"e":"depthUpdate","E":1788407335514,"s":"BTCUSDT","U":99603296189,"u":99603296192,"b":[["69903.48000000","0.00432000"],["62136.43000000","0.00032000"]],"a":[["77685.67000000","0.00257000"],["77723.52000000","0.12879000"]]}}
{"type":"depth","received_at_ms":1788407335409,"data":{"e":"depthUpdate","E":1788407335614,"s":"BTCUSDT","U":99603296193,"u":99603296205,"b":[["77663.08000000","0.00000000"],["77660.34000000","0.02000000"],["77624.24000000","0.00000000"],["77604.81000000","0.00000000"],["69903.48000000","0.00448000"],["69903.47000000","0.00000000"],["62136.43000000","0.00000000"]],"a":[["77670.54000000","0.16166000"],["77685.06000000","0.00000000"],["77685.67000000","0.00000000"],["77685.68000000","0.00257000"],["77685.87000000","0.00000000"],["77688.19000000","0.00200000"],["77705.29000000","0.00000000"],["77723.52000000","0.00000000"],["77724.72000000","0.00000000"]]}}
{"type":"depth","received_at_ms":1788407335511,"data":{"e":"depthUpdate","E":1788407335714,"s":"BTCUSDT","U":99603296206,"u":99603296220,"b":[["77652.29000000","0.00000000"],["77650.27000000","0.50011000"],["77626.41000000","0.97587000"],["75561.73000000","0.00010000"],["69903.48000000","0.00432000"],["62136.42000000","0.00020000"]],"a":[["77685.06000000","0.00000000"],["77688.19000000","0.00000000"],["77700.02000000","0.50220000"],["77723.90000000","0.98556000"]]}}
{"type":"depth","received_at_ms":1788407335611,"data":{"e":"depthUpdate","E":1788407335814,"s":"BTCUSDT","U":99603296221,"u":99603296230,"b":[["77664.97000000","0.02000000"],["77661.08000000","0.02200000"],["69903.48000000","0.00432000"],["62136.42000000","0.00000000"],["62136.00000000","0.00015000"]],"a":[["77685.06000000","0.00200000"],["77685.68000000","0.00000000"],["77685.69000000","0.00257000"]]}}
{"type":"depth","received_at_ms":1788407335711,"data":{"e":"depthUpdate","E":1788407335915,"s":"BTCUSDT","U":99603296231,"u":99603296238,"b":[["77593.90000000","0.00000000"],["77590.02000000","0.00000000"],["69903.48000000","0.00432000"]],"a":[["77685.06000000","0.00000000"],["77685.69000000","0.00000000"],["77688.19000000","0.00200000"],["81006.07000000","0.00010000"]]}}
{"type":"depth","received_at_ms":1788407335810,"data":{"e":"depthUpdate","E":1788407336014,"s":"BTCUSDT","U":99603296239,"u":99603296249,"b":[["77656.95000000","0.00000000"],["77653.07000000","0.00000000"],["69903.48000000","0.00432000"],["62136.43000000","0.00032000"]],"a":[["77685.70000000","0.00000000"],["77685.71000000","0.00257000"],["77723.44000000","0.12879000"]]}}
{"type":"depth","received_at_ms":1788407335910,"data":{"e":"depthUpdate","E":1788407336114,"s":"BTCUSDT","U":99603296250,"u":99603296273,"b":[["77670.53000000","13.80268000"],["77656.22000000","0.00007000"],["77648.79000000","0.04669000"],["77648.70000000","0.00000000"],["69903.48000000","0.00432000"],["69903.47000000","0.00009000"],["62136.00000000","0.00215000"]],"a":[["77685.06000000","0.00000000"],["77686.58000000","0.00000000"],["77687.13000000","0.00400000"],["77687.29000000","0.00007000"],["77688.19000000","0.00000000"],["77697.69000000","0.04665000"],["77714.16000000","0.00000000"],["77715.92000000","0.00000000"],["77720.78000000","0.90438000"],["77723.44000000","0.00000000"],["77723.53000000","0.00000000"]]}}
{"type":"depth","received_at_ms":1788407336010,"data":{"e":"depthUpdate","E":1788407336214,"s":"BTCUSDT","U":99603296274,"u":99603296291,"b":[["76505.47000000","0.00030000"],["69903.48000000","0.00432000"],["62136.43000000","0.00000000"],["62136.00000000","0.00015000"]],"a":[["77670.54000000","0.15931000"],["77674.08000000","0.00021000"],["77688.19000000","0.00200000"],["77723.02000000","0.00000000"],["77723.13000000","0.12879000"],["77723.71000000","0.00000000"],["77833.69000000","0.00106000"],["78835.60000000","0.00030000"]]}}
{"type":"depth","received_at_ms":1788407336110,"data":{"e":"depthUpdate","E":1788407336314,"s":"BTCUSDT","U":99603296292,"u":99603296330,"b":[["77669.87000000","1.39573000"],["77669.86000000","4.95133000"],["77665.12000000","0.00000000"],["77664.16000000","0.02200000"],["77625.31000000","0.02200000"],["69903.48000000","0.00464000"],["62136.00000000","0.00015000"]],"a":[["77670.54000000","0.15924000"],["77670.55000000","0.00070000"],["77674.00000000","0.03021000"],["77674.07000000","0.00200000"],["77674.08000000","0.00007000"],["77675.99000000","0.19969000"],["77676.41000000","0.00000000"],["77677.05000000","0.00000000"],["77678.64000000","0.00007000"],["77685.71000000","0.00000000"],["77685.72000000","0.00008000"],["77685.73000000","0.00257000"],["77687.13000000","0.00000000"],["77687.73000000","0.00400000"],["77689.06000000","0.02000000"],["77707.30000000","0.00000000"],["77708.49000000","0.02000000"],["77711.13000000","0.32967000"],["77723.13000000","0.00000000"],["77723.33000000","0.00000000"],["77727.91000000","0.02000000"],["77769.09000000","0.00089000"]]}}
{"type":"depth","received_at_ms":1788407336211,"data":{"e":"depthUpdate","E":1788407336414,"s":"BTCUSDT","U":99603296331,"u":99603296337,"b":[["77670.48000000","0.00414000"],["69903.48000000","0.00432000"],["62136.00000000","0.00015000"]],"a":[["77670.54000000","0.15917000"],["77687.64000000","0.00000000"],["77689.20000000","0.00643000"]]}}
{"type":"depth","received_at_ms":1788407336310,"data":{"e":"depthUpdate","E":1788407336514,"s":"BTCUSDT","U":99603296338,"u":99603296360,"b":[["77670.53000000","13.80268000"],["77663.00000000","0.00000000"],["77624.15000000","0.00000000"],["77604.73000000","0.00000000"],["77495.59000000","0.00000000"],["69903.48000000","0.00464000"],["62136.43000000","0.00032000"]],"a":[["77674.99000000","0.10880000"],["77685.73000000","0.00000000"],["77685.85000000","0.00000000"],["77688.18000000","0.00000000"],["77688.19000000","0.00000000"],["77688.36000000","0.01200000"],["77688.45000000","0.00200000"],["77700.00000000","0.21777000"],["77705.27000000","0.00000000"],["77708.33000000","0.00000000"],["77714.35000000","0.00863000"],["77723.67000000","0.00000000"],["77724.70000000","0.00000000"],["77852.58000000","0.00000000"]]}}
{"type":"depth","received_at_ms":1788407336410,"data":{"e":"depthUpdate","E":1788407336614,"s":"BTCUSDT","U":99603296361,"u":99603296402,"b":[["77670.53000000","13.80268000"],["77670.01000000","0.00207000"],["77670.00000000","0.01628000"],["77669.87000000","1.39566000"],["69903.48000000","0.00448000"],["62136.43000000","0.00000000"],["62136.00000000","0.00015000"]],"a":[["77670.54000000","0.15909000"],["77674.77000000","0.10036000"],["77674.99000000","0.10894000"],["77675.99000000","0.19955000"],["77678.64000000","0.00014000"],["77687.28000000","0.00200000"],["77687.42000000","0.00400000"],["77687.72000000","0.00800000"],["77687.73000000","0.00000000"],["77688.35000000","0.00400000"],["77688.36000000","0.00000000"],["77688.45000000","0.00000000"],["77714.35000000","0.00000000"],["77724.21000000","1.59627000"]]}}
{"type":"depth","received_at_ms":1788407336510,"data":{"e":"depthUpdate","E":1788407336714,"s":"BTCUSDT","U":99603296403,"u":99603296413,"b":[["77670.47000000","0.04038000"],["77497.31000000","4.59375000"],["69903.48000000","0.00464000"]],"a":[["77670.54000000","0.15940000"],["77854.07000000","4.41271000"]]}}
{"type":"depth","received_at_ms":1788407336611,"data":{"e":"depthUpdate","E":1788407336814,"s":"BTCUSDT","U":99603296414,"u":99603296469,"b":[["77670.53000000","13.78323000"],["77670.01000000","0.00400000"],["77670.00000000","0.01228000"],["77669.92000000","0.00400000"],["77663.18000000","0.00200000"],["77659.05000000","0.00000000"],["77645.46000000","0.02000000"],["77641.57000000","0.02200000"],["77593.90000000","0.02000000"],["77590.02000000","0.02200000"],["69903.48000000","0.00448000"],["69903.47000000","0.00000000"],["69903.46000000","0.00009000"],["62136.42000000","0.00000000"]],"a":[["77670.54000000","0.34265000"],["77670.55000000","0.00077000"],["77671.97000000","0.00014000"],["77671.98000000","0.10235000"],["77673.74000000","0.00014000"],["77673.75000000","0.11264000"],["77673.99000000","0.00000000"],["77674.76000000","0.00000000"],["77674.99000000","0.00014000"],["77682.16000000","0.00000000"],["77685.06000000","0.00000000"],["77685.91000000","0.00400000"],["77687.27000000","0.00400000"],["77687.28000000","0.00000000"],["77687.42000000","0.00000000"],["77687.72000000","0.00000000"],["77688.35000000","0.00000000"],["77724.68000000","0.12879000"]]}}
{"type":"depth","received_at_ms":1788407336710,"data":{"e":"depthUpdate","E":1788407336914,"s":"BTCUSDT","U":99603296470,"u":99603296528,"b":[["77670.53000000","13.79609000"],["77670.02000000","0.00000000"],["77670.00000000","0.01428000"],["77663.18000000","0.00000000"],["77639.00000000","0.70000000"],["77638.00000000","0.03000000"],["77593.90000000","0.00000000"],["77590.02000000","0.00000000"],["69903.48000000","0.00464000"]],"a":[["77670.54000000","0.33915000"],["77670.55000000","0.00084000"],["77671.98000000","0.10249000"],["77673.38000000","0.09898000"],["77673.75000000","0.11278000"],["77674.77000000","0.10036000"],["77674.99000000","0.00000000"],["77675.34000000","0.00890000"],["77675.99000000","0.00000000"],["77678.32000000","0.00000000"],["77681.08000000","0.00000000"],["77681.61000000","0.00400000"],["77684.86000000","0.00000000"],["77685.06000000","0.00200000"],["77685.91000000","0.00000000"],["77686.83000000","0.00400000"],["77687.28000000","0.00800000"]]}}
{"type":"depth","received_at_ms":1788407336810,"data":{"e":"depthUpdate","E":1788407337014,"s":"BTCUSDT","U":99603296529,"u":99603296541,"b":[["77664.06000000","0.02000000"],["77659.05000000","0.08643000"],["77625.21000000","0.02000000"],["69903.48000000","0.00448000"],["62136.43000000","0.00032000"],["62136.00000000","0.00015000"]],"a":[["77678.32000000","0.18065000"],["77689.00000000","0.02000000"],["77708.43000000","0.02000000"],["77727.85000000","0.02000000"]]}}
{"type":"depth","received_at_ms":1788407336910,"data":{"e":"depthUpdate","E":1788407337115,"s":"BTCUSDT","U":99603296542,"u":99603296565,"b":[["77670.53000000","13.79817000"],["77656.22000000","0.00000000"],["69903.48000000","0.00464000"]],"a":[["77670.54000000","0.33937000"],["77670.55000000","0.00091000"],["77672.84000000","0.00000000"],["77673.83000000","0.00560000"],["77677.23000000","0.00104000"],["77678.02000000","0.00104000"],["77678.33000000","0.20011000"],["77681.61000000","0.00000000"],["77682.20000000","0.00400000"],["77685.06000000","0.00000000"],["77687.27000000","0.00000000"],["77687.28000000","0.00000000"],["77687.29000000","0.00000000"],["77688.36000000","0.01200000"],["77688.45000000","0.00000000"],["77714.37000000","0.00847000"]]}}
{"type":"depth","received_at_ms":1788407337010,"data":{"e":"depthUpdate","E":1788407337214,"s":"BTCUSDT","U":99603296566,"u":99603296593,"b":[["77670.00000000","0.01228000"],["77656.22000000","0.00007000"],["76505.47000000","0.00030000"],["69903.48000000","0.00448000"],["62136.43000000","0.00000000"]],"a":[["77670.54000000","0.33923000"],["77670.55000000","0.00084000"],["77673.75000000","0.11278000"],["77673.77000000","0.00000000"],["77673.83000000","0.00574000"],["77674.77000000","0.10022000"],["77685.06000000","0.00200000"],["77687.29000000","0.00007000"],["77708.43000000","0.11421000"],["77724.68000000","0.00000000"],["78835.60000000","0.00030000"]]}}
{"type":"depth","received_at_ms":1788407337110,"data":{"e":"depthUpdate","E":1788407337314,"s":"BTCUSDT","U":99603296594,"u":99603296616,"b":[["77670.53000000","13.79779000"],["77663.18000000","0.00200000"],["77605.88000000","0.02215000"],["69903.48000000","0.00448000"],["69903.46000000","0.00000000"],["62136.00000000","0.00015000"]],"a":[["77670.68000000","0.00000000"],["77685.06000000","0.00200000"],["77687.28000000","0.01200000"],["77688.36000000","0.00000000"]]}}
{"type":"depth","received_at_ms":1788407337210,"data":{"e":"depthUpdate","E":1788407337414,"s":"BTCUSDT","U":99603296617,"u":99603296624,"b":[["77670.00000000","0.01428000"],["77663.18000000","0.00000000"],["62136.00000000","0.00015000"]],"a":[["77670.54000000","0.33857000"],["77673.83000000","0.00014000"]]}}
{"type":"depth","received_at_ms":1788407337310,"data":{"e":"depthUpdate","E":1788407337515,"s":"BTCUSDT","U":99603296625,"u":99603296641,"b":[["77662.91000000","0.00000000"],["77624.06000000","0.00000000"],["77604.64000000","0.00000000"],["69903.48000000","0.00448000"],["62136.43000000","0.00032000"]],"a":[["77670.54000000","0.33850000"],["77670.55000000","0.00077000"],["77673.75000000","0.11278000"],["77673.83000000","0.00000000"],["77674.77000000","0.10036000"],["77685.77000000","0.00000000"],["77704.00000000","0.73000000"],["77705.20000000","0.00000000"],["77724.62000000","0.00000000"]]}}
{"type":"depth","received_at_ms":1788407337410,"data":{"e":"depthUpdate","E":1788407337615,"s":"BTCUSDT","U":99603296642,"u":99603296656,"b":[["77640.00000000","0.73188000"],["77639.00000000","0.00000000"],["77600.01000000","0.00321000"],["77599.20000000","0.00000000"],["77596.01000000","0.00321000"],["77594.31000000","0.00000000"],["77282.17000000","0.00007000"],["69903.48000000","0.00464000"],["62136.43000000","0.00000000"]],"a":[["77685.32000000","0.00257000"],["77687.98000000","0.00643000"],["77689.20000000","0.00000000"],["77726.92000000","0.00000000"],["77727.84000000","0.00319000"],["77727.99000000","0.00000000"],["77728.89000000","0.00320000"],["77804.27000000","0.00000000"],["77805.56000000","0.00128000"],["77805.57000000","0.01737000"],["77807.26000000","0.00128000"]]}}
{"type":"depth","received_at_ms":1788407337510,"data":{"e":"depthUpdate","E":1788407337714,"s":"BTCUSDT","U":99603296657,"u":99603296756,"b":[["77670.53000000","13.79939000"],["77670.48000000","0.00014000"],["77670.02000000","0.00007000"],["77670.01000000","0.31266000"],["77669.86000000","4.94980000"],["77669.50000000","0.02000000"],["77664.25000000","0.41262000"],["77661.05000000","0.00000000"],["77644.78000000","0.34787000"],["77635.49000000","1.27569000"],["77625.52000000","0.00000000"],["77616.74000000","0.00000000"],["77436.82000000","0.00000000"],["69903.48000000","0.00441000"]],"a":[["77670.54000000","0.11919000"],["77670.55000000","0.00063000"],["77671.97000000","0.00000000"],["77671.98000000","0.00014000"],["77673.37000000","0.00000000"],["77673.38000000","0.00014000"],["77673.42000000","0.09988000"],["77673.74000000","0.00000000"],["77673.75000000","0.00014000"],["77673.99000000","0.00014000"],["77674.76000000","0.00014000"],["77675.70000000","0.00027000"],["77675.72000000","0.00000000"],["77675.99000000","0.00007000"],["77677.23000000","0.00000000"],["77678.32000000","0.00000000"],["77678.60000000","0.00000000"],["77680.49000000","0.00000000"],["77680.74000000","0.00000000"],["77681.48000000","0.00000000"],["77682.20000000","0.00000000"],["77682.23000000","0.17548000"],["77683.26000000","0.00400000"],["77685.06000000","0.00000000"],["77685.28000000","0.00000000"],["77685.32000000","0.00000000"],["77686.83000000","0.00000000"],["77687.26000000","0.00257000"],["77687.27000000","0.00000000"],["77687.28000000","0.00000000"],["77687.57000000","0.00000000"],["77687.98000000","0.00000000"],["77688.45000000","0.00800000"],["77688.97000000","0.00800000"],["77689.01000000","0.00400000"],["77689.05000000","0.00000000"],["77689.20000000","0.00200000"],["77689.52000000","0.00000000"],["77689.53000000","0.10235000"],["77690.42000000","0.00643000"],["77691.14000000","0.10235000"],["77696.00000000","0.03007000"],["77701.17000000","0.00000000"],["77704.00000000","0.73258000"],["77708.43000000","0.02000000"],["77714.37000000","0.00000000"],["77720.75000000","0.34753000"],["77769.09000000","0.00000000"]]}}
{"type":"depth","received_at_ms":1788407337610,"data":{"e":"depthUpdate","E":1788407337814,"s":"BTCUSDT","U":99603296757,"u":99603296817,"b":[["77670.48000000","0.00414000"],["77670.47000000","0.04038000"],["77669.53000000","0.08301000"],["77663.96000000","0.02000000"],["77655.19000000","0.00000000"],["77625.11000000","0.02000000"],["77575.78000000","0.00022000"],["77573.90000000","0.04379000"],["69903.48000000","0.00473000"],["62136.42000000","0.00000000"]],"a":[["77670.54000000","0.11933000"],["77671.98000000","0.00000000"],["77673.29000000","0.03193000"],["77673.38000000","0.00000000"],["77673.41000000","0.00007000"],["77673.42000000","0.10002000"],["77673.75000000","0.00000000"],["77673.77000000","0.00007000"],["77675.34000000","0.00904000"],["77675.99000000","0.00000000"],["77676.00000000","0.03014000"],["77678.32000000","0.17731000"],["77680.20000000","0.00000000"],["77681.46000000","0.00666000"],["77685.36000000","0.56398000"],["77687.25000000","0.00257000"],["77687.26000000","0.00000000"],["77687.57000000","0.00400000"],["77688.44000000","1.15151000"],["77688.87000000","0.02000000"],["77689.01000000","0.00000000"],["77691.14000000","0.00000000"],["77708.30000000","0.02000000"],["77715.30000000","0.00400000"],["77727.72000000","0.02000000"],["77806.98000000","0.00971000"],["77808.86000000","0.00000000"]]}}
{"type":"depth","received_at_ms":1788407337709,"data":{"e":"depthUpdate","E":1788407337914,"s":"BTCUSDT","U":99603296818,"u":99603296825,"b":[["69903.48000000","0.00457000"]],"a":[["77670.54000000","0.11940000"],["77670.55000000","0.00070000"],["77670.68000000","0.00007000"],["77687.25000000","0.00000000"],["77723.65000000","0.11933000"]]}}
{"type":"depth","received_at_ms":1788407337811,"data":{"e":"depthUpdate","E":1788407338014,"s":"BTCUSDT","U":99603296826,"u":99603296834,"b":[["77605.78000000","0.02023000"],["69903.48000000","0.00457000"],["62136.43000000","0.00032000"]],"a":[["77686.48000000","0.00257000"],["77689.05000000","0.00643000"],["77690.42000000","0.00000000"],["77723.65000000","0.00000000"],["77723.90000000","0.98556000"]]}}
{"type":"depth","received_at_ms":1788407337910,"data":{"e":"depthUpdate","E":1788407338114,"s":"BTCUSDT","U":99603296835,"u":99603296849,"b":[["77659.04000000","4.94837000"],["69903.48000000","0.00457000"]],"a":[["77670.54000000","0.11940000"],["77686.45000000","0.00257000"],["77686.48000000","0.00000000"],["77713.35000000","0.00400000"],["77715.30000000","0.00000000"],["77723.71000000","0.00000000"],["77800.67000000","0.00000000"],["77809.03000000","0.02017000"]]}}
{"type":"depth","received_at_ms":1788407338011,"data":{"e":"depthUpdate","E":1788407338215,"s":"BTCUSDT","U":99603296850,"u":99603296873,"b":[["77656.22000000","0.00007000"],["76505.47000000","0.00030000"],["69903.48000000","0.00473000"],["62136.43000000","0.00000000"]],"a":[["77670.54000000","0.12115000"],["77682.23000000","0.17948000"],["77683.26000000","0.00000000"],["77686.43000000","0.00257000"],["77686.45000000","0.00000000"],["77687.29000000","0.00007000"],["77688.43000000","0.00200000"],["77689.20000000","0.00000000"],["77714.66000000","0.00865000"],["77723.63000000","0.00000000"],["77723.97000000","0.00000000"],["78835.60000000","0.00030000"]]}}
{"type":"depth","received_at_ms":1788407338111,"data":{"e":"depthUpdate","E":1788407338314,"s":"BTCUSDT","U":99603296874,"u":99603296891,"b":[["77670.02000000","0.00207000"],["77670.00000000","0.01228000"],["77663.18000000","0.00000000"],["69903.48000000","0.00457000"],["62136.00000000","0.00015000"]],"a":[["77670.54000000","0.12122000"],["77670.55000000","0.00077000"],["77673.41000000","0.00014000"],["77674.70000000","0.12091000"],["77674.76000000","0.00007000"],["77686.40000000","0.00257000"],["77686.43000000","0.00000000"],["77688.43000000","0.00000000"],["77724.09000000","0.11940000"]]}}
{"type":"depth","received_at_ms":1788407338213,"data":{"e":"depthUpdate","E":1788407338414,"s":"BTCUSDT","U":99603296892,"u":99603297434,"b":[["77671.99000000","14.07086000"],["77671.98000000","0.00014000"],["77671.58000000","0.00000000"],["77671.44000000","0.00000000"],["77671.11000000","0.00000000"],["77670.92000000","0.00014000"],["77670.91000000","0.00000000"],["77670.90000000","0.00000000"],["77670.68000000","0.00000000"],["77670.67000000","0.00000000"],["77670.55000000","0.00000000"],["77670.54000000","0.32631000"],["77670.53000000","4.77453000"],["77670.52000000","0.00000000"],["77670.48000000","0.00000000"],["77670.47000000","0.04045000"],["77670.02000000","0.00200000"],["77670.01000000","0.31280000"],["77670.00000000","0.01214000"],["77669.99000000","0.00014000"],["77669.92000000","0.00000000"],["77669.88000000","0.00000000"],["77669.87000000","1.26588000"],["77669.86000000","0.18272000"],["77669.84000000","0.00008000"],["77669.53000000","0.08308000"],["77669.50000000","0.02007000"],["77669.31000000","0.03259000"],["77668.62000000","0.18531000"],["77668.61000000","0.01698000"],["77668.37000000","0.00000000"],["77667.85000000","0.00007000"],["77667.60000000","0.00000000"],["77667.18000000","0.00007000"],["77666.17000000","0.00013000"],["77665.11000000","0.00007000"],["77664.73000000","0.00000000"],["77664.22000000","0.00008000"],["77663.71000000","0.00000000"],["77663.16000000","0.14586000"],["77663.14000000","0.00007000"],["77662.29000000","0.00007000"],["77661.76000000","0.00000000"],["77661.70000000","0.08643000"],["77661.69000000","0.04000000"],["77661.57000000","0.00008000"],["77659.35000000","0.00000000"],["77659.05000000","0.00000000"],["77653.81000000","0.00000000"],["77651.98000000","0.00200000"],["77648.83000000","0.00000000"],["77648.23000000","0.00000000"],["77645.74000000","0.00000000"],["77641.85000000","0.00000000"],["77635.89000000","0.56619000"],["77632.32000000","0.00000000"],["77631.00000000","0.00000000"],["77623.24000000","1.89323000"],["77623.23000000","4.63496000"],["77623.19000000","0.00000000"],["77623.18000000","1.13026000"],["77620.11000000","0.00000000"],["77613.27000000","0.00000000"],["77609.43000000","0.00000000"],["77588.20000000","0.00000000"],["77587.31000000","0.00000000"],["77583.35000000","0.00000000"],["76505.47000000","0.00000000"],["69904.80000000","0.00016000"],["69903.48000000","0.00000000"],["69903.47000000","0.00009000"],["66019.64000000","0.00136000"]],"a":[["77670.54000000","0.00000000"],["77670.55000000","0.00000000"],["77670.68000000","0.00000000"],["77670.91000000","0.00000000"],["77670.92000000","0.00000000"],["77671.12000000","0.00000000"],["77671.23000000","0.00000000"],["77671.45000000","0.00000000"],["77671.59000000","0.00000000"],["77671.99000000","0.00000000"],["77672.00000000","0.01291000"],["77672.01000000","0.00063000"],["77673.28000000","0.00000000"],["77673.29000000","0.00014000"],["77673.41000000","0.00000000"],["77673.42000000","0.00014000"],["77674.09000000","0.00555000"],["77674.69000000","0.00000000"],["77674.70000000","0.00014000"],["77674.74000000","0.00014000"],["77674.75000000","0.03179000"],["77674.76000000","0.00000000"],["77674.77000000","0.00014000"],["77675.36000000","0.00000000"],["77675.58000000","0.00000000"],["77675.70000000","0.00000000"],["77675.99000000","0.00014000"],["77676.00000000","0.03014000"],["77676.16000000","0.00014000"],["77676.17000000","0.09976000"],["77676.18000000","0.00000000"],["77676.51000000","0.00627000"],["77676.74000000","0.00000000"],["77676.75000000","0.00000000"],["77676.93000000","0.00007000"],["77677.31000000","0.00000000"],["77677.33000000","0.00000000"],["77677.76000000","0.10235000"],["77677.82000000","0.01081000"],["77678.02000000","0.00000000"],["77678.03000000","0.00000000"],["77678.32000000","0.00000000"],["77678.33000000","0.00000000"],["77678.64000000","0.00007000"],["77679.20000000","0.10235000"],["77679.77000000","0.00008000"],["77680.41000000","0.00000000"],["77680.64000000","0.09471000"],["77680.94000000","0.00000000"],["77682.08000000","0.10235000"],["77682.22000000","0.00000000"],["77682.23000000","0.00000000"],["77682.50000000","0.00007000"],["77683.19000000","0.17425000"],["77683.52000000","0.10235000"],["77684.34000000","0.00000000"],["77684.55000000","0.00400000"],["77684.91000000","0.02007000"],["77685.21000000","0.15000000"],["77685.36000000","0.47585000"],["77686.39000000","0.00000000"],["77686.40000000","0.00000000"],["77687.57000000","0.00000000"],["77688.36000000","0.00200000"],["77688.43000000","1.15151000"],["77688.44000000","0.00000000"],["77688.46000000","0.00000000"],["77689.05000000","0.00000000"],["77689.28000000","0.00257000"],["77689.53000000","0.10235000"],["77689.54000000","0.66324000"],["77690.34000000","0.00000000"],["77690.54000000","0.00400000"],["77691.13000000","0.10235000"],["77691.14000000","0.00643000"],["77691.96000000","0.00000000"],["77692.14000000","0.00000000"],["77692.58000000","0.09705000"],["77692.59000000","1.15151000"],["77692.60000000","0.00000000"],["77693.39000000","1.74616000"],["77693.40000000","0.00000000"],["77694.13000000","0.00000000"],["77695.02000000","0.00000000"],["77696.33000000","4.63496000"],["77696.34000000","0.90970000"],["77696.35000000","0.00000000"],["77697.27000000","0.24299000"],["77697.28000000","0.00000000"],["77697.83000000","0.00128000"],["77699.40000000","0.12870000"],["77699.47000000","0.53607000"],["77699.87000000","0.30866000"],["77700.02000000","0.00000000"],["77701.50000000","2.35031000"],["77701.51000000","4.63496000"],["77702.34000000","0.00000000"],["77704.00000000","0.03258000"],["77706.28000000","0.00000000"],["77709.52000000","0.00014000"],["77710.00000000","0.03200000"],["77711.00000000","0.01000000"],["77711.40000000","0.02000000"],["77714.66000000","0.00027000"],["77716.60000000","0.00000000"],["77716.91000000","0.00824000"],["77717.24000000","0.00007000"],["77719.53000000","0.00008000"],["77722.34000000","0.38525000"],["77723.90000000","0.00000000"],["77724.09000000","0.00000000"],["77731.57000000","0.00000000"],["77758.56000000","0.00000000"],["77759.28000000","0.00007000"],["77774.99000000","0.00000000"],["77777.54000000","2.60865000"],["77787.93000000","0.00000000"],["77873.93000000","0.00007000"],["77877.81000000","0.00007000"],["78029.33000000","0.01278000"],["78835.60000000","0.00000000"]]}}
{"type":"depth","received_at_ms":1788407338311,"data":{"e":"depthUpdate","E":1788407338514,"s":"BTCUSDT","U":99603297435,"u":99603297580,"b":[["77671.99000000","14.38932000"],["77670.55000000","0.00014000"],["77670.54000000","0.32659000"],["77670.02000000","0.00000000"],["77670.00000000","0.01200000"],["77669.99000000","0.00014000"],["77669.88000000","0.00014000"],["77669.86000000","0.17262000"],["77669.54000000","0.00007000"],["77669.31000000","0.03266000"],["77668.61000000","0.00014000"],["77667.71000000","0.00000000"],["77667.37000000","0.00000000"],["77666.88000000","0.49816000"],["77666.85000000","0.00000000"],["77666.13000000","0.00000000"],["77665.57000000","0.00000000"],["77665.14000000","0.00200000"],["77664.98000000","0.00000000"],["77663.60000000","0.00000000"],["77663.16000000","0.13389000"],["77655.79000000","0.00012000"],["77651.98000000","0.00000000"],["77650.69000000","0.00000000"],["77648.74000000","0.00210000"],["77648.00000000","0.03007000"],["77633.00000000","0.01000000"],["77624.75000000","0.00000000"],["77621.20000000","0.00427000"],["77619.85000000","0.00012000"],["77611.93000000","0.00000000"],["77605.38000000","0.01698000"],["77605.32000000","0.00000000"],["77604.28000000","0.00537000"],["77467.81000000","0.00000000"],["69904.80000000","0.00032000"],["66021.20000000","0.00017000"],["62137.60000000","0.00032000"]],"a":[["77672.00000000","0.01298000"],["77672.01000000","0.00063000"],["77673.29000000","0.00000000"],["77673.42000000","0.00000000"],["77674.09000000","0.00021000"],["77674.70000000","0.00000000"],["77674.75000000","0.03207000"],["77674.77000000","0.00000000"],["77674.87000000","0.00014000"],["77674.88000000","0.10235000"],["77675.34000000","0.00014000"],["77676.00000000","0.03021000"],["77676.17000000","0.09997000"],["77676.51000000","0.00641000"],["77676.58000000","0.00014000"],["77676.93000000","0.00000000"],["77677.82000000","0.00013000"],["77678.64000000","0.00007000"],["77679.26000000","0.00208000"],["77679.62000000","0.09989000"],["77679.87000000","0.00000000"],["77682.50000000","0.00014000"],["77682.81000000","0.00000000"],["77683.33000000","0.00400000"],["77684.55000000","0.00000000"],["77684.91000000","0.00007000"],["77686.95000000","0.00000000"],["77688.36000000","0.00000000"],["77688.67000000","0.00257000"],["77688.68000000","0.00000000"],["77689.28000000","0.00000000"],["77689.54000000","1.94622000"],["77689.58000000","0.00400000"],["77690.54000000","0.00000000"],["77691.11000000","0.00000000"],["77691.12000000","4.63496000"],["77691.13000000","0.00000000"],["77692.58000000","0.00000000"],["77697.27000000","0.37194000"],["77704.33000000","0.00000000"],["77707.87000000","0.00012000"],["77716.91000000","0.00000000"],["77717.24000000","0.00007000"],["77717.34000000","0.04692000"],["77723.76000000","0.00000000"],["77745.02000000","0.00112000"],["77778.58000000","0.41569000"],["77778.60000000","0.00000000"],["77877.81000000","0.00000000"],["77879.49000000","0.00000000"],["77890.22000000","0.02017000"]]}}
{"type":"depth","received_at_ms":1788407338411,"data":{"e":"depthUpdate","E":1788407338614,"s":"BTCUSDT","U":99603297581,"u":99603297629,"b":[["77671.99000000","14.40874000"],["77670.74000000","0.01684000"],["77670.00000000","0.01214000"],["77669.50000000","0.04028000"],["77668.26000000","0.02021000"],["77282.17000000","0.00000000"],["69904.80000000","0.00064000"],["62137.60000000","0.00000000"]],"a":[["77672.00000000","0.01298000"],["77674.00000000","0.03021000"],["77674.09000000","0.00007000"],["77674.75000000","0.03207000"],["77674.88000000","0.10249000"],["77675.34000000","0.00000000"],["77676.22000000","0.00534000"],["77676.51000000","0.00641000"],["77676.58000000","0.00000000"],["77676.94000000","0.32211000"],["77677.47000000","0.00890000"],["77677.76000000","0.10249000"],["77678.71000000","0.01068000"],["77679.95000000","0.01068000"],["77688.19000000","0.00200000"],["77688.67000000","0.00000000"],["77691.11000000","0.30866000"],["77703.46000000","0.50771000"],["77727.33000000","1.00399000"]]}}
{"type":"depth","received_at_ms":1788407338511,"data":{"e":"depthUpdate","E":1788407338714,"s":"BTCUSDT","U":99603297630,"u":99603298093,"b":[["77674.87000000","13.38948000"],["77674.86000000","0.00014000"],["77674.78000000","0.00014000"],["77674.75000000","0.00014000"],["77674.74000000","0.41269000"],["77674.73000000","0.00000000"],["77674.35000000","0.00400000"],["77674.11000000","0.00400000"],["77674.08000000","0.00000000"],["77674.07000000","0.00000000"],["77674.06000000","0.00000000"],["77673.99000000","0.00000000"],["77673.98000000","0.00000000"],["77673.76000000","0.00000000"],["77672.62000000","0.00014000"],["77672.61000000","0.12387000"],["77672.40000000","0.00400000"],["77672.22000000","0.00014000"],["77672.21000000","0.03276000"],["77672.00000000","2.51196000"],["77671.99000000","5.51764000"],["77671.98000000","0.00000000"],["77670.55000000","0.00000000"],["77670.54000000","0.32652000"],["77670.53000000","0.13953000"],["77669.99000000","0.00000000"],["77669.88000000","0.00000000"],["77669.87000000","1.26574000"],["77669.86000000","0.12702000"],["77669.31000000","0.00007000"],["77669.05000000","0.00013000"],["77668.62000000","0.18538000"],["77667.10000000","0.00008000"],["77666.25000000","0.00007000"],["77666.17000000","0.00000000"],["77665.90000000","0.14957000"],["77665.56000000","0.00000000"],["77665.37000000","0.00000000"],["77665.17000000","0.00007000"],["77665.11000000","0.00000000"],["77664.30000000","0.00010000"],["77664.22000000","0.00000000"],["77660.36000000","0.00000000"],["77659.34000000","0.00022000"],["77656.92000000","0.03000000"],["77655.45000000","0.10544000"],["77654.00000000","0.00000000"],["77651.57000000","0.00008000"],["77650.53000000","0.00000000"],["77650.11000000","0.00000000"],["77647.68000000","0.00008000"],["77646.23000000","0.00000000"],["77643.80000000","0.00008000"],["77643.15000000","0.00000000"],["77642.35000000","0.00000000"],["77641.20000000","0.00000000"],["77639.92000000","0.00008000"],["77639.90000000","0.02556000"],["77638.46000000","0.00000000"],["77636.03000000","0.00008000"],["77636.00000000","0.04000000"],["77634.58000000","0.00000000"],["77633.00000000","0.00000000"],["77630.70000000","0.00000000"],["77623.26000000","1.89451000"],["77623.25000000","4.63487000"],["77623.24000000","0.00000000"],["77623.23000000","0.00000000"],["77622.92000000","0.25000000"],["77617.91000000","0.00007000"],["77609.45000000","0.00321000"],["77604.36000000","0.00321000"],["77604.01000000","0.00000000"],["77600.01000000","0.00000000"],["77597.20000000","0.00008000"],["77589.67000000","0.00000000"],["77587.43000000","0.00000000"],["77568.39000000","0.10726000"],["77568.38000000","0.00000000"],["77530.01000000","0.00128000"],["77520.13000000","0.00000000"],["77519.52000000","0.00008000"],["77509.77000000","0.00000000"],["77441.85000000","0.00008000"],["77432.10000000","0.00000000"],["77364.17000000","0.00008000"],["77354.44000000","0.00000000"],["77286.50000000","0.00008000"],["77276.77000000","0.00000000"],["77208.82000000","0.00008000"],["77199.11000000","0.00000000"],["77131.15000000","0.00008000"],["77121.44000000","0.00000000"],["77053.47000000","0.00008000"],["77043.78000000","0.00000000"],["69904.80000000","0.00000000"],["69903.47000000","0.00000000"]],"a":[["77672.00000000","0.00000000"],["77672.01000000","0.00000000"],["77672.23000000","0.00000000"],["77672.62000000","0.00000000"],["77673.77000000","0.00000000"],["77673.99000000","0.00000000"],["77674.00000000","0.00000000"],["77674.07000000","0.00000000"],["77674.08000000","0.00000000"],["77674.09000000","0.00000000"],["77674.74000000","0.00000000"],["77674.75000000","0.00000000"],["77674.78000000","0.00000000"],["77674.87000000","0.00000000"],["77674.88000000","0.19175000"],["77674.89000000","0.00063000"],["77675.56000000","0.00000000"],["77675.91000000","0.00000000"],["77676.16000000","0.00000000"],["77676.17000000","0.00028000"],["77676.22000000","0.01176000"],["77676.51000000","0.00021000"],["77676.93000000","0.00014000"],["77676.94000000","0.32218000"],["77677.47000000","0.00911000"],["77677.63000000","0.00014000"],["77677.64000000","0.13154000"],["77677.65000000","0.03162000"],["77677.75000000","0.00014000"],["77677.76000000","0.10249000"],["77677.82000000","0.00000000"],["77677.99000000","0.00000000"],["77678.00000000","0.03014000"],["77678.13000000","0.00000000"],["77678.36000000","0.00000000"],["77678.69000000","0.00000000"],["77679.77000000","0.00000000"],["77680.70000000","0.00013000"],["77682.37000000","0.00744000"],["77682.65000000","0.00008000"],["77683.33000000","0.00000000"],["77685.07000000","0.10235000"],["77685.17000000","0.00400000"],["77688.02000000","0.00007000"],["77688.96000000","0.00000000"],["77689.42000000","0.00257000"],["77689.58000000","0.00000000"],["77690.41000000","0.00016000"],["77690.94000000","0.00400000"],["77691.14000000","0.00000000"],["77692.15000000","0.00000000"],["77692.58000000","0.00643000"],["77692.84000000","0.00000000"],["77694.30000000","0.00008000"],["77696.72000000","0.00000000"],["77697.69000000","0.00000000"],["77698.18000000","0.00008000"],["77700.61000000","0.00000000"],["77702.07000000","0.00008000"],["77704.49000000","0.00000000"],["77705.04000000","0.04711000"],["77705.95000000","0.00008000"],["77708.37000000","0.02569000"],["77709.83000000","0.00008000"],["77711.00000000","0.00000000"],["77713.38000000","0.00014000"],["77713.72000000","0.00008000"],["77714.00000000","0.04000000"],["77717.34000000","0.03863000"],["77724.89000000","0.00000000"],["77728.89000000","0.00000000"],["77732.76000000","0.00321000"],["77742.77000000","0.00000000"],["77752.55000000","0.00008000"],["77759.50000000","0.00000000"],["77807.26000000","0.00000000"],["77811.34000000","0.00128000"],["77820.43000000","0.00000000"],["77830.23000000","0.00008000"],["77898.10000000","0.00000000"],["77907.90000000","0.00026000"],["77975.76000000","0.00000000"],["77985.58000000","0.00008000"],["78053.43000000","0.00000000"],["78063.25000000","0.00008000"],["78131.09000000","0.00000000"],["78140.93000000","0.00008000"],["78208.76000000","0.00000000"],["78218.60000000","0.00008000"]]}}
{"type":"depth","received_at_ms":1788407338610,"data":{"e":"depthUpdate","E":1788407338814,"s":"BTCUSDT","U":99603298094,"u":99603298198,"b":[["77674.87000000","13.39000000"],["77674.74000000","0.41283000"],["77674.12000000","0.00400000"],["77672.61000000","0.12401000"],["77672.21000000","0.03297000"],["77672.01000000","0.00600000"],["77671.99000000","5.33834000"],["77670.74000000","0.00000000"],["77670.47000000","0.04031000"],["77670.01000000","0.31266000"],["77670.00000000","0.01200000"],["77669.98000000","0.41262000"],["77669.50000000","0.02007000"],["77668.62000000","0.18531000"],["77668.26000000","0.00000000"],["77667.10000000","0.16878000"],["77666.88000000","0.49809000"],["77665.99000000","0.00000000"],["77665.98000000","0.00000000"],["77665.97000000","0.00000000"],["77665.14000000","0.00000000"],["77664.65000000","0.02000000"],["77659.24000000","0.00000000"],["77650.00000000","0.01007000"],["77625.80000000","0.02000000"],["77605.69000000","0.02000000"],["77545.01000000","0.15873000"],["77541.03000000","0.00000000"],["77537.44000000","0.00000000"],["77471.69000000","0.00000000"],["75805.56000000","0.00035000"],["69907.39000000","0.00032000"],["62140.00000000","0.00225000"],["62139.90000000","0.00000000"]],"a":[["77674.88000000","0.19182000"],["77674.89000000","0.00063000"],["77675.97000000","0.00014000"],["77675.98000000","0.01513000"],["77676.00000000","0.03021000"],["77676.17000000","0.00014000"],["77676.22000000","0.00642000"],["77676.51000000","0.00007000"],["77677.47000000","0.00021000"],["77677.64000000","0.13175000"],["77677.65000000","0.03183000"],["77677.75000000","0.00000000"],["77677.76000000","0.10256000"],["77678.71000000","0.00000000"],["77679.95000000","0.00000000"],["77680.34000000","0.00000000"],["77691.15000000","0.40629000"],["77691.93000000","0.00007000"],["77699.87000000","0.48868000"],["77710.58000000","0.02000000"],["77711.88000000","0.09529000"],["77717.76000000","0.00839000"],["77724.48000000","0.00000000"],["77728.19000000","0.76133000"],["77729.91000000","0.25000000"],["77752.41000000","0.00000000"],["77783.28000000","0.00000000"],["77787.34000000","0.00000000"]]}}
{"type":"depth","received_at_ms":1788407338712,"data":{"e":"depthUpdate","E":1788407338914,"s":"BTCUSDT","U":99603298199,"u":99603298261,"b":[["77674.87000000","13.44408000"],["77674.86000000","0.01024000"],["77674.81000000","0.00400000"],["77674.11000000","0.00000000"],["77673.62000000","0.01684000"],["77672.38000000","0.02021000"],["77672.21000000","0.03297000"],["77672.01000000","0.01814000"],["77672.00000000","2.45405000"],["77671.99000000","5.33177000"],["77671.14000000","0.02021000"],["77670.01000000","0.30866000"],["77670.00000000","0.00400000"],["77659.34000000","0.00030000"],["77652.10000000","0.00200000"],["77648.74000000","0.00010000"],["77644.84000000","0.00000000"],["77542.44000000","0.00012000"],["69907.39000000","0.00048000"]],"a":[["77674.88000000","0.19189000"],["77675.98000000","0.01527000"],["77676.94000000","0.32218000"],["77677.47000000","0.00007000"],["77678.00000000","0.03021000"],["77679.10000000","0.00534000"],["77680.35000000","0.00890000"],["77681.59000000","0.01068000"],["77682.83000000","0.01068000"],["77685.17000000","0.00000000"],["77685.74000000","0.00400000"],["77694.88000000","0.00012000"],["77695.99000000","0.00000000"],["77696.34000000","0.26573000"],["77701.06000000","0.25757000"],["77701.49000000","0.64393000"],["77779.16000000","0.00000000"],["77784.18000000","0.00012000"],["77788.30000000","0.00019000"]]}}
{"type":"depth","received_at_ms":1788407338814,"data":{"e":"depthUpdate","E":1788407339016,"s":"BTCUSDT","U":99603298262,"u":99603298289,"b":[["77674.87000000","13.44422000"],["77674.86000000","0.01038000"],["77674.74000000","0.41283000"],["77673.78000000","0.00007000"],["77673.62000000","0.01698000"],["77672.61000000","0.12387000"],["77672.00000000","2.05444000"],["77671.99000000","5.31556000"],["77670.54000000","0.32638000"],["77670.53000000","0.13939000"],["71456.28000000","0.00014000"],["69907.39000000","0.00064000"],["62139.90000000","0.00032000"]],"a":[["77678.00000000","0.03021000"],["77704.00000000","0.73258000"],["77792.35000000","0.00032000"]]}}
{"type":"depth","received_at_ms":1788407338912,"data":{"e":"depthUpdate","E":1788407339115,"s":"BTCUSDT","U":99603298290,"u":99603298306,"b":[["77674.87000000","13.43779000"],["77674.36000000","0.00643000"],["77670.57000000","0.03863000"],["77652.37000000","0.00000000"],["77642.00000000","0.73000000"],["69907.39000000","0.00096000"],["62136.00000000","0.00215000"]],"a":[["77674.88000000","0.19175000"],["77674.89000000","0.00063000"],["77676.20000000","0.00916000"],["77676.22000000","0.00014000"],["77685.11000000","0.00000000"],["77693.14000000","0.00162000"],["77766.84000000","0.00000000"],["77771.19000000","0.00025000"]]}}
{"type":"depth","received_at_ms":1788407339011,"data":{"e":"depthUpdate","E":1788407339214,"s":"BTCUSDT","U":99603298307,"u":99603298390,"b":[["77674.87000000","13.55152000"],["77674.81000000","0.00000000"],["77674.74000000","0.41290000"],["77674.36000000","0.00014000"],["77672.61000000","0.12401000"],["77671.99000000","5.31403000"],["77660.56000000","0.00007000"],["77656.22000000","0.00000000"],["77652.00000000","0.00500000"],["77650.00000000","0.01507000"],["77600.37000000","0.00321000"],["77596.01000000","0.00000000"],["76509.74000000","0.00030000"],["69907.39000000","0.00121000"],["62139.90000000","0.00000000"],["62136.00000000","0.00015000"]],"a":[["77674.88000000","0.01200000"],["77676.00000000","0.03021000"],["77676.17000000","0.00007000"],["77676.20000000","0.00930000"],["77676.22000000","0.00000000"],["77677.63000000","0.00000000"],["77677.64000000","0.00035000"],["77677.75000000","0.00007000"],["77679.26000000","0.00000000"],["77679.39000000","0.00027000"],["77679.62000000","0.00000000"],["77680.75000000","0.00208000"],["77681.06000000","0.09996000"],["77681.21000000","0.00000000"],["77682.15000000","0.00000000"],["77683.49000000","0.00000000"],["77685.74000000","0.00000000"],["77686.69000000","0.00400000"],["77687.29000000","0.00000000"],["77689.42000000","0.00000000"],["77690.72000000","0.00000000"],["77690.94000000","0.00000000"],["77691.52000000","0.00400000"],["77691.64000000","0.00007000"],["77692.94000000","0.12871000"],["77711.88000000","0.00000000"],["77717.25000000","0.00400000"],["77717.76000000","0.00000000"],["77727.84000000","0.00000000"],["77731.73000000","0.00320000"],["77805.56000000","0.00000000"],["77809.02000000","0.00128000"],["78840.01000000","0.00030000"]]}}
{"type":"depth","received_at_ms":1788407339110,"data":{"e":"depthUpdate","E":1788407339314,"s":"BTCUSDT","U":99603298391,"u":99603298753,"b":[["77676.93000000","10.82377000"],["77676.92000000","0.00021000"],["77676.50000000","0.00000000"],["77676.30000000","0.00400000"],["77676.19000000","0.00000000"],["77676.16000000","0.00000000"],["77675.99000000","0.00000000"],["77675.98000000","0.00000000"],["77675.97000000","0.00000000"],["77675.96000000","0.00000000"],["77674.89000000","0.00014000"],["77674.88000000","2.20299000"],["77674.87000000","4.88685000"],["77674.86000000","0.01024000"],["77674.75000000","0.00000000"],["77674.74000000","0.41290000"],["77674.36000000","0.00000000"],["77674.12000000","0.00000000"],["77673.95000000","0.03276000"],["77672.62000000","0.00000000"],["77672.61000000","0.00028000"],["77672.38000000","0.02035000"],["77672.22000000","0.00000000"],["77672.21000000","0.00021000"],["77672.01000000","0.01835000"],["77672.00000000","1.04799000"],["77671.99000000","0.64688000"],["77671.14000000","0.02028000"],["77669.87000000","1.19074000"],["77669.16000000","0.00008000"],["77669.05000000","0.00000000"],["77667.23000000","0.00007000"],["77667.10000000","0.16870000"],["77666.40000000","0.00008000"],["77664.27000000","0.08643000"],["77661.70000000","0.00000000"],["77660.37000000","0.01201000"],["77658.55000000","0.10450000"],["77655.45000000","0.00008000"],["77650.00000000","0.01500000"],["77645.10000000","0.00000000"],["77638.00000000","0.04000000"],["77636.18000000","0.00000000"],["77636.00000000","0.03000000"],["77634.47000000","0.00000000"],["77623.28000000","1.96917000"],["77623.27000000","4.63470000"],["77623.26000000","0.00000000"],["77623.25000000","0.00000000"],["77589.66000000","0.00000000"],["77511.84000000","0.00000000"],["77510.23000000","0.00000000"],["77494.70000000","0.00000000"],["77479.17000000","0.00000000"],["77463.64000000","0.00000000"],["77448.11000000","0.00000000"],["77432.58000000","0.00000000"],["77417.05000000","0.00000000"],["77120.00000000","0.01697000"],["69909.24000000","0.00016000"],["69907.39000000","0.00009000"],["62142.00000000","0.00000000"]],"a":[["77674.88000000","0.00000000"],["77674.89000000","0.00000000"],["77675.97000000","0.00000000"],["77675.98000000","0.00000000"],["77675.99000000","0.00000000"],["77676.00000000","0.00000000"],["77676.06000000","0.00000000"],["77676.17000000","0.00000000"],["77676.20000000","0.00000000"],["77676.51000000","0.00000000"],["77676.93000000","0.00000000"],["77676.94000000","0.77222000"],["77676.95000000","0.00063000"],["77677.64000000","0.00007000"],["77677.65000000","0.00021000"],["77677.75000000","0.00014000"],["77677.99000000","0.00014000"],["77679.10000000","0.00548000"],["77679.19000000","0.00014000"],["77679.20000000","0.10249000"],["77679.29000000","0.00014000"],["77679.30000000","0.02910000"],["77679.70000000","0.00007000"],["77679.71000000","0.03162000"],["77680.00000000","0.03014000"],["77680.35000000","0.00904000"],["77680.70000000","0.00000000"],["77681.06000000","0.09989000"],["77682.37000000","0.00000000"],["77682.65000000","0.00000000"],["77682.76000000","0.00321000"],["77683.97000000","0.00000000"],["77684.71000000","0.00008000"],["77687.02000000","0.10234000"],["77691.24000000","0.00000000"],["77691.52000000","0.00000000"],["77692.02000000","0.00400000"],["77692.58000000","0.00000000"],["77693.38000000","0.00643000"],["77696.59000000","0.00050000"],["77697.73000000","0.00007000"],["77704.00000000","0.03265000"],["77704.27000000","0.00000000"],["77714.00000000","0.03000000"],["77716.00000000","0.04000000"],["77718.34000000","0.00825000"],["77727.07000000","0.01200000"],["77805.30000000","0.00000000"],["77820.83000000","0.00000000"],["77836.36000000","0.00000000"],["77851.89000000","0.00000000"],["77867.42000000","0.00000000"],["77871.74000000","0.00007000"],["77873.93000000","0.00000000"],["77882.95000000","0.00000000"],["77898.48000000","0.00000000"],["78840.01000000","0.00000000"]]}}
{"type":"depth","received_at_ms":1788407339210,"data":{"e":"depthUpdate","E":1788407339414,"s":"BTCUSDT","U":99603298754,"u":99603298840,"b":[["77676.93000000","10.85585000"],["77676.92000000","0.00028000"],["77676.31000000","0.00400000"],["77674.90000000","0.00014000"],["77674.89000000","0.01814000"],["77674.88000000","2.20313000"],["77674.86000000","0.00014000"],["77674.74000000","0.41297000"],["77673.95000000","0.03290000"],["77673.62000000","0.00014000"],["77672.78000000","0.00007000"],["77672.61000000","0.00007000"],["77672.38000000","0.00000000"],["77672.21000000","0.00007000"],["77672.01000000","0.00435000"],["77671.14000000","0.00007000"],["77671.11000000","0.00013000"],["77670.53000000","0.13932000"],["77670.00000000","0.00000000"],["77669.98000000","0.41269000"],["77669.53000000","0.08301000"],["77664.26000000","0.67762000"],["77649.09000000","0.00000000"],["77473.77000000","0.00000000"],["76971.50000000","0.00000000"],["76509.74000000","0.00000000"],["69909.24000000","0.00032000"]],"a":[["77676.94000000","0.65857000"],["77676.95000000","0.00063000"],["77677.65000000","0.00007000"],["77678.00000000","0.03690000"],["77679.10000000","0.00014000"],["77679.30000000","0.02910000"],["77679.71000000","0.03176000"],["77679.95000000","0.00007000"],["77680.35000000","0.00014000"],["77681.59000000","0.00000000"],["77682.76000000","0.00334000"],["77682.83000000","0.00000000"],["77727.07000000","0.00000000"],["78842.10000000","0.00053000"]]}}
{"type":"depth","received_at_ms":1788407339311,"data":{"e":"depthUpdate","E":1788407339514,"s":"BTCUSDT","U":99603298841,"u":99603298919,"b":[["77676.93000000","10.89696000"],["77676.92000000","0.01059000"],["77676.10000000","0.00007000"],["77675.68000000","0.01684000"],["77674.89000000","0.01828000"],["77674.88000000","2.09842000"],["77674.87000000","4.83920000"],["77674.86000000","0.00000000"],["77674.74000000","0.41297000"],["77674.44000000","0.02021000"],["77673.99000000","0.00257000"],["77673.95000000","0.03290000"],["77673.78000000","0.00000000"],["77673.62000000","0.00000000"],["77673.20000000","0.02021000"],["77672.01000000","0.00421000"],["77672.00000000","1.04813000"],["77652.00000000","0.01500000"],["77650.00000000","0.02500000"],["69909.24000000","0.00064000"],["62141.55000000","0.00032000"]],"a":[["77676.94000000","0.65871000"],["77676.95000000","0.00070000"],["77678.00000000","0.03690000"],["77678.59000000","0.00014000"],["77678.60000000","0.14741000"],["77679.10000000","0.00000000"],["77679.70000000","0.00000000"],["77680.00000000","0.03014000"],["77680.35000000","0.00000000"],["77680.64000000","0.09485000"],["77681.06000000","0.10003000"],["77681.16000000","0.00534000"],["77682.41000000","0.00890000"],["77683.65000000","0.01068000"],["77684.89000000","0.01068000"],["77686.95000000","0.10165000"],["77687.58000000","0.00000000"],["77688.20000000","0.00000000"],["77691.13000000","0.28627000"],["77817.88000000","0.51805000"]]}}
{"type":"depth","received_at_ms":1788407339411,"data":{"e":"depthUpdate","E":1788407339614,"s":"BTCUSDT","U":99603298920,"u":99603298960,"b":[["77676.93000000","10.89710000"],["77676.92000000","0.01073000"],["77675.68000000","0.01698000"],["77674.89000000","0.01628000"],["77674.88000000","2.65679000"],["77674.74000000","0.41283000"],["77673.95000000","0.03276000"],["77672.00000000","1.04799000"],["77671.99000000","0.60697000"],["77667.24000000","0.00000000"],["77666.26000000","0.00200000"],["77609.45000000","0.00000000"],["77530.01000000","0.00000000"],["71456.28000000","0.00000000"],["62142.00000000","0.00000000"],["62141.55000000","0.00000000"]],"a":[["77676.94000000","0.79965000"],["77678.00000000","0.03690000"],["77678.59000000","0.00000000"],["77678.60000000","0.00014000"],["77681.06000000","0.09989000"]]}}
{"type":"depth","received_at_ms":1788407339510,"data":{"e":"depthUpdate","E":1788407339714,"s":"BTCUSDT","U":99603298961,"u":99603298979,"b":[["77675.84000000","0.04059000"],["77675.69000000","0.00007000"],["77670.47000000","0.00007000"],["77652.90000000","0.00400000"],["77611.24000000","0.00320000"],["77532.96000000","0.00128000"],["69909.24000000","0.00096000"]],"a":[["77678.00000000","0.03690000"],["77678.60000000","0.00000000"],["77679.70000000","0.00007000"],["77681.06000000","0.10003000"],["77711.40000000","0.02400000"],["77717.25000000","0.00000000"]]}}
{"type":"depth","received_at_ms":1788407339611,"data":{"e":"depthUpdate","E":1788407339814,"s":"BTCUSDT","U":99603298980,"u":99603299005,"b":[["77676.93000000","10.76897000"],["77676.92000000","0.01087000"],["77675.85000000","0.00014000"],["77672.01000000","0.00407000"],["77669.13000000","0.12875000"],["77668.61000000","0.00007000"],["77667.85000000","0.00000000"],["77606.37000000","0.02000000"],["69909.24000000","0.00112000"],["69907.39000000","0.00000000"],["69907.38000000","0.00009000"],["62141.54000000","0.00000000"]],"a":[["77676.94000000","0.79958000"],["77676.95000000","0.00063000"],["77684.43000000","0.00841000"],["77730.01000000","0.02000000"]]}}
{"type":"depth","received_at_ms":1788407339711,"data":{"e":"depthUpdate","E":1788407339914,"s":"BTCUSDT","U":99603299006,"u":99603299033,"b":[["77676.93000000","10.76905000"],["77676.92000000","0.01094000"],["77676.31000000","0.00000000"],["77675.86000000","0.00643000"],["77674.90000000","0.00414000"],["77674.89000000","0.20729000"],["77674.88000000","1.18768000"],["77674.87000000","0.19790000"],["77673.95000000","0.03283000"],["77669.54000000","0.00000000"],["77668.62000000","1.57870000"],["77668.61000000","0.00000000"],["77667.19000000","0.00200000"],["77666.44000000","4.63458000"],["77666.26000000","0.00000000"],["69909.24000000","0.00128000"]],"a":[["77676.94000000","0.67411000"]]}}
{"type":"depth","received_at_ms":1788407339813,"data":{"e":"depthUpdate","E":1788407340014,"s":"BTCUSDT","U":99603299034,"u":99603299088,"b":[["77676.93000000","10.76905000"],["77676.92000000","0.01087000"],["77676.31000000","0.00044000"],["77675.90000000","0.00538000"],["77675.86000000","0.00000000"],["77675.33000000","0.00007000"],["77674.91000000","0.00643000"],["77674.89000000","0.19129000"],["77674.87000000","0.19745000"],["77672.01000000","0.00535000"],["77670.02000000","0.02000000"],["77669.86000000","0.12695000"],["77668.63000000","0.00000000"],["77667.19000000","0.00000000"],["77667.11000000","0.00200000"],["77666.89000000","0.00000000"],["77666.45000000","0.08642000"],["77664.27000000","0.00000000"],["77664.26000000","0.59045000"],["77663.18000000","0.10973000"],["77659.66000000","0.25756000"],["77659.05000000","0.20052000"],["77656.52000000","0.30010000"],["77653.52000000","0.44173000"],["77649.43000000","0.00000000"],["77647.07000000","0.00000000"],["77638.81000000","0.00000000"],["73100.00000000","7.67097000"],["69909.24000000","0.00144000"],["62142.00000000","0.00000000"],["62141.55000000","0.00032000"]],"a":[["77676.94000000","0.80713000"],["77679.20000000","0.10256000"],["77679.30000000","0.02917000"],["77687.99000000","0.00000000"],["77688.19000000","0.00000000"],["77688.42000000","0.00600000"],["77695.13000000","0.00000000"],["77696.34000000","0.00000000"],["77699.39000000","0.41520000"],["77699.46000000","0.00013000"],["77701.06000000","0.00000000"],["77702.34000000","0.25756000"]]}}
{"type":"depth","received_at_ms":1788407339911,"data":{"e":"depthUpdate","E":1788407340114,"s":"BTCUSDT","U":99603299089,"u":99603299144,"b":[["77676.93000000","10.87102000"],["77676.92000000","0.01094000"],["77675.90000000","0.00552000"],["77675.68000000","0.01691000"],["77670.53000000","0.13939000"],["77670.03000000","0.00400000"],["77670.02000000","0.01600000"],["77669.50000000","0.02000000"],["77669.31000000","0.00000000"],["77665.75000000","0.00007000"],["77660.89000000","0.19836000"],["77659.67000000","0.00000000"],["77659.05000000","0.00000000"],["77653.38000000","0.00007000"],["77637.84000000","0.00007000"],["77593.96000000","0.72114000"],["77591.41000000","0.00000000"],["77513.52000000","0.00017000"],["77497.98000000","0.00007000"],["77492.31000000","0.00000000"],["77482.44000000","0.00007000"],["77466.90000000","0.00007000"],["77451.36000000","0.00007000"],["77435.82000000","0.00007000"],["69909.24000000","0.00160000"]],"a":[["77676.94000000","0.79533000"],["77689.07000000","0.00007000"],["77697.27000000","0.51926000"],["77793.24000000","0.00007000"],["77808.78000000","0.00007000"],["77824.32000000","0.00007000"],["77839.86000000","0.00007000"],["77855.40000000","0.00007000"],["77870.94000000","0.00007000"],["77886.48000000","0.00007000"],["77902.02000000","0.00007000"],["77917.56000000","0.00007000"],["77952.59000000","0.00000000"],["86422.88000000","0.24583000"]]}}
{"type":"depth","received_at_ms":1788407340011,"data":{"e":"depthUpdate","E":1788407340214,"s":"BTCUSDT","U":99603299145,"u":99603299217,"b":[["77676.93000000","10.87310000"],["77676.92000000","0.01115000"],["77676.31000000","0.00000000"],["77676.11000000","0.00643000"],["77675.69000000","0.00007000"],["77675.68000000","0.01684000"],["77675.34000000","0.00400000"],["77674.91000000","0.00000000"],["77674.90000000","0.00014000"],["77674.89000000","0.52993000"],["77674.87000000","0.19592000"],["77670.55000000","0.00000000"],["77670.04000000","0.00000000"],["77670.03000000","0.00000000"],["77670.02000000","0.02000000"],["77668.63000000","0.00200000"],["77667.12000000","0.00000000"],["77667.11000000","0.00000000"],["77660.56000000","0.00000000"],["69909.24000000","0.00160000"],["62141.55000000","0.00000000"]],"a":[["77676.94000000","0.52982000"],["77676.95000000","0.00063000"],["77677.75000000","0.00000000"],["77677.76000000","0.00021000"],["77678.00000000","0.03021000"],["77679.39000000","0.00000000"],["77679.70000000","0.00014000"],["77679.99000000","0.00007000"],["77681.14000000","0.00027000"],["77684.10000000","0.00000000"],["77689.54000000","0.66324000"],["77691.12000000","0.00000000"],["77691.64000000","0.00000000"],["77692.02000000","0.00000000"],["77692.61000000","0.00400000"],["77693.38000000","0.00000000"],["77694.29000000","0.00643000"],["77701.49000000","0.00000000"],["77702.33000000","0.64392000"],["77718.34000000","0.00000000"],["77718.83000000","0.00000000"],["77719.20000000","0.00400000"],["77774.98000000","0.13329000"],["77777.54000000","0.00000000"]]}}
{"type":"depth","received_at_ms":1788407340119,"data":{"e":"depthUpdate","E":1788407340314,"s":"BTCUSDT","U":99603299218,"u":99603299272,"b":[["77676.93000000","10.87109000"],["77676.92000000","0.01122000"],["77676.00000000","0.00400000"],["77674.87000000","0.19192000"],["77670.03000000","0.00400000"],["77670.02000000","0.01600000"],["77662.62000000","0.00007000"],["77653.51000000","0.00000000"],["76511.77000000","0.00030000"],["69909.24000000","0.00176000"],["62142.00000000","0.00000000"]],"a":[["77676.94000000","0.53104000"],["77676.95000000","0.00063000"],["77677.76000000","0.00007000"],["77680.75000000","0.00000000"],["77681.06000000","0.00014000"],["77681.16000000","0.00548000"],["77682.50000000","0.00007000"],["77688.42000000","0.00200000"],["77688.45000000","0.00000000"],["77688.66000000","0.00257000"],["77688.97000000","0.00000000"],["77692.58000000","0.02000000"],["77693.70000000","0.00007000"],["77707.00000000","0.70000000"],["77727.42000000","0.12879000"],["84202.54000000","0.01768000"]]}}
{"type":"depth","received_at_ms":1788407340212,"data":{"e":"depthUpdate","E":1788407340414,"s":"BTCUSDT","U":99603299273,"u":99603299295,"b":[["77674.89000000","0.45852000"],["77659.04000000","4.63518000"],["76977.84000000","0.00010000"],["69909.24000000","0.00176000"]],"a":[["77679.64000000","0.00007000"],["77679.65000000","0.10699000"],["77679.99000000","0.00000000"],["77680.64000000","0.09485000"],["77681.06000000","0.00000000"],["77681.46000000","0.00680000"],["77686.69000000","0.00000000"],["77687.04000000","0.00400000"],["77727.42000000","0.00000000"],["77762.29000000","0.00007000"],["77766.36000000","0.00007000"],["78842.10000000","0.00053000"]]}}
{"type":"depth","received_at_ms":1788407340311,"data":{"e":"depthUpdate","E":1788407340514,"s":"BTCUSDT","U":99603299296,"u":99603299320,"b":[["77611.65000000","0.00000000"],["76628.21000000","0.00000000"],["76337.83000000","0.06618000"],["69909.24000000","0.00192000"],["62141.55000000","0.00032000"]],"a":[["77676.94000000","0.53114000"],["77679.30000000","0.02917000"],["77679.65000000","0.10713000"],["77679.95000000","0.00000000"],["77681.46000000","0.00666000"],["77682.50000000","0.00014000"],["77688.66000000","0.00000000"],["77727.31000000","0.00000000"],["77727.51000000","0.12879000"],["77745.75000000","0.00000000"],["78049.37000000","0.08812000"]]}}
{"type":"depth","received_at_ms":1788407340411,"data":{"e":"depthUpdate","E":1788407340614,"s":"BTCUSDT","U":99603299321,"u":99603299333,"b":[["77676.93000000","10.87238000"],["77674.56000000","0.00027000"],["77671.99000000","0.60568000"],["75561.73000000","0.00000000"],["69909.24000000","0.00208000"],["62141.55000000","0.00000000"]],"a":[["77676.94000000","0.53121000"],["77676.95000000","0.00070000"],["77678.41000000","0.00007000"],["77689.40000000","0.00257000"],["77699.46000000","0.00000000"],["77703.45000000","0.00013000"],["77717.25000000","0.00400000"],["77719.20000000","0.00000000"],["81006.07000000","0.00000000"]]}}
{"type":"depth","received_at_ms":1788407340511,"data":{"e":"depthUpdate","E":1788407340714,"s":"BTCUSDT","U":99603299334,"u":99603299429,"b":[["77676.93000000","10.87383000"],["77676.92000000","0.01059000"],["77676.28000000","0.00400000"],["77676.11000000","0.00000000"],["77676.00000000","0.00000000"],["77675.90000000","0.00809000"],["77675.68000000","0.01691000"],["77675.34000000","0.00000000"],["77674.91000000","0.00643000"],["77674.87000000","0.19865000"],["77673.99000000","0.00000000"],["77670.55000000","0.01600000"],["77670.53000000","0.13932000"],["77670.02000000","0.00000000"],["77668.63000000","0.00200000"],["77666.45000000","0.00000000"],["77663.19000000","0.08643000"],["77661.58000000","0.26895000"],["77660.89000000","0.00000000"],["77659.67000000","0.26075000"],["77644.59000000","0.00000000"],["77643.75000000","0.34787000"],["77623.94000000","0.00000000"],["76337.83000000","0.00000000"],["69909.24000000","0.00208000"],["62142.00000000","0.00000000"]],"a":[["77676.94000000","0.35138000"],["77679.30000000","0.02924000"],["77679.64000000","0.00000000"],["77679.65000000","0.00014000"],["77679.99000000","0.00007000"],["77681.46000000","0.00000000"],["77682.07000000","0.18866000"],["77682.38000000","0.00208000"],["77682.69000000","0.09989000"],["77683.19000000","0.00000000"],["77683.20000000","0.00000000"],["77685.08000000","0.00000000"],["77685.36000000","0.19935000"],["77685.53000000","0.00000000"],["77685.84000000","0.00000000"],["77687.09000000","0.00000000"],["77687.43000000","0.00523000"],["77688.43000000","0.00000000"],["77689.40000000","0.00000000"],["77689.41000000","0.00000000"],["77691.10000000","0.10165000"],["77691.15000000","0.02000000"],["77691.32000000","0.00539000"],["77692.47000000","0.10165000"],["77692.48000000","0.16870000"],["77692.61000000","0.00000000"],["77693.78000000","0.00400000"],["77694.29000000","0.00000000"],["77695.21000000","0.00522000"],["77695.79000000","0.00643000"],["77699.10000000","0.00531000"],["77702.99000000","0.00535000"],["77704.12000000","0.04733000"],["77705.04000000","0.00008000"],["77712.69000000","0.64364000"],["77719.32000000","0.00000000"],["77719.35000000","0.00830000"],["77727.51000000","0.00000000"]]}}
{"type":"depth","received_at_ms":1788407340611,"data":{"e":"depthUpdate","E":1788407340814,"s":"BTCUSDT","U":99603299430,"u":99603299467,"b":[["77676.92000000","0.01059000"],["77676.31000000","0.00400000"],["77676.28000000","0.00000000"],["77676.05000000","0.00257000"],["77675.90000000","0.00552000"],["77675.46000000","0.00400000"],["77670.57000000","0.03870000"],["76594.19000000","0.06596000"],["69909.24000000","0.00224000"],["62141.54000000","0.00000000"]],"a":[["77676.94000000","0.35131000"],["77676.95000000","0.00063000"],["77679.30000000","0.02917000"],["77679.65000000","0.00000000"],["77681.16000000","0.00548000"],["77682.00000000","0.03014000"],["77685.87000000","0.00647000"],["77688.42000000","0.00000000"],["77689.52000000","0.00200000"]]}}
{"type":"depth","received_at_ms":1788407340712,"data":{"e":"depthUpdate","E":1788407340915,"s":"BTCUSDT","U":99603299468,"u":99603299486,"b":[["77676.93000000","10.87390000"],["77668.63000000","0.00000000"],["77667.19000000","0.00200000"],["77654.00000000","0.00500000"],["77652.00000000","0.02000000"],["77650.00000000","0.03000000"],["76594.19000000","0.00000000"],["76337.80000000","0.06618000"]],"a":[["77676.94000000","0.53106000"],["77684.71000000","0.16878000"],["77728.08000000","0.00000000"],["78049.37000000","0.00000000"],["80165.19000000","0.09135000"]]}}
{"type":"depth","received_at_ms":1788407340811,"data":{"e":"depthUpdate","E":1788407341014,"s":"BTCUSDT","U":99603299487,"u":99603299510,"b":[["77676.93000000","10.87353000"],["77676.92000000","0.01066000"],["77676.32000000","0.00043000"],["77674.56000000","0.00000000"],["77671.99000000","0.60299000"],["77666.45000000","0.08642000"],["77664.27000000","0.10912000"],["77663.19000000","0.00000000"],["77663.18000000","0.00000000"],["77660.89000000","0.26393000"],["77660.40000000","0.25756000"],["77659.67000000","0.00000000"],["77659.66000000","0.00000000"],["69909.24000000","0.00240000"],["62141.55000000","0.00032000"]],"a":[["77676.94000000","0.53748000"],["77676.95000000","0.00070000"],["77679.87000000","0.11378000"],["77695.31000000","0.38634000"],["77702.34000000","0.00000000"],["77702.81000000","0.25756000"],["77707.32000000","0.00000000"],["77729.01000000","0.12879000"],["78041.02000000","0.08900000"],["80165.19000000","0.00000000"]]}}
{"type":"depth","received_at_ms":1788407340910,"data":{"e":"depthUpdate","E":1788407341114,"s":"BTCUSDT","U":99603299511,"u":99603299541,"b":[["77676.93000000","10.87395000"],["77676.92000000","0.01101000"],["77664.27000000","0.00000000"],["77663.18000000","0.14100000"],["76594.06000000","0.06596000"],["76337.80000000","0.00000000"],["69909.24000000","0.00240000"]],"a":[["77679.71000000","0.03176000"],["77679.87000000","0.11392000"],["77682.00000000","0.03000000"],["77692.21000000","0.00400000"],["77693.78000000","0.00000000"],["77729.01000000","0.00000000"],["77771.19000000","0.00000000"],["77773.25000000","0.00025000"],["77798.08000000","0.30866000"],["77807.72000000","0.00108000"]]}}
{"type":"depth","received_at_ms":1788407341011,"data":{"e":"depthUpdate","E":1788407341214,"s":"BTCUSDT","U":99603299542,"u":99603299557,"b":[["77676.93000000","10.87409000"],["77676.92000000","0.01108000"],["69909.24000000","0.00240000"],["62141.55000000","0.00000000"]],"a":[["77676.94000000","0.67333000"],["77676.95000000","0.00070000"],["77678.29000000","0.00007000"],["77678.30000000","0.10987000"],["77679.87000000","0.00014000"],["77679.99000000","0.00000000"]]}}
{"type":"depth","received_at_ms":1788407341110,"data":{"e":"depthUpdate","E":1788407341314,"s":"BTCUSDT","U":99603299558,"u":99603299579,"b":[["77662.62000000","0.00007000"],["76511.77000000","0.00030000"],["76306.94000000","0.00000000"],["69909.24000000","0.00256000"],["62142.00000000","0.00000000"]],"a":[["77678.00000000","0.03021000"],["77678.29000000","0.00541000"],["77678.30000000","0.11001000"],["77679.71000000","0.03176000"],["77679.87000000","0.00000000"],["77693.70000000","0.00007000"]]}}
{"type":"depth","received_at_ms":1788407341210,"data":{"e":"depthUpdate","E":1788407341414,"s":"BTCUSDT","U":99603299580,"u":99603299603,"b":[["77676.93000000","10.87395000"],["77676.92000000","0.01101000"],["76594.06000000","0.00000000"],["76337.74000000","0.06618000"],["76123.40000000","1.20000000"],["69909.24000000","0.00272000"]],"a":[["77676.94000000","0.67340000"],["77676.95000000","0.00077000"],["77678.00000000","0.03021000"],["77678.29000000","0.00555000"],["77681.16000000","0.00534000"],["78041.02000000","0.00000000"],["78842.10000000","0.00053000"],["78926.74000000","0.09092000"],["79230.47000000","1.19998000"]]}}
{"type":"depth","received_at_ms":1788407341311,"data":{"e":"depthUpdate","E":1788407341515,"s":"BTCUSDT","U":99603299604,"u":99603299610,"b":[["77676.05000000","0.00000000"],["77675.27000000","0.00257000"],["75561.73000000","0.00010000"],["69909.24000000","0.00256000"],["62141.55000000","0.00032000"]],"a":[["77728.33000000","0.00000000"]]}}
{"type":"depth","received_at_ms":1788407341410,"data":{"e":"depthUpdate","E":1788407341614,"s":"BTCUSDT","U":99603299611,"u":99603299616,"b":[["77676.93000000","10.87388000"],["77676.92000000","0.01094000"],["76832.64000000","0.00032000"],["69909.24000000","0.00288000"],["62141.55000000","0.00000000"]],"a":[]}}
{"type":"depth","received_at_ms":1788407341510,"data":{"e":"depthUpdate","E":1788407341714,"s":"BTCUSDT","U":99603299617,"u":99603299625,"b":[["69909.24000000","0.00288000"]],"a":[["77678.41000000","0.00000000"],["77679.95000000","0.00007000"],["77727.95000000","0.00000000"],["77728.24000000","0.12879000"],["77728.75000000","0.00000000"]]}}
{"type":"depth","received_at_ms":1788407341611,"data":{"e":"depthUpdate","E":1788407341814,"s":"BTCUSDT","U":99603299626,"u":99603299635,"b":[["69909.24000000","0.00304000"],["62142.00000000","0.00000000"]],"a":[["77690.01000000","0.00257000"],["77728.24000000","0.00000000"],["77728.25000000","0.00000000"],["81006.07000000","0.00010000"]]}}
{"type":"depth","received_at_ms":1788407341710,"data":{"e":"depthUpdate","E":1788407341914,"s":"BTCUSDT","U":99603299636,"u":99603299641,"b":[["62141.54000000","0.00000000"]],"a":[["77774.98000000","0.89493000"],["77777.54000000","2.60865000"]]}}
{"type":"depth","received_at_ms":1788407341811,"data":{"e":"depthUpdate","E":1788407342014,"s":"BTCUSDT","U":99603299642,"u":99603299652,"b":[["77660.40000000","0.00000000"],["77659.66000000","0.25756000"],["77654.00000000","0.01500000"],["77652.00000000","0.03000000"],["69909.24000000","0.00320000"],["62141.55000000","0.00032000"]],"a":[["77728.70000000","0.00000000"],["78040.19000000","0.08978000"],["78926.74000000","0.00000000"]]}}
{"type":"depth","received_at_ms":1788407341911,"data":{"e":"depthUpdate","E":1788407342114,"s":"BTCUSDT","U":99603299653,"u":99603299657,"b":[["69909.24000000","0.00336000"],["62142.00000000","0.00200000"]],"a":[["77728.87000000","0.12879000"]]}}
{"type":"depth","received_at_ms":1788407342011,"data":{"e":"depthUpdate","E":1788407342214,"s":"BTCUSDT","U":99603299658,"u":99603299670,"b":[["77676.93000000","10.87360000"],["77675.84000000","0.04073000"],["77675.68000000","0.01705000"],["69907.38000000","0.00000000"],["62142.00000000","0.00000000"],["62141.55000000","0.00000000"]],"a":[["77676.94000000","0.67322000"],["77728.87000000","0.00000000"]]}}
{"type":"depth","received_at_ms":1788407342111,"data":{"e":"depthUpdate","E":1788407342314,"s":"BTCUSDT","U":99603299671,"u":99603299682,"b":[["77675.27000000","0.00000000"],["77675.26000000","0.00257000"],["77662.62000000","0.00007000"],["76511.77000000","0.00030000"],["69909.24000000","0.00352000"],["62142.00000000","0.00000000"]],"a":[["77693.70000000","0.00007000"]]}}
{"type":"depth","received_at_ms":1788407342210,"data":{"e":"depthUpdate","E":1788407342414,"s":"BTCUSDT","U":99603299683,"u":99603299691,"b":[["77675.26000000","0.00000000"],["77675.25000000","0.00257000"],["77654.00000000","0.02000000"],["69909.24000000","0.00352000"],["62142.00000000","0.00000000"]],"a":[["78842.10000000","0.00053000"]]}}
{"type":"depth","received_at_ms":1788407342310,"data":{"e":"depthUpdate","E":1788407342514,"s":"BTCUSDT","U":99603299692,"u":99603299713,"b":[["77676.93000000","10.87325000"],["77676.92000000","0.01066000"],["77675.25000000","0.00000000"],["77675.24000000","0.00257000"],["77664.27000000","0.10753000"],["77663.18000000","0.00000000"],["77640.00000000","0.03188000"],["69909.24000000","0.00368000"],["62141.55000000","0.00032000"]],"a":[["77689.52000000","0.00000000"],["77691.09000000","0.00200000"],["77729.31000000","0.12879000"]]}}
{"type":"depth","received_at_ms":1788407342410,"data":{"e":"depthUpdate","E":1788407342614,"s":"BTCUSDT","U":99603299714,"u":99603299732,"b":[["77675.24000000","0.00000000"],["77675.23000000","0.00257000"],["77664.27000000","0.00000000"],["77663.18000000","0.14141000"],["69909.24000000","0.00368000"],["66025.39000000","0.06047000"],["66001.00000000","0.02060000"],["62142.00000000","0.00000000"],["62141.55000000","0.00000000"]],"a":[["77676.94000000","0.67332000"],["77711.89000000","0.80196000"],["77729.31000000","0.00000000"]]}}
{"type":"depth","received_at_ms":1788407342511,"data":{"e":"depthUpdate","E":1788407342714,"s":"BTCUSDT","U":99603299733,"u":99603299744,"b":[["77675.23000000","0.00000000"],["77674.31000000","0.00027000"],["77654.00000000","0.03000000"],["69909.24000000","0.00384000"]],"a":[["77681.14000000","0.00000000"],["77682.50000000","0.00007000"],["77683.07000000","0.00027000"],["77690.01000000","0.00000000"],["77691.91000000","0.00257000"],["77721.10000000","0.00007000"]]}}
{"type":"depth","received_at_ms":1788407342610,"data":{"e":"depthUpdate","E":1788407342814,"s":"BTCUSDT","U":99603299745,"u":99603299751,"b":[["69909.24000000","0.00368000"]],"a":[["77682.50000000","0.00014000"],["77690.98000000","0.00257000"],["77691.91000000","0.00000000"],["77721.10000000","0.00000000"],["77774.98000000","0.13329000"],["77777.54000000","0.00000000"]]}}
{"type":"depth","received_at_ms":1788407342710,"data":{"e":"depthUpdate","E":1788407342914,"s":"BTCUSDT","U":99603299752,"u":99603299763,"b":[["77676.93000000","10.87325000"],["77454.88000000","0.00000000"],["69909.24000000","0.00400000"],["62141.54000000","0.00000000"]],"a":[["77676.94000000","0.67347000"]]}}
{"type":"depth","received_at_ms":1788407342810,"data":{"e":"depthUpdate","E":1788407343014,"s":"BTCUSDT","U":99603299764,"u":99603299769,"b":[["77485.20000000","0.02017000"],["69909.24000000","0.00400000"],["62142.00000000","0.00000000"],["62141.55000000","0.00032000"]],"a":[]}}
{"type":"depth","received_at_ms":1788407342911,"data":{"e":"depthUpdate","E":1788407343114,"s":"BTCUSDT","U":99603299770,"u":99603299790,"b":[["77676.93000000","10.87301000"],["77676.92000000","0.01101000"],["77643.00000000","0.70000000"],["77485.20000000","0.00000000"],["76593.86000000","0.06596000"],["76337.74000000","0.00000000"],["69909.24000000","0.00400000"],["69909.23000000","0.00009000"]],"a":[["78040.19000000","0.00000000"],["80165.37000000","0.08778000"]]}}
{"type":"depth","received_at_ms":1788407343010,"data":{"e":"depthUpdate","E":1788407343214,"s":"BTCUSDT","U":99603299791,"u":99603299810,"b":[["77676.93000000","10.87266000"],["77676.92000000","0.01073000"],["77459.87000000","0.02017000"],["76593.86000000","0.00000000"],["75998.01000000","0.06648000"],["69909.24000000","0.00416000"],["62141.55000000","0.00000000"]],"a":[["77691.13000000","0.00000000"],["77703.46000000","0.00000000"],["77712.59000000","0.09878000"],["77730.94000000","0.00000000"],["77732.62000000","0.12879000"]]}}
{"type":"depth","received_at_ms":1788407343110,"data":{"e":"depthUpdate","E":1788407343314,"s":"BTCUSDT","U":99603299811,"u":99603299832,"b":[["77676.93000000","10.87308000"],["77676.92000000","0.01108000"],["77662.62000000","0.00000000"],["76511.77000000","0.00030000"],["69909.24000000","0.00432000"],["62142.00000000","0.00000000"]],"a":[["77691.56000000","0.27300000"],["77693.70000000","0.00000000"],["78384.54000000","0.09384000"],["80165.37000000","0.00000000"]]}}
{"type":"depth","received_at_ms":1788407343210,"data":{"e":"depthUpdate","E":1788407343414,"s":"BTCUSDT","U":99603299833,"u":99603299844,"b":[["77662.62000000","0.00007000"],["77546.26000000","0.00000000"],["69909.24000000","0.00432000"],["62142.00000000","0.00000000"]],"a":[["77693.70000000","0.00007000"],["77703.14000000","0.51849000"],["78842.10000000","0.00053000"]]}}
{"type":"depth","received_at_ms":1788407343310,"data":{"e":"depthUpdate","E":1788407343514,"s":"BTCUSDT","U":99603299845,"u":99603299851,"b":[["77642.00000000","0.03000000"],["69909.24000000","0.00432000"],["62141.55000000","0.00032000"]],"a":[["77732.62000000","0.00000000"],["77782.57000000","0.80887000"],["77782.64000000","2.60865000"]]}}
{"type":"depth","received_at_ms":1788407343411,"data":{"e":"depthUpdate","E":1788407343614,"s":"BTCUSDT","U":99603299852,"u":99603299859,"b":[["77676.93000000","10.80872000"],["77507.48000000","0.00000000"],["69909.24000000","0.00448000"],["69909.23000000","0.00000000"],["69909.22000000","0.00009000"],["62141.55000000","0.00000000"]],"a":[["77818.65000000","0.01000000"]]}}
{"type":"depth","received_at_ms":1788407343510,"data":{"e":"depthUpdate","E":1788407343714,"s":"BTCUSDT","U":99603299860,"u":99603299878,"b":[["69909.24000000","0.00432000"]],"a":[["77676.94000000","0.79049000"],["77676.95000000","0.00070000"],["77678.29000000","0.00548000"],["77678.30000000","0.00014000"],["77678.37000000","0.00007000"],["77678.38000000","0.10246000"],["77679.99000000","0.00000000"],["77688.46000000","0.10246000"],["77832.30000000","0.01000000"]]}}
{"type":"depth","received_at_ms":1788407343610,"data":{"e":"depthUpdate","E":1788407343814,"s":"BTCUSDT","U":99603299879,"u":99603299890,"b":[["77676.00000000","0.00257000"],["69909.24000000","0.00448000"]],"a":[["77676.94000000","0.91851000"],["77678.29000000","0.00548000"],["77678.30000000","0.00000000"],["77678.38000000","0.10260000"]]}}
{"type":"depth","received_at_ms":1788407343711,"data":{"e":"depthUpdate","E":1788407343914,"s":"BTCUSDT","U":99603299891,"u":99603299907,"b":[["77676.93000000","10.80879000"],["77676.92000000","0.01115000"],["77676.00000000","0.00000000"],["69909.24000000","0.00432000"],["62141.54000000","0.00000000"]],"a":[["77676.94000000","0.91858000"],["77676.95000000","0.00077000"],["77678.41000000","0.00007000"],["77729.84000000","0.00000000"],["77794.80000000","0.00000000"],["77818.65000000","0.00000000"]]}}
{"type":"depth","received_at_ms":1788407343812,"data":{"e":"depthUpdate","E":1788407344014,"s":"BTCUSDT","U":99603299908,"u":99603299918,"b":[["77676.93000000","10.80872000"],["77676.92000000","0.01108000"],["77675.97000000","0.00000000"],["77675.95000000","0.00257000"],["77596.51000000","0.72114000"],["77593.96000000","0.00000000"],["69909.24000000","0.00448000"],["62141.55000000","0.00032000"]],"a":[]}}
{"type":"depth","received_at_ms":1788407343911,"data":{"e":"depthUpdate","E":1788407344114,"s":"BTCUSDT","U":99603299919,"u":99603299990,"b":[["77676.93000000","9.35277000"],["77676.92000000","0.01059000"],["77675.95000000","0.00000000"],["77675.92000000","0.00257000"],["77674.89000000","0.55448000"],["69909.24000000","0.00432000"],["69909.22000000","0.00000000"]],"a":[["77676.94000000","0.41068000"],["77678.29000000","0.00014000"],["77682.50000000","0.00007000"],["77682.69000000","0.00000000"],["77684.43000000","0.00100000"],["77684.44000000","0.00722000"],["77833.69000000","0.00000000"]]}}
{"type":"depth","received_at_ms":1788407344010,"data":{"e":"depthUpdate","E":1788407344214,"s":"BTCUSDT","U":99603299991,"u":99603300022,"b":[["77676.93000000","9.35277000"],["77675.92000000","0.00000000"],["77675.89000000","0.00257000"],["77670.02000000","0.00200000"],["77669.53000000","0.08294000"],["77667.19000000","0.00000000"],["69909.24000000","0.00448000"],["62141.55000000","0.00000000"]],"a":[["77676.94000000","0.27795000"],["77676.95000000","0.00070000"],["77678.00000000","0.03028000"],["77678.29000000","0.00000000"],["77681.16000000","0.00548000"],["77730.44000000","0.12879000"],["77832.30000000","0.02000000"]]}}
{"type":"depth","received_at_ms":1788407344110,"data":{"e":"depthUpdate","E":1788407344314,"s":"BTCUSDT","U":99603300023,"u":99603300035,"b":[["77675.89000000","0.00000000"],["77675.87000000","0.00257000"],["76511.77000000","0.00030000"],["69909.24000000","0.00432000"],["62142.00000000","0.00000000"]],"a":[["77682.50000000","0.00014000"],["77712.59000000","0.09580000"],["77730.44000000","0.00000000"]]}}
{"type":"depth","received_at_ms":1788407344211,"data":{"e":"depthUpdate","E":1788407344414,"s":"BTCUSDT","U":99603300036,"u":99603300046,"b":[["77675.87000000","0.00000000"],["77675.85000000","0.00271000"],["77662.62000000","0.00007000"],["76977.84000000","0.00000000"],["69909.24000000","0.00448000"]],"a":[["77676.94000000","0.27756000"],["77693.70000000","0.00007000"],["77712.59000000","0.00000000"],["78842.10000000","0.00053000"]]}}
{"type":"depth","received_at_ms":1788407344311,"data":{"e":"depthUpdate","E":1788407344514,"s":"BTCUSDT","U":99603300047,"u":99603300053,"b":[["77675.85000000","0.00014000"],["77675.83000000","0.00257000"],["69909.24000000","0.00432000"],["62141.55000000","0.00032000"]],"a":[["77776.98000000","0.00089000"]]}}
{"type":"depth","received_at_ms":1788407344410,"data":{"e":"depthUpdate","E":1788407344614,"s":"BTCUSDT","U":99603300054,"u":99603300080,"b":[["77676.93000000","9.35326000"],["77676.92000000","0.01101000"],["77675.83000000","0.00000000"],["77675.81000000","0.00257000"],["71462.78000000","0.00014000"],["69909.24000000","0.00448000"],["62141.55000000","0.00000000"]],"a":[["77676.94000000","0.60303000"],["77677.49000000","0.12388000"]]}}
{"type":"depth","received_at_ms":1788407344510,"data":{"e":"depthUpdate","E":1788407344714,"s":"BTCUSDT","U":99603300081,"u":99603300092,"b":[["77675.81000000","0.00000000"],["69909.24000000","0.00432000"]],"a":[["77676.94000000","0.60317000"],["77677.48000000","0.00014000"],["77679.70000000","0.00000000"],["77681.16000000","0.00534000"]]}}
{"type":"depth","received_at_ms":1788407344611,"data":{"e":"depthUpdate","E":1788407344814,"s":"BTCUSDT","U":99603300093,"u":99603300123,"b":[["77676.93000000","9.35277000"],["77676.92000000","0.01059000"],["77675.79000000","0.00000000"],["77675.77000000","0.00257000"],["69909.24000000","0.00448000"],["62142.00000000","0.00000000"]],"a":[["77676.94000000","0.59967000"],["77676.95000000","0.00070000"],["77677.48000000","0.00000000"],["77677.49000000","0.00000000"],["77678.37000000","0.00014000"],["77679.70000000","0.00007000"]]}}
{"type":"depth","received_at_ms":1788407344711,"data":{"e":"depthUpdate","E":1788407344914,"s":"BTCUSDT","U":99603300124,"u":99603300133,"b":[["77676.93000000","9.35269000"],["77675.77000000","0.00000000"],["69909.24000000","0.00448000"],["62141.54000000","0.00000000"]],"a":[]}}
{"type":"depth","received_at_ms":1788407344810,"data":{"e":"depthUpdate","E":1788407345014,"s":"BTCUSDT","U":99603300134,"u":99603300183,"b":[["77676.93000000","9.32117000"],["77676.32000000","0.00000000"],["77676.31000000","0.00000000"],["69909.24000000","0.00441000"],["62141.55000000","0.00032000"]],"a":[["77676.94000000","0.37784000"],["77676.95000000","0.00070000"],["77678.37000000","0.00000000"],["77678.38000000","0.00014000"],["77679.70000000","0.00014000"],["77679.99000000","0.00007000"],["77681.15000000","0.11606000"],["77684.71000000","0.16878000"],["77685.21000000","0.03000000"],["77685.87000000","0.00000000"],["77686.13000000","0.00000000"],["77686.80000000","0.00676000"],["77687.43000000","0.12000000"],["77688.04000000","0.00000000"],["77692.21000000","0.00000000"],["77693.39000000","0.20100000"],["77694.64000000","0.00400000"],["77696.33000000","0.00000000"],["77702.89000000","0.00000000"],["77731.45000000","0.34748000"],["77778.60000000","4.63458000"],["77782.64000000","0.00000000"],["77785.19000000","2.60865000"]]}}
{"type":"depth","received_at_ms":1788407344910,"data":{"e":"depthUpdate","E":1788407345114,"s":"BTCUSDT","U":99603300184,"u":99603300211,"b":[["77676.93000000","9.35335000"],["77664.00000000","0.00265000"],["69909.24000000","0.00473000"],["62142.00000000","0.00200000"]],"a":[["77677.64000000","0.00014000"],["77678.00000000","0.03021000"],["77678.38000000","0.00000000"],["77679.71000000","0.03183000"],["77680.64000000","0.09485000"],["77681.15000000","0.11620000"],["77686.80000000","0.00000000"],["77687.01000000","0.00645000"],["77688.34000000","0.00536000"],["77707.00000000","0.00000000"],["77733.87000000","0.00000000"],["78384.54000000","0.00000000"],["80519.41000000","0.09384000"]]}}
{"type":"depth","received_at_ms":1788407345010,"data":{"e":"depthUpdate","E":1788407345214,"s":"BTCUSDT","U":99603300212,"u":99603300219,"b":[["71462.78000000","0.00000000"],["69909.24000000","0.00457000"],["62142.00000000","0.00000000"],["62141.55000000","0.00000000"]],"a":[["77716.70000000","0.00000000"],["77725.59000000","0.00623000"]]}}
{"type":"depth","received_at_ms":1788407345111,"data":{"e":"depthUpdate","E":1788407345314,"s":"BTCUSDT","U":99603300220,"u":99603300235,"b":[["77676.93000000","9.35277000"],["77676.31000000","0.00458000"],["76511.77000000","0.00030000"],["69909.24000000","0.00473000"],["62142.00000000","0.00000000"]],"a":[["77690.98000000","0.00000000"],["77691.56000000","0.00000000"],["77692.24000000","0.00257000"],["77733.20000000","0.00000000"],["78389.84000000","0.09384000"],["80519.41000000","0.00000000"]]}}
{"type":"depth","received_at_ms":1788407345210,"data":{"e":"depthUpdate","E":1788407345414,"s":"BTCUSDT","U":99603300236,"u":99603300249,"b":[["77662.62000000","0.00007000"],["76977.84000000","0.00010000"],["69909.24000000","0.00457000"]],"a":[["77676.94000000","0.55759000"],["77679.71000000","0.14187000"],["77681.15000000","0.00021000"],["77686.14000000","0.00000000"],["77693.21000000","0.00400000"],["77693.70000000","0.00007000"],["77694.64000000","0.00000000"],["78842.10000000","0.00053000"]]}}
{"type":"depth","received_at_ms":1788407345310,"data":{"e":"depthUpdate","E":1788407345514,"s":"BTCUSDT","U":99603300250,"u":99603300276,"b":[["77674.31000000","0.00000000"],["77670.02000000","0.00200000"],["77667.19000000","0.00000000"],["77552.65000000","0.00077000"],["69909.24000000","0.00473000"],["62141.55000000","0.00032000"]],"a":[["77676.94000000","0.55762000"],["77676.95000000","0.00063000"],["77680.64000000","0.09485000"],["77681.15000000","0.00007000"],["77681.16000000","0.00548000"],["77691.31000000","0.00257000"],["77691.79000000","0.00400000"],["77692.24000000","0.00000000"],["77693.21000000","0.00000000"],["77719.35000000","0.00007000"],["77778.58000000","1.75648000"]]}}
{"type":"depth","received_at_ms":1788407345410,"data":{"e":"depthUpdate","E":1788407345614,"s":"BTCUSDT","U":99603300277,"u":99603300287,"b":[["77660.89000000","0.00000000"],["77659.67000000","0.23854000"],["69909.24000000","0.00457000"],["62142.00000000","0.00000000"],["62141.55000000","0.00000000"]],"a":[["77734.15000000","0.00000000"]]}}
{"type":"depth","received_at_ms":1788407345511,"data":{"e":"depthUpdate","E":1788407345714,"s":"BTCUSDT","U":99603300288,"u":99603300291,"b":[["77513.87000000","0.00077000"],["69909.24000000","0.00473000"]],"a":[["77677.64000000","0.00007000"],["77679.95000000","0.00000000"]]}}
{"type":"depth","received_at_ms":1788407345610,"data":{"e":"depthUpdate","E":1788407345814,"s":"BTCUSDT","U":99603300292,"u":99603300332,"b":[["77676.93000000","9.32154000"],["77610.21000000","0.00000000"],["69909.24000000","0.00448000"],["69909.23000000","0.00009000"]],"a":[["77676.94000000","0.51784000"],["77680.00000000","0.03021000"],["77682.00000000","0.03014000"],["77691.79000000","0.00000000"],["77692.63000000","0.00400000"]]}}
{"type":"depth","received_at_ms":1788407345714,"data":{"e":"depthUpdate","E":1788407345914,"s":"BTCUSDT","U":99603300333,"u":99603300349,"b":[["77676.93000000","9.35372000"],["77676.92000000","0.01059000"],["77670.02000000","0.00000000"],["77667.68000000","0.32966000"],["77667.24000000","0.00200000"],["77658.32000000","0.00000000"],["69909.24000000","0.00464000"],["62141.54000000","0.00000000"]],"a":[["77801.21000000","0.00102000"]]}}
{"type":"depth","received_at_ms":1788407345810,"data":{"e":"depthUpdate","E":1788407346015,"s":"BTCUSDT","U":99603300350,"u":99603300359,"b":[["77670.02000000","0.00200000"],["77669.86000000","0.12537000"],["77667.24000000","0.00000000"],["69909.24000000","0.00448000"],["62142.00000000","0.00000000"],["62141.55000000","0.00032000"]],"a":[["77686.14000000","0.00007000"],["77710.00000000","0.73200000"],["77719.51000000","0.00833000"]]}}
{"type":"depth","received_at_ms":1788407345910,"data":{"e":"depthUpdate","E":1788407346114,"s":"BTCUSDT","U":99603300360,"u":99603300370,"b":[["77676.47000000","0.00257000"],["77661.58000000","0.00000000"],["77400.00000000","1.66406000"],["69909.24000000","0.00464000"]],"a":[["77731.95000000","0.00000000"],["77780.09000000","2.60865000"],["77782.57000000","0.03463000"],["77785.19000000","0.00000000"]]}}
{"type":"depth","received_at_ms":1788407346010,"data":{"e":"depthUpdate","E":1788407346214,"s":"BTCUSDT","U":99603300371,"u":99603300385,"b":[["77676.47000000","0.00000000"],["77676.46000000","0.00000000"],["77676.45000000","0.00257000"],["77670.02000000","0.00000000"],["77667.24000000","0.00200000"],["69909.24000000","0.00448000"],["62141.55000000","0.00000000"]],"a":[["77676.94000000","0.51791000"],["77682.15000000","0.09989000"],["77731.16000000","0.00000000"],["77840.11000000","0.00102000"]]}}
{"type":"depth","received_at_ms":1788407346111,"data":{"e":"depthUpdate","E":1788407346314,"s":"BTCUSDT","U":99603300386,"u":99603300398,"b":[["77676.45000000","0.00000000"],["77676.44000000","0.00257000"],["77670.02000000","0.00200000"],["77667.24000000","0.00000000"],["76511.77000000","0.00030000"],["69909.24000000","0.00432000"],["62142.00000000","0.00000000"]],"a":[["77731.52000000","0.00000000"]]}}
{"type":"depth","received_at_ms":1788407346210,"data":{"e":"depthUpdate","E":1788407346414,"s":"BTCUSDT","U":99603300399,"u":99603300410,"b":[["77676.93000000","9.35430000"],["77676.31000000","0.00400000"],["77663.27000000","0.30640000"],["77662.62000000","0.00000000"],["77621.47000000","0.02000000"],["77497.31000000","0.00000000"],["75561.73000000","0.00000000"],["69909.24000000","0.00448000"]],"a":[["77693.70000000","0.00000000"],["77731.82000000","0.00000000"],["77854.07000000","0.00000000"],["78842.10000000","0.00053000"],["81006.07000000","0.00000000"]]}}
{"type":"depth","received_at_ms":1788407346311,"data":{"e":"depthUpdate","E":1788407346514,"s":"BTCUSDT","U":99603300411,"u":99603300432,"b":[["77676.44000000","0.00000000"],["77676.43000000","0.00257000"],["77670.02000000","0.00000000"],["77667.19000000","0.00200000"],["77662.62000000","0.00007000"],["77608.57000000","0.00000000"],["69909.24000000","0.00448000"],["62141.55000000","0.00032000"]],"a":[["77678.39000000","0.10317000"],["77678.67000000","0.00007000"],["77678.68000000","0.11916000"],["77679.71000000","0.03183000"],["77679.99000000","0.00000000"],["77693.70000000","0.00007000"],["77697.24000000","0.10317000"],["77698.69000000","0.10317000"],["77699.38000000","0.10317000"],["77717.32000000","0.00000000"],["77730.30000000","0.00000000"]]}}
{"type":"depth","received_at_ms":1788407346410,"data":{"e":"depthUpdate","E":1788407346614,"s":"BTCUSDT","U":99603300433,"u":99603300463,"b":[["77676.43000000","0.00000000"],["77613.40000000","0.02000000"],["77503.63000000","4.46301000"],["69909.24000000","0.00448000"],["62141.55000000","0.00000000"],["50000.00000000","488.77739000"]],"a":[["77676.94000000","0.51805000"],["77676.95000000","0.00077000"],["77678.00000000","0.03021000"],["77678.38000000","0.00014000"],["77678.39000000","0.10331000"],["77678.68000000","0.11930000"],["77679.70000000","0.00000000"],["77681.16000000","0.00534000"],["77682.00000000","0.03000000"],["77714.35000000","0.02000000"],["77731.68000000","0.12879000"],["77756.17000000","0.02000000"],["77856.14000000","4.46879000"]]}}
{"type":"depth","received_at_ms":1788407346510,"data":{"e":"depthUpdate","E":1788407346714,"s":"BTCUSDT","U":99603300464,"u":99603300480,"b":[["77676.42000000","0.00257000"],["77670.02000000","0.00200000"],["77667.19000000","0.00000000"],["75388.00000000","2.10334000"],["69909.24000000","0.00448000"],["62142.00000000","0.00000000"]],"a":[["77677.81000000","0.13008000"],["77678.67000000","0.00000000"],["77678.68000000","0.00014000"],["77692.30000000","0.28098000"],["77731.68000000","0.00000000"]]}}
{"type":"depth","received_at_ms":1788407346610,"data":{"e":"depthUpdate","E":1788407346814,"s":"BTCUSDT","U":99603300481,"u":99603300508,"b":[["77676.93000000","9.35171000"],["77676.42000000","0.00000000"],["77676.41000000","0.00257000"],["77608.65000000","0.00000000"],["69909.24000000","0.00464000"],["69909.23000000","0.00000000"]],"a":[["77676.94000000","0.51816000"],["77676.95000000","0.00077000"],["77677.80000000","0.00007000"],["77677.81000000","0.13022000"],["77678.39000000","0.10331000"],["77678.68000000","0.00000000"],["77679.95000000","0.00007000"],["77720.40000000","0.00000000"]]}}
{"type":"depth","received_at_ms":1788407346710,"data":{"e":"depthUpdate","E":1788407346914,"s":"BTCUSDT","U":99603300509,"u":99603300518,"b":[["77676.93000000","9.35163000"],["69909.24000000","0.00448000"],["62141.54000000","0.00020000"]],"a":[["77678.41000000","0.00000000"],["77731.74000000","0.03210000"]]}}
{"type":"depth","received_at_ms":1788407346810,"data":{"e":"depthUpdate","E":1788407347014,"s":"BTCUSDT","U":99603300519,"u":99603300542,"b":[["77676.93000000","9.35110000"],["77676.92000000","0.01066000"],["77676.42000000","0.00059000"],["77670.02000000","0.00000000"],["77666.89000000","0.00200000"],["69909.24000000","0.00464000"],["62141.55000000","0.00032000"],["62141.54000000","0.00000000"]],"a":[["77676.94000000","0.55262000"],["77731.89000000","0.00000000"],["77756.17000000","0.00000000"]]}}
{"type":"depth","received_at_ms":1788407346910,"data":{"e":"depthUpdate","E":1788407347114,"s":"BTCUSDT","U":99603300543,"u":99603300547,"b":[["77654.49000000","0.04647000"],["77648.79000000","0.00000000"],["69909.24000000","0.00448000"]],"a":[]}}
{"type":"depth","received_at_ms":1788407347009,"data":{"e":"depthUpdate","E":1788407347214,"s":"BTCUSDT","U":99603300548,"u":99603300554,"b":[["69909.24000000","0.00473000"],["62141.55000000","0.00000000"]],"a":[["77676.94000000","0.55241000"],["77731.75000000","0.12879000"]]}}
{"type":"depth","received_at_ms":1788407347112,"data":{"e":"depthUpdate","E":1788407347315,"s":"BTCUSDT","U":99603300555,"u":99603300570,"b":[["77674.89000000","0.50091000"],["77650.27000000","0.00000000"],["77627.07000000","0.45328000"],["77626.41000000","0.00000000"],["77599.06000000","0.72114000"],["77596.51000000","0.00000000"],["76511.77000000","0.00030000"],["75561.73000000","0.00010000"],["69909.24000000","0.00457000"],["62142.00000000","0.00000000"]],"a":[["77703.14000000","0.00000000"],["77727.33000000","0.00000000"],["77731.75000000","0.00000000"]]}}
{"type":"depth","received_at_ms":1788407347210,"data":{"e":"depthUpdate","E":1788407347414,"s":"BTCUSDT","U":99603300571,"u":99603300583,"b":[["77676.93000000","9.35110000"],["77676.92000000","0.01066000"],["77667.24000000","0.00200000"],["77666.89000000","0.00000000"],["77619.93000000","0.02200000"],["69909.24000000","0.00473000"]],"a":[["77714.16000000","0.02000000"],["77759.25000000","0.02000000"],["78842.10000000","0.00023000"]]}}
{"type":"depth","received_at_ms":1788407347311,"data":{"e":"depthUpdate","E":1788407347514,"s":"BTCUSDT","U":99603300584,"u":99603300593,"b":[["77676.93000000","9.35117000"],["77676.92000000","0.01073000"],["77662.62000000","0.00007000"],["69909.24000000","0.00457000"],["62141.55000000","0.00032000"]],"a":[["77693.70000000","0.00007000"],["78842.10000000","0.00053000"]]}}
{"type":"depth","received_at_ms":1788407347412,"data":{"e":"depthUpdate","E":1788407347614,"s":"BTCUSDT","U":99603300594,"u":99603300603,"b":[["77656.86000000","0.51831000"],["77656.84000000","0.10695000"],["77633.57000000","1.02532000"],["69909.24000000","0.00457000"],["62141.55000000","0.00000000"]],"a":[["77694.33000000","0.10446000"],["77702.48000000","0.50467000"],["77725.79000000","0.97998000"],["81006.07000000","0.00010000"]]}}
{"type":"depth","received_at_ms":1788407347510,"data":{"e":"depthUpdate","E":1788407347714,"s":"BTCUSDT","U":99603300604,"u":99603300609,"b":[["76978.58000000","0.06563000"],["75998.01000000","0.00000000"],["69909.24000000","0.00457000"]],"a":[["77759.25000000","0.00000000"],["78065.33000000","0.00007000"]]}}
{"type":"depth","received_at_ms":1788407347611,"data":{"e":"depthUpdate","E":1788407347814,"s":"BTCUSDT","U":99603300610,"u":99603300618,"b":[["77670.02000000","0.00200000"],["77667.24000000","0.00000000"],["69909.24000000","0.00457000"],["62142.00000000","0.00000000"]],"a":[["77712.65000000","0.09642000"]]}}
{"type":"depth","received_at_ms":1788407347711,"data":{"e":"depthUpdate","E":1788407347914,"s":"BTCUSDT","U":99603300619,"u":99603300620,"b":[["69909.24000000","0.00441000"]],"a":[["77717.29000000","0.12782000"]]}}
{"type":"depth","received_at_ms":1788407347844,"data":{"e":"depthUpdate","E":1788407348014,"s":"BTCUSDT","U":99603300621,"u":99603300633,"b":[["69909.24000000","0.00457000"],["62141.55000000","0.00032000"],["62141.54000000","0.00000000"]],"a":[["77729.03000000","0.00000000"],["77729.17000000","0.00000000"],["77729.51000000","0.12879000"]]}}
{"type":"depth","received_at_ms":1788407347949,"data":{"e":"depthUpdate","E":1788407348114,"s":"BTCUSDT","U":99603300634,"u":99603300644,"b":[["76978.58000000","0.00000000"],["76253.85000000","0.06625000"],["69909.24000000","0.00457000"],["62142.00000000","0.00200000"]],"a":[["77729.51000000","0.00000000"],["77729.52000000","0.54141000"],["78389.84000000","0.00000000"],["79084.58000000","0.09384000"]]}}
{"type":"depth","received_at_ms":1788407348024,"data":{"e":"depthUpdate","E":1788407348214,"s":"BTCUSDT","U":99603300645,"u":99603300654,"b":[["77676.93000000","9.35078000"],["69909.24000000","0.00416000"],["69909.23000000","0.00009000"],["62142.00000000","0.00000000"],["62141.55000000","0.00000000"]],"a":[["77676.94000000","0.55386000"],["77729.52000000","0.41262000"],["77729.84000000","0.00000000"]]}}
{"type":"depth","received_at_ms":1788407348118,"data":{"e":"depthUpdate","E":1788407348314,"s":"BTCUSDT","U":99603300655,"u":99603300665,"b":[["76511.77000000","0.00030000"],["69909.24000000","0.00448000"],["62142.00000000","0.00000000"]],"a":[["77729.63000000","0.00000000"],["77729.91000000","0.37879000"],["77730.09000000","0.00000000"]]}}
{"type":"depth","received_at_ms":1788407348211,"data":{"e":"depthUpdate","E":1788407348414,"s":"BTCUSDT","U":99603300666,"u":99603300682,"b":[["77676.93000000","9.35071000"],["77676.92000000","0.01066000"],["77638.49000000","0.02486000"],["77634.75000000","0.00000000"],["69909.24000000","0.00432000"],["62142.00000000","0.00000000"]],"a":[["77708.37000000","0.00000000"],["77714.11000000","0.02000000"],["77729.48000000","0.00000000"],["77729.91000000","0.25000000"],["77756.14000000","0.02000000"],["78386.22000000","0.09384000"],["79084.58000000","0.00000000"]]}}
{"type":"depth","received_at_ms":1788407348312,"data":{"e":"depthUpdate","E":1788407348514,"s":"BTCUSDT","U":99603300683,"u":99603300704,"b":[["77676.93000000","9.35131000"],["77676.92000000","0.01059000"],["77676.42000000","0.00000000"],["77676.41000000","0.00000000"],["77675.97000000","0.00000000"],["77662.62000000","0.00007000"],["77642.09000000","0.91258000"],["77612.51000000","0.00000000"],["76975.01000000","0.06563000"],["76253.85000000","0.00000000"],["69909.24000000","0.00448000"],["62141.55000000","0.00032000"]],"a":[["77692.63000000","0.00000000"],["77693.34000000","0.00400000"],["77693.70000000","0.00007000"],["77756.14000000","0.00000000"],["78842.10000000","0.00053000"]]}}
{"type":"depth","received_at_ms":1788407348411,"data":{"e":"depthUpdate","E":1788407348614,"s":"BTCUSDT","U":99603300705,"u":99603300721,"b":[["77675.96000000","0.00000000"],["77634.48000000","0.85344000"],["77599.06000000","0.00000000"],["77596.51000000","0.72114000"],["76629.62000000","0.00014000"],["69909.24000000","0.00432000"],["62142.00000000","0.00000000"],["62141.55000000","0.00000000"]],"a":[]}}
{"type":"depth","received_at_ms":1788407348511,"data":{"e":"depthUpdate","E":1788407348714,"s":"BTCUSDT","U":99603300722,"u":99603300731,"b":[["77675.95000000","0.00257000"],["77670.02000000","0.00000000"],["77667.19000000","0.00000000"],["69909.24000000","0.00448000"],["69909.23000000","0.00000000"]],"a":[["77676.94000000","0.55263000"],["78065.33000000","0.00000000"]]}}
{"type":"depth","received_at_ms":1788407348611,"data":{"e":"depthUpdate","E":1788407348814,"s":"BTCUSDT","U":99603300732,"u":99603300742,"b":[["77675.95000000","0.00000000"],["77675.94000000","0.00257000"],["77670.02000000","0.00000000"],["77667.24000000","0.00200000"],["77622.14000000","0.02200000"],["77609.44000000","0.00000000"],["69909.24000000","0.00432000"]],"a":[["77676.96000000","0.00034000"]]}}
{"type":"depth","received_at_ms":1788407348710,"data":{"e":"depthUpdate","E":1788407348914,"s":"BTCUSDT","U":99603300743,"u":99603300751,"b":[["77676.93000000","9.35123000"],["77675.94000000","0.00000000"],["77670.02000000","0.00200000"],["77667.24000000","0.00000000"],["69909.24000000","0.00448000"]],"a":[["77729.93000000","0.00000000"]]}}
{"type":"depth","received_at_ms":1788407348811,"data":{"e":"depthUpdate","E":1788407349014,"s":"BTCUSDT","U":99603300752,"u":99603300766,"b":[["77676.93000000","9.35056000"],["77676.32000000","0.00089000"],["77675.93000000","0.00257000"],["69909.24000000","0.00432000"],["62142.00000000","0.00000000"],["62141.55000000","0.00032000"],["62141.54000000","0.00000000"]],"a":[["77780.09000000","0.00000000"],["77782.57000000","0.80887000"],["77785.19000000","2.60865000"]]}}
{"type":"depth","received_at_ms":1788407348910,"data":{"e":"depthUpdate","E":1788407349114,"s":"BTCUSDT","U":99603300767,"u":99603300772,"b":[["77675.93000000","0.00000000"],["77675.92000000","0.00257000"],["69909.24000000","0.00432000"]],"a":[]}}
{"type":"depth","received_at_ms":1788407349010,"data":{"e":"depthUpdate","E":1788407349214,"s":"BTCUSDT","U":99603300773,"u":99603300780,"b":[["77676.93000000","9.35064000"],["77675.92000000","0.00000000"],["77675.91000000","0.00257000"],["69909.24000000","0.00441000"],["62141.55000000","0.00000000"]],"a":[["77676.94000000","0.55294000"],["77693.18000000","0.00000000"]]}}
{"type":"depth","received_at_ms":1788407349110,"data":{"e":"depthUpdate","E":1788407349314,"s":"BTCUSDT","U":99603300781,"u":99603300796,"b":[["77670.02000000","0.00000000"],["77667.19000000","0.00200000"],["76511.77000000","0.00030000"],["69909.24000000","0.00441000"],["62142.00000000","0.00000000"]],"a":[["77676.94000000","0.55356000"],["77677.80000000","0.00000000"],["77677.81000000","0.00014000"],["77679.70000000","0.00007000"],["77698.69000000","0.00000000"],["77699.38000000","0.00000000"]]}}
{"type":"depth","received_at_ms":1788407349212,"data":{"e":"depthUpdate","E":1788407349415,"s":"BTCUSDT","U":99603300797,"u":99603300816,"b":[["77676.31000000","0.00000000"],["77676.11000000","0.00400000"],["77675.91000000","0.00000000"],["77675.90000000","0.00809000"],["77670.02000000","0.00200000"],["77667.19000000","0.00000000"],["77623.82000000","0.02400000"],["69909.24000000","0.00441000"],["62142.00000000","0.00000000"]],"a":[["77676.94000000","0.55363000"],["77676.95000000","0.00070000"],["77677.81000000","0.00000000"],["77730.46000000","0.12879000"]]}}
{"type":"depth","received_at_ms":1788407349310,"data":{"e":"depthUpdate","E":1788407349515,"s":"BTCUSDT","U":99603300817,"u":99603300832,"b":[["77675.90000000","0.00552000"],["77675.89000000","0.00257000"],["77670.02000000","0.00000000"],["77667.24000000","0.00200000"],["77662.62000000","0.00000000"],["77634.48000000","0.80289000"],["77613.32000000","0.00000000"],["69909.24000000","0.00432000"],["69909.23000000","0.00009000"],["62142.00000000","0.00000000"],["62141.55000000","0.00032000"]],"a":[["77676.94000000","0.55356000"],["77693.70000000","0.00000000"],["78842.10000000","0.00053000"]]}}
{"type":"depth","received_at_ms":1788407349409,"data":{"e":"depthUpdate","E":1788407349614,"s":"BTCUSDT","U":99603300833,"u":99603300843,"b":[["77676.11000000","0.00000000"],["77675.89000000","0.00000000"],["77670.02000000","0.00200000"],["77667.24000000","0.00000000"],["77662.62000000","0.00007000"],["69909.24000000","0.00448000"],["62141.55000000","0.00000000"]],"a":[["77678.41000000","0.00007000"],["77693.70000000","0.00007000"]]}}
{"type":"depth","received_at_ms":1788407349511,"data":{"e":"depthUpdate","E":1788407349715,"s":"BTCUSDT","U":99603300844,"u":99603300848,"b":[["77676.33000000","0.00400000"],["77675.88000000","0.00257000"],["69909.24000000","0.00432000"]],"a":[]}}
{"type":"depth","received_at_ms":1788407349610,"data":{"e":"depthUpdate","E":1788407349814,"s":"BTCUSDT","U":99603300849,"u":99603300854,"b":[["77675.88000000","0.00000000"],["77675.87000000","0.00257000"],["77626.03000000","0.02000000"],["77545.01000000","0.13856000"],["69909.24000000","0.00432000"]],"a":[]}}
{"type":"depth","received_at_ms":1788407349711,"data":{"e":"depthUpdate","E":1788407349914,"s":"BTCUSDT","U":99603300855,"u":99603300862,"b":[["77548.20000000","0.02017000"],["69909.24000000","0.00432000"]],"a":[["77676.94000000","0.55363000"],["77676.95000000","0.00077000"],["77678.76000000","0.00007000"],["77678.77000000","0.12719000"],["77679.70000000","0.00000000"]]}}
{"type":"depth","received_at_ms":1788407349811,"data":{"e":"depthUpdate","E":1788407350014,"s":"BTCUSDT","U":99603300863,"u":99603300876,"b":[["77675.87000000","0.00000000"],["77675.86000000","0.00257000"],["69909.24000000","0.00448000"],["62141.55000000","0.00032000"],["62141.54000000","0.00000000"]],"a":[["77678.39000000","0.10331000"]]}}
{"type":"depth","received_at_ms":1788407349911,"data":{"e":"depthUpdate","E":1788407350115,"s":"BTCUSDT","U":99603300877,"u":99603300881,"b":[["77675.86000000","0.00000000"],["77675.85000000","0.00271000"],["69909.24000000","0.00416000"]],"a":[["77679.95000000","0.00000000"]]}}
{"type":"depth","received_at_ms":1788407350010,"data":{"e":"depthUpdate","E":1788407350214,"s":"BTCUSDT","U":99603300882,"u":99603300887,"b":[["76975.01000000","0.00000000"],["76329.92000000","0.06619000"],["71462.78000000","0.00014000"],["69909.24000000","0.00448000"],["62141.55000000","0.00000000"]],"a":[]}}
{"type":"depth","received_at_ms":1788407350110,"data":{"e":"depthUpdate","E":1788407350314,"s":"BTCUSDT","U":99603300888,"u":99603300898,"b":[["77675.85000000","0.00014000"],["77675.84000000","0.04330000"],["76951.46000000","0.06565000"],["76511.77000000","0.00030000"],["76329.92000000","0.00000000"],["69909.24000000","0.00432000"],["62142.00000000","0.00000000"]],"a":[]}}
{"type":"depth","received_at_ms":1788407350211,"data":{"e":"depthUpdate","E":1788407350414,"s":"BTCUSDT","U":99603300899,"u":99603300906,"b":[["77675.84000000","0.04073000"],["77675.83000000","0.00257000"],["77670.02000000","0.00000000"],["77667.24000000","0.00000000"],["69909.24000000","0.00448000"]],"a":[]}}
{"type":"depth","received_at_ms":1788407350310,"data":{"e":"depthUpdate","E":1788407350514,"s":"BTCUSDT","U":99603300907,"u":99603300913,"b":[["77670.02000000","0.00200000"],["69909.24000000","0.00432000"],["62141.55000000","0.00032000"]],"a":[["77782.65000000","2.60865000"],["77785.19000000","0.00000000"],["78842.10000000","0.00053000"]]}}
{"type":"depth","received_at_ms":1788407350410,"data":{"e":"depthUpdate","E":1788407350614,"s":"BTCUSDT","U":99603300914,"u":99603300923,"b":[["77675.83000000","0.00000000"],["77675.82000000","0.00257000"],["77662.62000000","0.00007000"],["69909.24000000","0.00432000"],["62141.55000000","0.00000000"]],"a":[["77693.70000000","0.00007000"]]}}
{"type":"depth","received_at_ms":1788407350511,"data":{"e":"depthUpdate","E":1788407350714,"s":"BTCUSDT","U":99603300924,"u":99603300931,"b":[["77670.02000000","0.00200000"],["77648.24000000","0.00000000"],["77625.75000000","0.25754000"],["77619.05000000","0.85895000"],["77617.36000000","0.00000000"],["69909.24000000","0.00432000"]],"a":[]}}
{"type":"depth","received_at_ms":1788407350611,"data":{"e":"depthUpdate","E":1788407350814,"s":"BTCUSDT","U":99603300932,"u":99603300938,"b":[["77675.82000000","0.00000000"],["77675.81000000","0.00257000"],["71462.78000000","0.00000000"],["69909.24000000","0.00432000"],["62142.00000000","0.00000000"]],"a":[]}}
{"type":"depth","received_at_ms":1788407350710,"data":{"e":"depthUpdate","E":1788407350914,"s":"BTCUSDT","U":99603300939,"u":99603300945,"b":[["77676.93000000","9.35056000"],["77675.81000000","0.00000000"],["77675.80000000","0.00257000"],["69909.24000000","0.00432000"]],"a":[]}}
{"type":"depth","received_at_ms":1788407350814,"data":{"e":"depthUpdate","E":1788407351014,"s":"BTCUSDT","U":99603300946,"u":99603300952,"b":[["77599.06000000","0.72114000"],["77596.51000000","0.00000000"],["69909.24000000","0.00432000"],["62141.55000000","0.00032000"]],"a":[]}}
{"type":"depth","received_at_ms":1788407350911,"data":{"e":"depthUpdate","E":1788407351114,"s":"BTCUSDT","U":99603300953,"u":99603300974,"b":[["77676.92000000","0.02059000"],["77675.80000000","0.00000000"],["77675.79000000","0.00257000"],["77642.08000000","0.00000000"],["69909.24000000","0.00448000"],["69909.23000000","0.00000000"],["62142.00000000","0.00200000"],["62141.54000000","0.00000000"]],"a":[["77676.94000000","0.55205000"],["77704.12000000","0.04584000"]]}}
{"type":"depth","received_at_ms":1788407351011,"data":{"e":"depthUpdate","E":1788407351214,"s":"BTCUSDT","U":99603300975,"u":99603300983,"b":[["77676.93000000","9.35063000"],["77674.88000000","1.18754000"],["69909.24000000","0.00432000"],["62142.00000000","0.00000000"],["62141.55000000","0.00000000"]],"a":[["77678.76000000","0.00014000"]]}}
{"type":"depth","received_at_ms":1788407351110,"data":{"e":"depthUpdate","E":1788407351314,"s":"BTCUSDT","U":99603300984,"u":99603300994,"b":[["77675.79000000","0.00000000"],["77675.00000000","0.00257000"],["76511.77000000","0.00030000"],["69909.24000000","0.00448000"],["62142.00000000","0.00000000"]],"a":[["77690.53000000","0.00257000"],["77691.31000000","0.00000000"]]}}
{"type":"depth","received_at_ms":1788407351211,"data":{"e":"depthUpdate","E":1788407351414,"s":"BTCUSDT","U":99603300995,"u":99603300997,"b":[["69909.24000000","0.00416000"],["65146.32000000","0.00000000"]],"a":[]}}
{"type":"depth","received_at_ms":1788407351310,"data":{"e":"depthUpdate","E":1788407351514,"s":"BTCUSDT","U":99603300998,"u":99603301005,"b":[["77670.02000000","0.00000000"],["77667.19000000","0.00000000"],["69909.24000000","0.00448000"],["62141.55000000","0.00032000"]],"a":[["78842.10000000","0.00053000"]]}}
{"type":"depth","received_at_ms":1788407351410,"data":{"e":"depthUpdate","E":1788407351614,"s":"BTCUSDT","U":99603301006,"u":99603301024,"b":[["77676.93000000","9.34804000"],["77670.02000000","0.00200000"],["77662.62000000","0.00007000"],["69909.24000000","0.00432000"],["69909.23000000","0.00009000"],["65146.32000000","0.01188000"],["62142.00000000","0.00000000"],["62141.55000000","0.00000000"]],"a":[["77676.94000000","0.55191000"],["77678.77000000","0.12733000"],["77693.70000000","0.00007000"]]}}
{"type":"depth","received_at_ms":1788407351510,"data":{"e":"depthUpdate","E":1788407351714,"s":"BTCUSDT","U":99603301025,"u":99603301027,"b":[["69909.24000000","0.00432000"]],"a":[["77893.00000000","0.00000000"]]}}
{"type":"depth","received_at_ms":1788407351610,"data":{"e":"depthUpdate","E":1788407351814,"s":"BTCUSDT","U":99603301028,"u":99603301029,"b":[["69909.24000000","0.00432000"]],"a":[]}}
{"type":"depth","received_at_ms":1788407351711,"data":{"e":"depthUpdate","E":1788407351914,"s":"BTCUSDT","U":99603301030,"u":99603301035,"b":[["77676.93000000","9.34812000"],["69909.24000000","0.00448000"]],"a":[["77676.94000000","0.54013000"]]}}
{"type":"depth","received_at_ms":1788407351810,"data":{"e":"depthUpdate","E":1788407352014,"s":"BTCUSDT","U":99603301036,"u":99603301041,"b":[["69909.24000000","0.00432000"],["62142.00000000","0.00000000"],["62141.55000000","0.00032000"]],"a":[]}}
{"type":"depth","received_at_ms":1788407351910,"data":{"e":"depthUpdate","E":1788407352114,"s":"BTCUSDT","U":99603301042,"u":99603301047,"b":[["69909.24000000","0.00432000"],["62141.54000000","0.00000000"]],"a":[]}}
{"type":"depth","received_at_ms":1788407352012,"data":{"e":"depthUpdate","E":1788407352214,"s":"BTCUSDT","U":99603301048,"u":99603301052,"b":[["77670.02000000","0.00000000"],["77666.89000000","0.00200000"],["69909.24000000","0.00432000"],["62141.55000000","0.00000000"]],"a":[]}}
{"type":"depth","received_at_ms":1788407352111,"data":{"e":"depthUpdate","E":1788407352314,"s":"BTCUSDT","U":99603301053,"u":99603301065,"b":[["77630.61000000","0.00000000"],["76951.46000000","0.00000000"],["76951.02000000","0.06565000"],["76511.77000000","0.00030000"],["69909.24000000","0.00432000"],["62142.00000000","0.00000000"]],"a":[["78386.22000000","0.00000000"],["78386.45000000","0.09384000"]]}}
{"type":"depth","received_at_ms":1788407352210,"data":{"e":"depthUpdate","E":1788407352414,"s":"BTCUSDT","U":99603301066,"u":99603301082,"b":[["77676.93000000","9.34667000"],["77611.24000000","0.00000000"],["77532.96000000","0.00000000"],["75561.73000000","0.00000000"]],"a":[["77677.34000000","0.00014000"],["77677.35000000","0.11837000"],["77678.76000000","0.00000000"],["77678.77000000","0.00014000"],["77689.54000000","2.02561000"],["77692.17000000","0.00400000"],["77692.28000000","0.10317000"],["77692.29000000","4.63458000"],["77692.47000000","0.00000000"],["77693.34000000","0.00000000"],["77697.24000000","0.00000000"],["81006.07000000","0.00000000"]]}}
{"type":"depth","received_at_ms":1788407352311,"data":{"e":"depthUpdate","E":1788407352514,"s":"BTCUSDT","U":99603301083,"u":99603301114,"b":[["77611.24000000","0.00320000"],["77532.96000000","0.00128000"],["69909.24000000","0.00432000"],["69909.23000000","0.00000000"],["69909.22000000","0.00009000"],["62141.55000000","0.00032000"]],"a":[["77676.94000000","0.53923000"],["77677.35000000","0.11851000"],["77678.39000000","0.10331000"],["77678.77000000","0.00000000"],["77689.52000000","0.01600000"],["77692.58000000","0.00400000"],["77918.09000000","0.00257000"],["78842.10000000","0.00053000"]]}}
{"type":"depth","received_at_ms":1788407352410,"data":{"e":"depthUpdate","E":1788407352614,"s":"BTCUSDT","U":99603301115,"u":99603301123,"b":[["77670.02000000","0.00200000"],["77666.89000000","0.00000000"],["77662.62000000","0.00000000"],["77637.41000000","0.80273000"],["69909.24000000","0.00448000"],["62141.55000000","0.00000000"]],"a":[["77693.70000000","0.00000000"],["77696.04000000","0.10690000"]]}}
{"type":"depth","received_at_ms":1788407352510,"data":{"e":"depthUpdate","E":1788407352714,"s":"BTCUSDT","U":99603301124,"u":99603301134,"b":[["77662.62000000","0.00007000"],["77598.16000000","0.00483000"],["77587.64000000","0.00000000"],["69909.24000000","0.00432000"],["62142.00000000","0.00000000"]],"a":[["77676.94000000","0.53923000"],["77676.95000000","0.00077000"],["77693.70000000","0.00007000"]]}}
{"type":"depth","received_at_ms":1788407352609,"data":{"e":"depthUpdate","E":1788407352814,"s":"BTCUSDT","U":99603301135,"u":99603301140,"b":[["77670.02000000","0.00000000"],["77667.19000000","0.00200000"],["69909.24000000","0.00448000"]],"a":[["77679.95000000","0.00007000"]]}}
{"type":"depth","received_at_ms":1788407352710,"data":{"e":"depthUpdate","E":1788407352914,"s":"BTCUSDT","U":99603301141,"u":99603301149,"b":[["77676.93000000","9.34659000"],["77670.02000000","0.00000000"],["77667.19000000","0.00000000"],["69909.24000000","0.00432000"]],"a":[]}}
{"type":"depth","received_at_ms":1788407352811,"data":{"e":"depthUpdate","E":1788407353014,"s":"BTCUSDT","U":99603301150,"u":99603301167,"b":[["77676.93000000","9.31476000"],["77675.00000000","0.00000000"],["77670.02000000","0.00200000"],["69909.24000000","0.00432000"],["69909.22000000","0.00000000"],["62141.55000000","0.00032000"]],"a":[["77676.94000000","0.49723000"],["77683.07000000","0.00000000"],["77690.53000000","0.00000000"],["77721.10000000","0.00007000"]]}}
{"type":"depth","received_at_ms":1788407352910,"data":{"e":"depthUpdate","E":1788407353114,"s":"BTCUSDT","U":99603301168,"u":99603301195,"b":[["77676.93000000","9.31804000"],["77676.32000000","0.00000000"],["77670.02000000","0.00000000"],["77666.89000000","0.00200000"],["69909.24000000","0.00448000"],["62141.54000000","0.00000000"]],"a":[["77676.94000000","0.34268000"],["77676.95000000","0.00070000"],["77677.34000000","0.00000000"],["77677.35000000","0.00014000"],["77679.70000000","0.00007000"],["77681.81000000","0.00027000"],["77689.54000000","0.66324000"],["77692.02000000","0.00257000"],["77692.17000000","0.00000000"],["77692.29000000","0.00000000"],["77692.74000000","0.00400000"],["77782.65000000","0.00000000"],["77785.19000000","2.60865000"]]}}
{"type":"depth","received_at_ms":1788407353010,"data":{"e":"depthUpdate","E":1788407353214,"s":"BTCUSDT","U":99603301196,"u":99603301218,"b":[["77676.93000000","9.34765000"],["77488.19000000","0.02017000"],["77459.87000000","0.00000000"],["69909.24000000","0.00464000"],["62141.55000000","0.00000000"]],"a":[["77676.94000000","0.34617000"],["77677.35000000","0.00000000"],["77689.52000000","0.00000000"],["77692.27000000","0.01600000"],["77721.10000000","0.00000000"]]}}
{"type":"depth","received_at_ms":1788407353110,"data":{"e":"depthUpdate","E":1788407353314,"s":"BTCUSDT","U":99603301219,"u":99603301227,"b":[["76511.77000000","0.00030000"],["75561.73000000","0.00010000"],["69909.24000000","0.00432000"],["62142.00000000","0.00000000"]],"a":[["77676.94000000","0.41432000"]]}}
{"type":"depth","received_at_ms":1788407353210,"data":{"e":"depthUpdate","E":1788407353414,"s":"BTCUSDT","U":99603301228,"u":99603301232,"b":[["77670.02000000","0.00200000"],["77666.89000000","0.00000000"],["69909.24000000","0.00464000"]],"a":[["77676.94000000","0.41082000"]]}}
{"type":"depth","received_at_ms":1788407353309,"data":{"e":"depthUpdate","E":1788407353514,"s":"BTCUSDT","U":99603301233,"u":99603301245,"b":[["69909.24000000","0.00448000"],["62141.55000000","0.00032000"]],"a":[["77678.98000000","0.00007000"],["77678.99000000","0.12878000"],["77679.70000000","0.00000000"],["77697.24000000","0.10317000"],["77698.69000000","0.09981000"],["77699.38000000","0.10317000"],["78842.10000000","0.00053000"],["81006.07000000","0.00010000"]]}}
{"type":"depth","received_at_ms":1788407353410,"data":{"e":"depthUpdate","E":1788407353614,"s":"BTCUSDT","U":99603301246,"u":99603301255,"b":[["69909.24000000","0.00432000"],["62141.55000000","0.00000000"]],"a":[["77678.39000000","0.10331000"],["77713.62000000","0.00000000"],["77720.52000000","0.00224000"]]}}
{"type":"depth","received_at_ms":1788407353510,"data":{"e":"depthUpdate","E":1788407353714,"s":"BTCUSDT","U":99603301256,"u":99603301259,"b":[["77662.62000000","0.00007000"],["69909.24000000","0.00448000"]],"a":[["77693.70000000","0.00007000"]]}}
{"type":"depth","received_at_ms":1788407353610,"data":{"e":"depthUpdate","E":1788407353814,"s":"BTCUSDT","U":99603301260,"u":99603301274,"b":[["77676.93000000","9.34748000"],["69909.24000000","0.00448000"],["69909.23000000","0.00009000"],["62142.00000000","0.00000000"]],"a":[["77676.94000000","0.41075000"],["77676.95000000","0.00077000"],["77678.99000000","0.12892000"],["77750.69000000","0.00227000"]]}}
{"type":"depth","received_at_ms":1788407353710,"data":{"e":"depthUpdate","E":1788407353914,"s":"BTCUSDT","U":99603301275,"u":99603301278,"b":[["69909.24000000","0.00464000"]],"a":[["77679.95000000","0.00000000"]]}}
{"type":"depth","received_at_ms":1788407353810,"data":{"e":"depthUpdate","E":1788407354014,"s":"BTCUSDT","U":99603301279,"u":99603301281,"b":[["77676.93000000","9.34657000"],["77676.34000000","0.00090000"],["69909.24000000","0.00448000"],["62141.55000000","0.00032000"]],"a":[]}}
{"type":"depth","received_at_ms":1788407353910,"data":{"e":"depthUpdate","E":1788407354114,"s":"BTCUSDT","U":99603301282,"u":99603301298,"b":[["77670.02000000","0.00000000"],["77667.24000000","0.00000000"],["69909.24000000","0.00464000"],["69909.23000000","0.00000000"],["69909.22000000","0.00009000"],["62142.00000000","0.00200000"],["62141.54000000","0.00000000"]],"a":[["77676.94000000","0.40725000"],["77780.09000000","2.60864000"],["77782.57000000","0.03463000"],["77785.19000000","0.00000000"]]}}
{"type":"depth","received_at_ms":1788407354011,"data":{"e":"depthUpdate","E":1788407354215,"s":"BTCUSDT","U":99603301299,"u":99603301306,"b":[["77676.73000000","0.00257000"],["77670.02000000","0.00000000"],["69909.24000000","0.00448000"],["62142.00000000","0.00000000"],["62141.55000000","0.00000000"]],"a":[]}}
{"type":"depth","received_at_ms":1788407354110,"data":{"e":"depthUpdate","E":1788407354314,"s":"BTCUSDT","U":99603301307,"u":99603301316,"b":[["77676.73000000","0.00000000"],["77676.72000000","0.00257000"],["77670.02000000","0.00200000"],["77667.19000000","0.00000000"],["76511.77000000","0.00030000"],["69909.24000000","0.00464000"],["62142.00000000","0.00000000"]],"a":[]}}
{"type":"depth","received_at_ms":1788407354210,"data":{"e":"depthUpdate","E":1788407354414,"s":"BTCUSDT","U":99603301317,"u":99603301334,"b":[["77676.93000000","9.34756000"],["77676.72000000","0.00000000"],["77676.34000000","0.00000000"],["77675.94000000","0.00257000"],["69909.24000000","0.00448000"],["62142.00000000","0.00000000"]],"a":[["77676.94000000","0.40718000"],["77682.07000000","0.00000000"],["77682.15000000","0.00000000"],["77682.50000000","0.00007000"],["77684.71000000","0.00008000"],["77686.36000000","0.00007000"],["77690.22000000","0.00007000"],["77692.02000000","0.00000000"]]}}
{"type":"depth","received_at_ms":1788407354309,"data":{"e":"depthUpdate","E":1788407354514,"s":"BTCUSDT","U":99603301335,"u":99603301344,"b":[["69909.24000000","0.00464000"],["62141.55000000","0.00032000"]],"a":[["77682.07000000","0.17330000"],["77684.71000000","0.16878000"],["77690.68000000","0.00000000"],["78842.10000000","0.00053000"]]}}
{"type":"depth","received_at_ms":1788407354411,"data":{"e":"depthUpdate","E":1788407354614,"s":"BTCUSDT","U":99603301345,"u":99603301361,"b":[["77676.93000000","9.17091000"],["69909.24000000","0.00448000"],["69909.22000000","0.00000000"],["62142.00000000","0.00000000"],["62141.55000000","0.00000000"]],"a":[["77676.94000000","0.40725000"],["77682.50000000","0.00014000"],["77686.36000000","0.00014000"],["77690.22000000","0.00014000"],["77691.44000000","0.00257000"]]}}
{"type":"depth","received_at_ms":1788407354510,"data":{"e":"depthUpdate","E":1788407354714,"s":"BTCUSDT","U":99603301362,"u":99603301373,"b":[["77670.02000000","0.00200000"],["77667.24000000","0.00000000"],["77663.27000000","0.00000000"],["77662.62000000","0.00007000"],["69909.24000000","0.00464000"]],"a":[["77692.30000000","0.00000000"],["77693.70000000","0.00007000"]]}}
{"type":"depth","received_at_ms":1788407354610,"data":{"e":"depthUpdate","E":1788407354814,"s":"BTCUSDT","U":99603301374,"u":99603301951,"b":[["77678.38000000","12.80785000"],["77678.37000000","0.00014000"],["77677.99000000","0.00000000"],["77677.98000000","0.00000000"],["77677.75000000","0.00007000"],["77677.65000000","2.00933000"],["77677.64000000","0.62313000"],["77677.63000000","0.00000000"],["77677.46000000","0.00000000"],["77676.95000000","0.39982000"],["77676.94000000","4.75153000"],["77676.93000000","0.38276000"],["77676.92000000","0.02045000"],["77676.33000000","0.00000000"],["77675.94000000","0.00000000"],["77675.85000000","0.00000000"],["77675.84000000","0.04080000"],["77675.72000000","0.03276000"],["77675.69000000","0.00000000"],["77675.68000000","0.01698000"],["77675.46000000","0.00000000"],["77674.91000000","0.00000000"],["77674.90000000","0.00000000"],["77674.89000000","0.00000000"],["77674.88000000","1.18740000"],["77674.87000000","0.19451000"],["77674.29000000","0.00027000"],["77673.95000000","0.00007000"],["77672.00000000","0.97299000"],["77670.58000000","0.00000000"],["77670.57000000","0.03863000"],["77670.55000000","0.00000000"],["77670.54000000","0.25138000"],["77670.02000000","0.01800000"],["77669.86000000","0.12530000"],["77669.36000000","0.00007000"],["77667.20000000","0.00007000"],["77666.46000000","0.00000000"],["77665.75000000","0.00000000"],["77663.18000000","0.00000000"],["77663.16000000","0.07056000"],["77662.87000000","0.00000000"],["77661.70000000","0.16661000"],["77660.03000000","0.00000000"],["77659.66000000","0.26046000"],["77659.51000000","0.00000000"],["77657.62000000","1.00620000"],["77655.53000000","0.64412000"],["77634.48000000","2.20427000"],["77631.20000000","4.63458000"],["77630.80000000","0.00000000"],["77630.79000000","0.00000000"],["77623.28000000","0.00008000"],["77623.27000000","0.00000000"],["77609.29000000","0.20068000"],["77609.28000000","0.00000000"],["77539.75000000","1.54310000"],["77522.75000000","0.00000000"],["77507.49000000","1.20000000"],["77498.35000000","0.00000000"],["77497.50000000","0.00000000"],["77450.81000000","0.00000000"],["77344.37000000","1.79103000"],["77310.91000000","0.00000000"],["77258.67000000","0.00000000"],["76511.77000000","0.00000000"],["76123.40000000","0.00000000"],["69909.24000000","0.00000000"]],"a":[["77676.94000000","0.00000000"],["77676.95000000","0.00000000"],["77676.96000000","0.00000000"],["77677.47000000","0.00000000"],["77677.64000000","0.00000000"],["77677.65000000","0.00000000"],["77677.76000000","0.00000000"],["77677.99000000","0.00000000"],["77678.00000000","0.00000000"],["77678.38000000","0.00000000"],["77678.39000000","0.02206000"],["77678.40000000","0.00063000"],["77678.98000000","0.00000000"],["77678.99000000","0.00021000"],["77679.19000000","0.00000000"],["77679.20000000","0.00021000"],["77679.70000000","0.00000000"],["77679.71000000","0.00021000"],["77679.99000000","0.00014000"],["77680.64000000","0.00021000"],["77680.92000000","0.00000000"],["77681.15000000","0.00021000"],["77681.16000000","0.00562000"],["77681.50000000","0.00314000"],["77681.80000000","0.00000000"],["77681.99000000","0.03176000"],["77682.00000000","0.03014000"],["77682.07000000","0.00000000"],["77682.08000000","0.00000000"],["77682.38000000","0.00000000"],["77682.50000000","0.00007000"],["77682.73000000","0.00007000"],["77682.74000000","0.10316000"],["77684.44000000","0.00000000"],["77684.71000000","0.00008000"],["77685.14000000","0.00000000"],["77685.36000000","0.00008000"],["77686.36000000","0.00007000"],["77686.53000000","0.00000000"],["77686.95000000","0.10165000"],["77687.01000000","0.00000000"],["77687.04000000","0.00000000"],["77688.01000000","0.01184000"],["77688.11000000","0.00000000"],["77688.18000000","0.00000000"],["77688.34000000","0.00671000"],["77690.22000000","0.00007000"],["77690.64000000","0.02000000"],["77691.11000000","0.00000000"],["77691.13000000","0.00007000"],["77691.44000000","0.00000000"],["77692.27000000","0.00000000"],["77692.47000000","0.32066000"],["77692.58000000","0.00000000"],["77692.74000000","0.00000000"],["77693.39000000","0.14565000"],["77694.08000000","0.00007000"],["77694.30000000","0.10324000"],["77695.31000000","0.00007000"],["77695.79000000","0.10316000"],["77697.24000000","0.10316000"],["77697.94000000","0.00014000"],["77698.06000000","0.00000000"],["77698.69000000","0.10316000"],["77699.38000000","0.10316000"],["77699.40000000","0.00000000"],["77699.87000000","0.18002000"],["77701.23000000","0.30866000"],["77701.80000000","0.00007000"],["77703.80000000","0.12869000"],["77704.12000000","0.00000000"],["77705.66000000","0.00007000"],["77708.13000000","0.04536000"],["77709.52000000","0.00007000"],["77709.80000000","0.00853000"],["77712.65000000","0.00000000"],["77714.74000000","0.00000000"],["77715.43000000","0.64362000"],["77716.00000000","0.03000000"],["77717.00000000","0.00000000"],["77718.00000000","0.04000000"],["77719.51000000","0.00000000"],["77721.10000000","0.00007000"],["77731.73000000","0.00000000"],["77732.76000000","0.00000000"],["77734.61000000","0.00321000"],["77736.40000000","0.00321000"],["77746.52000000","1.27387000"],["77780.09000000","0.00000000"],["77782.57000000","0.80886000"],["77782.64000000","2.60864000"],["77817.89000000","0.00000000"],["77834.95000000","1.54310000"],["77972.12000000","1.19998000"],["78070.47000000","0.00000000"],["78842.10000000","0.00023000"],["79230.47000000","0.00000000"]]}}
{"type":"depth","received_at_ms":1788407354711,"data":{"e":"depthUpdate","E":1788407354914,"s":"BTCUSDT","U":99603301952,"u":99603302131,"b":[["77678.38000000","12.81545000"],["77677.66000000","0.00414000"],["77677.65000000","0.88799000"],["77677.64000000","0.22352000"],["77677.60000000","0.00008000"],["77676.97000000","0.00000000"],["77676.96000000","0.00000000"],["77676.95000000","0.00028000"],["77676.92000000","0.01028000"],["77676.74000000","0.00400000"],["77675.84000000","0.04066000"],["77675.68000000","0.00000000"],["77674.89000000","0.00014000"],["77674.74000000","0.41269000"],["77674.44000000","0.00000000"],["77673.95000000","0.00000000"],["77673.20000000","0.00000000"],["77670.02000000","0.01600000"],["77668.63000000","0.00000000"],["77666.89000000","0.00200000"],["77663.51000000","0.10450000"],["77661.57000000","0.10703000"],["77660.37000000","0.00666000"],["77658.55000000","0.00000000"],["77657.17000000","0.00007000"],["77656.84000000","0.00000000"],["77639.00000000","0.01000000"],["77638.00000000","0.03000000"],["77629.17000000","0.85194000"],["77619.05000000","0.00000000"],["77617.41000000","0.00000000"],["77268.78000000","0.00072000"],["69910.55000000","0.00016000"],["62143.00000000","0.01609000"]],"a":[["77678.39000000","0.23551000"],["77678.40000000","0.00063000"],["77678.99000000","0.00007000"],["77679.20000000","0.00007000"],["77679.30000000","0.02917000"],["77679.71000000","0.00007000"],["77680.00000000","0.03028000"],["77680.64000000","0.00007000"],["77680.79000000","0.00000000"],["77681.15000000","0.00007000"],["77681.16000000","0.00021000"],["77681.25000000","0.00000000"],["77681.28000000","0.00014000"],["77681.29000000","0.10323000"],["77681.72000000","0.00000000"],["77681.98000000","0.00014000"],["77681.99000000","0.03190000"],["77682.00000000","0.03021000"],["77682.09000000","0.00000000"],["77682.41000000","0.00014000"],["77682.73000000","0.00000000"],["77682.74000000","0.10330000"],["77683.37000000","0.00000000"],["77683.52000000","0.10249000"],["77683.65000000","0.00000000"],["77684.89000000","0.00000000"],["77686.36000000","0.00014000"],["77687.01000000","0.17006000"],["77689.26000000","0.00048000"],["77689.93000000","0.00048000"],["77690.10000000","0.00070000"],["77690.22000000","0.00014000"],["77690.54000000","0.00048000"],["77692.46000000","0.00800000"],["77693.89000000","0.00257000"],["77694.08000000","0.00414000"],["77694.33000000","0.00000000"],["77695.78000000","0.00643000"],["77696.04000000","0.00000000"],["77697.94000000","0.00021000"],["77701.80000000","0.00014000"],["77705.66000000","0.00014000"],["77709.52000000","0.00014000"],["77730.46000000","0.00000000"],["77782.57000000","0.03463000"],["77782.64000000","0.00000000"],["77817.85000000","0.14341000"],["77817.88000000","0.00000000"],["77876.14000000","0.00007000"],["77880.02000000","0.00007000"]]}}
{"type":"depth","received_at_ms":1788407354812,"data":{"e":"depthUpdate","E":1788407355014,"s":"BTCUSDT","U":99603302132,"u":99603302192,"b":[["77678.38000000","12.82555000"],["77677.67000000","0.00097000"],["77677.64000000","0.22352000"],["77677.13000000","0.01684000"],["77676.95000000","0.00021000"],["77676.94000000","4.75160000"],["77676.93000000","0.21307000"],["77676.85000000","0.00400000"],["77676.74000000","0.00000000"],["77675.89000000","0.02021000"],["77674.65000000","0.02021000"],["77665.14000000","0.13910000"],["77664.07000000","0.38477000"],["77661.70000000","0.00000000"],["77652.10000000","0.00000000"],["77650.97000000","0.00200000"],["69910.55000000","0.00032000"],["62143.00000000","0.01609000"],["62142.71000000","0.00032000"]],"a":[["77678.39000000","0.40022000"],["77678.40000000","0.00077000"],["77680.00000000","0.03028000"],["77681.16000000","0.00007000"],["77681.29000000","0.10337000"],["77682.00000000","0.03021000"],["77682.41000000","0.00000000"],["77682.61000000","0.00534000"],["77682.73000000","0.11127000"],["77683.52000000","0.10249000"],["77683.86000000","0.00890000"],["77684.00000000","0.03014000"],["77684.11000000","0.09989000"],["77685.10000000","0.01068000"],["77685.89000000","0.00722000"],["77686.34000000","0.01068000"],["77687.95000000","0.00400000"],["77689.33000000","0.00524000"],["77692.71000000","0.28249000"],["77693.11000000","0.00257000"],["77693.89000000","0.00000000"]]}}
{"type":"depth","received_at_ms":1788407354911,"data":{"e":"depthUpdate","E":1788407355114,"s":"BTCUSDT","U":99603302193,"u":99603302253,"b":[["77678.38000000","12.95838000"],["77678.37000000","0.00042000"],["77677.67000000","0.00000000"],["77677.65000000","2.09119000"],["77677.64000000","0.22352000"],["77677.14000000","0.00097000"],["77677.13000000","0.01698000"],["77676.93000000","0.17238000"],["77675.90000000","0.00538000"],["69910.55000000","0.00064000"],["62142.70000000","0.00022000"]],"a":[["77678.39000000","0.77827000"],["77678.40000000","0.00084000"],["77679.39000000","0.00014000"],["77679.40000000","0.12810000"],["77681.50000000","0.00007000"],["77681.99000000","0.03176000"],["77682.00000000","0.03021000"],["77682.61000000","0.00548000"],["77682.73000000","0.11141000"],["77683.52000000","0.10235000"],["77684.00000000","0.03000000"],["77773.25000000","0.00000000"],["77774.70000000","0.00025000"],["77809.03000000","0.00000000"],["77818.40000000","0.00000000"],["77853.54000000","0.02017000"]]}}
{"type":"depth","received_at_ms":1788407355010,"data":{"e":"depthUpdate","E":1788407355214,"s":"BTCUSDT","U":99603302254,"u":99603302301,"b":[["77678.38000000","12.95853000"],["77678.37000000","0.00014000"],["77675.90000000","0.00552000"],["69910.55000000","0.00073000"],["62142.71000000","0.00000000"]],"a":[["77678.39000000","0.61945000"],["77678.40000000","0.00077000"],["77679.30000000","0.02917000"],["77679.40000000","0.12824000"],["77681.81000000","0.00000000"],["77682.74000000","0.10316000"],["77683.66000000","0.00208000"],["77694.30000000","0.00008000"],["77702.33000000","0.00000000"],["77703.54000000","0.64391000"],["77710.00000000","0.03200000"],["77853.54000000","0.00000000"],["77867.47000000","0.02017000"]]}}
{"type":"depth","received_at_ms":1788407355110,"data":{"e":"depthUpdate","E":1788407355314,"s":"BTCUSDT","U":99603302302,"u":99603302353,"b":[["77678.38000000","12.97000000"],["77677.14000000","0.00000000"],["77676.94000000","4.74517000"],["77676.85000000","0.00000000"],["77672.22000000","0.00800000"],["77672.01000000","0.00735000"],["77670.02000000","0.00800000"],["77666.89000000","0.00000000"],["77663.18000000","0.30841000"],["77659.67000000","0.00000000"],["77656.51000000","0.00200000"],["77650.97000000","0.00000000"],["69910.55000000","0.00105000"],["62143.00000000","0.01609000"]],"a":[["77678.39000000","0.61833000"],["77678.40000000","0.00063000"],["77679.39000000","0.00000000"],["77679.40000000","0.00014000"],["77681.99000000","0.03183000"],["77682.24000000","0.00027000"],["77682.50000000","0.00014000"],["77682.73000000","0.00014000"],["77687.95000000","0.00000000"],["77689.26000000","0.00448000"],["77691.09000000","0.00000000"],["77692.01000000","0.00264000"],["77692.46000000","0.00000000"],["77692.47000000","0.31266000"],["77693.11000000","0.00000000"],["77695.42000000","0.01600000"],["77697.27000000","0.37291000"],["77699.39000000","0.00000000"],["77701.22000000","0.34197000"],["77702.81000000","0.00000000"],["77704.50000000","0.25756000"],["77719.71000000","0.00852000"],["77721.10000000","0.00000000"],["77731.33000000","0.12879000"],["79900.00000000","7.37637000"]]}}
{"type":"depth","received_at_ms":1788407355211,"data":{"e":"depthUpdate","E":1788407355414,"s":"BTCUSDT","U":99603302354,"u":99603302389,"b":[["77656.51000000","0.30200000"],["77656.30000000","0.00000000"],["77552.65000000","0.00000000"],["77513.10000000","0.00671000"],["76977.84000000","0.00000000"],["76513.20000000","0.00030000"],["69910.55000000","0.00137000"],["62143.00000000","0.01609000"]],"a":[["77678.39000000","0.61840000"],["77678.40000000","0.00070000"],["77678.41000000","0.00000000"],["77679.30000000","0.02917000"],["77679.40000000","0.00000000"],["77679.95000000","0.00007000"],["77682.61000000","0.00548000"],["77682.73000000","0.14747000"],["77682.74000000","0.10330000"],["77683.52000000","0.10249000"],["77686.14000000","0.00000000"],["77692.46000000","0.00200000"],["77731.33000000","0.00000000"]]}}
{"type":"depth","received_at_ms":1788407355310,"data":{"e":"depthUpdate","E":1788407355514,"s":"BTCUSDT","U":99603302390,"u":99603302410,"b":[["77571.42000000","0.00276000"],["77563.95000000","0.00000000"],["77000.00000000","7.58015000"],["69910.55000000","0.00153000"],["62142.71000000","0.00032000"]],"a":[["77678.39000000","0.61833000"],["77681.26000000","0.00014000"],["77681.27000000","0.10245000"],["77681.99000000","0.03176000"],["77682.61000000","0.00548000"],["77682.73000000","0.14761000"],["77683.52000000","0.00000000"],["77695.67000000","0.10245000"],["77699.38000000","0.00000000"]]}}
{"type":"depth","received_at_ms":1788407355411,"data":{"e":"depthUpdate","E":1788407355614,"s":"BTCUSDT","U":99603302411,"u":99603302427,"b":[["77513.87000000","0.00000000"],["69910.55000000","0.00169000"],["62142.71000000","0.00000000"]],"a":[["77678.39000000","0.61840000"],["77678.40000000","0.00077000"],["77680.00000000","0.03028000"],["77681.27000000","0.10259000"],["77682.74000000","0.10316000"],["77685.06000000","0.32193000"],["77731.32000000","0.00000000"],["78843.57000000","0.00030000"]]}}
{"type":"depth","received_at_ms":1788407355511,"data":{"e":"depthUpdate","E":1788407355714,"s":"BTCUSDT","U":99603302428,"u":99603302451,"b":[["77678.38000000","12.97008000"],["77662.62000000","0.00000000"],["69910.55000000","0.00169000"]],"a":[["77678.39000000","0.61892000"],["77678.40000000","0.00084000"],["77679.82000000","0.00014000"],["77679.83000000","0.10245000"],["77681.48000000","0.00000000"],["77681.49000000","0.12936000"],["77681.98000000","0.00000000"],["77681.99000000","0.25560000"],["77682.73000000","0.00014000"],["77693.70000000","0.00000000"],["77780.09000000","0.00000000"]]}}
{"type":"depth","received_at_ms":1788407355610,"data":{"e":"depthUpdate","E":1788407355814,"s":"BTCUSDT","U":99603302452,"u":99603302486,"b":[["77676.93000000","0.17247000"],["77672.01000000","0.00535000"],["77670.55000000","0.00200000"],["77664.07000000","0.38484000"],["71462.78000000","0.00014000"],["69910.55000000","0.00185000"]],"a":[["77678.39000000","0.62201000"],["77679.30000000","0.02917000"],["77679.83000000","0.10259000"],["77681.29000000","0.10337000"],["77681.49000000","0.12950000"],["77682.61000000","0.00534000"],["77682.73000000","0.00000000"],["77692.46000000","0.01800000"],["77695.15000000","0.00007000"],["77695.42000000","0.00000000"],["77801.21000000","0.00000000"]]}}
{"type":"depth","received_at_ms":1788407355710,"data":{"e":"depthUpdate","E":1788407355914,"s":"BTCUSDT","U":99603302487,"u":99603302496,"b":[["77677.30000000","0.00257000"]],"a":[["77692.46000000","0.00200000"],["77695.30000000","0.01600000"],["77710.00000000","0.73200000"]]}}
{"type":"depth","received_at_ms":1788407355810,"data":{"e":"depthUpdate","E":1788407356014,"s":"BTCUSDT","U":99603302497,"u":99603302687,"b":[["77678.38000000","12.52630000"],["77678.25000000","0.00400000"],["77677.76000000","0.00000000"],["77677.67000000","0.00014000"],["77677.66000000","0.01614000"],["77677.64000000","0.22359000"],["77677.30000000","0.00000000"],["77676.94000000","4.74309000"],["77676.93000000","0.13879000"],["77675.90000000","0.00559000"],["77674.89000000","0.00007000"],["77672.22000000","0.00000000"],["77670.53000000","0.13925000"],["77670.02000000","0.00000000"],["77664.08000000","0.25755000"],["77659.66000000","0.00290000"],["77654.49000000","0.00000000"],["77647.24000000","0.04558000"],["77647.05000000","0.00000000"],["77620.81000000","0.00000000"],["77593.79000000","0.00000000"],["69910.55000000","0.00192000"],["69910.54000000","0.00009000"],["62142.71000000","0.00032000"]],"a":[["77678.39000000","0.63205000"],["77678.40000000","0.00063000"],["77679.82000000","0.00000000"],["77679.83000000","0.00014000"],["77681.25000000","0.00014000"],["77681.26000000","0.09852000"],["77681.27000000","0.00014000"],["77681.28000000","0.00000000"],["77681.29000000","0.00021000"],["77681.48000000","0.00000000"],["77681.49000000","0.00014000"],["77681.98000000","0.00014000"],["77681.99000000","0.03183000"],["77682.00000000","0.03014000"],["77682.24000000","0.00000000"],["77682.50000000","0.00007000"],["77682.70000000","0.20492000"],["77682.71000000","0.10245000"],["77682.74000000","0.00000000"],["77683.62000000","0.00309000"],["77683.66000000","0.00000000"],["77684.10000000","0.10245000"],["77684.11000000","0.00000000"],["77685.21000000","0.00000000"],["77686.43000000","0.00000000"],["77686.44000000","0.00208000"],["77687.33000000","0.03000000"],["77688.34000000","0.00000000"],["77688.39000000","0.00645000"],["77688.98000000","0.00000000"],["77689.26000000","0.00048000"],["77689.33000000","0.00000000"],["77689.54000000","0.20881000"],["77690.08000000","0.00000000"],["77691.09000000","0.10245000"],["77691.10000000","0.00000000"],["77692.01000000","0.00007000"],["77692.46000000","0.30866000"],["77692.47000000","0.00400000"],["77692.59000000","0.00000000"],["77692.71000000","0.00000000"],["77693.39000000","0.13867000"],["77693.71000000","0.00000000"],["77693.97000000","0.00257000"],["77694.08000000","0.00014000"],["77694.23000000","0.10245000"],["77695.02000000","0.00000000"],["77695.30000000","0.00000000"],["77695.67000000","0.10245000"],["77695.76000000","0.00400000"],["77695.78000000","0.00000000"],["77695.79000000","0.00000000"],["77695.99000000","0.00200000"],["77696.89000000","0.00800000"],["77696.90000000","0.07214000"],["77697.11000000","0.10245000"],["77697.24000000","0.00000000"],["77697.52000000","0.00643000"],["77698.55000000","0.10245000"],["77698.69000000","0.00000000"],["77699.46000000","0.10245000"],["77701.21000000","0.10245000"],["77701.22000000","0.00000000"],["77701.49000000","0.09212000"],["77702.48000000","0.00000000"],["77703.54000000","0.31621000"],["77704.00000000","0.03007000"],["77704.50000000","0.00000000"],["77706.47000000","0.64390000"],["77707.49000000","0.25756000"],["77708.13000000","0.00000000"],["77710.00000000","0.03200000"],["77711.13000000","0.00000000"],["77712.00000000","0.03265000"],["77713.36000000","0.00000000"],["77715.05000000","0.04636000"],["77715.30000000","0.00400000"],["77717.25000000","0.00000000"],["77717.34000000","0.00000000"],["77717.55000000","0.00000000"],["77717.95000000","0.00000000"],["77718.57000000","0.00000000"],["77719.71000000","0.00000000"],["77721.10000000","0.00007000"],["77721.66000000","0.00000000"],["77730.55000000","0.00000000"],["77776.98000000","0.00000000"]]}}
{"type":"depth","received_at_ms":1788407355912,"data":{"e":"depthUpdate","E":1788407356115,"s":"BTCUSDT","U":99603302688,"u":99603302747,"b":[["77678.38000000","12.52630000"],["77678.26000000","0.00400000"],["77677.67000000","0.00014000"],["77677.60000000","0.00000000"],["77672.01000000","0.00735000"],["77670.55000000","0.00000000"],["77632.16000000","0.00621000"],["77631.16000000","0.01144000"],["77610.92000000","0.00000000"],["77609.50000000","0.00110000"],["69910.55000000","0.00192000"]],"a":[["77678.39000000","0.65297000"],["77679.30000000","0.02917000"],["77679.83000000","0.00000000"],["77680.00000000","0.03028000"],["77681.26000000","0.09866000"],["77681.27000000","0.00000000"],["77681.29000000","0.00007000"],["77681.49000000","0.00000000"],["77682.20000000","0.00027000"],["77682.61000000","0.00548000"],["77682.70000000","0.00014000"],["77682.71000000","0.10259000"],["77690.82000000","0.00400000"],["77694.25000000","0.00400000"],["77695.76000000","0.00000000"],["77696.89000000","0.01600000"],["77727.02000000","0.00433000"],["77727.09000000","0.32964000"],["77727.16000000","0.00431000"],["77728.19000000","0.76563000"],["77737.98000000","0.03863000"],["77840.11000000","0.00000000"]]}}
{"type":"depth","received_at_ms":1788407356010,"data":{"e":"depthUpdate","E":1788407356214,"s":"BTCUSDT","U":99603302748,"u":99603302781,"b":[["77678.38000000","12.55829000"],["77580.61000000","0.04565000"],["77559.85000000","0.00000000"],["69910.55000000","0.00208000"],["62142.71000000","0.00000000"],["62142.70000000","0.00022000"]],"a":[["77678.39000000","0.65293000"],["77678.40000000","0.00063000"],["77682.61000000","0.00548000"],["77682.70000000","0.00000000"],["77683.86000000","0.00904000"],["77689.49000000","0.00400000"],["77690.82000000","0.00000000"],["77707.17000000","0.50721000"],["77731.39000000","0.00000000"],["77732.32000000","0.12878000"]]}}
{"type":"depth","received_at_ms":1788407356110,"data":{"e":"depthUpdate","E":1788407356314,"s":"BTCUSDT","U":99603302782,"u":99603302816,"b":[["77677.67000000","0.01800000"],["77677.66000000","0.00014000"],["77674.89000000","0.00014000"],["77672.22000000","0.00000000"],["77672.01000000","0.00535000"],["69910.55000000","0.00208000"],["62143.00000000","0.01609000"]],"a":[["77678.39000000","0.65307000"],["77682.78000000","0.14636000"],["77684.72000000","0.09989000"],["77686.44000000","0.00000000"],["77731.85000000","0.00000000"],["77732.12000000","0.12878000"],["77732.32000000","0.00000000"]]}}
{"type":"depth","received_at_ms":1788407356210,"data":{"e":"depthUpdate","E":1788407356414,"s":"BTCUSDT","U":99603302817,"u":99603302875,"b":[["77678.38000000","12.55829000"],["77677.68000000","0.00000000"],["77677.67000000","0.00000000"],["77672.22000000","0.01600000"],["77671.15000000","0.00200000"],["77666.93000000","0.02200000"],["77666.89000000","0.02000000"],["77664.08000000","0.00000000"],["77662.41000000","0.25756000"],["77656.00000000","0.00772000"],["77503.63000000","0.00000000"],["76979.27000000","0.00010000"],["76513.20000000","0.00030000"],["71462.78000000","0.00000000"],["69910.55000000","0.00224000"],["69910.54000000","0.00000000"],["62143.00000000","0.01609000"]],"a":[["77678.39000000","0.65282000"],["77678.40000000","0.00070000"],["77681.93000000","0.00014000"],["77681.94000000","0.13914000"],["77681.99000000","0.03176000"],["77682.71000000","0.10259000"],["77682.78000000","0.00014000"],["77683.86000000","0.00890000"],["77685.54000000","0.00208000"],["77693.89000000","0.00257000"],["77693.97000000","0.00000000"],["77732.12000000","0.00000000"],["77732.39000000","0.00000000"],["77732.42000000","0.00000000"],["77779.85000000","0.00000000"],["77794.96000000","0.01568000"],["77856.14000000","0.00000000"]]}}
{"type":"depth","received_at_ms":1788407356311,"data":{"e":"depthUpdate","E":1788407356514,"s":"BTCUSDT","U":99603302876,"u":99603302931,"b":[["77678.38000000","12.55843000"],["77678.37000000","0.00028000"],["77677.66000000","0.00014000"],["77672.22000000","0.00000000"],["77672.01000000","0.02135000"],["77670.81000000","0.02400000"],["77668.47000000","0.02000000"],["77666.93000000","0.04200000"],["77662.73000000","0.00000000"],["77658.84000000","0.02000000"],["69910.55000000","0.00208000"],["62142.71000000","0.00032000"]],"a":[["77678.39000000","0.65292000"],["77678.41000000","0.00007000"],["77681.26000000","0.09866000"],["77681.94000000","0.13928000"],["77682.71000000","0.10259000"],["77682.78000000","0.00000000"],["77689.33000000","0.00516000"],["77693.86000000","0.00257000"],["77693.88000000","0.00000000"],["77693.89000000","0.00000000"],["77694.07000000","0.00200000"],["77695.99000000","0.00000000"],["77721.69000000","0.00843000"],["77727.87000000","0.56147000"],["77731.74000000","0.03210000"]]}}
{"type":"depth","received_at_ms":1788407356411,"data":{"e":"depthUpdate","E":1788407356614,"s":"BTCUSDT","U":99603302932,"u":99603302973,"b":[["77678.38000000","12.55443000"],["77678.37000000","0.00028000"],["77677.89000000","0.00400000"],["77660.39000000","0.00000000"],["77658.85000000","0.00000000"],["77658.84000000","0.00000000"],["77621.47000000","0.00000000"],["77503.64000000","4.37133000"],["69910.55000000","0.00240000"],["62142.71000000","0.00000000"]],"a":[["77678.39000000","0.83289000"],["77678.40000000","0.00063000"],["77681.07000000","0.00014000"],["77681.08000000","0.14321000"],["77681.50000000","0.00000000"],["77681.93000000","0.00000000"],["77681.94000000","0.00014000"],["77682.75000000","0.20415000"],["77697.27000000","0.70627000"],["77698.46000000","1.27148000"],["77701.49000000","0.00000000"],["77710.00000000","0.73200000"],["77860.74000000","4.37845000"],["78843.57000000","0.00030000"]]}}
{"type":"depth","received_at_ms":1788407356512,"data":{"e":"depthUpdate","E":1788407356714,"s":"BTCUSDT","U":99603302974,"u":99603303037,"b":[["77678.38000000","12.55443000"],["77678.37000000","0.00028000"],["77677.66000000","0.01814000"],["77672.01000000","0.00535000"],["77671.15000000","0.00000000"],["77629.18000000","0.60081000"],["69910.55000000","0.00240000"]],"a":[["77678.39000000","0.83289000"],["77678.40000000","0.00070000"],["77680.00000000","0.03028000"],["77681.08000000","0.14335000"],["77681.26000000","0.09866000"],["77681.94000000","0.00000000"],["77682.71000000","0.10259000"],["77682.75000000","0.20415000"],["77694.07000000","0.00000000"],["77695.79000000","0.00200000"],["77701.21000000","0.00000000"],["77732.54000000","0.00000000"],["77794.95000000","0.01379000"]]}}
{"type":"depth","received_at_ms":1788407356610,"data":{"e":"depthUpdate","E":1788407356814,"s":"BTCUSDT","U":99603303038,"u":99603303049,"b":[["77678.38000000","12.55443000"],["77664.07000000","0.38484000"],["69910.55000000","0.00240000"],["62143.00000000","0.01609000"]],"a":[["77678.39000000","0.83296000"],["77695.15000000","0.00007000"]]}}
{"type":"depth","received_at_ms":1788407356710,"data":{"e":"depthUpdate","E":1788407356914,"s":"BTCUSDT","U":99603303050,"u":99603303074,"b":[["77678.38000000","12.55313000"],["77677.66000000","0.00014000"],["77677.64000000","0.22230000"],["77672.22000000","0.01600000"],["77670.82000000","0.00200000"],["69910.55000000","0.00272000"],["69910.54000000","0.00009000"]],"a":[["77678.39000000","0.96132000"],["77683.62000000","0.00000000"]]}}
{"type":"depth","received_at_ms":1788407356810,"data":{"e":"depthUpdate","E":1788407357014,"s":"BTCUSDT","U":99603303075,"u":99603303091,"b":[["77678.38000000","12.55313000"],["77678.37000000","0.00028000"],["77664.07000000","0.00007000"],["77639.36000000","0.04200000"],["69910.55000000","0.00272000"],["62142.71000000","0.00032000"]],"a":[["77687.38000000","0.12872000"],["77715.13000000","0.09760000"],["77732.63000000","0.00000000"]]}}
{"type":"depth","received_at_ms":1788407356910,"data":{"e":"depthUpdate","E":1788407357114,"s":"BTCUSDT","U":99603303092,"u":99603303120,"b":[["77678.38000000","12.55299000"],["77678.37000000","0.00014000"],["77677.66000000","0.01814000"],["77672.22000000","0.00000000"],["77670.82000000","0.00000000"],["77667.70000000","0.02000000"],["69910.55000000","0.00288000"],["62142.00000000","0.00200000"]],"a":[["77678.39000000","0.83590000"],["77678.41000000","0.00000000"],["77698.55000000","0.00000000"],["77785.19000000","2.60864000"]]}}
{"type":"depth","received_at_ms":1788407357011,"data":{"e":"depthUpdate","E":1788407357214,"s":"BTCUSDT","U":99603303121,"u":99603303155,"b":[["77678.38000000","12.55299000"],["77677.67000000","0.01800000"],["77677.66000000","0.00014000"],["77672.01000000","0.00535000"],["77671.12000000","0.00000000"],["77667.28000000","0.02000000"],["77659.65000000","0.00000000"],["77659.23000000","0.00000000"],["62142.71000000","0.00000000"],["62142.70000000","0.00022000"],["62142.00000000","0.00000000"]],"a":[["77678.39000000","0.87720000"]]}}
{"type":"depth","received_at_ms":1788407357109,"data":{"e":"depthUpdate","E":1788407357314,"s":"BTCUSDT","U":99603303156,"u":99603303175,"b":[["77678.38000000","12.55299000"],["77665.38000000","0.18352000"],["77488.19000000","0.00000000"],["77461.86000000","0.02016000"],["69910.55000000","0.00304000"],["62143.00000000","0.01609000"]],"a":[["77678.39000000","0.87745000"],["77693.39000000","0.23644000"],["77693.48000000","0.34536000"],["77733.08000000","0.00000000"]]}}
{"type":"depth","received_at_ms":1788407357210,"data":{"e":"depthUpdate","E":1788407357414,"s":"BTCUSDT","U":99603303176,"u":99603303191,"b":[["77678.38000000","12.52081000"],["77554.09000000","0.00086000"],["76513.20000000","0.00030000"],["69910.55000000","0.00304000"]],"a":[["77678.39000000","0.69776000"],["77682.75000000","0.00000000"],["77688.39000000","0.00000000"],["77689.33000000","0.00000000"],["77689.49000000","0.00000000"],["77690.01000000","0.00400000"],["77694.25000000","0.00000000"],["77694.78000000","0.00400000"],["77699.46000000","0.00000000"]]}}
{"type":"depth","received_at_ms":1788407357309,"data":{"e":"depthUpdate","E":1788407357514,"s":"BTCUSDT","U":99603303192,"u":99603303211,"b":[["77677.67000000","0.01600000"],["77677.66000000","0.00214000"],["77654.53000000","0.09531000"],["77621.47000000","0.02000000"],["69910.55000000","0.00320000"],["69910.54000000","0.00000000"],["69910.53000000","0.00009000"],["62142.71000000","0.00032000"]],"a":[["77678.39000000","0.97950000"],["77679.90000000","0.15049000"],["77681.08000000","0.00014000"],["77682.71000000","0.10259000"],["77688.43000000","0.00647000"]]}}
{"type":"depth","received_at_ms":1788407357411,"data":{"e":"depthUpdate","E":1788407357614,"s":"BTCUSDT","U":99603303212,"u":99603303287,"b":[["77678.38000000","12.55376000"],["77678.37000000","0.00063000"],["77677.68000000","0.00000000"],["77677.67000000","0.00000000"],["77677.66000000","0.00014000"],["77672.22000000","0.01600000"],["77672.01000000","0.00542000"],["77670.93000000","0.00200000"],["77656.00000000","0.01772000"],["76497.17000000","0.00007000"],["69910.55000000","0.00320000"],["62143.00000000","0.01609000"],["62142.71000000","0.00000000"]],"a":[["77678.39000000","0.97950000"],["77678.40000000","0.00070000"],["77679.30000000","0.02917000"],["77679.89000000","0.00014000"],["77679.90000000","0.15063000"],["77679.95000000","0.00000000"],["77680.00000000","0.03028000"],["77681.07000000","0.00000000"],["77681.08000000","0.00000000"],["77681.98000000","0.00007000"],["77688.65000000","0.00400000"],["77690.01000000","0.00000000"],["77693.25000000","0.00400000"],["77694.78000000","0.00000000"],["77697.26000000","0.10245000"],["78843.57000000","0.00030000"]]}}
{"type":"depth","received_at_ms":1788407357511,"data":{"e":"depthUpdate","E":1788407357714,"s":"BTCUSDT","U":99603303288,"u":99603303311,"b":[["77678.38000000","12.55369000"],["77678.37000000","0.00063000"],["77655.59000000","0.00000000"],["77623.19000000","0.51075000"],["77515.31000000","0.00086000"],["69910.55000000","0.00336000"]],"a":[["77678.39000000","0.98086000"],["77681.50000000","0.00007000"],["77682.70000000","0.23385000"],["77686.14000000","0.00007000"],["77693.38000000","0.00200000"],["77695.79000000","0.00000000"],["77731.55000000","0.00000000"],["77782.57000000","0.80886000"]]}}
{"type":"depth","received_at_ms":1788407357610,"data":{"e":"depthUpdate","E":1788407357814,"s":"BTCUSDT","U":99603303312,"u":99603303344,"b":[["77678.38000000","12.55112000"],["77668.67000000","0.00321000"],["77665.29000000","0.14160000"],["77664.07000000","0.00007000"],["77662.82000000","0.00000000"],["77656.00000000","0.02272000"]],"a":[["77678.39000000","0.98086000"],["77678.40000000","0.00070000"],["77678.72000000","0.00014000"],["77678.73000000","0.11910000"],["77679.89000000","0.00000000"],["77679.90000000","0.00014000"],["77682.50000000","0.00014000"],["77682.61000000","0.00548000"],["77682.70000000","0.23399000"],["77682.71000000","0.10245000"],["77692.72000000","0.00257000"],["77693.86000000","0.00000000"],["77695.15000000","0.00007000"],["77719.90000000","0.00000000"],["77721.10000000","0.00000000"],["77731.66000000","0.00000000"]]}}
{"type":"depth","received_at_ms":1788407357709,"data":{"e":"depthUpdate","E":1788407357914,"s":"BTCUSDT","U":99603303345,"u":99603303359,"b":[["77289.98000000","0.00007000"],["69910.55000000","0.00352000"],["62143.00000000","0.01609000"]],"a":[["77678.39000000","0.98100000"],["77678.73000000","0.11924000"],["77679.30000000","0.02903000"],["77679.90000000","0.00000000"],["77802.67000000","0.00093000"]]}}
{"type":"depth","received_at_ms":1788407357810,"data":{"e":"depthUpdate","E":1788407358014,"s":"BTCUSDT","U":99603303360,"u":99603303374,"b":[["77678.38000000","12.55084000"],["77678.37000000","0.00049000"],["77656.00000000","0.03272000"],["69910.55000000","0.00352000"],["62143.00000000","0.01809000"],["62142.71000000","0.00032000"]],"a":[["77678.39000000","0.97169000"],["77731.94000000","0.00000000"]]}}
{"type":"depth","received_at_ms":1788407357910,"data":{"e":"depthUpdate","E":1788407358114,"s":"BTCUSDT","U":99603303375,"u":99603303379,"b":[["69910.55000000","0.00368000"],["62143.00000000","0.01609000"]],"a":[["77732.35000000","0.00000000"],["77732.58000000","0.12878000"]]}}
{"type":"depth","received_at_ms":1788407358010,"data":{"e":"depthUpdate","E":1788407358214,"s":"BTCUSDT","U":99603303380,"u":99603303391,"b":[["69910.55000000","0.00368000"],["62142.71000000","0.00000000"],["62142.70000000","0.00022000"]],"a":[["77679.95000000","0.00007000"],["77686.14000000","0.00000000"],["77715.13000000","0.00000000"],["77732.58000000","0.00000000"],["77841.57000000","0.00093000"]]}}
{"type":"depth","received_at_ms":1788407358111,"data":{"e":"depthUpdate","E":1788407358314,"s":"BTCUSDT","U":99603303392,"u":99603303412,"b":[["77654.53000000","0.00000000"],["77654.03000000","0.09840000"],["75561.73000000","0.00000000"],["69910.55000000","0.00384000"],["69910.53000000","0.00000000"],["62143.00000000","0.01609000"]],"a":[["77678.39000000","0.97040000"],["77685.54000000","0.00000000"],["77688.93000000","0.00527000"],["77691.79000000","0.00257000"],["77692.72000000","0.00000000"],["77693.38000000","0.00000000"],["77694.35000000","0.00200000"],["77715.13000000","0.00000000"],["77731.96000000","0.00000000"],["81006.07000000","0.00000000"]]}}
{"type":"depth","received_at_ms":1788407358210,"data":{"e":"depthUpdate","E":1788407358414,"s":"BTCUSDT","U":99603303413,"u":99603303416,"b":[["76513.20000000","0.00030000"],["69910.55000000","0.00384000"]],"a":[]}}
{"type":"depth","received_at_ms":1788407358310,"data":{"e":"depthUpdate","E":1788407358514,"s":"BTCUSDT","U":99603303417,"u":99603303420,"b":[["69910.55000000","0.00400000"],["62142.71000000","0.00032000"]],"a":[["77732.51000000","0.00000000"]]}}
{"type":"depth","received_at_ms":1788407358410,"data":{"e":"depthUpdate","E":1788407358614,"s":"BTCUSDT","U":99603303421,"u":99603303427,"b":[["69910.55000000","0.00416000"],["62143.00000000","0.01809000"],["62142.71000000","0.00000000"]],"a":[["78843.57000000","0.00030000"]]}}
{"type":"depth","received_at_ms":1788407358510,"data":{"e":"depthUpdate","E":1788407358714,"s":"BTCUSDT","U":99603303428,"u":99603303462,"b":[["77678.38000000","12.55042000"],["77678.37000000","0.00014000"],["77677.66000000","0.01814000"],["77672.22000000","0.00000000"],["77670.93000000","0.00000000"],["77619.05000000","0.58670000"],["69910.55000000","0.00400000"],["62143.00000000","0.01609000"]],"a":[["77678.39000000","0.84269000"],["77679.30000000","0.03543000"],["77688.65000000","0.00000000"],["77689.27000000","0.00400000"],["77693.25000000","0.00000000"],["77694.06000000","0.00400000"]]}}
{"type":"depth","received_at_ms":1788407358611,"data":{"e":"depthUpdate","E":1788407358814,"s":"BTCUSDT","U":99603303463,"u":99603303485,"b":[["77678.38000000","12.55028000"],["77677.67000000","0.00000000"],["77677.66000000","0.00014000"],["77672.22000000","0.01600000"],["77672.01000000","0.00535000"],["77664.07000000","0.00000000"],["77547.76000000","0.01571000"],["77512.78000000","0.00515000"],["69910.55000000","0.00432000"]],"a":[["77679.30000000","0.03557000"],["77695.15000000","0.00000000"],["78888.00000000","2.21229000"],["78899.00000000","0.28487000"]]}}
{"type":"depth","received_at_ms":1788407358711,"data":{"e":"depthUpdate","E":1788407358914,"s":"BTCUSDT","U":99603303486,"u":99603303500,"b":[["77678.38000000","12.55020000"],["77677.07000000","0.00257000"],["77674.74000000","0.41276000"],["77672.01000000","0.00542000"],["77670.93000000","0.00200000"],["77670.53000000","0.13918000"],["77664.07000000","0.00007000"],["77601.61000000","0.72112000"],["77599.06000000","0.00000000"],["77289.98000000","0.00000000"],["69910.55000000","0.00432000"]],"a":[["77695.15000000","0.00007000"]]}}
{"type":"depth","received_at_ms":1788407358809,"data":{"e":"depthUpdate","E":1788407359014,"s":"BTCUSDT","U":99603303501,"u":99603303504,"b":[["69910.55000000","0.00448000"],["62142.71000000","0.00032000"]],"a":[]}}
{"type":"depth","received_at_ms":1788407358910,"data":{"e":"depthUpdate","E":1788407359114,"s":"BTCUSDT","U":99603303505,"u":99603303508,"b":[["77678.38000000","12.55028000"],["69910.55000000","0.00432000"]],"a":[["77678.39000000","0.97342000"]]}}
{"type":"depth","received_at_ms":1788407359010,"data":{"e":"depthUpdate","E":1788407359214,"s":"BTCUSDT","U":99603303509,"u":99603303556,"b":[["77677.67000000","0.00007000"],["77677.66000000","0.01814000"],["77672.22000000","0.00000000"],["77672.01000000","0.00535000"],["77670.93000000","0.00000000"],["77607.89000000","0.00321000"],["77604.36000000","0.00000000"],["77604.01000000","0.00321000"],["77600.37000000","0.00000000"],["77530.01000000","0.00128000"],["77526.01000000","0.00128000"],["77521.67000000","0.00000000"],["77517.58000000","0.00000000"],["69910.55000000","0.00448000"],["62142.71000000","0.00000000"],["62142.70000000","0.00022000"]],"a":[["77678.39000000","0.84240000"],["77678.40000000","0.00063000"],["77678.72000000","0.00000000"],["77678.73000000","0.00014000"],["77679.30000000","0.02917000"],["77679.71000000","0.00615000"],["77681.98000000","0.00014000"],["77681.99000000","0.03183000"],["77682.70000000","0.00014000"],["77688.93000000","0.00000000"],["77689.27000000","0.00000000"],["77689.92000000","0.00400000"],["77694.06000000","0.00000000"],["77694.35000000","0.00000000"],["77695.07000000","0.00400000"],["77695.99000000","0.00200000"],["77696.58000000","0.00643000"],["77697.52000000","0.00000000"],["77698.91000000","0.10487000"],["77700.85000000","0.10698000"],["77809.02000000","0.00000000"],["77811.34000000","0.00000000"],["77813.09000000","0.00128000"],["77815.19000000","0.00128000"]]}}
{"type":"depth","received_at_ms":1788407359110,"data":{"e":"depthUpdate","E":1788407359314,"s":"BTCUSDT","U":99603303557,"u":99603303599,"b":[["77678.38000000","12.54385000"],["77678.27000000","0.00000000"],["77677.90000000","0.00643000"],["77677.67000000","0.00000000"],["77677.66000000","0.00014000"],["77672.22000000","0.01600000"],["77672.01000000","0.00735000"],["77638.49000000","0.00000000"],["75561.55000000","0.00019000"],["69910.55000000","0.00441000"],["62143.00000000","0.01609000"]],"a":[["77678.39000000","0.84222000"],["77678.40000000","0.00070000"],["77678.73000000","0.00000000"],["77679.30000000","0.02917000"],["77679.71000000","0.00629000"],["77682.61000000","0.00548000"],["77682.70000000","0.00000000"],["77682.71000000","0.10259000"],["77695.66000000","0.00643000"],["77696.58000000","0.00000000"]]}}
{"type":"depth","received_at_ms":1788407359209,"data":{"e":"depthUpdate","E":1788407359414,"s":"BTCUSDT","U":99603303600,"u":99603303629,"b":[["77678.38000000","12.54406000"],["77678.37000000","0.00028000"],["77674.65000000","0.02028000"],["77672.01000000","0.00542000"],["77670.82000000","0.00200000"],["77670.53000000","0.13911000"],["77670.47000000","0.00000000"],["77642.30000000","0.02474000"],["76513.20000000","0.00030000"],["69910.55000000","0.00457000"]],"a":[["77678.39000000","0.98158000"],["77682.70000000","0.23385000"],["77688.45000000","0.00400000"],["77689.92000000","0.00000000"],["77693.38000000","0.00200000"],["77693.46000000","0.00400000"],["77695.07000000","0.00000000"],["77695.99000000","0.00000000"],["77732.46000000","0.00000000"],["77732.48000000","0.00000000"]]}}
{"type":"depth","received_at_ms":1788407359310,"data":{"e":"depthUpdate","E":1788407359514,"s":"BTCUSDT","U":99603303630,"u":99603303654,"b":[["77678.38000000","12.54441000"],["77678.37000000","0.00056000"],["69910.55000000","0.00441000"],["62142.71000000","0.00032000"]],"a":[["77679.71000000","0.00021000"],["77682.61000000","0.00548000"],["77682.70000000","0.23399000"],["77682.71000000","0.10245000"],["77693.38000000","0.00000000"],["77694.22000000","0.00200000"],["81006.26000000","0.00010000"]]}}
{"type":"depth","received_at_ms":1788407359410,"data":{"e":"depthUpdate","E":1788407359614,"s":"BTCUSDT","U":99603303655,"u":99603303695,"b":[["77678.38000000","12.54234000"],["77678.37000000","0.00063000"],["77677.91000000","0.00097000"],["77677.89000000","0.00000000"],["77677.18000000","0.00400000"],["77656.51000000","0.30000000"],["77655.17000000","0.00200000"],["77611.24000000","0.00000000"],["77532.96000000","0.00000000"],["69910.55000000","0.00441000"],["62142.71000000","0.00000000"]],"a":[["77678.39000000","1.31858000"],["77678.40000000","0.00070000"],["77679.30000000","0.02917000"],["77679.71000000","0.00007000"],["77682.71000000","0.10259000"],["77694.35000000","0.00643000"],["77695.66000000","0.00000000"],["77699.86000000","0.27233000"],["77703.54000000","0.00000000"],["78843.57000000","0.00030000"]]}}
