{"type":"depth","received_at_ms":1788331842285,"data":{"e":"depthUpdate","E":1788331842414,"s":"BTCUSDT","U":99555814344,"u":99555814719,"b":[["77581.14000000","1.65939000"],["77581.13000000","0.00132000"],["77580.62000000","0.00014000"],["77580.61000000","0.08219000"],["77579.98000000","0.00327000"],["77579.68000000","0.19957000"],["77579.67000000","0.00098000"],["77579.54000000","0.00335000"],["77578.60000000","0.00014000"],["77578.01000000","0.00014000"],["77577.80000000","0.01322000"],["77577.54000000","0.00000000"],["77577.20000000","0.00014000"],["77576.75000000","0.34778000"],["77576.62000000","0.00329000"],["77576.05000000","0.00000000"],["77576.00000000","0.03007000"],["77575.40000000","0.00099000"],["77575.29000000","0.00000000"],["77574.91000000","0.02000000"],["77574.67000000","0.00116000"],["77574.19000000","0.00000000"],["77574.18000000","0.00000000"],["77574.13000000","0.03210000"],["77574.01000000","0.00644000"],["77573.69000000","0.00000000"],["77572.94000000","0.01200000"],["77572.84000000","0.00400000"],["77572.63000000","0.00000000"],["77572.34000000","0.00257000"],["77572.19000000","0.00000000"],["77571.92000000","0.00407000"],["77571.63000000","0.00000000"],["77570.73000000","0.00000000"],["77570.07000000","0.00000000"],["77570.02000000","0.00027000"],["77570.01000000","0.00000000"],["77569.81000000","0.00000000"],["77569.40000000","0.00644000"],["77567.94000000","0.00000000"],["77567.36000000","0.00000000"],["77566.87000000","0.00000000"],["77566.05000000","0.00000000"],["77565.80000000","0.00000000"],["77565.64000000","0.00200000"],["77565.03000000","0.00000000"],["77563.50000000","0.00000000"],["77550.85000000","0.64503000"],["77550.03000000","0.00200000"],["77546.69000000","0.00000000"],["77541.80000000","0.00000000"],["77540.20000000","0.02511000"],["77539.20000000","0.00000000"],["77522.10000000","0.00000000"],["77522.09000000","0.00000000"],["69823.03000000","0.00432000"],["62065.00000000","0.00000000"]],"a":[["77581.15000000","3.77140000"],["77581.16000000","0.00069000"],["77581.18000000","0.03139000"],["77581.19000000","0.00021000"],["77581.20000000","0.00014000"],["77581.21000000","0.00021000"],["77581.29000000","0.32266000"],["77581.30000000","0.04822000"],["77582.13000000","0.00021000"],["77582.27000000","0.00000000"],["77582.45000000","0.00000000"],["77582.51000000","0.00000000"],["77582.53000000","0.00000000"],["77582.62000000","0.00000000"],["77582.63000000","0.00400000"],["77582.67000000","0.00000000"],["77582.77000000","0.00000000"],["77582.81000000","0.00000000"],["77582.86000000","0.00000000"],["77582.87000000","0.00000000"],["77583.01000000","0.00000000"],["77583.09000000","0.00000000"],["77583.20000000","0.00000000"],["77583.21000000","0.00000000"],["77583.22000000","0.00000000"],["77583.26000000","0.00000000"],["77583.28000000","0.00000000"],["77583.50000000","0.00644000"],["77583.51000000","0.00021000"],["77583.62000000","0.00000000"],["77583.85000000","0.00007000"],["77583.99000000","0.00000000"],["77584.00000000","0.00644000"],["77584.10000000","0.00000000"],["77584.51000000","0.00000000"],["77584.57000000","0.00000000"],["77584.78000000","0.00000000"],["77584.80000000","0.00000000"],["77584.83000000","0.00000000"],["77585.10000000","0.00000000"],["77585.12000000","0.00000000"],["77585.58000000","0.00000000"],["77586.16000000","0.02000000"],["77586.17000000","0.00000000"],["77586.18000000","0.00000000"],["77586.19000000","0.53928000"],["77586.20000000","0.00000000"],["77586.33000000","0.48492000"],["77587.31000000","0.00000000"],["77587.85000000","0.00257000"],["77589.97000000","0.00000000"],["77589.98000000","0.00000000"],["77589.99000000","0.63900000"],["77590.00000000","0.22264000"],["77590.91000000","0.04000000"],["77592.38000000","0.00000000"],["77592.53000000","0.00000000"],["77592.54000000","0.00000000"],["77595.03000000","0.09622000"],["77595.07000000","0.33667000"],["77597.04000000","1.93226000"],["77597.05000000","0.00000000"],["77597.06000000","0.26235000"],["77597.63000000","0.00128000"],["77597.77000000","0.00000000"],["77600.00000000","0.00022000"],["77600.21000000","0.64483000"],["77600.45000000","0.25793000"],["77601.27000000","0.00000000"],["77603.41000000","0.00200000"],["77604.01000000","0.00000000"],["77613.54000000","0.00000000"],["77615.41000000","1.27610000"],["77617.56000000","0.34801000"],["77674.09000000","0.00000000"],["77692.33000000","0.00000000"]]}}
{"type":"depth","received_at_ms":1788331842373,"data":{"e":"depthUpdate","E":1788331842514,"s":"BTCUSDT","U":99555814720,"u":99555814844,"b":[["77581.14000000","1.34362000"],["77581.13000000","0.00139000"],["77580.61000000","0.08233000"],["77580.00000000","0.03056000"],["77579.70000000","0.00014000"],["77579.69000000","0.07789000"],["77579.68000000","0.19957000"],["77579.67000000","0.00084000"],["77578.01000000","0.00007000"],["77577.80000000","0.01315000"],["77577.20000000","0.00000000"],["77574.67000000","0.00000000"],["77573.77000000","0.00115000"],["77572.94000000","0.00000000"],["77572.34000000","0.00000000"],["77566.79000000","0.01200000"],["77487.68000000","0.00000000"],["69823.03000000","0.00432000"],["62064.92000000","0.00032000"]],"a":[["77581.15000000","3.64484000"],["77581.16000000","0.00069000"],["77581.18000000","0.03139000"],["77581.19000000","0.00000000"],["77581.20000000","0.00000000"],["77581.21000000","0.00007000"],["77581.22000000","0.00014000"],["77581.23000000","0.19319000"],["77581.30000000","0.04822000"],["77582.13000000","0.00007000"],["77582.40000000","0.01877000"],["77582.63000000","0.00000000"],["77582.68000000","0.00000000"],["77583.50000000","0.00658000"],["77583.64000000","0.02241000"],["77583.85000000","0.00000000"],["77583.86000000","0.02928000"],["77583.87000000","0.01292000"],["77586.16000000","0.00400000"],["77587.85000000","0.00000000"],["77588.32000000","0.01066000"],["77588.34000000","0.00000000"],["77589.98000000","0.00400000"],["77597.03000000","0.83874000"],["77597.06000000","0.00000000"],["77681.85000000","1.29789000"],["77681.86000000","2.15391000"],["77720.50000000","0.00000000"]]}}
{"type":"depth","received_at_ms":1788331842474,"data":{"e":"depthUpdate","E":1788331842614,"s":"BTCUSDT","U":99555814845,"u":99555814885,"b":[["77581.14000000","1.34440000"],["77580.00000000","0.03056000"],["77579.69000000","0.07803000"],["77576.74000000","0.11454000"],["77573.38000000","0.00257000"],["77568.69000000","0.00000000"],["77477.21000000","0.00000000"],["76417.42000000","0.00030000"],["69823.03000000","0.00432000"],["62065.00000000","0.00000000"],["62064.92000000","0.00000000"]],"a":[["77581.15000000","3.62386000"],["77581.16000000","0.00076000"],["77581.18000000","0.03139000"],["77581.23000000","0.19333000"],["77583.86000000","0.02914000"],["77588.31000000","0.00400000"],["77588.89000000","0.00257000"],["77710.00000000","0.03850000"]]}}
{"type":"trade","received_at_ms":1788331842540,"data":{"e":"trade","E":1788331842681,"s":"BTCUSDT","t":6646633767,"p":"77581.15000000","q":"0.00039000","T":1788331842680,"m":false,"M":true}}
{"type":"depth","received_at_ms":1788331842573,"data":{"e":"depthUpdate","E":1788331842714,"s":"BTCUSDT","U":99555814886,"u":99555814905,"b":[["77581.14000000","1.34768000"],["77580.69000000","0.00118000"],["77580.00000000","0.03068000"],["77576.75000000","0.34792000"],["77573.38000000","0.00000000"],["77571.99000000","0.00257000"],["77489.67000000","0.03997000"],["77370.55000000","0.00813000"],["77358.32000000","0.00000000"],["69823.03000000","0.00448000"],["69823.02000000","0.00000000"]],"a":[["77581.15000000","3.48767000"],["77587.50000000","0.15257000"],["77588.89000000","0.00000000"],["77722.49000000","0.00971000"]]}}
{"type":"depth","received_at_ms":1788331842673,"data":{"e":"depthUpdate","E":1788331842814,"s":"BTCUSDT","U":99555814906,"u":99555814912,"b":[["77579.54000000","0.00000000"],["77579.36000000","0.00331000"],["77561.86000000","0.00007000"],["69823.03000000","0.00416000"]],"a":[["77592.90000000","0.00007000"]]}}
{"type":"depth","received_at_ms":1788331842775,"data":{"e":"depthUpdate","E":1788331842914,"s":"BTCUSDT","U":99555814913,"u":99555814920,"b":[["77581.14000000","1.34768000"],["77581.13000000","0.00139000"],["77571.99000000","0.00000000"],["69823.03000000","0.00448000"]],"a":[["77587.50000000","0.15000000"]]}}
{"type":"depth","received_at_ms":1788331842873,"data":{"e":"depthUpdate","E":1788331843014,"s":"BTCUSDT","U":99555814921,"u":99555814930,"b":[["77571.16000000","0.00601000"],["69823.03000000","0.00432000"],["62065.00000000","0.00000000"],["62064.92000000","0.00032000"],["62064.91000000","0.00000000"]],"a":[["77586.67000000","0.00257000"]]}}
{"type":"depth","received_at_ms":1788331842973,"data":{"e":"depthUpdate","E":1788331843114,"s":"BTCUSDT","U":99555814931,"u":99555814934,"b":[["69823.03000000","0.00448000"]],"a":[["77581.59000000","0.13453000"]]}}
{"type":"depth","received_at_ms":1788331843073,"data":{"e":"depthUpdate","E":1788331843214,"s":"BTCUSDT","U":99555814935,"u":99555814952,"b":[["77574.01000000","0.00000000"],["77572.49000000","0.00644000"],["77571.92000000","0.00007000"],["77568.92000000","0.00200000"],["77565.64000000","0.00000000"],["69823.03000000","0.00432000"],["62064.92000000","0.00000000"]],"a":[["77581.15000000","3.48760000"],["77581.16000000","0.00069000"],["77581.30000000","0.04822000"],["77581.59000000","0.13467000"],["77583.64000000","0.02227000"],["77588.31000000","0.00000000"],["77589.98000000","0.00800000"]]}}
{"type":"trade","received_at_ms":1788331843100,"data":{"e":"trade","E":1788331843240,"s":"BTCUSDT","t":6646633768,"p":"77581.15000000","q":"0.00257000","T":1788331843239,"m":false,"M":true}}
{"type":"depth","received_at_ms":1788331843173,"data":{"e":"depthUpdate","E":1788331843314,"s":"BTCUSDT","U":99555814953,"u":99555814977,"b":[["77581.14000000","1.31889000"],["77568.92000000","0.00000000"],["77566.60000000","0.00200000"],["77560.00000000","1.96491000"],["77553.25000000","1.56925000"],["77553.00000000","0.70000000"],["77500.58000000","1.61644000"],["77498.72000000","0.03162000"],["77497.99000000","0.00000000"],["69823.03000000","0.00441000"],["69823.00000000","0.00000000"],["62064.91000000","0.00000000"]],"a":[["77581.15000000","3.48517000"],["77581.16000000","0.00076000"],["77588.32000000","0.00866000"],["78744.87000000","0.00030000"]]}}
{"type":"depth","received_at_ms":1788331843274,"data":{"e":"depthUpdate","E":1788331843414,"s":"BTCUSDT","U":99555814978,"u":99555814982,"b":[["69823.03000000","0.00441000"]],"a":[["77584.26000000","0.00336000"],["77586.38000000","0.00327000"],["77588.32000000","0.01066000"]]}}
{"type":"depth","received_at_ms":1788331843374,"data":{"e":"depthUpdate","E":1788331843514,"s":"BTCUSDT","U":99555814983,"u":99555814988,"b":[["69823.03000000","0.00441000"],["62065.00000000","0.00200000"],["62064.92000000","0.00032000"]],"a":[]}}
{"type":"trade","received_at_ms":1788331843412,"data":{"e":"trade","E":1788331843551,"s":"BTCUSDT","t":6646633769,"p":"77581.15000000","q":"0.00064000","T":1788331843551,"m":false,"M":true}}
{"type":"depth","received_at_ms":1788331843477,"data":{"e":"depthUpdate","E":1788331843614,"s":"BTCUSDT","U":99555814989,"u":99555814999,"b":[["77581.14000000","1.34518000"],["76417.42000000","0.00030000"],["69823.03000000","0.00464000"],["69823.02000000","0.00009000"],["62064.92000000","0.00000000"]],"a":[["77581.15000000","3.48418000"]]}}
{"type":"depth","received_at_ms":1788331843575,"data":{"e":"depthUpdate","E":1788331843714,"s":"BTCUSDT","U":99555815000,"u":99555815009,"b":[["77553.99000000","0.00219000"],["77549.79000000","0.00412000"],["77521.57000000","0.77459000"],["77511.01000000","0.00000000"],["69823.03000000","0.00448000"]],"a":[["77599.60000000","0.00000000"],["77638.40000000","0.00000000"],["77669.44000000","0.00000000"]]}}
{"type":"depth","received_at_ms":1788331843674,"data":{"e":"depthUpdate","E":1788331843814,"s":"BTCUSDT","U":99555815010,"u":99555815013,"b":[["77561.86000000","0.00007000"],["69823.03000000","0.00464000"]],"a":[["77592.90000000","0.00007000"]]}}
{"type":"depth","received_at_ms":1788331843782,"data":{"e":"depthUpdate","E":1788331843914,"s":"BTCUSDT","U":99555815014,"u":99555815029,"b":[["77551.91000000","0.34831000"],["77527.75000000","0.00000000"],["69823.03000000","0.00448000"]],"a":[["77581.15000000","3.40192000"],["77581.16000000","0.00069000"],["77581.22000000","0.00000000"],["77581.23000000","0.00028000"],["77581.58000000","0.00007000"],["77582.54000000","0.00407000"],["77584.26000000","0.00000000"],["77586.38000000","0.00000000"],["77638.40000000","0.00412000"]]}}
{"type":"depth","received_at_ms":1788331843873,"data":{"e":"depthUpdate","E":1788331844014,"s":"BTCUSDT","U":99555815030,"u":99555815045,"b":[["69823.03000000","0.00464000"],["62064.92000000","0.00032000"],["62064.91000000","0.00000000"]],"a":[["77581.18000000","0.03139000"],["77581.23000000","0.00014000"],["77583.64000000","0.02241000"],["77615.40000000","0.33001000"],["77632.83000000","0.00000000"]]}}
{"type":"trade","received_at_ms":1788331843961,"data":{"e":"trade","E":1788331844098,"s":"BTCUSDT","t":6646633770,"p":"77581.15000000","q":"0.00100000","T":1788331844098,"m":false,"M":true}}
{"type":"depth","received_at_ms":1788331843979,"data":{"e":"depthUpdate","E":1788331844114,"s":"BTCUSDT","U":99555815046,"u":99555815069,"b":[["77581.14000000","1.34860000"],["77554.00000000","0.73000000"],["69823.03000000","0.00432000"],["69823.02000000","0.00000000"]],"a":[["77581.15000000","3.03394000"],["77581.16000000","0.00076000"],["77581.22000000","0.00014000"],["77581.23000000","0.23213000"],["77581.24000000","0.00051000"],["77581.30000000","0.00028000"],["77581.58000000","0.00000000"],["77582.54000000","0.00414000"],["77586.33000000","0.44492000"],["77599.60000000","0.00412000"]]}}
{"type":"depth","received_at_ms":1788331844076,"data":{"e":"depthUpdate","E":1788331844214,"s":"BTCUSDT","U":99555815070,"u":99555815120,"b":[["77581.14000000","1.67825000"],["77579.71000000","0.00014000"],["77579.70000000","0.11461000"],["77578.21000000","0.00060000"],["77568.92000000","0.00000000"],["77566.60000000","0.00000000"],["77489.67000000","0.00000000"],["69823.03000000","0.00464000"],["62064.92000000","0.00000000"]],"a":[["77581.15000000","3.11591000"],["77581.18000000","0.03139000"],["77581.23000000","0.16845000"],["77581.24000000","0.00037000"],["77581.29000000","0.32252000"],["77581.30000000","0.00014000"],["77581.58000000","0.00014000"],["77583.25000000","0.00333000"],["77583.50000000","0.00014000"],["77583.86000000","0.02928000"],["77584.61000000","0.00007000"],["77584.80000000","0.00328000"],["77585.40000000","0.00644000"],["77588.32000000","0.00866000"],["77589.98000000","0.01000000"],["77603.41000000","0.00000000"],["77605.75000000","0.00200000"],["77722.49000000","0.00000000"]]}}
{"type":"depth","received_at_ms":1788331844173,"data":{"e":"depthUpdate","E":1788331844314,"s":"BTCUSDT","U":99555815121,"u":99555815158,"b":[["77581.14000000","1.67832000"],["77581.13000000","0.00146000"],["77580.00000000","0.03075000"],["77579.70000000","0.11475000"],["77576.75000000","0.34778000"],["77566.52000000","0.00200000"],["77487.99000000","0.03997000"],["69823.03000000","0.00448000"],["62065.00000000","0.00200000"],["62064.91000000","0.00000000"]],"a":[["77581.15000000","3.11591000"],["77581.16000000","0.00076000"],["77582.40000000","0.01870000"],["77583.50000000","0.00000000"],["77583.87000000","0.01306000"],["77720.81000000","0.00971000"],["78744.87000000","0.00030000"]]}}
{"type":"depth","received_at_ms":1788331844280,"data":{"e":"depthUpdate","E":1788331844414,"s":"BTCUSDT","U":99555815159,"u":99555815161,"b":[["69823.03000000","0.00448000"],["69823.00000000","0.00020000"]],"a":[]}}
{"type":"depth","received_at_ms":1788331844373,"data":{"e":"depthUpdate","E":1788331844514,"s":"BTCUSDT","U":99555815162,"u":99555815170,"b":[["77568.92000000","0.00200000"],["77566.52000000","0.00000000"],["77487.99000000","0.00000000"],["69823.03000000","0.00448000"],["69823.00000000","0.00000000"],["62064.92000000","0.00032000"]],"a":[["77669.44000000","0.00412000"],["77720.81000000","0.00000000"]]}}
{"type":"depth","received_at_ms":1788331844474,"data":{"e":"depthUpdate","E":1788331844614,"s":"BTCUSDT","U":99555815171,"u":99555815186,"b":[["77572.67000000","0.00257000"],["77571.16000000","0.00344000"],["77476.84000000","0.04884000"],["76417.42000000","0.00030000"],["69823.03000000","0.00464000"],["62065.00000000","0.00200000"],["62064.92000000","0.00000000"]],"a":[["77586.67000000","0.00000000"],["77588.17000000","0.00257000"],["77709.63000000","0.00971000"]]}}
{"type":"depth","received_at_ms":1788331844573,"data":{"e":"depthUpdate","E":1788331844714,"s":"BTCUSDT","U":99555815187,"u":99555815191,"b":[["77566.79000000","0.00400000"],["69823.03000000","0.00448000"]],"a":[]}}
{"type":"depth","received_at_ms":1788331844674,"data":{"e":"depthUpdate","E":1788331844814,"s":"BTCUSDT","U":99555815192,"u":99555815202,"b":[["77572.67000000","0.00000000"],["77571.84000000","0.00257000"],["69823.03000000","0.00448000"]],"a":[["77581.15000000","3.11584000"],["77581.16000000","0.00069000"],["77583.25000000","0.00000000"],["77584.80000000","0.00000000"],["77587.35000000","0.00257000"],["77588.17000000","0.00000000"],["77696.90000000","0.00000000"]]}}
{"type":"depth","received_at_ms":1788331844773,"data":{"e":"depthUpdate","E":1788331844914,"s":"BTCUSDT","U":99555815203,"u":99555815208,"b":[["77561.86000000","0.00007000"],["69823.03000000","0.00448000"]],"a":[["77591.82000000","0.13304000"],["77592.90000000","0.00007000"]]}}
{"type":"depth","received_at_ms":1788331844874,"data":{"e":"depthUpdate","E":1788331845014,"s":"BTCUSDT","U":99555815209,"u":99555815222,"b":[["77568.92000000","0.00000000"],["77566.79000000","0.00400000"],["75493.45000000","0.00000000"],["69823.03000000","0.00448000"],["62064.92000000","0.00032000"],["62064.91000000","0.00000000"]],"a":[["77581.15000000","3.11591000"],["77597.63000000","0.00000000"],["77601.01000000","0.00128000"]]}}
{"type":"trade","received_at_ms":1788331844919,"data":{"e":"trade","E":1788331845059,"s":"BTCUSDT","t":6646633771,"p":"77581.14000000","q":"0.00064000","T":1788331845059,"m":true,"M":true}}
{"type":"trade","received_at_ms":1788331844944,"data":{"e":"trade","E":1788331845084,"s":"BTCUSDT","t":6646633772,"p":"77581.15000000","q":"0.01308000","T":1788331845084,"m":false,"M":true}}
{"type":"trade","received_at_ms":1788331844950,"data":{"e":"trade","E":1788331845091,"s":"BTCUSDT","t":6646633773,"p":"77581.14000000","q":"0.00007000","T":1788331845090,"m":true,"M":true}}
{"type":"depth","received_at_ms":1788331844973,"data":{"e":"depthUpdate","E":1788331845114,"s":"BTCUSDT","U":99555815223,"u":99555815232,"b":[["77581.14000000","1.67761000"],["77574.78000000","0.00400000"],["77568.92000000","0.00200000"],["77543.74000000","0.00000000"],["69823.03000000","0.00464000"],["69823.02000000","0.00009000"]],"a":[["77581.15000000","3.10283000"],["77586.18000000","0.00000000"]]}}
{"type":"trade","received_at_ms":1788331844991,"data":{"e":"trade","E":1788331845131,"s":"BTCUSDT","t":6646633774,"p":"77581.14000000","q":"0.00100000","T":1788331845131,"m":true,"M":true}}
{"type":"depth","received_at_ms":1788331845073,"data":{"e":"depthUpdate","E":1788331845214,"s":"BTCUSDT","U":99555815233,"u":99555815237,"b":[["77581.14000000","1.67661000"],["69823.03000000","0.00448000"],["62064.92000000","0.00000000"]],"a":[]}}
{"type":"depth","received_at_ms":1788331845174,"data":{"e":"depthUpdate","E":1788331845314,"s":"BTCUSDT","U":99555815238,"u":99555815248,"b":[["77549.79000000","0.00000000"],["77511.00000000","0.00412000"],["69823.03000000","0.00464000"],["62064.91000000","0.00020000"]],"a":[["77599.60000000","0.00000000"],["77638.40000000","0.00000000"],["77669.44000000","0.00000000"],["78744.87000000","0.00030000"]]}}
{"type":"depth","received_at_ms":1788331845281,"data":{"e":"depthUpdate","E":1788331845414,"s":"BTCUSDT","U":99555815249,"u":99555815259,"b":[["77581.14000000","1.67654000"],["77581.13000000","0.00139000"],["77576.74000000","0.00007000"],["77568.92000000","0.00000000"],["77566.79000000","0.00400000"],["69823.03000000","0.00448000"],["62064.91000000","0.00000000"]],"a":[["77581.15000000","3.10290000"]]}}
{"type":"trade","received_at_ms":1788331845336,"data":{"e":"trade","E":1788331845470,"s":"BTCUSDT","t":6646633775,"p":"77581.15000000","q":"0.00064000","T":1788331845470,"m":false,"M":true}}
{"type":"depth","received_at_ms":1788331845374,"data":{"e":"depthUpdate","E":1788331845515,"s":"BTCUSDT","U":99555815260,"u":99555815273,"b":[["77568.92000000","0.00200000"],["77566.52000000","0.00000000"],["77564.60000000","0.02000000"],["69823.03000000","0.00464000"],["69823.02000000","0.00000000"],["69823.01000000","0.00009000"],["69823.00000000","0.00000000"],["62064.92000000","0.00032000"]],"a":[["77581.15000000","3.10226000"],["77589.98000000","0.00800000"],["77638.40000000","0.00412000"]]}}
{"type":"trade","received_at_ms":1788331845426,"data":{"e":"trade","E":1788331845566,"s":"BTCUSDT","t":6646633776,"p":"77581.14000000","q":"0.00257000","T":1788331845566,"m":true,"M":true}}
{"type":"depth","received_at_ms":1788331845475,"data":{"e":"depthUpdate","E":1788331845614,"s":"BTCUSDT","U":99555815274,"u":99555815289,"b":[["77581.14000000","1.67397000"],["77573.48000000","0.00644000"],["77572.49000000","0.00000000"],["77570.25000000","0.00644000"],["77569.40000000","0.00000000"],["77568.92000000","0.00000000"],["77566.79000000","0.00400000"],["77556.78000000","0.00000000"],["76417.42000000","0.00030000"],["69823.03000000","0.00448000"],["62065.00000000","0.00400000"],["62064.92000000","0.00000000"]],"a":[["77584.00000000","0.00000000"],["77584.47000000","0.01288000"],["77585.40000000","0.00000000"]]}}
{"type":"depth","received_at_ms":1788331845574,"data":{"e":"depthUpdate","E":1788331845714,"s":"BTCUSDT","U":99555815290,"u":99555815301,"b":[["77568.92000000","0.00200000"],["69823.03000000","0.00464000"],["62065.00000000","0.00200000"]],"a":[["77581.15000000","3.10226000"],["77581.29000000","0.32259000"],["77583.87000000","0.01299000"],["77589.98000000","0.01000000"]]}}
{"type":"trade","received_at_ms":1788331845577,"data":{"e":"trade","E":1788331845718,"s":"BTCUSDT","t":6646633777,"p":"77581.14000000","q":"0.00039000","T":1788331845717,"m":true,"M":true}}
{"type":"depth","received_at_ms":1788331845674,"data":{"e":"depthUpdate","E":1788331845814,"s":"BTCUSDT","U":99555815302,"u":99555815309,"b":[["77581.14000000","1.67358000"],["77568.92000000","0.00000000"],["77566.80000000","0.00200000"],["69823.03000000","0.00448000"]],"a":[]}}
{"type":"depth","received_at_ms":1788331845774,"data":{"e":"depthUpdate","E":1788331845914,"s":"BTCUSDT","U":99555815310,"u":99555815331,"b":[["77581.14000000","1.67337000"],["77581.13000000","0.00125000"],["77579.98000000","0.00000000"],["77579.68000000","0.18668000"],["77579.36000000","0.00000000"],["77576.62000000","0.00000000"],["77568.92000000","0.00200000"],["77566.80000000","0.00000000"],["77561.86000000","0.00007000"],["77302.53000000","0.00000000"],["71374.65000000","0.00015000"],["69823.03000000","0.00464000"]],"a":[["77592.90000000","0.00007000"],["77597.06000000","0.20507000"],["77669.44000000","0.00412000"],["77943.35000000","0.00000000"]]}}
{"type":"depth","received_at_ms":1788331845874,"data":{"e":"depthUpdate","E":1788331846014,"s":"BTCUSDT","U":99555815332,"u":99555815343,"b":[["77260.90000000","0.00009000"],["69823.03000000","0.00432000"],["62065.00000000","0.00200000"],["62064.92000000","0.00032000"],["62064.91000000","0.00000000"]],"a":[["77581.15000000","3.10219000"],["77901.39000000","0.00009000"]]}}
{"type":"depth","received_at_ms":1788331845973,"data":{"e":"depthUpdate","E":1788331846114,"s":"BTCUSDT","U":99555815344,"u":99555815356,"b":[["77495.59000000","0.00396000"],["69823.03000000","0.00464000"]],"a":[["77581.15000000","3.10226000"],["77584.40000000","0.00000000"],["77584.44000000","0.00329000"],["77585.95000000","0.00000000"],["77586.00000000","0.00340000"],["77599.60000000","0.00412000"]]}}
{"type":"depth","received_at_ms":1788331846073,"data":{"e":"depthUpdate","E":1788331846214,"s":"BTCUSDT","U":99555815357,"u":99555815369,"b":[["77581.14000000","1.67344000"],["77577.83000000","0.00330000"],["77568.92000000","0.00000000"],["77566.79000000","0.00400000"],["77557.15000000","0.00000000"],["77533.31000000","0.00000000"],["69823.03000000","0.00448000"],["62064.92000000","0.00000000"]],"a":[]}}
{"type":"trade","received_at_ms":1788331846154,"data":{"e":"trade","E":1788331846292,"s":"BTCUSDT","t":6646633778,"p":"77581.15000000","q":"0.00007000","T":1788331846291,"m":false,"M":true}}
{"type":"depth","received_at_ms":1788331846173,"data":{"e":"depthUpdate","E":1788331846314,"s":"BTCUSDT","U":99555815370,"u":99555815384,"b":[["77568.92000000","0.00200000"],["77553.00000000","0.00000000"],["75493.45000000","0.00026000"],["69823.03000000","0.00432000"],["69823.01000000","0.00000000"],["62065.00000000","0.00200000"]],"a":[["77581.15000000","3.10219000"],["77584.47000000","0.00644000"],["77584.87000000","0.00644000"],["78744.87000000","0.00030000"]]}}
{"type":"depth","received_at_ms":1788331846274,"data":{"e":"depthUpdate","E":1788331846414,"s":"BTCUSDT","U":99555815385,"u":99555815388,"b":[["71374.65000000","0.00000000"],["69823.03000000","0.00448000"],["62064.91000000","0.00000000"]],"a":[]}}
{"type":"depth","received_at_ms":1788331846374,"data":{"e":"depthUpdate","E":1788331846514,"s":"BTCUSDT","U":99555815389,"u":99555815422,"b":[["77581.14000000","1.67337000"],["77577.83000000","0.00000000"],["77571.01000000","0.00644000"],["77570.25000000","0.00000000"],["77568.92000000","0.00000000"],["77566.39000000","0.00200000"],["75557.06000000","0.00000000"],["69823.03000000","0.00448000"],["69823.00000000","0.00020000"],["62065.00000000","0.00400000"],["62064.92000000","0.00032000"]],"a":[["77581.15000000","3.10212000"],["77581.16000000","0.00069000"],["77581.22000000","0.00000000"],["77581.23000000","0.00014000"],["77583.85000000","0.00014000"],["77584.44000000","0.00000000"],["77584.47000000","0.00000000"],["77584.87000000","0.00000000"],["77585.40000000","0.01288000"],["77586.00000000","0.00000000"],["77589.98000000","0.00600000"],["77589.99000000","1.18574000"],["77591.54000000","1.93226000"],["81001.06000000","0.00000000"]]}}
{"type":"trade","received_at_ms":1788331846459,"data":{"e":"trade","E":1788331846598,"s":"BTCUSDT","t":6646633779,"p":"77581.14000000","q":"0.00051000","T":1788331846598,"m":true,"M":true}}
{"type":"depth","received_at_ms":1788331846474,"data":{"e":"depthUpdate","E":1788331846614,"s":"BTCUSDT","U":99555815423,"u":99555815460,"b":[["77581.14000000","1.67628000"],["77577.39000000","0.00343000"],["77568.92000000","0.00200000"],["77566.39000000","0.00000000"],["77565.72000000","0.08038000"],["77556.41000000","1.42242000"],["77555.43000000","0.49697000"],["77531.59000000","0.97679000"],["77476.84000000","0.00000000"],["76417.42000000","0.00030000"],["69823.03000000","0.00464000"],["69823.02000000","0.00009000"],["69823.00000000","0.00000000"],["62064.92000000","0.00000000"]],"a":[["77581.15000000","3.10220000"],["77581.18000000","0.03139000"],["77581.21000000","0.00000000"],["77581.23000000","0.00000000"],["77583.87000000","0.01299000"],["77584.62000000","0.04166000"],["77584.88000000","0.02234000"],["77586.02000000","0.00341000"],["77589.98000000","0.00400000"],["77709.63000000","0.00000000"]]}}
{"type":"depth","received_at_ms":1788331846574,"data":{"e":"depthUpdate","E":1788331846714,"s":"BTCUSDT","U":99555815461,"u":99555815465,"b":[["77581.14000000","1.67635000"],["77487.99000000","0.03997000"],["69823.03000000","0.00448000"]],"a":[["77589.98000000","0.00600000"],["77720.81000000","0.00971000"]]}}
{"type":"trade","received_at_ms":1788331846671,"data":{"e":"trade","E":1788331846809,"s":"BTCUSDT","t":6646633780,"p":"77581.14000000","q":"0.00018000","T":1788331846809,"m":true,"M":true}}
{"type":"depth","received_at_ms":1788331846673,"data":{"e":"depthUpdate","E":1788331846814,"s":"BTCUSDT","U":99555815466,"u":99555815472,"b":[["77581.14000000","1.67617000"],["77551.55000000","0.04715000"],["77537.76000000","0.00000000"],["77370.55000000","0.00000000"],["77358.32000000","0.00813000"],["69823.03000000","0.00464000"]],"a":[]}}
{"type":"trade","received_at_ms":1788331846739,"data":{"e":"trade","E":1788331846877,"s":"BTCUSDT","t":6646633781,"p":"77581.15000000","q":"0.00007000","T":1788331846876,"m":false,"M":true}}
{"type":"trade","received_at_ms":1788331846739,"data":{"e":"trade","E":1788331846877,"s":"BTCUSDT","t":6646633782,"p":"77581.15000000","q":"0.00008000","T":1788331846876,"m":false,"M":true}}
{"type":"trade","received_at_ms":1788331846739,"data":{"e":"trade","E":1788331846877,"s":"BTCUSDT","t":6646633783,"p":"77581.15000000","q":"0.00007000","T":1788331846876,"m":false,"M":true}}
{"type":"trade","received_at_ms":1788331846739,"data":{"e":"trade","E":1788331846877,"s":"BTCUSDT","t":6646633784,"p":"77581.15000000","q":"0.00007000","T":1788331846876,"m":false,"M":true}}
{"type":"trade","received_at_ms":1788331846739,"data":{"e":"trade","E":1788331846877,"s":"BTCUSDT","t":6646633785,"p":"77581.15000000","q":"0.00013000","T":1788331846876,"m":false,"M":true}}
{"type":"trade","received_at_ms":1788331846739,"data":{"e":"trade","E":1788331846877,"s":"BTCUSDT","t":6646633786,"p":"77581.15000000","q":"0.00007000","T":1788331846876,"m":false,"M":true}}
{"type":"trade","received_at_ms":1788331846739,"data":{"e":"trade","E":1788331846877,"s":"BTCUSDT","t":6646633787,"p":"77581.15000000","q":"0.00007000","T":1788331846876,"m":false,"M":true}}
{"type":"trade","received_at_ms":1788331846739,"data":{"e":"trade","E":1788331846877,"s":"BTCUSDT","t":6646633788,"p":"77581.15000000","q":"0.00007000","T":1788331846876,"m":false,"M":true}}
{"type":"trade","received_at_ms":1788331846739,"data":{"e":"trade","E":1788331846877,"s":"BTCUSDT","t":6646633789,"p":"77581.15000000","q":"0.00007000","T":1788331846876,"m":false,"M":true}}
{"type":"trade","received_at_ms":1788331846739,"data":{"e":"trade","E":1788331846877,"s":"BTCUSDT","t":6646633790,"p":"77581.15000000","q":"0.00007000","T":1788331846876,"m":false,"M":true}}
{"type":"trade","received_at_ms":1788331846739,"data":{"e":"trade","E":1788331846877,"s":"BTCUSDT","t":6646633791,"p":"77581.15000000","q":"0.00007000","T":1788331846876,"m":false,"M":true}}
{"type":"trade","received_at_ms":1788331846739,"data":{"e":"trade","E":1788331846877,"s":"BTCUSDT","t":6646633792,"p":"77581.15000000","q":"0.00007000","T":1788331846876,"m":false,"M":true}}
{"type":"trade","received_at_ms":1788331846739,"data":{"e":"trade","E":1788331846877,"s":"BTCUSDT","t":6646633793,"p":"77581.15000000","q":"0.00383000","T":1788331846876,"m":false,"M":true}}
{"type":"trade","received_at_ms":1788331846739,"data":{"e":"trade","E":1788331846877,"s":"BTCUSDT","t":6646633794,"p":"77581.15000000","q":"0.00009000","T":1788331846877,"m":false,"M":true}}
{"type":"trade","received_at_ms":1788331846743,"data":{"e":"trade","E":1788331846883,"s":"BTCUSDT","t":6646633795,"p":"77581.15000000","q":"0.00223000","T":1788331846883,"m":false,"M":true}}
{"type":"trade","received_at_ms":1788331846758,"data":{"e":"trade","E":1788331846897,"s":"BTCUSDT","t":6646633796,"p":"77581.15000000","q":"0.00474000","T":1788331846896,"m":false,"M":true}}
{"type":"trade","received_at_ms":1788331846761,"data":{"e":"trade","E":1788331846901,"s":"BTCUSDT","t":6646633797,"p":"77581.15000000","q":"0.00024000","T":1788331846900,"m":false,"M":true}}
{"type":"trade","received_at_ms":1788331846761,"data":{"e":"trade","E":1788331846901,"s":"BTCUSDT","t":6646633798,"p":"77581.15000000","q":"0.00048000","T":1788331846900,"m":false,"M":true}}
{"type":"trade","received_at_ms":1788331846761,"data":{"e":"trade","E":1788331846901,"s":"BTCUSDT","t":6646633799,"p":"77581.15000000","q":"0.00007000","T":1788331846900,"m":false,"M":true}}
{"type":"trade","received_at_ms":1788331846761,"data":{"e":"trade","E":1788331846901,"s":"BTCUSDT","t":6646633800,"p":"77581.15000000","q":"0.00047000","T":1788331846900,"m":false,"M":true}}
{"type":"trade","received_at_ms":1788331846761,"data":{"e":"trade","E":1788331846901,"s":"BTCUSDT","t":6646633801,"p":"77581.15000000","q":"0.00118000","T":1788331846900,"m":false,"M":true}}
{"type":"trade","received_at_ms":1788331846764,"data":{"e":"trade","E":1788331846904,"s":"BTCUSDT","t":6646633802,"p":"77581.15000000","q":"0.00048000","T":1788331846904,"m":false,"M":true}}
{"type":"trade","received_at_ms":1788331846764,"data":{"e":"trade","E":1788331846904,"s":"BTCUSDT","t":6646633803,"p":"77581.15000000","q":"0.00069000","T":1788331846904,"m":false,"M":true}}
{"type":"trade","received_at_ms":1788331846764,"data":{"e":"trade","E":1788331846904,"s":"BTCUSDT","t":6646633804,"p":"77581.15000000","q":"0.00007000","T":1788331846904,"m":false,"M":true}}
{"type":"trade","received_at_ms":1788331846764,"data":{"e":"trade","E":1788331846904,"s":"BTCUSDT","t":6646633805,"p":"77581.15000000","q":"0.00076000","T":1788331846904,"m":false,"M":true}}
{"type":"depth","received_at_ms":1788331846774,"data":{"e":"depthUpdate","E":1788331846914,"s":"BTCUSDT","U":99555815473,"u":99555815859,"b":[["77581.14000000","4.00892000"],["77581.13000000","0.03669000"],["77580.89000000","0.04000000"],["77580.80000000","0.00124000"],["77580.61000000","0.08240000"],["77580.60000000","0.00400000"],["77580.02000000","0.00644000"],["77579.76000000","0.00000000"],["77579.71000000","0.00000000"],["77579.70000000","0.00028000"],["77579.68000000","0.13052000"],["77578.66000000","0.00400000"],["77578.44000000","0.01294000"],["77578.20000000","0.00014000"],["77578.07000000","0.00075000"],["77578.00000000","0.03049000"],["77577.80000000","0.00021000"],["77576.86000000","0.03000000"],["77576.76000000","0.00000000"],["77576.75000000","0.34778000"],["77576.72000000","0.00408000"],["77576.57000000","0.00644000"],["77576.56000000","0.00000000"],["77575.40000000","0.00000000"],["77574.91000000","0.00000000"],["77574.42000000","0.00400000"],["77573.79000000","0.00000000"],["77573.77000000","0.00000000"],["77573.48000000","0.00000000"],["77572.95000000","0.62859000"],["77572.94000000","0.00000000"],["77572.45000000","0.00000000"],["77572.25000000","0.00151000"],["77571.84000000","0.00000000"],["77571.66000000","0.00865000"],["77571.01000000","0.00000000"],["77569.06000000","0.04000000"],["77568.96000000","0.00015000"],["77568.92000000","0.00000000"],["77568.64000000","0.00000000"],["77568.50000000","0.00000000"],["77568.25000000","0.00000000"],["77566.79000000","0.00000000"],["77564.30000000","0.00000000"],["77561.86000000","0.00007000"],["77561.47000000","0.00000000"],["77561.17000000","0.64501000"],["77560.03000000","0.00400000"],["77559.88000000","0.34827000"],["77556.96000000","0.00200000"],["77556.41000000","1.40953000"],["77552.00000000","0.03007000"],["77551.62000000","0.00000000"],["77551.28000000","0.00000000"],["77550.97000000","0.34831000"],["77550.92000000","0.33895000"],["77550.03000000","0.00000000"],["77549.56000000","0.00000000"],["77547.62000000","0.00000000"],["77545.68000000","0.00008000"],["77540.20000000","0.00000000"],["77536.18000000","0.00000000"],["77535.85000000","0.00000000"],["77534.14000000","0.00000000"],["77531.07000000","0.00000000"],["77508.56000000","0.00000000"],["69823.03000000","0.00448000"],["69823.02000000","0.00000000"],["69823.01000000","0.00009000"]],"a":[["77581.15000000","0.73176000"],["77581.17000000","0.00013000"],["77581.18000000","0.00014000"],["77581.28000000","0.00000000"],["77581.29000000","0.00021000"],["77581.58000000","0.00000000"],["77581.59000000","0.00014000"],["77582.39000000","0.00014000"],["77582.54000000","0.00007000"],["77583.51000000","0.00014000"],["77583.63000000","0.00014000"],["77583.86000000","0.02942000"],["77584.48000000","0.00000000"],["77584.62000000","0.00021000"],["77584.75000000","0.00000000"],["77584.88000000","0.02227000"],["77585.40000000","0.00000000"],["77585.41000000","0.00000000"],["77586.01000000","0.00000000"],["77586.02000000","0.00000000"],["77586.16000000","0.00000000"],["77586.19000000","0.00000000"],["77586.33000000","0.00000000"],["77586.42000000","0.00000000"],["77586.48000000","0.00007000"],["77586.54000000","0.00000000"],["77586.95000000","0.00000000"],["77586.97000000","0.00000000"],["77587.03000000","0.11447000"],["77587.35000000","0.00000000"],["77587.50000000","0.00000000"],["77588.32000000","0.00211000"],["77588.33000000","0.00000000"],["77588.50000000","0.11447000"],["77588.53000000","0.00000000"],["77588.91000000","0.16880000"],["77589.29000000","0.00000000"],["77589.50000000","0.00000000"],["77589.97000000","0.10359000"],["77589.98000000","0.00200000"],["77589.99000000","0.00000000"],["77590.00000000","0.10322000"],["77590.01000000","0.42120000"],["77590.40000000","0.00159000"],["77590.42000000","0.00007000"],["77590.44000000","0.32235000"],["77590.84000000","0.12888000"],["77590.91000000","0.00000000"],["77591.53000000","0.00644000"],["77591.54000000","0.00000000"],["77591.55000000","0.00000000"],["77591.79000000","0.00000000"],["77591.83000000","0.00000000"],["77592.20000000","0.00000000"],["77592.25000000","0.00000000"],["77592.31000000","0.07000000"],["77592.90000000","0.00007000"],["77592.91000000","0.00000000"],["77593.29000000","0.00000000"],["77594.13000000","0.11447000"],["77594.36000000","0.18177000"],["77594.41000000","0.08000000"],["77594.52000000","0.02000000"],["77595.03000000","0.00000000"],["77595.07000000","0.00000000"],["77595.08000000","0.00000000"],["77595.27000000","0.00000000"],["77595.34000000","0.00644000"],["77595.62000000","0.12958000"],["77595.82000000","0.00000000"],["77596.10000000","0.00000000"],["77596.67000000","0.16880000"],["77597.03000000","0.32279000"],["77597.04000000","0.00000000"],["77598.37000000","0.00257000"],["77600.20000000","0.09622000"],["77600.21000000","0.43001000"],["77600.22000000","1.02235000"],["77600.45000000","0.00000000"],["77601.11000000","0.00000000"],["77601.38000000","0.00000000"],["77602.54000000","0.00000000"],["77602.88000000","0.00000000"],["77602.96000000","0.00000000"],["77602.98000000","0.00000000"],["77603.28000000","0.00000000"],["77605.11000000","0.12885000"],["77605.62000000","0.00000000"],["77605.75000000","0.00000000"],["77607.82000000","1.85888000"],["77607.83000000","1.25051000"],["77607.84000000","0.00000000"],["77608.00000000","0.03007000"],["77608.83000000","0.04753000"],["77609.65000000","0.00200000"],["77612.82000000","0.00000000"],["77613.28000000","0.00038000"],["77613.58000000","0.00400000"],["77614.41000000","0.64450000"],["77615.40000000","0.00000000"],["77615.41000000","0.00000000"],["77616.00000000","0.03265000"],["77616.78000000","0.34802000"],["77617.46000000","0.00400000"],["77621.34000000","0.00400000"],["77621.94000000","0.00007000"],["77623.25000000","0.00000000"],["77623.49000000","1.27596000"],["77624.56000000","0.00000000"],["77625.54000000","0.34798000"],["77625.88000000","0.00007000"],["77629.82000000","0.00007000"],["77643.33000000","0.35949000"],["77645.43000000","1.27560000"],["77658.75000000","1.76499000"],["77658.76000000","0.00000000"],["77681.85000000","0.75095000"],["77681.86000000","0.00000000"],["77684.45000000","0.00000000"],["77775.16000000","3.85902000"],["77778.38000000","0.00000000"],["77792.63000000","0.02019000"]]}}
{"type":"trade","received_at_ms":1788331846838,"data":{"e":"trade","E":1788331846977,"s":"BTCUSDT","t":6646633806,"p":"77581.15000000","q":"0.00169000","T":1788331846976,"m":false,"M":true}}
{"type":"depth","received_at_ms":1788331846874,"data":{"e":"depthUpdate","E":1788331847014,"s":"BTCUSDT","U":99555815860,"u":99555816094,"b":[["77581.14000000","4.01642000"],["77581.13000000","0.03648000"],["77580.90000000","0.00014000"],["77580.89000000","0.04014000"],["77580.61000000","0.08240000"],["77580.51000000","0.00000000"],["77580.02000000","0.00014000"],["77580.00000000","0.03068000"],["77579.70000000","0.00014000"],["77579.69000000","0.07789000"],["77579.68000000","0.13052000"],["77579.04000000","0.00000000"],["77578.95000000","0.00257000"],["77578.67000000","0.01288000"],["77578.20000000","0.00000000"],["77578.00000000","0.03035000"],["77577.80000000","0.00007000"],["77576.75000000","0.34785000"],["77576.57000000","0.00000000"],["77574.42000000","0.00000000"],["77573.77000000","0.00400000"],["77572.96000000","0.00000000"],["77572.95000000","0.00000000"],["77568.00000000","0.03265000"],["77566.79000000","0.62863000"],["77565.72000000","0.00000000"],["77556.96000000","0.00000000"],["77556.17000000","0.00000000"],["77555.15000000","0.00335000"],["77553.30000000","0.00200000"],["77540.35000000","1.29997000"],["77533.32000000","0.45641000"],["77532.37000000","0.00000000"],["77529.95000000","0.00436000"],["77518.91000000","0.00000000"],["77413.01000000","0.00000000"],["69823.03000000","0.00448000"],["62064.92000000","0.00032000"],["62064.91000000","0.00000000"]],"a":[["77581.15000000","0.88011000"],["77581.16000000","0.00069000"],["77581.18000000","0.00000000"],["77581.24000000","0.00030000"],["77581.29000000","0.00000000"],["77581.59000000","0.00000000"],["77582.72000000","0.00007000"],["77583.87000000","0.01299000"],["77583.91000000","0.00000000"],["77584.01000000","0.00000000"],["77584.22000000","0.00000000"],["77584.61000000","0.00000000"],["77584.62000000","0.00007000"],["77584.69000000","0.00000000"],["77584.87000000","0.00007000"],["77584.88000000","0.02255000"],["77585.56000000","0.00208000"],["77585.93000000","0.08219000"],["77587.03000000","0.11468000"],["77587.98000000","0.00000000"],["77588.36000000","0.00000000"],["77588.50000000","0.11468000"],["77588.54000000","0.30021000"],["77589.96000000","0.00644000"],["77589.98000000","0.00000000"],["77589.99000000","0.11447000"],["77590.00000000","0.00000000"],["77590.30000000","0.00000000"],["77590.42000000","0.00014000"],["77591.53000000","0.00000000"],["77591.80000000","0.00027000"],["77592.30000000","0.00342000"],["77592.31000000","0.03000000"],["77593.06000000","0.00644000"],["77593.07000000","0.00048000"],["77594.00000000","0.00047000"],["77594.11000000","0.11447000"],["77594.12000000","0.29446000"],["77594.13000000","0.00000000"],["77594.31000000","0.14426000"],["77594.36000000","0.00014000"],["77594.46000000","0.00257000"],["77594.52000000","0.00000000"],["77594.54000000","0.00000000"],["77595.05000000","0.00189000"],["77595.34000000","0.00000000"],["77596.02000000","0.00000000"],["77596.03000000","0.00000000"],["77597.02000000","0.00800000"],["77597.54000000","0.00000000"],["77598.37000000","0.00000000"],["77598.52000000","0.04000000"],["77598.91000000","0.00000000"],["77600.21000000","0.00000000"],["77601.01000000","0.00000000"],["77602.88000000","0.38675000"],["77602.96000000","0.38372000"],["77605.07000000","0.00463000"],["77608.41000000","0.00000000"],["77614.21000000","0.00125000"],["77614.31000000","0.00000000"],["77614.67000000","0.00000000"],["77615.52000000","0.00415000"],["77615.73000000","0.00000000"],["77616.24000000","0.09609000"],["77616.39000000","1.29870000"],["77619.44000000","0.00000000"],["77619.48000000","0.00000000"],["77619.51000000","0.23936000"],["77623.49000000","0.00000000"],["77625.22000000","0.00400000"],["77625.67000000","0.00431000"],["77625.89000000","0.03867000"],["77626.26000000","0.00628000"],["77629.34000000","0.33002000"],["77629.82000000","0.00000000"],["77630.89000000","0.00432000"],["77631.79000000","0.00427000"]]}}
{"type":"trade","received_at_ms":1788331846906,"data":{"e":"trade","E":1788331847046,"s":"BTCUSDT","t":6646633807,"p":"77581.15000000","q":"0.00168000","T":1788331847045,"m":false,"M":true}}
{"type":"depth","received_at_ms":1788331846974,"data":{"e":"depthUpdate","E":1788331847114,"s":"BTCUSDT","U":99555816095,"u":99555816147,"b":[["77581.14000000","4.01842000"],["77580.61000000","0.08233000"],["77580.02000000","0.00000000"],["77579.68000000","0.13059000"],["77578.67000000","0.01302000"],["77578.00000000","0.03042000"],["77577.85000000","0.00027000"],["77576.75000000","0.34778000"],["77569.81000000","0.00200000"],["77547.17000000","0.00000000"],["77545.45000000","0.02488000"],["77531.38000000","0.00625000"],["77519.87000000","0.00000000"],["77427.60000000","0.02237000"],["77411.24000000","0.00000000"],["77383.19000000","0.02019000"],["77357.27000000","0.00000000"],["69823.03000000","0.00432000"]],"a":[["77581.15000000","0.87789000"],["77584.42000000","0.11924000"],["77584.88000000","0.02255000"],["77585.93000000","0.08233000"],["77588.54000000","0.30007000"],["77590.09000000","0.00069000"],["77592.30000000","0.00542000"]]}}
{"type":"trade","received_at_ms":1788331847000,"data":{"e":"trade","E":1788331847132,"s":"BTCUSDT","t":6646633808,"p":"77581.15000000","q":"0.00674000","T":1788331847131,"m":false,"M":true}}
{"type":"trade","received_at_ms":1788331847025,"data":{"e":"trade","E":1788331847164,"s":"BTCUSDT","t":6646633809,"p":"77581.14000000","q":"0.01308000","T":1788331847164,"m":true,"M":true}}
{"type":"depth","received_at_ms":1788331847087,"data":{"e":"depthUpdate","E":1788331847214,"s":"BTCUSDT","U":99555816148,"u":99555816173,"b":[["77581.14000000","4.00534000"],["77578.44000000","0.01308000"],["69823.03000000","0.00448000"],["69823.01000000","0.00000000"],["62065.00000000","0.00400000"],["62064.92000000","0.00000000"]],"a":[["77581.15000000","0.87108000"],["77581.16000000","0.00076000"],["77583.87000000","0.01306000"],["77584.41000000","0.00007000"],["77584.42000000","0.00014000"],["77588.50000000","0.11454000"]]}}
{"type":"trade","received_at_ms":1788331847138,"data":{"e":"trade","E":1788331847278,"s":"BTCUSDT","t":6646633810,"p":"77581.15000000","q":"0.00212000","T":1788331847278,"m":false,"M":true}}
{"type":"trade","received_at_ms":1788331847138,"data":{"e":"trade","E":1788331847278,"s":"BTCUSDT","t":6646633811,"p":"77581.15000000","q":"0.00006000","T":1788331847278,"m":false,"M":true}}
{"type":"trade","received_at_ms":1788331847173,"data":{"e":"trade","E":1788331847313,"s":"BTCUSDT","t":6646633812,"p":"77581.15000000","q":"0.00001000","T":1788331847313,"m":false,"M":true}}
{"type":"trade","received_at_ms":1788331847173,"data":{"e":"trade","E":1788331847313,"s":"BTCUSDT","t":6646633813,"p":"77581.15000000","q":"0.00142000","T":1788331847313,"m":false,"M":true}}
{"type":"depth","received_at_ms":1788331847173,"data":{"e":"depthUpdate","E":1788331847314,"s":"BTCUSDT","U":99555816174,"u":99555816207,"b":[["77581.14000000","4.00534000"],["77578.67000000","0.00658000"],["77578.00000000","0.03049000"],["77577.81000000","0.00644000"],["77576.25000000","0.00000000"],["77572.94000000","0.00000000"],["77569.81000000","0.00200000"],["77408.92000000","4.63609000"],["75557.06000000","0.00010000"],["69823.03000000","0.00432000"]],"a":[["77581.15000000","0.86798000"],["77581.16000000","0.00069000"],["77583.87000000","0.01299000"],["77584.41000000","0.00000000"],["77584.42000000","0.00000000"],["77584.88000000","0.02262000"],["77585.56000000","0.11655000"],["77588.50000000","0.11468000"],["77590.09000000","0.00000000"],["78744.87000000","0.00030000"]]}}
{"type":"trade","received_at_ms":1788331847202,"data":{"e":"trade","E":1788331847342,"s":"BTCUSDT","t":6646633814,"p":"77581.15000000","q":"0.00218000","T":1788331847341,"m":false,"M":true}}
{"type":"trade","received_at_ms":1788331847202,"data":{"e":"trade","E":1788331847343,"s":"BTCUSDT","t":6646633815,"p":"77581.14000000","q":"0.03081000","T":1788331847343,"m":true,"M":true}}
{"type":"depth","received_at_ms":1788331847274,"data":{"e":"depthUpdate","E":1788331847414,"s":"BTCUSDT","U":99555816208,"u":99555816264,"b":[["77581.14000000","3.84098000"],["77580.02000000","0.00054000"],["77578.95000000","0.00000000"],["77578.67000000","0.00014000"],["77578.02000000","0.00644000"],["77578.00000000","0.03049000"],["77577.81000000","0.00000000"],["77576.87000000","0.00644000"],["77569.81000000","0.00000000"],["77569.07000000","0.00200000"],["69823.03000000","0.00448000"],["62064.91000000","0.00000000"]],"a":[["77581.15000000","0.83548000"],["77583.87000000","0.01306000"],["77584.08000000","0.00007000"],["77584.09000000","0.11447000"],["77584.88000000","0.02262000"],["77585.56000000","0.11669000"],["77586.48000000","0.00014000"],["77588.50000000","0.11454000"],["77588.53000000","0.50956000"],["77588.91000000","0.16912000"],["77592.91000000","0.11447000"],["77593.06000000","0.00901000"],["77594.10000000","0.00400000"],["77594.46000000","0.00000000"],["77596.27000000","1.37182000"],["77596.28000000","1.31471000"],["77596.67000000","0.16912000"],["77597.00000000","0.00000000"],["77597.01000000","1.93226000"],["77597.03000000","0.00000000"],["77604.43000000","0.00042000"],["77612.19000000","0.00042000"],["77625.88000000","0.00000000"],["77692.33000000","0.00200000"]]}}
{"type":"trade","received_at_ms":1788331847274,"data":{"e":"trade","E":1788331847414,"s":"BTCUSDT","t":6646633816,"p":"77581.14000000","q":"0.00059000","T":1788331847414,"m":true,"M":true}}
{"type":"trade","received_at_ms":1788331847317,"data":{"e":"trade","E":1788331847457,"s":"BTCUSDT","t":6646633817,"p":"77581.15000000","q":"0.01071000","T":1788331847457,"m":false,"M":true}}
{"type":"trade","received_at_ms":1788331847317,"data":{"e":"trade","E":1788331847457,"s":"BTCUSDT","t":6646633818,"p":"77581.15000000","q":"0.00010000","T":1788331847457,"m":false,"M":true}}
{"type":"trade","received_at_ms":1788331847317,"data":{"e":"trade","E":1788331847457,"s":"BTCUSDT","t":6646633819,"p":"77581.15000000","q":"0.02142000","T":1788331847457,"m":false,"M":true}}
{"type":"depth","received_at_ms":1788331847374,"data":{"e":"depthUpdate","E":1788331847514,"s":"BTCUSDT","U":99555816265,"u":99555816350,"b":[["77581.14000000","3.70966000"],["77581.13000000","0.04292000"],["77579.68000000","0.13052000"],["77578.67000000","0.00000000"],["77578.44000000","0.01315000"],["77578.02000000","0.00658000"],["77578.00000000","0.03035000"],["77577.85000000","0.00000000"],["77576.87000000","0.00000000"],["77576.25000000","0.02000000"],["77575.40000000","0.00000000"],["77573.78000000","0.00644000"],["77573.58000000","0.02000000"],["77572.79000000","0.02000000"],["77569.07000000","0.00000000"],["77561.17000000","0.00007000"],["77521.28000000","0.00000000"],["77515.50000000","1.27774000"],["69823.03000000","0.00432000"],["69823.02000000","0.00009000"],["62064.92000000","0.00032000"]],"a":[["77581.15000000","1.30536000"],["77581.16000000","0.00069000"],["77581.42000000","0.11481000"],["77581.95000000","0.00007000"],["77582.40000000","0.01877000"],["77583.16000000","0.00014000"],["77583.17000000","0.00000000"],["77583.86000000","0.02928000"],["77583.87000000","0.01306000"],["77583.98000000","0.00027000"],["77584.09000000","0.11461000"],["77584.27000000","0.00000000"],["77585.56000000","0.11461000"],["77585.93000000","0.00014000"],["77587.03000000","0.11454000"],["77588.49000000","0.00000000"],["77588.50000000","0.11461000"],["77589.95000000","0.00644000"],["77592.30000000","0.00342000"],["77592.76000000","0.00200000"],["77592.91000000","0.00000000"],["77593.06000000","0.00000000"],["81001.06000000","0.00010000"]]}}
{"type":"depth","received_at_ms":1788331847474,"data":{"e":"depthUpdate","E":1788331847614,"s":"BTCUSDT","U":99555816351,"u":99555816404,"b":[["77581.14000000","3.70966000"],["77580.90000000","0.00354000"],["77575.78000000","0.00400000"],["77572.94000000","0.00200000"],["77560.09000000","0.00000000"],["77557.00000000","0.70000000"],["77554.00000000","0.03000000"],["76417.42000000","0.00030000"],["69823.03000000","0.00432000"],["62065.00000000","0.00400000"],["62064.92000000","0.00000000"]],"a":[["77581.15000000","1.30684000"],["77581.16000000","0.00069000"],["77581.41000000","0.00014000"],["77581.42000000","0.11495000"],["77582.40000000","0.01870000"],["77583.16000000","0.00000000"],["77584.88000000","0.02255000"],["77585.56000000","0.11447000"],["77585.93000000","0.00000000"],["77586.65000000","0.00400000"],["77588.53000000","0.71499000"],["77588.91000000","0.46912000"],["77589.29000000","0.00007000"],["77589.95000000","0.30644000"],["77589.96000000","0.30644000"],["77589.97000000","0.00000000"],["77589.99000000","0.00000000"],["77594.11000000","0.00000000"],["77619.40000000","0.00400000"],["77625.22000000","0.00000000"]]}}
{"type":"depth","received_at_ms":1788331847573,"data":{"e":"depthUpdate","E":1788331847714,"s":"BTCUSDT","U":99555816405,"u":99555816419,"b":[["77560.95000000","0.00000000"],["77549.39000000","0.00000000"],["77511.00000000","0.00000000"],["77479.99000000","0.00000000"],["69823.03000000","0.00432000"],["69823.00000000","0.00020000"]],"a":[["77581.15000000","1.30691000"],["77588.49000000","0.00200000"],["77592.76000000","0.00000000"],["77599.60000000","0.00000000"],["77616.24000000","0.00000000"],["77638.40000000","0.00000000"],["77669.44000000","0.00000000"]]}}
{"type":"trade","received_at_ms":1788331847574,"data":{"e":"trade","E":1788331847714,"s":"BTCUSDT","t":6646633820,"p":"77581.15000000","q":"0.00100000","T":1788331847714,"m":false,"M":true}}
{"type":"trade","received_at_ms":1788331847666,"data":{"e":"trade","E":1788331847806,"s":"BTCUSDT","t":6646633821,"p":"77581.15000000","q":"0.00013000","T":1788331847806,"m":false,"M":true}}
{"type":"depth","received_at_ms":1788331847675,"data":{"e":"depthUpdate","E":1788331847814,"s":"BTCUSDT","U":99555816420,"u":99555816430,"b":[["77541.63000000","1.33539000"],["69823.03000000","0.00432000"],["69823.02000000","0.00000000"],["69823.01000000","0.00009000"],["69823.00000000","0.00000000"]],"a":[["77581.15000000","1.30578000"]]}}
{"type":"trade","received_at_ms":1788331847741,"data":{"e":"trade","E":1788331847877,"s":"BTCUSDT","t":6646633822,"p":"77581.15000000","q":"0.00382000","T":1788331847877,"m":false,"M":true}}
{"type":"depth","received_at_ms":1788331847773,"data":{"e":"depthUpdate","E":1788331847914,"s":"BTCUSDT","U":99555816431,"u":99555816456,"b":[["77572.94000000","0.00000000"],["77569.40000000","0.00000000"],["77562.46000000","0.12892000"],["77561.86000000","0.00000000"],["77553.77000000","0.00412000"],["77373.13000000","0.00813000"],["77358.32000000","0.00000000"],["69823.03000000","0.00416000"],["62065.00000000","0.00400000"]],"a":[["77581.15000000","1.31128000"],["77581.41000000","0.00000000"],["77581.42000000","0.00014000"],["77583.86000000","0.02942000"],["77586.65000000","0.00000000"],["77587.28000000","0.00400000"],["77588.52000000","0.11447000"],["77592.90000000","0.00000000"]]}}
{"type":"trade","received_at_ms":1788331847829,"data":{"e":"trade","E":1788331847970,"s":"BTCUSDT","t":6646633823,"p":"77581.14000000","q":"0.00200000","T":1788331847970,"m":true,"M":true}}
{"type":"depth","received_at_ms":1788331847874,"data":{"e":"depthUpdate","E":1788331848014,"s":"BTCUSDT","U":99555816457,"u":99555816491,"b":[["77581.14000000","3.70766000"],["77568.97000000","0.00200000"],["77561.86000000","0.00007000"],["77383.19000000","0.00000000"],["77365.24000000","0.02019000"],["69823.03000000","0.00432000"],["69823.01000000","0.00000000"],["62064.92000000","0.00032000"],["62064.91000000","0.00000000"]],"a":[["77581.15000000","1.31107000"],["77581.16000000","0.00069000"],["77581.42000000","0.00000000"],["77582.40000000","0.01877000"],["77582.83000000","0.00014000"],["77582.84000000","0.32238000"],["77583.86000000","0.02928000"],["77584.87000000","0.00000000"],["77585.56000000","0.11461000"],["77587.03000000","0.11468000"],["77590.44000000","0.00000000"],["77592.90000000","0.00007000"],["77710.07000000","0.00000000"]]}}
{"type":"depth","received_at_ms":1788331847973,"data":{"e":"depthUpdate","E":1788331848114,"s":"BTCUSDT","U":99555816492,"u":99555816509,"b":[["77581.14000000","3.70427000"],["77580.90000000","0.00014000"],["77580.11000000","0.00339000"],["69823.03000000","0.00448000"]],"a":[["77582.40000000","0.01877000"],["77582.84000000","0.32252000"],["77584.27000000","0.00007000"],["77587.03000000","0.11454000"],["77589.34000000","0.00337000"],["77589.72000000","0.00336000"],["77603.99000000","0.00412000"]]}}
{"type":"depth","received_at_ms":1788331848074,"data":{"e":"depthUpdate","E":1788331848214,"s":"BTCUSDT","U":99555816510,"u":99555816520,"b":[["76882.91000000","0.00000000"],["69823.03000000","0.00432000"],["62064.92000000","0.00000000"]],"a":[["77589.29000000","0.00000000"],["77589.34000000","0.30337000"],["77589.72000000","0.30336000"],["77589.96000000","0.00644000"],["77590.01000000","0.12120000"],["77616.25000000","0.09568000"]]}}
{"type":"depth","received_at_ms":1788331848174,"data":{"e":"depthUpdate","E":1788331848314,"s":"BTCUSDT","U":99555816521,"u":99555816553,"b":[["77578.07000000","0.00475000"],["77575.78000000","0.00000000"],["77572.94000000","0.00000000"],["77569.40000000","0.00200000"],["77568.97000000","0.00000000"],["69823.03000000","0.00448000"],["62065.00000000","0.00400000"]],"a":[["77581.15000000","0.96625000"],["77581.16000000","0.00076000"],["77584.08000000","0.00000000"],["77584.09000000","0.00014000"],["77584.87000000","0.00007000"],["77584.88000000","0.02262000"],["77585.10000000","0.12916000"],["77587.28000000","0.00000000"],["77588.24000000","0.00000000"],["77588.94000000","0.00400000"],["77673.84000000","0.00412000"],["78744.87000000","0.00030000"]]}}
{"type":"trade","received_at_ms":1788331848217,"data":{"e":"trade","E":1788331848351,"s":"BTCUSDT","t":6646633824,"p":"77581.14000000","q":"0.00034000","T":1788331848351,"m":true,"M":true}}
{"type":"depth","received_at_ms":1788331848274,"data":{"e":"depthUpdate","E":1788331848414,"s":"BTCUSDT","U":99555816554,"u":99555816589,"b":[["77581.14000000","3.70393000"],["77581.10000000","0.05000000"],["77581.05000000","0.05000000"],["77577.80000000","0.00034000"],["77575.87000000","0.00257000"],["77572.94000000","0.00200000"],["77569.40000000","0.00000000"],["69823.03000000","0.00432000"],["69823.02000000","0.00009000"],["62065.00000000","0.00400000"],["62064.91000000","0.00000000"]],"a":[["77581.15000000","0.83201000"],["77583.87000000","0.01299000"],["77583.98000000","0.00000000"],["77584.09000000","0.00000000"],["77584.88000000","0.02262000"],["77585.10000000","0.12930000"],["77588.49000000","0.00000000"],["77592.81000000","0.00200000"]]}}
{"type":"trade","received_at_ms":1788331848353,"data":{"e":"trade","E":1788331848486,"s":"BTCUSDT","t":6646633825,"p":"77581.14000000","q":"0.00007000","T":1788331848486,"m":true,"M":true}}
{"type":"depth","received_at_ms":1788331848374,"data":{"e":"depthUpdate","E":1788331848514,"s":"BTCUSDT","U":99555816590,"u":99555816633,"b":[["77581.14000000","3.70386000"],["77581.13000000","0.04299000"],["77581.11000000","0.00014000"],["77581.10000000","0.05021000"],["77581.06000000","0.00014000"],["77581.05000000","0.05014000"],["77580.01000000","0.00007000"],["77580.00000000","0.03061000"],["77579.70000000","0.00000000"],["77578.44000000","0.01301000"],["77578.02000000","0.00644000"],["77575.87000000","0.00000000"],["77572.94000000","0.00000000"],["77569.81000000","0.00200000"],["77521.28000000","0.02000000"],["77483.97000000","0.00412000"],["69823.03000000","0.00448000"],["62064.92000000","0.00032000"]],"a":[["77581.15000000","0.83208000"],["77588.49000000","0.00000000"],["77588.94000000","0.00000000"],["77589.34000000","0.30000000"],["77589.44000000","0.00339000"],["77589.66000000","0.00400000"],["77589.95000000","0.30000000"],["77591.71000000","0.00644000"],["77592.54000000","0.00257000"],["77592.81000000","0.00000000"],["77592.89000000","0.00200000"]]}}
{"type":"depth","received_at_ms":1788331848473,"data":{"e":"depthUpdate","E":1788331848614,"s":"BTCUSDT","U":99555816634,"u":99555816653,"b":[["77579.88000000","0.00339000"],["77577.36000000","0.00008000"],["77576.04000000","0.00000000"],["77559.00000000","0.70117000"],["76417.42000000","0.00030000"],["69823.03000000","0.00432000"],["62065.00000000","0.00400000"],["62064.92000000","0.00000000"]],"a":[["77581.15000000","0.83208000"],["77588.49000000","0.00200000"],["77592.89000000","0.00000000"],["77681.85000000","1.29789000"],["77684.45000000","2.15391000"]]}}
{"type":"depth","received_at_ms":1788331848574,"data":{"e":"depthUpdate","E":1788331848714,"s":"BTCUSDT","U":99555816654,"u":99555816657,"b":[["77514.99000000","0.00412000"],["69823.03000000","0.00448000"]],"a":[]}}
{"type":"trade","received_at_ms":1788331848604,"data":{"e":"trade","E":1788331848744,"s":"BTCUSDT","t":6646633826,"p":"77581.14000000","q":"0.00100000","T":1788331848743,"m":true,"M":true}}
{"type":"depth","received_at_ms":1788331848674,"data":{"e":"depthUpdate","E":1788331848814,"s":"BTCUSDT","U":99555816658,"u":99555816662,"b":[["77581.14000000","3.70286000"],["69823.03000000","0.00432000"],["69823.02000000","0.00000000"],["69823.01000000","0.00009000"]],"a":[]}}
{"type":"depth","received_at_ms":1788331848774,"data":{"e":"depthUpdate","E":1788331848914,"s":"BTCUSDT","U":99555816663,"u":99555816667,"b":[["77542.78000000","0.54647000"],["69823.03000000","0.00448000"],["69823.00000000","0.00000000"]],"a":[["77631.90000000","0.52181000"]]}}
{"type":"depth","received_at_ms":1788331848876,"data":{"e":"depthUpdate","E":1788331849014,"s":"BTCUSDT","U":99555816668,"u":99555816684,"b":[["77561.86000000","0.00007000"],["77518.29000000","1.00891000"],["69823.03000000","0.00432000"],["62065.00000000","0.00400000"],["62064.92000000","0.00032000"],["62064.91000000","0.00000000"]],"a":[["77581.15000000","0.83208000"],["77581.16000000","0.00069000"],["77585.10000000","0.00014000"],["77586.09000000","0.00340000"],["77592.90000000","0.00007000"]]}}
{"type":"trade","received_at_ms":1788331848929,"data":{"e":"trade","E":1788331849068,"s":"BTCUSDT","t":6646633827,"p":"77581.15000000","q":"0.04100000","T":1788331849067,"m":false,"M":true}}
{"type":"depth","received_at_ms":1788331848977,"data":{"e":"depthUpdate","E":1788331849114,"s":"BTCUSDT","U":99555816685,"u":99555816706,"b":[["69823.03000000","0.00448000"],["69823.01000000","0.00000000"]],"a":[["77581.15000000","0.79101000"],["77584.88000000","0.02255000"],["77585.10000000","0.00000000"],["77587.03000000","0.11468000"],["77588.50000000","0.11454000"],["77588.53000000","0.00000000"],["77589.66000000","0.00000000"],["77589.68000000","0.00400000"],["77594.10000000","0.00000000"],["77595.34000000","0.00400000"]]}}
{"type":"depth","received_at_ms":1788331849073,"data":{"e":"depthUpdate","E":1788331849214,"s":"BTCUSDT","U":99555816707,"u":99555816727,"b":[["77569.81000000","0.00000000"],["77568.92000000","0.00200000"],["77454.84000000","0.00059000"],["76882.91000000","0.00010000"],["69823.03000000","0.00416000"],["62064.92000000","0.00000000"]],"a":[["77581.15000000","0.79868000"],["77586.09000000","0.00000000"],["77588.49000000","0.00200000"],["77588.50000000","0.11461000"],["77589.44000000","0.00000000"],["77592.81000000","0.00000000"]]}}
{"type":"trade","received_at_ms":1788331849138,"data":{"e":"trade","E":1788331849278,"s":"BTCUSDT","t":6646633828,"p":"77581.15000000","q":"0.00218000","T":1788331849277,"m":false,"M":true}}
{"type":"depth","received_at_ms":1788331849187,"data":{"e":"depthUpdate","E":1788331849314,"s":"BTCUSDT","U":99555816728,"u":99555816750,"b":[["77580.89000000","0.04021000"],["77580.63000000","0.00007000"],["77580.62000000","0.19572000"],["77579.68000000","0.00021000"],["77578.00000000","0.03042000"],["77577.81000000","0.00644000"],["77573.78000000","0.00000000"],["69823.03000000","0.00432000"]],"a":[["77581.15000000","0.79643000"],["77587.03000000","0.25501000"],["77588.49000000","0.00000000"],["77589.68000000","0.00000000"],["77590.34000000","0.00400000"],["77592.23000000","0.00200000"],["77616.25000000","0.00000000"],["77616.78000000","0.44634000"],["78744.87000000","0.00030000"]]}}
{"type":"trade","received_at_ms":1788331849227,"data":{"e":"trade","E":1788331849365,"s":"BTCUSDT","t":6646633829,"p":"77581.15000000","q":"0.00075000","T":1788331849365,"m":false,"M":true}}
{"type":"trade","received_at_ms":1788331849250,"data":{"e":"trade","E":1788331849390,"s":"BTCUSDT","t":6646633830,"p":"77581.15000000","q":"0.00168000","T":1788331849390,"m":false,"M":true}}
{"type":"depth","received_at_ms":1788331849273,"data":{"e":"depthUpdate","E":1788331849414,"s":"BTCUSDT","U":99555816751,"u":99555816782,"b":[["77580.89000000","0.04021000"],["77580.62000000","0.19586000"],["77579.69000000","0.07789000"],["77579.68000000","0.00007000"],["69823.03000000","0.00441000"],["62065.00000000","0.00400000"],["62064.91000000","0.00000000"]],"a":[["77581.15000000","0.79233000"],["77581.16000000","0.00076000"],["77583.87000000","0.01306000"],["77584.81000000","0.00275000"],["77584.85000000","0.01375000"],["77585.56000000","0.11468000"],["77585.71000000","0.00620000"]]}}
{"type":"trade","received_at_ms":1788331849321,"data":{"e":"trade","E":1788331849457,"s":"BTCUSDT","t":6646633831,"p":"77581.15000000","q":"0.00167000","T":1788331849456,"m":false,"M":true}}
{"type":"depth","received_at_ms":1788331849374,"data":{"e":"depthUpdate","E":1788331849514,"s":"BTCUSDT","U":99555816783,"u":99555816808,"b":[["77569.81000000","0.00200000"],["77568.92000000","0.00000000"],["69823.03000000","0.00425000"],["62065.00000000","0.00400000"],["62064.92000000","0.00032000"]],"a":[["77581.15000000","0.79066000"],["77583.87000000","0.01306000"],["77584.85000000","0.01389000"],["77585.56000000","0.11468000"],["77587.03000000","0.25487000"],["77589.72000000","0.30000000"],["77592.23000000","0.00000000"],["77592.76000000","0.00200000"],["77605.07000000","0.00335000"],["77607.35000000","0.00128000"]]}}
{"type":"trade","received_at_ms":1788331849438,"data":{"e":"trade","E":1788331849578,"s":"BTCUSDT","t":6646633832,"p":"77581.15000000","q":"0.00167000","T":1788331849577,"m":false,"M":true}}
{"type":"depth","received_at_ms":1788331849473,"data":{"e":"depthUpdate","E":1788331849614,"s":"BTCUSDT","U":99555816809,"u":99555816813,"b":[["77577.81000000","0.00901000"],["69823.03000000","0.00457000"],["62064.92000000","0.00000000"]],"a":[["77581.15000000","0.78899000"]]}}
{"type":"trade","received_at_ms":1788331849546,"data":{"e":"trade","E":1788331849686,"s":"BTCUSDT","t":6646633833,"p":"77581.15000000","q":"0.00217000","T":1788331849686,"m":false,"M":true}}
{"type":"depth","received_at_ms":1788331849580,"data":{"e":"depthUpdate","E":1788331849714,"s":"BTCUSDT","U":99555816814,"u":99555816824,"b":[["77577.81000000","0.00644000"],["77577.80000000","0.00291000"],["77569.81000000","0.00000000"],["77569.35000000","0.00200000"],["76417.42000000","0.00030000"],["69823.03000000","0.00432000"],["69823.02000000","0.00009000"]],"a":[["77581.15000000","0.78682000"]]}}
{"type":"trade","received_at_ms":1788331849638,"data":{"e":"trade","E":1788331849775,"s":"BTCUSDT","t":6646633834,"p":"77581.15000000","q":"0.00167000","T":1788331849774,"m":false,"M":true}}
{"type":"depth","received_at_ms":1788331849682,"data":{"e":"depthUpdate","E":1788331849814,"s":"BTCUSDT","U":99555816825,"u":99555816837,"b":[["77308.30000000","0.00013000"],["69823.03000000","0.00448000"]],"a":[["77581.15000000","0.78522000"],["77581.16000000","0.00083000"],["77583.87000000","0.01313000"],["77584.23000000","0.00007000"],["77584.24000000","0.08219000"],["77584.87000000","0.00000000"],["77592.54000000","0.00000000"],["77592.56000000","0.00257000"]]}}
{"type":"trade","received_at_ms":1788331849751,"data":{"e":"trade","E":1788331849890,"s":"BTCUSDT","t":6646633835,"p":"77581.15000000","q":"0.00702000","T":1788331849889,"m":false,"M":true}}
{"type":"depth","received_at_ms":1788331849773,"data":{"e":"depthUpdate","E":1788331849914,"s":"BTCUSDT","U":99555816838,"u":99555816865,"b":[["77581.14000000","3.70738000"],["77580.02000000","0.00000000"],["77578.07000000","0.00075000"],["69823.03000000","0.00432000"]],"a":[["77581.15000000","0.43922000"],["77581.16000000","0.00076000"],["77583.87000000","0.01313000"],["77584.24000000","0.08233000"],["77585.56000000","0.00007000"],["77587.03000000","0.11454000"],["77588.91000000","0.46912000"],["77590.34000000","0.00000000"],["77591.71000000","0.00000000"],["77592.04000000","0.00400000"],["77593.53000000","0.00644000"],["77596.27000000","0.79381000"],["77597.01000000","0.00000000"]]}}
{"type":"trade","received_at_ms":1788331849829,"data":{"e":"trade","E":1788331849968,"s":"BTCUSDT","t":6646633836,"p":"77581.15000000","q":"0.00334000","T":1788331849968,"m":false,"M":true}}
{"type":"trade","received_at_ms":1788331849853,"data":{"e":"trade","E":1788331849992,"s":"BTCUSDT","t":6646633837,"p":"77581.15000000","q":"0.00217000","T":1788331849991,"m":false,"M":true}}
{"type":"depth","received_at_ms":1788331849874,"data":{"e":"depthUpdate","E":1788331850014,"s":"BTCUSDT","U":99555816866,"u":99555816897,"b":[["77581.14000000","3.70338000"],["77580.47000000","0.00400000"],["77561.86000000","0.00007000"],["77508.35000000","1.61644000"],["77500.58000000","0.00000000"],["69823.03000000","0.00448000"],["69823.02000000","0.00000000"],["69823.00000000","0.00000000"],["62064.92000000","0.00032000"]],"a":[["77581.15000000","0.43302000"],["77581.24000000","0.00007000"],["77584.88000000","0.02255000"],["77585.56000000","0.11454000"],["77589.88000000","0.00000000"],["77590.43000000","0.00326000"],["77592.90000000","0.00007000"],["77681.85000000","0.75095000"],["77684.45000000","0.00000000"]]}}
{"type":"depth","received_at_ms":1788331849973,"data":{"e":"depthUpdate","E":1788331850114,"s":"BTCUSDT","U":99555816898,"u":99555816920,"b":[["77580.47000000","0.00000000"],["77579.69000000","0.08189000"],["77553.77000000","0.00000000"],["77514.99000000","0.00000000"],["77483.97000000","0.00000000"],["77461.32000000","0.00000000"],["69823.03000000","0.00432000"],["62064.91000000","0.00000000"]],"a":[["77581.15000000","0.56223000"],["77584.88000000","0.02255000"],["77587.28000000","0.13207000"],["77603.99000000","0.00000000"],["77642.80000000","0.00412000"],["77673.84000000","0.00000000"]]}}
{"type":"depth","received_at_ms":1788331850076,"data":{"e":"depthUpdate","E":1788331850215,"s":"BTCUSDT","U":99555816921,"u":99555816930,"b":[["77573.51000000","0.33003000"],["77560.01000000","1.28059000"],["69823.03000000","0.00448000"],["62064.92000000","0.00000000"]],"a":[["77581.15000000","0.75425000"],["77584.73000000","0.00208000"],["77592.56000000","0.00000000"]]}}
{"type":"trade","received_at_ms":1788331850153,"data":{"e":"trade","E":1788331850292,"s":"BTCUSDT","t":6646633838,"p":"77581.15000000","q":"0.00257000","T":1788331850292,"m":false,"M":true}}
{"type":"depth","received_at_ms":1788331850178,"data":{"e":"depthUpdate","E":1788331850314,"s":"BTCUSDT","U":99555816931,"u":99555816949,"b":[["77578.53000000","0.00400000"],["77572.94000000","0.00400000"],["69823.03000000","0.00441000"],["62065.00000000","0.00400000"]],"a":[["77581.15000000","0.75175000"],["77581.16000000","0.00083000"],["77589.40000000","0.00400000"],["77593.06000000","0.00257000"],["77595.61000000","0.00400000"],["77603.98000000","0.00412000"],["78744.87000000","0.00030000"]]}}
{"type":"depth","received_at_ms":1788331850274,"data":{"e":"depthUpdate","E":1788331850414,"s":"BTCUSDT","U":99555816950,"u":99555816964,"b":[["77572.94000000","0.01000000"],["77571.77000000","0.06758000"],["77569.35000000","0.00000000"],["77557.00000000","0.00000000"],["69823.03000000","0.00457000"],["62064.91000000","0.00000000"]],"a":[["77589.40000000","0.30400000"],["77589.95000000","0.00000000"],["77592.76000000","0.00000000"],["77593.53000000","0.00844000"],["77595.61000000","0.00800000"]]}}
{"type":"depth","received_at_ms":1788331850374,"data":{"e":"depthUpdate","E":1788331850515,"s":"BTCUSDT","U":99555816965,"u":99555816969,"b":[["77561.00000000","0.70515000"],["77559.00000000","0.00117000"],["77514.98000000","0.00412000"],["69823.03000000","0.00441000"],["62064.92000000","0.00032000"]],"a":[]}}
{"type":"depth","received_at_ms":1788331850474,"data":{"e":"depthUpdate","E":1788331850614,"s":"BTCUSDT","U":99555816970,"u":99555816980,"b":[["77572.94000000","0.00800000"],["77569.81000000","0.00200000"],["69823.03000000","0.00441000"],["62065.00000000","0.00400000"],["62064.92000000","0.00000000"]],"a":[]}}
{"type":"depth","received_at_ms":1788331850573,"data":{"e":"depthUpdate","E":1788331850714,"s":"BTCUSDT","U":99555816981,"u":99555816987,"b":[["77581.14000000","3.70681000"],["77483.96000000","0.00412000"],["77186.16000000","0.00013000"],["76417.42000000","0.00030000"],["69823.03000000","0.00441000"]],"a":[]}}
{"type":"trade","received_at_ms":1788331850646,"data":{"e":"trade","E":1788331850787,"s":"BTCUSDT","t":6646633839,"p":"77581.14000000","q":"0.00382000","T":1788331850786,"m":true,"M":true}}
{"type":"depth","received_at_ms":1788331850674,"data":{"e":"depthUpdate","E":1788331850814,"s":"BTCUSDT","U":99555816988,"u":99555816991,"b":[["77581.14000000","3.70299000"],["69823.03000000","0.00432000"],["69823.02000000","0.00009000"]],"a":[]}}
{"type":"depth","received_at_ms":1788331850773,"data":{"e":"depthUpdate","E":1788331850914,"s":"BTCUSDT","U":99555816992,"u":99555816995,"b":[["69823.03000000","0.00432000"],["62065.00000000","0.00400000"]],"a":[]}}
{"type":"depth","received_at_ms":1788331850874,"data":{"e":"depthUpdate","E":1788331851014,"s":"BTCUSDT","U":99555816996,"u":99555817001,"b":[["77561.86000000","0.00000000"],["69823.03000000","0.00432000"],["62064.92000000","0.00032000"]],"a":[["77592.90000000","0.00000000"]]}}
{"type":"depth","received_at_ms":1788331850974,"data":{"e":"depthUpdate","E":1788331851114,"s":"BTCUSDT","U":99555817002,"u":99555817012,"b":[["77561.86000000","0.00007000"],["77553.76000000","0.00412000"],["77493.61000000","0.00200000"],["76500.00000000","28.71816000"],["69823.03000000","0.00432000"],["69823.00000000","0.00000000"],["62064.91000000","0.00000000"]],"a":[["77592.90000000","0.00007000"]]}}
{"type":"depth","received_at_ms":1788331851073,"data":{"e":"depthUpdate","E":1788331851214,"s":"BTCUSDT","U":99555817013,"u":99555817015,"b":[["69823.03000000","0.00432000"],["62064.92000000","0.00000000"]],"a":[]}}
{"type":"depth","received_at_ms":1788331851174,"data":{"e":"depthUpdate","E":1788331851314,"s":"BTCUSDT","U":99555817016,"u":99555817031,"b":[["77553.76000000","0.00000000"],["77514.98000000","0.00000000"],["77483.96000000","0.00000000"],["69823.03000000","0.00448000"]],"a":[["77581.15000000","0.75175000"],["77586.24000000","0.11965000"],["77587.28000000","0.00000000"],["77603.98000000","0.00000000"],["77642.80000000","0.00000000"],["77673.83000000","0.00412000"],["77732.91000000","0.00000000"],["78744.87000000","0.00030000"]]}}
{"type":"trade","received_at_ms":1788331851184,"data":{"e":"trade","E":1788331851324,"s":"BTCUSDT","t":6646633840,"p":"77581.15000000","q":"0.00100000","T":1788331851323,"m":false,"M":true}}
{"type":"depth","received_at_ms":1788331851274,"data":{"e":"depthUpdate","E":1788331851414,"s":"BTCUSDT","U":99555817032,"u":99555817041,"b":[["77581.14000000","3.70306000"],["77581.13000000","0.04306000"],["69823.03000000","0.00416000"],["69823.02000000","0.00000000"],["62065.00000000","0.00400000"],["62064.91000000","0.00000000"]],"a":[["77581.15000000","0.75075000"]]}}
{"type":"depth","received_at_ms":1788331851374,"data":{"e":"depthUpdate","E":1788331851514,"s":"BTCUSDT","U":99555817042,"u":99555817052,"b":[["77579.13000000","0.00257000"],["77577.80000000","0.00034000"],["77571.77000000","0.00000000"],["77553.71000000","0.13306000"],["71374.65000000","0.00015000"],["69823.03000000","0.00448000"],["62064.92000000","0.00032000"]],"a":[["77586.48000000","0.00007000"],["77593.06000000","0.00000000"],["77594.64000000","0.00257000"]]}}
{"type":"trade","received_at_ms":1788331851433,"data":{"e":"trade","E":1788331851573,"s":"BTCUSDT","t":6646633841,"p":"77581.15000000","q":"0.05675000","T":1788331851573,"m":false,"M":true}}
{"type":"depth","received_at_ms":1788331851474,"data":{"e":"depthUpdate","E":1788331851614,"s":"BTCUSDT","U":99555817053,"u":99555817058,"b":[["69823.03000000","0.00432000"],["62065.00000000","0.00600000"],["62064.92000000","0.00000000"]],"a":[["77581.15000000","0.69400000"]]}}
{"type":"depth","received_at_ms":1788331851574,"data":{"e":"depthUpdate","E":1788331851714,"s":"BTCUSDT","U":99555817059,"u":99555817076,"b":[["77580.90000000","0.00000000"],["77580.89000000","0.00021000"],["77580.63000000","0.00014000"],["77579.13000000","0.00000000"],["77578.30000000","0.00257000"],["77514.93000000","0.00412000"],["76417.42000000","0.00030000"],["69823.03000000","0.00448000"],["62065.00000000","0.00400000"]],"a":[["77586.48000000","0.00014000"],["77593.81000000","0.00257000"],["77594.64000000","0.00000000"],["77681.85000000","1.29789000"],["77684.45000000","2.15391000"]]}}
{"type":"depth","received_at_ms":1788331851679,"data":{"e":"depthUpdate","E":1788331851814,"s":"BTCUSDT","U":99555817077,"u":99555817089,"b":[["77581.14000000","3.70320000"],["77581.13000000","0.04313000"],["77581.05000000","0.05014000"],["77580.89000000","0.00007000"],["77578.44000000","0.01315000"],["77196.21000000","0.00013000"],["69823.03000000","0.00432000"]],"a":[]}}
{"type":"depth","received_at_ms":1788331851774,"data":{"e":"depthUpdate","E":1788331851914,"s":"BTCUSDT","U":99555817090,"u":99555817094,"b":[["77257.95000000","0.00000000"],["69823.03000000","0.00448000"]],"a":[["77603.98000000","0.00412000"]]}}
{"type":"depth","received_at_ms":1788331851874,"data":{"e":"depthUpdate","E":1788331852014,"s":"BTCUSDT","U":99555817095,"u":99555817105,"b":[["77266.02000000","0.00033000"],["71374.65000000","0.00000000"],["69823.03000000","0.00448000"],["62065.00000000","0.00400000"],["62064.92000000","0.00032000"]],"a":[]}}
{"type":"depth","received_at_ms":1788331851976,"data":{"e":"depthUpdate","E":1788331852114,"s":"BTCUSDT","U":99555817106,"u":99555817115,"b":[["77581.14000000","3.70306000"],["77581.13000000","0.04306000"],["77561.86000000","0.00007000"],["69823.03000000","0.00448000"],["62064.91000000","0.00000000"]],"a":[["77592.90000000","0.00007000"]]}}
{"type":"depth","received_at_ms":1788331852073,"data":{"e":"depthUpdate","E":1788331852214,"s":"BTCUSDT","U":99555817116,"u":99555817123,"b":[["77514.01000000","1.05470000"],["77510.94000000","1.61644000"],["77508.35000000","0.00000000"],["69823.03000000","0.00448000"],["69823.00000000","0.00000000"],["62064.92000000","0.00000000"]],"a":[]}}
{"type":"depth","received_at_ms":1788331852173,"data":{"e":"depthUpdate","E":1788331852314,"s":"BTCUSDT","U":99555817124,"u":99555817141,"b":[["77581.14000000","3.70299000"],["77581.13000000","0.04299000"],["77483.91000000","0.00412000"],["75557.06000000","0.00000000"],["69823.03000000","0.00448000"],["62065.00000000","0.00400000"]],"a":[["78744.87000000","0.00030000"],["81001.06000000","0.00000000"]]}}
{"type":"trade","received_at_ms":1788331852223,"data":{"e":"trade","E":1788331852355,"s":"BTCUSDT","t":6646633842,"p":"77581.14000000","q":"0.00100000","T":1788331852355,"m":true,"M":true}}
{"type":"depth","received_at_ms":1788331852273,"data":{"e":"depthUpdate","E":1788331852414,"s":"BTCUSDT","U":99555817142,"u":99555817162,"b":[["77581.14000000","3.70234000"],["77581.13000000","0.04320000"],["77561.00000000","0.00515000"],["77514.01000000","0.61945000"],["77510.94000000","0.00000000"],["69823.02000000","0.00009000"]],"a":[["77581.15000000","0.69407000"],["77581.16000000","0.00076000"],["77584.81000000","0.00000000"],["77584.85000000","0.00014000"],["77585.60000000","0.00291000"],["77585.64000000","0.01455000"]]}}
{"type":"trade","received_at_ms":1788331852291,"data":{"e":"trade","E":1788331852428,"s":"BTCUSDT","t":6646633843,"p":"77581.14000000","q":"0.00257000","T":1788331852427,"m":true,"M":true}}
{"type":"depth","received_at_ms":1788331852373,"data":{"e":"depthUpdate","E":1788331852514,"s":"BTCUSDT","U":99555817163,"u":99555817184,"b":[["77581.14000000","3.69977000"],["77572.94000000","0.01000000"],["77569.81000000","0.00000000"],["69823.03000000","0.00448000"],["62065.00000000","0.00400000"],["62064.92000000","0.00032000"],["62064.91000000","0.00000000"]],"a":[["77584.24000000","0.08233000"],["77584.85000000","0.00000000"],["77585.56000000","0.11468000"],["77590.03000000","0.00400000"],["77592.04000000","0.00000000"]]}}
{"type":"depth","received_at_ms":1788331852473,"data":{"e":"depthUpdate","E":1788331852614,"s":"BTCUSDT","U":99555817185,"u":99555817190,"b":[["77572.94000000","0.00800000"],["77569.81000000","0.00200000"],["69823.03000000","0.00464000"],["62064.92000000","0.00000000"]],"a":[]}}
{"type":"trade","received_at_ms":1788331852498,"data":{"e":"trade","E":1788331852639,"s":"BTCUSDT","t":6646633844,"p":"77581.15000000","q":"0.00051000","T":1788331852639,"m":false,"M":true}}
{"type":"depth","received_at_ms":1788331852574,"data":{"e":"depthUpdate","E":1788331852714,"s":"BTCUSDT","U":99555817191,"u":99555817212,"b":[["77553.71000000","0.12894000"],["77514.93000000","0.00000000"],["77483.91000000","0.00000000"],["77206.25000000","0.00013000"],["76417.42000000","0.00030000"],["69823.03000000","0.00432000"],["69823.02000000","0.00000000"],["69823.01000000","0.00009000"],["62065.00000000","0.00400000"]],"a":[["77581.15000000","0.69356000"],["77583.87000000","0.01306000"],["77585.56000000","0.11475000"],["77603.98000000","0.00000000"],["77642.79000000","0.00412000"],["77673.83000000","0.00000000"],["78597.98000000","0.00000000"]]}}
{"type":"depth","received_at_ms":1788331852674,"data":{"e":"depthUpdate","E":1788331852814,"s":"BTCUSDT","U":99555817213,"u":99555817231,"b":[["77579.75000000","0.00257000"],["77578.30000000","0.00000000"],["69823.03000000","0.00464000"]],"a":[["77581.15000000","0.69342000"],["77581.16000000","0.00069000"],["77584.23000000","0.00000000"],["77584.24000000","0.00014000"],["77584.73000000","0.00000000"],["77584.87000000","0.00007000"],["77586.48000000","0.00007000"],["77593.81000000","0.00000000"],["77595.26000000","0.00257000"],["77625.88000000","0.00007000"],["79449.80000000","0.00000000"]]}}
{"type":"depth","received_at_ms":1788331852774,"data":{"e":"depthUpdate","E":1788331852914,"s":"BTCUSDT","U":99555817232,"u":99555817245,"b":[["69823.03000000","0.00448000"]],"a":[["77583.87000000","0.01299000"],["77584.24000000","0.00000000"],["77585.64000000","0.01469000"],["77763.23000000","0.00000000"]]}}
{"type":"depth","received_at_ms":1788331852873,"data":{"e":"depthUpdate","E":1788331853014,"s":"BTCUSDT","U":99555817246,"u":99555817249,"b":[["69823.03000000","0.00448000"],["62064.92000000","0.00032000"]],"a":[["77736.32000000","0.01000000"]]}}
{"type":"depth","received_at_ms":1788331852974,"data":{"e":"depthUpdate","E":1788331853114,"s":"BTCUSDT","U":99555817250,"u":99555817260,"b":[["77561.86000000","0.00007000"],["77560.00000000","2.66491000"],["77508.35000000","1.61644000"],["77445.42000000","0.00020000"],["69823.03000000","0.00448000"],["62064.91000000","0.00000000"]],"a":[["77592.90000000","0.00007000"],["77716.96000000","0.00020000"]]}}
{"type":"depth","received_at_ms":1788331853084,"data":{"e":"depthUpdate","E":1788331853214,"s":"BTCUSDT","U":99555817261,"u":99555817268,"b":[["75557.06000000","0.00010000"],["69823.03000000","0.00464000"],["62064.92000000","0.00000000"]],"a":[["77736.32000000","0.02000000"],["77798.04000000","0.00256000"],["77875.36000000","0.00000000"]]}}
{"type":"trade","received_at_ms":1788331853166,"data":{"e":"trade","E":1788331853302,"s":"BTCUSDT","t":6646633845,"p":"77581.15000000","q":"0.00387000","T":1788331853301,"m":false,"M":true}}
{"type":"depth","received_at_ms":1788331853177,"data":{"e":"depthUpdate","E":1788331853314,"s":"BTCUSDT","U":99555817269,"u":99555817287,"b":[["77572.94000000","0.01000000"],["77569.81000000","0.00000000"],["69823.03000000","0.00448000"],["69823.01000000","0.00000000"],["69823.00000000","0.00000000"]],"a":[["77581.15000000","0.68962000"],["77585.71000000","0.00627000"],["77586.47000000","0.00208000"],["77586.48000000","0.08226000"],["77603.98000000","0.00412000"],["77677.04000000","0.00087000"],["77687.56000000","0.00515000"],["78744.87000000","0.00030000"]]}}
{"type":"depth","received_at_ms":1788331853275,"data":{"e":"depthUpdate","E":1788331853414,"s":"BTCUSDT","U":99555817288,"u":99555817297,"b":[["77581.14000000","3.69949000"],["77581.13000000","0.04299000"],["69823.03000000","0.00464000"]],"a":[["77677.04000000","0.00000000"],["81001.06000000","0.00010000"]]}}
{"type":"depth","received_at_ms":1788331853378,"data":{"e":"depthUpdate","E":1788331853514,"s":"BTCUSDT","U":99555817298,"u":99555817305,"b":[["77572.94000000","0.00800000"],["77569.81000000","0.00200000"],["69823.03000000","0.00448000"],["62064.92000000","0.00032000"],["62064.91000000","0.00000000"]],"a":[]}}
{"type":"trade","received_at_ms":1788331853434,"data":{"e":"trade","E":1788331853567,"s":"BTCUSDT","t":6646633846,"p":"77581.15000000","q":"0.00382000","T":1788331853567,"m":false,"M":true}}
{"type":"depth","received_at_ms":1788331853475,"data":{"e":"depthUpdate","E":1788331853614,"s":"BTCUSDT","U":99555817306,"u":99555817324,"b":[["77572.94000000","0.00800000"],["77569.81000000","0.00000000"],["69823.03000000","0.00457000"],["62065.00000000","0.00400000"],["62064.92000000","0.00000000"]],"a":[["77581.15000000","0.68580000"],["77597.07000000","0.71994000"]]}}
{"type":"depth","received_at_ms":1788331853574,"data":{"e":"depthUpdate","E":1788331853714,"s":"BTCUSDT","U":99555817325,"u":99555817337,"b":[["77581.14000000","3.70206000"],["77579.75000000","0.00000000"],["77569.35000000","0.00200000"],["77483.92000000","0.00412000"],["76486.08000000","0.00061000"],["76417.42000000","0.00030000"]],"a":[["77581.15000000","0.68573000"],["77586.47000000","0.00000000"],["77586.48000000","0.00007000"],["77595.26000000","0.00000000"],["77596.66000000","0.02865000"]]}}
{"type":"depth","received_at_ms":1788331853677,"data":{"e":"depthUpdate","E":1788331853814,"s":"BTCUSDT","U":99555817338,"u":99555817351,"b":[["69823.03000000","0.00457000"]],"a":[["77581.15000000","0.55712000"],["77586.24000000","0.00000000"],["77590.03000000","0.00000000"],["77590.66000000","0.00400000"],["77596.64000000","0.00257000"],["77596.66000000","0.02608000"]]}}
{"type":"depth","received_at_ms":1788331853774,"data":{"e":"depthUpdate","E":1788331853914,"s":"BTCUSDT","U":99555817352,"u":99555817360,"b":[["77553.72000000","0.00412000"],["77513.53000000","1.61644000"],["77508.35000000","0.00000000"],["69823.03000000","0.00457000"]],"a":[["77581.15000000","0.55705000"],["77585.71000000","0.00620000"],["77596.60000000","0.00257000"],["77596.64000000","0.00000000"]]}}
{"type":"depth","received_at_ms":1788331853880,"data":{"e":"depthUpdate","E":1788331854014,"s":"BTCUSDT","U":99555817361,"u":99555817365,"b":[["69823.03000000","0.00457000"],["62064.92000000","0.00032000"]],"a":[["77596.57000000","0.00257000"],["77596.60000000","0.00000000"]]}}
{"type":"depth","received_at_ms":1788331853975,"data":{"e":"depthUpdate","E":1788331854114,"s":"BTCUSDT","U":99555817366,"u":99555817375,"b":[["77561.86000000","0.00000000"],["77514.94000000","0.03622000"],["77514.01000000","1.05470000"],["69823.03000000","0.00473000"],["62064.91000000","0.00000000"]],"a":[["77592.90000000","0.00000000"],["77596.53000000","0.00257000"],["77596.57000000","0.00000000"]]}}
{"type":"depth","received_at_ms":1788331854075,"data":{"e":"depthUpdate","E":1788331854214,"s":"BTCUSDT","U":99555817376,"u":99555817383,"b":[["77561.86000000","0.00007000"],["69823.03000000","0.00457000"],["62064.92000000","0.00000000"]],"a":[["77592.90000000","0.00007000"],["77596.48000000","0.00257000"],["77596.53000000","0.00000000"]]}}
{"type":"depth","received_at_ms":1788331854173,"data":{"e":"depthUpdate","E":1788331854314,"s":"BTCUSDT","U":99555817384,"u":99555817393,"b":[["69823.03000000","0.00457000"],["62065.00000000","0.00400000"]],"a":[["77596.44000000","0.00257000"],["77596.48000000","0.00000000"],["78744.87000000","0.00030000"]]}}
{"type":"depth","received_at_ms":1788331854275,"data":{"e":"depthUpdate","E":1788331854414,"s":"BTCUSDT","U":99555817394,"u":99555817401,"b":[["77561.00000000","0.70515000"],["69823.03000000","0.00457000"],["69823.00000000","0.00020000"],["62065.00000000","0.00400000"]],"a":[["77596.39000000","0.00257000"],["77596.44000000","0.00000000"]]}}
{"type":"depth","received_at_ms":1788331854375,"data":{"e":"depthUpdate","E":1788331854514,"s":"BTCUSDT","U":99555817402,"u":99555817410,"b":[["69823.03000000","0.00473000"],["69823.00000000","0.00000000"],["62064.92000000","0.00032000"],["62064.91000000","0.00000000"]],"a":[["77596.34000000","0.00257000"],["77596.39000000","0.00000000"]]}}
{"type":"depth","received_at_ms":1788331854474,"data":{"e":"depthUpdate","E":1788331854614,"s":"BTCUSDT","U":99555817411,"u":99555817431,"b":[["69823.03000000","0.00441000"],["62065.00000000","0.00600000"],["62064.92000000","0.00000000"]],"a":[["77581.15000000","0.70664000"],["77585.60000000","0.00000000"],["77585.64000000","0.00014000"],["77585.71000000","0.00627000"],["77586.38000000","0.00291000"],["77586.42000000","0.01455000"],["77587.57000000","0.11145000"],["77596.30000000","0.00257000"],["77596.34000000","0.00000000"]]}}
{"type":"depth","received_at_ms":1788331854576,"data":{"e":"depthUpdate","E":1788331854714,"s":"BTCUSDT","U":99555817432,"u":99555817458,"b":[["77581.14000000","3.70234000"],["77581.13000000","0.04320000"],["77560.00000000","1.96491000"],["76417.42000000","0.00030000"],["69823.03000000","0.00473000"],["62065.00000000","0.00400000"]],"a":[["77585.56000000","0.11468000"],["77585.64000000","0.00000000"],["77585.71000000","0.00641000"],["77586.63000000","0.12545000"],["77587.03000000","0.11461000"],["77587.57000000","0.00000000"],["77596.25000000","0.10682000"],["77596.30000000","0.00000000"]]}}
{"type":"depth","received_at_ms":1788331854674,"data":{"e":"depthUpdate","E":1788331854814,"s":"BTCUSDT","U":99555817459,"u":99555817466,"b":[["69823.03000000","0.00457000"]],"a":[["77581.15000000","0.70664000"],["77587.03000000","0.11454000"],["77596.21000000","0.00257000"],["77596.25000000","0.10425000"]]}}
{"type":"depth","received_at_ms":1788331854774,"data":{"e":"depthUpdate","E":1788331854914,"s":"BTCUSDT","U":99555817467,"u":99555817470,"b":[["69823.03000000","0.00457000"]],"a":[["77596.16000000","0.00257000"],["77596.21000000","0.00000000"]]}}
{"type":"trade","received_at_ms":1788331854793,"data":{"e":"trade","E":1788331854931,"s":"BTCUSDT","t":6646633847,"p":"77581.15000000","q":"0.00100000","T":1788331854931,"m":false,"M":true}}
{"type":"trade","received_at_ms":1788331854800,"data":{"e":"trade","E":1788331854941,"s":"BTCUSDT","t":6646633848,"p":"77581.15000000","q":"0.04100000","T":1788331854940,"m":false,"M":true}}
{"type":"trade","received_at_ms":1788331854851,"data":{"e":"trade","E":1788331854991,"s":"BTCUSDT","t":6646633849,"p":"77581.15000000","q":"0.00674000","T":1788331854991,"m":false,"M":true}}
{"type":"depth","received_at_ms":1788331854874,"data":{"e":"depthUpdate","E":1788331855014,"s":"BTCUSDT","U":99555817471,"u":99555817484,"b":[["69823.03000000","0.00448000"],["69823.02000000","0.00009000"],["62065.00000000","0.00400000"],["62064.92000000","0.00032000"]],"a":[["77581.15000000","0.65790000"],["77586.42000000","0.01462000"],["77596.12000000","0.00657000"],["77596.16000000","0.00000000"],["77656.18000000","0.25784000"],["77665.06000000","0.00000000"]]}}
{"type":"depth","received_at_ms":1788331854974,"data":{"e":"depthUpdate","E":1788331855114,"s":"BTCUSDT","U":99555817485,"u":99555817509,"b":[["77553.72000000","0.00000000"],["77514.94000000","0.03210000"],["77483.92000000","0.00000000"],["76255.93000000","0.00022000"],["69823.03000000","0.00448000"],["62064.91000000","0.00000000"]],"a":[["77581.15000000","0.65790000"],["77585.74000000","0.14243000"],["77586.42000000","0.01455000"],["77586.63000000","0.00000000"],["77588.50000000","0.11669000"],["77588.59000000","0.08219000"],["77596.12000000","0.00400000"],["77596.24000000","0.00257000"],["77596.29000000","0.00000000"],["77603.98000000","0.00000000"],["77642.79000000","0.00000000"],["77673.83000000","0.00412000"]]}}
{"type":"depth","received_at_ms":1788331855074,"data":{"e":"depthUpdate","E":1788331855214,"s":"BTCUSDT","U":99555817510,"u":99555817519,"b":[["77561.86000000","0.00007000"],["69823.03000000","0.00448000"],["62064.92000000","0.00000000"]],"a":[["77585.71000000","0.00641000"],["77592.90000000","0.00007000"]]}}
{"type":"depth","received_at_ms":1788331855174,"data":{"e":"depthUpdate","E":1788331855314,"s":"BTCUSDT","U":99555817520,"u":99555817526,"b":[["69823.03000000","0.00448000"]],"a":[["77596.16000000","0.00257000"],["77596.24000000","0.00000000"],["77604.12000000","0.00412000"],["78744.87000000","0.00030000"]]}}
{"type":"depth","received_at_ms":1788331855276,"data":{"e":"depthUpdate","E":1788331855414,"s":"BTCUSDT","U":99555817527,"u":99555817532,"b":[["69823.03000000","0.00432000"]],"a":[["77590.26000000","0.00332000"],["77596.12000000","0.00657000"],["77596.16000000","0.00000000"]]}}
{"type":"trade","received_at_ms":1788331855314,"data":{"e":"trade","E":1788331855454,"s":"BTCUSDT","t":6646633850,"p":"77581.14000000","q":"0.01726000","T":1788331855454,"m":true,"M":true}}
{"type":"depth","received_at_ms":1788331855375,"data":{"e":"depthUpdate","E":1788331855514,"s":"BTCUSDT","U":99555817533,"u":99555817558,"b":[["77581.14000000","3.68844000"],["77581.13000000","0.04313000"],["77553.85000000","0.08187000"],["69823.03000000","0.00432000"],["69823.02000000","0.00000000"],["69823.00000000","0.00020000"],["62065.00000000","0.00600000"],["62064.92000000","0.00032000"],["62064.91000000","0.00000000"]],"a":[["77585.71000000","0.00648000"],["77596.07000000","0.00257000"],["77596.12000000","0.00400000"]]}}
{"type":"depth","received_at_ms":1788331855478,"data":{"e":"depthUpdate","E":1788331855614,"s":"BTCUSDT","U":99555817559,"u":99555817564,"b":[["77567.30000000","0.00000000"],["77542.42000000","0.00000000"],["77523.01000000","0.00000000"],["69823.03000000","0.00448000"],["69823.00000000","0.00000000"],["62064.92000000","0.00000000"]],"a":[["77593.54000000","0.02600000"],["77596.03000000","0.00257000"],["77596.07000000","0.00000000"],["77625.08000000","0.00000000"],["77644.48000000","0.00000000"]]}}
{"type":"depth","received_at_ms":1788331855573,"data":{"e":"depthUpdate","E":1788331855714,"s":"BTCUSDT","U":99555817565,"u":99555817573,"b":[["77581.14000000","3.68851000"],["77581.13000000","0.04320000"],["76417.42000000","0.00030000"],["69823.03000000","0.00432000"]],"a":[["77595.99000000","0.00257000"],["77596.03000000","0.00000000"]]}}
{"type":"depth","received_at_ms":1788331855673,"data":{"e":"depthUpdate","E":1788331855814,"s":"BTCUSDT","U":99555817574,"u":99555817579,"b":[["77216.29000000","0.00013000"],["69823.03000000","0.00448000"]],"a":[["77595.94000000","0.00257000"],["77595.99000000","0.00000000"]]}}
{"type":"depth","received_at_ms":1788331855773,"data":{"e":"depthUpdate","E":1788331855914,"s":"BTCUSDT","U":99555817580,"u":99555817582,"b":[["69823.03000000","0.00432000"]],"a":[["77595.90000000","0.00257000"],["77595.94000000","0.00000000"]]}}
{"type":"trade","received_at_ms":1788331855824,"data":{"e":"trade","E":1788331855960,"s":"BTCUSDT","t":6646633851,"p":"77581.14000000","q":"0.00100000","T":1788331855960,"m":true,"M":true}}
{"type":"depth","received_at_ms":1788331855874,"data":{"e":"depthUpdate","E":1788331856014,"s":"BTCUSDT","U":99555817583,"u":99555817591,"b":[["77581.14000000","3.68751000"],["69823.03000000","0.00448000"],["69823.02000000","0.00009000"],["62064.92000000","0.00032000"]],"a":[["77584.08000000","0.00007000"],["77584.09000000","0.11088000"],["77584.87000000","0.00000000"]]}}
{"type":"depth","received_at_ms":1788331855974,"data":{"e":"depthUpdate","E":1788331856114,"s":"BTCUSDT","U":99555817592,"u":99555817606,"b":[["77581.14000000","3.70743000"],["77576.25000000","0.00000000"],["77484.05000000","0.00412000"],["69823.03000000","0.00432000"]],"a":[["77583.87000000","0.01299000"],["77584.09000000","0.11102000"],["77585.71000000","0.00634000"]]}}
{"type":"depth","received_at_ms":1788331856075,"data":{"e":"depthUpdate","E":1788331856214,"s":"BTCUSDT","U":99555817607,"u":99555817614,"b":[["77561.86000000","0.00007000"],["69823.03000000","0.00432000"],["62064.92000000","0.00000000"],["62064.91000000","0.00000000"]],"a":[["77592.90000000","0.00007000"]]}}
{"type":"depth","received_at_ms":1788331856174,"data":{"e":"depthUpdate","E":1788331856314,"s":"BTCUSDT","U":99555817615,"u":99555817627,"b":[["77260.90000000","0.00000000"],["69823.03000000","0.00432000"],["62065.00000000","0.00600000"]],"a":[["77595.80000000","0.00257000"],["77595.90000000","0.00000000"],["77642.93000000","0.00412000"],["77901.39000000","0.00000000"],["78744.87000000","0.00030000"]]}}
{"type":"trade","received_at_ms":1788331856192,"data":{"e":"trade","E":1788331856331,"s":"BTCUSDT","t":6646633852,"p":"77581.15000000","q":"0.00647000","T":1788331856331,"m":false,"M":true}}
{"type":"depth","received_at_ms":1788331856274,"data":{"e":"depthUpdate","E":1788331856415,"s":"BTCUSDT","U":99555817628,"u":99555817632,"b":[["69823.03000000","0.00448000"],["69823.02000000","0.00000000"],["69823.01000000","0.00009000"]],"a":[["77581.15000000","0.65143000"]]}}
{"type":"trade","received_at_ms":1788331856305,"data":{"e":"trade","E":1788331856445,"s":"BTCUSDT","t":6646633853,"p":"77581.14000000","q":"0.00382000","T":1788331856445,"m":true,"M":true}}
{"type":"depth","received_at_ms":1788331856376,"data":{"e":"depthUpdate","E":1788331856514,"s":"BTCUSDT","U":99555817633,"u":99555817644,"b":[["77581.14000000","3.70361000"],["77573.29000000","0.02000000"],["77567.27000000","0.00000000"],["77544.98000000","0.00000000"],["77534.48000000","0.02000000"],["77525.57000000","0.00000000"],["69823.03000000","0.00416000"],["62064.92000000","0.00032000"],["62064.91000000","0.00000000"]],"a":[["77593.58000000","0.00000000"],["77596.42000000","0.03000000"],["77615.82000000","0.03000000"],["77625.17000000","0.00000000"],["77635.23000000","0.03000000"],["77644.57000000","0.00000000"]]}}
{"type":"depth","received_at_ms":1788331856475,"data":{"e":"depthUpdate","E":1788331856615,"s":"BTCUSDT","U":99555817645,"u":99555817652,"b":[["69823.03000000","0.00432000"],["62065.00000000","0.00600000"],["62064.92000000","0.00000000"]],"a":[]}}
{"type":"trade","received_at_ms":1788331856500,"data":{"e":"trade","E":1788331856622,"s":"BTCUSDT","t":6646633854,"p":"77581.15000000","q":"0.00063000","T":1788331856622,"m":false,"M":true}}
{"type":"depth","received_at_ms":1788331856573,"data":{"e":"depthUpdate","E":1788331856714,"s":"BTCUSDT","U":99555817653,"u":99555817667,"b":[["77572.94000000","0.01000000"],["77569.35000000","0.00000000"],["76417.42000000","0.00030000"],["69823.03000000","0.00432000"],["69823.01000000","0.00000000"],["69823.00000000","0.00000000"],["66572.39000000","0.00016000"]],"a":[["77581.15000000","0.65080000"],["77592.30000000","0.00342000"],["77593.06000000","0.00200000"],["77593.53000000","0.00644000"]]}}
{"type":"depth","received_at_ms":1788331856673,"data":{"e":"depthUpdate","E":1788331856814,"s":"BTCUSDT","U":99555817668,"u":99555817671,"b":[["69823.03000000","0.00432000"]],"a":[]}}
{"type":"depth","received_at_ms":1788331856774,"data":{"e":"depthUpdate","E":1788331856914,"s":"BTCUSDT","U":99555817672,"u":99555817676,"b":[["77572.94000000","0.00800000"],["77569.81000000","0.00200000"],["77515.07000000","0.00412000"],["77484.05000000","0.00000000"]],"a":[["77642.93000000","0.00000000"]]}}
{"type":"depth","received_at_ms":1788331856873,"data":{"e":"depthUpdate","E":1788331857014,"s":"BTCUSDT","U":99555817677,"u":99555817682,"b":[["71374.65000000","0.00015000"],["69823.03000000","0.00432000"],["62064.92000000","0.00032000"]],"a":[]}}
{"type":"trade","received_at_ms":1788331856937,"data":{"e":"trade","E":1788331857075,"s":"BTCUSDT","t":6646633855,"p":"77581.14000000","q":"0.00378000","T":1788331857075,"m":true,"M":true}}
{"type":"trade","received_at_ms":1788331856937,"data":{"e":"trade","E":1788331857075,"s":"BTCUSDT","t":6646633856,"p":"77581.14000000","q":"0.00007000","T":1788331857075,"m":true,"M":true}}
{"type":"trade","received_at_ms":1788331856937,"data":{"e":"trade","E":1788331857075,"s":"BTCUSDT","t":6646633857,"p":"77581.14000000","q":"0.00007000","T":1788331857075,"m":true,"M":true}}
{"type":"trade","received_at_ms":1788331856937,"data":{"e":"trade","E":1788331857075,"s":"BTCUSDT","t":6646633858,"p":"77581.14000000","q":"0.00008000","T":1788331857075,"m":true,"M":true}}
{"type":"trade","received_at_ms":1788331856937,"data":{"e":"trade","E":1788331857075,"s":"BTCUSDT","t":6646633859,"p":"77581.14000000","q":"0.00007000","T":1788331857075,"m":true,"M":true}}
{"type":"trade","received_at_ms":1788331856937,"data":{"e":"trade","E":1788331857075,"s":"BTCUSDT","t":6646633860,"p":"77581.14000000","q":"0.00267000","T":1788331857075,"m":true,"M":true}}
{"type":"trade","received_at_ms":1788331856942,"data":{"e":"trade","E":1788331857079,"s":"BTCUSDT","t":6646633861,"p":"77581.14000000","q":"0.00133000","T":1788331857079,"m":true,"M":true}}
{"type":"trade","received_at_ms":1788331856942,"data":{"e":"trade","E":1788331857079,"s":"BTCUSDT","t":6646633862,"p":"77581.14000000","q":"0.01000000","T":1788331857079,"m":true,"M":true}}
{"type":"trade","received_at_ms":1788331856942,"data":{"e":"trade","E":1788331857079,"s":"BTCUSDT","t":6646633863,"p":"77581.14000000","q":"0.00013000","T":1788331857079,"m":true,"M":true}}
{"type":"trade","received_at_ms":1788331856942,"data":{"e":"trade","E":1788331857079,"s":"BTCUSDT","t":6646633864,"p":"77581.14000000","q":"0.00064000","T":1788331857079,"m":true,"M":true}}
{"type":"trade","received_at_ms":1788331856942,"data":{"e":"trade","E":1788331857079,"s":"BTCUSDT","t":6646633865,"p":"77581.14000000","q":"0.00065000","T":1788331857079,"m":true,"M":true}}
{"type":"trade","received_at_ms":1788331856942,"data":{"e":"trade","E":1788331857079,"s":"BTCUSDT","t":6646633866,"p":"77581.14000000","q":"0.02000000","T":1788331857079,"m":true,"M":true}}
{"type":"trade","received_at_ms":1788331856942,"data":{"e":"trade","E":1788331857079,"s":"BTCUSDT","t":6646633867,"p":"77581.14000000","q":"0.02000000","T":1788331857079,"m":true,"M":true}}
{"type":"trade","received_at_ms":1788331856942,"data":{"e":"trade","E":1788331857079,"s":"BTCUSDT","t":6646633868,"p":"77581.14000000","q":"0.00018000","T":1788331857079,"m":true,"M":true}}
{"type":"trade","received_at_ms":1788331856942,"data":{"e":"trade","E":1788331857079,"s":"BTCUSDT","t":6646633869,"p":"77581.14000000","q":"0.07595000","T":1788331857079,"m":true,"M":true}}
{"type":"trade","received_at_ms":1788331856942,"data":{"e":"trade","E":1788331857079,"s":"BTCUSDT","t":6646633870,"p":"77581.14000000","q":"0.01000000","T":1788331857079,"m":true,"M":true}}
{"type":"trade","received_at_ms":1788331856942,"data":{"e":"trade","E":1788331857079,"s":"BTCUSDT","t":6646633871,"p":"77581.14000000","q":"0.02000000","T":1788331857079,"m":true,"M":true}}
{"type":"trade","received_at_ms":1788331856942,"data":{"e":"trade","E":1788331857079,"s":"BTCUSDT","t":6646633872,"p":"77581.14000000","q":"0.02000000","T":1788331857079,"m":true,"M":true}}
{"type":"depth","received_at_ms":1788331856973,"data":{"e":"depthUpdate","E":1788331857114,"s":"BTCUSDT","U":99555817683,"u":99555817727,"b":[["77581.14000000","3.64894000"],["77581.13000000","0.04348000"],["69823.03000000","0.00448000"],["69823.02000000","0.00009000"]],"a":[["77581.15000000","0.65609000"],["77581.16000000","0.00076000"],["77583.87000000","0.01306000"],["77584.09000000","0.11109000"],["77584.40000000","0.11841000"],["77585.71000000","0.00627000"],["77585.74000000","0.00000000"],["77588.59000000","0.38219000"],["77589.72000000","0.00000000"],["77792.63000000","0.00000000"],["77801.03000000","0.02019000"]]}}
{"type":"depth","received_at_ms":1788331857074,"data":{"e":"depthUpdate","E":1788331857214,"s":"BTCUSDT","U":99555817728,"u":99555817750,"b":[["77581.14000000","3.66894000"],["77579.69000000","0.07789000"],["77578.98000000","0.00400000"],["77561.86000000","0.00000000"],["77441.41000000","0.02019000"],["77427.60000000","0.00218000"],["69823.03000000","0.00432000"],["62064.92000000","0.00000000"],["62064.91000000","0.00000000"]],"a":[["77581.15000000","0.88420000"],["77584.09000000","0.11109000"],["77584.40000000","0.11855000"],["77585.56000000","0.11454000"],["77590.30000000","0.00400000"],["77592.90000000","0.00000000"],["77621.34000000","0.00000000"]]}}
{"type":"trade","received_at_ms":1788331857110,"data":{"e":"trade","E":1788331857232,"s":"BTCUSDT","t":6646633873,"p":"77581.15000000","q":"0.00200000","T":1788331857232,"m":false,"M":true}}
{"type":"depth","received_at_ms":1788331857175,"data":{"e":"depthUpdate","E":1788331857314,"s":"BTCUSDT","U":99555817751,"u":99555817769,"b":[["77581.14000000","3.67852000"],["77581.13000000","0.04320000"],["77561.86000000","0.00007000"],["69823.03000000","0.00448000"]],"a":[["77581.15000000","0.88220000"],["77592.90000000","0.00007000"],["78744.87000000","0.00030000"]]}}
{"type":"depth","received_at_ms":1788331857273,"data":{"e":"depthUpdate","E":1788331857414,"s":"BTCUSDT","U":99555817770,"u":99555817772,"b":[["69823.03000000","0.00432000"]],"a":[]}}
{"type":"depth","received_at_ms":1788331857375,"data":{"e":"depthUpdate","E":1788331857516,"s":"BTCUSDT","U":99555817773,"u":99555817783,"b":[["77573.25000000","0.02000000"],["77567.28000000","0.00343000"],["77545.08000000","0.00000000"],["77534.44000000","0.02000000"],["77525.67000000","0.00000000"],["77515.08000000","0.02000000"],["69823.03000000","0.00448000"],["62064.92000000","0.00032000"],["62064.91000000","0.00000000"]],"a":[["77593.61000000","0.00000000"],["77596.42000000","0.05400000"],["77615.82000000","0.05400000"],["77625.20000000","0.00000000"],["77635.22000000","0.02400000"],["77644.61000000","0.00000000"]]}}
{"type":"depth","received_at_ms":1788331857473,"data":{"e":"depthUpdate","E":1788331857614,"s":"BTCUSDT","U":99555817784,"u":99555817789,"b":[["71374.65000000","0.00000000"],["69823.03000000","0.00432000"],["62065.00000000","0.00800000"],["62064.92000000","0.00000000"]],"a":[]}}
{"type":"trade","received_at_ms":1788331857498,"data":{"e":"trade","E":1788331857637,"s":"BTCUSDT","t":6646633874,"p":"77581.15000000","q":"0.01970000","T":1788331857636,"m":false,"M":true}}
{"type":"trade","received_at_ms":1788331857545,"data":{"e":"trade","E":1788331857686,"s":"BTCUSDT","t":6646633875,"p":"77581.15000000","q":"0.00200000","T":1788331857685,"m":false,"M":true}}
{"type":"trade","received_at_ms":1788331857545,"data":{"e":"trade","E":1788331857686,"s":"BTCUSDT","t":6646633876,"p":"77581.15000000","q":"0.00200000","T":1788331857685,"m":false,"M":true}}
{"type":"trade","received_at_ms":1788331857546,"data":{"e":"trade","E":1788331857686,"s":"BTCUSDT","t":6646633877,"p":"77581.15000000","q":"0.00200000","T":1788331857685,"m":false,"M":true}}
{"type":"depth","received_at_ms":1788331857574,"data":{"e":"depthUpdate","E":1788331857714,"s":"BTCUSDT","U":99555817790,"u":99555817831,"b":[["77581.14000000","3.67824000"],["77581.13000000","0.04299000"],["76417.42000000","0.00030000"],["69823.03000000","0.00448000"],["69823.02000000","0.00000000"],["69823.01000000","0.00009000"],["69823.00000000","0.00020000"],["66589.16000000","0.00016000"],["62065.00000000","0.00600000"]],"a":[["77581.15000000","0.85650000"]]}}
{"type":"depth","received_at_ms":1788331857674,"data":{"e":"depthUpdate","E":1788331857814,"s":"BTCUSDT","U":99555817832,"u":99555817839,"b":[["77558.68000000","0.04579000"],["77551.55000000","0.00000000"],["69823.03000000","0.00416000"],["69823.00000000","0.00000000"]],"a":[["77590.26000000","0.00000000"],["77608.83000000","0.00000000"],["77610.58000000","0.04540000"]]}}
{"type":"depth","received_at_ms":1788331857774,"data":{"e":"depthUpdate","E":1788331857914,"s":"BTCUSDT","U":99555817840,"u":99555817842,"b":[["69823.03000000","0.00448000"]],"a":[["77581.15000000","0.85522000"]]}}
{"type":"trade","received_at_ms":1788331857775,"data":{"e":"trade","E":1788331857914,"s":"BTCUSDT","t":6646633878,"p":"77581.15000000","q":"0.00128000","T":1788331857913,"m":false,"M":true}}
{"type":"depth","received_at_ms":1788331857874,"data":{"e":"depthUpdate","E":1788331858014,"s":"BTCUSDT","U":99555817843,"u":99555817855,"b":[["77408.92000000","0.00000000"],["77365.24000000","0.00000000"],["69823.03000000","0.00432000"],["69823.01000000","0.00000000"],["62065.00000000","0.00600000"],["62064.92000000","0.00032000"]],"a":[["77581.15000000","0.85535000"]]}}
{"type":"depth","received_at_ms":1788331857975,"data":{"e":"depthUpdate","E":1788331858114,"s":"BTCUSDT","U":99555817856,"u":99555817861,"b":[["77391.17000000","0.02019000"],["69823.03000000","0.00416000"]],"a":[["77588.53000000","0.57157000"],["77642.94000000","0.00412000"]]}}
{"type":"trade","received_at_ms":1788331858010,"data":{"e":"trade","E":1788331858150,"s":"BTCUSDT","t":6646633879,"p":"77581.15000000","q":"0.00205000","T":1788331858150,"m":false,"M":true}}
{"type":"trade","received_at_ms":1788331858017,"data":{"e":"trade","E":1788331858157,"s":"BTCUSDT","t":6646633880,"p":"77581.15000000","q":"0.00257000","T":1788331858157,"m":false,"M":true}}
{"type":"depth","received_at_ms":1788331858082,"data":{"e":"depthUpdate","E":1788331858214,"s":"BTCUSDT","U":99555817862,"u":99555817876,"b":[["77581.14000000","3.69816000"],["75557.06000000","0.00000000"],["69823.03000000","0.00432000"],["62064.92000000","0.00000000"],["62064.91000000","0.00000000"]],"a":[["77581.15000000","0.85073000"],["77588.49000000","0.00200000"],["77592.76000000","0.00000000"],["77593.06000000","0.00000000"],["81001.06000000","0.00000000"]]}}
{"type":"depth","received_at_ms":1788331858187,"data":{"e":"depthUpdate","E":1788331858314,"s":"BTCUSDT","U":99555817877,"u":99555817895,"b":[["77569.81000000","0.00000000"],["77569.35000000","0.00200000"],["77561.86000000","0.00007000"],["77408.77000000","6.62784000"],["69823.03000000","0.00432000"],["62065.00000000","0.00600000"]],"a":[["77588.49000000","0.00200000"],["77592.76000000","0.00000000"],["77592.90000000","0.00007000"],["78744.87000000","0.00000000"]]}}
{"type":"depth","received_at_ms":1788331858295,"data":{"e":"depthUpdate","E":1788331858414,"s":"BTCUSDT","U":99555817896,"u":99555817903,"b":[["77581.14000000","3.69559000"],["77569.35000000","0.00000000"],["77568.92000000","0.00200000"],["76255.93000000","0.00048000"],["69823.03000000","0.00448000"]],"a":[["78744.87000000","0.00030000"]]}}
{"type":"trade","received_at_ms":1788331858295,"data":{"e":"trade","E":1788331858428,"s":"BTCUSDT","t":6646633881,"p":"77581.15000000","q":"0.00277000","T":1788331858428,"m":false,"M":true}}
{"type":"depth","received_at_ms":1788331858405,"data":{"e":"depthUpdate","E":1788331858514,"s":"BTCUSDT","U":99555817904,"u":99555817922,"b":[["77581.14000000","3.69507000"],["77580.12000000","0.00079000"],["77573.21000000","0.02000000"],["77568.05000000","0.00000000"],["77545.93000000","0.00000000"],["77534.40000000","0.02000000"],["77526.52000000","0.00000000"],["77515.07000000","0.00000000"],["77515.04000000","0.02000000"],["77484.06000000","0.00412000"],["69823.03000000","0.00441000"],["62065.00000000","0.00800000"],["62064.92000000","0.00032000"],["62064.91000000","0.00020000"]],"a":[["77581.15000000","0.84796000"],["77592.82000000","0.00000000"],["77596.38000000","0.03000000"],["77615.78000000","0.03000000"],["77624.45000000","0.00000000"],["77635.18000000","0.03000000"],["77642.94000000","0.00000000"],["77643.86000000","0.00000000"]]}}
{"type":"trade","received_at_ms":1788331858405,"data":{"e":"trade","E":1788331858536,"s":"BTCUSDT","t":6646633882,"p":"77581.15000000","q":"0.00100000","T":1788331858536,"m":false,"M":true}}
{"type":"depth","received_at_ms":1788331858509,"data":{"e":"depthUpdate","E":1788331858614,"s":"BTCUSDT","U":99555817923,"u":99555817928,"b":[["69823.03000000","0.00457000"],["62064.92000000","0.00000000"],["62064.91000000","0.00000000"]],"a":[["77581.15000000","0.84696000"]]}}
{"type":"depth","received_at_ms":1788331858614,"data":{"e":"depthUpdate","E":1788331858715,"s":"BTCUSDT","U":99555817929,"u":99555817936,"b":[["77569.81000000","0.00200000"],["77568.92000000","0.00000000"],["76417.42000000","0.00030000"],["69823.03000000","0.00441000"],["66605.94000000","0.00016000"]],"a":[]}}
{"type":"depth","received_at_ms":1788331858674,"data":{"e":"depthUpdate","E":1788331858814,"s":"BTCUSDT","U":99555817937,"u":99555817939,"b":[["69823.03000000","0.00457000"]],"a":[["77588.49000000","0.00200000"]]}}
{"type":"depth","received_at_ms":1788331858786,"data":{"e":"depthUpdate","E":1788331858914,"s":"BTCUSDT","U":99555817940,"u":99555817947,"b":[["77515.08000000","0.02412000"],["69823.03000000","0.00441000"],["69823.00000000","0.00000000"]],"a":[["77588.49000000","0.00000000"],["77592.76000000","0.00200000"]]}}
{"type":"depth","received_at_ms":1788331858893,"data":{"e":"depthUpdate","E":1788331859015,"s":"BTCUSDT","U":99555817948,"u":99555817951,"b":[["69823.03000000","0.00457000"],["62064.92000000","0.00032000"]],"a":[]}}
{"type":"depth","received_at_ms":1788331858998,"data":{"e":"depthUpdate","E":1788331859114,"s":"BTCUSDT","U":99555817952,"u":99555817956,"b":[["77515.08000000","0.02000000"],["77484.06000000","0.00000000"],["75557.06000000","0.00010000"],["69823.03000000","0.00441000"]],"a":[["77642.93000000","0.00412000"]]}}
{"type":"depth","received_at_ms":1788331859078,"data":{"e":"depthUpdate","E":1788331859214,"s":"BTCUSDT","U":99555817957,"u":99555817964,"b":[["69823.03000000","0.00457000"],["62065.00000000","0.00800000"],["62064.92000000","0.00000000"],["62064.91000000","0.00000000"]],"a":[]}}
{"type":"trade","received_at_ms":1788331859089,"data":{"e":"trade","E":1788331859229,"s":"BTCUSDT","t":6646633883,"p":"77581.15000000","q":"0.00382000","T":1788331859229,"m":false,"M":true}}
{"type":"depth","received_at_ms":1788331859178,"data":{"e":"depthUpdate","E":1788331859314,"s":"BTCUSDT","U":99555817965,"u":99555817975,"b":[["77561.86000000","0.00007000"],["69823.03000000","0.00432000"],["69823.02000000","0.00009000"]],"a":[["77581.15000000","0.84314000"],["77588.49000000","0.00200000"],["77592.76000000","0.00000000"],["77592.90000000","0.00007000"],["81001.06000000","0.00010000"]]}}
{"type":"depth","received_at_ms":1788331859274,"data":{"e":"depthUpdate","E":1788331859414,"s":"BTCUSDT","U":99555817976,"u":99555818007,"b":[["77581.14000000","3.69543000"],["77581.13000000","0.04320000"],["77569.81000000","0.00000000"],["77569.40000000","0.00200000"],["69823.03000000","0.00448000"]],"a":[["77596.23000000","1.42499000"],["77596.24000000","1.93226000"],["77596.27000000","0.00000000"],["78744.87000000","0.00030000"]]}}
{"type":"depth","received_at_ms":1788331859400,"data":{"e":"depthUpdate","E":1788331859514,"s":"BTCUSDT","U":99555818008,"u":99555818020,"b":[["77573.95000000","0.02000000"],["77535.14000000","0.02000000"],["77515.00000000","0.02000000"],["77484.06000000","0.00412000"],["69823.03000000","0.00432000"],["62064.92000000","0.00032000"]],"a":[["77588.49000000","0.00000000"],["77592.76000000","0.00200000"],["77595.56000000","0.02600000"],["77614.97000000","0.02600000"],["77634.37000000","0.02600000"]]}}
{"type":"trade","received_at_ms":1788331859426,"data":{"e":"trade","E":1788331859565,"s":"BTCUSDT","t":6646633884,"p":"77581.14000000","q":"0.00100000","T":1788331859565,"m":true,"M":true}}
{"type":"depth","received_at_ms":1788331859506,"data":{"e":"depthUpdate","E":1788331859614,"s":"BTCUSDT","U":99555818021,"u":99555818039,"b":[["77581.14000000","3.69443000"],["77580.84000000","0.00257000"],["77578.00000000","0.03035000"],["69823.03000000","0.00432000"],["69823.02000000","0.00000000"],["62065.00000000","0.00800000"],["62064.92000000","0.00000000"],["62064.91000000","0.00000000"]],"a":[]}}
{"type":"depth","received_at_ms":1788331859614,"data":{"e":"depthUpdate","E":1788331859714,"s":"BTCUSDT","U":99555818040,"u":99555818057,"b":[["77581.14000000","3.69415000"],["77581.13000000","0.04299000"],["77580.84000000","0.00000000"],["77580.82000000","0.00257000"],["77569.81000000","0.00200000"],["77569.40000000","0.00000000"],["77515.08000000","0.02412000"],["77484.06000000","0.00000000"],["76417.42000000","0.00030000"],["69823.03000000","0.00416000"],["66622.72000000","0.00016000"]],"a":[["77642.93000000","0.00000000"]]}}
{"type":"depth","received_at_ms":1788331859673,"data":{"e":"depthUpdate","E":1788331859814,"s":"BTCUSDT","U":99555818058,"u":99555818073,"b":[["77580.82000000","0.00000000"],["77580.79000000","0.00000000"],["77537.06000000","0.00000000"],["77528.80000000","0.25784000"],["77456.15000000","0.00000000"],["77433.92000000","0.01547000"],["69823.03000000","0.00432000"]],"a":[["77592.76000000","0.00000000"],["77593.06000000","0.00200000"],["77681.85000000","0.75095000"],["77684.45000000","0.00000000"],["77687.03000000","1.63709000"],["77687.04000000","2.15391000"],["77688.30000000","0.00000000"]]}}
{"type":"trade","received_at_ms":1788331859742,"data":{"e":"trade","E":1788331859883,"s":"BTCUSDT","t":6646633885,"p":"77581.15000000","q":"0.00136000","T":1788331859883,"m":false,"M":true}}
{"type":"depth","received_at_ms":1788331859774,"data":{"e":"depthUpdate","E":1788331859915,"s":"BTCUSDT","U":99555818074,"u":99555818080,"b":[["77580.76000000","0.00000000"],["69823.03000000","0.00457000"]],"a":[["77581.15000000","0.84178000"]]}}
{"type":"depth","received_at_ms":1788331859874,"data":{"e":"depthUpdate","E":1788331860014,"s":"BTCUSDT","U":99555818081,"u":99555818102,"b":[["77580.73000000","0.00000000"],["77580.70000000","0.00087000"],["77580.12000000","0.00000000"],["77579.16000000","0.00112000"],["77578.07000000","0.00000000"],["77566.79000000","0.00000000"],["77566.52000000","0.62862000"],["77563.44000000","0.44229000"],["77554.97000000","0.00000000"],["77510.01000000","0.00000000"],["77509.99000000","0.00322000"],["69823.03000000","0.00425000"],["69823.00000000","0.00000000"],["62064.92000000","0.00032000"]],"a":[["77592.89000000","0.00200000"],["77593.06000000","0.00000000"],["77596.22000000","0.09622000"],["77600.20000000","0.00000000"],["77602.87000000","0.49743000"],["77602.96000000","0.00000000"],["77605.06000000","0.25791000"],["77605.10000000","0.64477000"],["77607.83000000","0.34778000"],["77609.50000000","0.00038000"],["77613.28000000","0.00000000"],["77715.88000000","0.00000000"],["77715.99000000","0.00128000"],["86422.88000000","0.22692000"]]}}
{"type":"depth","received_at_ms":1788331859974,"data":{"e":"depthUpdate","E":1788331860115,"s":"BTCUSDT","U":99555818103,"u":99555818110,"b":[["77580.71000000","0.00000000"],["69823.03000000","0.00457000"]],"a":[["77607.82000000","1.20043000"],["77655.27000000","0.00000000"],["77677.04000000","0.00087000"]]}}
{"type":"depth","received_at_ms":1788331860076,"data":{"e":"depthUpdate","E":1788331860214,"s":"BTCUSDT","U":99555818111,"u":99555818119,"b":[["77580.68000000","0.00257000"],["69823.03000000","0.00441000"],["62064.92000000","0.00000000"],["62064.91000000","0.00000000"]],"a":[["77592.76000000","0.00200000"],["77592.89000000","0.00000000"]]}}
{"type":"depth","received_at_ms":1788331860174,"data":{"e":"depthUpdate","E":1788331860314,"s":"BTCUSDT","U":99555818120,"u":99555818149,"b":[["77580.70000000","0.00000000"],["77580.68000000","0.00000000"],["77580.65000000","0.00000000"],["77580.12000000","0.00087000"],["77579.16000000","0.00000000"],["77578.99000000","0.00113000"],["77578.53000000","0.00000000"],["77577.81000000","0.01044000"],["77561.86000000","0.00000000"],["77484.05000000","0.00412000"],["69823.03000000","0.00457000"],["62065.00000000","0.00800000"]],"a":[["77581.15000000","0.84171000"],["77581.16000000","0.00069000"],["77584.40000000","0.00014000"],["77588.49000000","0.00200000"],["77592.75000000","0.00000000"],["77592.76000000","0.00000000"],["77592.89000000","0.00000000"],["77592.90000000","0.00000000"],["77625.88000000","0.00000000"],["84202.54000000","0.01768000"]]}}
{"type":"depth","received_at_ms":1788331860273,"data":{"e":"depthUpdate","E":1788331860414,"s":"BTCUSDT","U":99555818150,"u":99555818171,"b":[["77580.62000000","0.19843000"],["77561.86000000","0.00007000"],["69823.03000000","0.00457000"],["62065.00000000","0.00800000"]],"a":[["77581.15000000","0.84116000"],["77584.09000000","0.11102000"],["77584.40000000","0.00000000"],["77585.56000000","0.11468000"],["77588.53000000","0.00000000"],["77592.90000000","0.00007000"],["77596.24000000","0.00000000"],["78744.87000000","0.00030000"]]}}
{"type":"trade","received_at_ms":1788331860283,"data":{"e":"trade","E":1788331860424,"s":"BTCUSDT","t":6646633886,"p":"77581.14000000","q":"0.00257000","T":1788331860424,"m":true,"M":true}}
{"type":"depth","received_at_ms":1788331860373,"data":{"e":"depthUpdate","E":1788331860514,"s":"BTCUSDT","U":99555818172,"u":99555818189,"b":[["77581.14000000","3.69158000"],["77580.62000000","0.19586000"],["77580.61000000","0.08240000"],["77580.60000000","0.00657000"],["77515.74000000","0.02000000"],["69823.03000000","0.00464000"],["69823.02000000","0.00009000"],["62064.92000000","0.00032000"]],"a":[["77581.15000000","0.84101000"],["77585.56000000","0.11475000"],["77585.67000000","0.10736000"],["77588.49000000","0.00000000"],["77592.30000000","0.00542000"],["77596.22000000","0.00000000"],["77596.23000000","0.84821000"],["77600.21000000","0.09622000"]]}}
{"type":"depth","received_at_ms":1788331860474,"data":{"e":"depthUpdate","E":1788331860614,"s":"BTCUSDT","U":99555818190,"u":99555818218,"b":[["77580.61000000","0.08240000"],["77580.60000000","0.00414000"],["77580.57000000","0.00257000"],["77578.44000000","0.01301000"],["69823.03000000","0.00448000"],["62065.00000000","0.00800000"],["62064.92000000","0.00000000"],["62064.91000000","0.00000000"]],"a":[["77584.81000000","0.14620000"],["77585.56000000","0.11468000"],["77585.67000000","0.00000000"],["77590.35000000","0.00332000"],["77684.45000000","2.15391000"],["77687.03000000","0.00000000"],["77687.04000000","0.00000000"]]}}
{"type":"trade","received_at_ms":1788331860558,"data":{"e":"trade","E":1788331860698,"s":"BTCUSDT","t":6646633887,"p":"77581.14000000","q":"0.00268000","T":1788331860697,"m":true,"M":true}}
{"type":"depth","received_at_ms":1788331860574,"data":{"e":"depthUpdate","E":1788331860714,"s":"BTCUSDT","U":99555818219,"u":99555818245,"b":[["77581.14000000","3.68890000"],["77580.61000000","0.08240000"],["77580.60000000","0.00400000"],["77580.57000000","0.00000000"],["77580.55000000","0.00257000"],["77578.44000000","0.01315000"],["77515.08000000","0.02000000"],["77484.05000000","0.00000000"],["76417.42000000","0.00030000"],["69823.03000000","0.00464000"],["69823.02000000","0.00000000"]],"a":[["77584.09000000","0.11109000"],["77584.81000000","0.14634000"],["77585.56000000","0.11454000"],["77642.92000000","0.00412000"]]}}
{"type":"trade","received_at_ms":1788331860668,"data":{"e":"trade","E":1788331860808,"s":"BTCUSDT","t":6646633888,"p":"77581.15000000","q":"0.04100000","T":1788331860808,"m":false,"M":true}}
{"type":"depth","received_at_ms":1788331860673,"data":{"e":"depthUpdate","E":1788331860814,"s":"BTCUSDT","U":99555818246,"u":99555818253,"b":[["77580.55000000","0.00000000"],["77580.54000000","0.00000000"],["69823.03000000","0.00448000"],["66639.49000000","0.00016000"]],"a":[["77581.15000000","0.80001000"]]}}
{"type":"trade","received_at_ms":1788331860687,"data":{"e":"trade","E":1788331860828,"s":"BTCUSDT","t":6646633889,"p":"77581.14000000","q":"0.00017000","T":1788331860828,"m":true,"M":true}}
{"type":"depth","received_at_ms":1788331860773,"data":{"e":"depthUpdate","E":1788331860914,"s":"BTCUSDT","U":99555818254,"u":99555818260,"b":[["77581.14000000","3.68873000"],["77580.52000000","0.00000000"],["77522.95000000","0.25133000"],["69823.03000000","0.00464000"]],"a":[]}}
{"type":"depth","received_at_ms":1788331860873,"data":{"e":"depthUpdate","E":1788331861014,"s":"BTCUSDT","U":99555818261,"u":99555818274,"b":[["77581.14000000","3.68901000"],["77581.13000000","0.04320000"],["77580.64000000","0.00088000"],["77580.50000000","0.00257000"],["77580.12000000","0.00000000"],["69823.03000000","0.00448000"],["62065.00000000","0.00800000"],["62064.92000000","0.00032000"]],"a":[["77581.15000000","0.80016000"]]}}
{"type":"depth","received_at_ms":1788331860975,"data":{"e":"depthUpdate","E":1788331861114,"s":"BTCUSDT","U":99555818275,"u":99555818292,"b":[["77581.14000000","3.68873000"],["77581.13000000","0.04299000"],["77580.50000000","0.00000000"],["77580.49000000","0.00000000"],["77579.16000000","0.00113000"],["77578.99000000","0.00000000"],["77555.43000000","0.00007000"],["77531.59000000","0.00000000"],["69823.03000000","0.00448000"],["69823.00000000","0.00020000"]],"a":[]}}
{"type":"depth","received_at_ms":1788331861074,"data":{"e":"depthUpdate","E":1788331861215,"s":"BTCUSDT","U":99555818293,"u":99555818307,"b":[["77580.47000000","0.00257000"],["77564.11000000","0.10430000"],["77562.18000000","0.10430000"],["77556.63000000","0.00000000"],["77556.41000000","0.95884000"],["77554.69000000","0.00000000"],["77545.53000000","0.79594000"],["77538.31000000","0.00000000"],["77533.32000000","0.16670000"],["69823.03000000","0.00448000"],["69823.00000000","0.00000000"],["62064.92000000","0.00000000"],["62064.91000000","0.00020000"]],"a":[]}}
{"type":"depth","received_at_ms":1788331861174,"data":{"e":"depthUpdate","E":1788331861314,"s":"BTCUSDT","U":99555818308,"u":99555818320,"b":[["77580.47000000","0.00000000"],["77580.45000000","0.00257000"],["77575.79000000","0.04000000"],["77569.81000000","0.00000000"],["77553.30000000","0.00000000"],["77515.09000000","0.00412000"],["69823.03000000","0.00432000"],["62064.91000000","0.00000000"]],"a":[["77592.30000000","0.00342000"],["77609.65000000","0.00000000"],["77681.85000000","1.29789000"]]}}
{"type":"depth","received_at_ms":1788331861276,"data":{"e":"depthUpdate","E":1788331861414,"s":"BTCUSDT","U":99555818321,"u":99555818332,"b":[["77580.45000000","0.00000000"],["77580.43000000","0.00257000"],["77561.86000000","0.00007000"],["77260.90000000","0.00009000"],["69823.03000000","0.00464000"]],"a":[["77592.90000000","0.00007000"],["77612.84000000","0.00000000"],["77901.39000000","0.00009000"],["78744.87000000","0.00030000"]]}}
{"type":"depth","received_at_ms":1788331861374,"data":{"e":"depthUpdate","E":1788331861514,"s":"BTCUSDT","U":99555818333,"u":99555818342,"b":[["77580.43000000","0.00000000"],["77580.41000000","0.00257000"],["77561.57000000","0.49756000"],["77538.01000000","0.99220000"],["69823.03000000","0.00448000"],["62065.00000000","0.00800000"],["62064.92000000","0.00032000"]],"a":[]}}
{"type":"depth","received_at_ms":1788331861472,"data":{"e":"depthUpdate","E":1788331861614,"s":"BTCUSDT","U":99555818343,"u":99555818349,"b":[["77580.41000000","0.00000000"],["77580.39000000","0.00257000"],["69823.03000000","0.00448000"],["62064.92000000","0.00000000"],["62064.91000000","0.00000000"]],"a":[]}}
{"type":"trade","received_at_ms":1788331861480,"data":{"e":"trade","E":1788331861620,"s":"BTCUSDT","t":6646633890,"p":"77581.14000000","q":"0.02483000","T":1788331861619,"m":true,"M":true}}
{"type":"depth","received_at_ms":1788331861573,"data":{"e":"depthUpdate","E":1788331861714,"s":"BTCUSDT","U":99555818350,"u":99555818357,"b":[["77581.14000000","3.66390000"],["77580.39000000","0.00000000"],["77553.99000000","0.00007000"],["76417.42000000","0.00030000"],["69823.03000000","0.00448000"],["69823.02000000","0.00009000"]],"a":[]}}
{"type":"trade","received_at_ms":1788331861661,"data":{"e":"trade","E":1788331861761,"s":"BTCUSDT","t":6646633891,"p":"77581.15000000","q":"0.00067000","T":1788331861761,"m":false,"M":true}}
{"type":"depth","received_at_ms":1788331861673,"data":{"e":"depthUpdate","E":1788331861814,"s":"BTCUSDT","U":99555818358,"u":99555818363,"b":[["77577.28000000","0.00212000"],["77511.66000000","0.00000000"],["69823.03000000","0.00464000"]],"a":[["77581.15000000","0.79949000"]]}}
{"type":"depth","received_at_ms":1788331861774,"data":{"e":"depthUpdate","E":1788331861915,"s":"BTCUSDT","U":99555818364,"u":99555818366,"b":[["69823.03000000","0.00448000"]],"a":[]}}
{"type":"depth","received_at_ms":1788331861876,"data":{"e":"depthUpdate","E":1788331862014,"s":"BTCUSDT","U":99555818367,"u":99555818371,"b":[["77580.81000000","0.00087000"],["77580.64000000","0.00000000"],["77572.94000000","0.01000000"],["77555.70000000","0.00200000"],["69823.03000000","0.00464000"],["62064.92000000","0.00032000"]],"a":[]}}
{"type":"trade","received_at_ms":1788331861883,"data":{"e":"trade","E":1788331862023,"s":"BTCUSDT","t":6646633892,"p":"77581.15000000","q":"0.01288000","T":1788331862023,"m":false,"M":true}}
{"type":"depth","received_at_ms":1788331861980,"data":{"e":"depthUpdate","E":1788331862114,"s":"BTCUSDT","U":99555818372,"u":99555818378,"b":[["69823.03000000","0.00448000"],["69823.02000000","0.00000000"],["69823.01000000","0.00009000"]],"a":[["77581.15000000","0.78661000"],["77593.53000000","0.00844000"],["77608.03000000","0.00200000"]]}}
{"type":"trade","received_at_ms":1788331862004,"data":{"e":"trade","E":1788331862145,"s":"BTCUSDT","t":6646633893,"p":"77581.15000000","q":"0.00100000","T":1788331862145,"m":false,"M":true}}
{"type":"depth","received_at_ms":1788331862088,"data":{"e":"depthUpdate","E":1788331862214,"s":"BTCUSDT","U":99555818379,"u":99555818386,"b":[["77579.16000000","0.00000000"],["77578.99000000","0.00113000"],["69823.03000000","0.00464000"],["69823.00000000","0.00000000"],["62064.92000000","0.00000000"]],"a":[["77581.15000000","0.78561000"]]}}
{"type":"trade","received_at_ms":1788331862142,"data":{"e":"trade","E":1788331862282,"s":"BTCUSDT","t":6646633894,"p":"77581.14000000","q":"0.00382000","T":1788331862282,"m":true,"M":true}}
{"type":"depth","received_at_ms":1788331862193,"data":{"e":"depthUpdate","E":1788331862314,"s":"BTCUSDT","U":99555818387,"u":99555818404,"b":[["77581.14000000","3.66008000"],["77572.94000000","0.00800000"],["77569.81000000","0.00200000"],["77515.09000000","0.00000000"],["77484.07000000","0.00412000"],["69823.03000000","0.00448000"],["69823.01000000","0.00000000"],["62065.00000000","0.00800000"],["62064.91000000","0.00000000"]],"a":[["77581.15000000","0.78568000"],["77584.90000000","0.00306000"],["77585.71000000","0.00007000"],["77642.92000000","0.00000000"],["77688.30000000","0.95913000"]]}}
{"type":"trade","received_at_ms":1788331862225,"data":{"e":"trade","E":1788331862365,"s":"BTCUSDT","t":6646633895,"p":"77581.14000000","q":"0.00019000","T":1788331862364,"m":true,"M":true}}
{"type":"depth","received_at_ms":1788331862300,"data":{"e":"depthUpdate","E":1788331862414,"s":"BTCUSDT","U":99555818405,"u":99555818416,"b":[["77581.14000000","3.65989000"],["77561.86000000","0.00007000"],["69823.03000000","0.00464000"]],"a":[["77588.50000000","0.11461000"],["77588.59000000","0.30000000"],["77592.90000000","0.00007000"],["78744.87000000","0.00030000"]]}}
{"type":"depth","received_at_ms":1788331862374,"data":{"e":"depthUpdate","E":1788331862514,"s":"BTCUSDT","U":99555818417,"u":99555818424,"b":[["77572.94000000","0.01000000"],["77569.81000000","0.00000000"],["69823.03000000","0.00448000"],["62064.92000000","0.00032000"]],"a":[["77590.35000000","0.00000000"],["77641.91000000","0.00412000"]]}}
{"type":"trade","received_at_ms":1788331862416,"data":{"e":"trade","E":1788331862556,"s":"BTCUSDT","t":6646633896,"p":"77581.15000000","q":"0.00849000","T":1788331862556,"m":false,"M":true}}
{"type":"depth","received_at_ms":1788331862474,"data":{"e":"depthUpdate","E":1788331862614,"s":"BTCUSDT","U":99555818425,"u":99555818437,"b":[["77572.94000000","0.00800000"],["77568.97000000","0.00200000"],["69823.03000000","0.00457000"],["62065.00000000","0.00800000"],["62064.92000000","0.00000000"],["62064.91000000","0.00000000"]],"a":[["77581.15000000","0.77719000"]]}}
{"type":"depth","received_at_ms":1788331862578,"data":{"e":"depthUpdate","E":1788331862714,"s":"BTCUSDT","U":99555818438,"u":99555818442,"b":[["76417.42000000","0.00030000"],["71374.65000000","0.00015000"],["69823.03000000","0.00457000"]],"a":[]}}
{"type":"depth","received_at_ms":1788331862685,"data":{"e":"depthUpdate","E":1788331862814,"s":"BTCUSDT","U":99555818443,"u":99555818447,"b":[["77580.37000000","0.00257000"],["69823.03000000","0.00457000"]],"a":[]}}
{"type":"depth","received_at_ms":1788331862792,"data":{"e":"depthUpdate","E":1788331862914,"s":"BTCUSDT","U":99555818448,"u":99555818451,"b":[["77580.37000000","0.00000000"],["77580.36000000","0.00257000"],["69823.03000000","0.00457000"]],"a":[]}}
{"type":"trade","received_at_ms":1788331862902,"data":{"e":"trade","E":1788331863011,"s":"BTCUSDT","t":6646633897,"p":"77581.15000000","q":"0.08000000","T":1788331863010,"m":false,"M":true}}
{"type":"trade","received_at_ms":1788331862902,"data":{"e":"trade","E":1788331863011,"s":"BTCUSDT","t":6646633898,"p":"77581.15000000","q":"0.04000000","T":1788331863010,"m":false,"M":true}}
{"type":"trade","received_at_ms":1788331862902,"data":{"e":"trade","E":1788331863012,"s":"BTCUSDT","t":6646633899,"p":"77581.15000000","q":"0.00009000","T":1788331863012,"m":false,"M":true}}
{"type":"depth","received_at_ms":1788331862902,"data":{"e":"depthUpdate","E":1788331863014,"s":"BTCUSDT","U":99555818452,"u":99555818494,"b":[["77581.14000000","3.66876000"],["77580.81000000","0.00000000"],["77580.36000000","0.00000000"],["77580.35000000","0.00257000"],["77578.98000000","0.00000000"],["77577.81000000","0.00644000"],["77576.76000000","0.00800000"],["77572.94000000","0.00200000"],["77568.97000000","0.00000000"],["69823.03000000","0.00448000"],["69823.02000000","0.00009000"],["62064.92000000","0.00032000"]],"a":[["77581.15000000","0.28562000"],["77584.09000000","0.00021000"],["77584.81000000","0.00014000"],["77585.55000000","0.11021000"],["77585.56000000","0.00007000"],["77589.40000000","0.30000000"],["77589.96000000","0.00000000"],["77589.98000000","0.00000000"],["77590.66000000","0.00000000"],["77592.33000000","0.00400000"],["77592.76000000","0.00644000"],["77595.34000000","0.00000000"],["77595.61000000","0.00000000"],["77596.28000000","0.00000000"],["77600.21000000","0.00000000"],["77602.86000000","0.09622000"],["77602.97000000","0.00000000"],["77607.83000000","0.00000000"],["77608.03000000","0.00000000"],["77610.18000000","0.00200000"],["77610.58000000","0.00000000"],["77621.20000000","0.04765000"]]}}
{"type":"trade","received_at_ms":1788331862908,"data":{"e":"trade","E":1788331863016,"s":"BTCUSDT","t":6646633900,"p":"77581.15000000","q":"0.03327000","T":1788331863016,"m":false,"M":true}}
{"type":"trade","received_at_ms":1788331862908,"data":{"e":"trade","E":1788331863016,"s":"BTCUSDT","t":6646633901,"p":"77581.15000000","q":"0.00107000","T":1788331863016,"m":false,"M":true}}
{"type":"trade","received_at_ms":1788331862908,"data":{"e":"trade","E":1788331863016,"s":"BTCUSDT","t":6646633902,"p":"77581.15000000","q":"0.00007000","T":1788331863016,"m":false,"M":true}}
{"type":"trade","received_at_ms":1788331862909,"data":{"e":"trade","E":1788331863016,"s":"BTCUSDT","t":6646633903,"p":"77581.15000000","q":"0.00007000","T":1788331863016,"m":false,"M":true}}
{"type":"trade","received_at_ms":1788331862909,"data":{"e":"trade","E":1788331863016,"s":"BTCUSDT","t":6646633904,"p":"77581.15000000","q":"0.00007000","T":1788331863016,"m":false,"M":true}}
{"type":"trade","received_at_ms":1788331862909,"data":{"e":"trade","E":1788331863016,"s":"BTCUSDT","t":6646633905,"p":"77581.15000000","q":"0.00007000","T":1788331863016,"m":false,"M":true}}
{"type":"trade","received_at_ms":1788331862909,"data":{"e":"trade","E":1788331863016,"s":"BTCUSDT","t":6646633906,"p":"77581.15000000","q":"0.00007000","T":1788331863016,"m":false,"M":true}}
{"type":"trade","received_at_ms":1788331862909,"data":{"e":"trade","E":1788331863016,"s":"BTCUSDT","t":6646633907,"p":"77581.15000000","q":"0.00007000","T":1788331863016,"m":false,"M":true}}
{"type":"trade","received_at_ms":1788331862909,"data":{"e":"trade","E":1788331863016,"s":"BTCUSDT","t":6646633908,"p":"77581.15000000","q":"0.00007000","T":1788331863016,"m":false,"M":true}}
{"type":"trade","received_at_ms":1788331862909,"data":{"e":"trade","E":1788331863016,"s":"BTCUSDT","t":6646633909,"p":"77581.15000000","q":"0.00008000","T":1788331863016,"m":false,"M":true}}
{"type":"trade","received_at_ms":1788331862909,"data":{"e":"trade","E":1788331863016,"s":"BTCUSDT","t":6646633910,"p":"77581.15000000","q":"0.00013000","T":1788331863016,"m":false,"M":true}}
{"type":"trade","received_at_ms":1788331862909,"data":{"e":"trade","E":1788331863016,"s":"BTCUSDT","t":6646633911,"p":"77581.15000000","q":"0.00007000","T":1788331863016,"m":false,"M":true}}
{"type":"trade","received_at_ms":1788331862909,"data":{"e":"trade","E":1788331863016,"s":"BTCUSDT","t":6646633912,"p":"77581.15000000","q":"0.00007000","T":1788331863016,"m":false,"M":true}}
{"type":"trade","received_at_ms":1788331862909,"data":{"e":"trade","E":1788331863016,"s":"BTCUSDT","t":6646633913,"p":"77581.15000000","q":"0.00007000","T":1788331863016,"m":false,"M":true}}
{"type":"trade","received_at_ms":1788331862909,"data":{"e":"trade","E":1788331863016,"s":"BTCUSDT","t":6646633914,"p":"77581.15000000","q":"0.00007000","T":1788331863016,"m":false,"M":true}}
{"type":"trade","received_at_ms":1788331862909,"data":{"e":"trade","E":1788331863016,"s":"BTCUSDT","t":6646633915,"p":"77581.15000000","q":"0.00047000","T":1788331863016,"m":false,"M":true}}
{"type":"trade","received_at_ms":1788331862909,"data":{"e":"trade","E":1788331863016,"s":"BTCUSDT","t":6646633916,"p":"77581.15000000","q":"0.00007000","T":1788331863016,"m":false,"M":true}}
{"type":"trade","received_at_ms":1788331862909,"data":{"e":"trade","E":1788331863016,"s":"BTCUSDT","t":6646633917,"p":"77581.15000000","q":"0.00007000","T":1788331863016,"m":false,"M":true}}
{"type":"trade","received_at_ms":1788331862909,"data":{"e":"trade","E":1788331863016,"s":"BTCUSDT","t":6646633918,"p":"77581.15000000","q":"0.00042000","T":1788331863016,"m":false,"M":true}}
{"type":"trade","received_at_ms":1788331862909,"data":{"e":"trade","E":1788331863016,"s":"BTCUSDT","t":6646633919,"p":"77581.15000000","q":"0.03223000","T":1788331863016,"m":false,"M":true}}
{"type":"trade","received_at_ms":1788331862909,"data":{"e":"trade","E":1788331863016,"s":"BTCUSDT","t":6646633920,"p":"77581.15000000","q":"0.00007000","T":1788331863016,"m":false,"M":true}}
{"type":"trade","received_at_ms":1788331862909,"data":{"e":"trade","E":1788331863016,"s":"BTCUSDT","t":6646633921,"p":"77581.15000000","q":"0.00007000","T":1788331863016,"m":false,"M":true}}
{"type":"trade","received_at_ms":1788331862909,"data":{"e":"trade","E":1788331863016,"s":"BTCUSDT","t":6646633922,"p":"77581.15000000","q":"0.00007000","T":1788331863016,"m":false,"M":true}}
{"type":"trade","received_at_ms":1788331862909,"data":{"e":"trade","E":1788331863016,"s":"BTCUSDT","t":6646633923,"p":"77581.15000000","q":"0.00322000","T":1788331863016,"m":false,"M":true}}
{"type":"trade","received_at_ms":1788331862909,"data":{"e":"trade","E":1788331863016,"s":"BTCUSDT","t":6646633924,"p":"77581.15000000","q":"0.00323000","T":1788331863016,"m":false,"M":true}}
{"type":"trade","received_at_ms":1788331862909,"data":{"e":"trade","E":1788331863016,"s":"BTCUSDT","t":6646633925,"p":"77581.15000000","q":"0.00065000","T":1788331863016,"m":false,"M":true}}
{"type":"trade","received_at_ms":1788331862909,"data":{"e":"trade","E":1788331863016,"s":"BTCUSDT","t":6646633926,"p":"77581.15000000","q":"0.00064000","T":1788331863016,"m":false,"M":true}}
{"type":"trade","received_at_ms":1788331862909,"data":{"e":"trade","E":1788331863016,"s":"BTCUSDT","t":6646633927,"p":"77581.15000000","q":"0.00010000","T":1788331863016,"m":false,"M":true}}
{"type":"trade","received_at_ms":1788331862909,"data":{"e":"trade","E":1788331863016,"s":"BTCUSDT","t":6646633928,"p":"77581.15000000","q":"0.00068000","T":1788331863016,"m":false,"M":true}}
{"type":"trade","received_at_ms":1788331862909,"data":{"e":"trade","E":1788331863016,"s":"BTCUSDT","t":6646633929,"p":"77581.15000000","q":"0.00007000","T":1788331863016,"m":false,"M":true}}
{"type":"trade","received_at_ms":1788331862909,"data":{"e":"trade","E":1788331863016,"s":"BTCUSDT","t":6646633930,"p":"77581.15000000","q":"0.00007000","T":1788331863016,"m":false,"M":true}}
{"type":"trade","received_at_ms":1788331862909,"data":{"e":"trade","E":1788331863016,"s":"BTCUSDT","t":6646633931,"p":"77581.15000000","q":"0.00560000","T":1788331863016,"m":false,"M":true}}
{"type":"trade","received_at_ms":1788331862909,"data":{"e":"trade","E":1788331863016,"s":"BTCUSDT","t":6646633932,"p":"77581.15000000","q":"0.00129000","T":1788331863016,"m":false,"M":true}}
{"type":"trade","received_at_ms":1788331862909,"data":{"e":"trade","E":1788331863016,"s":"BTCUSDT","t":6646633933,"p":"77581.15000000","q":"0.00400000","T":1788331863016,"m":false,"M":true}}
{"type":"trade","received_at_ms":1788331862909,"data":{"e":"trade","E":1788331863016,"s":"BTCUSDT","t":6646633934,"p":"77581.15000000","q":"0.00519000","T":1788331863016,"m":false,"M":true}}
{"type":"trade","received_at_ms":1788331862910,"data":{"e":"trade","E":1788331863016,"s":"BTCUSDT","t":6646633935,"p":"77581.15000000","q":"0.00015000","T":1788331863016,"m":false,"M":true}}
{"type":"trade","received_at_ms":1788331862910,"data":{"e":"trade","E":1788331863016,"s":"BTCUSDT","t":6646633936,"p":"77581.15000000","q":"0.00007000","T":1788331863016,"m":false,"M":true}}
{"type":"trade","received_at_ms":1788331862910,"data":{"e":"trade","E":1788331863016,"s":"BTCUSDT","t":6646633937,"p":"77581.15000000","q":"0.00007000","T":1788331863016,"m":false,"M":true}}
{"type":"trade","received_at_ms":1788331862910,"data":{"e":"trade","E":1788331863016,"s":"BTCUSDT","t":6646633938,"p":"77581.15000000","q":"0.00007000","T":1788331863016,"m":false,"M":true}}
{"type":"trade","received_at_ms":1788331862910,"data":{"e":"trade","E":1788331863016,"s":"BTCUSDT","t":6646633939,"p":"77581.15000000","q":"0.00007000","T":1788331863016,"m":false,"M":true}}
{"type":"trade","received_at_ms":1788331862910,"data":{"e":"trade","E":1788331863016,"s":"BTCUSDT","t":6646633940,"p":"77581.15000000","q":"0.00007000","T":1788331863016,"m":false,"M":true}}
{"type":"trade","received_at_ms":1788331862910,"data":{"e":"trade","E":1788331863016,"s":"BTCUSDT","t":6646633941,"p":"77581.15000000","q":"0.00007000","T":1788331863016,"m":false,"M":true}}
{"type":"trade","received_at_ms":1788331862910,"data":{"e":"trade","E":1788331863016,"s":"BTCUSDT","t":6646633942,"p":"77581.15000000","q":"0.00007000","T":1788331863016,"m":false,"M":true}}
{"type":"trade","received_at_ms":1788331862910,"data":{"e":"trade","E":1788331863016,"s":"BTCUSDT","t":6646633943,"p":"77581.15000000","q":"0.00007000","T":1788331863016,"m":false,"M":true}}
{"type":"trade","received_at_ms":1788331862910,"data":{"e":"trade","E":1788331863016,"s":"BTCUSDT","t":6646633944,"p":"77581.15000000","q":"0.00007000","T":1788331863016,"m":false,"M":true}}
{"type":"trade","received_at_ms":1788331862910,"data":{"e":"trade","E":1788331863016,"s":"BTCUSDT","t":6646633945,"p":"77581.15000000","q":"0.00007000","T":1788331863016,"m":false,"M":true}}
{"type":"trade","received_at_ms":1788331862910,"data":{"e":"trade","E":1788331863016,"s":"BTCUSDT","t":6646633946,"p":"77581.15000000","q":"0.00007000","T":1788331863016,"m":false,"M":true}}
{"type":"trade","received_at_ms":1788331862910,"data":{"e":"trade","E":1788331863016,"s":"BTCUSDT","t":6646633947,"p":"77581.16000000","q":"0.00007000","T":1788331863016,"m":false,"M":true}}
{"type":"trade","received_at_ms":1788331862910,"data":{"e":"trade","E":1788331863016,"s":"BTCUSDT","t":6646633948,"p":"77581.16000000","q":"0.00007000","T":1788331863016,"m":false,"M":true}}
{"type":"trade","received_at_ms":1788331862910,"data":{"e":"trade","E":1788331863016,"s":"BTCUSDT","t":6646633949,"p":"77581.16000000","q":"0.00013000","T":1788331863016,"m":false,"M":true}}
{"type":"trade","received_at_ms":1788331862910,"data":{"e":"trade","E":1788331863016,"s":"BTCUSDT","t":6646633950,"p":"77581.16000000","q":"0.00007000","T":1788331863016,"m":false,"M":true}}
{"type":"trade","received_at_ms":1788331862910,"data":{"e":"trade","E":1788331863016,"s":"BTCUSDT","t":6646633951,"p":"77581.16000000","q":"0.00007000","T":1788331863016,"m":false,"M":true}}
{"type":"trade","received_at_ms":1788331862910,"data":{"e":"trade","E":1788331863016,"s":"BTCUSDT","t":6646633952,"p":"77581.16000000","q":"0.00007000","T":1788331863016,"m":false,"M":true}}
{"type":"trade","received_at_ms":1788331862910,"data":{"e":"trade","E":1788331863016,"s":"BTCUSDT","t":6646633953,"p":"77581.16000000","q":"0.00007000","T":1788331863016,"m":false,"M":true}}
{"type":"trade","received_at_ms":1788331862910,"data":{"e":"trade","E":1788331863016,"s":"BTCUSDT","t":6646633954,"p":"77581.16000000","q":"0.00007000","T":1788331863016,"m":false,"M":true}}
{"type":"trade","received_at_ms":1788331862910,"data":{"e":"trade","E":1788331863016,"s":"BTCUSDT","t":6646633955,"p":"77581.16000000","q":"0.00007000","T":1788331863016,"m":false,"M":true}}
{"type":"trade","received_at_ms":1788331862910,"data":{"e":"trade","E":1788331863016,"s":"BTCUSDT","t":6646633956,"p":"77581.17000000","q":"0.00013000","T":1788331863016,"m":false,"M":true}}
{"type":"trade","received_at_ms":1788331862910,"data":{"e":"trade","E":1788331863016,"s":"BTCUSDT","t":6646633957,"p":"77581.24000000","q":"0.00007000","T":1788331863016,"m":false,"M":true}}
{"type":"trade","received_at_ms":1788331862910,"data":{"e":"trade","E":1788331863016,"s":"BTCUSDT","t":6646633958,"p":"77581.24000000","q":"0.00007000","T":1788331863016,"m":false,"M":true}}
{"type":"trade","received_at_ms":1788331862910,"data":{"e":"trade","E":1788331863016,"s":"BTCUSDT","t":6646633959,"p":"77581.24000000","q":"0.00007000","T":1788331863016,"m":false,"M":true}}
{"type":"trade","received_at_ms":1788331862910,"data":{"e":"trade","E":1788331863016,"s":"BTCUSDT","t":6646633960,"p":"77581.24000000","q":"0.00007000","T":1788331863016,"m":false,"M":true}}
{"type":"trade","received_at_ms":1788331862910,"data":{"e":"trade","E":1788331863016,"s":"BTCUSDT","t":6646633961,"p":"77581.24000000","q":"0.00007000","T":1788331863016,"m":false,"M":true}}
{"type":"trade","received_at_ms":1788331862910,"data":{"e":"trade","E":1788331863016,"s":"BTCUSDT","t":6646633962,"p":"77581.30000000","q":"0.00007000","T":1788331863016,"m":false,"M":true}}
{"type":"trade","received_at_ms":1788331862910,"data":{"e":"trade","E":1788331863016,"s":"BTCUSDT","t":6646633963,"p":"77581.30000000","q":"0.00007000","T":1788331863016,"m":false,"M":true}}
{"type":"trade","received_at_ms":1788331862910,"data":{"e":"trade","E":1788331863016,"s":"BTCUSDT","t":6646633964,"p":"77581.30000000","q":"0.00007000","T":1788331863016,"m":false,"M":true}}
{"type":"trade","received_at_ms":1788331862910,"data":{"e":"trade","E":1788331863016,"s":"BTCUSDT","t":6646633965,"p":"77581.30000000","q":"0.00007000","T":1788331863016,"m":false,"M":true}}
{"type":"trade","received_at_ms":1788331862910,"data":{"e":"trade","E":1788331863016,"s":"BTCUSDT","t":6646633966,"p":"77581.30000000","q":"0.00007000","T":1788331863016,"m":false,"M":true}}
{"type":"trade","received_at_ms":1788331862910,"data":{"e":"trade","E":1788331863016,"s":"BTCUSDT","t":6646633967,"p":"77581.30000000","q":"0.00007000","T":1788331863016,"m":false,"M":true}}
{"type":"trade","received_at_ms":1788331862910,"data":{"e":"trade","E":1788331863016,"s":"BTCUSDT","t":6646633968,"p":"77581.30000000","q":"0.00007000","T":1788331863016,"m":false,"M":true}}
{"type":"trade","received_at_ms":1788331862910,"data":{"e":"trade","E":1788331863016,"s":"BTCUSDT","t":6646633969,"p":"77581.70000000","q":"0.00007000","T":1788331863016,"m":false,"M":true}}
{"type":"trade","received_at_ms":1788331862910,"data":{"e":"trade","E":1788331863016,"s":"BTCUSDT","t":6646633970,"p":"77581.70000000","q":"0.00007000","T":1788331863016,"m":false,"M":true}}
{"type":"trade","received_at_ms":1788331862910,"data":{"e":"trade","E":1788331863016,"s":"BTCUSDT","t":6646633971,"p":"77581.75000000","q":"0.00007000","T":1788331863016,"m":false,"M":true}}
{"type":"trade","received_at_ms":1788331862910,"data":{"e":"trade","E":1788331863016,"s":"BTCUSDT","t":6646633972,"p":"77581.75000000","q":"0.00007000","T":1788331863016,"m":false,"M":true}}
{"type":"trade","received_at_ms":1788331862910,"data":{"e":"trade","E":1788331863016,"s":"BTCUSDT","t":6646633973,"p":"77581.85000000","q":"0.00007000","T":1788331863016,"m":false,"M":true}}
{"type":"trade","received_at_ms":1788331862910,"data":{"e":"trade","E":1788331863016,"s":"BTCUSDT","t":6646633974,"p":"77581.85000000","q":"0.00007000","T":1788331863016,"m":false,"M":true}}
{"type":"trade","received_at_ms":1788331862910,"data":{"e":"trade","E":1788331863016,"s":"BTCUSDT","t":6646633975,"p":"77581.85000000","q":"0.00007000","T":1788331863016,"m":false,"M":true}}
{"type":"trade","received_at_ms":1788331862910,"data":{"e":"trade","E":1788331863016,"s":"BTCUSDT","t":6646633976,"p":"77581.85000000","q":"0.00007000","T":1788331863016,"m":false,"M":true}}
{"type":"trade","received_at_ms":1788331862910,"data":{"e":"trade","E":1788331863016,"s":"BTCUSDT","t":6646633977,"p":"77581.85000000","q":"0.00007000","T":1788331863016,"m":false,"M":true}}
{"type":"trade","received_at_ms":1788331862910,"data":{"e":"trade","E":1788331863016,"s":"BTCUSDT","t":6646633978,"p":"77581.94000000","q":"0.00007000","T":1788331863016,"m":false,"M":true}}
{"type":"trade","received_at_ms":1788331862910,"data":{"e":"trade","E":1788331863016,"s":"BTCUSDT","t":6646633979,"p":"77581.94000000","q":"0.00007000","T":1788331863016,"m":false,"M":true}}
{"type":"trade","received_at_ms":1788331862910,"data":{"e":"trade","E":1788331863016,"s":"BTCUSDT","t":6646633980,"p":"77581.94000000","q":"0.00007000","T":1788331863016,"m":false,"M":true}}
{"type":"trade","received_at_ms":1788331862910,"data":{"e":"trade","E":1788331863016,"s":"BTCUSDT","t":6646633981,"p":"77581.94000000","q":"0.00007000","T":1788331863016,"m":false,"M":true}}
{"type":"trade","received_at_ms":1788331862911,"data":{"e":"trade","E":1788331863016,"s":"BTCUSDT","t":6646633982,"p":"77581.94000000","q":"0.00007000","T":1788331863016,"m":false,"M":true}}
{"type":"trade","received_at_ms":1788331862911,"data":{"e":"trade","E":1788331863016,"s":"BTCUSDT","t":6646633983,"p":"77581.95000000","q":"0.00007000","T":1788331863016,"m":false,"M":true}}
{"type":"trade","received_at_ms":1788331862911,"data":{"e":"trade","E":1788331863016,"s":"BTCUSDT","t":6646633984,"p":"77582.01000000","q":"0.00007000","T":1788331863016,"m":false,"M":true}}
{"type":"trade","received_at_ms":1788331862911,"data":{"e":"trade","E":1788331863016,"s":"BTCUSDT","t":6646633985,"p":"77582.01000000","q":"0.00007000","T":1788331863016,"m":false,"M":true}}
{"type":"trade","received_at_ms":1788331862911,"data":{"e":"trade","E":1788331863016,"s":"BTCUSDT","t":6646633986,"p":"77582.01000000","q":"0.00007000","T":1788331863016,"m":false,"M":true}}
{"type":"trade","received_at_ms":1788331862911,"data":{"e":"trade","E":1788331863016,"s":"BTCUSDT","t":6646633987,"p":"77582.01000000","q":"0.00007000","T":1788331863016,"m":false,"M":true}}
{"type":"trade","received_at_ms":1788331862911,"data":{"e":"trade","E":1788331863016,"s":"BTCUSDT","t":6646633988,"p":"77582.01000000","q":"0.00007000","T":1788331863016,"m":false,"M":true}}
{"type":"trade","received_at_ms":1788331862911,"data":{"e":"trade","E":1788331863016,"s":"BTCUSDT","t":6646633989,"p":"77582.13000000","q":"0.00007000","T":1788331863016,"m":false,"M":true}}
{"type":"trade","received_at_ms":1788331862911,"data":{"e":"trade","E":1788331863016,"s":"BTCUSDT","t":6646633990,"p":"77582.13000000","q":"0.00007000","T":1788331863016,"m":false,"M":true}}
{"type":"trade","received_at_ms":1788331862911,"data":{"e":"trade","E":1788331863016,"s":"BTCUSDT","t":6646633991,"p":"77582.24000000","q":"0.00007000","T":1788331863016,"m":false,"M":true}}
{"type":"trade","received_at_ms":1788331862911,"data":{"e":"trade","E":1788331863016,"s":"BTCUSDT","t":6646633992,"p":"77582.24000000","q":"0.00007000","T":1788331863016,"m":false,"M":true}}
{"type":"trade","received_at_ms":1788331862911,"data":{"e":"trade","E":1788331863016,"s":"BTCUSDT","t":6646633993,"p":"77582.24000000","q":"0.00007000","T":1788331863016,"m":false,"M":true}}
{"type":"trade","received_at_ms":1788331862911,"data":{"e":"trade","E":1788331863016,"s":"BTCUSDT","t":6646633994,"p":"77582.24000000","q":"0.00007000","T":1788331863016,"m":false,"M":true}}
{"type":"trade","received_at_ms":1788331862911,"data":{"e":"trade","E":1788331863016,"s":"BTCUSDT","t":6646633995,"p":"77582.24000000","q":"0.00007000","T":1788331863016,"m":false,"M":true}}
{"type":"trade","received_at_ms":1788331862911,"data":{"e":"trade","E":1788331863016,"s":"BTCUSDT","t":6646633996,"p":"77582.25000000","q":"0.00007000","T":1788331863016,"m":false,"M":true}}
{"type":"trade","received_at_ms":1788331862911,"data":{"e":"trade","E":1788331863016,"s":"BTCUSDT","t":6646633997,"p":"77582.25000000","q":"0.00007000","T":1788331863016,"m":false,"M":true}}
{"type":"trade","received_at_ms":1788331862911,"data":{"e":"trade","E":1788331863016,"s":"BTCUSDT","t":6646633998,"p":"77582.25000000","q":"0.00007000","T":1788331863016,"m":false,"M":true}}
{"type":"trade","received_at_ms":1788331862911,"data":{"e":"trade","E":1788331863016,"s":"BTCUSDT","t":6646633999,"p":"77582.25000000","q":"0.00007000","T":1788331863016,"m":false,"M":true}}
{"type":"trade","received_at_ms":1788331862911,"data":{"e":"trade","E":1788331863016,"s":"BTCUSDT","t":6646634000,"p":"77582.25000000","q":"0.00007000","T":1788331863016,"m":false,"M":true}}
{"type":"trade","received_at_ms":1788331862911,"data":{"e":"trade","E":1788331863016,"s":"BTCUSDT","t":6646634001,"p":"77582.39000000","q":"0.00007000","T":1788331863016,"m":false,"M":true}}
{"type":"trade","received_at_ms":1788331862911,"data":{"e":"trade","E":1788331863016,"s":"BTCUSDT","t":6646634002,"p":"77582.39000000","q":"0.00007000","T":1788331863016,"m":false,"M":true}}
{"type":"trade","received_at_ms":1788331862911,"data":{"e":"trade","E":1788331863016,"s":"BTCUSDT","t":6646634003,"p":"77582.39000000","q":"0.00007000","T":1788331863016,"m":false,"M":true}}
{"type":"trade","received_at_ms":1788331862911,"data":{"e":"trade","E":1788331863016,"s":"BTCUSDT","t":6646634004,"p":"77582.40000000","q":"0.01856000","T":1788331863016,"m":false,"M":true}}
{"type":"trade","received_at_ms":1788331862911,"data":{"e":"trade","E":1788331863016,"s":"BTCUSDT","t":6646634005,"p":"77582.40000000","q":"0.00007000","T":1788331863016,"m":false,"M":true}}
{"type":"trade","received_at_ms":1788331862911,"data":{"e":"trade","E":1788331863016,"s":"BTCUSDT","t":6646634006,"p":"77582.40000000","q":"0.00007000","T":1788331863016,"m":false,"M":true}}
{"type":"trade","received_at_ms":1788331862911,"data":{"e":"trade","E":1788331863016,"s":"BTCUSDT","t":6646634007,"p":"77582.40000000","q":"0.00007000","T":1788331863016,"m":false,"M":true}}
{"type":"trade","received_at_ms":1788331862911,"data":{"e":"trade","E":1788331863016,"s":"BTCUSDT","t":6646634008,"p":"77582.40000000","q":"0.00007000","T":1788331863016,"m":false,"M":true}}
{"type":"trade","received_at_ms":1788331862911,"data":{"e":"trade","E":1788331863016,"s":"BTCUSDT","t":6646634009,"p":"77582.54000000","q":"0.00007000","T":1788331863016,"m":false,"M":true}}
{"type":"trade","received_at_ms":1788331862911,"data":{"e":"trade","E":1788331863016,"s":"BTCUSDT","t":6646634010,"p":"77582.72000000","q":"0.00007000","T":1788331863016,"m":false,"M":true}}
{"type":"trade","received_at_ms":1788331862911,"data":{"e":"trade","E":1788331863016,"s":"BTCUSDT","t":6646634011,"p":"77582.83000000","q":"0.00007000","T":1788331863016,"m":false,"M":true}}
{"type":"trade","received_at_ms":1788331862911,"data":{"e":"trade","E":1788331863016,"s":"BTCUSDT","t":6646634012,"p":"77582.83000000","q":"0.00007000","T":1788331863016,"m":false,"M":true}}
{"type":"trade","received_at_ms":1788331862911,"data":{"e":"trade","E":1788331863016,"s":"BTCUSDT","t":6646634013,"p":"77582.83000000","q":"0.00007000","T":1788331863016,"m":false,"M":true}}
{"type":"depth","received_at_ms":1788331863005,"data":{"e":"depthUpdate","E":1788331863114,"s":"BTCUSDT","U":99555818495,"u":99555819017,"b":[["77582.83000000","5.65347000"],["77582.82000000","0.00055000"],["77582.81000000","0.00027000"],["77582.80000000","0.05007000"],["77582.76000000","0.00014000"],["77582.75000000","0.05000000"],["77582.71000000","0.00000000"],["77582.54000000","0.00414000"],["77582.40000000","0.00014000"],["77582.39000000","1.07552000"],["77582.24000000","0.00000000"],["77582.23000000","0.00000000"],["77582.12000000","0.00000000"],["77582.00000000","0.00000000"],["77581.93000000","0.00000000"],["77581.84000000","0.00000000"],["77581.74000000","0.00000000"],["77581.69000000","0.00000000"],["77581.29000000","0.00000000"],["77581.23000000","0.00000000"],["77581.16000000","0.00007000"],["77581.15000000","1.76750000"],["77581.14000000","2.40458000"],["77581.13000000","0.04279000"],["77581.12000000","0.00000000"],["77581.11000000","0.00000000"],["77581.10000000","0.00021000"],["77581.06000000","0.00000000"],["77581.05000000","0.00014000"],["77580.63000000","0.00000000"],["77580.62000000","0.00014000"],["77580.61000000","0.00021000"],["77580.35000000","0.00000000"],["77580.14000000","0.01297000"],["77580.00000000","0.03061000"],["77579.70000000","0.15433000"],["77579.68000000","0.00000000"],["77578.99000000","0.00000000"],["77578.44000000","0.00000000"],["77578.02000000","0.00000000"],["77578.00000000","0.03028000"],["77577.80000000","0.00027000"],["77577.76000000","0.00007000"],["77577.29000000","0.00200000"],["77576.76000000","0.00400000"],["77576.74000000","0.00000000"],["77575.39000000","0.00000000"],["77574.98000000","0.00800000"],["77574.14000000","0.00000000"],["77573.77000000","0.00000000"],["77572.94000000","0.00000000"],["77572.90000000","0.00000000"],["77572.01000000","0.24738000"],["77571.93000000","0.00000000"],["77571.66000000","0.00000000"],["77570.18000000","0.00007000"],["77570.01000000","0.62862000"],["77566.52000000","0.00000000"],["77562.46000000","0.00000000"],["77551.50000000","0.00000000"],["77544.00000000","0.04000000"],["77543.14000000","0.00000000"],["77542.00000000","0.03000000"],["77529.28000000","0.00427000"],["77517.13000000","0.00320000"],["77517.00000000","0.00000000"],["77516.01000000","0.00000000"],["77515.08000000","0.02412000"],["77512.01000000","0.00321000"],["77511.66000000","0.00322000"],["77510.03000000","0.00000000"],["77509.99000000","0.00000000"],["77497.93000000","0.00007000"],["77494.03000000","0.00000000"],["77484.07000000","0.00000000"],["77440.27000000","0.00128000"],["77438.27000000","0.00000000"],["77433.93000000","0.00128000"],["77431.01000000","0.00000000"],["77351.68000000","0.00015000"],["76417.42000000","0.00000000"],["69824.55000000","0.00032000"],["69823.03000000","0.00000000"],["65946.56000000","0.00068000"],["65945.41000000","0.00017000"]],"a":[["77581.15000000","0.00000000"],["77581.16000000","0.00000000"],["77581.17000000","0.00000000"],["77581.24000000","0.00000000"],["77581.30000000","0.00000000"],["77581.70000000","0.00000000"],["77581.75000000","0.00000000"],["77581.85000000","0.00000000"],["77581.94000000","0.00000000"],["77581.95000000","0.00000000"],["77582.01000000","0.00000000"],["77582.13000000","0.00000000"],["77582.24000000","0.00000000"],["77582.25000000","0.00000000"],["77582.39000000","0.00000000"],["77582.40000000","0.00000000"],["77582.54000000","0.00000000"],["77582.72000000","0.00000000"],["77582.83000000","0.00000000"],["77582.84000000","0.66022000"],["77582.85000000","0.00056000"],["77583.63000000","0.00000000"],["77583.64000000","0.00014000"],["77583.86000000","0.02928000"],["77583.87000000","0.00014000"],["77584.08000000","0.00000000"],["77584.09000000","0.00000000"],["77584.81000000","0.00000000"],["77584.87000000","0.00000000"],["77584.88000000","0.00035000"],["77585.54000000","0.00014000"],["77585.55000000","0.11042000"],["77585.57000000","0.01282000"],["77586.35000000","0.00000000"],["77586.38000000","0.00000000"],["77586.42000000","0.00014000"],["77586.54000000","0.00000000"],["77587.02000000","0.00014000"],["77587.03000000","0.11475000"],["77587.06000000","0.00250000"],["77587.10000000","0.01250000"],["77588.49000000","0.00014000"],["77588.50000000","0.11468000"],["77588.52000000","0.00000000"],["77588.53000000","0.00007000"],["77588.54000000","0.30014000"],["77588.91000000","0.46919000"],["77589.34000000","0.30007000"],["77589.40000000","0.30007000"],["77590.30000000","0.00000000"],["77590.42000000","0.00007000"],["77590.43000000","0.00000000"],["77591.88000000","0.00069000"],["77592.31000000","0.03000000"],["77592.33000000","0.00000000"],["77592.76000000","0.00000000"],["77592.84000000","0.00400000"],["77593.00000000","0.00000000"],["77593.52000000","0.00000000"],["77593.53000000","0.00200000"],["77593.70000000","0.00000000"],["77594.11000000","0.11447000"],["77594.14000000","0.00000000"],["77594.19000000","0.00400000"],["77594.36000000","0.00007000"],["77594.68000000","0.00644000"],["77595.34000000","0.00644000"],["77595.80000000","0.00000000"],["77596.22000000","0.00000000"],["77596.23000000","0.45577000"],["77597.02000000","0.00400000"],["77597.63000000","0.00000000"],["77598.30000000","0.00007000"],["77598.91000000","0.00000000"],["77599.68000000","0.00000000"],["77599.78000000","0.01600000"],["77600.22000000","0.72826000"],["77602.87000000","0.00000000"],["77603.99000000","0.00000000"],["77605.06000000","0.00000000"],["77605.10000000","0.35158000"],["77607.81000000","0.99255000"],["77607.99000000","0.00007000"],["77608.58000000","0.25791000"],["77609.50000000","0.00000000"],["77610.18000000","0.00000000"],["77612.74000000","0.00038000"],["77614.88000000","0.00200000"],["77615.49000000","0.00000000"],["77616.78000000","0.34802000"],["77620.00000000","0.03200000"],["77622.00000000","0.05344000"],["77625.22000000","0.00400000"],["77625.88000000","0.00007000"],["77637.99000000","0.00000000"],["77639.54000000","0.00322000"],["77640.69000000","0.00000000"],["77641.91000000","0.00000000"],["77642.04000000","0.00322000"],["77677.04000000","0.00000000"],["77681.52000000","0.00007000"],["77681.85000000","0.75095000"],["77684.45000000","0.00000000"],["77687.04000000","2.15391000"],["77715.99000000","0.00000000"],["77717.36000000","0.00128000"],["77717.99000000","0.00000000"],["77719.74000000","0.00128000"],["77816.07000000","0.00000000"],["77818.21000000","0.00000000"],["78744.87000000","0.00000000"]]}}
{"type":"trade","received_at_ms":1788331863005,"data":{"e":"trade","E":1788331863119,"s":"BTCUSDT","t":6646634014,"p":"77582.84000000","q":"0.03223000","T":1788331863118,"m":false,"M":true}}
{"type":"trade","received_at_ms":1788331863034,"data":{"e":"trade","E":1788331863174,"s":"BTCUSDT","t":6646634015,"p":"77582.83000000","q":"0.00100000","T":1788331863174,"m":true,"M":true}}
{"type":"depth","received_at_ms":1788331863112,"data":{"e":"depthUpdate","E":1788331863214,"s":"BTCUSDT","U":99555819018,"u":99555819145,"b":[["77582.83000000","6.18213000"],["77582.82000000","0.00062000"],["77582.81000000","0.07802000"],["77582.80000000","0.05021000"],["77582.75000000","0.05014000"],["77582.39000000","1.07566000"],["77581.15000000","1.76757000"],["77581.14000000","2.37458000"],["77581.13000000","0.04265000"],["77581.10000000","0.00000000"],["77581.05000000","0.00000000"],["77580.89000000","0.00000000"],["77580.62000000","0.00000000"],["77580.61000000","0.00007000"],["77580.14000000","0.01311000"],["77580.00000000","0.03047000"],["77579.69000000","0.07782000"],["77578.86000000","0.00551000"],["77577.62000000","0.00919000"],["77577.29000000","0.00000000"],["77576.38000000","0.01103000"],["77575.34000000","0.00200000"],["77575.14000000","0.01103000"],["77530.47000000","0.00436000"],["77518.57000000","0.00000000"],["76882.91000000","0.00000000"],["71374.65000000","0.00000000"],["62064.92000000","0.00000000"]],"a":[["77582.84000000","0.66990000"],["77582.85000000","0.00070000"],["77583.49000000","0.00014000"],["77583.50000000","0.01320000"],["77583.51000000","0.00007000"],["77583.64000000","0.00000000"],["77583.86000000","0.02928000"],["77583.87000000","0.00000000"],["77584.08000000","0.00014000"],["77584.09000000","0.01665000"],["77584.27000000","0.00000000"],["77584.88000000","0.00014000"],["77585.32000000","0.00014000"],["77585.33000000","0.01990000"],["77585.55000000","0.11042000"],["77585.56000000","0.00000000"],["77585.57000000","0.01303000"],["77585.71000000","0.00000000"],["77585.81000000","0.00007000"],["77586.42000000","0.00000000"],["77586.57000000","0.01990000"],["77587.02000000","0.00000000"],["77587.03000000","0.11475000"],["77587.10000000","0.01264000"],["77588.49000000","0.00000000"],["77588.50000000","0.11468000"],["77588.53000000","0.00000000"],["77588.54000000","0.30028000"],["77588.59000000","0.30014000"],["77590.01000000","0.12127000"],["77591.52000000","0.00047000"],["77592.30000000","0.00000000"],["77596.84000000","0.00257000"]]}}
{"type":"trade","received_at_ms":1788331863112,"data":{"e":"trade","E":1788331863245,"s":"BTCUSDT","t":6646634016,"p":"77582.84000000","q":"0.03867000","T":1788331863245,"m":false,"M":true}}
{"type":"trade","received_at_ms":1788331863112,"data":{"e":"trade","E":1788331863249,"s":"BTCUSDT","t":6646634017,"p":"77582.84000000","q":"0.02578000","T":1788331863249,"m":false,"M":true}}
{"type":"trade","received_at_ms":1788331863112,"data":{"e":"trade","E":1788331863252,"s":"BTCUSDT","t":6646634018,"p":"77582.84000000","q":"0.01161000","T":1788331863251,"m":false,"M":true}}
{"type":"depth","received_at_ms":1788331863172,"data":{"e":"depthUpdate","E":1788331863314,"s":"BTCUSDT","U":99555819146,"u":99555819210,"b":[["77582.83000000","6.20977000"],["77580.69000000","0.00097000"],["77580.43000000","0.00257000"],["77575.57000000","0.03867000"],["77552.75000000","0.00000000"],["77378.67000000","0.00813000"],["77373.13000000","0.00000000"],["69824.55000000","0.00064000"],["69824.00000000","0.00000000"],["62066.26000000","0.00000000"]],"a":[["77582.84000000","0.59384000"],["77583.50000000","0.01334000"],["77583.86000000","0.02928000"],["77584.09000000","0.01679000"],["77585.33000000","0.02004000"],["77585.57000000","0.01303000"],["77586.57000000","0.02004000"],["77587.10000000","0.01257000"],["77588.40000000","0.12508000"],["77588.50000000","0.11454000"],["77588.54000000","0.30014000"],["77588.59000000","0.30000000"],["77590.42000000","0.00014000"],["77592.34000000","0.00329000"],["77593.53000000","0.00000000"],["77594.36000000","0.00014000"],["77595.94000000","0.00257000"],["77596.22000000","0.00200000"],["77596.84000000","0.00000000"],["77598.30000000","0.00014000"],["77639.55000000","0.00000000"],["77641.91000000","0.00412000"],["77653.11000000","0.00111000"],["77687.03000000","1.63709000"],["77688.30000000","0.00000000"]]}}
{"type":"depth","received_at_ms":1788331863273,"data":{"e":"depthUpdate","E":1788331863414,"s":"BTCUSDT","U":99555819211,"u":99555819232,"b":[["77581.96000000","0.00007000"],["77566.12000000","0.00007000"],["77561.86000000","0.00000000"],["69824.55000000","0.00080000"]],"a":[["77582.84000000","0.59135000"],["77587.27000000","0.11343000"],["77588.40000000","0.00000000"],["77592.77000000","0.00000000"],["77592.90000000","0.00000000"],["77593.54000000","0.00000000"],["77595.88000000","0.00000000"],["77596.22000000","0.00200000"],["77596.65000000","0.00000000"],["77596.66000000","0.00008000"],["77597.08000000","0.00000000"],["77597.43000000","0.00000000"],["77597.44000000","0.00000000"],["77597.45000000","0.00000000"],["77623.28000000","0.00408000"],["77625.22000000","0.00000000"]]}}
{"type":"depth","received_at_ms":1788331863374,"data":{"e":"depthUpdate","E":1788331863514,"s":"BTCUSDT","U":99555819233,"u":99555819283,"b":[["77581.13000000","0.04272000"],["77580.86000000","0.04000000"],["77575.79000000","0.00000000"],["77573.10000000","0.02000000"],["77571.55000000","0.04000000"],["77563.55000000","0.00007000"],["77563.42000000","0.00000000"],["77515.08000000","0.02000000"],["77484.06000000","0.00412000"],["69824.55000000","0.00096000"],["62066.27000000","0.00032000"]],"a":[["77582.84000000","0.82952000"],["77585.57000000","0.01310000"],["77586.45000000","0.11573000"],["77587.10000000","0.01250000"],["77587.27000000","0.00000000"],["77588.91000000","0.46877000"],["77590.60000000","0.00033000"],["77594.59000000","0.00007000"],["77596.21000000","0.80042000"],["77596.22000000","1.31471000"],["77596.23000000","0.00000000"],["77596.67000000","0.16870000"],["77598.13000000","0.00200000"],["77598.36000000","0.00033000"],["77600.71000000","0.02000000"],["77601.49000000","0.02600000"],["77603.81000000","0.02800000"],["77604.43000000","0.00000000"],["77604.59000000","0.02400000"],["77605.37000000","0.04600000"],["77606.12000000","0.00033000"],["77612.19000000","0.00000000"],["77613.88000000","0.00033000"],["77641.91000000","0.00000000"],["77663.22000000","0.02000000"],["77663.65000000","0.02600000"],["77666.37000000","0.02800000"],["77667.12000000","0.02400000"],["77667.54000000","0.02400000"],["77667.90000000","0.02200000"],["78746.59000000","0.00030000"]]}}
{"type":"depth","received_at_ms":1788331863495,"data":{"e":"depthUpdate","E":1788331863614,"s":"BTCUSDT","U":99555819284,"u":99555819331,"b":[["77582.83000000","6.21006000"],["77582.82000000","0.00076000"],["77582.81000000","0.07816000"],["77581.13000000","0.04272000"],["77580.14000000","0.01297000"],["77572.33000000","0.02000000"],["69824.55000000","0.00112000"],["62066.27000000","0.00000000"],["62066.26000000","0.00000000"],["62066.00000000","0.00100000"]],"a":[["77582.84000000","0.83165000"],["77585.57000000","0.01310000"],["77586.45000000","0.11587000"],["77587.03000000","0.11461000"],["77591.52000000","0.00000000"],["77596.20000000","0.01800000"],["77598.13000000","0.00000000"],["77599.78000000","0.00000000"],["77604.59000000","0.05000000"],["77615.58000000","0.02062000"],["77616.91000000","0.09458000"],["77663.65000000","0.00000000"],["77666.77000000","0.02600000"]]}}
{"type":"depth","received_at_ms":1788331863612,"data":{"e":"depthUpdate","E":1788331863714,"s":"BTCUSDT","U":99555819332,"u":99555819349,"b":[["77582.83000000","6.20985000"],["77582.82000000","0.00062000"],["77564.97000000","0.00000000"],["77563.43000000","0.00000000"],["77521.00000000","0.00000000"],["69824.55000000","0.00144000"]],"a":[["77582.84000000","0.83158000"],["77585.33000000","0.16008000"],["77585.81000000","0.00000000"],["77586.45000000","0.00014000"],["77621.34000000","0.00400000"],["77623.28000000","0.00008000"],["77666.77000000","0.00000000"],["77667.54000000","0.00000000"]]}}
{"type":"depth","received_at_ms":1788331863709,"data":{"e":"depthUpdate","E":1788331863814,"s":"BTCUSDT","U":99555819350,"u":99555819369,"b":[["77581.42000000","0.00257000"],["77580.43000000","0.00000000"],["77571.89000000","0.02000000"],["77564.21000000","0.00000000"],["69824.55000000","0.00144000"]],"a":[["77585.57000000","0.01303000"],["77586.45000000","0.00000000"],["77587.03000000","0.11475000"],["77595.94000000","0.00000000"],["77596.93000000","0.00257000"],["77605.00000000","0.02000000"],["77661.09000000","0.02000000"],["77667.90000000","0.00000000"]]}}
{"type":"trade","received_at_ms":1788331863709,"data":{"e":"trade","E":1788331863839,"s":"BTCUSDT","t":6646634019,"p":"77582.84000000","q":"0.00009000","T":1788331863838,"m":false,"M":true}}
{"type":"depth","received_at_ms":1788331863816,"data":{"e":"depthUpdate","E":1788331863914,"s":"BTCUSDT","U":99555819370,"u":99555819380,"b":[["77582.83000000","6.20992000"],["77582.82000000","0.00069000"],["77563.74000000","0.00000000"],["76419.08000000","0.00030000"],["69824.55000000","0.00160000"],["69823.02000000","0.00000000"]],"a":[["77582.84000000","0.82999000"],["77584.27000000","0.00007000"],["77616.51000000","0.00000000"],["77663.22000000","0.00000000"]]}}
{"type":"depth","received_at_ms":1788331863874,"data":{"e":"depthUpdate","E":1788331864014,"s":"BTCUSDT","U":99555819381,"u":99555819419,"b":[["77582.83000000","6.28666000"],["77582.55000000","0.00112000"],["77581.43000000","0.00644000"],["77571.50000000","0.02000000"],["77563.36000000","0.00000000"],["77525.02000000","0.00000000"],["69824.55000000","0.00160000"],["62066.27000000","0.00032000"],["62066.00000000","0.00100000"]],"a":[["77582.84000000","0.83019000"],["77582.85000000","0.00083000"],["77582.86000000","0.00013000"],["77584.09000000","0.01686000"],["77584.39000000","0.00014000"],["77584.40000000","0.14344000"],["77585.33000000","0.02004000"],["77585.54000000","0.00000000"],["77587.10000000","0.01257000"],["77588.20000000","0.00208000"],["77588.29000000","0.08219000"],["77602.86000000","0.00000000"],["77604.58000000","0.09622000"],["77605.39000000","0.02800000"],["77616.86000000","0.00007000"],["77661.46000000","0.00000000"],["77666.37000000","0.00000000"],["77667.12000000","0.00000000"]]}}
{"type":"depth","received_at_ms":1788331863973,"data":{"e":"depthUpdate","E":1788331864114,"s":"BTCUSDT","U":99555819420,"u":99555819442,"b":[["77582.83000000","6.29249000"],["77582.75000000","0.05021000"],["77582.39000000","1.07566000"],["77581.14000000","2.35458000"],["77578.00000000","0.03021000"],["77563.67000000","0.12892000"],["69824.55000000","0.00176000"]],"a":[["77584.09000000","0.01686000"],["77584.40000000","0.14358000"],["77587.03000000","0.11461000"],["77667.35000000","0.00007000"],["77677.34000000","0.00000000"],["77679.03000000","0.00025000"]]}}
{"type":"depth","received_at_ms":1788331864073,"data":{"e":"depthUpdate","E":1788331864214,"s":"BTCUSDT","U":99555819443,"u":99555819450,"b":[["77582.83000000","6.31263000"],["77582.82000000","0.00076000"],["76884.58000000","0.00010000"],["62066.27000000","0.00000000"]],"a":[["77582.84000000","0.83026000"],["77582.85000000","0.00090000"]]}}
{"type":"depth","received_at_ms":1788331864174,"data":{"e":"depthUpdate","E":1788331864314,"s":"BTCUSDT","U":99555819451,"u":99555819464,"b":[["77571.50000000","0.04000000"],["77516.79000000","0.00412000"],["75557.06000000","0.00000000"],["69824.55000000","0.00192000"],["62066.26000000","0.00000000"],["62066.00000000","0.00100000"],["62065.00000000","0.00800000"]],"a":[["77605.36000000","0.03000000"],["77661.54000000","0.03000000"],["81001.06000000","0.00000000"]]}}
{"type":"depth","received_at_ms":1788331864275,"data":{"e":"depthUpdate","E":1788331864414,"s":"BTCUSDT","U":99555819465,"u":99555819476,"b":[["77582.83000000","6.31263000"],["77563.37000000","0.00000000"],["77457.01000000","0.00000000"],["69824.55000000","0.00208000"]],"a":[["77582.84000000","0.83186000"],["77616.87000000","0.00000000"]]}}
{"type":"depth","received_at_ms":1788331864376,"data":{"e":"depthUpdate","E":1788331864514,"s":"BTCUSDT","U":99555819477,"u":99555819492,"b":[["77582.83000000","6.31263000"],["77563.55000000","0.00007000"],["77516.79000000","0.00000000"],["77484.06000000","0.00000000"],["69824.00000000","0.00020000"],["62066.27000000","0.00032000"],["62066.00000000","0.00100000"]],"a":[["77594.59000000","0.00007000"],["77643.63000000","0.00412000"],["78746.59000000","0.00030000"]]}}
{"type":"depth","received_at_ms":1788331864475,"data":{"e":"depthUpdate","E":1788331864614,"s":"BTCUSDT","U":99555819493,"u":99555819510,"b":[["77582.83000000","6.31277000"],["77521.01000000","0.02000000"],["69824.55000000","0.00224000"],["69824.00000000","0.00000000"],["62066.27000000","0.00000000"],["62066.26000000","0.00020000"]],"a":[["77582.84000000","0.83511000"],["77584.90000000","0.00000000"],["77702.14000000","0.00000000"],["77712.30000000","0.00108000"]]}}
{"type":"depth","received_at_ms":1788331864575,"data":{"e":"depthUpdate","E":1788331864714,"s":"BTCUSDT","U":99555819511,"u":99555819522,"b":[["77582.83000000","6.31284000"],["69824.55000000","0.00224000"],["62066.26000000","0.00000000"],["62066.00000000","0.00100000"]],"a":[["77582.84000000","0.83504000"],["77582.85000000","0.00083000"]]}}
{"type":"depth","received_at_ms":1788331864675,"data":{"e":"depthUpdate","E":1788331864814,"s":"BTCUSDT","U":99555819523,"u":99555819524,"b":[["69824.55000000","0.00224000"]],"a":[]}}
{"type":"depth","received_at_ms":1788331864782,"data":{"e":"depthUpdate","E":1788331864914,"s":"BTCUSDT","U":99555819525,"u":99555819528,"b":[["76486.08000000","0.00000000"],["76419.08000000","0.00030000"],["69824.55000000","0.00240000"]],"a":[]}}
{"type":"depth","received_at_ms":1788331864885,"data":{"e":"depthUpdate","E":1788331865014,"s":"BTCUSDT","U":99555819529,"u":99555819534,"b":[["77525.02000000","0.02000000"],["69824.55000000","0.00256000"],["62066.27000000","0.00032000"]],"a":[["77661.46000000","0.02800000"]]}}
{"type":"depth","received_at_ms":1788331864976,"data":{"e":"depthUpdate","E":1788331865114,"s":"BTCUSDT","U":99555819535,"u":99555819547,"b":[["77582.83000000","6.31884000"],["77517.14000000","0.00412000"],["69824.55000000","0.00240000"]],"a":[["77582.84000000","0.83504000"],["77588.24000000","0.00333000"],["77590.40000000","0.00000000"],["77598.21000000","0.00159000"]]}}
{"type":"depth","received_at_ms":1788331865086,"data":{"e":"depthUpdate","E":1788331865215,"s":"BTCUSDT","U":99555819548,"u":99555819551,"b":[["75557.06000000","0.00010000"],["69824.55000000","0.00272000"],["62066.27000000","0.00000000"]],"a":[]}}
{"type":"depth","received_at_ms":1788331865173,"data":{"e":"depthUpdate","E":1788331865314,"s":"BTCUSDT","U":99555819552,"u":99555819555,"b":[["69824.55000000","0.00272000"],["62066.26000000","0.00000000"]],"a":[]}}
{"type":"trade","received_at_ms":1788331865193,"data":{"e":"trade","E":1788331865329,"s":"BTCUSDT","t":6646634020,"p":"77582.84000000","q":"0.00382000","T":1788331865329,"m":false,"M":true}}
{"type":"depth","received_at_ms":1788331865273,"data":{"e":"depthUpdate","E":1788331865414,"s":"BTCUSDT","U":99555819556,"u":99555819566,"b":[["77418.28000000","0.00023000"],["69824.55000000","0.00297000"]],"a":[["77582.84000000","0.82972000"],["77684.93000000","0.00087000"],["77705.27000000","0.00000000"],["77744.12000000","0.00000000"],["81001.06000000","0.00010000"]]}}
{"type":"depth","received_at_ms":1788331865376,"data":{"e":"depthUpdate","E":1788331865515,"s":"BTCUSDT","U":99555819567,"u":99555819574,"b":[["77582.83000000","6.32220000"],["77563.55000000","0.00007000"],["62066.27000000","0.00032000"]],"a":[["77582.84000000","0.83122000"],["77594.59000000","0.00007000"],["78746.59000000","0.00030000"]]}}
{"type":"trade","received_at_ms":1788331865414,"data":{"e":"trade","E":1788331865555,"s":"BTCUSDT","t":6646634021,"p":"77582.84000000","q":"0.00257000","T":1788331865555,"m":false,"M":true}}
{"type":"depth","received_at_ms":1788331865473,"data":{"e":"depthUpdate","E":1788331865614,"s":"BTCUSDT","U":99555819575,"u":99555819587,"b":[["69824.55000000","0.00313000"],["62066.27000000","0.00000000"],["62066.00000000","0.00100000"]],"a":[["77582.84000000","0.82865000"]]}}
{"type":"depth","received_at_ms":1788331865573,"data":{"e":"depthUpdate","E":1788331865714,"s":"BTCUSDT","U":99555819588,"u":99555819593,"b":[["69824.55000000","0.00313000"],["69824.00000000","0.00000000"],["62066.26000000","0.00000000"]],"a":[]}}
{"type":"trade","received_at_ms":1788331865614,"data":{"e":"trade","E":1788331865755,"s":"BTCUSDT","t":6646634022,"p":"77582.84000000","q":"0.00100000","T":1788331865755,"m":false,"M":true}}
{"type":"depth","received_at_ms":1788331865673,"data":{"e":"depthUpdate","E":1788331865814,"s":"BTCUSDT","U":99555819594,"u":99555819596,"b":[["69824.55000000","0.00320000"],["69824.54000000","0.00009000"]],"a":[["77582.84000000","0.82765000"]]}}
{"type":"depth","received_at_ms":1788331865774,"data":{"e":"depthUpdate","E":1788331865914,"s":"BTCUSDT","U":99555819597,"u":99555819601,"b":[["76419.08000000","0.00030000"],["69824.55000000","0.00336000"]],"a":[]}}
{"type":"depth","received_at_ms":1788331865874,"data":{"e":"depthUpdate","E":1788331866014,"s":"BTCUSDT","U":99555819602,"u":99555819641,"b":[["77582.83000000","6.32157000"],["77582.82000000","0.00062000"],["69824.55000000","0.00336000"],["62066.27000000","0.00032000"],["62065.00000000","0.00400000"]],"a":[["77582.84000000","0.68818000"],["77582.85000000","0.00076000"],["77584.39000000","0.00000000"],["77584.40000000","0.00014000"],["77585.54000000","0.00007000"],["77585.57000000","0.01310000"],["77586.39000000","0.00241000"],["77586.43000000","0.01205000"],["77587.06000000","0.00000000"],["77587.10000000","0.00007000"],["77588.54000000","0.00014000"],["77588.59000000","0.00000000"],["77592.84000000","0.00000000"],["77593.58000000","0.00400000"],["77596.22000000","0.00000000"]]}}
{"type":"depth","received_at_ms":1788331865973,"data":{"e":"depthUpdate","E":1788331866114,"s":"BTCUSDT","U":99555819642,"u":99555819756,"b":[["77582.83000000","6.32891000"],["77582.82000000","0.00034000"],["77582.75000000","0.05014000"],["77582.55000000","0.00000000"],["77581.43000000","0.00000000"],["77563.21000000","0.00012000"],["77561.84000000","0.00000000"],["77555.70000000","0.00000000"],["77550.53000000","0.00000000"],["69824.55000000","0.00352000"]],"a":[["77582.84000000","0.44982000"],["77582.85000000","0.00069000"],["77584.09000000","0.01679000"],["77584.40000000","0.00000000"],["77585.57000000","0.01310000"],["77586.43000000","0.01219000"],["77588.54000000","0.00007000"],["77588.91000000","0.00007000"],["77591.82000000","0.13352000"],["77592.34000000","0.00000000"],["77592.81000000","0.00332000"],["77593.50000000","0.00000000"],["77593.58000000","0.00000000"],["77593.63000000","0.00400000"],["77593.79000000","0.00000000"],["77594.19000000","0.00000000"],["77594.48000000","0.00000000"],["77594.73000000","0.00400000"],["77594.82000000","0.00000000"],["77594.84000000","0.00000000"],["77596.19000000","0.00200000"],["77596.20000000","0.00000000"],["77596.21000000","0.40385000"],["77598.91000000","0.00000000"],["77599.68000000","0.00000000"],["77599.78000000","0.01600000"],["77599.99000000","0.00000000"],["77607.81000000","0.34778000"],["77608.57000000","0.64475000"],["77608.58000000","0.00000000"],["77609.30000000","0.25790000"]]}}
{"type":"trade","received_at_ms":1788331865978,"data":{"e":"trade","E":1788331866119,"s":"BTCUSDT","t":6646634023,"p":"77582.84000000","q":"0.00104000","T":1788331866119,"m":false,"M":true}}
{"type":"depth","received_at_ms":1788331866074,"data":{"e":"depthUpdate","E":1788331866214,"s":"BTCUSDT","U":99555819757,"u":99555819807,"b":[["77582.83000000","6.32933000"],["77582.82000000","0.00069000"],["77582.39000000","1.07566000"],["77559.19000000","0.00200000"],["69824.55000000","0.00352000"],["69824.54000000","0.00000000"],["62066.27000000","0.00000000"]],"a":[["77582.84000000","0.59535000"],["77586.57000000","0.02011000"],["77586.67000000","0.10710000"],["77591.82000000","0.13304000"],["77593.13000000","0.00400000"],["77593.14000000","0.00000000"],["77593.63000000","0.00000000"],["77593.81000000","0.00400000"],["77594.73000000","0.00000000"],["77596.19000000","0.79808000"],["77596.20000000","1.31471000"],["77596.21000000","0.00000000"],["77598.51000000","0.00200000"],["77598.91000000","0.01200000"],["77599.78000000","0.00400000"]]}}
{"type":"depth","received_at_ms":1788331866175,"data":{"e":"depthUpdate","E":1788331866314,"s":"BTCUSDT","U":99555819808,"u":99555819840,"b":[["77582.83000000","6.32891000"],["77582.82000000","0.00034000"],["77381.66000000","0.00813000"],["77378.67000000","0.00000000"],["69824.55000000","0.00368000"],["62066.26000000","0.00000000"],["62066.00000000","0.00100000"]],"a":[["77582.84000000","0.44885000"],["77586.57000000","0.02011000"],["77591.53000000","0.00000000"],["77596.18000000","0.00600000"],["77598.51000000","0.00000000"],["77599.78000000","0.00000000"],["77616.91000000","0.00000000"]]}}
{"type":"depth","received_at_ms":1788331866273,"data":{"e":"depthUpdate","E":1788331866414,"s":"BTCUSDT","U":99555819841,"u":99555819862,"b":[["77582.83000000","6.32933000"],["77582.82000000","0.00069000"],["77458.70000000","0.00074000"],["69824.55000000","0.00352000"],["62066.00000000","0.00100000"]],"a":[["77582.84000000","0.57787000"],["77592.81000000","0.00000000"],["77593.10000000","0.00328000"],["77615.58000000","0.00000000"]]}}
{"type":"depth","received_at_ms":1788331866374,"data":{"e":"depthUpdate","E":1788331866514,"s":"BTCUSDT","U":99555819863,"u":99555819881,"b":[["77582.83000000","6.32891000"],["77582.82000000","0.00034000"],["77563.55000000","0.00000000"],["69824.55000000","0.00384000"],["62066.27000000","0.00032000"]],"a":[["77582.84000000","0.44932000"],["77585.81000000","0.00007000"],["77594.59000000","0.00000000"],["78746.59000000","0.00030000"]]}}
{"type":"depth","received_at_ms":1788331866473,"data":{"e":"depthUpdate","E":1788331866614,"s":"BTCUSDT","U":99555819882,"u":99555819893,"b":[["77578.20000000","0.02900000"],["77571.40000000","0.00000000"],["77563.55000000","0.00007000"],["77558.74000000","0.10000000"],["77557.13000000","0.00000000"],["69824.55000000","0.00384000"],["62066.27000000","0.00000000"],["62066.00000000","0.00100000"]],"a":[["77594.59000000","0.00007000"],["77617.68000000","1.30655000"]]}}
{"type":"trade","received_at_ms":1788331866497,"data":{"e":"trade","E":1788331866637,"s":"BTCUSDT","t":6646634024,"p":"77582.84000000","q":"0.03223000","T":1788331866637,"m":false,"M":true}}
{"type":"depth","received_at_ms":1788331866574,"data":{"e":"depthUpdate","E":1788331866714,"s":"BTCUSDT","U":99555819894,"u":99555819919,"b":[["77582.83000000","6.32933000"],["77582.82000000","0.00069000"],["77578.86000000","0.00558000"],["77570.19000000","0.00007000"],["77570.18000000","0.00000000"],["77419.97000000","0.00074000"],["69824.55000000","0.00393000"],["62066.26000000","0.00000000"]],"a":[["77582.84000000","0.56491000"],["77616.43000000","0.02024000"],["77619.86000000","0.00000000"]]}}
{"type":"trade","received_at_ms":1788331866637,"data":{"e":"trade","E":1788331866776,"s":"BTCUSDT","t":6646634025,"p":"77582.83000000","q":"0.00067000","T":1788331866776,"m":true,"M":true}}
{"type":"trade","received_at_ms":1788331866645,"data":{"e":"trade","E":1788331866785,"s":"BTCUSDT","t":6646634026,"p":"77582.83000000","q":"0.00100000","T":1788331866785,"m":true,"M":true}}
{"type":"depth","received_at_ms":1788331866673,"data":{"e":"depthUpdate","E":1788331866814,"s":"BTCUSDT","U":99555819920,"u":99555819951,"b":[["77582.83000000","6.32773000"],["77582.82000000","0.00069000"],["77573.09000000","0.13916000"],["69824.55000000","0.00409000"],["69824.00000000","0.00020000"]],"a":[["77582.84000000","0.56010000"]]}}
{"type":"depth","received_at_ms":1788331866773,"data":{"e":"depthUpdate","E":1788331866914,"s":"BTCUSDT","U":99555819952,"u":99555819970,"b":[["77582.83000000","6.32731000"],["77582.82000000","0.00034000"],["76419.08000000","0.00030000"],["69824.55000000","0.00425000"],["69824.00000000","0.00000000"]],"a":[["77582.84000000","0.41709000"],["77706.96000000","0.00085000"]]}}
{"type":"depth","received_at_ms":1788331866873,"data":{"e":"depthUpdate","E":1788331867014,"s":"BTCUSDT","U":99555819971,"u":99555819976,"b":[["77572.94000000","0.62861000"],["77570.01000000","0.00000000"],["69824.55000000","0.00425000"],["62066.27000000","0.00032000"],["62066.00000000","0.00100000"]],"a":[]}}
{"type":"depth","received_at_ms":1788331866973,"data":{"e":"depthUpdate","E":1788331867114,"s":"BTCUSDT","U":99555819977,"u":99555819983,"b":[["77572.94000000","0.00000000"],["77572.01000000","0.26599000"],["77570.73000000","0.62861000"],["77548.50000000","0.00000000"],["69824.55000000","0.00441000"]],"a":[["77791.42000000","0.02019000"],["77801.03000000","0.00000000"]]}}
{"type":"depth","received_at_ms":1788331867073,"data":{"e":"depthUpdate","E":1788331867214,"s":"BTCUSDT","U":99555819984,"u":99555819995,"b":[["77582.83000000","6.32087000"],["77582.55000000","0.00644000"],["77581.43000000","0.00644000"],["77577.81000000","0.00000000"],["77441.41000000","0.00000000"],["77434.40000000","0.00128000"],["77432.97000000","0.00000000"],["69824.55000000","0.00441000"],["62066.27000000","0.00000000"]],"a":[["77593.80000000","0.00644000"],["77594.68000000","0.00000000"],["77595.34000000","0.00000000"],["77595.55000000","0.00644000"],["77620.08000000","0.05473000"],["77639.54000000","0.00000000"],["77639.99000000","0.00321000"],["77745.81000000","0.00085000"]]}}
{"type":"depth","received_at_ms":1788331867174,"data":{"e":"depthUpdate","E":1788331867314,"s":"BTCUSDT","U":99555819996,"u":99555820035,"b":[["77582.83000000","6.32129000"],["77582.82000000","0.00069000"],["77582.75000000","0.05021000"],["77582.55000000","0.00665000"],["77582.39000000","1.07566000"],["77581.13000000","0.04258000"],["77578.00000000","0.03014000"],["77517.14000000","0.00000000"],["77486.11000000","0.00412000"],["77448.10000000","0.02019000"],["69824.55000000","0.00441000"],["62066.26000000","0.00020000"]],"a":[["77582.84000000","0.77416000"],["77643.63000000","0.00000000"]]}}
{"type":"depth","received_at_ms":1788331867273,"data":{"e":"depthUpdate","E":1788331867414,"s":"BTCUSDT","U":99555820036,"u":99555820044,"b":[["77582.83000000","6.32136000"],["77582.82000000","0.00076000"],["69824.55000000","0.00457000"],["62066.26000000","0.00000000"]],"a":[["77582.84000000","0.77409000"],["77585.33000000","0.02011000"],["77585.35000000","0.14728000"],["77586.57000000","0.02004000"],["77586.67000000","0.00000000"]]}}
{"type":"depth","received_at_ms":1788331867374,"data":{"e":"depthUpdate","E":1788331867515,"s":"BTCUSDT","U":99555820045,"u":99555820061,"b":[["69824.55000000","0.00441000"],["62066.27000000","0.00032000"],["62066.00000000","0.00300000"]],"a":[["77585.33000000","0.02011000"],["77585.35000000","0.14742000"],["77586.57000000","0.01990000"],["78746.59000000","0.00030000"]]}}
{"type":"trade","received_at_ms":1788331867470,"data":{"e":"trade","E":1788331867609,"s":"BTCUSDT","t":6646634027,"p":"77582.83000000","q":"0.00881000","T":1788331867609,"m":true,"M":true}}
{"type":"depth","received_at_ms":1788331867472,"data":{"e":"depthUpdate","E":1788331867614,"s":"BTCUSDT","U":99555820062,"u":99555820072,"b":[["77582.83000000","6.31255000"],["77563.55000000","0.00007000"],["77556.38000000","0.09516000"],["69824.55000000","0.00448000"],["69824.54000000","0.00009000"],["62066.27000000","0.00000000"]],"a":[["77585.81000000","0.00000000"],["77594.59000000","0.00007000"]]}}
{"type":"depth","received_at_ms":1788331867574,"data":{"e":"depthUpdate","E":1788331867714,"s":"BTCUSDT","U":99555820073,"u":99555820080,"b":[["77582.83000000","6.31151000"],["77582.56000000","0.00103000"],["77577.41000000","0.00000000"],["69824.55000000","0.00432000"],["62066.26000000","0.00000000"]],"a":[["77582.84000000","0.77409000"],["77643.95000000","0.00412000"]]}}
{"type":"trade","received_at_ms":1788331867595,"data":{"e":"trade","E":1788331867734,"s":"BTCUSDT","t":6646634028,"p":"77582.83000000","q":"0.00491000","T":1788331867734,"m":true,"M":true}}
{"type":"trade","received_at_ms":1788331867636,"data":{"e":"trade","E":1788331867775,"s":"BTCUSDT","t":6646634029,"p":"77582.83000000","q":"0.00257000","T":1788331867774,"m":true,"M":true}}
{"type":"depth","received_at_ms":1788331867674,"data":{"e":"depthUpdate","E":1788331867815,"s":"BTCUSDT","U":99555820081,"u":99555820086,"b":[["77582.83000000","6.30403000"],["77578.00000000","0.03007000"],["69824.55000000","0.00448000"]],"a":[]}}
{"type":"depth","received_at_ms":1788331867774,"data":{"e":"depthUpdate","E":1788331867914,"s":"BTCUSDT","U":99555820087,"u":99555820094,"b":[["77517.11000000","0.00412000"],["77486.11000000","0.00000000"],["76419.08000000","0.00030000"],["69824.55000000","0.00432000"]],"a":[["77643.95000000","0.00000000"]]}}
{"type":"depth","received_at_ms":1788331867874,"data":{"e":"depthUpdate","E":1788331868014,"s":"BTCUSDT","U":99555820095,"u":99555820101,"b":[["77582.55000000","0.00021000"],["77581.97000000","0.00644000"],["77581.43000000","0.00000000"],["77581.17000000","0.00644000"],["69824.55000000","0.00448000"],["69824.00000000","0.00000000"],["62066.27000000","0.00032000"]],"a":[["77593.06000000","0.00644000"],["77593.80000000","0.00000000"]]}}
{"type":"trade","received_at_ms":1788331867898,"data":{"e":"trade","E":1788331868038,"s":"BTCUSDT","t":6646634030,"p":"77582.83000000","q":"0.00382000","T":1788331868037,"m":true,"M":true}}
{"type":"depth","received_at_ms":1788331867974,"data":{"e":"depthUpdate","E":1788331868114,"s":"BTCUSDT","U":99555820102,"u":99555820128,"b":[["77582.83000000","6.30021000"],["77582.82000000","0.00076000"],["77582.75000000","0.05021000"],["77582.55000000","0.00000000"],["77582.39000000","1.07566000"],["77581.97000000","0.00665000"],["77413.51000000","0.02019000"],["77391.17000000","0.00000000"],["69824.55000000","0.00432000"],["69824.54000000","0.00000000"]],"a":[]}}
{"type":"trade","received_at_ms":1788331868052,"data":{"e":"trade","E":1788331868191,"s":"BTCUSDT","t":6646634031,"p":"77582.84000000","q":"0.00154000","T":1788331868191,"m":false,"M":true}}
{"type":"depth","received_at_ms":1788331868074,"data":{"e":"depthUpdate","E":1788331868214,"s":"BTCUSDT","U":99555820129,"u":99555820133,"b":[["69824.55000000","0.00448000"],["62066.27000000","0.00000000"]],"a":[["77582.84000000","0.77255000"]]}}
{"type":"depth","received_at_ms":1788331868173,"data":{"e":"depthUpdate","E":1788331868314,"s":"BTCUSDT","U":99555820134,"u":99555820140,"b":[["71374.65000000","0.00015000"],["69824.55000000","0.00416000"],["62066.00000000","0.00300000"]],"a":[]}}
{"type":"depth","received_at_ms":1788331868274,"data":{"e":"depthUpdate","E":1788331868414,"s":"BTCUSDT","U":99555820141,"u":99555820146,"b":[["77582.83000000","6.30125000"],["77582.56000000","0.00000000"],["69824.55000000","0.00448000"],["62066.26000000","0.00000000"]],"a":[["77582.84000000","0.77270000"]]}}
{"type":"trade","received_at_ms":1788331868329,"data":{"e":"trade","E":1788331868464,"s":"BTCUSDT","t":6646634032,"p":"77582.83000000","q":"0.00018000","T":1788331868464,"m":true,"M":true}}
{"type":"depth","received_at_ms":1788331868373,"data":{"e":"depthUpdate","E":1788331868514,"s":"BTCUSDT","U":99555820147,"u":99555820155,"b":[["77582.83000000","6.30107000"],["69824.55000000","0.00432000"],["69824.54000000","0.00009000"],["62066.27000000","0.00032000"]],"a":[["77643.94000000","0.00412000"],["78746.59000000","0.00030000"]]}}
{"type":"depth","received_at_ms":1788331868474,"data":{"e":"depthUpdate","E":1788331868614,"s":"BTCUSDT","U":99555820156,"u":99555820166,"b":[["77563.55000000","0.00007000"],["69824.55000000","0.00416000"],["62066.27000000","0.00000000"],["62066.00000000","0.00300000"]],"a":[["77594.59000000","0.00007000"]]}}
{"type":"trade","received_at_ms":1788331868477,"data":{"e":"trade","E":1788331868618,"s":"BTCUSDT","t":6646634033,"p":"77582.84000000","q":"0.00035000","T":1788331868618,"m":false,"M":true}}
{"type":"depth","received_at_ms":1788331868574,"data":{"e":"depthUpdate","E":1788331868714,"s":"BTCUSDT","U":99555820167,"u":99555820171,"b":[["77408.77000000","2.23342000"],["69824.55000000","0.00432000"],["62066.26000000","0.00000000"]],"a":[["77582.84000000","0.77235000"]]}}
{"type":"depth","received_at_ms":1788331868674,"data":{"e":"depthUpdate","E":1788331868814,"s":"BTCUSDT","U":99555820172,"u":99555820178,"b":[["77558.68000000","0.04745000"],["71374.65000000","0.00000000"],["69824.55000000","0.00432000"]],"a":[]}}
{"type":"depth","received_at_ms":1788331868773,"data":{"e":"depthUpdate","E":1788331868914,"s":"BTCUSDT","U":99555820179,"u":99555820186,"b":[["76419.08000000","0.00030000"],["69824.55000000","0.00464000"]],"a":[["77582.84000000","0.77832000"]]}}
{"type":"depth","received_at_ms":1788331868874,"data":{"e":"depthUpdate","E":1788331869014,"s":"BTCUSDT","U":99555820187,"u":99555820193,"b":[["77582.83000000","6.28714000"],["77582.55000000","0.00104000"],["77581.97000000","0.00021000"],["77581.43000000","0.00644000"],["77408.91000000","4.57968000"],["77381.66000000","0.00000000"],["77378.67000000","0.00813000"],["69824.55000000","0.00448000"],["62066.27000000","0.00032000"]],"a":[]}}
{"type":"depth","received_at_ms":1788331868974,"data":{"e":"depthUpdate","E":1788331869114,"s":"BTCUSDT","U":99555820194,"u":99555820212,"b":[["77582.83000000","6.28707000"],["77582.82000000","0.00069000"],["77582.75000000","0.05028000"],["77582.39000000","1.07566000"],["77581.97000000","0.00007000"],["77581.43000000","0.00658000"],["77517.11000000","0.00000000"],["77486.08000000","0.00412000"],["69824.55000000","0.00464000"],["69824.00000000","0.00000000"]],"a":[["77643.94000000","0.00000000"]]}}
{"type":"trade","received_at_ms":1788331869057,"data":{"e":"trade","E":1788331869197,"s":"BTCUSDT","t":6646634034,"p":"77582.83000000","q":"0.20000000","T":1788331869197,"m":true,"M":true}}
{"type":"depth","received_at_ms":1788331869073,"data":{"e":"depthUpdate","E":1788331869214,"s":"BTCUSDT","U":99555820213,"u":99555820222,"b":[["77582.83000000","6.08707000"],["69824.55000000","0.00448000"],["69824.54000000","0.00000000"],["69824.53000000","0.00009000"],["62066.27000000","0.00000000"]],"a":[["77584.16000000","0.13047000"],["77585.35000000","0.00014000"],["77590.30000000","0.00400000"],["77621.34000000","0.00000000"]]}}
{"type":"depth","received_at_ms":1788331869173,"data":{"e":"depthUpdate","E":1788331869314,"s":"BTCUSDT","U":99555820223,"u":99555820248,"b":[["77413.51000000","0.00000000"],["77361.26000000","0.02019000"],["69824.55000000","0.00464000"]],"a":[["77582.84000000","0.77839000"],["77582.85000000","0.00076000"],["77584.09000000","0.01686000"],["77584.15000000","0.00007000"],["77584.16000000","0.13061000"],["77585.33000000","0.02004000"],["77585.35000000","0.00000000"],["77585.54000000","0.00000000"],["77588.50000000","0.11461000"],["77589.33000000","0.11603000"],["77591.78000000","0.11610000"],["77593.27000000","0.11603000"],["77596.17000000","0.11603000"]]}}
{"type":"trade","received_at_ms":1788331869220,"data":{"e":"trade","E":1788331869359,"s":"BTCUSDT","t":6646634035,"p":"77582.84000000","q":"0.00100000","T":1788331869359,"m":false,"M":true}}
{"type":"depth","received_at_ms":1788331869274,"data":{"e":"depthUpdate","E":1788331869414,"s":"BTCUSDT","U":99555820249,"u":99555820257,"b":[["77582.83000000","6.08811000"],["77582.55000000","0.00000000"],["77481.75000000","0.00000000"],["77476.15000000","0.00108000"],["69824.55000000","0.00448000"],["62066.26000000","0.00000000"]],"a":[["77582.84000000","0.77739000"]]}}
{"type":"depth","received_at_ms":1788331869373,"data":{"e":"depthUpdate","E":1788331869514,"s":"BTCUSDT","U":99555820258,"u":99555820265,"b":[["69824.55000000","0.00464000"],["62066.27000000","0.00032000"]],"a":[["77584.27000000","0.00000000"],["77643.90000000","0.00412000"],["78746.59000000","0.00030000"]]}}
{"type":"depth","received_at_ms":1788331869474,"data":{"e":"depthUpdate","E":1788331869614,"s":"BTCUSDT","U":99555820266,"u":99555820270,"b":[["77563.55000000","0.00000000"],["69824.55000000","0.00448000"],["62066.27000000","0.00000000"],["62066.00000000","0.00500000"]],"a":[["77582.84000000","0.62783000"],["77594.59000000","0.00000000"]]}}
{"type":"depth","received_at_ms":1788331869573,"data":{"e":"depthUpdate","E":1788331869714,"s":"BTCUSDT","U":99555820271,"u":99555820282,"b":[["77563.55000000","0.00007000"],["77517.07000000","0.00412000"],["77486.08000000","0.00000000"],["69824.55000000","0.00464000"],["62066.26000000","0.00000000"],["62066.00000000","0.00300000"]],"a":[["77585.81000000","0.00007000"],["77594.59000000","0.00007000"],["77643.90000000","0.00000000"]]}}
{"type":"depth","received_at_ms":1788331869673,"data":{"e":"depthUpdate","E":1788331869814,"s":"BTCUSDT","U":99555820283,"u":99555820285,"b":[["69824.55000000","0.00448000"]],"a":[]}}
{"type":"depth","received_at_ms":1788331869774,"data":{"e":"depthUpdate","E":1788331869914,"s":"BTCUSDT","U":99555820286,"u":99555820290,"b":[["76419.08000000","0.00030000"],["69824.55000000","0.00432000"]],"a":[]}}
{"type":"depth","received_at_ms":1788331869874,"data":{"e":"depthUpdate","E":1788331870014,"s":"BTCUSDT","U":99555820291,"u":99555820308,"b":[["77582.83000000","6.08818000"],["77582.82000000","0.00076000"],["77582.75000000","0.05035000"],["77582.55000000","0.00644000"],["77581.43000000","0.00014000"],["69824.55000000","0.00448000"],["62066.27000000","0.00032000"],["62066.00000000","0.00300000"]],"a":[["77593.06000000","0.00000000"],["77593.80000000","0.00644000"],["77595.55000000","0.00000000"],["77596.11000000","0.00644000"],["77596.16000000","0.01200000"],["77598.91000000","0.00000000"]]}}
{"type":"depth","received_at_ms":1788331869973,"data":{"e":"depthUpdate","E":1788331870114,"s":"BTCUSDT","U":99555820309,"u":99555820327,"b":[["77582.75000000","0.05028000"],["77582.55000000","0.00014000"],["77582.39000000","1.07566000"],["77581.98000000","0.00644000"],["77581.43000000","0.00000000"],["77381.66000000","0.00813000"],["77378.67000000","0.00000000"],["69824.55000000","0.00448000"]],"a":[]}}
