{"type":"depth","received_at_ms":1788333157457,"data":{"e":"depthUpdate","E":1788333157614,"s":"BTCUSDT","U":99556315414,"u":99556315454,"b":[["77708.39000000","2.69296000"],["77703.99000000","0.00000000"],["77703.27000000","0.00400000"],["76542.76000000","0.00030000"],["69937.56000000","0.00441000"],["69937.00000000","0.00000000"],["62166.72000000","0.00000000"]],"a":[["77708.40000000","2.31070000"],["77708.41000000","0.00132000"],["77708.89000000","0.00014000"],["77708.90000000","0.18374000"],["77709.35000000","0.32200000"],["77710.82000000","0.00671000"],["77711.15000000","0.01289000"],["77714.88000000","0.00400000"],["77732.88000000","0.03861000"],["77734.10000000","0.32950000"],["77747.31000000","0.00000000"],["78874.03000000","0.00030000"]]}}
{"type":"depth","received_at_ms":1788333157548,"data":{"e":"depthUpdate","E":1788333157714,"s":"BTCUSDT","U":99556315455,"u":99556315478,"b":[["77689.77000000","0.02007000"],["73978.39000000","0.00045000"],["69937.56000000","0.00457000"]],"a":[["77708.40000000","1.99299000"],["77709.35000000","0.32200000"],["77710.82000000","0.00685000"],["77713.52000000","0.00929000"],["77714.45000000","0.00400000"],["77714.88000000","0.00000000"],["77716.03000000","0.00400000"],["77716.06000000","2.30564000"],["77720.87000000","0.00007000"],["77769.08000000","0.00411000"]]}}
{"type":"trade","received_at_ms":1788333157603,"data":{"e":"trade","E":1788333157769,"s":"BTCUSDT","t":6646665254,"p":"77708.40000000","q":"0.00070000","T":1788333157769,"m":false,"M":true}}
{"type":"depth","received_at_ms":1788333157648,"data":{"e":"depthUpdate","E":1788333157814,"s":"BTCUSDT","U":99556315479,"u":99556315485,"b":[["77630.37000000","0.00000000"],["69937.56000000","0.00432000"],["69937.55000000","0.00009000"]],"a":[["77708.40000000","1.99229000"],["77776.53000000","0.00000000"]]}}
{"type":"depth","received_at_ms":1788333157754,"data":{"e":"depthUpdate","E":1788333157914,"s":"BTCUSDT","U":99556315486,"u":99556315607,"b":[["77708.39000000","2.69088000"],["77705.09000000","0.00000000"],["77669.22000000","0.00000000"],["77655.16000000","0.00000000"],["69937.56000000","0.00448000"],["62166.71000000","0.00000000"]],"a":[["77708.40000000","2.09051000"],["77708.41000000","0.00111000"],["77708.62000000","0.00007000"],["77708.89000000","0.00000000"],["77708.90000000","0.00014000"],["77708.91000000","0.00014000"],["77710.82000000","0.00671000"],["77710.83000000","0.00014000"],["77711.15000000","0.01303000"],["77712.11000000","0.00000000"],["77714.45000000","0.00000000"],["77714.77000000","0.00000000"],["77714.99000000","0.00000000"],["77715.23000000","0.00000000"],["77715.26000000","0.00000000"],["77715.27000000","0.00400000"],["77716.00000000","0.00643000"],["77716.03000000","0.01214000"],["77716.04000000","0.11136000"],["77716.05000000","0.50454000"],["77716.06000000","0.37338000"],["77716.10000000","1.31471000"],["77717.24000000","0.00643000"],["77717.51000000","0.00000000"],["77727.59000000","0.00000000"],["77730.21000000","0.00411000"],["77745.59000000","0.00000000"],["77746.40000000","0.00000000"],["77769.08000000","0.00000000"],["77800.21000000","0.00000000"]]}}
{"type":"depth","received_at_ms":1788333157853,"data":{"e":"depthUpdate","E":1788333158014,"s":"BTCUSDT","U":99556315608,"u":99556315755,"b":[["77708.39000000","2.69507000"],["77708.38000000","0.00858000"],["77706.58000000","0.00257000"],["77705.65000000","0.11129000"],["77705.40000000","0.00000000"],["77704.81000000","0.00000000"],["77704.66000000","0.02021000"],["77704.30000000","0.11129000"],["77703.61000000","0.00000000"],["77703.27000000","0.00000000"],["77702.92000000","0.37338000"],["77702.59000000","0.00200000"],["77700.26000000","0.00000000"],["77686.55000000","0.64391000"],["77682.67000000","0.34773000"],["77664.91000000","0.00000000"],["77642.43000000","0.00000000"],["73512.14000000","0.00045000"],["69937.56000000","0.00432000"],["62166.72000000","0.00032000"]],"a":[["77708.40000000","0.81603000"],["77708.41000000","0.00111000"],["77708.90000000","0.00000000"],["77708.91000000","0.00000000"],["77710.82000000","0.00014000"],["77710.83000000","0.00000000"],["77711.16000000","0.03544000"],["77712.59000000","0.00208000"],["77712.82000000","0.09887000"],["77713.52000000","0.00943000"],["77713.88000000","0.11129000"],["77714.76000000","0.01129000"],["77715.27000000","0.00000000"],["77715.93000000","0.00000000"],["77715.98000000","0.00014000"],["77715.99000000","0.11129000"],["77716.00000000","0.00000000"],["77716.01000000","0.01115000"],["77716.02000000","0.00000000"],["77716.03000000","1.31471000"],["77716.04000000","0.00000000"],["77716.05000000","0.00007000"],["77716.10000000","0.00000000"],["77716.23000000","0.00000000"],["77716.46000000","0.00000000"],["77716.50000000","0.44189000"],["77717.02000000","0.00000000"],["77717.03000000","0.00000000"],["77717.04000000","0.00000000"],["77717.06000000","0.00150000"],["77717.24000000","0.00000000"],["77718.87000000","0.00643000"],["77718.91000000","0.00000000"],["77720.22000000","0.00643000"],["77720.62000000","0.00000000"],["77721.55000000","0.00000000"],["77722.34000000","0.00000000"],["77722.53000000","0.00800000"],["77723.69000000","0.00000000"],["77726.70000000","0.00200000"],["77728.42000000","0.09622000"],["77739.10000000","0.00000000"],["77741.38000000","0.00200000"],["77746.49000000","0.00000000"],["77748.02000000","0.00007000"],["77801.00000000","0.00000000"]]}}
{"type":"trade","received_at_ms":1788333157920,"data":{"e":"trade","E":1788333158085,"s":"BTCUSDT","t":6646665255,"p":"77708.39000000","q":"0.01500000","T":1788333158085,"m":true,"M":true}}
{"type":"trade","received_at_ms":1788333157936,"data":{"e":"trade","E":1788333158089,"s":"BTCUSDT","t":6646665256,"p":"77708.40000000","q":"0.07346000","T":1788333158088,"m":false,"M":true}}
{"type":"trade","received_at_ms":1788333157936,"data":{"e":"trade","E":1788333158089,"s":"BTCUSDT","t":6646665257,"p":"77708.40000000","q":"0.22797000","T":1788333158088,"m":false,"M":true}}
{"type":"trade","received_at_ms":1788333157936,"data":{"e":"trade","E":1788333158089,"s":"BTCUSDT","t":6646665258,"p":"77708.40000000","q":"0.22104000","T":1788333158088,"m":false,"M":true}}
{"type":"trade","received_at_ms":1788333157936,"data":{"e":"trade","E":1788333158089,"s":"BTCUSDT","t":6646665259,"p":"77708.40000000","q":"0.06800000","T":1788333158088,"m":false,"M":true}}
{"type":"trade","received_at_ms":1788333157936,"data":{"e":"trade","E":1788333158089,"s":"BTCUSDT","t":6646665260,"p":"77708.40000000","q":"0.00088000","T":1788333158088,"m":false,"M":true}}
{"type":"trade","received_at_ms":1788333157936,"data":{"e":"trade","E":1788333158089,"s":"BTCUSDT","t":6646665261,"p":"77708.40000000","q":"0.00010000","T":1788333158088,"m":false,"M":true}}
{"type":"trade","received_at_ms":1788333157936,"data":{"e":"trade","E":1788333158089,"s":"BTCUSDT","t":6646665262,"p":"77708.40000000","q":"0.00580000","T":1788333158088,"m":false,"M":true}}
{"type":"trade","received_at_ms":1788333157936,"data":{"e":"trade","E":1788333158089,"s":"BTCUSDT","t":6646665263,"p":"77708.40000000","q":"0.00358000","T":1788333158088,"m":false,"M":true}}
{"type":"trade","received_at_ms":1788333157936,"data":{"e":"trade","E":1788333158089,"s":"BTCUSDT","t":6646665264,"p":"77708.40000000","q":"0.00360000","T":1788333158088,"m":false,"M":true}}
{"type":"trade","received_at_ms":1788333157936,"data":{"e":"trade","E":1788333158089,"s":"BTCUSDT","t":6646665265,"p":"77708.40000000","q":"0.00260000","T":1788333158088,"m":false,"M":true}}
{"type":"trade","received_at_ms":1788333157936,"data":{"e":"trade","E":1788333158089,"s":"BTCUSDT","t":6646665266,"p":"77708.40000000","q":"0.00631000","T":1788333158088,"m":false,"M":true}}
{"type":"trade","received_at_ms":1788333157936,"data":{"e":"trade","E":1788333158089,"s":"BTCUSDT","t":6646665267,"p":"77708.40000000","q":"0.00007000","T":1788333158088,"m":false,"M":true}}
{"type":"trade","received_at_ms":1788333157936,"data":{"e":"trade","E":1788333158089,"s":"BTCUSDT","t":6646665268,"p":"77708.40000000","q":"0.00010000","T":1788333158088,"m":false,"M":true}}
{"type":"trade","received_at_ms":1788333157936,"data":{"e":"trade","E":1788333158089,"s":"BTCUSDT","t":6646665269,"p":"77708.40000000","q":"0.00064000","T":1788333158088,"m":false,"M":true}}
{"type":"trade","received_at_ms":1788333157936,"data":{"e":"trade","E":1788333158089,"s":"BTCUSDT","t":6646665270,"p":"77708.40000000","q":"0.00291000","T":1788333158088,"m":false,"M":true}}
{"type":"trade","received_at_ms":1788333157936,"data":{"e":"trade","E":1788333158089,"s":"BTCUSDT","t":6646665271,"p":"77708.40000000","q":"0.00292000","T":1788333158088,"m":false,"M":true}}
{"type":"trade","received_at_ms":1788333157936,"data":{"e":"trade","E":1788333158089,"s":"BTCUSDT","t":6646665272,"p":"77708.40000000","q":"0.00065000","T":1788333158088,"m":false,"M":true}}
{"type":"trade","received_at_ms":1788333157936,"data":{"e":"trade","E":1788333158089,"s":"BTCUSDT","t":6646665273,"p":"77708.40000000","q":"0.00007000","T":1788333158088,"m":false,"M":true}}
{"type":"trade","received_at_ms":1788333157936,"data":{"e":"trade","E":1788333158089,"s":"BTCUSDT","t":6646665274,"p":"77708.40000000","q":"0.00067000","T":1788333158088,"m":false,"M":true}}
{"type":"trade","received_at_ms":1788333157936,"data":{"e":"trade","E":1788333158089,"s":"BTCUSDT","t":6646665275,"p":"77708.40000000","q":"0.00048000","T":1788333158088,"m":false,"M":true}}
{"type":"trade","received_at_ms":1788333157936,"data":{"e":"trade","E":1788333158089,"s":"BTCUSDT","t":6646665276,"p":"77708.40000000","q":"0.00013000","T":1788333158088,"m":false,"M":true}}
{"type":"trade","received_at_ms":1788333157936,"data":{"e":"trade","E":1788333158089,"s":"BTCUSDT","t":6646665277,"p":"77708.40000000","q":"0.00008000","T":1788333158088,"m":false,"M":true}}
{"type":"trade","received_at_ms":1788333157936,"data":{"e":"trade","E":1788333158089,"s":"BTCUSDT","t":6646665278,"p":"77708.40000000","q":"0.00007000","T":1788333158088,"m":false,"M":true}}
{"type":"trade","received_at_ms":1788333157936,"data":{"e":"trade","E":1788333158089,"s":"BTCUSDT","t":6646665279,"p":"77708.40000000","q":"0.00007000","T":1788333158088,"m":false,"M":true}}
{"type":"trade","received_at_ms":1788333157936,"data":{"e":"trade","E":1788333158089,"s":"BTCUSDT","t":6646665280,"p":"77708.40000000","q":"0.00007000","T":1788333158088,"m":false,"M":true}}
{"type":"trade","received_at_ms":1788333157936,"data":{"e":"trade","E":1788333158089,"s":"BTCUSDT","t":6646665281,"p":"77708.40000000","q":"0.00007000","T":1788333158088,"m":false,"M":true}}
{"type":"trade","received_at_ms":1788333157936,"data":{"e":"trade","E":1788333158089,"s":"BTCUSDT","t":6646665282,"p":"77708.40000000","q":"0.00007000","T":1788333158088,"m":false,"M":true}}
{"type":"trade","received_at_ms":1788333157936,"data":{"e":"trade","E":1788333158089,"s":"BTCUSDT","t":6646665283,"p":"77708.40000000","q":"0.00007000","T":1788333158088,"m":false,"M":true}}
{"type":"trade","received_at_ms":1788333157936,"data":{"e":"trade","E":1788333158089,"s":"BTCUSDT","t":6646665284,"p":"77708.40000000","q":"0.00007000","T":1788333158088,"m":false,"M":true}}
{"type":"trade","received_at_ms":1788333157936,"data":{"e":"trade","E":1788333158089,"s":"BTCUSDT","t":6646665285,"p":"77708.40000000","q":"0.00007000","T":1788333158088,"m":false,"M":true}}
{"type":"trade","received_at_ms":1788333157936,"data":{"e":"trade","E":1788333158089,"s":"BTCUSDT","t":6646665286,"p":"77708.40000000","q":"0.00007000","T":1788333158088,"m":false,"M":true}}
{"type":"trade","received_at_ms":1788333157936,"data":{"e":"trade","E":1788333158089,"s":"BTCUSDT","t":6646665287,"p":"77708.40000000","q":"0.00007000","T":1788333158088,"m":false,"M":true}}
{"type":"trade","received_at_ms":1788333157936,"data":{"e":"trade","E":1788333158089,"s":"BTCUSDT","t":6646665288,"p":"77708.40000000","q":"0.00007000","T":1788333158088,"m":false,"M":true}}
{"type":"trade","received_at_ms":1788333157936,"data":{"e":"trade","E":1788333158089,"s":"BTCUSDT","t":6646665289,"p":"77708.40000000","q":"0.00007000","T":1788333158088,"m":false,"M":true}}
{"type":"trade","received_at_ms":1788333157936,"data":{"e":"trade","E":1788333158089,"s":"BTCUSDT","t":6646665290,"p":"77708.40000000","q":"0.00007000","T":1788333158088,"m":false,"M":true}}
{"type":"trade","received_at_ms":1788333157936,"data":{"e":"trade","E":1788333158089,"s":"BTCUSDT","t":6646665291,"p":"77708.40000000","q":"0.00007000","T":1788333158088,"m":false,"M":true}}
{"type":"trade","received_at_ms":1788333157936,"data":{"e":"trade","E":1788333158089,"s":"BTCUSDT","t":6646665292,"p":"77708.40000000","q":"0.00007000","T":1788333158088,"m":false,"M":true}}
{"type":"trade","received_at_ms":1788333157936,"data":{"e":"trade","E":1788333158089,"s":"BTCUSDT","t":6646665293,"p":"77708.40000000","q":"0.00007000","T":1788333158088,"m":false,"M":true}}
{"type":"trade","received_at_ms":1788333157936,"data":{"e":"trade","E":1788333158089,"s":"BTCUSDT","t":6646665294,"p":"77708.40000000","q":"0.00007000","T":1788333158088,"m":false,"M":true}}
{"type":"trade","received_at_ms":1788333157936,"data":{"e":"trade","E":1788333158089,"s":"BTCUSDT","t":6646665295,"p":"77708.40000000","q":"0.00007000","T":1788333158088,"m":false,"M":true}}
{"type":"trade","received_at_ms":1788333157936,"data":{"e":"trade","E":1788333158089,"s":"BTCUSDT","t":6646665296,"p":"77708.40000000","q":"0.00007000","T":1788333158088,"m":false,"M":true}}
{"type":"trade","received_at_ms":1788333157936,"data":{"e":"trade","E":1788333158089,"s":"BTCUSDT","t":6646665297,"p":"77708.40000000","q":"0.00007000","T":1788333158088,"m":false,"M":true}}
{"type":"trade","received_at_ms":1788333157936,"data":{"e":"trade","E":1788333158089,"s":"BTCUSDT","t":6646665298,"p":"77708.40000000","q":"0.00007000","T":1788333158088,"m":false,"M":true}}
{"type":"trade","received_at_ms":1788333157936,"data":{"e":"trade","E":1788333158089,"s":"BTCUSDT","t":6646665299,"p":"77708.40000000","q":"0.00007000","T":1788333158088,"m":false,"M":true}}
{"type":"trade","received_at_ms":1788333157936,"data":{"e":"trade","E":1788333158089,"s":"BTCUSDT","t":6646665300,"p":"77708.40000000","q":"0.00007000","T":1788333158088,"m":false,"M":true}}
{"type":"trade","received_at_ms":1788333157936,"data":{"e":"trade","E":1788333158089,"s":"BTCUSDT","t":6646665301,"p":"77708.40000000","q":"0.00007000","T":1788333158088,"m":false,"M":true}}
{"type":"trade","received_at_ms":1788333157936,"data":{"e":"trade","E":1788333158089,"s":"BTCUSDT","t":6646665302,"p":"77708.40000000","q":"0.00007000","T":1788333158088,"m":false,"M":true}}
{"type":"trade","received_at_ms":1788333157936,"data":{"e":"trade","E":1788333158089,"s":"BTCUSDT","t":6646665303,"p":"77708.40000000","q":"0.00007000","T":1788333158088,"m":false,"M":true}}
{"type":"trade","received_at_ms":1788333157936,"data":{"e":"trade","E":1788333158089,"s":"BTCUSDT","t":6646665304,"p":"77708.40000000","q":"0.00007000","T":1788333158088,"m":false,"M":true}}
{"type":"trade","received_at_ms":1788333157936,"data":{"e":"trade","E":1788333158089,"s":"BTCUSDT","t":6646665305,"p":"77708.40000000","q":"0.00007000","T":1788333158088,"m":false,"M":true}}
{"type":"trade","received_at_ms":1788333157936,"data":{"e":"trade","E":1788333158089,"s":"BTCUSDT","t":6646665306,"p":"77708.40000000","q":"0.00005000","T":1788333158088,"m":false,"M":true}}
{"type":"trade","received_at_ms":1788333157936,"data":{"e":"trade","E":1788333158089,"s":"BTCUSDT","t":6646665307,"p":"77708.40000000","q":"0.00002000","T":1788333158088,"m":false,"M":true}}
{"type":"trade","received_at_ms":1788333157936,"data":{"e":"trade","E":1788333158089,"s":"BTCUSDT","t":6646665308,"p":"77708.41000000","q":"0.00013000","T":1788333158088,"m":false,"M":true}}
{"type":"trade","received_at_ms":1788333157936,"data":{"e":"trade","E":1788333158089,"s":"BTCUSDT","t":6646665309,"p":"77708.41000000","q":"0.00013000","T":1788333158088,"m":false,"M":true}}
{"type":"trade","received_at_ms":1788333157936,"data":{"e":"trade","E":1788333158089,"s":"BTCUSDT","t":6646665310,"p":"77708.41000000","q":"0.00008000","T":1788333158088,"m":false,"M":true}}
{"type":"trade","received_at_ms":1788333157936,"data":{"e":"trade","E":1788333158089,"s":"BTCUSDT","t":6646665311,"p":"77708.41000000","q":"0.00014000","T":1788333158088,"m":false,"M":true}}
{"type":"trade","received_at_ms":1788333157936,"data":{"e":"trade","E":1788333158089,"s":"BTCUSDT","t":6646665312,"p":"77708.41000000","q":"0.00007000","T":1788333158088,"m":false,"M":true}}
{"type":"trade","received_at_ms":1788333157936,"data":{"e":"trade","E":1788333158089,"s":"BTCUSDT","t":6646665313,"p":"77708.41000000","q":"0.00007000","T":1788333158088,"m":false,"M":true}}
{"type":"trade","received_at_ms":1788333157936,"data":{"e":"trade","E":1788333158089,"s":"BTCUSDT","t":6646665314,"p":"77708.41000000","q":"0.00007000","T":1788333158088,"m":false,"M":true}}
{"type":"trade","received_at_ms":1788333157936,"data":{"e":"trade","E":1788333158089,"s":"BTCUSDT","t":6646665315,"p":"77708.41000000","q":"0.00007000","T":1788333158088,"m":false,"M":true}}
{"type":"trade","received_at_ms":1788333157936,"data":{"e":"trade","E":1788333158089,"s":"BTCUSDT","t":6646665316,"p":"77708.41000000","q":"0.00007000","T":1788333158088,"m":false,"M":true}}
{"type":"trade","received_at_ms":1788333157936,"data":{"e":"trade","E":1788333158089,"s":"BTCUSDT","t":6646665317,"p":"77708.41000000","q":"0.00007000","T":1788333158088,"m":false,"M":true}}
{"type":"trade","received_at_ms":1788333157936,"data":{"e":"trade","E":1788333158089,"s":"BTCUSDT","t":6646665318,"p":"77708.41000000","q":"0.00007000","T":1788333158088,"m":false,"M":true}}
{"type":"trade","received_at_ms":1788333157936,"data":{"e":"trade","E":1788333158089,"s":"BTCUSDT","t":6646665319,"p":"77708.41000000","q":"0.00007000","T":1788333158088,"m":false,"M":true}}
{"type":"trade","received_at_ms":1788333157936,"data":{"e":"trade","E":1788333158089,"s":"BTCUSDT","t":6646665320,"p":"77708.41000000","q":"0.00007000","T":1788333158088,"m":false,"M":true}}
{"type":"trade","received_at_ms":1788333157936,"data":{"e":"trade","E":1788333158089,"s":"BTCUSDT","t":6646665321,"p":"77708.41000000","q":"0.00007000","T":1788333158088,"m":false,"M":true}}
{"type":"trade","received_at_ms":1788333157936,"data":{"e":"trade","E":1788333158089,"s":"BTCUSDT","t":6646665322,"p":"77708.41000000","q":"0.00007000","T":1788333158088,"m":false,"M":true}}
{"type":"trade","received_at_ms":1788333157936,"data":{"e":"trade","E":1788333158089,"s":"BTCUSDT","t":6646665323,"p":"77708.41000000","q":"0.00007000","T":1788333158088,"m":false,"M":true}}
{"type":"trade","received_at_ms":1788333157936,"data":{"e":"trade","E":1788333158089,"s":"BTCUSDT","t":6646665324,"p":"77708.42000000","q":"0.00013000","T":1788333158088,"m":false,"M":true}}
{"type":"trade","received_at_ms":1788333157936,"data":{"e":"trade","E":1788333158089,"s":"BTCUSDT","t":6646665325,"p":"77708.62000000","q":"0.00007000","T":1788333158088,"m":false,"M":true}}
{"type":"trade","received_at_ms":1788333157936,"data":{"e":"trade","E":1788333158089,"s":"BTCUSDT","t":6646665326,"p":"77709.34000000","q":"0.00007000","T":1788333158088,"m":false,"M":true}}
{"type":"trade","received_at_ms":1788333157936,"data":{"e":"trade","E":1788333158089,"s":"BTCUSDT","t":6646665327,"p":"77709.34000000","q":"0.00007000","T":1788333158088,"m":false,"M":true}}
{"type":"trade","received_at_ms":1788333157936,"data":{"e":"trade","E":1788333158089,"s":"BTCUSDT","t":6646665328,"p":"77709.34000000","q":"0.00007000","T":1788333158088,"m":false,"M":true}}
{"type":"trade","received_at_ms":1788333157936,"data":{"e":"trade","E":1788333158089,"s":"BTCUSDT","t":6646665329,"p":"77709.35000000","q":"0.32186000","T":1788333158088,"m":false,"M":true}}
{"type":"trade","received_at_ms":1788333157936,"data":{"e":"trade","E":1788333158089,"s":"BTCUSDT","t":6646665330,"p":"77709.35000000","q":"0.00007000","T":1788333158088,"m":false,"M":true}}
{"type":"trade","received_at_ms":1788333157936,"data":{"e":"trade","E":1788333158089,"s":"BTCUSDT","t":6646665331,"p":"77709.35000000","q":"0.00007000","T":1788333158088,"m":false,"M":true}}
{"type":"trade","received_at_ms":1788333157936,"data":{"e":"trade","E":1788333158090,"s":"BTCUSDT","t":6646665332,"p":"77710.45000000","q":"0.00007000","T":1788333158089,"m":false,"M":true}}
{"type":"trade","received_at_ms":1788333157936,"data":{"e":"trade","E":1788333158090,"s":"BTCUSDT","t":6646665333,"p":"77710.45000000","q":"0.00007000","T":1788333158089,"m":false,"M":true}}
{"type":"trade","received_at_ms":1788333157936,"data":{"e":"trade","E":1788333158090,"s":"BTCUSDT","t":6646665334,"p":"77710.45000000","q":"0.00007000","T":1788333158089,"m":false,"M":true}}
{"type":"trade","received_at_ms":1788333157936,"data":{"e":"trade","E":1788333158090,"s":"BTCUSDT","t":6646665335,"p":"77711.15000000","q":"0.01275000","T":1788333158089,"m":false,"M":true}}
{"type":"trade","received_at_ms":1788333157936,"data":{"e":"trade","E":1788333158090,"s":"BTCUSDT","t":6646665336,"p":"77711.15000000","q":"0.00007000","T":1788333158089,"m":false,"M":true}}
{"type":"trade","received_at_ms":1788333157936,"data":{"e":"trade","E":1788333158090,"s":"BTCUSDT","t":6646665337,"p":"77711.15000000","q":"0.00007000","T":1788333158089,"m":false,"M":true}}
{"type":"trade","received_at_ms":1788333157936,"data":{"e":"trade","E":1788333158090,"s":"BTCUSDT","t":6646665338,"p":"77711.15000000","q":"0.00007000","T":1788333158089,"m":false,"M":true}}
{"type":"trade","received_at_ms":1788333157936,"data":{"e":"trade","E":1788333158090,"s":"BTCUSDT","t":6646665339,"p":"77711.15000000","q":"0.00007000","T":1788333158089,"m":false,"M":true}}
{"type":"trade","received_at_ms":1788333157936,"data":{"e":"trade","E":1788333158090,"s":"BTCUSDT","t":6646665340,"p":"77711.15000000","q":"0.00007000","T":1788333158089,"m":false,"M":true}}
{"type":"trade","received_at_ms":1788333157936,"data":{"e":"trade","E":1788333158090,"s":"BTCUSDT","t":6646665341,"p":"77711.16000000","q":"0.02895000","T":1788333158089,"m":false,"M":true}}
{"type":"trade","received_at_ms":1788333157936,"data":{"e":"trade","E":1788333158090,"s":"BTCUSDT","t":6646665342,"p":"77711.16000000","q":"0.00007000","T":1788333158089,"m":false,"M":true}}
{"type":"trade","received_at_ms":1788333157936,"data":{"e":"trade","E":1788333158090,"s":"BTCUSDT","t":6646665343,"p":"77711.16000000","q":"0.00007000","T":1788333158089,"m":false,"M":true}}
{"type":"trade","received_at_ms":1788333157936,"data":{"e":"trade","E":1788333158090,"s":"BTCUSDT","t":6646665344,"p":"77711.16000000","q":"0.00635000","T":1788333158089,"m":false,"M":true}}
{"type":"trade","received_at_ms":1788333157936,"data":{"e":"trade","E":1788333158090,"s":"BTCUSDT","t":6646665345,"p":"77712.27000000","q":"0.00200000","T":1788333158089,"m":false,"M":true}}
{"type":"trade","received_at_ms":1788333157936,"data":{"e":"trade","E":1788333158090,"s":"BTCUSDT","t":6646665346,"p":"77712.27000000","q":"0.00200000","T":1788333158089,"m":false,"M":true}}
{"type":"trade","received_at_ms":1788333157937,"data":{"e":"trade","E":1788333158090,"s":"BTCUSDT","t":6646665347,"p":"77712.27000000","q":"0.00157000","T":1788333158089,"m":false,"M":true}}
{"type":"trade","received_at_ms":1788333157937,"data":{"e":"trade","E":1788333158090,"s":"BTCUSDT","t":6646665348,"p":"77712.27000000","q":"0.00007000","T":1788333158089,"m":false,"M":true}}
{"type":"trade","received_at_ms":1788333157937,"data":{"e":"trade","E":1788333158090,"s":"BTCUSDT","t":6646665349,"p":"77712.27000000","q":"0.00007000","T":1788333158089,"m":false,"M":true}}
{"type":"trade","received_at_ms":1788333157937,"data":{"e":"trade","E":1788333158090,"s":"BTCUSDT","t":6646665350,"p":"77712.30000000","q":"0.00029000","T":1788333158089,"m":false,"M":true}}
{"type":"trade","received_at_ms":1788333157937,"data":{"e":"trade","E":1788333158090,"s":"BTCUSDT","t":6646665351,"p":"77712.30000000","q":"0.00107000","T":1788333158090,"m":false,"M":true}}
{"type":"trade","received_at_ms":1788333157937,"data":{"e":"trade","E":1788333158090,"s":"BTCUSDT","t":6646665352,"p":"77712.56000000","q":"0.00007000","T":1788333158090,"m":false,"M":true}}
{"type":"trade","received_at_ms":1788333157937,"data":{"e":"trade","E":1788333158090,"s":"BTCUSDT","t":6646665353,"p":"77712.81000000","q":"0.00007000","T":1788333158090,"m":false,"M":true}}
{"type":"trade","received_at_ms":1788333157937,"data":{"e":"trade","E":1788333158090,"s":"BTCUSDT","t":6646665354,"p":"77712.81000000","q":"0.00007000","T":1788333158090,"m":false,"M":true}}
{"type":"trade","received_at_ms":1788333157937,"data":{"e":"trade","E":1788333158090,"s":"BTCUSDT","t":6646665355,"p":"77712.81000000","q":"0.00007000","T":1788333158090,"m":false,"M":true}}
{"type":"trade","received_at_ms":1788333157937,"data":{"e":"trade","E":1788333158090,"s":"BTCUSDT","t":6646665356,"p":"77712.82000000","q":"0.00007000","T":1788333158090,"m":false,"M":true}}
{"type":"trade","received_at_ms":1788333157937,"data":{"e":"trade","E":1788333158090,"s":"BTCUSDT","t":6646665357,"p":"77712.82000000","q":"0.00007000","T":1788333158090,"m":false,"M":true}}
{"type":"trade","received_at_ms":1788333157937,"data":{"e":"trade","E":1788333158090,"s":"BTCUSDT","t":6646665358,"p":"77713.52000000","q":"0.00051000","T":1788333158090,"m":false,"M":true}}
{"type":"trade","received_at_ms":1788333157937,"data":{"e":"trade","E":1788333158091,"s":"BTCUSDT","t":6646665359,"p":"77713.52000000","q":"0.00878000","T":1788333158090,"m":false,"M":true}}
{"type":"trade","received_at_ms":1788333157937,"data":{"e":"trade","E":1788333158091,"s":"BTCUSDT","t":6646665360,"p":"77713.52000000","q":"0.00007000","T":1788333158090,"m":false,"M":true}}
{"type":"trade","received_at_ms":1788333157937,"data":{"e":"trade","E":1788333158091,"s":"BTCUSDT","t":6646665361,"p":"77713.52000000","q":"0.00007000","T":1788333158090,"m":false,"M":true}}
{"type":"trade","received_at_ms":1788333157937,"data":{"e":"trade","E":1788333158092,"s":"BTCUSDT","t":6646665362,"p":"77713.87000000","q":"0.00007000","T":1788333158091,"m":false,"M":true}}
{"type":"trade","received_at_ms":1788333157937,"data":{"e":"trade","E":1788333158092,"s":"BTCUSDT","t":6646665363,"p":"77713.87000000","q":"0.00007000","T":1788333158091,"m":false,"M":true}}
{"type":"trade","received_at_ms":1788333157937,"data":{"e":"trade","E":1788333158092,"s":"BTCUSDT","t":6646665364,"p":"77713.87000000","q":"0.00007000","T":1788333158091,"m":false,"M":true}}
{"type":"trade","received_at_ms":1788333157937,"data":{"e":"trade","E":1788333158092,"s":"BTCUSDT","t":6646665365,"p":"77713.88000000","q":"0.00007000","T":1788333158091,"m":false,"M":true}}
{"type":"trade","received_at_ms":1788333157937,"data":{"e":"trade","E":1788333158092,"s":"BTCUSDT","t":6646665366,"p":"77713.88000000","q":"0.00007000","T":1788333158091,"m":false,"M":true}}
{"type":"trade","received_at_ms":1788333157937,"data":{"e":"trade","E":1788333158092,"s":"BTCUSDT","t":6646665367,"p":"77713.96000000","q":"0.00165000","T":1788333158091,"m":false,"M":true}}
{"type":"trade","received_at_ms":1788333157937,"data":{"e":"trade","E":1788333158095,"s":"BTCUSDT","t":6646665368,"p":"77713.96000000","q":"0.00156000","T":1788333158094,"m":false,"M":true}}
{"type":"depth","received_at_ms":1788333157958,"data":{"e":"depthUpdate","E":1788333158114,"s":"BTCUSDT","U":99556315756,"u":99556316889,"b":[["77714.75000000","2.85259000"],["77714.74000000","0.00013000"],["77714.73000000","0.00013000"],["77714.71000000","0.00000000"],["77714.70000000","0.05000000"],["77714.22000000","0.00000000"],["77713.96000000","0.07500000"],["77713.95000000","0.30218000"],["77713.88000000","3.99455000"],["77713.87000000","0.37787000"],["77713.86000000","0.30725000"],["77713.78000000","0.00021000"],["77713.77000000","0.00000000"],["77713.76000000","0.00000000"],["77713.52000000","0.07507000"],["77713.51000000","0.30153000"],["77712.91000000","0.00000000"],["77712.81000000","0.00007000"],["77712.80000000","0.00000000"],["77712.58000000","0.00000000"],["77712.56000000","0.00007000"],["77712.55000000","0.00000000"],["77712.30000000","1.69699000"],["77712.29000000","1.93226000"],["77712.26000000","0.37345000"],["77711.40000000","0.00400000"],["77711.21000000","0.00000000"],["77711.19000000","0.01306000"],["77711.15000000","0.00000000"],["77711.14000000","0.00000000"],["77710.81000000","0.00000000"],["77710.46000000","0.00000000"],["77710.45000000","0.49217000"],["77710.44000000","1.51937000"],["77709.45000000","0.00400000"],["77709.35000000","0.00000000"],["77709.34000000","0.00028000"],["77709.31000000","0.04000000"],["77709.21000000","0.00000000"],["77709.15000000","0.00000000"],["77709.13000000","0.00007000"],["77708.75000000","0.00000000"],["77708.64000000","0.00008000"],["77708.62000000","0.00014000"],["77708.51000000","0.11000000"],["77708.41000000","0.65161000"],["77708.40000000","0.69867000"],["77708.39000000","0.93076000"],["77708.38000000","0.03361000"],["77708.37000000","0.00092000"],["77708.27000000","0.00000000"],["77708.00000000","0.00000000"],["77707.99000000","0.04021000"],["77707.69000000","0.00013000"],["77707.55000000","0.02000000"],["77707.39000000","0.00000000"],["77707.38000000","0.00000000"],["77707.37000000","0.00000000"],["77707.16000000","0.00000000"],["77707.15000000","0.01650000"],["77706.58000000","0.00000000"],["77706.55000000","0.00000000"],["77706.50000000","0.00000000"],["77706.10000000","0.00008000"],["77705.92000000","0.00000000"],["77705.91000000","0.01979000"],["77705.71000000","0.00007000"],["77705.65000000","0.00000000"],["77705.41000000","0.00007000"],["77705.05000000","0.00007000"],["77704.68000000","0.00074000"],["77704.66000000","0.01986000"],["77704.33000000","0.00000000"],["77704.32000000","0.60620000"],["77704.31000000","1.31471000"],["77704.30000000","0.00000000"],["77704.29000000","0.00000000"],["77704.24000000","0.12877000"],["77703.21000000","0.00000000"],["77702.93000000","0.00000000"],["77702.91000000","0.00000000"],["77702.79000000","0.00007000"],["77702.67000000","0.00000000"],["77702.59000000","0.00000000"],["77702.58000000","0.00000000"],["77701.55000000","0.00000000"],["77700.75000000","0.00000000"],["77700.63000000","0.00000000"],["77700.55000000","0.00000000"],["77700.25000000","1.13047000"],["77700.19000000","0.00000000"],["77699.57000000","0.34765000"],["77698.10000000","0.00000000"],["77697.97000000","0.00008000"],["77697.90000000","0.03210000"],["77697.50000000","0.00000000"],["77697.49000000","0.10445000"],["77697.37000000","0.00000000"],["77696.25000000","0.64383000"],["77696.08000000","0.00000000"],["77695.54000000","0.10445000"],["77695.13000000","0.00200000"],["77694.49000000","0.44154000"],["77694.22000000","0.12870000"],["77694.08000000","0.00008000"],["77693.10000000","0.00000000"],["77692.86000000","0.00014000"],["77691.60000000","0.00000000"],["77690.66000000","0.00000000"],["77690.57000000","0.00000000"],["77690.20000000","0.00008000"],["77689.77000000","0.02000000"],["77689.72000000","0.00000000"],["77688.97000000","0.00000000"],["77688.00000000","0.73407000"],["77686.31000000","0.00008000"],["77685.80000000","0.33285000"],["77685.15000000","0.33801000"],["77685.09000000","0.00000000"],["77684.46000000","0.00007000"],["77683.77000000","0.00000000"],["77683.21000000","0.00000000"],["77683.06000000","0.00000000"],["77682.88000000","0.00000000"],["77682.42000000","0.00008000"],["77681.83000000","0.00000000"],["77681.20000000","0.00000000"],["77681.07000000","0.00000000"],["77680.20000000","0.00000000"],["77678.54000000","0.00008000"],["77678.38000000","0.00000000"],["77678.25000000","0.00000000"],["77677.71000000","0.80240000"],["77677.32000000","0.00000000"],["77677.07000000","0.00000000"],["77675.49000000","0.00000000"],["77675.31000000","0.00000000"],["77674.65000000","0.00008000"],["77674.60000000","0.00000000"],["77674.12000000","0.00000000"],["77673.43000000","0.00000000"],["77673.40000000","0.13247000"],["77673.39000000","0.00000000"],["77673.16000000","0.00000000"],["77669.91000000","0.00000000"],["77669.55000000","0.00000000"],["77667.23000000","0.00000000"],["77665.33000000","0.00000000"],["77665.28000000","0.00000000"],["77664.50000000","0.80254000"],["77662.08000000","0.00008000"],["77660.00000000","0.03000000"],["77658.04000000","0.00000000"],["77650.88000000","0.00000000"],["77642.85000000","0.00321000"],["77637.07000000","0.00000000"],["77627.11000000","1.28708000"],["77625.26000000","0.00000000"],["77624.97000000","0.00000000"],["77619.19000000","0.00000000"],["77613.33000000","0.00000000"],["77610.40000000","0.00000000"],["77607.82000000","0.00000000"],["77607.76000000","0.00008000"],["77598.94000000","0.00000000"],["77594.05000000","0.00000000"],["77591.82000000","0.00000000"],["77584.32000000","0.00000000"],["77582.53000000","1.54224000"],["77579.69000000","0.00000000"],["77564.02000000","0.00128000"],["77561.47000000","0.00000000"],["77559.58000000","0.00000000"],["77521.05000000","0.00000000"],["77386.17000000","0.00000000"],["77322.42000000","0.00000000"],["77079.40000000","0.00000000"],["76542.76000000","0.00000000"],["69942.52000000","0.00000000"],["69937.56000000","0.00000000"],["69937.55000000","0.00000000"]],"a":[["77708.40000000","0.00000000"],["77708.41000000","0.00000000"],["77708.42000000","0.00000000"],["77708.62000000","0.00000000"],["77709.34000000","0.00000000"],["77709.35000000","0.00000000"],["77710.45000000","0.00000000"],["77710.46000000","0.00000000"],["77710.82000000","0.00000000"],["77711.15000000","0.00000000"],["77711.16000000","0.00000000"],["77712.27000000","0.00000000"],["77712.30000000","0.00000000"],["77712.56000000","0.00000000"],["77712.59000000","0.00000000"],["77712.81000000","0.00000000"],["77712.82000000","0.00000000"],["77712.92000000","0.00000000"],["77713.52000000","0.00000000"],["77713.87000000","0.00000000"],["77713.88000000","0.00000000"],["77713.96000000","0.00000000"],["77714.23000000","0.00000000"],["77714.72000000","0.00000000"],["77714.75000000","0.00000000"],["77714.76000000","0.01242000"],["77714.77000000","0.00063000"],["77714.78000000","0.00014000"],["77714.79000000","0.00000000"],["77715.24000000","0.00000000"],["77715.25000000","0.00014000"],["77715.30000000","0.00000000"],["77715.97000000","0.00000000"],["77715.98000000","0.00000000"],["77715.99000000","0.00014000"],["77716.00000000","0.00014000"],["77716.01000000","0.01129000"],["77716.02000000","0.00000000"],["77716.03000000","0.00014000"],["77716.05000000","0.00000000"],["77716.06000000","0.00014000"],["77716.18000000","0.00000000"],["77716.40000000","0.00000000"],["77716.50000000","0.00021000"],["77716.51000000","0.00014000"],["77716.87000000","0.00014000"],["77717.06000000","0.00000000"],["77717.25000000","0.00000000"],["77717.28000000","0.00069000"],["77717.52000000","0.00000000"],["77717.76000000","0.00000000"],["77717.98000000","0.00014000"],["77717.99000000","0.08062000"],["77718.22000000","0.00000000"],["77718.87000000","0.00000000"],["77719.12000000","0.00000000"],["77719.34000000","0.00013000"],["77719.99000000","0.00007000"],["77720.04000000","0.00000000"],["77720.22000000","0.00000000"],["77720.23000000","0.00000000"],["77720.43000000","0.00000000"],["77720.44000000","0.00007000"],["77720.73000000","0.00321000"],["77720.83000000","0.00000000"],["77720.87000000","0.02894000"],["77720.91000000","0.00000000"],["77721.28000000","0.01268000"],["77721.46000000","0.00000000"],["77721.65000000","0.00000000"],["77721.73000000","0.00008000"],["77722.44000000","0.00000000"],["77722.53000000","0.00000000"],["77722.54000000","0.00000000"],["77722.98000000","0.10788000"],["77723.47000000","0.11129000"],["77723.70000000","0.00000000"],["77723.77000000","0.00000000"],["77723.94000000","0.00000000"],["77723.95000000","0.00000000"],["77724.38000000","0.00007000"],["77724.73000000","0.00000000"],["77724.84000000","0.11129000"],["77724.85000000","0.00000000"],["77724.86000000","0.00000000"],["77724.96000000","0.00000000"],["77725.12000000","0.00000000"],["77725.18000000","0.00000000"],["77725.26000000","0.00000000"],["77725.46000000","0.00000000"],["77725.64000000","0.00000000"],["77725.95000000","0.00151000"],["77726.21000000","0.11129000"],["77726.56000000","0.01000000"],["77726.70000000","0.00000000"],["77726.71000000","0.00000000"],["77727.54000000","0.11129000"],["77727.55000000","0.00000000"],["77727.84000000","0.00000000"],["77728.10000000","0.00008000"],["77728.32000000","0.00007000"],["77728.41000000","0.00000000"],["77728.42000000","0.00000000"],["77728.43000000","0.00000000"],["77728.44000000","0.00000000"],["77728.45000000","0.00007000"],["77728.83000000","0.00643000"],["77728.96000000","0.03010000"],["77729.39000000","0.11129000"],["77730.32000000","0.11129000"],["77731.35000000","0.00000000"],["77731.54000000","0.00000000"],["77731.69000000","0.11129000"],["77731.72000000","0.00000000"],["77731.91000000","0.00643000"],["77731.99000000","0.00008000"],["77732.26000000","0.00007000"],["77732.74000000","0.11129000"],["77732.75000000","0.00007000"],["77732.76000000","0.00000000"],["77732.77000000","0.00000000"],["77732.86000000","0.00000000"],["77732.88000000","0.00000000"],["77733.99000000","0.00000000"],["77734.10000000","0.00000000"],["77735.04000000","0.00200000"],["77735.05000000","0.00000000"],["77735.06000000","0.00000000"],["77735.54000000","0.00000000"],["77735.55000000","0.00000000"],["77735.61000000","0.00000000"],["77735.87000000","0.00008000"],["77736.00000000","0.03007000"],["77736.20000000","0.00007000"],["77736.56000000","0.02000000"],["77736.90000000","0.44669000"],["77736.91000000","0.00000000"],["77737.03000000","0.00000000"],["77737.98000000","0.00000000"],["77738.03000000","0.00000000"],["77738.28000000","0.00000000"],["77738.83000000","0.00000000"],["77738.84000000","0.00000000"],["77739.24000000","0.00000000"],["77739.47000000","0.32709000"],["77739.49000000","0.00000000"],["77739.76000000","0.00008000"],["77739.78000000","0.09622000"],["77740.14000000","0.00007000"],["77740.64000000","0.00038000"],["77740.68000000","0.43309000"],["77740.69000000","0.00012000"],["77740.91000000","0.00000000"],["77741.39000000","1.93226000"],["77741.85000000","0.00022000"],["77741.96000000","0.00000000"],["77742.03000000","0.64373000"],["77743.57000000","0.00000000"],["77743.65000000","0.00008000"],["77743.99000000","0.25749000"],["77744.00000000","0.03007000"],["77744.08000000","0.00007000"],["77744.74000000","0.04527000"],["77745.11000000","0.00000000"],["77746.24000000","0.39346000"],["77746.45000000","0.00000000"],["77746.50000000","0.00400000"],["77747.14000000","0.00000000"],["77747.26000000","0.00000000"],["77747.52000000","0.00000000"],["77747.53000000","0.00008000"],["77747.56000000","0.00000000"],["77748.00000000","0.03000000"],["77748.02000000","0.00007000"],["77750.00000000","0.05097000"],["77750.40000000","0.00400000"],["77751.42000000","0.00008000"],["77751.96000000","0.00007000"],["77752.25000000","0.00000000"],["77755.39000000","0.34740000"],["77755.90000000","0.00071000"],["77755.93000000","0.00000000"],["77758.68000000","0.64332000"],["77759.84000000","0.00007000"],["77761.50000000","0.00000000"],["77763.78000000","0.00007000"],["77763.81000000","0.34737000"],["77764.16000000","0.00000000"],["77764.78000000","0.00000000"],["77765.15000000","0.00000000"],["77765.66000000","0.35877000"],["77767.85000000","0.00000000"],["77768.26000000","1.27368000"],["77769.92000000","0.00321000"],["77770.95000000","0.00320000"],["77777.42000000","0.00000000"],["77780.27000000","1.44773000"],["77780.52000000","1.27341000"],["77798.89000000","0.00010000"],["77801.75000000","0.00007000"],["77806.66000000","0.00017000"],["77844.15000000","0.00000000"],["77852.69000000","0.00128000"],["77856.75000000","0.00000000"],["77877.90000000","1.54224000"],["77906.27000000","0.00000000"],["78045.70000000","0.00027000"],["78053.48000000","0.00027000"],["78061.26000000","0.00027000"],["78110.62000000","0.00007000"],["78874.03000000","0.00000000"]]}}
{"type":"trade","received_at_ms":1788333158050,"data":{"e":"trade","E":1788333158183,"s":"BTCUSDT","t":6646665369,"p":"77714.76000000","q":"0.00007000","T":1788333158182,"m":false,"M":true}}
{"type":"trade","received_at_ms":1788333158050,"data":{"e":"trade","E":1788333158183,"s":"BTCUSDT","t":6646665370,"p":"77714.76000000","q":"0.00007000","T":1788333158182,"m":false,"M":true}}
{"type":"trade","received_at_ms":1788333158050,"data":{"e":"trade","E":1788333158183,"s":"BTCUSDT","t":6646665371,"p":"77714.76000000","q":"0.00007000","T":1788333158182,"m":false,"M":true}}
{"type":"trade","received_at_ms":1788333158050,"data":{"e":"trade","E":1788333158183,"s":"BTCUSDT","t":6646665372,"p":"77714.76000000","q":"0.00007000","T":1788333158182,"m":false,"M":true}}
{"type":"trade","received_at_ms":1788333158050,"data":{"e":"trade","E":1788333158183,"s":"BTCUSDT","t":6646665373,"p":"77714.76000000","q":"0.00007000","T":1788333158182,"m":false,"M":true}}
{"type":"trade","received_at_ms":1788333158050,"data":{"e":"trade","E":1788333158183,"s":"BTCUSDT","t":6646665374,"p":"77714.76000000","q":"0.00007000","T":1788333158182,"m":false,"M":true}}
{"type":"trade","received_at_ms":1788333158050,"data":{"e":"trade","E":1788333158183,"s":"BTCUSDT","t":6646665375,"p":"77714.76000000","q":"0.00007000","T":1788333158182,"m":false,"M":true}}
{"type":"trade","received_at_ms":1788333158050,"data":{"e":"trade","E":1788333158183,"s":"BTCUSDT","t":6646665376,"p":"77714.76000000","q":"0.00008000","T":1788333158182,"m":false,"M":true}}
{"type":"trade","received_at_ms":1788333158050,"data":{"e":"trade","E":1788333158183,"s":"BTCUSDT","t":6646665377,"p":"77714.76000000","q":"0.00007000","T":1788333158182,"m":false,"M":true}}
{"type":"trade","received_at_ms":1788333158050,"data":{"e":"trade","E":1788333158183,"s":"BTCUSDT","t":6646665378,"p":"77714.76000000","q":"0.00007000","T":1788333158182,"m":false,"M":true}}
{"type":"trade","received_at_ms":1788333158050,"data":{"e":"trade","E":1788333158183,"s":"BTCUSDT","t":6646665379,"p":"77714.76000000","q":"0.00007000","T":1788333158182,"m":false,"M":true}}
{"type":"trade","received_at_ms":1788333158050,"data":{"e":"trade","E":1788333158183,"s":"BTCUSDT","t":6646665380,"p":"77714.76000000","q":"0.00007000","T":1788333158182,"m":false,"M":true}}
{"type":"trade","received_at_ms":1788333158050,"data":{"e":"trade","E":1788333158183,"s":"BTCUSDT","t":6646665381,"p":"77714.76000000","q":"0.00007000","T":1788333158182,"m":false,"M":true}}
{"type":"trade","received_at_ms":1788333158050,"data":{"e":"trade","E":1788333158183,"s":"BTCUSDT","t":6646665382,"p":"77714.76000000","q":"0.00007000","T":1788333158182,"m":false,"M":true}}
{"type":"trade","received_at_ms":1788333158050,"data":{"e":"trade","E":1788333158185,"s":"BTCUSDT","t":6646665383,"p":"77714.77000000","q":"0.00007000","T":1788333158184,"m":false,"M":true}}
{"type":"trade","received_at_ms":1788333158050,"data":{"e":"trade","E":1788333158185,"s":"BTCUSDT","t":6646665384,"p":"77714.77000000","q":"0.00007000","T":1788333158184,"m":false,"M":true}}
{"type":"trade","received_at_ms":1788333158050,"data":{"e":"trade","E":1788333158185,"s":"BTCUSDT","t":6646665385,"p":"77714.77000000","q":"0.00007000","T":1788333158184,"m":false,"M":true}}
{"type":"trade","received_at_ms":1788333158050,"data":{"e":"trade","E":1788333158185,"s":"BTCUSDT","t":6646665386,"p":"77714.77000000","q":"0.00007000","T":1788333158184,"m":false,"M":true}}
{"type":"trade","received_at_ms":1788333158050,"data":{"e":"trade","E":1788333158185,"s":"BTCUSDT","t":6646665387,"p":"77714.77000000","q":"0.00007000","T":1788333158184,"m":false,"M":true}}
{"type":"trade","received_at_ms":1788333158050,"data":{"e":"trade","E":1788333158185,"s":"BTCUSDT","t":6646665388,"p":"77714.77000000","q":"0.00007000","T":1788333158184,"m":false,"M":true}}
{"type":"trade","received_at_ms":1788333158050,"data":{"e":"trade","E":1788333158185,"s":"BTCUSDT","t":6646665389,"p":"77714.77000000","q":"0.00007000","T":1788333158184,"m":false,"M":true}}
{"type":"trade","received_at_ms":1788333158050,"data":{"e":"trade","E":1788333158185,"s":"BTCUSDT","t":6646665390,"p":"77714.77000000","q":"0.00007000","T":1788333158184,"m":false,"M":true}}
{"type":"trade","received_at_ms":1788333158050,"data":{"e":"trade","E":1788333158185,"s":"BTCUSDT","t":6646665391,"p":"77714.77000000","q":"0.00007000","T":1788333158184,"m":false,"M":true}}
{"type":"trade","received_at_ms":1788333158050,"data":{"e":"trade","E":1788333158185,"s":"BTCUSDT","t":6646665392,"p":"77715.84000000","q":"0.00139000","T":1788333158184,"m":false,"M":true}}
{"type":"trade","received_at_ms":1788333158050,"data":{"e":"trade","E":1788333158185,"s":"BTCUSDT","t":6646665393,"p":"77716.01000000","q":"0.00007000","T":1788333158184,"m":false,"M":true}}
{"type":"trade","received_at_ms":1788333158050,"data":{"e":"trade","E":1788333158185,"s":"BTCUSDT","t":6646665394,"p":"77716.01000000","q":"0.00007000","T":1788333158184,"m":false,"M":true}}
{"type":"trade","received_at_ms":1788333158050,"data":{"e":"trade","E":1788333158185,"s":"BTCUSDT","t":6646665395,"p":"77716.50000000","q":"0.00007000","T":1788333158184,"m":false,"M":true}}
{"type":"trade","received_at_ms":1788333158050,"data":{"e":"trade","E":1788333158185,"s":"BTCUSDT","t":6646665396,"p":"77716.76000000","q":"0.00007000","T":1788333158184,"m":false,"M":true}}
{"type":"trade","received_at_ms":1788333158050,"data":{"e":"trade","E":1788333158185,"s":"BTCUSDT","t":6646665397,"p":"77717.83000000","q":"0.00022000","T":1788333158184,"m":false,"M":true}}
{"type":"trade","received_at_ms":1788333158050,"data":{"e":"trade","E":1788333158185,"s":"BTCUSDT","t":6646665398,"p":"77717.98000000","q":"0.00007000","T":1788333158184,"m":false,"M":true}}
{"type":"trade","received_at_ms":1788333158050,"data":{"e":"trade","E":1788333158185,"s":"BTCUSDT","t":6646665399,"p":"77717.98000000","q":"0.00007000","T":1788333158184,"m":false,"M":true}}
{"type":"trade","received_at_ms":1788333158050,"data":{"e":"trade","E":1788333158185,"s":"BTCUSDT","t":6646665400,"p":"77717.98000000","q":"0.00007000","T":1788333158184,"m":false,"M":true}}
{"type":"depth","received_at_ms":1788333158090,"data":{"e":"depthUpdate","E":1788333158214,"s":"BTCUSDT","U":99556316890,"u":99556317602,"b":[["77717.98000000","4.59948000"],["77717.97000000","0.14209000"],["77717.96000000","0.00013000"],["77717.95000000","0.05000000"],["77717.94000000","0.00000000"],["77717.90000000","0.05000000"],["77717.82000000","0.00000000"],["77717.27000000","0.00000000"],["77716.86000000","0.00000000"],["77716.76000000","0.00007000"],["77716.75000000","1.09125000"],["77716.50000000","0.00014000"],["77716.00000000","0.00000000"],["77715.99000000","0.00000000"],["77715.98000000","0.00000000"],["77715.84000000","0.07500000"],["77715.83000000","0.00000000"],["77715.38000000","0.00000000"],["77715.30000000","0.00400000"],["77715.24000000","0.00000000"],["77714.76000000","3.45094000"],["77714.75000000","0.65031000"],["77714.74000000","0.00000000"],["77714.73000000","0.00000000"],["77714.70000000","0.00028000"],["77714.02000000","0.00125000"],["77714.00000000","0.04012000"],["77713.97000000","0.00200000"],["77713.96000000","0.07521000"],["77713.95000000","0.07818000"],["77713.89000000","0.00000000"],["77713.88000000","0.00014000"],["77713.87000000","0.37787000"],["77713.86000000","0.07880000"],["77713.78000000","0.00007000"],["77713.52000000","0.07507000"],["77713.51000000","0.30146000"],["77713.35000000","0.00400000"],["77712.74000000","0.00160000"],["77712.56000000","0.00014000"],["77712.44000000","0.00123000"],["77712.30000000","0.26648000"],["77712.29000000","0.00000000"],["77712.26000000","0.37345000"],["77712.16000000","0.00013000"],["77712.00000000","0.00007000"],["77711.19000000","0.01313000"],["77710.45000000","0.49284000"],["77710.44000000","1.51923000"],["77709.34000000","0.00014000"],["77709.31000000","0.04007000"],["77708.98000000","0.00008000"],["77708.63000000","0.00000000"],["77708.52000000","0.00007000"],["77708.51000000","0.11007000"],["77708.41000000","1.15669000"],["77708.40000000","0.62367000"],["77708.39000000","0.92131000"],["77708.38000000","0.03326000"],["77707.99000000","0.00000000"],["77707.69000000","0.00000000"],["77707.16000000","0.00000000"],["77707.15000000","0.00000000"],["77706.63000000","0.00126000"],["77706.10000000","0.00000000"],["77705.91000000","0.00000000"],["77705.71000000","0.00000000"],["77705.42000000","2.55980000"],["77704.80000000","0.00000000"],["77704.68000000","0.00014000"],["77704.67000000","0.00000000"],["77704.66000000","0.00000000"],["77704.28000000","0.00075000"],["77704.00000000","0.00265000"],["77702.44000000","0.00008000"],["77699.19000000","0.00000000"],["77698.55000000","0.00008000"],["77698.04000000","0.03861000"],["77697.97000000","0.00000000"],["77696.13000000","0.00007000"],["77696.00000000","0.00007000"],["77695.13000000","0.00000000"],["77694.66000000","0.00008000"],["77694.08000000","0.00000000"],["77693.67000000","0.00000000"],["77693.11000000","0.41532000"],["77692.86000000","0.00074000"],["77692.62000000","0.00188000"],["77690.78000000","0.00008000"],["77690.57000000","0.00257000"],["77690.20000000","0.00000000"],["77690.00000000","0.03200000"],["77686.89000000","0.00008000"],["77686.31000000","0.00000000"],["77684.10000000","0.00000000"],["77683.42000000","0.09471000"],["77683.01000000","0.00008000"],["77682.42000000","0.00000000"],["77682.15000000","0.00000000"],["77679.12000000","0.00008000"],["77678.54000000","0.00000000"],["77677.10000000","0.00000000"],["77676.73000000","0.00000000"],["77674.78000000","0.00000000"],["77674.71000000","0.54194000"],["77674.65000000","0.00000000"],["77673.58000000","0.00000000"],["77673.40000000","0.00000000"],["77671.09000000","0.00000000"],["77671.00000000","0.01000000"],["77670.98000000","1.29779000"],["77669.24000000","1.22569000"],["77669.00000000","0.00000000"],["77667.58000000","0.00000000"],["77666.35000000","0.25000000"],["77664.22000000","1.00076000"],["77661.96000000","0.00432000"],["77660.95000000","0.00436000"],["77658.09000000","0.00000000"],["77652.44000000","0.00321000"],["77644.02000000","0.00000000"],["77643.93000000","0.00000000"],["77642.84000000","0.00000000"],["77627.11000000","2.42394000"],["77614.55000000","0.00000000"],["77586.78000000","0.00022000"],["77582.54000000","0.37654000"],["77579.38000000","0.02016000"],["77576.10000000","0.00000000"],["77499.17000000","0.00000000"],["77496.94000000","0.00000000"],["77459.81000000","0.01087000"],["77394.54000000","0.00036000"],["77323.29000000","0.00000000"],["62166.72000000","0.00000000"]],"a":[["77714.76000000","0.00000000"],["77714.77000000","0.00000000"],["77714.78000000","0.00000000"],["77715.25000000","0.00000000"],["77715.84000000","0.00000000"],["77715.99000000","0.00000000"],["77716.00000000","0.00000000"],["77716.01000000","0.00000000"],["77716.03000000","0.00000000"],["77716.06000000","0.00000000"],["77716.50000000","0.00000000"],["77716.51000000","0.00000000"],["77716.76000000","0.00000000"],["77716.87000000","0.00000000"],["77717.28000000","0.00000000"],["77717.83000000","0.00000000"],["77717.95000000","0.00000000"],["77717.98000000","0.00000000"],["77717.99000000","0.08238000"],["77718.00000000","0.03077000"],["77718.05000000","0.00000000"],["77718.30000000","0.00000000"],["77718.38000000","0.00614000"],["77719.20000000","0.00000000"],["77719.34000000","0.00000000"],["77719.78000000","0.00000000"],["77719.99000000","0.00014000"],["77720.00000000","0.03128000"],["77720.86000000","0.00014000"],["77720.87000000","0.02908000"],["77721.15000000","0.00000000"],["77721.19000000","0.00000000"],["77721.27000000","0.00014000"],["77721.28000000","0.01282000"],["77721.73000000","0.00000000"],["77721.99000000","0.00007000"],["77722.23000000","0.00000000"],["77722.35000000","0.00000000"],["77723.81000000","0.00013000"],["77724.38000000","0.00014000"],["77724.53000000","0.00008000"],["77725.95000000","0.00000000"],["77726.25000000","0.00047000"],["77726.56000000","0.00000000"],["77726.80000000","0.12865000"],["77726.85000000","0.00208000"],["77726.86000000","0.09887000"],["77726.98000000","0.00196000"],["77727.23000000","0.00007000"],["77727.43000000","0.00048000"],["77727.90000000","0.00000000"],["77728.04000000","0.00000000"],["77728.10000000","0.00000000"],["77728.16000000","0.03000000"],["77728.32000000","0.00014000"],["77728.82000000","0.11128000"],["77728.86000000","0.12000000"],["77728.96000000","0.03000000"],["77729.25000000","0.00048000"],["77729.38000000","0.00200000"],["77729.53000000","0.00192000"],["77729.98000000","0.00000000"],["77730.32000000","0.00000000"],["77731.56000000","0.00007000"],["77731.99000000","0.00000000"],["77732.26000000","0.00014000"],["77732.30000000","0.00008000"],["77733.51000000","0.00000000"],["77734.43000000","0.11128000"],["77734.54000000","0.00151000"],["77734.57000000","0.11128000"],["77735.04000000","0.00000000"],["77735.31000000","0.00000000"],["77735.34000000","0.00000000"],["77735.87000000","0.00000000"],["77735.99000000","0.10510000"],["77736.04000000","0.15440000"],["77736.19000000","0.00408000"],["77736.20000000","0.00014000"],["77736.47000000","0.00000000"],["77736.67000000","0.61334000"],["77736.68000000","0.11129000"],["77736.89000000","0.00000000"],["77736.90000000","0.00000000"],["77738.13000000","0.11128000"],["77738.14000000","1.31471000"],["77739.42000000","0.00000000"],["77739.46000000","0.00000000"],["77739.76000000","0.00000000"],["77740.08000000","0.00008000"],["77740.14000000","0.00014000"],["77740.68000000","0.81245000"],["77741.38000000","0.00000000"],["77741.53000000","0.00672000"],["77743.38000000","0.00000000"],["77743.65000000","0.00000000"],["77743.96000000","0.00008000"],["77744.08000000","0.00014000"],["77744.53000000","1.65337000"],["77744.74000000","0.00000000"],["77745.53000000","0.00000000"],["77746.24000000","0.37338000"],["77746.55000000","0.00000000"],["77746.64000000","0.02002000"],["77747.15000000","1.29652000"],["77747.53000000","0.00000000"],["77747.85000000","0.00008000"],["77748.02000000","0.00014000"],["77748.56000000","0.04726000"],["77748.81000000","0.00000000"],["77749.54000000","0.00200000"],["77749.89000000","0.00000000"],["77750.25000000","0.00000000"],["77750.30000000","0.05408000"],["77751.42000000","0.00000000"],["77751.96000000","0.00014000"],["77752.96000000","0.00008000"],["77753.46000000","0.00000000"],["77754.00000000","0.03000000"],["77754.30000000","0.00400000"],["77755.62000000","0.00008000"],["77755.79000000","0.62774000"],["77755.90000000","0.00078000"],["77756.25000000","0.00400000"],["77756.43000000","0.00000000"],["77756.66000000","0.32950000"],["77757.00000000","0.01000000"],["77760.25000000","0.03861000"],["77761.66000000","0.00625000"],["77762.24000000","0.00424000"],["77763.78000000","0.00000000"],["77766.72000000","0.00431000"],["77766.75000000","0.00432000"],["77768.71000000","0.00000000"],["77770.52000000","0.25000000"],["77776.26000000","0.00000000"],["77784.24000000","0.01709000"],["77897.68000000","0.00000000"],["77922.22000000","0.02016000"],["77969.37000000","0.00000000"]]}}
{"type":"trade","received_at_ms":1788333158090,"data":{"e":"trade","E":1788333158228,"s":"BTCUSDT","t":6646665401,"p":"77717.99000000","q":"0.00200000","T":1788333158228,"m":false,"M":true}}
{"type":"trade","received_at_ms":1788333158090,"data":{"e":"trade","E":1788333158229,"s":"BTCUSDT","t":6646665402,"p":"77717.99000000","q":"0.00200000","T":1788333158228,"m":false,"M":true}}
{"type":"trade","received_at_ms":1788333158090,"data":{"e":"trade","E":1788333158229,"s":"BTCUSDT","t":6646665403,"p":"77717.99000000","q":"0.00200000","T":1788333158228,"m":false,"M":true}}
{"type":"trade","received_at_ms":1788333158090,"data":{"e":"trade","E":1788333158229,"s":"BTCUSDT","t":6646665404,"p":"77717.99000000","q":"0.00200000","T":1788333158229,"m":false,"M":true}}
{"type":"trade","received_at_ms":1788333158090,"data":{"e":"trade","E":1788333158229,"s":"BTCUSDT","t":6646665405,"p":"77717.99000000","q":"0.00200000","T":1788333158229,"m":false,"M":true}}
{"type":"trade","received_at_ms":1788333158090,"data":{"e":"trade","E":1788333158229,"s":"BTCUSDT","t":6646665406,"p":"77717.99000000","q":"0.00200000","T":1788333158229,"m":false,"M":true}}
{"type":"trade","received_at_ms":1788333158090,"data":{"e":"trade","E":1788333158229,"s":"BTCUSDT","t":6646665407,"p":"77717.99000000","q":"0.00200000","T":1788333158229,"m":false,"M":true}}
{"type":"trade","received_at_ms":1788333158090,"data":{"e":"trade","E":1788333158229,"s":"BTCUSDT","t":6646665408,"p":"77717.99000000","q":"0.00200000","T":1788333158229,"m":false,"M":true}}
{"type":"trade","received_at_ms":1788333158090,"data":{"e":"trade","E":1788333158229,"s":"BTCUSDT","t":6646665409,"p":"77717.99000000","q":"0.00200000","T":1788333158229,"m":false,"M":true}}
{"type":"trade","received_at_ms":1788333158090,"data":{"e":"trade","E":1788333158229,"s":"BTCUSDT","t":6646665410,"p":"77717.99000000","q":"0.00200000","T":1788333158229,"m":false,"M":true}}
{"type":"trade","received_at_ms":1788333158090,"data":{"e":"trade","E":1788333158229,"s":"BTCUSDT","t":6646665411,"p":"77717.99000000","q":"0.00200000","T":1788333158229,"m":false,"M":true}}
{"type":"trade","received_at_ms":1788333158090,"data":{"e":"trade","E":1788333158229,"s":"BTCUSDT","t":6646665412,"p":"77717.99000000","q":"0.00200000","T":1788333158229,"m":false,"M":true}}
{"type":"trade","received_at_ms":1788333158090,"data":{"e":"trade","E":1788333158230,"s":"BTCUSDT","t":6646665413,"p":"77717.99000000","q":"0.00200000","T":1788333158229,"m":false,"M":true}}
{"type":"trade","received_at_ms":1788333158090,"data":{"e":"trade","E":1788333158230,"s":"BTCUSDT","t":6646665414,"p":"77717.98000000","q":"0.00140000","T":1788333158230,"m":true,"M":true}}
{"type":"trade","received_at_ms":1788333158090,"data":{"e":"trade","E":1788333158231,"s":"BTCUSDT","t":6646665415,"p":"77717.99000000","q":"0.00200000","T":1788333158230,"m":false,"M":true}}
{"type":"trade","received_at_ms":1788333158090,"data":{"e":"trade","E":1788333158231,"s":"BTCUSDT","t":6646665416,"p":"77717.99000000","q":"0.00200000","T":1788333158231,"m":false,"M":true}}
{"type":"trade","received_at_ms":1788333158090,"data":{"e":"trade","E":1788333158231,"s":"BTCUSDT","t":6646665417,"p":"77717.99000000","q":"0.00200000","T":1788333158231,"m":false,"M":true}}
{"type":"trade","received_at_ms":1788333158090,"data":{"e":"trade","E":1788333158231,"s":"BTCUSDT","t":6646665418,"p":"77717.99000000","q":"0.00200000","T":1788333158231,"m":false,"M":true}}
{"type":"depth","received_at_ms":1788333158149,"data":{"e":"depthUpdate","E":1788333158314,"s":"BTCUSDT","U":99556317603,"u":99556317871,"b":[["77717.98000000","5.26705000"],["77717.97000000","0.15236000"],["77717.95000000","0.05021000"],["77717.90000000","0.05021000"],["77717.25000000","0.00400000"],["77716.75000000","1.09125000"],["77716.73000000","0.01676000"],["77715.84000000","0.07521000"],["77715.49000000","0.02012000"],["77715.31000000","0.01306000"],["77714.75000000","0.64975000"],["77714.70000000","0.00014000"],["77714.24000000","0.02012000"],["77714.02000000","0.30125000"],["77714.00000000","0.34033000"],["77713.97000000","0.30000000"],["77713.96000000","0.07507000"],["77713.95000000","0.07804000"],["77713.88000000","0.00000000"],["77713.87000000","0.37773000"],["77713.51000000","0.00146000"],["77711.19000000","0.00007000"],["77710.44000000","1.51916000"],["77709.34000000","0.00000000"],["77708.51000000","0.11000000"],["77708.42000000","0.00200000"],["77708.39000000","0.60124000"],["77708.38000000","0.03319000"],["77708.28000000","0.00007000"],["77707.17000000","0.00000000"],["77705.05000000","0.00133000"],["77697.55000000","0.00012000"],["77686.05000000","0.00000000"],["77683.80000000","0.00007000"],["77679.12000000","0.02565000"],["77679.00000000","0.01000000"],["77675.00000000","0.00000000"],["77673.59000000","0.00000000"],["77671.21000000","0.00428000"],["77671.00000000","0.00000000"],["77659.07000000","0.00000000"],["77658.88000000","0.00000000"],["77614.59000000","0.03990000"],["77606.79000000","0.00000000"],["77501.76000000","0.00000000"],["73045.89000000","0.00045000"],["69946.19000000","0.00032000"],["62174.00000000","0.00000000"],["62167.00000000","0.00450000"]],"a":[["77717.99000000","0.24052000"],["77718.11000000","0.00000000"],["77722.00000000","0.03014000"],["77722.15000000","0.00537000"],["77722.98000000","0.00014000"],["77723.04000000","0.11333000"],["77723.10000000","0.00000000"],["77723.40000000","0.00896000"],["77723.47000000","0.00014000"],["77723.55000000","0.10671000"],["77724.38000000","0.00014000"],["77724.64000000","0.01075000"],["77724.74000000","0.00000000"],["77725.41000000","0.00144000"],["77725.52000000","0.00000000"],["77725.89000000","0.01075000"],["77725.99000000","0.17398000"],["77726.85000000","0.00000000"],["77726.86000000","0.00000000"],["77727.40000000","0.10095000"],["77727.85000000","0.00000000"],["77728.16000000","0.00000000"],["77728.62000000","0.00000000"],["77728.63000000","0.00000000"],["77728.81000000","0.00200000"],["77728.86000000","0.00000000"],["77728.93000000","0.20468000"],["77729.38000000","0.00000000"],["77729.40000000","0.00000000"],["77729.45000000","0.00000000"],["77729.46000000","0.00000000"],["77730.16000000","0.07000000"],["77730.98000000","0.00000000"],["77731.36000000","0.08010000"],["77732.73000000","0.08116000"],["77733.99000000","0.00000000"],["77734.42000000","0.00000000"],["77734.57000000","0.00000000"],["77735.61000000","0.00000000"],["77735.98000000","0.00000000"],["77736.18000000","0.00000000"],["77736.42000000","0.00000000"],["77736.44000000","0.00000000"],["77736.63000000","0.93619000"],["77736.64000000","2.03676000"],["77736.67000000","0.00000000"],["77736.68000000","0.00000000"],["77736.75000000","0.00400000"],["77738.13000000","0.00000000"],["77742.12000000","0.00128000"],["77746.64000000","0.00000000"],["77747.16000000","0.00000000"],["77747.69000000","0.00000000"],["77748.29000000","0.03200000"],["77748.32000000","0.00000000"],["77748.66000000","0.00000000"],["77748.77000000","0.00000000"],["77749.84000000","0.00059000"],["77750.02000000","0.00192000"],["77750.30000000","0.00000000"],["77750.33000000","0.00012000"],["77750.81000000","0.00000000"],["77751.97000000","0.00000000"],["77756.66000000","0.00000000"],["77758.20000000","0.00400000"],["77760.25000000","0.00000000"],["77763.78000000","0.00000000"],["77774.02000000","0.00000000"],["77774.38000000","0.00000000"],["77782.81000000","0.00000000"],["77800.17000000","0.00411000"],["77839.97000000","0.00000000"],["77847.80000000","0.00971000"],["77918.36000000","0.00000000"],["77938.85000000","0.00007000"],["77942.73000000","0.00007000"],["77965.46000000","0.11320000"],["77977.24000000","0.00031000"],["78272.00000000","0.00007000"]]}}
{"type":"trade","received_at_ms":1788333158222,"data":{"e":"trade","E":1788333158387,"s":"BTCUSDT","t":6646665419,"p":"77717.99000000","q":"0.02100000","T":1788333158387,"m":false,"M":true}}
{"type":"depth","received_at_ms":1788333158248,"data":{"e":"depthUpdate","E":1788333158414,"s":"BTCUSDT","U":99556317872,"u":99556317972,"b":[["77717.98000000","5.27117000"],["77716.75000000","1.09125000"],["77716.73000000","0.01690000"],["77716.40000000","0.00008000"],["77715.84000000","0.07521000"],["77715.49000000","0.02033000"],["77715.31000000","0.01320000"],["77714.77000000","0.00200000"],["77714.76000000","3.45080000"],["77714.75000000","0.64896000"],["77714.00000000","0.34019000"],["77713.95000000","0.07804000"],["77712.30000000","0.69249000"],["77710.20000000","0.16879000"],["77709.31000000","0.04000000"],["77708.42000000","0.00000000"],["77708.39000000","0.58112000"],["77702.43000000","0.00009000"],["77700.61000000","0.00000000"],["77694.66000000","0.00017000"],["77692.84000000","0.00000000"],["77688.00000000","0.73400000"],["77686.89000000","0.00017000"],["77685.07000000","0.00000000"],["77682.46000000","0.00012000"],["77677.30000000","0.00000000"],["77670.72000000","0.00625000"],["77646.06000000","0.00320000"],["77637.06000000","0.00000000"],["77568.01000000","0.00128000"],["77559.07000000","0.00000000"],["77542.45000000","0.00000000"],["77530.01000000","0.00811000"],["77519.70000000","0.02016000"],["77508.01000000","0.00000000"],["77487.79000000","0.00000000"],["69946.19000000","0.00057000"],["62174.38000000","0.00020000"]],"a":[["77717.99000000","0.21959000"],["77718.00000000","0.03077000"],["77720.00000000","0.03121000"],["77721.27000000","0.00000000"],["77721.28000000","0.00014000"],["77721.99000000","0.00014000"],["77722.00000000","0.03014000"],["77722.15000000","0.00558000"],["77722.16000000","0.11289000"],["77722.98000000","0.00000000"],["77723.04000000","0.00014000"],["77723.47000000","0.00000000"],["77723.88000000","0.01268000"],["77725.99000000","0.00000000"],["77728.81000000","0.00000000"],["77728.93000000","0.19632000"],["77730.44000000","0.00200000"],["77736.15000000","0.00000000"],["77757.53000000","0.00012000"],["77758.09000000","0.32950000"],["77761.76000000","0.03861000"],["77769.92000000","0.00000000"],["77777.99000000","0.00319000"],["77787.82000000","0.00112000"],["77788.30000000","0.00539000"],["77797.87000000","0.09253000"]]}}
{"type":"trade","received_at_ms":1788333158322,"data":{"e":"trade","E":1788333158489,"s":"BTCUSDT","t":6646665420,"p":"77717.99000000","q":"0.02100000","T":1788333158489,"m":false,"M":true}}
{"type":"trade","received_at_ms":1788333158325,"data":{"e":"trade","E":1788333158489,"s":"BTCUSDT","t":6646665421,"p":"77717.99000000","q":"0.00448000","T":1788333158489,"m":false,"M":true}}
{"type":"trade","received_at_ms":1788333158325,"data":{"e":"trade","E":1788333158489,"s":"BTCUSDT","t":6646665422,"p":"77717.99000000","q":"0.00007000","T":1788333158489,"m":false,"M":true}}
{"type":"trade","received_at_ms":1788333158325,"data":{"e":"trade","E":1788333158489,"s":"BTCUSDT","t":6646665423,"p":"77717.99000000","q":"0.00007000","T":1788333158489,"m":false,"M":true}}
{"type":"trade","received_at_ms":1788333158325,"data":{"e":"trade","E":1788333158489,"s":"BTCUSDT","t":6646665424,"p":"77717.99000000","q":"0.00007000","T":1788333158489,"m":false,"M":true}}
{"type":"trade","received_at_ms":1788333158325,"data":{"e":"trade","E":1788333158489,"s":"BTCUSDT","t":6646665425,"p":"77717.99000000","q":"0.00007000","T":1788333158489,"m":false,"M":true}}
{"type":"trade","received_at_ms":1788333158325,"data":{"e":"trade","E":1788333158489,"s":"BTCUSDT","t":6646665426,"p":"77717.99000000","q":"0.00007000","T":1788333158489,"m":false,"M":true}}
{"type":"trade","received_at_ms":1788333158325,"data":{"e":"trade","E":1788333158489,"s":"BTCUSDT","t":6646665427,"p":"77717.99000000","q":"0.00007000","T":1788333158489,"m":false,"M":true}}
{"type":"trade","received_at_ms":1788333158326,"data":{"e":"trade","E":1788333158489,"s":"BTCUSDT","t":6646665428,"p":"77717.99000000","q":"0.00007000","T":1788333158489,"m":false,"M":true}}
{"type":"trade","received_at_ms":1788333158326,"data":{"e":"trade","E":1788333158489,"s":"BTCUSDT","t":6646665429,"p":"77717.99000000","q":"0.00007000","T":1788333158489,"m":false,"M":true}}
{"type":"trade","received_at_ms":1788333158326,"data":{"e":"trade","E":1788333158489,"s":"BTCUSDT","t":6646665430,"p":"77717.99000000","q":"0.00007000","T":1788333158489,"m":false,"M":true}}
{"type":"trade","received_at_ms":1788333158326,"data":{"e":"trade","E":1788333158489,"s":"BTCUSDT","t":6646665431,"p":"77717.99000000","q":"0.00007000","T":1788333158489,"m":false,"M":true}}
{"type":"trade","received_at_ms":1788333158326,"data":{"e":"trade","E":1788333158489,"s":"BTCUSDT","t":6646665432,"p":"77717.99000000","q":"0.00007000","T":1788333158489,"m":false,"M":true}}
{"type":"trade","received_at_ms":1788333158326,"data":{"e":"trade","E":1788333158489,"s":"BTCUSDT","t":6646665433,"p":"77717.99000000","q":"0.00007000","T":1788333158489,"m":false,"M":true}}
{"type":"trade","received_at_ms":1788333158326,"data":{"e":"trade","E":1788333158489,"s":"BTCUSDT","t":6646665434,"p":"77717.99000000","q":"0.00007000","T":1788333158489,"m":false,"M":true}}
{"type":"trade","received_at_ms":1788333158326,"data":{"e":"trade","E":1788333158489,"s":"BTCUSDT","t":6646665435,"p":"77717.99000000","q":"0.00007000","T":1788333158489,"m":false,"M":true}}
{"type":"trade","received_at_ms":1788333158326,"data":{"e":"trade","E":1788333158489,"s":"BTCUSDT","t":6646665436,"p":"77717.99000000","q":"0.00007000","T":1788333158489,"m":false,"M":true}}
{"type":"trade","received_at_ms":1788333158326,"data":{"e":"trade","E":1788333158489,"s":"BTCUSDT","t":6646665437,"p":"77717.99000000","q":"0.00007000","T":1788333158489,"m":false,"M":true}}
{"type":"trade","received_at_ms":1788333158326,"data":{"e":"trade","E":1788333158489,"s":"BTCUSDT","t":6646665438,"p":"77717.99000000","q":"0.00007000","T":1788333158489,"m":false,"M":true}}
{"type":"trade","received_at_ms":1788333158326,"data":{"e":"trade","E":1788333158489,"s":"BTCUSDT","t":6646665439,"p":"77717.99000000","q":"0.00007000","T":1788333158489,"m":false,"M":true}}
{"type":"trade","received_at_ms":1788333158326,"data":{"e":"trade","E":1788333158489,"s":"BTCUSDT","t":6646665440,"p":"77717.99000000","q":"0.00007000","T":1788333158489,"m":false,"M":true}}
{"type":"trade","received_at_ms":1788333158326,"data":{"e":"trade","E":1788333158489,"s":"BTCUSDT","t":6646665441,"p":"77717.99000000","q":"0.00007000","T":1788333158489,"m":false,"M":true}}
{"type":"trade","received_at_ms":1788333158326,"data":{"e":"trade","E":1788333158489,"s":"BTCUSDT","t":6646665442,"p":"77717.99000000","q":"0.00007000","T":1788333158489,"m":false,"M":true}}
{"type":"trade","received_at_ms":1788333158326,"data":{"e":"trade","E":1788333158489,"s":"BTCUSDT","t":6646665443,"p":"77717.99000000","q":"0.00008000","T":1788333158489,"m":false,"M":true}}
{"type":"trade","received_at_ms":1788333158326,"data":{"e":"trade","E":1788333158489,"s":"BTCUSDT","t":6646665444,"p":"77717.99000000","q":"0.00013000","T":1788333158489,"m":false,"M":true}}
{"type":"trade","received_at_ms":1788333158326,"data":{"e":"trade","E":1788333158489,"s":"BTCUSDT","t":6646665445,"p":"77717.99000000","q":"0.00007000","T":1788333158489,"m":false,"M":true}}
{"type":"trade","received_at_ms":1788333158326,"data":{"e":"trade","E":1788333158489,"s":"BTCUSDT","t":6646665446,"p":"77717.99000000","q":"0.00007000","T":1788333158489,"m":false,"M":true}}
{"type":"trade","received_at_ms":1788333158326,"data":{"e":"trade","E":1788333158489,"s":"BTCUSDT","t":6646665447,"p":"77717.99000000","q":"0.00007000","T":1788333158489,"m":false,"M":true}}
{"type":"trade","received_at_ms":1788333158326,"data":{"e":"trade","E":1788333158489,"s":"BTCUSDT","t":6646665448,"p":"77717.99000000","q":"0.00007000","T":1788333158489,"m":false,"M":true}}
{"type":"trade","received_at_ms":1788333158326,"data":{"e":"trade","E":1788333158489,"s":"BTCUSDT","t":6646665449,"p":"77717.99000000","q":"0.00007000","T":1788333158489,"m":false,"M":true}}
{"type":"trade","received_at_ms":1788333158326,"data":{"e":"trade","E":1788333158489,"s":"BTCUSDT","t":6646665450,"p":"77717.99000000","q":"0.00007000","T":1788333158489,"m":false,"M":true}}
{"type":"trade","received_at_ms":1788333158326,"data":{"e":"trade","E":1788333158489,"s":"BTCUSDT","t":6646665451,"p":"77717.99000000","q":"0.00007000","T":1788333158489,"m":false,"M":true}}
{"type":"trade","received_at_ms":1788333158326,"data":{"e":"trade","E":1788333158489,"s":"BTCUSDT","t":6646665452,"p":"77717.99000000","q":"0.00007000","T":1788333158489,"m":false,"M":true}}
{"type":"trade","received_at_ms":1788333158326,"data":{"e":"trade","E":1788333158489,"s":"BTCUSDT","t":6646665453,"p":"77717.99000000","q":"0.00007000","T":1788333158489,"m":false,"M":true}}
{"type":"trade","received_at_ms":1788333158326,"data":{"e":"trade","E":1788333158489,"s":"BTCUSDT","t":6646665454,"p":"77717.99000000","q":"0.01421000","T":1788333158489,"m":false,"M":true}}
{"type":"trade","received_at_ms":1788333158326,"data":{"e":"trade","E":1788333158490,"s":"BTCUSDT","t":6646665455,"p":"77717.99000000","q":"0.02100000","T":1788333158490,"m":false,"M":true}}
{"type":"trade","received_at_ms":1788333158326,"data":{"e":"trade","E":1788333158493,"s":"BTCUSDT","t":6646665456,"p":"77717.99000000","q":"0.02100000","T":1788333158492,"m":false,"M":true}}
{"type":"depth","received_at_ms":1788333158347,"data":{"e":"depthUpdate","E":1788333158514,"s":"BTCUSDT","U":99556317973,"u":99556318054,"b":[["77717.98000000","5.29124000"],["77717.16000000","0.00007000"],["77716.75000000","1.92527000"],["77709.86000000","0.00010000"],["77707.11000000","0.00000000"],["77706.34000000","0.00007000"],["77702.31000000","0.02180000"],["77661.75000000","0.00000000"],["77602.24000000","0.02295000"],["77588.30000000","0.00000000"],["77582.54000000","0.00000000"],["77580.98000000","0.00000000"],["75557.14000000","0.00010000"],["69946.19000000","0.00073000"],["62174.39000000","0.00032000"],["62174.38000000","0.00000000"]],"a":[["77717.99000000","0.13700000"],["77720.31000000","0.00609000"],["77720.87000000","0.02908000"],["77721.28000000","0.00000000"],["77722.15000000","0.00551000"],["77722.16000000","0.00014000"],["77723.04000000","0.00000000"],["77723.40000000","0.00910000"],["77723.54000000","0.00007000"],["77725.88000000","0.16823000"],["77728.93000000","0.19572000"],["77730.44000000","0.00000000"],["77732.34000000","0.00200000"],["77736.18000000","0.00257000"],["77736.62000000","0.11289000"],["77736.64000000","1.93226000"],["77758.46000000","0.00000000"],["77758.50000000","0.00000000"],["77770.95000000","0.00000000"],["77774.99000000","0.00321000"],["77784.86000000","0.05800000"],["77822.79000000","0.00000000"],["77825.15000000","0.00000000"],["77829.89000000","0.00000000"]]}}
{"type":"depth","received_at_ms":1788333158448,"data":{"e":"depthUpdate","E":1788333158614,"s":"BTCUSDT","U":99556318055,"u":99556318127,"b":[["77717.98000000","5.29138000"],["77717.96000000","0.00027000"],["77717.91000000","0.00014000"],["77716.76000000","0.00021000"],["77708.40000000","0.00000000"],["77707.23000000","0.02000000"],["77707.16000000","0.02000000"],["77706.45000000","0.02000000"],["77706.38000000","0.02000000"],["77703.35000000","0.02000000"],["77702.55000000","0.02000000"],["77699.39000000","0.00007000"],["77697.84000000","0.34766000"],["77690.76000000","0.34769000"],["77688.45000000","0.00000000"],["77594.01000000","0.00012000"],["77519.70000000","0.00000000"],["77487.79000000","0.02016000"],["76552.21000000","0.00030000"],["72579.64000000","0.00045000"],["69946.19000000","0.00089000"],["62174.39000000","0.00000000"],["62174.00000000","0.00000000"]],"a":[["77717.99000000","0.13714000"],["77718.00000000","0.03084000"],["77720.00000000","0.03121000"],["77720.31000000","0.00623000"],["77722.15000000","0.00558000"],["77722.16000000","0.11289000"],["77725.28000000","0.12924000"],["77725.88000000","0.24278000"],["77726.18000000","0.32179000"],["77728.35000000","0.00000000"],["77728.93000000","0.18818000"],["77728.96000000","0.03010000"],["77733.80000000","0.02400000"],["77734.57000000","0.03000000"],["77735.54000000","0.00257000"],["77736.18000000","0.00000000"],["77737.69000000","0.02600000"],["77738.49000000","0.02200000"],["77752.00000000","0.03258000"],["77763.79000000","0.34737000"],["77772.15000000","0.34733000"],["77799.59000000","0.02400000"],["77800.37000000","0.03000000"],["77803.47000000","0.02600000"],["77804.25000000","0.02200000"],["77832.39000000","0.00012000"],["77834.75000000","0.00026000"],["77839.49000000","0.00032000"],["78883.76000000","0.00030000"]]}}
{"type":"trade","received_at_ms":1788333158477,"data":{"e":"trade","E":1788333158642,"s":"BTCUSDT","t":6646665457,"p":"77717.98000000","q":"0.01000000","T":1788333158642,"m":true,"M":true}}
{"type":"depth","received_at_ms":1788333158547,"data":{"e":"depthUpdate","E":1788333158714,"s":"BTCUSDT","U":99556318128,"u":99556318174,"b":[["77717.98000000","5.28789000"],["77714.75000000","0.64253000"],["77706.44000000","0.02000000"],["77706.36000000","0.02000000"],["77704.11000000","0.02000000"],["77703.33000000","0.02000000"],["77702.56000000","0.02000000"],["77702.41000000","0.02000000"],["77697.66000000","0.00115000"],["77697.61000000","0.00000000"],["77692.10000000","0.00000000"],["77689.01000000","1.76492000"],["77688.21000000","0.00000000"],["77688.00000000","0.03400000"],["77655.16000000","0.00411000"],["77640.01000000","0.00000000"],["69946.19000000","0.00112000"],["69946.18000000","0.00009000"]],"a":[["77717.99000000","0.13979000"],["77718.00000000","0.03077000"],["77720.31000000","0.00021000"],["77722.15000000","0.00558000"],["77722.16000000","0.11303000"],["77723.40000000","0.00896000"],["77732.34000000","0.00000000"],["77733.99000000","0.00200000"],["77735.54000000","0.00000000"],["77735.57000000","0.00257000"],["77736.93000000","0.03000000"],["77737.70000000","0.02800000"],["77738.47000000","0.03007000"],["77738.48000000","0.02400000"],["77798.81000000","0.03000000"],["77803.47000000","0.05400000"],["77804.25000000","0.02200000"],["77804.31000000","0.03000000"]]}}
{"type":"depth","received_at_ms":1788333158660,"data":{"e":"depthUpdate","E":1788333158814,"s":"BTCUSDT","U":99556318175,"u":99556318203,"b":[["77717.98000000","5.29789000"],["77715.61000000","0.00007000"],["77708.39000000","0.57112000"],["77702.86000000","0.02000000"],["77698.36000000","0.00000000"],["77697.24000000","0.52682000"],["77692.88000000","0.00000000"],["77689.77000000","0.00000000"],["77688.11000000","0.00000000"]],"a":[["77720.00000000","0.03121000"],["77720.31000000","0.00007000"],["77723.40000000","0.00910000"],["77735.57000000","0.00000000"],["77735.60000000","0.00000000"],["77738.14000000","1.33671000"],["77746.23000000","0.00200000"],["77748.40000000","0.01965000"],["77749.64000000","0.09507000"],["77752.06000000","0.05402000"],["77754.08000000","0.00335000"],["77800.09000000","0.02200000"],["77804.25000000","0.00000000"],["81001.14000000","0.00010000"]]}}
{"type":"depth","received_at_ms":1788333158748,"data":{"e":"depthUpdate","E":1788333158914,"s":"BTCUSDT","U":99556318204,"u":99556318227,"b":[["77697.76000000","0.00000000"],["77692.98000000","0.00000000"],["77688.99000000","0.00000000"],["77688.87000000","0.00000000"],["77655.16000000","0.00000000"],["77623.04000000","0.00000000"],["69946.19000000","0.00144000"],["62174.38000000","0.00000000"]],"a":[["77721.92000000","0.11912000"],["77725.28000000","0.00000000"],["77730.21000000","0.00000000"],["77734.19000000","1.31471000"],["77735.62000000","0.00000000"],["77758.67000000","0.00000000"],["77769.08000000","0.00000000"],["77799.59000000","0.00000000"],["77800.17000000","0.00000000"],["77804.31000000","0.00000000"],["77816.54000000","2.15325000"]]}}
{"type":"depth","received_at_ms":1788333158849,"data":{"e":"depthUpdate","E":1788333159014,"s":"BTCUSDT","U":99556318228,"u":99556318269,"b":[["69946.19000000","0.00160000"],["62174.39000000","0.00032000"]],"a":[["77717.99000000","0.13986000"],["77720.76000000","0.00014000"],["77720.77000000","0.11290000"],["77720.87000000","0.02908000"],["77720.90000000","0.00027000"],["77721.91000000","0.00014000"],["77721.92000000","0.11926000"],["77721.99000000","0.00000000"],["77722.15000000","0.00551000"],["77723.40000000","0.00896000"],["77723.54000000","0.00000000"],["77727.40000000","0.09887000"],["77728.80000000","0.63166000"],["77728.81000000","1.31471000"],["77728.82000000","0.00000000"],["77728.93000000","0.00000000"],["77729.39000000","0.00000000"],["77731.69000000","0.00000000"],["77732.73000000","0.47994000"],["77732.74000000","0.00000000"],["77734.18000000","0.00000000"],["77734.43000000","0.00000000"],["77734.79000000","0.00257000"],["77735.99000000","0.00000000"],["77736.62000000","0.00000000"],["77803.47000000","0.02800000"]]}}
{"type":"depth","received_at_ms":1788333158952,"data":{"e":"depthUpdate","E":1788333159114,"s":"BTCUSDT","U":99556318270,"u":99556318354,"b":[["77717.98000000","4.08712000"],["77716.38000000","0.00007000"],["77714.77000000","0.01000000"],["77714.76000000","1.51854000"],["77714.75000000","0.64190000"],["77714.25000000","0.00643000"],["77713.87000000","0.37773000"],["77710.46000000","1.93226000"],["77710.45000000","0.49217000"],["77709.46000000","0.00060000"],["77708.59000000","0.12868000"],["77693.34000000","0.00000000"],["77690.67000000","0.00000000"],["77634.70000000","0.00411000"],["77582.53000000","0.00000000"],["69946.19000000","0.00160000"],["69946.00000000","0.00020000"]],"a":[["77717.99000000","0.50226000"],["77718.00000000","0.03084000"],["77720.00000000","0.03121000"],["77720.49000000","0.11770000"],["77720.77000000","0.11304000"],["77721.92000000","0.00014000"],["77722.16000000","0.11289000"],["77724.28000000","0.00208000"],["77724.82000000","0.66219000"],["77724.83000000","1.31471000"],["77724.84000000","0.00000000"],["77725.88000000","0.00000000"],["77726.21000000","0.00000000"],["77727.40000000","0.00000000"],["77727.54000000","0.00000000"],["77728.35000000","0.00007000"],["77728.78000000","1.04659000"],["77728.79000000","1.93226000"],["77728.80000000","0.00000000"],["77733.61000000","0.12864000"],["77734.79000000","0.00000000"],["77738.13000000","0.37338000"],["77741.38000000","0.12863000"],["77749.64000000","0.00000000"],["77759.07000000","0.00000000"],["77759.23000000","0.00000000"],["77759.61000000","0.00000000"],["77759.84000000","0.00000000"],["77798.81000000","0.00000000"],["77800.37000000","0.00000000"],["77877.90000000","0.00000000"],["78110.62000000","0.00000000"]]}}
{"type":"depth","received_at_ms":1788333159055,"data":{"e":"depthUpdate","E":1788333159214,"s":"BTCUSDT","U":99556318355,"u":99556318427,"b":[["77716.76000000","0.00221000"],["77716.75000000","1.09125000"],["77715.31000000","0.01327000"],["77714.77000000","0.00800000"],["77714.75000000","0.64197000"],["77713.51000000","0.00139000"],["77712.30000000","1.26517000"],["77711.93000000","0.00007000"],["77710.47000000","0.00000000"],["77699.36000000","0.00015000"],["77696.13000000","0.00000000"],["77695.97000000","0.00200000"],["77690.00000000","0.03000000"],["77009.01000000","0.00000000"],["76542.78000000","0.00026000"],["69946.19000000","0.00192000"],["69946.00000000","0.00000000"],["62174.39000000","0.00000000"]],"a":[["77717.99000000","0.50398000"],["77718.00000000","0.03098000"],["77718.38000000","0.00014000"],["77719.37000000","0.00014000"],["77719.38000000","0.11232000"],["77719.39000000","0.13719000"],["77720.00000000","0.03121000"],["77720.36000000","0.00634000"],["77720.44000000","0.00014000"],["77720.48000000","0.00000000"],["77720.49000000","0.00014000"],["77720.86000000","0.00000000"],["77720.87000000","0.02908000"],["77721.91000000","0.00000000"],["77721.92000000","0.00000000"],["77723.33000000","0.09887000"],["77724.81000000","0.11490000"],["77727.23000000","0.00000000"],["77730.46000000","0.00007000"],["77733.99000000","0.00000000"],["77800.09000000","0.00000000"],["77801.50000000","0.00007000"],["77803.47000000","0.00000000"]]}}
{"type":"depth","received_at_ms":1788333159147,"data":{"e":"depthUpdate","E":1788333159314,"s":"BTCUSDT","U":99556318428,"u":99556318458,"b":[["77716.76000000","0.00021000"],["77714.77000000","0.01000000"],["77704.64000000","0.00411000"],["69946.19000000","0.00192000"]],"a":[["77717.99000000","0.50398000"],["77718.00000000","0.03098000"],["77718.38000000","0.00000000"],["77719.38000000","0.11260000"],["77719.39000000","0.13733000"],["77720.00000000","0.03121000"],["77720.36000000","0.00648000"],["77720.49000000","0.00000000"],["77722.15000000","0.00537000"]]}}
{"type":"depth","received_at_ms":1788333159249,"data":{"e":"depthUpdate","E":1788333159414,"s":"BTCUSDT","U":99556318459,"u":99556318478,"b":[["77715.61000000","0.00000000"],["77703.00000000","0.70000000"],["77685.63000000","1.27497000"],["77584.06000000","0.00000000"],["77516.68000000","0.00000000"],["77480.97000000","0.00000000"],["77435.90000000","0.00000000"],["77219.62000000","0.01551000"],["77183.69000000","0.01551000"],["77138.78000000","0.01591000"],["69946.19000000","0.00208000"]],"a":[["77717.99000000","0.50393000"],["77793.80000000","1.27343000"],["77836.11000000","0.00000000"],["77857.67000000","0.00000000"],["77863.06000000","0.01541000"],["77886.82000000","0.01540000"]]}}
{"type":"trade","received_at_ms":1788333159296,"data":{"e":"trade","E":1788333159462,"s":"BTCUSDT","t":6646665458,"p":"77717.99000000","q":"0.00200000","T":1788333159462,"m":false,"M":true}}
{"type":"trade","received_at_ms":1788333159296,"data":{"e":"trade","E":1788333159462,"s":"BTCUSDT","t":6646665459,"p":"77717.99000000","q":"0.00200000","T":1788333159462,"m":false,"M":true}}
{"type":"trade","received_at_ms":1788333159300,"data":{"e":"trade","E":1788333159466,"s":"BTCUSDT","t":6646665460,"p":"77717.99000000","q":"0.02100000","T":1788333159466,"m":false,"M":true}}
{"type":"trade","received_at_ms":1788333159301,"data":{"e":"trade","E":1788333159466,"s":"BTCUSDT","t":6646665461,"p":"77717.99000000","q":"0.02100000","T":1788333159466,"m":false,"M":true}}
{"type":"trade","received_at_ms":1788333159302,"data":{"e":"trade","E":1788333159468,"s":"BTCUSDT","t":6646665462,"p":"77717.99000000","q":"0.02100000","T":1788333159467,"m":false,"M":true}}
{"type":"depth","received_at_ms":1788333159348,"data":{"e":"depthUpdate","E":1788333159514,"s":"BTCUSDT","U":99556318479,"u":99556318518,"b":[["77710.47000000","0.00060000"],["77709.46000000","0.00000000"],["77708.39000000","2.06710000"],["77530.01000000","0.00000000"],["77524.01000000","0.00811000"],["69946.18000000","0.00000000"],["62174.39000000","0.00032000"],["62174.38000000","0.00000000"]],"a":[["77717.99000000","0.29789000"],["77718.00000000","0.03091000"],["77719.37000000","0.00000000"],["77719.38000000","0.00014000"],["77719.39000000","0.00014000"],["77720.76000000","0.00000000"],["77720.77000000","0.00014000"],["77720.86000000","0.00014000"],["77720.90000000","0.00000000"],["77721.99000000","0.00014000"],["77722.15000000","0.00544000"],["77722.16000000","0.11046000"],["77723.32000000","0.00007000"],["77758.09000000","0.00000000"],["77758.70000000","0.00000000"],["77761.76000000","0.00000000"]]}}
{"type":"depth","received_at_ms":1788333159447,"data":{"e":"depthUpdate","E":1788333159614,"s":"BTCUSDT","U":99556318519,"u":99556318565,"b":[["77708.41000000","0.65161000"],["77708.39000000","0.07112000"],["77695.97000000","0.00000000"],["77693.73000000","0.00200000"],["77690.14000000","1.66240000"],["77640.01000000","0.02000000"],["76552.21000000","0.00030000"],["69946.19000000","0.00224000"],["62174.39000000","0.00000000"],["62174.00000000","0.00000000"]],"a":[["77717.99000000","0.29775000"],["77718.00000000","0.03077000"],["77719.38000000","0.00000000"],["77719.39000000","0.00000000"],["77720.36000000","0.00648000"],["77720.77000000","0.00000000"],["77722.15000000","0.00558000"],["77722.16000000","0.11060000"],["77723.33000000","0.09901000"],["77750.10000000","0.09587000"],["77751.90000000","0.32950000"],["77754.79000000","0.03861000"],["78883.76000000","0.00030000"]]}}
{"type":"depth","received_at_ms":1788333159548,"data":{"e":"depthUpdate","E":1788333159714,"s":"BTCUSDT","U":99556318566,"u":99556318570,"b":[["77705.62000000","0.10671000"],["77665.78000000","0.00411000"],["71491.73000000","0.00014000"],["69946.19000000","0.00224000"]],"a":[]}}
{"type":"depth","received_at_ms":1788333159647,"data":{"e":"depthUpdate","E":1788333159814,"s":"BTCUSDT","U":99556318571,"u":99556318577,"b":[["69946.19000000","0.00240000"]],"a":[["77717.99000000","0.29782000"],["77720.44000000","0.00007000"],["77722.40000000","0.12564000"],["77723.32000000","0.00000000"],["77760.17000000","0.00000000"]]}}
{"type":"depth","received_at_ms":1788333159748,"data":{"e":"depthUpdate","E":1788333159914,"s":"BTCUSDT","U":99556318578,"u":99556318615,"b":[["77715.85000000","0.00007000"],["77693.11000000","0.68159000"],["77658.09000000","0.33527000"],["69946.19000000","0.00240000"],["62174.38000000","0.00000000"]],"a":[["77717.99000000","0.00441000"],["77722.16000000","0.11060000"],["77722.40000000","0.00014000"],["77723.33000000","0.00000000"],["77724.82000000","0.17007000"],["77724.83000000","0.00000000"],["77728.77000000","1.93226000"],["77728.78000000","0.53202000"],["77728.79000000","0.00000000"],["77736.19000000","0.00008000"],["77736.42000000","0.00400000"],["77736.47000000","0.00000000"],["77738.13000000","0.00000000"],["77759.84000000","0.00007000"],["77776.24000000","0.87694000"],["77815.81000000","0.00411000"]]}}
{"type":"depth","received_at_ms":1788333159856,"data":{"e":"depthUpdate","E":1788333160014,"s":"BTCUSDT","U":99556318616,"u":99556318659,"b":[["69946.19000000","0.00256000"],["69946.00000000","0.00000000"],["62174.39000000","0.00032000"],["62174.00000000","0.00000000"]],"a":[["77717.99000000","0.00447000"],["77718.00000000","0.03090000"],["77718.01000000","0.00013000"],["77720.36000000","0.00048000"],["77720.44000000","0.00607000"],["77722.16000000","0.11060000"],["77722.40000000","0.00000000"],["77723.40000000","0.00910000"],["77724.28000000","0.00000000"],["77724.79000000","0.59621000"],["77724.80000000","1.31471000"],["77724.81000000","0.00000000"],["77724.82000000","0.00000000"],["77726.34000000","0.09887000"],["77728.76000000","0.97590000"],["77728.78000000","0.00000000"],["77738.13000000","0.37338000"],["77758.10000000","0.00000000"]]}}
{"type":"depth","received_at_ms":1788333159948,"data":{"e":"depthUpdate","E":1788333160114,"s":"BTCUSDT","U":99556318660,"u":99556318684,"b":[["77709.58000000","0.00321000"],["77706.04000000","0.00007000"],["77700.54000000","0.00000000"],["77614.59000000","0.04877000"],["69946.00000000","0.00000000"]],"a":[["77717.99000000","0.00965000"],["77720.00000000","0.03121000"],["77720.36000000","0.00034000"],["77720.44000000","0.00621000"],["77723.20000000","0.14813000"],["77724.78000000","0.00200000"],["77728.76000000","0.97390000"],["77729.38000000","0.00007000"],["77745.83000000","0.00411000"],["77764.55000000","0.51277000"],["77804.75000000","0.00000000"],["77814.35000000","0.00025000"]]}}
{"type":"depth","received_at_ms":1788333160048,"data":{"e":"depthUpdate","E":1788333160214,"s":"BTCUSDT","U":99556318685,"u":99556318713,"b":[["77715.31000000","0.01334000"],["77714.98000000","0.02895000"],["77712.26000000","0.37338000"],["77711.19000000","0.00000000"],["77708.39000000","0.06787000"],["77700.50000000","0.00000000"],["77699.36000000","0.00015000"],["77539.19000000","0.00000000"],["77018.52000000","0.00010000"],["71491.73000000","0.00000000"],["69946.19000000","0.00272000"],["62174.39000000","0.00000000"]],"a":[["77717.99000000","0.00965000"],["77721.88000000","0.00136000"],["77722.16000000","0.11060000"],["77722.41000000","0.12951000"],["77723.20000000","0.00014000"],["77723.40000000","0.00896000"],["77730.46000000","0.00007000"]]}}
{"type":"depth","received_at_ms":1788333160149,"data":{"e":"depthUpdate","E":1788333160314,"s":"BTCUSDT","U":99556318714,"u":99556318752,"b":[["77717.92000000","0.00400000"],["77715.31000000","0.01334000"],["69946.19000000","0.00272000"],["69946.00000000","0.00020000"],["62174.00000000","0.00000000"]],"a":[["77722.16000000","0.11060000"],["77722.41000000","0.12965000"],["77723.20000000","0.00000000"],["77728.67000000","0.00000000"],["77728.69000000","0.00000000"],["77728.70000000","0.00000000"],["77728.76000000","0.97390000"],["77728.82000000","0.00000000"],["77728.83000000","0.01043000"],["77758.70000000","0.00000000"],["77758.78000000","0.00000000"],["77758.98000000","0.00000000"],["77849.97000000","0.02016000"],["77899.72000000","0.00012000"]]}}
{"type":"depth","received_at_ms":1788333160248,"data":{"e":"depthUpdate","E":1788333160414,"s":"BTCUSDT","U":99556318753,"u":99556318766,"b":[["77714.98000000","0.02902000"],["77714.78000000","0.00800000"],["77714.25000000","0.30643000"],["77714.24000000","0.32012000"],["77713.97000000","0.00000000"],["77713.87000000","0.07773000"],["77552.96000000","0.00033000"],["69946.19000000","0.00272000"],["69946.00000000","0.00000000"]],"a":[["77717.99000000","0.00975000"],["77724.78000000","0.01000000"]]}}
{"type":"trade","received_at_ms":1788333160299,"data":{"e":"trade","E":1788333160463,"s":"BTCUSDT","t":6646665463,"p":"77717.99000000","q":"0.00007000","T":1788333160462,"m":false,"M":true}}
{"type":"trade","received_at_ms":1788333160299,"data":{"e":"trade","E":1788333160463,"s":"BTCUSDT","t":6646665464,"p":"77717.99000000","q":"0.00008000","T":1788333160462,"m":false,"M":true}}
{"type":"trade","received_at_ms":1788333160299,"data":{"e":"trade","E":1788333160463,"s":"BTCUSDT","t":6646665465,"p":"77717.99000000","q":"0.00007000","T":1788333160462,"m":false,"M":true}}
{"type":"trade","received_at_ms":1788333160299,"data":{"e":"trade","E":1788333160463,"s":"BTCUSDT","t":6646665466,"p":"77717.99000000","q":"0.00007000","T":1788333160462,"m":false,"M":true}}
{"type":"trade","received_at_ms":1788333160299,"data":{"e":"trade","E":1788333160463,"s":"BTCUSDT","t":6646665467,"p":"77717.99000000","q":"0.00007000","T":1788333160462,"m":false,"M":true}}
{"type":"trade","received_at_ms":1788333160299,"data":{"e":"trade","E":1788333160463,"s":"BTCUSDT","t":6646665468,"p":"77717.99000000","q":"0.00007000","T":1788333160462,"m":false,"M":true}}
{"type":"trade","received_at_ms":1788333160299,"data":{"e":"trade","E":1788333160463,"s":"BTCUSDT","t":6646665469,"p":"77717.99000000","q":"0.00007000","T":1788333160462,"m":false,"M":true}}
{"type":"trade","received_at_ms":1788333160299,"data":{"e":"trade","E":1788333160463,"s":"BTCUSDT","t":6646665470,"p":"77717.99000000","q":"0.00007000","T":1788333160462,"m":false,"M":true}}
{"type":"trade","received_at_ms":1788333160299,"data":{"e":"trade","E":1788333160463,"s":"BTCUSDT","t":6646665471,"p":"77717.99000000","q":"0.00007000","T":1788333160462,"m":false,"M":true}}
{"type":"trade","received_at_ms":1788333160299,"data":{"e":"trade","E":1788333160463,"s":"BTCUSDT","t":6646665472,"p":"77717.99000000","q":"0.00007000","T":1788333160462,"m":false,"M":true}}
{"type":"trade","received_at_ms":1788333160299,"data":{"e":"trade","E":1788333160463,"s":"BTCUSDT","t":6646665473,"p":"77717.99000000","q":"0.00007000","T":1788333160462,"m":false,"M":true}}
{"type":"trade","received_at_ms":1788333160299,"data":{"e":"trade","E":1788333160463,"s":"BTCUSDT","t":6646665474,"p":"77717.99000000","q":"0.00007000","T":1788333160462,"m":false,"M":true}}
{"type":"trade","received_at_ms":1788333160299,"data":{"e":"trade","E":1788333160463,"s":"BTCUSDT","t":6646665475,"p":"77717.99000000","q":"0.00007000","T":1788333160462,"m":false,"M":true}}
{"type":"trade","received_at_ms":1788333160299,"data":{"e":"trade","E":1788333160463,"s":"BTCUSDT","t":6646665476,"p":"77717.99000000","q":"0.00007000","T":1788333160462,"m":false,"M":true}}
{"type":"trade","received_at_ms":1788333160299,"data":{"e":"trade","E":1788333160463,"s":"BTCUSDT","t":6646665477,"p":"77717.99000000","q":"0.00007000","T":1788333160462,"m":false,"M":true}}
{"type":"trade","received_at_ms":1788333160299,"data":{"e":"trade","E":1788333160463,"s":"BTCUSDT","t":6646665478,"p":"77717.99000000","q":"0.00007000","T":1788333160462,"m":false,"M":true}}
{"type":"trade","received_at_ms":1788333160299,"data":{"e":"trade","E":1788333160463,"s":"BTCUSDT","t":6646665479,"p":"77717.99000000","q":"0.00007000","T":1788333160462,"m":false,"M":true}}
{"type":"trade","received_at_ms":1788333160299,"data":{"e":"trade","E":1788333160463,"s":"BTCUSDT","t":6646665480,"p":"77717.99000000","q":"0.00007000","T":1788333160462,"m":false,"M":true}}
{"type":"trade","received_at_ms":1788333160299,"data":{"e":"trade","E":1788333160463,"s":"BTCUSDT","t":6646665481,"p":"77717.99000000","q":"0.00007000","T":1788333160462,"m":false,"M":true}}
{"type":"trade","received_at_ms":1788333160299,"data":{"e":"trade","E":1788333160463,"s":"BTCUSDT","t":6646665482,"p":"77717.99000000","q":"0.00066000","T":1788333160462,"m":false,"M":true}}
{"type":"trade","received_at_ms":1788333160300,"data":{"e":"trade","E":1788333160463,"s":"BTCUSDT","t":6646665483,"p":"77717.99000000","q":"0.00198000","T":1788333160462,"m":false,"M":true}}
{"type":"trade","received_at_ms":1788333160300,"data":{"e":"trade","E":1788333160463,"s":"BTCUSDT","t":6646665484,"p":"77717.99000000","q":"0.00002000","T":1788333160462,"m":false,"M":true}}
{"type":"trade","received_at_ms":1788333160300,"data":{"e":"trade","E":1788333160463,"s":"BTCUSDT","t":6646665485,"p":"77717.99000000","q":"0.00005000","T":1788333160463,"m":false,"M":true}}
{"type":"trade","received_at_ms":1788333160300,"data":{"e":"trade","E":1788333160463,"s":"BTCUSDT","t":6646665486,"p":"77717.99000000","q":"0.00007000","T":1788333160463,"m":false,"M":true}}
{"type":"trade","received_at_ms":1788333160300,"data":{"e":"trade","E":1788333160463,"s":"BTCUSDT","t":6646665487,"p":"77717.99000000","q":"0.00007000","T":1788333160463,"m":false,"M":true}}
{"type":"trade","received_at_ms":1788333160300,"data":{"e":"trade","E":1788333160463,"s":"BTCUSDT","t":6646665488,"p":"77717.99000000","q":"0.00013000","T":1788333160463,"m":false,"M":true}}
{"type":"trade","received_at_ms":1788333160300,"data":{"e":"trade","E":1788333160463,"s":"BTCUSDT","t":6646665489,"p":"77717.99000000","q":"0.00007000","T":1788333160463,"m":false,"M":true}}
{"type":"trade","received_at_ms":1788333160300,"data":{"e":"trade","E":1788333160463,"s":"BTCUSDT","t":6646665490,"p":"77717.99000000","q":"0.00161000","T":1788333160463,"m":false,"M":true}}
{"type":"trade","received_at_ms":1788333160323,"data":{"e":"trade","E":1788333160489,"s":"BTCUSDT","t":6646665491,"p":"77717.99000000","q":"0.00140000","T":1788333160489,"m":false,"M":true}}
{"type":"depth","received_at_ms":1788333160348,"data":{"e":"depthUpdate","E":1788333160514,"s":"BTCUSDT","U":99556318767,"u":99556318879,"b":[["77717.98000000","4.90170000"],["77716.75000000","0.27309000"],["77714.00000000","0.34012000"],["77704.64000000","0.00000000"],["77665.78000000","0.00000000"],["77634.70000000","0.00000000"],["77545.26000000","0.00000000"],["69946.19000000","0.00297000"],["69946.00000000","0.00010000"],["62174.39000000","0.00032000"],["62174.38000000","0.00000000"],["62174.00000000","0.00000000"]],"a":[["77717.99000000","0.00390000"],["77722.41000000","0.00014000"],["77724.77000000","0.00800000"],["77724.78000000","0.00200000"],["77728.83000000","0.00643000"],["77728.91000000","0.00400000"],["77728.92000000","0.00000000"],["77745.83000000","0.00000000"],["77759.84000000","0.00000000"],["77784.71000000","0.00418000"],["77815.81000000","0.00000000"],["77832.72000000","0.00000000"],["77871.63000000","0.00000000"]]}}
{"type":"depth","received_at_ms":1788333160447,"data":{"e":"depthUpdate","E":1788333160614,"s":"BTCUSDT","U":99556318880,"u":99556318902,"b":[["77524.01000000","0.00000000"],["77522.01000000","0.00811000"],["76552.21000000","0.00030000"],["69946.19000000","0.00313000"],["69946.00000000","0.00000000"],["62174.39000000","0.00000000"]],"a":[["77722.16000000","0.11060000"],["77722.41000000","0.00000000"],["77723.40000000","0.00910000"],["78883.76000000","0.00030000"]]}}
{"type":"trade","received_at_ms":1788333160494,"data":{"e":"trade","E":1788333160651,"s":"BTCUSDT","t":6646665492,"p":"77717.99000000","q":"0.00218000","T":1788333160651,"m":false,"M":true}}
{"type":"trade","received_at_ms":1788333160494,"data":{"e":"trade","E":1788333160651,"s":"BTCUSDT","t":6646665493,"p":"77717.99000000","q":"0.00010000","T":1788333160651,"m":false,"M":true}}
{"type":"trade","received_at_ms":1788333160494,"data":{"e":"trade","E":1788333160651,"s":"BTCUSDT","t":6646665494,"p":"77717.99000000","q":"0.00007000","T":1788333160651,"m":false,"M":true}}
{"type":"trade","received_at_ms":1788333160494,"data":{"e":"trade","E":1788333160651,"s":"BTCUSDT","t":6646665495,"p":"77717.99000000","q":"0.00007000","T":1788333160651,"m":false,"M":true}}
{"type":"trade","received_at_ms":1788333160494,"data":{"e":"trade","E":1788333160651,"s":"BTCUSDT","t":6646665496,"p":"77717.99000000","q":"0.00007000","T":1788333160651,"m":false,"M":true}}
{"type":"trade","received_at_ms":1788333160494,"data":{"e":"trade","E":1788333160651,"s":"BTCUSDT","t":6646665497,"p":"77717.99000000","q":"0.00007000","T":1788333160651,"m":false,"M":true}}
{"type":"trade","received_at_ms":1788333160494,"data":{"e":"trade","E":1788333160651,"s":"BTCUSDT","t":6646665498,"p":"77717.99000000","q":"0.00007000","T":1788333160651,"m":false,"M":true}}
{"type":"trade","received_at_ms":1788333160494,"data":{"e":"trade","E":1788333160651,"s":"BTCUSDT","t":6646665499,"p":"77717.99000000","q":"0.00007000","T":1788333160651,"m":false,"M":true}}
{"type":"trade","received_at_ms":1788333160494,"data":{"e":"trade","E":1788333160651,"s":"BTCUSDT","t":6646665500,"p":"77717.99000000","q":"0.00007000","T":1788333160651,"m":false,"M":true}}
{"type":"trade","received_at_ms":1788333160494,"data":{"e":"trade","E":1788333160651,"s":"BTCUSDT","t":6646665501,"p":"77717.99000000","q":"0.00007000","T":1788333160651,"m":false,"M":true}}
{"type":"trade","received_at_ms":1788333160494,"data":{"e":"trade","E":1788333160651,"s":"BTCUSDT","t":6646665502,"p":"77717.99000000","q":"0.00008000","T":1788333160651,"m":false,"M":true}}
{"type":"trade","received_at_ms":1788333160494,"data":{"e":"trade","E":1788333160651,"s":"BTCUSDT","t":6646665503,"p":"77717.99000000","q":"0.00007000","T":1788333160651,"m":false,"M":true}}
{"type":"trade","received_at_ms":1788333160494,"data":{"e":"trade","E":1788333160651,"s":"BTCUSDT","t":6646665504,"p":"77717.99000000","q":"0.00007000","T":1788333160651,"m":false,"M":true}}
{"type":"trade","received_at_ms":1788333160494,"data":{"e":"trade","E":1788333160651,"s":"BTCUSDT","t":6646665505,"p":"77717.99000000","q":"0.00007000","T":1788333160651,"m":false,"M":true}}
{"type":"trade","received_at_ms":1788333160494,"data":{"e":"trade","E":1788333160651,"s":"BTCUSDT","t":6646665506,"p":"77717.99000000","q":"0.00008000","T":1788333160651,"m":false,"M":true}}
{"type":"trade","received_at_ms":1788333160494,"data":{"e":"trade","E":1788333160651,"s":"BTCUSDT","t":6646665507,"p":"77717.99000000","q":"0.00007000","T":1788333160651,"m":false,"M":true}}
{"type":"trade","received_at_ms":1788333160494,"data":{"e":"trade","E":1788333160651,"s":"BTCUSDT","t":6646665508,"p":"77717.99000000","q":"0.00007000","T":1788333160651,"m":false,"M":true}}
{"type":"trade","received_at_ms":1788333160494,"data":{"e":"trade","E":1788333160651,"s":"BTCUSDT","t":6646665509,"p":"77717.99000000","q":"0.00007000","T":1788333160651,"m":false,"M":true}}
{"type":"trade","received_at_ms":1788333160494,"data":{"e":"trade","E":1788333160651,"s":"BTCUSDT","t":6646665510,"p":"77717.99000000","q":"0.00013000","T":1788333160651,"m":false,"M":true}}
{"type":"trade","received_at_ms":1788333160494,"data":{"e":"trade","E":1788333160651,"s":"BTCUSDT","t":6646665511,"p":"77717.99000000","q":"0.00007000","T":1788333160651,"m":false,"M":true}}
{"type":"trade","received_at_ms":1788333160494,"data":{"e":"trade","E":1788333160651,"s":"BTCUSDT","t":6646665512,"p":"77717.99000000","q":"0.00007000","T":1788333160651,"m":false,"M":true}}
{"type":"trade","received_at_ms":1788333160494,"data":{"e":"trade","E":1788333160651,"s":"BTCUSDT","t":6646665513,"p":"77717.99000000","q":"0.00007000","T":1788333160651,"m":false,"M":true}}
{"type":"trade","received_at_ms":1788333160494,"data":{"e":"trade","E":1788333160651,"s":"BTCUSDT","t":6646665514,"p":"77717.99000000","q":"0.00007000","T":1788333160651,"m":false,"M":true}}
{"type":"trade","received_at_ms":1788333160494,"data":{"e":"trade","E":1788333160651,"s":"BTCUSDT","t":6646665515,"p":"77717.99000000","q":"0.00007000","T":1788333160651,"m":false,"M":true}}
{"type":"trade","received_at_ms":1788333160494,"data":{"e":"trade","E":1788333160651,"s":"BTCUSDT","t":6646665516,"p":"77717.99000000","q":"0.00007000","T":1788333160651,"m":false,"M":true}}
{"type":"trade","received_at_ms":1788333160517,"data":{"e":"trade","E":1788333160683,"s":"BTCUSDT","t":6646665517,"p":"77718.00000000","q":"0.00012000","T":1788333160682,"m":false,"M":true}}
{"type":"depth","received_at_ms":1788333160548,"data":{"e":"depthUpdate","E":1788333160714,"s":"BTCUSDT","U":99556318903,"u":99556319087,"b":[["77717.99000000","4.38096000"],["77717.98000000","2.02156000"],["77717.97000000","0.01047000"],["77717.96000000","0.00000000"],["77717.91000000","0.00000000"],["77716.76000000","0.00007000"],["77716.75000000","0.00021000"],["77715.85000000","0.00000000"],["77715.31000000","0.01320000"],["77714.78000000","0.01200000"],["77713.52000000","0.00007000"],["77706.05000000","0.00007000"],["77706.04000000","0.00000000"],["77550.23000000","0.00000000"],["77466.90000000","0.00000000"],["77079.40000000","0.00250000"],["76552.21000000","0.00000000"],["69946.20000000","0.00016000"],["69946.19000000","0.00009000"],["62174.00000000","0.00000000"]],"a":[["77717.99000000","0.00000000"],["77718.00000000","0.03762000"],["77718.01000000","0.00076000"],["77722.15000000","0.00565000"],["77723.06000000","0.00007000"],["77723.07000000","0.11860000"],["77723.54000000","0.00007000"],["77723.55000000","0.10685000"],["77724.76000000","0.11690000"],["77726.27000000","0.00208000"],["77745.85000000","0.00411000"],["77748.40000000","0.00000000"],["77750.10000000","0.00000000"],["77897.68000000","0.00250000"],["78883.76000000","0.00000000"]]}}
{"type":"trade","received_at_ms":1788333160617,"data":{"e":"trade","E":1788333160780,"s":"BTCUSDT","t":6646665518,"p":"77718.00000000","q":"0.00025000","T":1788333160780,"m":false,"M":true}}
{"type":"depth","received_at_ms":1788333160648,"data":{"e":"depthUpdate","E":1788333160814,"s":"BTCUSDT","U":99556319088,"u":99556319125,"b":[["77717.99000000","4.40637000"],["77717.98000000","1.80286000"],["77717.90000000","0.05021000"],["77716.75000000","0.00007000"],["77714.77000000","0.01014000"],["77714.76000000","1.51868000"],["69946.20000000","0.00032000"],["69946.19000000","0.00000000"],["69946.18000000","0.00009000"]],"a":[["77718.00000000","0.03866000"],["77720.78000000","0.11290000"],["77722.16000000","0.11060000"],["77723.07000000","0.11874000"],["77723.55000000","0.10671000"],["77728.35000000","0.00000000"],["77758.51000000","0.03762000"],["77759.84000000","0.00007000"]]}}
{"type":"depth","received_at_ms":1788333160748,"data":{"e":"depthUpdate","E":1788333160915,"s":"BTCUSDT","U":99556319126,"u":99556319147,"b":[["77717.99000000","4.41637000"],["77714.26000000","0.00014000"],["69946.20000000","0.00064000"],["69946.00000000","0.00010000"],["62174.39000000","0.00000000"]],"a":[["77718.00000000","0.03873000"],["77718.01000000","0.00083000"],["77720.44000000","0.00621000"],["77720.77000000","0.00014000"],["77720.78000000","0.11304000"],["77723.06000000","0.00000000"],["77723.40000000","0.00896000"],["77723.54000000","0.00000000"]]}}
{"type":"trade","received_at_ms":1788333160801,"data":{"e":"trade","E":1788333160966,"s":"BTCUSDT","t":6646665519,"p":"77718.00000000","q":"0.00963000","T":1788333160965,"m":false,"M":true}}
{"type":"trade","received_at_ms":1788333160801,"data":{"e":"trade","E":1788333160966,"s":"BTCUSDT","t":6646665520,"p":"77718.00000000","q":"0.00500000","T":1788333160965,"m":false,"M":true}}
{"type":"trade","received_at_ms":1788333160801,"data":{"e":"trade","E":1788333160966,"s":"BTCUSDT","t":6646665521,"p":"77718.00000000","q":"0.00500000","T":1788333160965,"m":false,"M":true}}
{"type":"trade","received_at_ms":1788333160801,"data":{"e":"trade","E":1788333160966,"s":"BTCUSDT","t":6646665522,"p":"77718.00000000","q":"0.00137000","T":1788333160965,"m":false,"M":true}}
{"type":"trade","received_at_ms":1788333160805,"data":{"e":"trade","E":1788333160966,"s":"BTCUSDT","t":6646665523,"p":"77718.00000000","q":"0.00863000","T":1788333160966,"m":false,"M":true}}
{"type":"trade","received_at_ms":1788333160805,"data":{"e":"trade","E":1788333160966,"s":"BTCUSDT","t":6646665524,"p":"77718.00000000","q":"0.00007000","T":1788333160966,"m":false,"M":true}}
{"type":"trade","received_at_ms":1788333160805,"data":{"e":"trade","E":1788333160966,"s":"BTCUSDT","t":6646665525,"p":"77718.00000000","q":"0.00007000","T":1788333160966,"m":false,"M":true}}
{"type":"trade","received_at_ms":1788333160805,"data":{"e":"trade","E":1788333160966,"s":"BTCUSDT","t":6646665526,"p":"77718.00000000","q":"0.00007000","T":1788333160966,"m":false,"M":true}}
{"type":"trade","received_at_ms":1788333160805,"data":{"e":"trade","E":1788333160966,"s":"BTCUSDT","t":6646665527,"p":"77718.00000000","q":"0.00007000","T":1788333160966,"m":false,"M":true}}
{"type":"trade","received_at_ms":1788333160805,"data":{"e":"trade","E":1788333160966,"s":"BTCUSDT","t":6646665528,"p":"77718.00000000","q":"0.00007000","T":1788333160966,"m":false,"M":true}}
{"type":"trade","received_at_ms":1788333160805,"data":{"e":"trade","E":1788333160966,"s":"BTCUSDT","t":6646665529,"p":"77718.00000000","q":"0.00007000","T":1788333160966,"m":false,"M":true}}
{"type":"trade","received_at_ms":1788333160806,"data":{"e":"trade","E":1788333160966,"s":"BTCUSDT","t":6646665530,"p":"77718.00000000","q":"0.00007000","T":1788333160966,"m":false,"M":true}}
{"type":"trade","received_at_ms":1788333160806,"data":{"e":"trade","E":1788333160966,"s":"BTCUSDT","t":6646665531,"p":"77718.00000000","q":"0.00013000","T":1788333160966,"m":false,"M":true}}
{"type":"trade","received_at_ms":1788333160806,"data":{"e":"trade","E":1788333160966,"s":"BTCUSDT","t":6646665532,"p":"77718.00000000","q":"0.00007000","T":1788333160966,"m":false,"M":true}}
{"type":"trade","received_at_ms":1788333160806,"data":{"e":"trade","E":1788333160966,"s":"BTCUSDT","t":6646665533,"p":"77718.00000000","q":"0.00007000","T":1788333160966,"m":false,"M":true}}
{"type":"trade","received_at_ms":1788333160806,"data":{"e":"trade","E":1788333160966,"s":"BTCUSDT","t":6646665534,"p":"77718.00000000","q":"0.00007000","T":1788333160966,"m":false,"M":true}}
{"type":"trade","received_at_ms":1788333160806,"data":{"e":"trade","E":1788333160966,"s":"BTCUSDT","t":6646665535,"p":"77718.00000000","q":"0.00007000","T":1788333160966,"m":false,"M":true}}
{"type":"trade","received_at_ms":1788333160806,"data":{"e":"trade","E":1788333160966,"s":"BTCUSDT","t":6646665536,"p":"77718.00000000","q":"0.00007000","T":1788333160966,"m":false,"M":true}}
{"type":"trade","received_at_ms":1788333160806,"data":{"e":"trade","E":1788333160966,"s":"BTCUSDT","t":6646665537,"p":"77718.00000000","q":"0.00007000","T":1788333160966,"m":false,"M":true}}
{"type":"trade","received_at_ms":1788333160806,"data":{"e":"trade","E":1788333160966,"s":"BTCUSDT","t":6646665538,"p":"77718.00000000","q":"0.00585000","T":1788333160966,"m":false,"M":true}}
{"type":"trade","received_at_ms":1788333160806,"data":{"e":"trade","E":1788333160966,"s":"BTCUSDT","t":6646665539,"p":"77718.00000000","q":"0.00007000","T":1788333160966,"m":false,"M":true}}
{"type":"trade","received_at_ms":1788333160806,"data":{"e":"trade","E":1788333160966,"s":"BTCUSDT","t":6646665540,"p":"77718.00000000","q":"0.00007000","T":1788333160966,"m":false,"M":true}}
{"type":"trade","received_at_ms":1788333160806,"data":{"e":"trade","E":1788333160966,"s":"BTCUSDT","t":6646665541,"p":"77718.00000000","q":"0.00007000","T":1788333160966,"m":false,"M":true}}
{"type":"trade","received_at_ms":1788333160806,"data":{"e":"trade","E":1788333160966,"s":"BTCUSDT","t":6646665542,"p":"77718.00000000","q":"0.00007000","T":1788333160966,"m":false,"M":true}}
{"type":"trade","received_at_ms":1788333160806,"data":{"e":"trade","E":1788333160966,"s":"BTCUSDT","t":6646665543,"p":"77718.00000000","q":"0.00007000","T":1788333160966,"m":false,"M":true}}
{"type":"trade","received_at_ms":1788333160806,"data":{"e":"trade","E":1788333160966,"s":"BTCUSDT","t":6646665544,"p":"77718.00000000","q":"0.00007000","T":1788333160966,"m":false,"M":true}}
{"type":"trade","received_at_ms":1788333160806,"data":{"e":"trade","E":1788333160966,"s":"BTCUSDT","t":6646665545,"p":"77718.00000000","q":"0.00007000","T":1788333160966,"m":false,"M":true}}
{"type":"trade","received_at_ms":1788333160806,"data":{"e":"trade","E":1788333160966,"s":"BTCUSDT","t":6646665546,"p":"77718.00000000","q":"0.00007000","T":1788333160966,"m":false,"M":true}}
{"type":"trade","received_at_ms":1788333160806,"data":{"e":"trade","E":1788333160966,"s":"BTCUSDT","t":6646665547,"p":"77718.00000000","q":"0.00007000","T":1788333160966,"m":false,"M":true}}
{"type":"trade","received_at_ms":1788333160806,"data":{"e":"trade","E":1788333160966,"s":"BTCUSDT","t":6646665548,"p":"77718.00000000","q":"0.00007000","T":1788333160966,"m":false,"M":true}}
{"type":"trade","received_at_ms":1788333160806,"data":{"e":"trade","E":1788333160966,"s":"BTCUSDT","t":6646665549,"p":"77718.00000000","q":"0.00008000","T":1788333160966,"m":false,"M":true}}
{"type":"trade","received_at_ms":1788333160806,"data":{"e":"trade","E":1788333160966,"s":"BTCUSDT","t":6646665550,"p":"77718.00000000","q":"0.00007000","T":1788333160966,"m":false,"M":true}}
{"type":"trade","received_at_ms":1788333160806,"data":{"e":"trade","E":1788333160966,"s":"BTCUSDT","t":6646665551,"p":"77718.00000000","q":"0.00064000","T":1788333160966,"m":false,"M":true}}
{"type":"trade","received_at_ms":1788333160806,"data":{"e":"trade","E":1788333160966,"s":"BTCUSDT","t":6646665552,"p":"77718.00000000","q":"0.00065000","T":1788333160966,"m":false,"M":true}}
{"type":"trade","received_at_ms":1788333160806,"data":{"e":"trade","E":1788333160966,"s":"BTCUSDT","t":6646665553,"p":"77718.00000000","q":"0.00007000","T":1788333160966,"m":false,"M":true}}
{"type":"trade","received_at_ms":1788333160806,"data":{"e":"trade","E":1788333160966,"s":"BTCUSDT","t":6646665554,"p":"77718.01000000","q":"0.00013000","T":1788333160966,"m":false,"M":true}}
{"type":"trade","received_at_ms":1788333160806,"data":{"e":"trade","E":1788333160966,"s":"BTCUSDT","t":6646665555,"p":"77718.01000000","q":"0.00007000","T":1788333160966,"m":false,"M":true}}
{"type":"trade","received_at_ms":1788333160806,"data":{"e":"trade","E":1788333160966,"s":"BTCUSDT","t":6646665556,"p":"77718.01000000","q":"0.00007000","T":1788333160966,"m":false,"M":true}}
{"type":"trade","received_at_ms":1788333160806,"data":{"e":"trade","E":1788333160966,"s":"BTCUSDT","t":6646665557,"p":"77718.01000000","q":"0.00007000","T":1788333160966,"m":false,"M":true}}
{"type":"trade","received_at_ms":1788333160806,"data":{"e":"trade","E":1788333160966,"s":"BTCUSDT","t":6646665558,"p":"77718.01000000","q":"0.00007000","T":1788333160966,"m":false,"M":true}}
{"type":"trade","received_at_ms":1788333160806,"data":{"e":"trade","E":1788333160966,"s":"BTCUSDT","t":6646665559,"p":"77718.01000000","q":"0.00007000","T":1788333160966,"m":false,"M":true}}
{"type":"trade","received_at_ms":1788333160806,"data":{"e":"trade","E":1788333160966,"s":"BTCUSDT","t":6646665560,"p":"77718.01000000","q":"0.00007000","T":1788333160966,"m":false,"M":true}}
{"type":"trade","received_at_ms":1788333160806,"data":{"e":"trade","E":1788333160966,"s":"BTCUSDT","t":6646665561,"p":"77718.01000000","q":"0.00007000","T":1788333160966,"m":false,"M":true}}
{"type":"trade","received_at_ms":1788333160806,"data":{"e":"trade","E":1788333160966,"s":"BTCUSDT","t":6646665562,"p":"77718.01000000","q":"0.00007000","T":1788333160966,"m":false,"M":true}}
{"type":"trade","received_at_ms":1788333160806,"data":{"e":"trade","E":1788333160966,"s":"BTCUSDT","t":6646665563,"p":"77718.01000000","q":"0.00007000","T":1788333160966,"m":false,"M":true}}
{"type":"trade","received_at_ms":1788333160806,"data":{"e":"trade","E":1788333160966,"s":"BTCUSDT","t":6646665564,"p":"77718.01000000","q":"0.00007000","T":1788333160966,"m":false,"M":true}}
{"type":"trade","received_at_ms":1788333160806,"data":{"e":"trade","E":1788333160967,"s":"BTCUSDT","t":6646665565,"p":"77718.73000000","q":"0.00041000","T":1788333160967,"m":false,"M":true}}
{"type":"trade","received_at_ms":1788333160806,"data":{"e":"trade","E":1788333160967,"s":"BTCUSDT","t":6646665566,"p":"77718.88000000","q":"0.00008000","T":1788333160967,"m":false,"M":true}}
{"type":"trade","received_at_ms":1788333160809,"data":{"e":"trade","E":1788333160971,"s":"BTCUSDT","t":6646665567,"p":"77719.35000000","q":"0.00015000","T":1788333160970,"m":false,"M":true}}
{"type":"trade","received_at_ms":1788333160809,"data":{"e":"trade","E":1788333160971,"s":"BTCUSDT","t":6646665568,"p":"77719.35000000","q":"0.00031000","T":1788333160970,"m":false,"M":true}}
{"type":"trade","received_at_ms":1788333160809,"data":{"e":"trade","E":1788333160971,"s":"BTCUSDT","t":6646665569,"p":"77719.35000000","q":"0.00007000","T":1788333160970,"m":false,"M":true}}
{"type":"trade","received_at_ms":1788333160809,"data":{"e":"trade","E":1788333160971,"s":"BTCUSDT","t":6646665570,"p":"77719.35000000","q":"0.00191000","T":1788333160970,"m":false,"M":true}}
{"type":"trade","received_at_ms":1788333160811,"data":{"e":"trade","E":1788333160972,"s":"BTCUSDT","t":6646665571,"p":"77719.35000000","q":"0.00137000","T":1788333160972,"m":false,"M":true}}
{"type":"trade","received_at_ms":1788333160811,"data":{"e":"trade","E":1788333160972,"s":"BTCUSDT","t":6646665572,"p":"77719.35000000","q":"0.00007000","T":1788333160972,"m":false,"M":true}}
{"type":"trade","received_at_ms":1788333160811,"data":{"e":"trade","E":1788333160972,"s":"BTCUSDT","t":6646665573,"p":"77719.35000000","q":"0.00007000","T":1788333160972,"m":false,"M":true}}
{"type":"trade","received_at_ms":1788333160811,"data":{"e":"trade","E":1788333160972,"s":"BTCUSDT","t":6646665574,"p":"77719.35000000","q":"0.00007000","T":1788333160972,"m":false,"M":true}}
{"type":"trade","received_at_ms":1788333160811,"data":{"e":"trade","E":1788333160972,"s":"BTCUSDT","t":6646665575,"p":"77719.35000000","q":"0.00007000","T":1788333160972,"m":false,"M":true}}
{"type":"trade","received_at_ms":1788333160811,"data":{"e":"trade","E":1788333160972,"s":"BTCUSDT","t":6646665576,"p":"77719.35000000","q":"0.00007000","T":1788333160972,"m":false,"M":true}}
{"type":"trade","received_at_ms":1788333160811,"data":{"e":"trade","E":1788333160972,"s":"BTCUSDT","t":6646665577,"p":"77719.35000000","q":"0.00007000","T":1788333160972,"m":false,"M":true}}
{"type":"trade","received_at_ms":1788333160811,"data":{"e":"trade","E":1788333160972,"s":"BTCUSDT","t":6646665578,"p":"77719.35000000","q":"0.00007000","T":1788333160972,"m":false,"M":true}}
{"type":"trade","received_at_ms":1788333160811,"data":{"e":"trade","E":1788333160972,"s":"BTCUSDT","t":6646665579,"p":"77719.35000000","q":"0.00007000","T":1788333160972,"m":false,"M":true}}
{"type":"trade","received_at_ms":1788333160811,"data":{"e":"trade","E":1788333160972,"s":"BTCUSDT","t":6646665580,"p":"77719.35000000","q":"0.00007000","T":1788333160972,"m":false,"M":true}}
{"type":"trade","received_at_ms":1788333160811,"data":{"e":"trade","E":1788333160972,"s":"BTCUSDT","t":6646665581,"p":"77719.35000000","q":"0.00065000","T":1788333160972,"m":false,"M":true}}
{"type":"trade","received_at_ms":1788333160811,"data":{"e":"trade","E":1788333160972,"s":"BTCUSDT","t":6646665582,"p":"77719.35000000","q":"0.00064000","T":1788333160972,"m":false,"M":true}}
{"type":"trade","received_at_ms":1788333160811,"data":{"e":"trade","E":1788333160972,"s":"BTCUSDT","t":6646665583,"p":"77719.35000000","q":"0.00345000","T":1788333160972,"m":false,"M":true}}
{"type":"trade","received_at_ms":1788333160811,"data":{"e":"trade","E":1788333160972,"s":"BTCUSDT","t":6646665584,"p":"77719.35000000","q":"0.00007000","T":1788333160972,"m":false,"M":true}}
{"type":"trade","received_at_ms":1788333160811,"data":{"e":"trade","E":1788333160972,"s":"BTCUSDT","t":6646665585,"p":"77719.35000000","q":"0.00007000","T":1788333160972,"m":false,"M":true}}
{"type":"trade","received_at_ms":1788333160811,"data":{"e":"trade","E":1788333160972,"s":"BTCUSDT","t":6646665586,"p":"77719.36000000","q":"0.00007000","T":1788333160972,"m":false,"M":true}}
{"type":"trade","received_at_ms":1788333160812,"data":{"e":"trade","E":1788333160972,"s":"BTCUSDT","t":6646665587,"p":"77719.36000000","q":"0.00007000","T":1788333160972,"m":false,"M":true}}
{"type":"trade","received_at_ms":1788333160812,"data":{"e":"trade","E":1788333160972,"s":"BTCUSDT","t":6646665588,"p":"77719.36000000","q":"0.00007000","T":1788333160972,"m":false,"M":true}}
{"type":"trade","received_at_ms":1788333160812,"data":{"e":"trade","E":1788333160972,"s":"BTCUSDT","t":6646665589,"p":"77719.36000000","q":"0.00007000","T":1788333160972,"m":false,"M":true}}
{"type":"trade","received_at_ms":1788333160812,"data":{"e":"trade","E":1788333160972,"s":"BTCUSDT","t":6646665590,"p":"77719.36000000","q":"0.00007000","T":1788333160972,"m":false,"M":true}}
{"type":"trade","received_at_ms":1788333160812,"data":{"e":"trade","E":1788333160972,"s":"BTCUSDT","t":6646665591,"p":"77719.36000000","q":"0.00007000","T":1788333160972,"m":false,"M":true}}
{"type":"trade","received_at_ms":1788333160812,"data":{"e":"trade","E":1788333160972,"s":"BTCUSDT","t":6646665592,"p":"77719.99000000","q":"0.00007000","T":1788333160972,"m":false,"M":true}}
{"type":"trade","received_at_ms":1788333160812,"data":{"e":"trade","E":1788333160972,"s":"BTCUSDT","t":6646665593,"p":"77719.99000000","q":"0.00007000","T":1788333160972,"m":false,"M":true}}
{"type":"trade","received_at_ms":1788333160812,"data":{"e":"trade","E":1788333160972,"s":"BTCUSDT","t":6646665594,"p":"77719.99000000","q":"0.00007000","T":1788333160972,"m":false,"M":true}}
{"type":"trade","received_at_ms":1788333160812,"data":{"e":"trade","E":1788333160972,"s":"BTCUSDT","t":6646665595,"p":"77720.00000000","q":"0.00050000","T":1788333160972,"m":false,"M":true}}
{"type":"trade","received_at_ms":1788333160812,"data":{"e":"trade","E":1788333160972,"s":"BTCUSDT","t":6646665596,"p":"77720.00000000","q":"0.00008000","T":1788333160972,"m":false,"M":true}}
{"type":"trade","received_at_ms":1788333160812,"data":{"e":"trade","E":1788333160972,"s":"BTCUSDT","t":6646665597,"p":"77720.00000000","q":"0.00049000","T":1788333160972,"m":false,"M":true}}
{"type":"trade","received_at_ms":1788333160812,"data":{"e":"trade","E":1788333160972,"s":"BTCUSDT","t":6646665598,"p":"77720.00000000","q":"0.01000000","T":1788333160972,"m":false,"M":true}}
{"type":"trade","received_at_ms":1788333160812,"data":{"e":"trade","E":1788333160972,"s":"BTCUSDT","t":6646665599,"p":"77720.00000000","q":"0.00242000","T":1788333160972,"m":false,"M":true}}
{"type":"trade","received_at_ms":1788333160812,"data":{"e":"trade","E":1788333160973,"s":"BTCUSDT","t":6646665600,"p":"77720.00000000","q":"0.00258000","T":1788333160972,"m":false,"M":true}}
{"type":"trade","received_at_ms":1788333160812,"data":{"e":"trade","E":1788333160973,"s":"BTCUSDT","t":6646665601,"p":"77720.00000000","q":"0.00500000","T":1788333160972,"m":false,"M":true}}
{"type":"trade","received_at_ms":1788333160812,"data":{"e":"trade","E":1788333160973,"s":"BTCUSDT","t":6646665602,"p":"77720.00000000","q":"0.01000000","T":1788333160972,"m":false,"M":true}}
{"type":"trade","received_at_ms":1788333160812,"data":{"e":"trade","E":1788333160973,"s":"BTCUSDT","t":6646665603,"p":"77720.00000000","q":"0.00007000","T":1788333160972,"m":false,"M":true}}
{"type":"trade","received_at_ms":1788333160812,"data":{"e":"trade","E":1788333160973,"s":"BTCUSDT","t":6646665604,"p":"77720.00000000","q":"0.00007000","T":1788333160972,"m":false,"M":true}}
{"type":"trade","received_at_ms":1788333160812,"data":{"e":"trade","E":1788333160973,"s":"BTCUSDT","t":6646665605,"p":"77720.36000000","q":"0.00034000","T":1788333160972,"m":false,"M":true}}
{"type":"trade","received_at_ms":1788333160812,"data":{"e":"trade","E":1788333160973,"s":"BTCUSDT","t":6646665606,"p":"77720.44000000","q":"0.00007000","T":1788333160972,"m":false,"M":true}}
{"type":"trade","received_at_ms":1788333160812,"data":{"e":"trade","E":1788333160973,"s":"BTCUSDT","t":6646665607,"p":"77720.44000000","q":"0.00287000","T":1788333160972,"m":false,"M":true}}
{"type":"trade","received_at_ms":1788333160812,"data":{"e":"trade","E":1788333160973,"s":"BTCUSDT","t":6646665608,"p":"77720.44000000","q":"0.00313000","T":1788333160972,"m":false,"M":true}}
{"type":"trade","received_at_ms":1788333160812,"data":{"e":"trade","E":1788333160973,"s":"BTCUSDT","t":6646665609,"p":"77720.44000000","q":"0.00007000","T":1788333160972,"m":false,"M":true}}
{"type":"trade","received_at_ms":1788333160812,"data":{"e":"trade","E":1788333160973,"s":"BTCUSDT","t":6646665610,"p":"77720.44000000","q":"0.00007000","T":1788333160972,"m":false,"M":true}}
{"type":"trade","received_at_ms":1788333160812,"data":{"e":"trade","E":1788333160973,"s":"BTCUSDT","t":6646665611,"p":"77720.52000000","q":"0.00011000","T":1788333160972,"m":false,"M":true}}
{"type":"trade","received_at_ms":1788333160812,"data":{"e":"trade","E":1788333160973,"s":"BTCUSDT","t":6646665612,"p":"77720.73000000","q":"0.00321000","T":1788333160972,"m":false,"M":true}}
{"type":"trade","received_at_ms":1788333160812,"data":{"e":"trade","E":1788333160973,"s":"BTCUSDT","t":6646665613,"p":"77720.77000000","q":"0.00007000","T":1788333160972,"m":false,"M":true}}
{"type":"trade","received_at_ms":1788333160812,"data":{"e":"trade","E":1788333160973,"s":"BTCUSDT","t":6646665614,"p":"77720.77000000","q":"0.00007000","T":1788333160972,"m":false,"M":true}}
{"type":"trade","received_at_ms":1788333160812,"data":{"e":"trade","E":1788333160973,"s":"BTCUSDT","t":6646665615,"p":"77720.77000000","q":"0.00007000","T":1788333160972,"m":false,"M":true}}
{"type":"trade","received_at_ms":1788333160812,"data":{"e":"trade","E":1788333160973,"s":"BTCUSDT","t":6646665616,"p":"77720.78000000","q":"0.00007000","T":1788333160972,"m":false,"M":true}}
{"type":"trade","received_at_ms":1788333160812,"data":{"e":"trade","E":1788333160973,"s":"BTCUSDT","t":6646665617,"p":"77720.78000000","q":"0.00007000","T":1788333160972,"m":false,"M":true}}
{"type":"trade","received_at_ms":1788333160812,"data":{"e":"trade","E":1788333160973,"s":"BTCUSDT","t":6646665618,"p":"77720.86000000","q":"0.00007000","T":1788333160972,"m":false,"M":true}}
{"type":"trade","received_at_ms":1788333160812,"data":{"e":"trade","E":1788333160973,"s":"BTCUSDT","t":6646665619,"p":"77720.86000000","q":"0.00007000","T":1788333160972,"m":false,"M":true}}
{"type":"trade","received_at_ms":1788333160812,"data":{"e":"trade","E":1788333160973,"s":"BTCUSDT","t":6646665620,"p":"77720.86000000","q":"0.00007000","T":1788333160972,"m":false,"M":true}}
{"type":"trade","received_at_ms":1788333160812,"data":{"e":"trade","E":1788333160973,"s":"BTCUSDT","t":6646665621,"p":"77720.87000000","q":"0.01385000","T":1788333160972,"m":false,"M":true}}
{"type":"trade","received_at_ms":1788333160812,"data":{"e":"trade","E":1788333160973,"s":"BTCUSDT","t":6646665622,"p":"77720.87000000","q":"0.01509000","T":1788333160972,"m":false,"M":true}}
{"type":"trade","received_at_ms":1788333160812,"data":{"e":"trade","E":1788333160973,"s":"BTCUSDT","t":6646665623,"p":"77720.87000000","q":"0.00007000","T":1788333160972,"m":false,"M":true}}
{"type":"trade","received_at_ms":1788333160812,"data":{"e":"trade","E":1788333160973,"s":"BTCUSDT","t":6646665624,"p":"77720.87000000","q":"0.00007000","T":1788333160972,"m":false,"M":true}}
{"type":"trade","received_at_ms":1788333160812,"data":{"e":"trade","E":1788333160973,"s":"BTCUSDT","t":6646665625,"p":"77720.88000000","q":"0.00009000","T":1788333160972,"m":false,"M":true}}
{"type":"trade","received_at_ms":1788333160812,"data":{"e":"trade","E":1788333160973,"s":"BTCUSDT","t":6646665626,"p":"77720.88000000","q":"0.00009000","T":1788333160972,"m":false,"M":true}}
{"type":"trade","received_at_ms":1788333160812,"data":{"e":"trade","E":1788333160973,"s":"BTCUSDT","t":6646665627,"p":"77720.88000000","q":"0.00008000","T":1788333160972,"m":false,"M":true}}
{"type":"trade","received_at_ms":1788333160812,"data":{"e":"trade","E":1788333160973,"s":"BTCUSDT","t":6646665628,"p":"77720.88000000","q":"0.00011000","T":1788333160972,"m":false,"M":true}}
{"type":"trade","received_at_ms":1788333160812,"data":{"e":"trade","E":1788333160973,"s":"BTCUSDT","t":6646665629,"p":"77720.88000000","q":"0.00009000","T":1788333160972,"m":false,"M":true}}
{"type":"trade","received_at_ms":1788333160812,"data":{"e":"trade","E":1788333160973,"s":"BTCUSDT","t":6646665630,"p":"77721.18000000","q":"0.00010000","T":1788333160972,"m":false,"M":true}}
{"type":"trade","received_at_ms":1788333160812,"data":{"e":"trade","E":1788333160973,"s":"BTCUSDT","t":6646665631,"p":"77721.30000000","q":"0.00008000","T":1788333160972,"m":false,"M":true}}
{"type":"trade","received_at_ms":1788333160812,"data":{"e":"trade","E":1788333160973,"s":"BTCUSDT","t":6646665632,"p":"77721.50000000","q":"0.00007000","T":1788333160972,"m":false,"M":true}}
{"type":"trade","received_at_ms":1788333160812,"data":{"e":"trade","E":1788333160973,"s":"BTCUSDT","t":6646665633,"p":"77721.85000000","q":"0.00386000","T":1788333160972,"m":false,"M":true}}
{"type":"trade","received_at_ms":1788333160812,"data":{"e":"trade","E":1788333160973,"s":"BTCUSDT","t":6646665634,"p":"77721.88000000","q":"0.00120000","T":1788333160972,"m":false,"M":true}}
{"type":"trade","received_at_ms":1788333160812,"data":{"e":"trade","E":1788333160974,"s":"BTCUSDT","t":6646665635,"p":"77721.88000000","q":"0.00016000","T":1788333160973,"m":false,"M":true}}
{"type":"trade","received_at_ms":1788333160812,"data":{"e":"trade","E":1788333160974,"s":"BTCUSDT","t":6646665636,"p":"77721.99000000","q":"0.00007000","T":1788333160973,"m":false,"M":true}}
{"type":"trade","received_at_ms":1788333160812,"data":{"e":"trade","E":1788333160974,"s":"BTCUSDT","t":6646665637,"p":"77721.99000000","q":"0.00007000","T":1788333160973,"m":false,"M":true}}
{"type":"trade","received_at_ms":1788333160812,"data":{"e":"trade","E":1788333160974,"s":"BTCUSDT","t":6646665638,"p":"77721.99000000","q":"0.00007000","T":1788333160973,"m":false,"M":true}}
{"type":"trade","received_at_ms":1788333160814,"data":{"e":"trade","E":1788333160974,"s":"BTCUSDT","t":6646665639,"p":"77722.00000000","q":"0.01000000","T":1788333160973,"m":false,"M":true}}
{"type":"trade","received_at_ms":1788333160814,"data":{"e":"trade","E":1788333160974,"s":"BTCUSDT","t":6646665640,"p":"77722.00000000","q":"0.00500000","T":1788333160973,"m":false,"M":true}}
{"type":"trade","received_at_ms":1788333160814,"data":{"e":"trade","E":1788333160974,"s":"BTCUSDT","t":6646665641,"p":"77722.00000000","q":"0.00500000","T":1788333160973,"m":false,"M":true}}
{"type":"trade","received_at_ms":1788333160814,"data":{"e":"trade","E":1788333160974,"s":"BTCUSDT","t":6646665642,"p":"77722.00000000","q":"0.00063000","T":1788333160973,"m":false,"M":true}}
{"type":"trade","received_at_ms":1788333160814,"data":{"e":"trade","E":1788333160974,"s":"BTCUSDT","t":6646665643,"p":"77722.00000000","q":"0.00937000","T":1788333160974,"m":false,"M":true}}
{"type":"trade","received_at_ms":1788333160814,"data":{"e":"trade","E":1788333160974,"s":"BTCUSDT","t":6646665644,"p":"77722.00000000","q":"0.00007000","T":1788333160974,"m":false,"M":true}}
{"type":"trade","received_at_ms":1788333160814,"data":{"e":"trade","E":1788333160974,"s":"BTCUSDT","t":6646665645,"p":"77722.00000000","q":"0.00007000","T":1788333160974,"m":false,"M":true}}
{"type":"trade","received_at_ms":1788333160814,"data":{"e":"trade","E":1788333160974,"s":"BTCUSDT","t":6646665646,"p":"77722.15000000","q":"0.00537000","T":1788333160974,"m":false,"M":true}}
{"type":"trade","received_at_ms":1788333160814,"data":{"e":"trade","E":1788333160974,"s":"BTCUSDT","t":6646665647,"p":"77722.15000000","q":"0.00007000","T":1788333160974,"m":false,"M":true}}
{"type":"trade","received_at_ms":1788333160814,"data":{"e":"trade","E":1788333160974,"s":"BTCUSDT","t":6646665648,"p":"77722.15000000","q":"0.00007000","T":1788333160974,"m":false,"M":true}}
{"type":"trade","received_at_ms":1788333160814,"data":{"e":"trade","E":1788333160974,"s":"BTCUSDT","t":6646665649,"p":"77722.15000000","q":"0.00007000","T":1788333160974,"m":false,"M":true}}
{"type":"trade","received_at_ms":1788333160814,"data":{"e":"trade","E":1788333160974,"s":"BTCUSDT","t":6646665650,"p":"77722.15000000","q":"0.00007000","T":1788333160974,"m":false,"M":true}}
{"type":"trade","received_at_ms":1788333160814,"data":{"e":"trade","E":1788333160974,"s":"BTCUSDT","t":6646665651,"p":"77722.15000000","q":"0.00007000","T":1788333160974,"m":false,"M":true}}
{"type":"trade","received_at_ms":1788333160814,"data":{"e":"trade","E":1788333160974,"s":"BTCUSDT","t":6646665652,"p":"77722.16000000","q":"0.00007000","T":1788333160974,"m":false,"M":true}}
{"type":"trade","received_at_ms":1788333160814,"data":{"e":"trade","E":1788333160974,"s":"BTCUSDT","t":6646665653,"p":"77722.16000000","q":"0.00007000","T":1788333160974,"m":false,"M":true}}
{"type":"trade","received_at_ms":1788333160814,"data":{"e":"trade","E":1788333160974,"s":"BTCUSDT","t":6646665654,"p":"77722.99000000","q":"0.00011000","T":1788333160974,"m":false,"M":true}}
{"type":"trade","received_at_ms":1788333160814,"data":{"e":"trade","E":1788333160974,"s":"BTCUSDT","t":6646665655,"p":"77723.06000000","q":"0.00007000","T":1788333160974,"m":false,"M":true}}
{"type":"trade","received_at_ms":1788333160814,"data":{"e":"trade","E":1788333160974,"s":"BTCUSDT","t":6646665656,"p":"77723.07000000","q":"0.00007000","T":1788333160974,"m":false,"M":true}}
{"type":"trade","received_at_ms":1788333160815,"data":{"e":"trade","E":1788333160974,"s":"BTCUSDT","t":6646665657,"p":"77723.07000000","q":"0.00007000","T":1788333160974,"m":false,"M":true}}
{"type":"trade","received_at_ms":1788333160815,"data":{"e":"trade","E":1788333160974,"s":"BTCUSDT","t":6646665658,"p":"77723.40000000","q":"0.00531000","T":1788333160974,"m":false,"M":true}}
{"type":"trade","received_at_ms":1788333160815,"data":{"e":"trade","E":1788333160974,"s":"BTCUSDT","t":6646665659,"p":"77723.40000000","q":"0.00200000","T":1788333160974,"m":false,"M":true}}
{"type":"trade","received_at_ms":1788333160815,"data":{"e":"trade","E":1788333160975,"s":"BTCUSDT","t":6646665660,"p":"77723.40000000","q":"0.00165000","T":1788333160974,"m":false,"M":true}}
{"type":"trade","received_at_ms":1788333160815,"data":{"e":"trade","E":1788333160975,"s":"BTCUSDT","t":6646665661,"p":"77723.54000000","q":"0.00007000","T":1788333160974,"m":false,"M":true}}
{"type":"trade","received_at_ms":1788333160815,"data":{"e":"trade","E":1788333160975,"s":"BTCUSDT","t":6646665662,"p":"77723.54000000","q":"0.00007000","T":1788333160974,"m":false,"M":true}}
{"type":"trade","received_at_ms":1788333160815,"data":{"e":"trade","E":1788333160975,"s":"BTCUSDT","t":6646665663,"p":"77723.54000000","q":"0.00007000","T":1788333160974,"m":false,"M":true}}
{"type":"trade","received_at_ms":1788333160815,"data":{"e":"trade","E":1788333160975,"s":"BTCUSDT","t":6646665664,"p":"77723.76000000","q":"0.00008000","T":1788333160974,"m":false,"M":true}}
{"type":"trade","received_at_ms":1788333160815,"data":{"e":"trade","E":1788333160975,"s":"BTCUSDT","t":6646665665,"p":"77723.88000000","q":"0.00006000","T":1788333160974,"m":false,"M":true}}
{"type":"trade","received_at_ms":1788333160815,"data":{"e":"trade","E":1788333160975,"s":"BTCUSDT","t":6646665666,"p":"77723.88000000","q":"0.00200000","T":1788333160974,"m":false,"M":true}}
{"type":"trade","received_at_ms":1788333160815,"data":{"e":"trade","E":1788333160975,"s":"BTCUSDT","t":6646665667,"p":"77723.87000000","q":"0.00007000","T":1788333160975,"m":false,"M":true}}
{"type":"trade","received_at_ms":1788333160815,"data":{"e":"trade","E":1788333160975,"s":"BTCUSDT","t":6646665668,"p":"77723.87000000","q":"0.00007000","T":1788333160975,"m":false,"M":true}}
{"type":"trade","received_at_ms":1788333160815,"data":{"e":"trade","E":1788333160975,"s":"BTCUSDT","t":6646665669,"p":"77723.88000000","q":"0.00186000","T":1788333160975,"m":false,"M":true}}
{"type":"trade","received_at_ms":1788333160815,"data":{"e":"trade","E":1788333160975,"s":"BTCUSDT","t":6646665670,"p":"77723.91000000","q":"0.00007000","T":1788333160975,"m":false,"M":true}}
{"type":"trade","received_at_ms":1788333160816,"data":{"e":"trade","E":1788333160975,"s":"BTCUSDT","t":6646665671,"p":"77723.99000000","q":"0.00007000","T":1788333160975,"m":false,"M":true}}
{"type":"trade","received_at_ms":1788333160816,"data":{"e":"trade","E":1788333160975,"s":"BTCUSDT","t":6646665672,"p":"77724.00000000","q":"0.00186000","T":1788333160975,"m":false,"M":true}}
{"type":"trade","received_at_ms":1788333160816,"data":{"e":"trade","E":1788333160976,"s":"BTCUSDT","t":6646665673,"p":"77724.00000000","q":"0.00200000","T":1788333160975,"m":false,"M":true}}
{"type":"trade","received_at_ms":1788333160816,"data":{"e":"trade","E":1788333160976,"s":"BTCUSDT","t":6646665674,"p":"77724.00000000","q":"0.00200000","T":1788333160975,"m":false,"M":true}}
{"type":"trade","received_at_ms":1788333160816,"data":{"e":"trade","E":1788333160976,"s":"BTCUSDT","t":6646665675,"p":"77724.00000000","q":"0.00200000","T":1788333160975,"m":false,"M":true}}
{"type":"trade","received_at_ms":1788333160816,"data":{"e":"trade","E":1788333160976,"s":"BTCUSDT","t":6646665676,"p":"77724.00000000","q":"0.00200000","T":1788333160975,"m":false,"M":true}}
{"type":"trade","received_at_ms":1788333160816,"data":{"e":"trade","E":1788333160976,"s":"BTCUSDT","t":6646665677,"p":"77724.00000000","q":"0.00014000","T":1788333160975,"m":false,"M":true}}
{"type":"trade","received_at_ms":1788333160816,"data":{"e":"trade","E":1788333160976,"s":"BTCUSDT","t":6646665678,"p":"77724.00000000","q":"0.00186000","T":1788333160975,"m":false,"M":true}}
{"type":"trade","received_at_ms":1788333160816,"data":{"e":"trade","E":1788333160976,"s":"BTCUSDT","t":6646665679,"p":"77724.00000000","q":"0.00200000","T":1788333160975,"m":false,"M":true}}
{"type":"trade","received_at_ms":1788333160816,"data":{"e":"trade","E":1788333160976,"s":"BTCUSDT","t":6646665680,"p":"77724.00000000","q":"0.00114000","T":1788333160976,"m":false,"M":true}}
{"type":"trade","received_at_ms":1788333160816,"data":{"e":"trade","E":1788333160976,"s":"BTCUSDT","t":6646665681,"p":"77724.00000000","q":"0.00086000","T":1788333160976,"m":false,"M":true}}
{"type":"trade","received_at_ms":1788333160816,"data":{"e":"trade","E":1788333160976,"s":"BTCUSDT","t":6646665682,"p":"77724.00000000","q":"0.00200000","T":1788333160976,"m":false,"M":true}}
{"type":"trade","received_at_ms":1788333160816,"data":{"e":"trade","E":1788333160977,"s":"BTCUSDT","t":6646665683,"p":"77724.00000000","q":"0.00200000","T":1788333160977,"m":false,"M":true}}
{"type":"trade","received_at_ms":1788333160816,"data":{"e":"trade","E":1788333160978,"s":"BTCUSDT","t":6646665684,"p":"77724.00000000","q":"0.00014000","T":1788333160977,"m":false,"M":true}}
{"type":"trade","received_at_ms":1788333160816,"data":{"e":"trade","E":1788333160978,"s":"BTCUSDT","t":6646665685,"p":"77724.00000000","q":"0.00186000","T":1788333160977,"m":false,"M":true}}
{"type":"trade","received_at_ms":1788333160816,"data":{"e":"trade","E":1788333160978,"s":"BTCUSDT","t":6646665686,"p":"77724.00000000","q":"0.00200000","T":1788333160977,"m":false,"M":true}}
{"type":"depth","received_at_ms":1788333160852,"data":{"e":"depthUpdate","E":1788333161014,"s":"BTCUSDT","U":99556319148,"u":99556320475,"b":[["77723.99000000","3.13932000"],["77723.98000000","0.00027000"],["77723.97000000","0.00013000"],["77723.90000000","0.00000000"],["77723.89000000","0.00014000"],["77723.88000000","0.04084000"],["77723.87000000","0.00239000"],["77723.80000000","0.00000000"],["77723.75000000","0.00000000"],["77723.55000000","0.00014000"],["77723.54000000","0.32960000"],["77723.41000000","0.00014000"],["77723.40000000","0.07514000"],["77723.39000000","0.16508000"],["77723.10000000","0.00000000"],["77723.07000000","0.00000000"],["77723.06000000","0.00021000"],["77722.98000000","0.00000000"],["77722.47000000","0.00007000"],["77722.46000000","0.12958000"],["77722.15000000","0.00021000"],["77722.14000000","0.00021000"],["77722.00000000","0.00000000"],["77721.99000000","0.00207000"],["77721.98000000","0.00000000"],["77721.97000000","0.00000000"],["77721.87000000","0.00000000"],["77721.86000000","0.00000000"],["77721.32000000","0.01314000"],["77720.87000000","0.41422000"],["77720.86000000","0.00028000"],["77720.85000000","0.00007000"],["77720.77000000","0.00000000"],["77720.76000000","0.00000000"],["77720.72000000","0.00000000"],["77720.51000000","0.00000000"],["77720.44000000","0.00014000"],["77720.43000000","0.00014000"],["77720.30000000","0.00000000"],["77720.09000000","0.00000000"],["77719.99000000","0.30007000"],["77719.98000000","0.00007000"],["77719.36000000","0.08414000"],["77719.35000000","0.07500000"],["77719.34000000","0.97086000"],["77719.33000000","0.00000000"],["77719.32000000","0.00000000"],["77718.87000000","0.00000000"],["77718.81000000","0.00000000"],["77718.73000000","0.00000000"],["77718.72000000","0.12979000"],["77718.65000000","0.05000000"],["77718.20000000","0.00500000"],["77718.00000000","0.12500000"],["77717.99000000","0.59782000"],["77717.98000000","0.17972000"],["77717.97000000","0.01020000"],["77717.95000000","0.00007000"],["77717.92000000","0.00000000"],["77717.90000000","0.00007000"],["77717.83000000","0.00027000"],["77716.75000000","0.00000000"],["77716.73000000","0.01676000"],["77716.67000000","0.00000000"],["77715.84000000","0.00007000"],["77715.77000000","0.00008000"],["77715.54000000","0.00000000"],["77715.49000000","0.02019000"],["77715.31000000","0.00007000"],["77715.30000000","0.00400000"],["77714.98000000","0.02895000"],["77714.79000000","0.00060000"],["77714.77000000","0.92466000"],["77714.76000000","1.51847000"],["77714.75000000","0.64162000"],["77714.74000000","0.00007000"],["77714.73000000","0.00007000"],["77714.70000000","0.00000000"],["77714.26000000","0.00000000"],["77714.25000000","0.00000000"],["77714.24000000","0.02012000"],["77714.02000000","0.00125000"],["77714.01000000","0.00000000"],["77714.00000000","0.00000000"],["77713.96000000","0.00000000"],["77713.87000000","0.07759000"],["77713.86000000","0.00000000"],["77713.78000000","0.00000000"],["77713.52000000","0.00000000"],["77713.51000000","0.00000000"],["77713.09000000","0.00000000"],["77712.82000000","0.12867000"],["77712.81000000","0.00000000"],["77712.31000000","0.00000000"],["77712.16000000","0.00000000"],["77712.05000000","0.00007000"],["77711.63000000","0.00007000"],["77710.95000000","0.00000000"],["77710.47000000","0.00000000"],["77710.45000000","0.41262000"],["77710.44000000","1.31471000"],["77709.12000000","0.00008000"],["77708.98000000","0.00000000"],["77708.59000000","0.00000000"],["77708.49000000","0.00000000"],["77708.39000000","0.00027000"],["77707.40000000","0.00000000"],["77706.78000000","0.00000000"],["77706.45000000","0.02008000"],["77706.05000000","0.00000000"],["77705.41000000","0.00000000"],["77705.37000000","0.00007000"],["77705.22000000","0.10444000"],["77703.28000000","0.10444000"],["77703.20000000","0.00000000"],["77702.56000000","0.02008000"],["77702.44000000","0.00000000"],["77702.31000000","0.02000000"],["77702.30000000","0.00000000"],["77699.36000000","0.00008000"],["77699.15000000","0.00000000"],["77698.67000000","0.00008000"],["77698.55000000","0.00000000"],["77698.47000000","0.00257000"],["77698.05000000","0.00128000"],["77697.49000000","0.00000000"],["77695.54000000","0.00000000"],["77694.79000000","0.00008000"],["77694.66000000","0.00009000"],["77694.22000000","0.00000000"],["77690.90000000","0.00008000"],["77690.78000000","0.00000000"],["77690.57000000","0.00000000"],["77687.02000000","0.00008000"],["77686.89000000","0.00009000"],["77685.45000000","0.80232000"],["77684.98000000","0.00000000"],["77683.13000000","0.00008000"],["77683.01000000","0.00000000"],["77681.98000000","0.00000000"],["77681.04000000","0.00000000"],["77680.00000000","0.03014000"],["77679.12000000","0.02557000"],["77677.71000000","0.00000000"],["77677.11000000","0.00007000"],["77673.99000000","0.00000000"],["77670.99000000","0.39828000"],["77666.35000000","0.00000000"],["77659.02000000","0.80259000"],["77652.45000000","0.00319000"],["77644.27000000","0.00008000"],["77642.85000000","0.00000000"],["77640.03000000","0.00000000"],["77639.10000000","0.00007000"],["77636.27000000","0.00000000"],["77633.64000000","0.00000000"],["77632.03000000","0.00000000"],["77627.11000000","1.61249000"],["77566.55000000","0.00008000"],["77563.99000000","0.00000000"],["77558.55000000","0.00000000"],["77552.96000000","0.00025000"],["77541.97000000","0.00000000"],["77524.01000000","0.00811000"],["77522.01000000","0.00000000"],["77518.00000000","0.03011000"],["77515.00000000","0.00008000"],["77500.64000000","0.00381000"],["77488.76000000","0.00008000"],["77487.27000000","0.00008000"],["77486.71000000","0.00041000"],["77485.78000000","0.00007000"],["77480.00000000","0.00099000"],["77478.85000000","0.00000000"],["77474.85000000","0.00046000"],["77473.67000000","0.00011000"],["77411.10000000","0.00008000"],["77403.12000000","0.00000000"],["77389.33000000","1.78998000"],["77355.40000000","0.00000000"],["77331.83000000","0.00008000"],["77323.43000000","0.00000000"],["77321.83000000","0.00000000"],["77255.66000000","0.00008000"],["77247.70000000","0.00000000"],["77226.76000000","0.00000000"],["77177.94000000","0.00008000"],["77169.98000000","0.00000000"],["77100.21000000","0.00008000"],["77092.27000000","0.00000000"],["76960.00000000","0.00313000"],["69951.60000000","0.00016000"],["69946.20000000","0.00000000"],["69946.00000000","0.00000000"],["62179.20000000","0.00032000"]],"a":[["77718.00000000","0.00000000"],["77718.01000000","0.00000000"],["77718.73000000","0.00000000"],["77718.88000000","0.00000000"],["77719.35000000","0.00000000"],["77719.36000000","0.00000000"],["77719.99000000","0.00000000"],["77720.00000000","0.00000000"],["77720.31000000","0.00000000"],["77720.36000000","0.00000000"],["77720.44000000","0.00000000"],["77720.52000000","0.00000000"],["77720.73000000","0.00000000"],["77720.77000000","0.00000000"],["77720.78000000","0.00000000"],["77720.86000000","0.00000000"],["77720.87000000","0.00000000"],["77720.88000000","0.00000000"],["77721.18000000","0.00000000"],["77721.30000000","0.00000000"],["77721.50000000","0.00000000"],["77721.85000000","0.00000000"],["77721.88000000","0.00000000"],["77721.99000000","0.00000000"],["77722.00000000","0.00000000"],["77722.15000000","0.00000000"],["77722.16000000","0.00000000"],["77722.99000000","0.00000000"],["77723.06000000","0.00000000"],["77723.07000000","0.00000000"],["77723.11000000","0.00000000"],["77723.40000000","0.00000000"],["77723.54000000","0.00000000"],["77723.55000000","0.00000000"],["77723.76000000","0.00000000"],["77723.81000000","0.00000000"],["77723.87000000","0.00000000"],["77723.88000000","0.00000000"],["77723.91000000","0.00000000"],["77723.99000000","0.00000000"],["77724.00000000","0.72463000"],["77724.01000000","0.00063000"],["77724.38000000","0.00007000"],["77724.53000000","0.00000000"],["77724.63000000","0.00014000"],["77724.64000000","0.01089000"],["77724.75000000","0.00000000"],["77724.76000000","0.00014000"],["77724.77000000","0.00014000"],["77724.79000000","0.00014000"],["77724.80000000","0.00014000"],["77725.34000000","0.00000000"],["77725.88000000","0.00014000"],["77725.99000000","0.00014000"],["77726.16000000","0.00000000"],["77726.17000000","0.12174000"],["77726.22000000","0.00000000"],["77726.25000000","0.00000000"],["77726.27000000","0.00000000"],["77726.33000000","0.00000000"],["77726.34000000","0.00000000"],["77726.42000000","0.00018000"],["77726.50000000","0.00000000"],["77726.76000000","0.01267000"],["77726.79000000","0.00000000"],["77726.80000000","0.00000000"],["77726.98000000","0.00128000"],["77727.19000000","0.00000000"],["77727.30000000","0.00321000"],["77727.43000000","0.00000000"],["77727.97000000","0.00007000"],["77728.45000000","0.00000000"],["77728.76000000","0.54988000"],["77728.77000000","0.00000000"],["77728.83000000","0.00000000"],["77728.91000000","0.00000000"],["77729.50000000","0.00000000"],["77729.61000000","0.00000000"],["77729.65000000","0.00000000"],["77729.70000000","0.00000000"],["77730.16000000","0.00000000"],["77730.22000000","0.02894000"],["77730.46000000","0.00000000"],["77730.73000000","0.03210000"],["77731.07000000","0.00643000"],["77731.36000000","0.15010000"],["77731.77000000","0.00008000"],["77731.78000000","0.16870000"],["77731.94000000","0.12864000"],["77732.30000000","0.00000000"],["77733.61000000","0.00000000"],["77734.67000000","0.00007000"],["77736.19000000","0.00000000"],["77736.47000000","0.00007000"],["77736.62000000","0.00400000"],["77736.65000000","0.00000000"],["77737.42000000","0.00008000"],["77737.78000000","0.00007000"],["77739.47000000","0.00000000"],["77740.06000000","0.10439000"],["77740.08000000","0.00000000"],["77741.31000000","0.00008000"],["77742.01000000","0.10439000"],["77742.03000000","0.00000000"],["77743.96000000","0.00000000"],["77743.98000000","0.42009000"],["77745.20000000","0.00008000"],["77745.61000000","0.12862000"],["77746.23000000","0.64563000"],["77747.32000000","0.00128000"],["77747.85000000","0.00000000"],["77748.10000000","0.00515000"],["77748.11000000","0.00000000"],["77748.46000000","0.00000000"],["77748.69000000","0.00000000"],["77749.08000000","0.00008000"],["77750.17000000","0.00000000"],["77750.44000000","0.00000000"],["77751.57000000","0.00000000"],["77751.90000000","0.00000000"],["77752.06000000","0.00000000"],["77752.34000000","0.00000000"],["77752.96000000","0.00000000"],["77752.97000000","0.00008000"],["77753.60000000","0.05283000"],["77754.79000000","0.00000000"],["77755.62000000","0.00000000"],["77756.85000000","0.00008000"],["77757.00000000","0.00000000"],["77758.00000000","0.03000000"],["77759.84000000","0.00014000"],["77760.00000000","0.05900000"],["77760.44000000","1.07666000"],["77760.74000000","0.00008000"],["77761.32000000","0.00000000"],["77763.00000000","0.01000000"],["77768.25000000","0.51903000"],["77769.47000000","0.00000000"],["77770.52000000","0.00000000"],["77770.96000000","1.09247000"],["77772.37000000","0.00000000"],["77772.56000000","0.00008000"],["77774.99000000","0.00000000"],["77777.99000000","0.00000000"],["77780.91000000","0.00321000"],["77781.31000000","0.00321000"],["77789.71000000","0.00000000"],["77792.76000000","0.43213000"],["77797.72000000","0.00008000"],["77804.30000000","0.00000000"],["77852.69000000","0.00000000"],["77852.70000000","0.00000000"],["77863.05000000","0.00256000"],["77869.42000000","0.00000000"],["77877.32000000","0.00008000"],["77947.14000000","0.00000000"],["77955.05000000","0.00008000"],["78000.00000000","17.77563000"],["78024.86000000","0.00000000"],["78032.77000000","0.00008000"],["78102.56000000","0.00000000"],["78110.49000000","0.00008000"],["78110.62000000","0.00007000"],["78180.27000000","0.00000000"],["78188.21000000","0.00008000"],["78255.98000000","0.00000000"],["78264.04000000","0.00008000"],["78335.70000000","0.00000000"],["78343.66000000","0.00008000"]]}}
{"type":"depth","received_at_ms":1788333160950,"data":{"e":"depthUpdate","E":1788333161114,"s":"BTCUSDT","U":99556320476,"u":99556320704,"b":[["77723.99000000","2.81897000"],["77723.96000000","0.00014000"],["77723.95000000","0.05007000"],["77723.91000000","0.00014000"],["77723.90000000","0.05000000"],["77723.88000000","0.04098000"],["77723.87000000","0.00225000"],["77723.54000000","0.02960000"],["77723.40000000","0.07514000"],["77723.39000000","0.16508000"],["77723.06000000","0.00007000"],["77722.47000000","0.00000000"],["77722.46000000","0.12972000"],["77722.15000000","0.00007000"],["77722.14000000","0.00007000"],["77722.11000000","0.00000000"],["77721.99000000","0.00193000"],["77721.32000000","0.01585000"],["77720.87000000","0.41436000"],["77720.86000000","0.00007000"],["77720.85000000","0.00000000"],["77719.99000000","0.30028000"],["77719.36000000","0.04891000"],["77719.20000000","0.00400000"],["77718.72000000","0.12972000"],["77718.65000000","0.00000000"],["77718.00000000","0.07500000"],["77717.99000000","0.56595000"],["77717.98000000","0.17927000"],["77717.97000000","0.00000000"],["77717.95000000","0.00000000"],["77717.90000000","0.00000000"],["77716.76000000","0.00000000"],["77716.73000000","0.00000000"],["77716.21000000","0.00009000"],["77715.84000000","0.00000000"],["77715.49000000","0.00000000"],["77715.31000000","0.00000000"],["77714.77000000","0.92266000"],["77714.29000000","0.00007000"],["77714.24000000","0.00000000"],["77710.47000000","0.00200000"],["77710.41000000","0.00007000"],["77710.20000000","0.16870000"],["77708.44000000","0.00009000"],["77704.66000000","0.00411000"],["77702.43000000","0.00000000"],["77700.67000000","0.00009000"],["77694.66000000","0.00000000"],["77692.90000000","0.00009000"],["77688.00000000","0.03000000"],["77686.89000000","0.00000000"],["77685.00000000","0.01000000"],["77684.98000000","0.00007000"],["77683.12000000","0.02522000"],["77680.00000000","0.03014000"],["77679.12000000","0.00000000"],["77679.00000000","0.00000000"],["77675.58000000","0.25000000"],["77582.20000000","1.54224000"],["77507.89000000","0.00000000"],["77505.59000000","0.00000000"],["69951.60000000","0.00032000"]],"a":[["77724.00000000","0.72609000"],["77724.01000000","0.00070000"],["77724.38000000","0.00014000"],["77724.63000000","0.00000000"],["77724.64000000","0.00014000"],["77724.76000000","0.00000000"],["77724.77000000","0.00000000"],["77724.78000000","0.00000000"],["77724.79000000","0.00000000"],["77724.80000000","0.00000000"],["77725.05000000","0.00000000"],["77725.37000000","0.10098000"],["77725.41000000","0.00000000"],["77725.88000000","0.00000000"],["77725.89000000","0.00014000"],["77726.00000000","0.03014000"],["77726.14000000","0.00014000"],["77726.15000000","0.18806000"],["77726.16000000","0.11144000"],["77726.17000000","0.00028000"],["77726.18000000","0.32193000"],["77726.76000000","0.01281000"],["77727.96000000","0.00007000"],["77727.97000000","0.11144000"],["77727.98000000","0.02814000"],["77727.99000000","0.00000000"],["77728.00000000","0.03021000"],["77728.24000000","0.09887000"],["77728.73000000","0.11144000"],["77728.74000000","0.94329000"],["77728.75000000","1.93226000"],["77728.76000000","0.00000000"],["77734.40000000","0.00054000"],["77736.62000000","0.01200000"],["77736.86000000","0.00257000"],["77737.65000000","0.00000000"],["77758.51000000","0.00000000"],["77760.15000000","0.00400000"],["77760.40000000","0.32949000"],["77761.45000000","0.03861000"],["77779.77000000","0.25000000"],["77877.56000000","1.54224000"],["77947.10000000","0.00007000"],["77950.98000000","0.00000000"]]}}
{"type":"depth","received_at_ms":1788333161048,"data":{"e":"depthUpdate","E":1788333161214,"s":"BTCUSDT","U":99556320705,"u":99556320824,"b":[["77723.99000000","2.86112000"],["77723.98000000","0.00083000"],["77723.95000000","0.05021000"],["77723.41000000","0.00000000"],["77723.40000000","0.00021000"],["77723.39000000","0.16515000"],["77722.74000000","0.01772000"],["77722.46000000","0.12979000"],["77721.50000000","0.02126000"],["77720.87000000","0.04091000"],["77720.25000000","0.02126000"],["77719.99000000","0.30014000"],["77717.99000000","0.39725000"],["77717.98000000","0.17920000"],["77714.79000000","0.00000000"],["77710.47000000","0.00000000"],["77631.01000000","0.00093000"],["77564.45000000","0.16870000"],["77018.52000000","0.00000000"],["69951.60000000","0.00048000"],["62179.20000000","0.00000000"]],"a":[["77724.00000000","0.85750000"],["77724.01000000","0.00077000"],["77724.64000000","0.00000000"],["77725.36000000","0.00014000"],["77725.37000000","0.10112000"],["77725.85000000","0.00014000"],["77725.86000000","0.14481000"],["77725.89000000","0.00000000"],["77726.00000000","0.03014000"],["77726.15000000","0.18820000"],["77726.16000000","0.11158000"],["77726.17000000","0.00000000"],["77726.76000000","0.01281000"],["77727.96000000","0.00000000"],["77727.97000000","0.11158000"],["77728.00000000","0.03007000"],["77728.72000000","0.01400000"],["77729.03000000","0.00480000"],["77730.28000000","0.00800000"],["77731.42000000","0.00144000"],["77731.52000000","0.00960000"],["77732.77000000","0.00960000"],["77736.62000000","0.00000000"],["77775.97000000","0.00027000"],["77911.57000000","0.00055000"],["77944.76000000","0.01539000"]]}}
{"type":"depth","received_at_ms":1788333161148,"data":{"e":"depthUpdate","E":1788333161314,"s":"BTCUSDT","U":99556320825,"u":99556320890,"b":[["77723.99000000","2.86105000"],["77723.98000000","0.00083000"],["77723.90000000","0.05014000"],["77723.54000000","0.02960000"],["77723.40000000","0.00007000"],["77723.39000000","0.16515000"],["77722.74000000","0.01786000"],["77722.56000000","0.00007000"],["77722.46000000","0.12979000"],["77721.32000000","0.01571000"],["77719.36000000","0.52196000"],["77719.34000000","0.77086000"],["77717.16000000","0.00000000"],["77716.38000000","0.00000000"],["77714.79000000","0.00200000"],["77714.00000000","0.00008000"],["77710.47000000","0.00000000"],["77665.20000000","0.00000000"],["77524.01000000","0.00000000"],["77522.01000000","0.00811000"],["69951.60000000","0.00080000"]],"a":[["77724.00000000","0.86377000"],["77724.01000000","0.00084000"],["77725.37000000","0.10112000"],["77725.86000000","0.14495000"],["77727.98000000","0.02800000"],["77728.72000000","0.00200000"],["77728.73000000","0.00000000"],["77736.62000000","0.01200000"],["77760.86000000","0.02506000"],["77790.43000000","3.23948000"],["78307.39000000","0.00406000"]]}}
{"type":"trade","received_at_ms":1788333161197,"data":{"e":"trade","E":1788333161361,"s":"BTCUSDT","t":6646665687,"p":"77723.99000000","q":"0.02000000","T":1788333161361,"m":true,"M":true}}
{"type":"depth","received_at_ms":1788333161248,"data":{"e":"depthUpdate","E":1788333161414,"s":"BTCUSDT","U":99556320891,"u":99556320903,"b":[["77723.99000000","2.84105000"],["77721.50000000","0.02140000"],["77714.79000000","0.00000000"],["77710.47000000","0.00200000"],["77705.18000000","0.00007000"],["77693.59000000","0.00000000"],["69946.18000000","0.00000000"]],"a":[["77724.00000000","0.86363000"],["77749.05000000","0.01344000"],["77761.94000000","0.12872000"],["77775.97000000","0.00093000"]]}}
{"type":"depth","received_at_ms":1788333161347,"data":{"e":"depthUpdate","E":1788333161514,"s":"BTCUSDT","U":99556320904,"u":99556320929,"b":[["77721.32000000","0.01314000"],["77720.06000000","0.00257000"],["77717.99000000","0.40051000"],["77705.62000000","0.00000000"],["77643.03000000","1.61359000"],["77624.90000000","0.00000000"],["77600.01000000","0.00012000"],["77587.87000000","0.00000000"],["77146.19000000","0.00000000"],["69951.60000000","0.00112000"],["62179.20000000","0.00032000"],["62179.19000000","0.00000000"]],"a":[["77726.16000000","0.11366000"],["77728.24000000","0.00000000"],["77735.60000000","0.00257000"],["77736.86000000","0.00000000"],["77749.95000000","0.02048000"],["77751.91000000","0.09671000"],["77761.94000000","0.00000000"],["77815.83000000","0.00411000"],["77832.39000000","0.00000000"],["77834.75000000","0.00007000"],["77839.49000000","0.00000000"]]}}
{"type":"depth","received_at_ms":1788333161447,"data":{"e":"depthUpdate","E":1788333161614,"s":"BTCUSDT","U":99556320930,"u":99556320955,"b":[["77723.99000000","2.86105000"],["77720.25000000","0.02133000"],["77717.98000000","0.15920000"],["77687.72000000","0.02000000"],["77687.64000000","0.02000000"],["77686.94000000","0.02000000"],["77686.86000000","0.02000000"],["77683.84000000","0.02000000"],["77683.04000000","0.02000000"],["77610.81000000","0.00386000"],["77593.63000000","0.00076000"],["77457.56000000","0.00000000"],["76558.13000000","0.00030000"],["69951.60000000","0.00128000"],["62179.20000000","0.00000000"],["62179.00000000","0.00000000"]],"a":[["77726.42000000","0.00011000"],["77838.41000000","0.00012000"],["78889.86000000","0.00030000"]]}}
{"type":"depth","received_at_ms":1788333161548,"data":{"e":"depthUpdate","E":1788333161714,"s":"BTCUSDT","U":99556320956,"u":99556320975,"b":[["77723.99000000","2.86113000"],["77717.99000000","0.39017000"],["77686.93000000","0.02000000"],["77686.85000000","0.02000000"],["77684.61000000","0.02000000"],["77683.83000000","0.02000000"],["77683.05000000","0.02000000"],["77682.90000000","0.02000000"],["77642.06000000","0.00000000"],["77640.01000000","0.00000000"],["69951.60000000","0.00144000"],["69951.00000000","0.00068000"]],"a":[["77724.00000000","0.87036000"],["77751.91000000","0.00000000"],["77753.65000000","0.09506000"],["77840.76000000","0.00019000"],["77845.51000000","0.00032000"]]}}
{"type":"depth","received_at_ms":1788333161648,"data":{"e":"depthUpdate","E":1788333161815,"s":"BTCUSDT","U":99556320976,"u":99556321000,"b":[["77723.99000000","2.86189000"],["77721.79000000","0.00007000"],["77721.09000000","0.00257000"],["77720.06000000","0.00000000"],["77717.99000000","0.38948000"],["77683.42000000","0.00000000"],["77683.36000000","0.02000000"],["77676.29000000","0.09766000"],["77625.14000000","0.00000000"],["77554.83000000","0.00076000"],["69951.60000000","0.00144000"]],"a":[["77724.00000000","0.73303000"],["77725.04000000","0.00000000"],["77725.05000000","0.00000000"],["77726.15000000","0.18813000"],["77735.60000000","0.00000000"],["77736.62000000","0.01457000"]]}}
{"type":"trade","received_at_ms":1788333161744,"data":{"e":"trade","E":1788333161911,"s":"BTCUSDT","t":6646665688,"p":"77723.99000000","q":"0.00397000","T":1788333161910,"m":true,"M":true}}
{"type":"depth","received_at_ms":1788333161747,"data":{"e":"depthUpdate","E":1788333161914,"s":"BTCUSDT","U":99556321001,"u":99556321030,"b":[["77723.99000000","2.85792000"],["77704.00000000","0.70265000"],["77703.00000000","0.00000000"],["77702.00000000","0.00500000"],["77665.80000000","0.00411000"],["77639.31000000","0.00000000"],["77629.80000000","0.00000000"],["77623.69000000","0.02000000"],["69951.60000000","0.00160000"],["69951.59000000","0.00009000"],["62179.19000000","0.00000000"]],"a":[["77724.00000000","1.00134000"],["77728.73000000","0.01200000"],["77734.14000000","0.00007000"],["77736.62000000","0.00257000"],["85000.00000000","161.03634000"]]}}
{"type":"trade","received_at_ms":1788333161825,"data":{"e":"trade","E":1788333161990,"s":"BTCUSDT","t":6646665689,"p":"77723.99000000","q":"0.00739000","T":1788333161989,"m":true,"M":true}}
{"type":"depth","received_at_ms":1788333161849,"data":{"e":"depthUpdate","E":1788333162014,"s":"BTCUSDT","U":99556321031,"u":99556321093,"b":[["77723.99000000","2.85653000"],["77723.90000000","0.05028000"],["77723.89000000","0.13925000"],["77723.88000000","0.00014000"],["77717.53000000","0.00007000"],["77705.37000000","0.00000000"],["77700.00000000","0.00507000"],["77698.71000000","0.12870000"],["77698.00000000","0.00500000"],["77696.00000000","0.00507000"],["77685.06000000","0.77486000"],["77684.53000000","0.00000000"],["77639.25000000","0.00000000"],["77625.91000000","0.00000000"],["77530.00000000","0.03050000"],["69951.60000000","0.00144000"],["62179.20000000","0.00032000"]],"a":[["77724.00000000","1.13012000"],["77724.01000000","0.00097000"],["77724.02000000","0.00013000"],["77724.80000000","0.00014000"],["77724.81000000","0.12101000"],["77725.85000000","0.00000000"],["77725.86000000","0.00014000"],["77728.73000000","0.00000000"],["77736.47000000","0.00000000"],["77736.62000000","0.01457000"],["77749.99000000","0.63015000"],["77761.37000000","0.00000000"],["77762.16000000","0.00007000"],["77762.41000000","0.00000000"],["77790.42000000","1.41970000"],["77792.76000000","0.00000000"],["77808.83000000","0.00007000"]]}}
{"type":"depth","received_at_ms":1788333161948,"data":{"e":"depthUpdate","E":1788333162114,"s":"BTCUSDT","U":99556321094,"u":99556321144,"b":[["77723.99000000","2.85646000"],["77723.98000000","0.00083000"],["77723.90000000","0.05035000"],["77723.89000000","0.13939000"],["77723.88000000","0.00000000"],["77705.37000000","0.00007000"],["77704.66000000","0.00000000"],["77665.80000000","0.00000000"],["77643.59000000","0.00000000"],["77634.72000000","0.00000000"],["77629.03000000","0.00000000"],["69951.60000000","0.00176000"]],"a":[["77724.00000000","1.00747000"],["77724.80000000","0.00000000"],["77724.81000000","0.00014000"],["77725.37000000","0.10112000"],["77725.86000000","0.00000000"],["77726.15000000","0.18820000"],["77736.47000000","0.00007000"],["77736.62000000","0.00657000"],["77745.85000000","0.00000000"],["77784.71000000","0.00007000"],["77814.35000000","0.00000000"],["77815.83000000","0.00000000"],["77820.37000000","0.00025000"],["77842.33000000","0.00083000"],["78874.04000000","0.00025000"]]}}
{"type":"depth","received_at_ms":1788333162047,"data":{"e":"depthUpdate","E":1788333162214,"s":"BTCUSDT","U":99556321145,"u":99556321205,"b":[["77723.99000000","2.85639000"],["77722.04000000","0.00257000"],["77721.09000000","0.00000000"],["77718.17000000","0.00013000"],["77704.00000000","0.00265000"],["77702.00000000","0.01500000"],["77700.00000000","0.01507000"],["77698.00000000","0.01500000"],["77642.83000000","0.00000000"],["77642.36000000","0.00000000"],["77639.41000000","0.00000000"],["77434.50000000","0.00000000"],["77355.08000000","0.00000000"],["77275.66000000","0.00000000"],["77024.47000000","0.00010000"],["69951.60000000","0.00192000"],["62179.20000000","0.00000000"]],"a":[["77724.00000000","1.12800000"],["77724.01000000","0.00083000"],["77724.81000000","0.00000000"],["77725.36000000","0.00000000"],["77725.37000000","0.00014000"],["77726.15000000","0.18806000"],["77726.16000000","0.00222000"],["77726.17000000","0.00014000"],["77727.96000000","0.00014000"],["77727.98000000","0.02814000"],["77727.99000000","0.00007000"],["77728.37000000","0.09887000"],["77728.73000000","0.00000000"],["77729.82000000","0.00013000"],["77736.55000000","0.00400000"],["77736.62000000","0.00000000"],["77737.58000000","0.00257000"],["77749.95000000","0.00000000"],["77750.60000000","0.02006000"],["77753.60000000","0.00000000"],["77754.25000000","0.05447000"],["77849.97000000","0.00000000"],["77872.09000000","0.00000000"]]}}
{"type":"depth","received_at_ms":1788333162148,"data":{"e":"depthUpdate","E":1788333162314,"s":"BTCUSDT","U":99556321206,"u":99556321241,"b":[["77723.99000000","2.85646000"],["77723.89000000","0.09764000"],["77723.39000000","0.06628000"],["77696.00000000","0.01507000"],["69951.60000000","0.00176000"],["62179.00000000","0.00000000"],["62174.00000000","0.00000000"]],"a":[["77724.00000000","1.12800000"],["77724.01000000","0.00076000"],["77725.37000000","0.00000000"],["77726.15000000","0.18806000"],["77726.16000000","0.00000000"],["77728.00000000","0.03021000"],["77728.37000000","0.00014000"],["77749.72000000","0.00411000"],["77891.19000000","0.00000000"],["77919.87000000","0.02016000"]]}}
{"type":"depth","received_at_ms":1788333162249,"data":{"e":"depthUpdate","E":1788333162415,"s":"BTCUSDT","U":99556321242,"u":99556321262,"b":[["77702.00000000","0.01886000"],["77524.01000000","0.00811000"],["77522.01000000","0.00000000"],["69951.60000000","0.00208000"],["62179.00000000","0.00000000"]],"a":[["77724.00000000","1.12947000"],["77728.00000000","0.03021000"],["77728.37000000","0.00000000"],["77728.74000000","0.94343000"],["77881.25000000","0.00083000"]]}}
{"type":"depth","received_at_ms":1788333162351,"data":{"e":"depthUpdate","E":1788333162514,"s":"BTCUSDT","U":99556321263,"u":99556321284,"b":[["77723.99000000","2.85648000"],["77716.21000000","0.00011000"],["77708.44000000","0.00011000"],["77700.67000000","0.00011000"],["77700.00000000","0.02507000"],["77698.00000000","0.02500000"],["77696.00000000","0.02507000"],["77692.90000000","0.00011000"],["69951.60000000","0.00208000"],["62179.20000000","0.00032000"],["62179.19000000","0.00000000"]],"a":[["77725.27000000","0.00014000"],["77725.28000000","0.14491000"],["77727.99000000","0.00000000"]]}}
{"type":"depth","received_at_ms":1788333162448,"data":{"e":"depthUpdate","E":1788333162614,"s":"BTCUSDT","U":99556321285,"u":99556321308,"b":[["76558.13000000","0.00030000"],["69951.60000000","0.00224000"],["62179.20000000","0.00000000"],["62174.00000000","0.00000000"]],"a":[["77724.00000000","1.12954000"],["77724.01000000","0.00083000"],["77725.28000000","0.14505000"],["77728.74000000","0.94329000"],["77761.84000000","0.00000000"],["77762.50000000","0.00000000"],["78889.86000000","0.00030000"]]}}
{"type":"depth","received_at_ms":1788333162549,"data":{"e":"depthUpdate","E":1788333162715,"s":"BTCUSDT","U":99556321309,"u":99556321314,"b":[["77708.81000000","0.09452000"],["77638.59000000","0.00411000"]],"a":[["77724.44000000","0.12927000"],["77725.28000000","0.00014000"],["77761.97000000","0.00000000"]]}}
{"type":"depth","received_at_ms":1788333162648,"data":{"e":"depthUpdate","E":1788333162814,"s":"BTCUSDT","U":99556321315,"u":99556321335,"b":[["77703.00000000","0.70000000"],["77434.50000000","2.50000000"],["69951.60000000","0.00240000"]],"a":[["77724.00000000","1.12954000"],["77724.01000000","0.00083000"],["77724.43000000","0.00014000"],["77724.44000000","0.12941000"],["77725.27000000","0.00000000"],["77725.28000000","0.00000000"]]}}
{"type":"depth","received_at_ms":1788333162748,"data":{"e":"depthUpdate","E":1788333162914,"s":"BTCUSDT","U":99556321336,"u":99556321342,"b":[["77723.99000000","2.85974000"],["69951.60000000","0.00240000"],["62179.19000000","0.00000000"]],"a":[["77724.00000000","1.26218000"]]}}
{"type":"trade","received_at_ms":1788333162822,"data":{"e":"trade","E":1788333162989,"s":"BTCUSDT","t":6646665690,"p":"77723.99000000","q":"0.00011000","T":1788333162988,"m":true,"M":true}}
{"type":"depth","received_at_ms":1788333162848,"data":{"e":"depthUpdate","E":1788333163014,"s":"BTCUSDT","U":99556321343,"u":99556321366,"b":[["77723.99000000","2.94160000"],["77714.79000000","0.00000000"],["77710.47000000","0.00000000"],["77646.05000000","1.16956000"],["69951.60000000","0.00256000"],["69951.59000000","0.00000000"],["69951.58000000","0.00009000"],["69951.00000000","0.00068000"],["62179.20000000","0.00032000"],["62179.00000000","0.00000000"]],"a":[["77724.00000000","1.25688000"],["77728.36000000","0.08411000"],["77807.10000000","0.00007000"],["78014.43000000","0.00007000"]]}}
{"type":"depth","received_at_ms":1788333162948,"data":{"e":"depthUpdate","E":1788333163114,"s":"BTCUSDT","U":99556321367,"u":99556321380,"b":[["77723.99000000","2.94168000"],["77710.47000000","0.00200000"],["77705.37000000","0.00007000"],["69951.60000000","0.00256000"]],"a":[["77724.00000000","1.12954000"],["77728.00000000","0.03021000"],["77736.47000000","0.00007000"],["77762.26000000","0.12872000"],["77819.70000000","0.00411000"]]}}
{"type":"depth","received_at_ms":1788333163048,"data":{"e":"depthUpdate","E":1788333163214,"s":"BTCUSDT","U":99556321381,"u":99556321396,"b":[["77719.37000000","0.00643000"],["77718.73000000","0.00643000"],["77717.99000000","0.38305000"],["77717.98000000","0.15277000"],["77652.46000000","0.00321000"],["77648.21000000","1.61347000"],["77646.06000000","0.00000000"],["77646.05000000","0.82294000"],["77643.03000000","0.00000000"],["77575.46000000","0.00128000"],["77574.01000000","0.00128000"],["77568.01000000","0.00000000"],["77564.02000000","0.00000000"],["69951.60000000","0.00272000"],["62179.20000000","0.00000000"]],"a":[["77730.72000000","0.00643000"],["77731.07000000","0.00000000"],["77731.91000000","0.00000000"],["77733.32000000","0.00643000"],["77762.26000000","0.00000000"],["77781.31000000","0.00000000"],["77783.34000000","0.00321000"]]}}
{"type":"depth","received_at_ms":1788333163147,"data":{"e":"depthUpdate","E":1788333163314,"s":"BTCUSDT","U":99556321397,"u":99556321404,"b":[["77719.99000000","0.30021000"],["77719.34000000","0.77093000"],["77708.53000000","0.00411000"],["77702.00000000","0.02386000"],["77700.00000000","0.03007000"],["77698.00000000","0.03000000"],["77696.00000000","0.03007000"],["77355.08000000","2.50000000"]],"a":[]}}
{"type":"depth","received_at_ms":1788333163248,"data":{"e":"depthUpdate","E":1788333163414,"s":"BTCUSDT","U":99556321405,"u":99556321407,"b":[["69951.60000000","0.00288000"]],"a":[]}}
{"type":"depth","received_at_ms":1788333163348,"data":{"e":"depthUpdate","E":1788333163514,"s":"BTCUSDT","U":99556321408,"u":99556321414,"b":[["69951.60000000","0.00288000"],["62179.20000000","0.00032000"],["62179.19000000","0.00000000"],["62179.00000000","0.00000000"]],"a":[]}}
{"type":"depth","received_at_ms":1788333163447,"data":{"e":"depthUpdate","E":1788333163614,"s":"BTCUSDT","U":99556321415,"u":99556321420,"b":[["76558.13000000","0.00030000"],["75557.14000000","0.00000000"],["69951.60000000","0.00304000"],["62179.20000000","0.00000000"]],"a":[["78889.86000000","0.00000000"],["81001.14000000","0.00000000"]]}}
{"type":"depth","received_at_ms":1788333163548,"data":{"e":"depthUpdate","E":1788333163714,"s":"BTCUSDT","U":99556321421,"u":99556321427,"b":[["69951.60000000","0.00320000"]],"a":[["77724.00000000","1.15013000"],["78889.86000000","0.00030000"]]}}
{"type":"depth","received_at_ms":1788333163648,"data":{"e":"depthUpdate","E":1788333163814,"s":"BTCUSDT","U":99556321428,"u":99556321439,"b":[["77722.04000000","0.00000000"],["77721.18000000","0.00257000"],["77275.66000000","2.50000000"],["69951.60000000","0.00320000"]],"a":[["77724.00000000","1.27089000"],["77736.71000000","0.00257000"],["77737.58000000","0.00000000"],["77762.36000000","0.00000000"]]}}
{"type":"depth","received_at_ms":1788333163747,"data":{"e":"depthUpdate","E":1788333163914,"s":"BTCUSDT","U":99556321440,"u":99556321456,"b":[["77723.99000000","2.94175000"],["77708.41000000","0.97676000"],["77708.39000000","0.00177000"],["77708.00000000","0.70000000"],["77703.00000000","0.00000000"],["77693.06000000","0.04631000"],["77677.41000000","0.00000000"],["77669.67000000","0.00411000"],["69951.60000000","0.00320000"],["62179.19000000","0.00020000"]],"a":[["77761.76000000","0.00000000"],["77761.83000000","0.00000000"],["77762.03000000","0.00000000"]]}}
{"type":"trade","received_at_ms":1788333163831,"data":{"e":"trade","E":1788333163997,"s":"BTCUSDT","t":6646665691,"p":"77723.99000000","q":"0.00140000","T":1788333163996,"m":true,"M":true}}
{"type":"depth","received_at_ms":1788333163848,"data":{"e":"depthUpdate","E":1788333164014,"s":"BTCUSDT","U":99556321457,"u":99556321466,"b":[["77723.99000000","2.94035000"],["77719.38000000","0.00643000"],["77718.73000000","0.00000000"],["77650.02000000","1.41403000"],["77602.24000000","0.00000000"],["69951.60000000","0.00336000"],["69951.58000000","0.00000000"],["62179.20000000","0.00032000"],["62179.19000000","0.00000000"]],"a":[["77724.00000000","1.15028000"],["77733.32000000","0.00000000"],["77733.49000000","0.00643000"]]}}
{"type":"depth","received_at_ms":1788333163948,"data":{"e":"depthUpdate","E":1788333164114,"s":"BTCUSDT","U":99556321467,"u":99556321485,"b":[["77723.99000000","2.94028000"],["77719.99000000","0.30028000"],["77719.34000000","0.77086000"],["77714.79000000","0.00000000"],["77710.47000000","0.00000000"],["77708.53000000","0.00000000"],["77705.37000000","0.00007000"],["77669.67000000","0.00000000"],["77638.59000000","0.00000000"],["69951.60000000","0.00352000"]],"a":[["77730.72000000","0.00000000"],["77730.89000000","0.00643000"],["77736.47000000","0.00007000"],["77749.72000000","0.00000000"],["77788.60000000","0.00428000"],["77819.70000000","0.00000000"]]}}
{"type":"depth","received_at_ms":1788333164047,"data":{"e":"depthUpdate","E":1788333164214,"s":"BTCUSDT","U":99556321486,"u":99556321488,"b":[["77710.47000000","0.00200000"],["69951.60000000","0.00336000"],["62179.20000000","0.00000000"]],"a":[]}}
{"type":"depth","received_at_ms":1788333164148,"data":{"e":"depthUpdate","E":1788333164314,"s":"BTCUSDT","U":99556321489,"u":99556321501,"b":[["77685.53000000","0.09860000"],["77676.29000000","0.00000000"],["69951.60000000","0.00368000"],["69951.00000000","0.00068000"],["62179.00000000","0.00000000"]],"a":[["77751.03000000","0.00411000"],["77762.34000000","0.00000000"]]}}
{"type":"depth","received_at_ms":1788333164249,"data":{"e":"depthUpdate","E":1788333164414,"s":"BTCUSDT","U":99556321502,"u":99556321505,"b":[["69951.60000000","0.00368000"]],"a":[["77761.71000000","0.00000000"]]}}
{"type":"trade","received_at_ms":1788333164332,"data":{"e":"trade","E":1788333164497,"s":"BTCUSDT","t":6646665692,"p":"77724.00000000","q":"0.00614000","T":1788333164497,"m":false,"M":true}}
{"type":"trade","received_at_ms":1788333164332,"data":{"e":"trade","E":1788333164497,"s":"BTCUSDT","t":6646665693,"p":"77724.00000000","q":"0.00886000","T":1788333164497,"m":false,"M":true}}
{"type":"depth","received_at_ms":1788333164348,"data":{"e":"depthUpdate","E":1788333164514,"s":"BTCUSDT","U":99556321506,"u":99556321516,"b":[["69951.60000000","0.00393000"],["62179.20000000","0.00032000"],["62179.19000000","0.00000000"]],"a":[["77724.00000000","1.26741000"],["77821.01000000","0.00411000"]]}}
{"type":"depth","received_at_ms":1788333164448,"data":{"e":"depthUpdate","E":1788333164614,"s":"BTCUSDT","U":99556321517,"u":99556321521,"b":[["62179.20000000","0.00000000"],["62179.00000000","0.00000000"]],"a":[]}}
{"type":"depth","received_at_ms":1788333164548,"data":{"e":"depthUpdate","E":1788333164714,"s":"BTCUSDT","U":99556321522,"u":99556321540,"b":[["77723.99000000","2.94021000"],["77722.01000000","0.00257000"],["77721.18000000","0.00000000"],["77703.92000000","0.32948000"],["77685.80000000","0.00335000"],["77639.00000000","0.00411000"],["76558.13000000","0.00030000"],["76154.24000000","0.00026000"],["75557.14000000","0.00010000"],["69951.60000000","0.00409000"]],"a":[["77736.71000000","0.00000000"],["77737.55000000","0.00257000"],["77761.55000000","0.00010000"],["78889.86000000","0.00030000"]]}}
{"type":"depth","received_at_ms":1788333164647,"data":{"e":"depthUpdate","E":1788333164814,"s":"BTCUSDT","U":99556321541,"u":99556321542,"b":[["69951.60000000","0.00409000"]],"a":[]}}
{"type":"depth","received_at_ms":1788333164747,"data":{"e":"depthUpdate","E":1788333164914,"s":"BTCUSDT","U":99556321543,"u":99556321556,"b":[["77723.99000000","2.94028000"],["77708.94000000","0.00411000"],["69951.60000000","0.00425000"],["62179.00000000","0.00000000"]],"a":[["77728.73000000","0.00000000"],["77736.41000000","0.00400000"],["77736.42000000","0.00400000"],["77736.55000000","0.00000000"],["81001.14000000","0.00010000"]]}}
{"type":"depth","received_at_ms":1788333164848,"data":{"e":"depthUpdate","E":1788333165014,"s":"BTCUSDT","U":99556321557,"u":99556321566,"b":[["77719.38000000","0.00000000"],["77718.73000000","0.00643000"],["69951.60000000","0.00425000"],["69951.00000000","0.00068000"],["62179.20000000","0.00032000"],["62179.19000000","0.00000000"]],"a":[["77759.15000000","0.80156000"],["77772.36000000","0.80142000"]]}}
{"type":"depth","received_at_ms":1788333164948,"data":{"e":"depthUpdate","E":1788333165114,"s":"BTCUSDT","U":99556321567,"u":99556321584,"b":[["77719.99000000","0.30021000"],["77719.34000000","0.77093000"],["77708.94000000","0.00000000"],["77705.37000000","0.00007000"],["77670.08000000","0.00419000"],["77639.00000000","0.00000000"],["77622.43000000","0.00000000"],["69951.60000000","0.00441000"],["69951.00000000","0.00068000"]],"a":[["77736.47000000","0.00007000"],["77751.03000000","0.00000000"],["77788.60000000","0.00017000"],["77816.43000000","0.00087000"],["77821.01000000","0.00000000"]]}}
{"type":"trade","received_at_ms":1788333165024,"data":{"e":"trade","E":1788333165189,"s":"BTCUSDT","t":6646665694,"p":"77724.00000000","q":"0.00010000","T":1788333165189,"m":false,"M":true}}
{"type":"depth","received_at_ms":1788333165048,"data":{"e":"depthUpdate","E":1788333165214,"s":"BTCUSDT","U":99556321585,"u":99556321588,"b":[["69951.60000000","0.00448000"],["69951.59000000","0.00009000"],["62179.20000000","0.00000000"]],"a":[["77724.00000000","1.26731000"]]}}
{"type":"depth","received_at_ms":1788333165149,"data":{"e":"depthUpdate","E":1788333165314,"s":"BTCUSDT","U":99556321589,"u":99556321686,"b":[["77723.99000000","1.60095000"],["77723.90000000","0.05021000"],["77723.89000000","0.00014000"],["77723.40000000","0.00014000"],["77722.75000000","0.00007000"],["77722.46000000","0.00021000"],["77722.01000000","0.00000000"],["77720.44000000","0.00007000"],["77720.38000000","0.00000000"],["77719.99000000","0.00021000"],["77719.37000000","0.00000000"],["77719.36000000","0.00000000"],["77719.35000000","0.00000000"],["77719.34000000","0.76829000"],["77718.73000000","0.00000000"],["77718.51000000","0.00257000"],["77718.21000000","0.00000000"],["77717.84000000","0.00000000"],["77717.54000000","0.00000000"],["77716.51000000","0.00257000"],["77715.78000000","0.00643000"],["77715.31000000","0.00000000"],["77714.78000000","0.00000000"],["77714.77000000","0.34738000"],["77714.76000000","0.20376000"],["77713.36000000","0.00643000"],["77712.30000000","0.61027000"],["77712.26000000","0.00000000"],["77710.47000000","0.00600000"],["77710.46000000","0.00000000"],["77708.00000000","0.00000000"],["77699.57000000","0.00000000"],["77685.63000000","0.00000000"],["77681.68000000","0.34773000"],["77681.04000000","0.00007000"],["77677.11000000","0.00000000"],["77556.67000000","0.16870000"],["77533.05000000","3.87116000"],["71506.08000000","0.00014000"],["69951.60000000","0.00432000"]],"a":[["77724.00000000","4.32450000"],["77724.52000000","0.00014000"],["77724.53000000","0.03210000"],["77724.74000000","0.08411000"],["77727.96000000","0.00000000"],["77727.97000000","0.00014000"],["77728.36000000","0.00000000"],["77728.73000000","0.37738000"],["77729.81000000","0.00643000"],["77730.21000000","0.00643000"],["77730.89000000","0.00000000"],["77733.49000000","0.00000000"],["77734.05000000","0.00257000"],["77735.91000000","0.00000000"],["77736.41000000","0.00000000"],["77736.42000000","0.00400000"],["77737.55000000","0.00000000"]]}}
{"type":"depth","received_at_ms":1788333165248,"data":{"e":"depthUpdate","E":1788333165414,"s":"BTCUSDT","U":99556321687,"u":99556321769,"b":[["77723.99000000","1.60074000"],["77723.98000000","0.00076000"],["77723.90000000","0.05014000"],["77723.89000000","0.00000000"],["77722.74000000","0.01786000"],["77722.46000000","0.00007000"],["77721.32000000","0.01328000"],["77720.87000000","0.04105000"],["77720.43000000","0.00007000"],["77720.25000000","0.02140000"],["77719.99000000","0.00007000"],["77719.98000000","0.00000000"],["77719.35000000","0.45615000"],["77719.34000000","0.76655000"],["77718.01000000","0.00223000"],["77710.47000000","0.00400000"],["77707.17000000","0.00200000"],["77693.73000000","0.00000000"],["77693.02000000","0.00200000"],["69951.60000000","0.00448000"],["69951.00000000","0.00068000"]],"a":[["77724.00000000","4.34637000"],["77724.01000000","0.00104000"],["77724.44000000","0.12941000"],["77724.53000000","0.03224000"],["77724.73000000","0.00014000"],["77724.74000000","0.08425000"],["77725.99000000","0.00657000"],["77726.15000000","0.12142000"],["77726.17000000","0.00000000"],["77726.76000000","0.01281000"],["77727.97000000","0.00000000"],["77728.00000000","0.03007000"],["77729.25000000","0.00000000"],["77730.21000000","0.00000000"],["77734.40000000","0.00007000"],["77748.45000000","0.00400000"],["77760.15000000","0.00000000"]]}}
{"type":"depth","received_at_ms":1788333165349,"data":{"e":"depthUpdate","E":1788333165514,"s":"BTCUSDT","U":99556321770,"u":99556321786,"b":[["77714.77000000","1.66209000"],["77636.37000000","3.86600000"],["77528.68000000","0.00000000"],["69951.60000000","0.00416000"],["69951.00000000","0.00078000"],["62179.20000000","0.00032000"],["62179.19000000","0.00020000"]],"a":[["77724.74000000","0.08425000"],["77725.99000000","0.00671000"],["77727.98000000","0.02800000"],["77751.18000000","0.00411000"]]}}
{"type":"trade","received_at_ms":1788333165363,"data":{"e":"trade","E":1788333165528,"s":"BTCUSDT","t":6646665695,"p":"77723.99000000","q":"0.01500000","T":1788333165528,"m":true,"M":true}}
{"type":"trade","received_at_ms":1788333165388,"data":{"e":"trade","E":1788333165551,"s":"BTCUSDT","t":6646665696,"p":"77723.99000000","q":"0.00257000","T":1788333165551,"m":true,"M":true}}
{"type":"depth","received_at_ms":1788333165461,"data":{"e":"depthUpdate","E":1788333165614,"s":"BTCUSDT","U":99556321787,"u":99556321803,"b":[["77723.99000000","1.58317000"],["77702.00000000","0.03000000"],["77524.01000000","0.00000000"],["77518.01000000","0.00811000"],["69951.60000000","0.00448000"],["69951.59000000","0.00000000"],["69951.00000000","0.00068000"],["62179.20000000","0.00000000"],["62179.19000000","0.00000000"],["62179.00000000","0.00200000"]],"a":[]}}
{"type":"depth","received_at_ms":1788333165548,"data":{"e":"depthUpdate","E":1788333165714,"s":"BTCUSDT","U":99556321804,"u":99556321818,"b":[["77714.78000000","0.73613000"],["77714.77000000","1.32271000"],["77709.08000000","0.00411000"],["77650.02000000","0.70020000"],["77648.21000000","0.00000000"],["77640.44000000","1.61347000"],["76558.13000000","0.00030000"],["69951.60000000","0.00432000"],["62179.00000000","0.00000000"]],"a":[["77729.53000000","0.00000000"],["78889.86000000","0.00030000"]]}}
{"type":"depth","received_at_ms":1788333165648,"data":{"e":"depthUpdate","E":1788333165814,"s":"BTCUSDT","U":99556321819,"u":99556321825,"b":[["77710.47000000","0.00000000"],["77708.82000000","0.00400000"],["77698.00000000","0.73000000"],["71506.08000000","0.00000000"],["69951.60000000","0.00432000"]],"a":[["77724.00000000","4.34827000"]]}}
{"type":"depth","received_at_ms":1788333165747,"data":{"e":"depthUpdate","E":1788333165914,"s":"BTCUSDT","U":99556321826,"u":99556321830,"b":[["69951.60000000","0.00432000"],["69951.00000000","0.00078000"]],"a":[["77724.00000000","4.34637000"],["77790.06000000","0.00411000"]]}}
{"type":"depth","received_at_ms":1788333165860,"data":{"e":"depthUpdate","E":1788333166014,"s":"BTCUSDT","U":99556321831,"u":99556321868,"b":[["77723.99000000","1.74988000"],["77720.44000000","0.00007000"],["77719.47000000","0.00000000"],["77718.51000000","0.00000000"],["77718.07000000","0.00257000"],["77718.01000000","0.00000000"],["77716.52000000","0.00225000"],["77716.51000000","0.00000000"],["77715.78000000","0.00000000"],["77715.31000000","0.00257000"],["77714.99000000","0.00643000"],["77714.81000000","0.00187000"],["77681.04000000","0.00007000"],["77677.11000000","0.00000000"],["69951.60000000","0.00448000"],["69951.00000000","0.00068000"],["62179.20000000","0.00032000"],["62179.19000000","0.00000000"],["62179.00000000","0.00000000"]],"a":[["77724.00000000","4.34825000"],["77733.12000000","0.00000000"],["77733.60000000","0.00257000"],["77734.05000000","0.00000000"],["77735.01000000","0.00000000"],["77762.51000000","0.12872000"]]}}
{"type":"trade","received_at_ms":1788333165886,"data":{"e":"trade","E":1788333166051,"s":"BTCUSDT","t":6646665697,"p":"77723.99000000","q":"0.00007000","T":1788333166050,"m":true,"M":true}}
{"type":"trade","received_at_ms":1788333165886,"data":{"e":"trade","E":1788333166051,"s":"BTCUSDT","t":6646665698,"p":"77723.99000000","q":"0.00007000","T":1788333166050,"m":true,"M":true}}
{"type":"trade","received_at_ms":1788333165886,"data":{"e":"trade","E":1788333166051,"s":"BTCUSDT","t":6646665699,"p":"77723.99000000","q":"0.00064000","T":1788333166050,"m":true,"M":true}}
{"type":"trade","received_at_ms":1788333165886,"data":{"e":"trade","E":1788333166051,"s":"BTCUSDT","t":6646665700,"p":"77723.99000000","q":"0.00065000","T":1788333166050,"m":true,"M":true}}
{"type":"trade","received_at_ms":1788333165886,"data":{"e":"trade","E":1788333166051,"s":"BTCUSDT","t":6646665701,"p":"77723.99000000","q":"0.00008000","T":1788333166050,"m":true,"M":true}}
{"type":"trade","received_at_ms":1788333165886,"data":{"e":"trade","E":1788333166051,"s":"BTCUSDT","t":6646665702,"p":"77723.99000000","q":"0.00013000","T":1788333166050,"m":true,"M":true}}
{"type":"trade","received_at_ms":1788333165886,"data":{"e":"trade","E":1788333166051,"s":"BTCUSDT","t":6646665703,"p":"77723.99000000","q":"0.00007000","T":1788333166050,"m":true,"M":true}}
{"type":"trade","received_at_ms":1788333165886,"data":{"e":"trade","E":1788333166051,"s":"BTCUSDT","t":6646665704,"p":"77723.99000000","q":"0.00065000","T":1788333166050,"m":true,"M":true}}
{"type":"trade","received_at_ms":1788333165886,"data":{"e":"trade","E":1788333166051,"s":"BTCUSDT","t":6646665705,"p":"77723.99000000","q":"0.00066000","T":1788333166050,"m":true,"M":true}}
{"type":"trade","received_at_ms":1788333165886,"data":{"e":"trade","E":1788333166051,"s":"BTCUSDT","t":6646665706,"p":"77723.99000000","q":"0.00007000","T":1788333166050,"m":true,"M":true}}
{"type":"trade","received_at_ms":1788333165886,"data":{"e":"trade","E":1788333166051,"s":"BTCUSDT","t":6646665707,"p":"77723.99000000","q":"0.00007000","T":1788333166050,"m":true,"M":true}}
{"type":"trade","received_at_ms":1788333165886,"data":{"e":"trade","E":1788333166051,"s":"BTCUSDT","t":6646665708,"p":"77723.99000000","q":"0.00007000","T":1788333166050,"m":true,"M":true}}
{"type":"trade","received_at_ms":1788333165886,"data":{"e":"trade","E":1788333166051,"s":"BTCUSDT","t":6646665709,"p":"77723.99000000","q":"0.04208000","T":1788333166050,"m":true,"M":true}}
{"type":"trade","received_at_ms":1788333165889,"data":{"e":"trade","E":1788333166055,"s":"BTCUSDT","t":6646665710,"p":"77723.99000000","q":"0.00958000","T":1788333166054,"m":true,"M":true}}
{"type":"depth","received_at_ms":1788333165947,"data":{"e":"depthUpdate","E":1788333166114,"s":"BTCUSDT","U":99556321869,"u":99556322091,"b":[["77723.99000000","0.42776000"],["77723.98000000","0.00076000"],["77723.96000000","0.00000000"],["77723.95000000","0.00021000"],["77723.91000000","0.00000000"],["77723.90000000","0.00014000"],["77723.55000000","0.00000000"],["77723.54000000","0.00021000"],["77723.40000000","0.00000000"],["77723.39000000","0.00079000"],["77722.75000000","0.00014000"],["77722.74000000","0.01793000"],["77722.06000000","0.00014000"],["77722.05000000","0.05007000"],["77722.01000000","0.00014000"],["77722.00000000","0.05000000"],["77721.51000000","0.00014000"],["77720.88000000","0.00007000"],["77720.25000000","0.02147000"],["77719.88000000","0.11191000"],["77719.35000000","0.11191000"],["77719.34000000","0.35400000"],["77718.72000000","0.00007000"],["77718.07000000","0.00000000"],["77718.00000000","0.11191000"],["77716.52000000","0.00000000"],["77716.50000000","0.00007000"],["77715.77000000","0.11199000"],["77715.31000000","0.00000000"],["77714.99000000","0.00000000"],["77714.79000000","0.11191000"],["77714.78000000","0.00000000"],["77714.77000000","0.00000000"],["77714.76000000","0.00000000"],["77714.75000000","0.56543000"],["77714.30000000","0.00224000"],["77713.95000000","0.00000000"],["77713.72000000","0.00257000"],["77713.61000000","0.00047000"],["77713.36000000","0.00000000"],["77712.83000000","0.00257000"],["77712.75000000","0.00000000"],["77712.56000000","0.00007000"],["77712.30000000","0.58464000"],["77711.64000000","0.00643000"],["77710.47000000","0.11191000"],["77710.46000000","1.31471000"],["77710.44000000","0.00000000"],["77710.21000000","0.00000000"],["77709.32000000","0.00000000"],["77708.82000000","0.00000000"],["77708.41000000","0.65161000"],["77707.56000000","0.00643000"],["77707.17000000","0.00000000"],["77706.58000000","0.00000000"],["77706.37000000","0.00000000"],["77706.35000000","0.00200000"],["77705.56000000","0.00000000"],["77705.43000000","1.32671000"],["77705.42000000","0.62754000"],["77705.37000000","0.00000000"],["77704.32000000","0.33965000"],["77704.31000000","0.00000000"],["77700.27000000","1.24920000"],["77700.26000000","1.93226000"],["77700.25000000","0.00000000"],["77700.24000000","0.00000000"],["77698.00000000","0.03000000"],["77697.90000000","0.00000000"],["77697.84000000","0.00000000"],["77693.06000000","0.04765000"],["77693.02000000","0.00000000"],["77689.62000000","0.00200000"],["77678.19000000","0.34775000"],["77677.10000000","0.00007000"],["77640.44000000","0.00000000"],["69951.60000000","0.00432000"],["69951.59000000","0.00009000"]],"a":[["77724.00000000","4.36184000"],["77724.01000000","0.00027000"],["77724.37000000","0.00000000"],["77724.74000000","0.08219000"],["77725.99000000","0.00028000"],["77726.14000000","0.00007000"],["77729.81000000","0.00000000"],["77733.60000000","0.00000000"],["77734.56000000","0.27836000"],["77736.47000000","0.00000000"],["77739.75000000","0.38608000"],["77743.45000000","0.00200000"],["77743.98000000","0.00000000"],["77746.43000000","0.34744000"],["77749.54000000","0.00000000"],["77752.35000000","0.00400000"],["77758.20000000","0.00000000"],["77772.15000000","0.00000000"],["77776.24000000","0.49585000"],["77776.27000000","0.00000000"]]}}
{"type":"depth","received_at_ms":1788333166047,"data":{"e":"depthUpdate","E":1788333166214,"s":"BTCUSDT","U":99556322092,"u":99556322172,"b":[["77723.99000000","0.44474000"],["77723.98000000","0.00076000"],["77723.95000000","0.00000000"],["77723.90000000","0.00000000"],["77723.54000000","0.00007000"],["77723.39000000","0.00065000"],["77722.74000000","0.01800000"],["77722.63000000","0.00014000"],["77722.62000000","0.11191000"],["77722.06000000","0.00000000"],["77722.05000000","0.00021000"],["77722.01000000","0.00000000"],["77722.00000000","0.00014000"],["77721.33000000","0.00000000"],["77721.32000000","0.01335000"],["77721.26000000","0.00014000"],["77721.25000000","0.10612000"],["77721.21000000","0.00007000"],["77721.20000000","0.05007000"],["77721.15000000","0.05000000"],["77720.88000000","0.00000000"],["77720.25000000","0.02161000"],["77714.80000000","0.26841000"],["77713.59000000","0.00048000"],["77712.56000000","0.00014000"],["77712.31000000","0.11191000"],["77705.37000000","0.00007000"],["69951.60000000","0.00432000"],["62179.20000000","0.00000000"]],"a":[["77724.74000000","0.08219000"],["77725.99000000","0.00014000"],["77727.98000000","0.02814000"],["77734.32000000","0.00128000"],["77736.47000000","0.00007000"],["77742.12000000","0.00000000"]]}}
{"type":"depth","received_at_ms":1788333166148,"data":{"e":"depthUpdate","E":1788333166314,"s":"BTCUSDT","U":99556322173,"u":99556322274,"b":[["77723.99000000","1.03237000"],["77723.98000000","0.00076000"],["77723.24000000","0.00206000"],["77723.21000000","0.08205000"],["77722.74000000","0.01793000"],["77722.62000000","0.11205000"],["77722.05000000","0.00000000"],["77722.00000000","0.00000000"],["77721.32000000","0.01335000"],["77721.25000000","0.10626000"],["77721.21000000","0.00000000"],["77721.20000000","0.00014000"],["77721.15000000","0.00000000"],["77721.11000000","0.00007000"],["77721.10000000","2.00000000"],["77720.25000000","0.02133000"],["77719.88000000","0.00000000"],["77719.35000000","0.00000000"],["77719.34000000","0.35393000"],["77718.00000000","0.00000000"],["77715.77000000","0.00008000"],["77714.79000000","0.00000000"],["77712.57000000","0.00643000"],["77712.31000000","0.00000000"],["77710.47000000","0.00000000"],["77708.41000000","1.16323000"],["77707.56000000","0.00000000"],["77706.35000000","0.00000000"],["77705.44000000","1.93226000"],["77705.43000000","1.32271000"],["69951.60000000","0.00432000"],["62179.00000000","0.00000000"]],"a":[["77724.00000000","4.35010000"],["77724.01000000","0.00083000"],["77725.98000000","0.00643000"],["77726.75000000","0.00643000"],["77734.56000000","0.00000000"],["77737.68000000","0.31013000"],["77750.60000000","0.00000000"],["77754.25000000","0.00000000"],["77821.16000000","0.00411000"],["78500.00000000","12.10021000"]]}}
{"type":"depth","received_at_ms":1788333166248,"data":{"e":"depthUpdate","E":1788333166414,"s":"BTCUSDT","U":99556322275,"u":99556322324,"b":[["77723.99000000","0.95443000"],["77723.98000000","0.00090000"],["77723.22000000","0.00014000"],["77723.21000000","0.08219000"],["77722.63000000","0.00000000"],["77722.62000000","0.00014000"],["77721.33000000","0.00014000"],["77721.25000000","0.10605000"],["77721.20000000","0.00000000"],["77721.11000000","0.00000000"],["77705.44000000","1.93426000"],["77652.44000000","0.00000000"],["77619.19000000","0.64767000"],["77564.01000000","0.00000000"],["69951.60000000","0.00432000"],["62179.00000000","0.00000000"]],"a":[["77724.74000000","0.08219000"],["77725.98000000","0.00657000"],["77726.18000000","0.32193000"],["77726.75000000","0.00657000"],["77726.76000000","0.01267000"],["77727.98000000","0.02800000"]]}}
{"type":"depth","received_at_ms":1788333166348,"data":{"e":"depthUpdate","E":1788333166514,"s":"BTCUSDT","U":99556322325,"u":99556322381,"b":[["77723.99000000","0.44474000"],["77723.98000000","0.00083000"],["77722.74000000","0.01786000"],["77722.62000000","0.00000000"],["77721.25000000","0.10619000"],["77712.57000000","0.00000000"],["77710.47000000","0.00643000"],["77709.08000000","0.00000000"],["77670.08000000","0.00008000"],["77658.64000000","0.00321000"],["77639.14000000","0.00411000"],["77580.24000000","0.00128000"],["69951.00000000","0.00068000"],["62179.20000000","0.00032000"],["62179.00000000","0.00000000"]],"a":[["77724.00000000","4.35541000"],["77724.01000000","0.00027000"],["77725.98000000","0.00014000"],["77750.69000000","0.01984000"],["77751.18000000","0.00000000"],["77754.34000000","0.05478000"],["77790.06000000","0.00000000"],["77821.16000000","0.00000000"]]}}
{"type":"depth","received_at_ms":1788333166448,"data":{"e":"depthUpdate","E":1788333166614,"s":"BTCUSDT","U":99556322382,"u":99556322402,"b":[["77723.99000000","0.44474000"],["77708.81000000","0.00000000"],["69951.60000000","0.00432000"],["62179.20000000","0.00000000"],["62179.19000000","0.00000000"]],"a":[["77724.00000000","4.36184000"],["77724.74000000","0.08219000"],["77725.98000000","0.00000000"],["77726.75000000","0.00014000"],["77726.76000000","0.01281000"]]}}
{"type":"depth","received_at_ms":1788333166548,"data":{"e":"depthUpdate","E":1788333166714,"s":"BTCUSDT","U":99556322403,"u":99556322425,"b":[["77723.99000000","0.44481000"],["77721.25000000","0.10626000"],["77721.11000000","0.10612000"],["77714.71000000","0.00257000"],["77713.72000000","0.00000000"],["77708.87000000","0.00411000"],["77698.00000000","0.73000000"],["77677.10000000","0.00000000"],["76558.13000000","0.00030000"],["69951.60000000","0.00448000"]],"a":[["77726.18000000","0.32193000"],["77726.75000000","0.00000000"],["77727.98000000","0.02814000"],["78889.86000000","0.00030000"]]}}
{"type":"depth","received_at_ms":1788333166647,"data":{"e":"depthUpdate","E":1788333166814,"s":"BTCUSDT","U":99556322426,"u":99556322434,"b":[["77721.25000000","0.10626000"],["77708.42000000","0.00000000"],["77707.17000000","0.00200000"],["77705.44000000","1.93226000"],["69951.60000000","0.00432000"]],"a":[]}}
{"type":"depth","received_at_ms":1788333166748,"data":{"e":"depthUpdate","E":1788333166914,"s":"BTCUSDT","U":99556322435,"u":99556322473,"b":[["77723.99000000","1.02921000"],["77723.98000000","0.00090000"],["77722.74000000","0.01793000"],["77722.63000000","0.00014000"],["77722.62000000","0.11191000"],["77721.33000000","0.00000000"],["69951.60000000","0.00448000"]],"a":[["77724.00000000","4.35003000"],["77724.01000000","0.00076000"],["77725.98000000","0.00643000"],["77726.75000000","0.00643000"]]}}
{"type":"depth","received_at_ms":1788333166847,"data":{"e":"depthUpdate","E":1788333167014,"s":"BTCUSDT","U":99556322474,"u":99556322509,"b":[["77723.99000000","0.95442000"],["77722.74000000","0.01793000"],["77722.62000000","0.11205000"],["77720.87000000","0.04091000"],["77716.50000000","0.00014000"],["77635.26000000","1.61347000"],["69951.60000000","0.00432000"],["62179.20000000","0.00032000"],["62179.19000000","0.00000000"]],"a":[["77724.00000000","4.35010000"],["77724.01000000","0.00083000"],["77724.74000000","0.08219000"],["77725.98000000","0.00657000"],["77726.18000000","0.32193000"],["77726.75000000","0.00657000"],["77726.76000000","0.01267000"],["77727.98000000","0.02800000"]]}}
{"type":"depth","received_at_ms":1788333166948,"data":{"e":"depthUpdate","E":1788333167114,"s":"BTCUSDT","U":99556322510,"u":99556322518,"b":[["77716.29000000","0.00257000"],["77714.71000000","0.00000000"],["77707.17000000","0.00000000"],["77706.35000000","0.00200000"],["69951.60000000","0.00432000"]],"a":[["77724.00000000","4.34721000"],["77731.05000000","0.00257000"],["77747.13000000","0.00411000"]]}}
{"type":"depth","received_at_ms":1788333167048,"data":{"e":"depthUpdate","E":1788333167214,"s":"BTCUSDT","U":99556322519,"u":99556322526,"b":[["77705.37000000","0.00007000"],["69951.60000000","0.00432000"],["62179.20000000","0.00000000"],["62179.00000000","0.00000000"]],"a":[["77736.47000000","0.00007000"]]}}
{"type":"depth","received_at_ms":1788333167148,"data":{"e":"depthUpdate","E":1788333167314,"s":"BTCUSDT","U":99556322527,"u":99556322535,"b":[["77723.99000000","1.02890000"],["77670.01000000","0.00411000"],["77520.01000000","0.00811000"],["77518.01000000","0.00000000"],["69951.60000000","0.00448000"]],"a":[]}}
