{"type":"trade","received_at_ms":1788333187800,"data":{"e":"trade","E":1788333187966,"s":"BTCUSDT","t":6646665940,"p":"77724.00000000","q":"0.00200000","T":1788333187966,"m":false,"M":true}}
{"type":"trade","received_at_ms":1788333187800,"data":{"e":"trade","E":1788333187967,"s":"BTCUSDT","t":6646665941,"p":"77724.00000000","q":"0.00200000","T":1788333187966,"m":false,"M":true}}
{"type":"trade","received_at_ms":1788333187803,"data":{"e":"trade","E":1788333187967,"s":"BTCUSDT","t":6646665942,"p":"77724.00000000","q":"0.00200000","T":1788333187967,"m":false,"M":true}}
{"type":"depth","received_at_ms":1788333187847,"data":{"e":"depthUpdate","E":1788333188014,"s":"BTCUSDT","U":99556330158,"u":99556330220,"b":[["77723.99000000","2.06869000"],["77723.98000000","0.00090000"],["77723.90000000","0.05021000"],["77722.76000000","0.00657000"],["77722.69000000","0.00000000"],["77722.64000000","0.37338000"],["77722.63000000","0.00400000"],["77722.00000000","0.00000000"],["77721.11000000","0.00007000"],["77720.25000000","0.02147000"],["77719.88000000","0.00000000"],["77719.40000000","0.86088000"],["77719.39000000","0.00000000"],["77712.31000000","0.62746000"],["75557.14000000","0.00010000"],["69951.60000000","0.00432000"],["69951.59000000","0.00000000"],["62179.20000000","0.00032000"]],"a":[["77724.00000000","0.52993000"],["77724.01000000","0.00104000"],["77724.64000000","0.11967000"],["77725.37000000","0.11205000"],["77725.68000000","0.00000000"],["77729.59000000","0.14290000"],["77733.58000000","0.00400000"],["77736.49000000","0.00400000"],["77736.50000000","1.11022000"],["77755.79000000","0.50651000"],["77756.89000000","0.34740000"],["77767.72000000","0.00000000"],["77772.00000000","0.03000000"]]}}
{"type":"depth","received_at_ms":1788333187947,"data":{"e":"depthUpdate","E":1788333188114,"s":"BTCUSDT","U":99556330221,"u":99556330235,"b":[["77723.99000000","2.06862000"],["77722.64000000","0.37352000"],["77721.32000000","0.01328000"],["77720.25000000","0.02140000"],["69951.60000000","0.00432000"]],"a":[["77724.00000000","0.53435000"],["77726.00000000","0.03014000"],["77766.17000000","0.00000000"],["77766.59000000","0.00000000"]]}}
{"type":"depth","received_at_ms":1788333188052,"data":{"e":"depthUpdate","E":1788333188214,"s":"BTCUSDT","U":99556330236,"u":99556330240,"b":[["71506.08000000","0.00000000"],["69951.60000000","0.00432000"],["69951.00000000","0.00088000"],["62179.20000000","0.00000000"]],"a":[]}}
{"type":"depth","received_at_ms":1788333188153,"data":{"e":"depthUpdate","E":1788333188314,"s":"BTCUSDT","U":99556330241,"u":99556330258,"b":[["77710.42000000","0.00000000"],["77640.48000000","0.00411000"],["77528.01000000","0.00000000"],["77526.01000000","0.00811000"],["69951.60000000","0.00448000"],["69951.00000000","0.00068000"],["62179.19000000","0.00000000"],["62179.00000000","0.00600000"]],"a":[["77724.00000000","0.53593000"],["77791.43000000","0.00000000"],["77822.55000000","0.00000000"],["81001.14000000","0.00010000"]]}}
{"type":"depth","received_at_ms":1788333188248,"data":{"e":"depthUpdate","E":1788333188414,"s":"BTCUSDT","U":99556330259,"u":99556330261,"b":[["69951.60000000","0.00432000"]],"a":[]}}
{"type":"depth","received_at_ms":1788333188373,"data":{"e":"depthUpdate","E":1788333188514,"s":"BTCUSDT","U":99556330262,"u":99556330264,"b":[["69951.60000000","0.00432000"],["62179.20000000","0.00032000"]],"a":[]}}
{"type":"depth","received_at_ms":1788333188476,"data":{"e":"depthUpdate","E":1788333188614,"s":"BTCUSDT","U":99556330265,"u":99556330274,"b":[["69951.60000000","0.00432000"],["62179.20000000","0.00000000"],["62179.00000000","0.00600000"]],"a":[["77766.40000000","0.00000000"],["77766.77000000","0.12871000"]]}}
{"type":"depth","received_at_ms":1788333188561,"data":{"e":"depthUpdate","E":1788333188715,"s":"BTCUSDT","U":99556330275,"u":99556330278,"b":[["69951.60000000","0.00432000"]],"a":[]}}
{"type":"depth","received_at_ms":1788333188700,"data":{"e":"depthUpdate","E":1788333188815,"s":"BTCUSDT","U":99556330279,"u":99556330289,"b":[["77705.37000000","0.00007000"],["76558.13000000","0.00030000"],["75000.00000000","110.23056000"],["69951.60000000","0.00448000"]],"a":[["77736.47000000","0.00007000"],["77762.10000000","0.00400000"],["77764.05000000","0.00000000"],["78889.86000000","0.00030000"]]}}
{"type":"depth","received_at_ms":1788333188755,"data":{"e":"depthUpdate","E":1788333188914,"s":"BTCUSDT","U":99556330290,"u":99556330299,"b":[["77723.55000000","0.00000000"],["77723.11000000","0.00257000"],["77712.31000000","0.00000000"],["77710.48000000","0.62746000"],["69951.60000000","0.00432000"],["62179.19000000","0.00000000"],["62179.00000000","0.00600000"]],"a":[["77741.94000000","0.00257000"]]}}
{"type":"depth","received_at_ms":1788333188847,"data":{"e":"depthUpdate","E":1788333189014,"s":"BTCUSDT","U":99556330300,"u":99556330309,"b":[["77723.99000000","2.06862000"],["77723.98000000","0.00090000"],["77719.41000000","1.93826000"],["77591.31000000","0.00000000"],["69951.60000000","0.00448000"],["62179.20000000","0.00032000"]],"a":[]}}
{"type":"trade","received_at_ms":1788333188850,"data":{"e":"trade","E":1788333189017,"s":"BTCUSDT","t":6646665943,"p":"77724.00000000","q":"0.02100000","T":1788333189016,"m":false,"M":true}}
{"type":"trade","received_at_ms":1788333188854,"data":{"e":"trade","E":1788333189017,"s":"BTCUSDT","t":6646665944,"p":"77724.00000000","q":"0.01976000","T":1788333189017,"m":false,"M":true}}
{"type":"trade","received_at_ms":1788333188854,"data":{"e":"trade","E":1788333189017,"s":"BTCUSDT","t":6646665945,"p":"77724.00000000","q":"0.00007000","T":1788333189017,"m":false,"M":true}}
{"type":"trade","received_at_ms":1788333188854,"data":{"e":"trade","E":1788333189017,"s":"BTCUSDT","t":6646665946,"p":"77724.00000000","q":"0.00013000","T":1788333189017,"m":false,"M":true}}
{"type":"trade","received_at_ms":1788333188854,"data":{"e":"trade","E":1788333189017,"s":"BTCUSDT","t":6646665947,"p":"77724.00000000","q":"0.00010000","T":1788333189017,"m":false,"M":true}}
{"type":"trade","received_at_ms":1788333188854,"data":{"e":"trade","E":1788333189017,"s":"BTCUSDT","t":6646665948,"p":"77724.00000000","q":"0.00007000","T":1788333189017,"m":false,"M":true}}
{"type":"trade","received_at_ms":1788333188854,"data":{"e":"trade","E":1788333189017,"s":"BTCUSDT","t":6646665949,"p":"77724.00000000","q":"0.00007000","T":1788333189017,"m":false,"M":true}}
{"type":"trade","received_at_ms":1788333188854,"data":{"e":"trade","E":1788333189017,"s":"BTCUSDT","t":6646665950,"p":"77724.00000000","q":"0.00007000","T":1788333189017,"m":false,"M":true}}
{"type":"trade","received_at_ms":1788333188854,"data":{"e":"trade","E":1788333189017,"s":"BTCUSDT","t":6646665951,"p":"77724.00000000","q":"0.00007000","T":1788333189017,"m":false,"M":true}}
{"type":"trade","received_at_ms":1788333188854,"data":{"e":"trade","E":1788333189017,"s":"BTCUSDT","t":6646665952,"p":"77724.00000000","q":"0.00007000","T":1788333189017,"m":false,"M":true}}
{"type":"trade","received_at_ms":1788333188854,"data":{"e":"trade","E":1788333189017,"s":"BTCUSDT","t":6646665953,"p":"77724.00000000","q":"0.00007000","T":1788333189017,"m":false,"M":true}}
{"type":"trade","received_at_ms":1788333188854,"data":{"e":"trade","E":1788333189017,"s":"BTCUSDT","t":6646665954,"p":"77724.00000000","q":"0.00007000","T":1788333189017,"m":false,"M":true}}
{"type":"trade","received_at_ms":1788333188854,"data":{"e":"trade","E":1788333189017,"s":"BTCUSDT","t":6646665955,"p":"77724.00000000","q":"0.00007000","T":1788333189017,"m":false,"M":true}}
{"type":"trade","received_at_ms":1788333188854,"data":{"e":"trade","E":1788333189017,"s":"BTCUSDT","t":6646665956,"p":"77724.00000000","q":"0.00007000","T":1788333189017,"m":false,"M":true}}
{"type":"trade","received_at_ms":1788333188854,"data":{"e":"trade","E":1788333189017,"s":"BTCUSDT","t":6646665957,"p":"77724.00000000","q":"0.00007000","T":1788333189017,"m":false,"M":true}}
{"type":"trade","received_at_ms":1788333188854,"data":{"e":"trade","E":1788333189017,"s":"BTCUSDT","t":6646665958,"p":"77724.00000000","q":"0.00007000","T":1788333189017,"m":false,"M":true}}
{"type":"trade","received_at_ms":1788333188854,"data":{"e":"trade","E":1788333189017,"s":"BTCUSDT","t":6646665959,"p":"77724.00000000","q":"0.00007000","T":1788333189017,"m":false,"M":true}}
{"type":"trade","received_at_ms":1788333188854,"data":{"e":"trade","E":1788333189017,"s":"BTCUSDT","t":6646665960,"p":"77724.00000000","q":"0.00007000","T":1788333189017,"m":false,"M":true}}
{"type":"trade","received_at_ms":1788333188854,"data":{"e":"trade","E":1788333189017,"s":"BTCUSDT","t":6646665961,"p":"77724.00000000","q":"0.00003000","T":1788333189017,"m":false,"M":true}}
{"type":"trade","received_at_ms":1788333188854,"data":{"e":"trade","E":1788333189019,"s":"BTCUSDT","t":6646665962,"p":"77724.00000000","q":"0.01197000","T":1788333189018,"m":false,"M":true}}
{"type":"trade","received_at_ms":1788333188854,"data":{"e":"trade","E":1788333189019,"s":"BTCUSDT","t":6646665963,"p":"77724.00000000","q":"0.00007000","T":1788333189018,"m":false,"M":true}}
{"type":"trade","received_at_ms":1788333188854,"data":{"e":"trade","E":1788333189019,"s":"BTCUSDT","t":6646665964,"p":"77724.00000000","q":"0.00007000","T":1788333189018,"m":false,"M":true}}
{"type":"trade","received_at_ms":1788333188855,"data":{"e":"trade","E":1788333189019,"s":"BTCUSDT","t":6646665965,"p":"77724.00000000","q":"0.00390000","T":1788333189018,"m":false,"M":true}}
{"type":"trade","received_at_ms":1788333188855,"data":{"e":"trade","E":1788333189019,"s":"BTCUSDT","t":6646665966,"p":"77724.00000000","q":"0.00007000","T":1788333189018,"m":false,"M":true}}
{"type":"trade","received_at_ms":1788333188855,"data":{"e":"trade","E":1788333189019,"s":"BTCUSDT","t":6646665967,"p":"77724.00000000","q":"0.00400000","T":1788333189018,"m":false,"M":true}}
{"type":"trade","received_at_ms":1788333188855,"data":{"e":"trade","E":1788333189019,"s":"BTCUSDT","t":6646665968,"p":"77724.00000000","q":"0.00007000","T":1788333189018,"m":false,"M":true}}
{"type":"trade","received_at_ms":1788333188855,"data":{"e":"trade","E":1788333189019,"s":"BTCUSDT","t":6646665969,"p":"77724.00000000","q":"0.00007000","T":1788333189018,"m":false,"M":true}}
{"type":"trade","received_at_ms":1788333188855,"data":{"e":"trade","E":1788333189019,"s":"BTCUSDT","t":6646665970,"p":"77724.00000000","q":"0.00069000","T":1788333189018,"m":false,"M":true}}
{"type":"trade","received_at_ms":1788333188855,"data":{"e":"trade","E":1788333189019,"s":"BTCUSDT","t":6646665971,"p":"77724.00000000","q":"0.00009000","T":1788333189018,"m":false,"M":true}}
{"type":"depth","received_at_ms":1788333188951,"data":{"e":"depthUpdate","E":1788333189114,"s":"BTCUSDT","U":99556330310,"u":99556330358,"b":[["77723.99000000","2.06778000"],["77723.98000000","0.00027000"],["77721.11000000","0.62753000"],["77719.42000000","1.43945000"],["77719.40000000","0.00000000"],["77710.48000000","0.00000000"],["77594.80000000","0.02015000"],["69951.60000000","0.00441000"]],"a":[["77724.00000000","0.47392000"],["77741.94000000","0.00000000"],["77741.95000000","0.00257000"]]}}
{"type":"trade","received_at_ms":1788333188975,"data":{"e":"trade","E":1788333189142,"s":"BTCUSDT","t":6646665972,"p":"77724.00000000","q":"0.00008000","T":1788333189141,"m":false,"M":true}}
{"type":"depth","received_at_ms":1788333189048,"data":{"e":"depthUpdate","E":1788333189214,"s":"BTCUSDT","U":99556330359,"u":99556330368,"b":[["77539.25000000","0.02015000"],["77511.73000000","0.00000000"],["77024.47000000","0.00000000"],["75486.25000000","0.00000000"],["69951.60000000","0.00457000"],["62179.20000000","0.00000000"]],"a":[["77724.00000000","0.47392000"]]}}
{"type":"depth","received_at_ms":1788333189148,"data":{"e":"depthUpdate","E":1788333189314,"s":"BTCUSDT","U":99556330369,"u":99556330381,"b":[["75493.01000000","0.00000000"],["69951.60000000","0.00441000"],["62179.19000000","0.00000000"]],"a":[["77724.00000000","0.47392000"],["77724.01000000","0.00097000"],["77724.63000000","0.00000000"],["77724.64000000","0.00014000"],["77727.99000000","0.00007000"]]}}
{"type":"depth","received_at_ms":1788333189248,"data":{"e":"depthUpdate","E":1788333189414,"s":"BTCUSDT","U":99556330382,"u":99556330393,"b":[["77548.18000000","0.00000000"],["77539.25000000","0.00000000"],["77528.01000000","0.00811000"],["77526.01000000","0.00000000"],["77510.73000000","0.02015000"],["69951.60000000","0.00441000"],["69951.00000000","0.00068000"]],"a":[["77724.64000000","0.00000000"],["77729.46000000","0.10092000"]]}}
{"type":"depth","received_at_ms":1788333189347,"data":{"e":"depthUpdate","E":1788333189514,"s":"BTCUSDT","U":99556330394,"u":99556330397,"b":[["69951.60000000","0.00441000"],["62179.20000000","0.00032000"]],"a":[["77791.43000000","0.00411000"]]}}
{"type":"depth","received_at_ms":1788333189446,"data":{"e":"depthUpdate","E":1788333189614,"s":"BTCUSDT","U":99556330398,"u":99556330411,"b":[["69951.60000000","0.00457000"],["62179.20000000","0.00000000"],["62179.00000000","0.00600000"]],"a":[["77724.00000000","0.47399000"],["77724.01000000","0.00104000"],["77725.22000000","0.00014000"],["77725.23000000","0.12239000"],["77727.99000000","0.00000000"],["77741.95000000","0.00000000"],["77741.96000000","0.00257000"]]}}
{"type":"depth","received_at_ms":1788333189548,"data":{"e":"depthUpdate","E":1788333189714,"s":"BTCUSDT","U":99556330412,"u":99556330422,"b":[["77549.56000000","4.59178000"],["77528.01000000","0.00000000"],["77526.01000000","0.00811000"],["75505.70000000","0.00000000"],["69951.60000000","0.00425000"]],"a":[["77724.00000000","0.47413000"],["77729.46000000","0.10078000"],["77741.96000000","0.00000000"],["77741.97000000","0.00257000"]]}}
{"type":"trade","received_at_ms":1788333189624,"data":{"e":"trade","E":1788333189792,"s":"BTCUSDT","t":6646665973,"p":"77724.00000000","q":"0.00047000","T":1788333189791,"m":false,"M":true}}
{"type":"trade","received_at_ms":1788333189626,"data":{"e":"trade","E":1788333189792,"s":"BTCUSDT","t":6646665974,"p":"77724.00000000","q":"0.00068000","T":1788333189791,"m":false,"M":true}}
{"type":"trade","received_at_ms":1788333189626,"data":{"e":"trade","E":1788333189792,"s":"BTCUSDT","t":6646665975,"p":"77724.00000000","q":"0.00065000","T":1788333189791,"m":false,"M":true}}
{"type":"trade","received_at_ms":1788333189626,"data":{"e":"trade","E":1788333189792,"s":"BTCUSDT","t":6646665976,"p":"77724.00000000","q":"0.00007000","T":1788333189791,"m":false,"M":true}}
{"type":"trade","received_at_ms":1788333189626,"data":{"e":"trade","E":1788333189792,"s":"BTCUSDT","t":6646665977,"p":"77724.00000000","q":"0.00008000","T":1788333189791,"m":false,"M":true}}
{"type":"trade","received_at_ms":1788333189626,"data":{"e":"trade","E":1788333189792,"s":"BTCUSDT","t":6646665978,"p":"77724.00000000","q":"0.00007000","T":1788333189791,"m":false,"M":true}}
{"type":"trade","received_at_ms":1788333189626,"data":{"e":"trade","E":1788333189792,"s":"BTCUSDT","t":6646665979,"p":"77724.00000000","q":"0.00007000","T":1788333189791,"m":false,"M":true}}
{"type":"trade","received_at_ms":1788333189626,"data":{"e":"trade","E":1788333189792,"s":"BTCUSDT","t":6646665980,"p":"77724.00000000","q":"0.00007000","T":1788333189791,"m":false,"M":true}}
{"type":"trade","received_at_ms":1788333189626,"data":{"e":"trade","E":1788333189792,"s":"BTCUSDT","t":6646665981,"p":"77724.00000000","q":"0.00007000","T":1788333189791,"m":false,"M":true}}
{"type":"trade","received_at_ms":1788333189626,"data":{"e":"trade","E":1788333189792,"s":"BTCUSDT","t":6646665982,"p":"77724.00000000","q":"0.01277000","T":1788333189791,"m":false,"M":true}}
{"type":"depth","received_at_ms":1788333189647,"data":{"e":"depthUpdate","E":1788333189814,"s":"BTCUSDT","U":99556330423,"u":99556330442,"b":[["77722.70000000","0.00400000"],["77722.63000000","0.00000000"],["76558.13000000","0.00030000"],["69951.60000000","0.00448000"],["69951.59000000","0.00009000"]],"a":[["77724.00000000","0.46054000"],["77725.23000000","0.12253000"],["77741.97000000","0.00000000"],["77741.99000000","0.00257000"],["78889.86000000","0.00030000"]]}}
{"type":"depth","received_at_ms":1788333189747,"data":{"e":"depthUpdate","E":1788333189914,"s":"BTCUSDT","U":99556330443,"u":99556330451,"b":[["77705.37000000","0.00007000"],["69951.60000000","0.00432000"]],"a":[["77736.47000000","0.00007000"],["77741.99000000","0.00000000"],["77742.00000000","0.03000000"]]}}
{"type":"depth","received_at_ms":1788333189847,"data":{"e":"depthUpdate","E":1788333190014,"s":"BTCUSDT","U":99556330452,"u":99556330465,"b":[["77723.88000000","0.00257000"],["77723.11000000","0.00000000"],["75521.27000000","0.00000000"],["69951.60000000","0.00416000"],["69951.00000000","0.00068000"],["62179.20000000","0.00032000"],["62179.19000000","0.00000000"],["62179.00000000","0.00600000"]],"a":[]}}
{"type":"trade","received_at_ms":1788333189869,"data":{"e":"trade","E":1788333190036,"s":"BTCUSDT","t":6646665983,"p":"77724.00000000","q":"0.00200000","T":1788333190035,"m":false,"M":true}}
{"type":"trade","received_at_ms":1788333189869,"data":{"e":"trade","E":1788333190036,"s":"BTCUSDT","t":6646665984,"p":"77724.00000000","q":"0.00200000","T":1788333190035,"m":false,"M":true}}
{"type":"trade","received_at_ms":1788333189869,"data":{"e":"trade","E":1788333190036,"s":"BTCUSDT","t":6646665985,"p":"77724.00000000","q":"0.00200000","T":1788333190035,"m":false,"M":true}}
{"type":"trade","received_at_ms":1788333189869,"data":{"e":"trade","E":1788333190036,"s":"BTCUSDT","t":6646665986,"p":"77724.00000000","q":"0.00200000","T":1788333190035,"m":false,"M":true}}
{"type":"trade","received_at_ms":1788333189869,"data":{"e":"trade","E":1788333190036,"s":"BTCUSDT","t":6646665987,"p":"77724.00000000","q":"0.00200000","T":1788333190036,"m":false,"M":true}}
{"type":"trade","received_at_ms":1788333189870,"data":{"e":"trade","E":1788333190036,"s":"BTCUSDT","t":6646665988,"p":"77724.00000000","q":"0.00200000","T":1788333190036,"m":false,"M":true}}
{"type":"trade","received_at_ms":1788333189870,"data":{"e":"trade","E":1788333190036,"s":"BTCUSDT","t":6646665989,"p":"77724.00000000","q":"0.00200000","T":1788333190036,"m":false,"M":true}}
{"type":"trade","received_at_ms":1788333189870,"data":{"e":"trade","E":1788333190036,"s":"BTCUSDT","t":6646665990,"p":"77724.00000000","q":"0.00200000","T":1788333190036,"m":false,"M":true}}
{"type":"trade","received_at_ms":1788333189870,"data":{"e":"trade","E":1788333190036,"s":"BTCUSDT","t":6646665991,"p":"77724.00000000","q":"0.00200000","T":1788333190036,"m":false,"M":true}}
{"type":"trade","received_at_ms":1788333189870,"data":{"e":"trade","E":1788333190037,"s":"BTCUSDT","t":6646665992,"p":"77724.00000000","q":"0.00200000","T":1788333190036,"m":false,"M":true}}
{"type":"trade","received_at_ms":1788333189870,"data":{"e":"trade","E":1788333190037,"s":"BTCUSDT","t":6646665993,"p":"77724.00000000","q":"0.00200000","T":1788333190036,"m":false,"M":true}}
{"type":"trade","received_at_ms":1788333189873,"data":{"e":"trade","E":1788333190038,"s":"BTCUSDT","t":6646665994,"p":"77724.00000000","q":"0.00200000","T":1788333190038,"m":false,"M":true}}
{"type":"trade","received_at_ms":1788333189873,"data":{"e":"trade","E":1788333190038,"s":"BTCUSDT","t":6646665995,"p":"77724.00000000","q":"0.00200000","T":1788333190038,"m":false,"M":true}}
{"type":"trade","received_at_ms":1788333189873,"data":{"e":"trade","E":1788333190039,"s":"BTCUSDT","t":6646665996,"p":"77724.00000000","q":"0.00200000","T":1788333190038,"m":false,"M":true}}
{"type":"trade","received_at_ms":1788333189873,"data":{"e":"trade","E":1788333190039,"s":"BTCUSDT","t":6646665997,"p":"77724.00000000","q":"0.02100000","T":1788333190039,"m":false,"M":true}}
{"type":"trade","received_at_ms":1788333189873,"data":{"e":"trade","E":1788333190041,"s":"BTCUSDT","t":6646665998,"p":"77724.00000000","q":"0.02100000","T":1788333190040,"m":false,"M":true}}
{"type":"depth","received_at_ms":1788333189949,"data":{"e":"depthUpdate","E":1788333190115,"s":"BTCUSDT","U":99556330466,"u":99556330490,"b":[["77723.99000000","2.07035000"],["77723.88000000","0.00000000"],["77723.55000000","0.00000000"],["77717.10000000","0.00321000"],["77709.58000000","0.00000000"],["75560.56000000","0.00000000"],["75542.76000000","0.00000000"],["69951.60000000","0.00432000"],["69951.00000000","0.00068000"]],"a":[["77724.00000000","0.39054000"]]}}
{"type":"depth","received_at_ms":1788333190047,"data":{"e":"depthUpdate","E":1788333190214,"s":"BTCUSDT","U":99556330491,"u":99556330499,"b":[["77720.25000000","0.02147000"],["77720.08000000","0.02895000"],["77714.98000000","0.00000000"],["77024.47000000","0.00010000"],["69951.60000000","0.00432000"],["62179.20000000","0.00000000"]],"a":[]}}
{"type":"depth","received_at_ms":1788333190149,"data":{"e":"depthUpdate","E":1788333190314,"s":"BTCUSDT","U":99556330500,"u":99556330513,"b":[["77723.31000000","0.00400000"],["77714.61000000","0.00000000"],["69951.60000000","0.00448000"],["62179.19000000","0.00000000"],["62179.00000000","0.00600000"]],"a":[["77734.20000000","0.00400000"],["77766.77000000","0.00000000"],["77822.53000000","0.00411000"]]}}
{"type":"depth","received_at_ms":1788333190248,"data":{"e":"depthUpdate","E":1788333190414,"s":"BTCUSDT","U":99556330514,"u":99556330521,"b":[["77721.12000000","0.00800000"],["69951.60000000","0.00432000"]],"a":[["77724.00000000","0.39064000"],["77736.49000000","0.01200000"],["77765.85000000","0.00000000"]]}}
{"type":"trade","received_at_ms":1788333190262,"data":{"e":"trade","E":1788333190427,"s":"BTCUSDT","t":6646665999,"p":"77724.00000000","q":"0.00129000","T":1788333190427,"m":false,"M":true}}
{"type":"trade","received_at_ms":1788333190263,"data":{"e":"trade","E":1788333190429,"s":"BTCUSDT","t":6646666000,"p":"77724.00000000","q":"0.00129000","T":1788333190428,"m":false,"M":true}}
{"type":"trade","received_at_ms":1788333190263,"data":{"e":"trade","E":1788333190429,"s":"BTCUSDT","t":6646666001,"p":"77724.00000000","q":"0.00007000","T":1788333190429,"m":false,"M":true}}
{"type":"trade","received_at_ms":1788333190282,"data":{"e":"trade","E":1788333190446,"s":"BTCUSDT","t":6646666002,"p":"77724.00000000","q":"0.02574000","T":1788333190445,"m":false,"M":true}}
{"type":"depth","received_at_ms":1788333190348,"data":{"e":"depthUpdate","E":1788333190514,"s":"BTCUSDT","U":99556330522,"u":99556330540,"b":[["77721.32000000","0.01335000"],["69951.60000000","0.00448000"],["69951.59000000","0.00000000"],["69951.00000000","0.00078000"],["62179.20000000","0.00032000"],["62179.00000000","0.00600000"]],"a":[["77724.00000000","0.36225000"],["77765.55000000","0.00000000"],["77765.72000000","0.00000000"]]}}
{"type":"trade","received_at_ms":1788333190350,"data":{"e":"trade","E":1788333190515,"s":"BTCUSDT","t":6646666003,"p":"77724.00000000","q":"0.00007000","T":1788333190515,"m":false,"M":true}}
{"type":"trade","received_at_ms":1788333190388,"data":{"e":"trade","E":1788333190551,"s":"BTCUSDT","t":6646666004,"p":"77724.00000000","q":"0.00140000","T":1788333190550,"m":false,"M":true}}
{"type":"depth","received_at_ms":1788333190447,"data":{"e":"depthUpdate","E":1788333190614,"s":"BTCUSDT","U":99556330541,"u":99556330554,"b":[["69951.60000000","0.00432000"],["69951.00000000","0.00068000"],["62179.20000000","0.00000000"]],"a":[["77724.00000000","0.36078000"],["77765.69000000","0.00000000"]]}}
{"type":"depth","received_at_ms":1788333190548,"data":{"e":"depthUpdate","E":1788333190714,"s":"BTCUSDT","U":99556330555,"u":99556330559,"b":[["77710.43000000","0.00411000"],["77640.48000000","0.00000000"],["69951.60000000","0.00448000"]],"a":[["77791.43000000","0.00000000"],["77822.53000000","0.00000000"]]}}
{"type":"trade","received_at_ms":1788333190549,"data":{"e":"trade","E":1788333190715,"s":"BTCUSDT","t":6646666005,"p":"77724.00000000","q":"0.00010000","T":1788333190715,"m":false,"M":true}}
{"type":"trade","received_at_ms":1788333190612,"data":{"e":"trade","E":1788333190778,"s":"BTCUSDT","t":6646666006,"p":"77724.00000000","q":"0.00008000","T":1788333190777,"m":false,"M":true}}
{"type":"trade","received_at_ms":1788333190617,"data":{"e":"trade","E":1788333190781,"s":"BTCUSDT","t":6646666007,"p":"77724.00000000","q":"0.02100000","T":1788333190781,"m":false,"M":true}}
{"type":"trade","received_at_ms":1788333190617,"data":{"e":"trade","E":1788333190781,"s":"BTCUSDT","t":6646666008,"p":"77724.00000000","q":"0.02100000","T":1788333190781,"m":false,"M":true}}
{"type":"trade","received_at_ms":1788333190647,"data":{"e":"trade","E":1788333190812,"s":"BTCUSDT","t":6646666009,"p":"77724.00000000","q":"0.02100000","T":1788333190812,"m":false,"M":true}}
{"type":"trade","received_at_ms":1788333190647,"data":{"e":"trade","E":1788333190814,"s":"BTCUSDT","t":6646666010,"p":"77724.00000000","q":"0.00007000","T":1788333190813,"m":false,"M":true}}
{"type":"depth","received_at_ms":1788333190647,"data":{"e":"depthUpdate","E":1788333190814,"s":"BTCUSDT","U":99556330560,"u":99556330574,"b":[["77528.01000000","0.00811000"],["77526.01000000","0.00000000"],["76558.13000000","0.00030000"],["69951.60000000","0.00441000"]],"a":[["77724.00000000","0.29753000"],["78889.86000000","0.00030000"]]}}
{"type":"trade","received_at_ms":1788333190655,"data":{"e":"trade","E":1788333190821,"s":"BTCUSDT","t":6646666011,"p":"77723.99000000","q":"0.01500000","T":1788333190821,"m":true,"M":true}}
{"type":"depth","received_at_ms":1788333190748,"data":{"e":"depthUpdate","E":1788333190915,"s":"BTCUSDT","U":99556330575,"u":99556330588,"b":[["77723.99000000","2.05535000"],["77721.32000000","0.01349000"],["77705.37000000","0.00007000"],["69951.60000000","0.00457000"],["69951.00000000","0.00078000"]],"a":[["77724.00000000","0.29739000"],["77736.47000000","0.00007000"],["77765.80000000","0.01378000"]]}}
{"type":"trade","received_at_ms":1788333190751,"data":{"e":"trade","E":1788333190916,"s":"BTCUSDT","t":6646666012,"p":"77724.00000000","q":"0.00007000","T":1788333190916,"m":false,"M":true}}
{"type":"depth","received_at_ms":1788333190847,"data":{"e":"depthUpdate","E":1788333191014,"s":"BTCUSDT","U":99556330589,"u":99556330633,"b":[["77723.99000000","2.05376000"],["77723.98000000","0.00076000"],["77723.55000000","0.00257000"],["77723.31000000","0.00000000"],["77722.70000000","0.00000000"],["77722.51000000","0.00400000"],["77721.83000000","0.00400000"],["77720.88000000","0.00000000"],["77719.84000000","0.00643000"],["77658.64000000","0.00000000"],["77580.24000000","0.00000000"],["69951.60000000","0.00441000"],["69951.00000000","0.00068000"],["62179.20000000","0.00032000"],["62179.19000000","0.00000000"]],"a":[["77724.00000000","0.63793000"],["77725.23000000","0.00014000"],["77742.14000000","0.00257000"]]}}
{"type":"trade","received_at_ms":1788333190887,"data":{"e":"trade","E":1788333191052,"s":"BTCUSDT","t":6646666013,"p":"77724.00000000","q":"0.01585000","T":1788333191051,"m":false,"M":true}}
{"type":"trade","received_at_ms":1788333190887,"data":{"e":"trade","E":1788333191052,"s":"BTCUSDT","t":6646666014,"p":"77724.00000000","q":"0.00415000","T":1788333191051,"m":false,"M":true}}
{"type":"trade","received_at_ms":1788333190887,"data":{"e":"trade","E":1788333191052,"s":"BTCUSDT","t":6646666015,"p":"77724.00000000","q":"0.02100000","T":1788333191052,"m":false,"M":true}}
{"type":"trade","received_at_ms":1788333190945,"data":{"e":"trade","E":1788333191112,"s":"BTCUSDT","t":6646666016,"p":"77724.00000000","q":"0.00008000","T":1788333191111,"m":false,"M":true}}
{"type":"depth","received_at_ms":1788333190946,"data":{"e":"depthUpdate","E":1788333191114,"s":"BTCUSDT","U":99556330634,"u":99556330848,"b":[["77723.99000000","3.98632000"],["77723.98000000","0.00076000"],["77723.79000000","0.00400000"],["77723.55000000","0.00000000"],["77723.22000000","0.00000000"],["77723.05000000","0.00400000"],["77722.51000000","0.00000000"],["77721.83000000","0.00000000"],["77721.32000000","0.01342000"],["77721.13000000","0.00800000"],["77721.12000000","0.00000000"],["77721.11000000","0.00000000"],["77720.08000000","0.02902000"],["77714.29000000","0.03217000"],["77712.31000000","0.62746000"],["77658.64000000","0.00321000"],["77580.24000000","0.00128000"],["69951.60000000","0.00448000"],["69951.59000000","0.00009000"]],"a":[["77724.00000000","0.54673000"],["77724.01000000","0.00097000"],["77725.22000000","0.00000000"],["77725.23000000","0.00000000"],["77727.99000000","0.00007000"],["77729.59000000","0.00000000"],["77731.99000000","0.19248000"],["77732.26000000","0.00007000"],["77732.65000000","0.00000000"],["77732.90000000","0.00000000"],["77733.44000000","0.00000000"],["77733.45000000","0.00000000"],["77733.58000000","0.00000000"],["77734.20000000","0.00000000"],["77734.21000000","0.00000000"],["77734.22000000","0.00007000"],["77734.33000000","0.00400000"],["77734.82000000","0.00400000"],["77736.20000000","0.00007000"],["77736.32000000","1.14194000"],["77736.47000000","0.11198000"],["77736.48000000","1.95253000"],["77736.49000000","1.31471000"],["77736.50000000","0.00000000"],["77736.51000000","0.00000000"],["77736.55000000","0.00000000"],["77736.62000000","0.00000000"],["77739.07000000","0.00000000"],["77740.14000000","0.00007000"],["77740.44000000","0.00000000"],["77740.67000000","0.00000000"],["77740.68000000","0.82251000"],["77741.33000000","0.09622000"],["77741.34000000","1.93226000"],["77741.35000000","1.31471000"],["77742.14000000","0.00000000"],["77744.08000000","0.00007000"],["77748.02000000","0.00007000"],["77751.96000000","0.00007000"],["77755.90000000","0.00071000"],["77791.42000000","0.00411000"],["77821.72000000","0.00000000"],["77824.31000000","4.08551000"]]}}
{"type":"depth","received_at_ms":1788333191047,"data":{"e":"depthUpdate","E":1788333191214,"s":"BTCUSDT","U":99556330849,"u":99556330889,"b":[["77723.99000000","2.05427000"],["77723.98000000","0.00083000"],["77723.79000000","0.00000000"],["77723.05000000","0.00000000"],["77722.78000000","0.00400000"],["77722.11000000","0.00400000"],["77721.32000000","0.01321000"],["77721.13000000","0.00000000"],["77719.43000000","0.00800000"],["77714.29000000","0.00007000"],["69951.60000000","0.00432000"],["62179.20000000","0.00000000"],["62179.00000000","0.00600000"]],"a":[["77724.00000000","0.54823000"],["77729.46000000","0.10092000"],["77729.59000000","0.14290000"],["77732.26000000","0.00014000"],["77736.20000000","0.00014000"],["77736.32000000","0.99134000"],["77736.47000000","0.00007000"],["77740.14000000","0.00014000"],["77742.16000000","0.00257000"],["77744.08000000","0.00014000"],["77748.02000000","0.00014000"],["77751.96000000","0.00014000"],["77755.90000000","0.00078000"],["77765.53000000","0.00000000"]]}}
{"type":"depth","received_at_ms":1788333191148,"data":{"e":"depthUpdate","E":1788333191314,"s":"BTCUSDT","U":99556330890,"u":99556330914,"b":[["77723.99000000","2.05420000"],["77722.80000000","0.00400000"],["77722.78000000","0.00000000"],["77722.34000000","0.00400000"],["77722.11000000","0.00000000"],["77721.11000000","0.00800000"],["77719.43000000","0.00000000"],["69951.60000000","0.00432000"]],"a":[["77729.46000000","0.10092000"],["77742.16000000","0.00000000"],["77742.17000000","0.00257000"]]}}
{"type":"depth","received_at_ms":1788333191248,"data":{"e":"depthUpdate","E":1788333191414,"s":"BTCUSDT","U":99556330915,"u":99556330922,"b":[["77723.99000000","2.05427000"],["77721.32000000","0.01328000"],["69951.60000000","0.00432000"],["62179.19000000","0.00000000"],["62179.00000000","0.00600000"]],"a":[]}}
{"type":"depth","received_at_ms":1788333191347,"data":{"e":"depthUpdate","E":1788333191514,"s":"BTCUSDT","U":99556330923,"u":99556330940,"b":[["77723.99000000","2.05420000"],["77723.98000000","0.00076000"],["69951.60000000","0.00432000"],["62179.20000000","0.00032000"]],"a":[["77724.00000000","0.54830000"],["77727.30000000","0.00335000"],["77727.31000000","0.12976000"],["77727.99000000","0.00000000"],["77821.72000000","2.15325000"],["77824.31000000","1.93226000"]]}}
{"type":"depth","received_at_ms":1788333191448,"data":{"e":"depthUpdate","E":1788333191614,"s":"BTCUSDT","U":99556330941,"u":99556330975,"b":[["77658.64000000","0.00321000"],["77648.13000000","0.00401000"],["77642.87000000","0.00000000"],["77580.24000000","0.00128000"],["69951.60000000","0.00416000"],["62179.20000000","0.00000000"],["62179.00000000","0.00600000"]],"a":[["77724.00000000","0.54830000"],["77724.01000000","0.00104000"],["77725.51000000","0.00014000"],["77725.52000000","0.14026000"],["77726.74000000","0.11205000"],["77727.30000000","0.00321000"],["77727.31000000","0.00014000"],["77729.46000000","0.10078000"],["77765.49000000","0.00000000"]]}}
{"type":"depth","received_at_ms":1788333191548,"data":{"e":"depthUpdate","E":1788333191714,"s":"BTCUSDT","U":99556330976,"u":99556330995,"b":[["77723.99000000","2.05427000"],["75637.53000000","0.00000000"],["75569.87000000","0.00000000"],["69951.60000000","0.00432000"],["69951.00000000","0.00068000"]],"a":[["77725.37000000","0.11205000"],["77725.52000000","0.14040000"],["77726.74000000","0.11205000"],["77727.31000000","0.00000000"]]}}
{"type":"depth","received_at_ms":1788333191648,"data":{"e":"depthUpdate","E":1788333191814,"s":"BTCUSDT","U":99556330996,"u":99556331004,"b":[["77714.32000000","0.10845000"],["76558.13000000","0.00030000"],["75644.30000000","0.00000000"],["69951.60000000","0.00448000"]],"a":[["78889.86000000","0.00030000"]]}}
{"type":"depth","received_at_ms":1788333191747,"data":{"e":"depthUpdate","E":1788333191914,"s":"BTCUSDT","U":99556331005,"u":99556331035,"b":[["77723.99000000","2.05420000"],["77705.37000000","0.00007000"],["75657.02000000","0.00000000"],["69951.60000000","0.00432000"]],"a":[["77724.00000000","0.54680000"],["77733.38000000","0.00400000"],["77733.90000000","0.00400000"],["77733.91000000","0.00000000"],["77734.33000000","0.00000000"],["77734.82000000","0.00000000"],["77736.31000000","0.01200000"],["77736.47000000","0.00007000"],["77736.48000000","1.94053000"],["77739.54000000","0.04771000"],["77742.17000000","0.00000000"],["77742.18000000","0.00257000"],["77747.18000000","0.00000000"],["77747.84000000","0.00128000"],["77749.92000000","0.00000000"],["77848.26000000","0.00000000"],["77857.46000000","0.00108000"]]}}
{"type":"trade","received_at_ms":1788333191813,"data":{"e":"trade","E":1788333191979,"s":"BTCUSDT","t":6646666017,"p":"77723.99000000","q":"0.00006000","T":1788333191978,"m":true,"M":true}}
{"type":"depth","received_at_ms":1788333191848,"data":{"e":"depthUpdate","E":1788333192014,"s":"BTCUSDT","U":99556331036,"u":99556331049,"b":[["77723.99000000","2.05157000"],["77723.55000000","0.00257000"],["77721.32000000","0.01342000"],["77721.12000000","0.62745000"],["77712.31000000","0.00000000"],["69951.60000000","0.00448000"],["69951.59000000","0.00000000"],["62179.20000000","0.00032000"],["62179.19000000","0.00000000"]],"a":[["77724.00000000","0.54816000"],["77736.30000000","0.09622000"],["77741.33000000","0.00000000"]]}}
{"type":"depth","received_at_ms":1788333191952,"data":{"e":"depthUpdate","E":1788333192114,"s":"BTCUSDT","U":99556331050,"u":99556331067,"b":[["77723.99000000","2.05157000"],["77723.98000000","0.00083000"],["77721.32000000","0.01349000"],["75672.62000000","0.00000000"],["69951.60000000","0.00432000"]],"a":[["77724.00000000","0.54666000"],["77756.15000000","0.00000000"],["77822.52000000","0.00411000"],["85496.39000000","0.00000000"]]}}
{"type":"depth","received_at_ms":1788333192047,"data":{"e":"depthUpdate","E":1788333192214,"s":"BTCUSDT","U":99556331068,"u":99556331073,"b":[["69951.60000000","0.00448000"],["62179.20000000","0.00000000"]],"a":[["77756.32000000","0.00000000"]]}}
{"type":"depth","received_at_ms":1788333192147,"data":{"e":"depthUpdate","E":1788333192314,"s":"BTCUSDT","U":99556331074,"u":99556331099,"b":[["77723.99000000","2.05370000"],["77722.80000000","0.00000000"],["77722.34000000","0.00000000"],["77722.12000000","0.00000000"],["77721.32000000","0.01342000"],["77721.13000000","0.00000000"],["77721.11000000","0.00000000"],["69951.60000000","0.00432000"],["62179.00000000","0.00600000"]],"a":[["77724.00000000","0.54666000"],["77732.82000000","0.08205000"],["77733.22000000","0.00206000"]]}}
{"type":"depth","received_at_ms":1788333192246,"data":{"e":"depthUpdate","E":1788333192414,"s":"BTCUSDT","U":99556331100,"u":99556331118,"b":[["77723.99000000","2.05363000"],["77723.98000000","0.00076000"],["77722.13000000","0.00400000"],["77721.32000000","0.01349000"],["77721.13000000","0.00800000"],["77549.33000000","0.00672000"],["77525.12000000","0.00000000"],["69951.60000000","0.00448000"],["62179.19000000","0.00000000"],["62179.00000000","0.00600000"]],"a":[["77724.00000000","0.54666000"]]}}
{"type":"depth","received_at_ms":1788333192354,"data":{"e":"depthUpdate","E":1788333192514,"s":"BTCUSDT","U":99556331119,"u":99556331128,"b":[["77723.99000000","2.05370000"],["77721.32000000","0.01349000"],["75694.15000000","0.00000000"],["69951.60000000","0.00432000"],["62179.20000000","0.00032000"]],"a":[]}}
{"type":"depth","received_at_ms":1788333192448,"data":{"e":"depthUpdate","E":1788333192614,"s":"BTCUSDT","U":99556331129,"u":99556331140,"b":[["77723.99000000","2.05363000"],["75789.11000000","0.00000000"],["75721.32000000","0.00000000"],["75711.99000000","0.00000000"],["69951.60000000","0.00448000"],["62179.20000000","0.00000000"],["62179.00000000","0.00600000"]],"a":[["77736.29000000","0.11191000"],["77736.33000000","0.00000000"],["77742.18000000","0.00000000"],["77742.19000000","0.00257000"]]}}
{"type":"depth","received_at_ms":1788333192547,"data":{"e":"depthUpdate","E":1788333192714,"s":"BTCUSDT","U":99556331141,"u":99556331150,"b":[["77723.99000000","2.05356000"],["77710.43000000","0.00000000"],["77640.48000000","0.00411000"],["69951.60000000","0.00448000"]],"a":[["77756.66000000","0.12871000"],["77791.42000000","0.00000000"],["77822.52000000","0.00000000"]]}}
{"type":"depth","received_at_ms":1788333192647,"data":{"e":"depthUpdate","E":1788333192814,"s":"BTCUSDT","U":99556331151,"u":99556331159,"b":[["76558.13000000","0.00030000"],["75795.90000000","0.00000000"],["69951.60000000","0.00464000"],["69951.00000000","0.00088000"]],"a":[["78889.86000000","0.00030000"]]}}
{"type":"depth","received_at_ms":1788333192747,"data":{"e":"depthUpdate","E":1788333192914,"s":"BTCUSDT","U":99556331160,"u":99556331168,"b":[["77705.37000000","0.00000000"],["75824.27000000","0.00000000"],["75808.64000000","0.00000000"],["69951.60000000","0.00432000"],["69951.00000000","0.00068000"]],"a":[["77724.00000000","0.64429000"],["77736.47000000","0.00000000"],["77791.44000000","0.00411000"]]}}
{"type":"depth","received_at_ms":1788333192849,"data":{"e":"depthUpdate","E":1788333193015,"s":"BTCUSDT","U":99556331169,"u":99556331185,"b":[["77723.99000000","2.05370000"],["77705.37000000","0.00007000"],["75873.07000000","0.00010000"],["75863.72000000","0.00000000"],["75845.85000000","0.00029000"],["69951.60000000","0.00448000"],["62179.20000000","0.00032000"],["62179.19000000","0.00000000"],["62179.00000000","0.00600000"]],"a":[["77724.00000000","0.64587000"],["77736.47000000","0.00007000"]]}}
{"type":"depth","received_at_ms":1788333192947,"data":{"e":"depthUpdate","E":1788333193114,"s":"BTCUSDT","U":99556331186,"u":99556331201,"b":[["77723.99000000","2.05363000"],["77723.98000000","0.00076000"],["77723.55000000","0.00000000"],["77723.11000000","0.00257000"],["77710.44000000","0.00411000"],["77631.01000000","0.00000000"],["75941.00000000","0.00000000"],["75557.14000000","0.00000000"],["69951.60000000","0.00448000"]],"a":[["77724.00000000","0.64587000"],["77775.97000000","0.00000000"],["81001.14000000","0.00000000"]]}}
{"type":"trade","received_at_ms":1788333193036,"data":{"e":"trade","E":1788333193200,"s":"BTCUSDT","t":6646666018,"p":"77724.00000000","q":"0.00010000","T":1788333193199,"m":false,"M":true}}
{"type":"depth","received_at_ms":1788333193047,"data":{"e":"depthUpdate","E":1788333193214,"s":"BTCUSDT","U":99556331202,"u":99556331208,"b":[["71506.08000000","0.00014000"],["69951.60000000","0.00441000"],["62179.20000000","0.00000000"]],"a":[["77724.00000000","0.64577000"]]}}
{"type":"depth","received_at_ms":1788333193147,"data":{"e":"depthUpdate","E":1788333193314,"s":"BTCUSDT","U":99556331209,"u":99556331216,"b":[["77710.44000000","0.00000000"],["77640.48000000","0.00000000"],["69951.60000000","0.00473000"]],"a":[["77742.19000000","0.00000000"],["77742.20000000","0.00257000"],["77791.44000000","0.00000000"],["77822.54000000","0.00411000"]]}}
{"type":"trade","received_at_ms":1788333193242,"data":{"e":"trade","E":1788333193398,"s":"BTCUSDT","t":6646666019,"p":"77724.00000000","q":"0.01500000","T":1788333193398,"m":false,"M":true}}
{"type":"depth","received_at_ms":1788333193250,"data":{"e":"depthUpdate","E":1788333193414,"s":"BTCUSDT","U":99556331217,"u":99556331226,"b":[["75976.23000000","0.00000000"],["75960.57000000","0.00000000"],["75947.80000000","0.00000000"],["69951.60000000","0.00457000"],["62179.19000000","0.00000000"]],"a":[["77724.00000000","0.62927000"]]}}
{"type":"depth","received_at_ms":1788333193347,"data":{"e":"depthUpdate","E":1788333193514,"s":"BTCUSDT","U":99556331227,"u":99556331237,"b":[["77723.99000000","2.05356000"],["75997.85000000","0.00000000"],["69951.60000000","0.00473000"],["65146.32000000","0.00000000"],["62179.20000000","0.00032000"],["62179.00000000","0.00800000"]],"a":[["77756.66000000","0.00000000"]]}}
{"type":"depth","received_at_ms":1788333193448,"data":{"e":"depthUpdate","E":1788333193614,"s":"BTCUSDT","U":99556331238,"u":99556331244,"b":[["77723.99000000","2.05349000"],["76015.76000000","0.00000000"],["69951.60000000","0.00457000"],["62179.20000000","0.00000000"]],"a":[["77742.20000000","0.00000000"]]}}
{"type":"depth","received_at_ms":1788333193547,"data":{"e":"depthUpdate","E":1788333193714,"s":"BTCUSDT","U":99556331245,"u":99556331249,"b":[["76025.13000000","0.00000000"],["71506.08000000","0.00000000"],["69951.60000000","0.00473000"]],"a":[]}}
{"type":"trade","received_at_ms":1788333193643,"data":{"e":"trade","E":1788333193810,"s":"BTCUSDT","t":6646666020,"p":"77723.99000000","q":"0.00613000","T":1788333193810,"m":true,"M":true}}
{"type":"depth","received_at_ms":1788333193651,"data":{"e":"depthUpdate","E":1788333193814,"s":"BTCUSDT","U":99556331250,"u":99556331260,"b":[["77723.99000000","2.04736000"],["76558.13000000","0.00030000"],["76093.19000000","0.00000000"],["69951.60000000","0.00448000"],["69951.59000000","0.00009000"]],"a":[["77724.00000000","0.63077000"],["78889.86000000","0.00030000"]]}}
{"type":"depth","received_at_ms":1788333193747,"data":{"e":"depthUpdate","E":1788333193914,"s":"BTCUSDT","U":99556331261,"u":99556331268,"b":[["77723.99000000","2.04743000"],["76100.01000000","0.00000000"],["75557.14000000","0.00010000"],["69951.60000000","0.00464000"],["69951.00000000","0.00068000"]],"a":[["77756.20000000","0.00000000"]]}}
{"type":"depth","received_at_ms":1788333193848,"data":{"e":"depthUpdate","E":1788333194014,"s":"BTCUSDT","U":99556331269,"u":99556331283,"b":[["77705.37000000","0.00007000"],["76112.80000000","0.00000000"],["69951.60000000","0.00448000"],["62179.20000000","0.00032000"],["62179.19000000","0.00000000"]],"a":[["77736.47000000","0.00007000"],["77756.08000000","0.00000000"],["77756.25000000","0.00400000"],["77756.28000000","0.12871000"]]}}
{"type":"depth","received_at_ms":1788333193950,"data":{"e":"depthUpdate","E":1788333194114,"s":"BTCUSDT","U":99556331284,"u":99556331292,"b":[["77723.99000000","2.04729000"],["77640.49000000","0.00411000"],["69951.60000000","0.00464000"]],"a":[["77756.28000000","0.00000000"],["77756.96000000","0.12871000"],["77767.72000000","0.00007000"]]}}
{"type":"depth","received_at_ms":1788333194046,"data":{"e":"depthUpdate","E":1788333194214,"s":"BTCUSDT","U":99556331293,"u":99556331299,"b":[["77723.99000000","2.04743000"],["77715.39000000","0.00269000"],["69951.60000000","0.00448000"],["62179.20000000","0.00000000"]],"a":[["77859.39000000","0.00093000"],["81001.14000000","0.00010000"]]}}
{"type":"depth","received_at_ms":1788333194147,"data":{"e":"depthUpdate","E":1788333194314,"s":"BTCUSDT","U":99556331300,"u":99556331309,"b":[["77710.43000000","0.00411000"],["76128.49000000","0.00000000"],["69951.60000000","0.00464000"],["65146.32000000","0.01188000"],["62179.00000000","0.00800000"]],"a":[]}}
{"type":"depth","received_at_ms":1788333194247,"data":{"e":"depthUpdate","E":1788333194414,"s":"BTCUSDT","U":99556331310,"u":99556331316,"b":[["69951.60000000","0.00448000"],["62179.19000000","0.00000000"]],"a":[["77747.18000000","0.00128000"],["77747.84000000","0.00000000"]]}}
{"type":"trade","received_at_ms":1788333194259,"data":{"e":"trade","E":1788333194425,"s":"BTCUSDT","t":6646666021,"p":"77723.99000000","q":"0.00475000","T":1788333194425,"m":true,"M":true}}
{"type":"trade","received_at_ms":1788333194260,"data":{"e":"trade","E":1788333194425,"s":"BTCUSDT","t":6646666022,"p":"77723.99000000","q":"0.01025000","T":1788333194425,"m":true,"M":true}}
{"type":"depth","received_at_ms":1788333194347,"data":{"e":"depthUpdate","E":1788333194514,"s":"BTCUSDT","U":99556331317,"u":99556331332,"b":[["77723.99000000","2.22408000"],["77721.32000000","0.01342000"],["77721.13000000","0.00807000"],["77721.12000000","0.62747000"],["77721.11000000","0.00000000"],["77710.48000000","0.00000000"],["69951.60000000","0.00448000"],["69951.59000000","0.00000000"],["62179.20000000","0.00032000"]],"a":[]}}
{"type":"depth","received_at_ms":1788333194447,"data":{"e":"depthUpdate","E":1788333194614,"s":"BTCUSDT","U":99556331333,"u":99556331345,"b":[["77723.99000000","2.22408000"],["77721.13000000","0.00800000"],["77721.12000000","0.00000000"],["77710.48000000","0.62747000"],["69951.60000000","0.00448000"],["62179.20000000","0.00000000"],["62179.00000000","0.00800000"]],"a":[["77724.00000000","0.62927000"],["77746.23000000","0.37338000"]]}}
{"type":"trade","received_at_ms":1788333194454,"data":{"e":"trade","E":1788333194622,"s":"BTCUSDT","t":6646666023,"p":"77723.99000000","q":"0.00258000","T":1788333194621,"m":true,"M":true}}
{"type":"depth","received_at_ms":1788333194547,"data":{"e":"depthUpdate","E":1788333194714,"s":"BTCUSDT","U":99556331346,"u":99556331365,"b":[["77723.99000000","2.22165000"],["77722.13000000","0.00000000"],["77722.07000000","0.00400000"],["77721.32000000","0.01342000"],["77721.13000000","0.00000000"],["77721.11000000","0.00800000"],["76150.16000000","0.00000000"],["69951.60000000","0.00448000"]],"a":[["77724.00000000","0.63077000"],["77742.38000000","0.00257000"]]}}
{"type":"depth","received_at_ms":1788333194647,"data":{"e":"depthUpdate","E":1788333194814,"s":"BTCUSDT","U":99556331366,"u":99556331377,"b":[["77723.99000000","2.22151000"],["77721.32000000","0.01342000"],["76558.13000000","0.00030000"],["69951.60000000","0.00448000"]],"a":[["77742.38000000","0.00000000"],["77742.39000000","0.00257000"]]}}
{"type":"depth","received_at_ms":1788333194747,"data":{"e":"depthUpdate","E":1788333194914,"s":"BTCUSDT","U":99556331378,"u":99556331383,"b":[["77721.12000000","0.00200000"],["77719.41000000","1.93626000"],["69951.60000000","0.00448000"]],"a":[["78889.86000000","0.00030000"]]}}
{"type":"depth","received_at_ms":1788333194848,"data":{"e":"depthUpdate","E":1788333195014,"s":"BTCUSDT","U":99556331384,"u":99556331397,"b":[["77721.12000000","0.62947000"],["77710.48000000","0.00000000"],["77705.37000000","0.00007000"],["69951.60000000","0.00464000"],["69951.00000000","0.00068000"],["62179.20000000","0.00032000"],["62179.19000000","0.00000000"]],"a":[["77736.47000000","0.00007000"]]}}
{"type":"depth","received_at_ms":1788333194947,"data":{"e":"depthUpdate","E":1788333195114,"s":"BTCUSDT","U":99556331398,"u":99556331411,"b":[["77721.32000000","0.01349000"],["77710.43000000","0.00000000"],["76168.10000000","0.00000000"],["69951.60000000","0.00432000"],["69951.00000000","0.00078000"]],"a":[["77724.00000000","0.63077000"],["77791.43000000","0.00411000"],["77822.54000000","0.00000000"]]}}
{"type":"depth","received_at_ms":1788333195048,"data":{"e":"depthUpdate","E":1788333195214,"s":"BTCUSDT","U":99556331412,"u":99556331420,"b":[["69951.60000000","0.00464000"],["69951.00000000","0.00068000"],["62179.20000000","0.00000000"]],"a":[["77732.82000000","0.00000000"],["77733.22000000","0.00000000"],["77742.39000000","0.00000000"],["77744.36000000","0.00257000"]]}}
{"type":"trade","received_at_ms":1788333195134,"data":{"e":"trade","E":1788333195299,"s":"BTCUSDT","t":6646666024,"p":"77724.00000000","q":"0.00130000","T":1788333195299,"m":false,"M":true}}
{"type":"depth","received_at_ms":1788333195146,"data":{"e":"depthUpdate","E":1788333195314,"s":"BTCUSDT","U":99556331421,"u":99556331428,"b":[["77710.42000000","0.00411000"],["76177.49000000","0.00000000"],["69951.60000000","0.00457000"]],"a":[["77724.00000000","0.62797000"]]}}
{"type":"depth","received_at_ms":1788333195248,"data":{"e":"depthUpdate","E":1788333195415,"s":"BTCUSDT","U":99556331429,"u":99556331440,"b":[["77723.99000000","2.21945000"],["77723.11000000","0.00000000"],["77722.77000000","0.00257000"],["77722.76000000","0.00014000"],["77722.00000000","0.00643000"],["77721.13000000","0.62746000"],["77721.12000000","0.00200000"],["77710.48000000","0.00000000"],["76281.06000000","0.00000000"],["76265.34000000","0.00000000"],["69951.60000000","0.00473000"],["62179.19000000","0.00000000"]],"a":[]}}
{"type":"depth","received_at_ms":1788333195346,"data":{"e":"depthUpdate","E":1788333195514,"s":"BTCUSDT","U":99556331441,"u":99556331490,"b":[["77723.99000000","2.21938000"],["77723.98000000","0.00076000"],["77723.90000000","0.05014000"],["77722.76000000","0.00000000"],["77722.65000000","0.33061000"],["77722.64000000","0.37359000"],["77722.00000000","0.00657000"],["77721.32000000","0.01363000"],["77721.25000000","0.00000000"],["77721.16000000","0.62746000"],["77721.15000000","0.00400000"],["77721.14000000","0.00000000"],["77721.13000000","0.00000000"],["77721.10000000","0.00000000"],["77719.34000000","0.35386000"],["77710.48000000","0.00000000"],["77710.42000000","0.00000000"],["69951.60000000","0.00457000"],["69951.00000000","0.00078000"],["62179.20000000","0.00032000"]],"a":[["77724.00000000","0.62947000"],["77791.43000000","0.00000000"],["77822.52000000","0.00411000"]]}}
{"type":"depth","received_at_ms":1788333195448,"data":{"e":"depthUpdate","E":1788333195614,"s":"BTCUSDT","U":99556331491,"u":99556331516,"b":[["77721.32000000","0.01342000"],["77721.12000000","0.00000000"],["77721.11000000","0.00000000"],["77719.43000000","0.01000000"],["69951.60000000","0.00473000"],["69951.00000000","0.00068000"],["62179.20000000","0.00000000"],["62179.00000000","0.01000000"]],"a":[["77744.36000000","0.00000000"],["77744.37000000","0.00257000"]]}}
{"type":"depth","received_at_ms":1788333195547,"data":{"e":"depthUpdate","E":1788333195714,"s":"BTCUSDT","U":99556331517,"u":99556331528,"b":[["77601.79000000","0.00000000"],["76302.77000000","0.00000000"],["69951.60000000","0.00457000"],["62179.00000000","0.00800000"]],"a":[["77724.68000000","0.00014000"],["77724.69000000","0.12408000"],["77725.51000000","0.00000000"],["77725.52000000","0.00014000"]]}}
{"type":"depth","received_at_ms":1788333195648,"data":{"e":"depthUpdate","E":1788333195815,"s":"BTCUSDT","U":99556331529,"u":99556331539,"b":[["69951.60000000","0.00473000"]],"a":[["77724.00000000","0.62961000"],["77724.69000000","0.12422000"],["77725.37000000","0.11191000"],["77725.52000000","0.00000000"],["77744.36000000","0.00257000"],["77744.37000000","0.00000000"]]}}
{"type":"depth","received_at_ms":1788333195748,"data":{"e":"depthUpdate","E":1788333195914,"s":"BTCUSDT","U":99556331540,"u":99556331551,"b":[["77723.99000000","2.21952000"],["77528.01000000","0.00000000"],["77526.01000000","0.00811000"],["76558.13000000","0.00030000"],["69951.60000000","0.00457000"],["69951.00000000","0.00078000"]],"a":[["77744.36000000","0.00000000"],["78889.86000000","0.00030000"]]}}
{"type":"trade","received_at_ms":1788333195767,"data":{"e":"trade","E":1788333195932,"s":"BTCUSDT","t":6646666025,"p":"77724.00000000","q":"0.00013000","T":1788333195932,"m":false,"M":true}}
{"type":"trade","received_at_ms":1788333195814,"data":{"e":"trade","E":1788333195982,"s":"BTCUSDT","t":6646666026,"p":"77724.00000000","q":"0.00006000","T":1788333195981,"m":false,"M":true}}
{"type":"depth","received_at_ms":1788333195850,"data":{"e":"depthUpdate","E":1788333196016,"s":"BTCUSDT","U":99556331552,"u":99556331578,"b":[["77723.99000000","2.21938000"],["77705.37000000","0.00000000"],["76320.75000000","0.00000000"],["69951.60000000","0.00448000"],["69951.59000000","0.00009000"],["69951.00000000","0.00078000"],["62179.20000000","0.00032000"],["62179.19000000","0.00000000"],["62179.00000000","0.00800000"]],"a":[["77724.00000000","0.62942000"],["77724.01000000","0.00104000"],["77736.47000000","0.00000000"],["77744.33000000","0.00257000"],["77744.35000000","0.00000000"]]}}
{"type":"depth","received_at_ms":1788333195949,"data":{"e":"depthUpdate","E":1788333196114,"s":"BTCUSDT","U":99556331579,"u":99556331593,"b":[["77723.99000000","2.24116000"],["77723.98000000","0.00055000"],["77705.37000000","0.00007000"],["76330.16000000","0.00000000"],["69951.60000000","0.00432000"],["69951.00000000","0.00068000"]],"a":[["77736.47000000","0.00007000"],["77744.33000000","0.00000000"],["77791.35000000","0.00411000"]]}}
{"type":"depth","received_at_ms":1788333196047,"data":{"e":"depthUpdate","E":1788333196214,"s":"BTCUSDT","U":99556331594,"u":99556331607,"b":[["77568.54000000","0.02723000"],["69951.60000000","0.00432000"],["69951.00000000","0.00088000"],["62179.20000000","0.00000000"]],"a":[["77724.00000000","0.62792000"],["77744.32000000","0.00257000"],["77756.57000000","0.00000000"],["77756.81000000","0.00000000"],["77756.96000000","0.00000000"]]}}
{"type":"depth","received_at_ms":1788333196148,"data":{"e":"depthUpdate","E":1788333196314,"s":"BTCUSDT","U":99556331608,"u":99556331618,"b":[["77413.40000000","0.03363000"],["69951.60000000","0.00448000"],["69951.00000000","0.00068000"],["62179.00000000","0.00800000"]],"a":[["77744.30000000","0.00257000"],["77744.32000000","0.00000000"]]}}
{"type":"depth","received_at_ms":1788333196248,"data":{"e":"depthUpdate","E":1788333196414,"s":"BTCUSDT","U":99556331619,"u":99556331631,"b":[["77258.57000000","0.04152000"],["69951.60000000","0.00416000"],["62179.19000000","0.00000000"]],"a":[["77724.00000000","0.62785000"],["77724.01000000","0.00097000"],["77724.68000000","0.00000000"],["77724.69000000","0.00014000"],["77727.99000000","0.00007000"],["77744.29000000","0.00257000"],["77744.30000000","0.00000000"]]}}
{"type":"trade","received_at_ms":1788333196339,"data":{"e":"trade","E":1788333196506,"s":"BTCUSDT","t":6646666027,"p":"77724.00000000","q":"0.00010000","T":1788333196506,"m":false,"M":true}}
{"type":"depth","received_at_ms":1788333196347,"data":{"e":"depthUpdate","E":1788333196514,"s":"BTCUSDT","U":99556331632,"u":99556331647,"b":[["77104.05000000","0.05126000"],["76949.84000000","0.06329000"],["69951.60000000","0.00448000"],["69951.59000000","0.00000000"],["62179.20000000","0.00032000"],["62179.00000000","0.00800000"]],"a":[["77724.00000000","0.62775000"],["77724.69000000","0.00000000"],["77725.37000000","0.11205000"],["77744.28000000","0.00257000"],["77744.29000000","0.00000000"],["77757.43000000","0.12871000"]]}}
{"type":"depth","received_at_ms":1788333196450,"data":{"e":"depthUpdate","E":1788333196616,"s":"BTCUSDT","U":99556331648,"u":99556331654,"b":[["76795.94000000","0.07815000"],["69951.60000000","0.00432000"],["62179.20000000","0.00000000"]],"a":[["77744.26000000","0.00477000"],["77744.28000000","0.00000000"]]}}
{"type":"depth","received_at_ms":1788333196548,"data":{"e":"depthUpdate","E":1788333196715,"s":"BTCUSDT","U":99556331655,"u":99556331684,"b":[["77723.99000000","2.24081000"],["77723.98000000","0.00027000"],["77710.35000000","0.00411000"],["69951.60000000","0.00416000"],["62179.00000000","0.00800000"]],"a":[["77724.00000000","0.62782000"],["77724.01000000","0.00104000"],["77727.06000000","0.00014000"],["77727.07000000","0.13221000"],["77727.99000000","0.00000000"],["77744.25000000","0.00284000"],["77744.26000000","0.00220000"],["77757.43000000","0.00000000"],["77761.39000000","0.32943000"],["77770.37000000","0.00000000"],["77791.35000000","0.00000000"],["77822.52000000","0.00000000"]]}}
{"type":"trade","received_at_ms":1788333196634,"data":{"e":"trade","E":1788333196800,"s":"BTCUSDT","t":6646666028,"p":"77723.99000000","q":"0.00031000","T":1788333196800,"m":true,"M":true}}
{"type":"depth","received_at_ms":1788333196647,"data":{"e":"depthUpdate","E":1788333196814,"s":"BTCUSDT","U":99556331685,"u":99556331699,"b":[["77723.99000000","2.24050000"],["69951.60000000","0.00416000"],["69951.59000000","0.00009000"]],"a":[["77724.00000000","0.62768000"],["77726.74000000","0.11205000"],["77727.07000000","0.13235000"],["77744.24000000","0.00000000"],["77744.25000000","0.00027000"]]}}
{"type":"trade","received_at_ms":1788333196713,"data":{"e":"trade","E":1788333196880,"s":"BTCUSDT","t":6646666029,"p":"77724.00000000","q":"0.00014000","T":1788333196880,"m":false,"M":true}}
{"type":"depth","received_at_ms":1788333196747,"data":{"e":"depthUpdate","E":1788333196914,"s":"BTCUSDT","U":99556331700,"u":99556331718,"b":[["77723.99000000","2.24248000"],["76642.34000000","0.09648000"],["76558.13000000","0.00030000"],["76489.05000000","0.11913000"],["69951.60000000","0.00432000"]],"a":[["77724.00000000","0.62754000"],["77732.68000000","0.08205000"],["77733.03000000","0.00206000"],["77742.10000000","0.00000000"],["77822.54000000","0.00411000"],["78889.86000000","0.00030000"]]}}
{"type":"trade","received_at_ms":1788333196790,"data":{"e":"trade","E":1788333196956,"s":"BTCUSDT","t":6646666030,"p":"77724.00000000","q":"0.00129000","T":1788333196956,"m":false,"M":true}}
{"type":"trade","received_at_ms":1788333196790,"data":{"e":"trade","E":1788333196958,"s":"BTCUSDT","t":6646666031,"p":"77724.00000000","q":"0.00100000","T":1788333196957,"m":false,"M":true}}
{"type":"trade","received_at_ms":1788333196825,"data":{"e":"trade","E":1788333196992,"s":"BTCUSDT","t":6646666032,"p":"77724.00000000","q":"0.01500000","T":1788333196991,"m":false,"M":true}}
{"type":"depth","received_at_ms":1788333196846,"data":{"e":"depthUpdate","E":1788333197014,"s":"BTCUSDT","U":99556331719,"u":99556331726,"b":[["69951.60000000","0.00416000"],["62179.20000000","0.00032000"]],"a":[["77724.00000000","0.61025000"],["77742.09000000","0.00257000"]]}}
{"type":"depth","received_at_ms":1788333196946,"data":{"e":"depthUpdate","E":1788333197114,"s":"BTCUSDT","U":99556331727,"u":99556331738,"b":[["77710.35000000","0.00000000"],["77705.37000000","0.00007000"],["69951.60000000","0.00432000"],["62179.19000000","0.00000000"]],"a":[["77736.47000000","0.00007000"],["77742.08000000","0.00000000"],["77742.09000000","0.00000000"],["77791.44000000","0.00411000"],["77822.54000000","0.00000000"]]}}
{"type":"depth","received_at_ms":1788333197049,"data":{"e":"depthUpdate","E":1788333197214,"s":"BTCUSDT","U":99556331739,"u":99556331775,"b":[["77723.99000000","2.24256000"],["77723.98000000","0.00027000"],["77722.69000000","0.00400000"],["77722.07000000","0.00000000"],["77719.44000000","0.00800000"],["77719.43000000","0.00200000"],["69951.60000000","0.00416000"],["62179.20000000","0.00000000"]],"a":[["77724.00000000","0.61347000"],["77724.01000000","0.00104000"],["77726.23000000","0.00014000"],["77726.24000000","0.13736000"],["77727.06000000","0.00000000"],["77727.07000000","0.00014000"],["77742.07000000","0.00257000"]]}}
{"type":"trade","received_at_ms":1788333197069,"data":{"e":"trade","E":1788333197236,"s":"BTCUSDT","t":6646666033,"p":"77724.00000000","q":"0.00023000","T":1788333197235,"m":false,"M":true}}
{"type":"trade","received_at_ms":1788333197142,"data":{"e":"trade","E":1788333197309,"s":"BTCUSDT","t":6646666034,"p":"77724.00000000","q":"0.00015000","T":1788333197309,"m":false,"M":true}}
{"type":"trade","received_at_ms":1788333197143,"data":{"e":"trade","E":1788333197309,"s":"BTCUSDT","t":6646666035,"p":"77724.00000000","q":"0.00035000","T":1788333197309,"m":false,"M":true}}
{"type":"depth","received_at_ms":1788333197147,"data":{"e":"depthUpdate","E":1788333197314,"s":"BTCUSDT","U":99556331776,"u":99556331919,"b":[["77723.99000000","2.24333000"],["77723.98000000","0.00076000"],["69951.60000000","0.00432000"],["69951.59000000","0.00000000"],["69951.58000000","0.00009000"]],"a":[["77724.00000000","0.61264000"],["77726.00000000","0.03014000"],["77726.23000000","0.00000000"],["77726.24000000","0.00014000"],["77726.74000000","0.11205000"],["77727.07000000","0.00000000"],["77727.99000000","0.00007000"],["77733.38000000","0.00000000"],["77733.50000000","0.00163000"],["77733.90000000","0.00000000"],["77734.17000000","0.00000000"],["77736.28000000","0.01200000"],["77736.30000000","0.00000000"],["77736.31000000","0.00000000"],["77736.32000000","0.49119000"],["77736.48000000","0.00827000"],["77736.49000000","0.00000000"],["77742.05000000","0.00257000"],["77742.07000000","0.00000000"],["77745.60000000","0.09622000"],["77747.18000000","0.00000000"],["77748.38000000","0.00128000"],["77756.39000000","0.00000000"],["77756.55000000","0.00000000"],["77757.58000000","0.00000000"],["77822.53000000","0.00411000"]]}}
{"type":"depth","received_at_ms":1788333197249,"data":{"e":"depthUpdate","E":1788333197414,"s":"BTCUSDT","U":99556331920,"u":99556332009,"b":[["77723.99000000","2.24284000"],["77723.98000000","0.00048000"],["69951.60000000","0.00416000"],["62179.19000000","0.00000000"]],"a":[["77724.00000000","0.61257000"],["77724.01000000","0.00097000"],["77726.00000000","0.03014000"],["77726.24000000","0.00000000"],["77729.46000000","0.10092000"],["77736.26000000","0.88813000"],["77736.27000000","1.93226000"],["77736.28000000","0.00000000"],["77736.29000000","0.00000000"],["77736.32000000","0.00000000"],["77736.48000000","0.00027000"],["77737.70000000","0.00000000"],["77739.07000000","0.00000000"],["77739.76000000","0.01200000"],["77740.44000000","0.00000000"],["77740.67000000","0.00200000"],["77742.04000000","0.00257000"],["77742.05000000","0.00000000"],["77756.80000000","0.00000000"],["77756.92000000","0.12871000"]]}}
{"type":"depth","received_at_ms":1788333197346,"data":{"e":"depthUpdate","E":1788333197514,"s":"BTCUSDT","U":99556332010,"u":99556332028,"b":[["69951.60000000","0.00416000"],["62179.20000000","0.00032000"]],"a":[["77724.00000000","0.61107000"],["77736.24000000","0.20813000"],["77736.25000000","1.32271000"],["77736.26000000","0.77622000"],["77739.76000000","0.00400000"],["77742.04000000","0.00000000"],["77742.81000000","0.00257000"],["77745.60000000","0.00000000"],["77756.92000000","0.00000000"],["77757.19000000","0.00000000"]]}}
{"type":"depth","received_at_ms":1788333197449,"data":{"e":"depthUpdate","E":1788333197614,"s":"BTCUSDT","U":99556332029,"u":99556332048,"b":[["77723.99000000","2.24078000"],["77528.64000000","0.00811000"],["77526.01000000","0.00000000"],["69951.60000000","0.00416000"],["62179.20000000","0.00000000"],["62179.00000000","0.00800000"]],"a":[["77733.03000000","0.00000000"],["77734.07000000","0.00400000"],["77736.23000000","0.00200000"],["77740.67000000","0.00000000"],["77742.80000000","0.00257000"],["77742.81000000","0.00000000"]]}}
{"type":"trade","received_at_ms":1788333197477,"data":{"e":"trade","E":1788333197643,"s":"BTCUSDT","t":6646666036,"p":"77724.00000000","q":"0.02434000","T":1788333197642,"m":false,"M":true}}
{"type":"depth","received_at_ms":1788333197547,"data":{"e":"depthUpdate","E":1788333197714,"s":"BTCUSDT","U":99556332049,"u":99556332063,"b":[["77722.69000000","0.00000000"],["77721.16000000","0.00000000"],["77719.44000000","0.00000000"],["69951.60000000","0.00416000"],["69951.58000000","0.00000000"],["69951.00000000","0.00068000"]],"a":[["77724.00000000","0.58673000"],["77725.65000000","0.11124000"],["77742.79000000","0.00257000"],["77742.80000000","0.00000000"],["77821.72000000","0.00000000"],["77824.31000000","4.08551000"]]}}
{"type":"depth","received_at_ms":1788333197647,"data":{"e":"depthUpdate","E":1788333197814,"s":"BTCUSDT","U":99556332064,"u":99556332089,"b":[["77723.15000000","0.00400000"],["77722.65000000","0.13905000"],["77721.32000000","0.01335000"],["77719.43000000","0.62946000"],["76336.07000000","0.14713000"],["69951.60000000","0.00432000"]],"a":[["77724.00000000","0.58680000"],["77724.01000000","0.00104000"],["77725.37000000","0.11205000"],["77725.64000000","0.00014000"],["77725.65000000","0.11138000"],["77727.99000000","0.00000000"],["77729.46000000","0.10078000"]]}}
{"type":"depth","received_at_ms":1788333197752,"data":{"e":"depthUpdate","E":1788333197916,"s":"BTCUSDT","U":99556332090,"u":99556332106,"b":[["77719.44000000","0.11191000"],["77710.50000000","0.00411000"],["76558.13000000","0.00030000"],["69951.60000000","0.00416000"]],"a":[["77724.00000000","0.79079000"],["77742.78000000","0.00000000"],["77742.79000000","0.00000000"],["77791.44000000","0.00000000"],["77822.53000000","0.00000000"],["78889.86000000","0.00030000"]]}}
{"type":"depth","received_at_ms":1788333197847,"data":{"e":"depthUpdate","E":1788333198014,"s":"BTCUSDT","U":99556332107,"u":99556332113,"b":[["69951.60000000","0.00416000"],["62179.20000000","0.00032000"]],"a":[["77732.68000000","0.00000000"],["77742.77000000","0.00000000"],["77743.50000000","0.00257000"]]}}
{"type":"trade","received_at_ms":1788333197852,"data":{"e":"trade","E":1788333198018,"s":"BTCUSDT","t":6646666037,"p":"77723.99000000","q":"0.01500000","T":1788333198018,"m":true,"M":true}}
{"type":"depth","received_at_ms":1788333197947,"data":{"e":"depthUpdate","E":1788333198114,"s":"BTCUSDT","U":99556332114,"u":99556332126,"b":[["77723.99000000","2.22578000"],["77705.37000000","0.00007000"],["69951.60000000","0.00416000"],["69951.59000000","0.00009000"],["62179.19000000","0.00000000"]],"a":[["77736.47000000","0.00007000"],["77743.49000000","0.00257000"],["77743.50000000","0.00000000"],["77757.46000000","0.00000000"]]}}
{"type":"depth","received_at_ms":1788333198047,"data":{"e":"depthUpdate","E":1788333198214,"s":"BTCUSDT","U":99556332127,"u":99556332132,"b":[["69951.60000000","0.00432000"],["62179.20000000","0.00000000"]],"a":[["77757.55000000","0.00000000"]]}}
{"type":"depth","received_at_ms":1788333198147,"data":{"e":"depthUpdate","E":1788333198315,"s":"BTCUSDT","U":99556332133,"u":99556332140,"b":[["69951.60000000","0.00400000"],["62179.00000000","0.00800000"]],"a":[["77743.46000000","0.02657000"],["77743.49000000","0.00000000"]]}}
{"type":"depth","received_at_ms":1788333198247,"data":{"e":"depthUpdate","E":1788333198414,"s":"BTCUSDT","U":99556332141,"u":99556332148,"b":[["69951.60000000","0.00432000"],["62179.00000000","0.00800000"]],"a":[["77724.70000000","0.13928000"],["77725.65000000","0.00014000"],["77743.44000000","0.00257000"],["77743.46000000","0.02400000"]]}}
{"type":"depth","received_at_ms":1788333198346,"data":{"e":"depthUpdate","E":1788333198514,"s":"BTCUSDT","U":99556332149,"u":99556332195,"b":[["77723.99000000","2.22550000"],["77723.98000000","0.00027000"],["69951.60000000","0.00416000"],["62179.20000000","0.00032000"],["62179.19000000","0.00000000"]],"a":[["77724.00000000","0.79072000"],["77724.01000000","0.00097000"],["77724.69000000","0.00014000"],["77724.70000000","0.13942000"],["77725.36000000","0.00000000"],["77725.37000000","0.00014000"],["77725.64000000","0.00000000"],["77725.65000000","0.00000000"],["77727.64000000","0.00014000"],["77727.99000000","0.00007000"],["77743.42000000","0.00257000"],["77743.44000000","0.00000000"],["77746.22000000","0.00200000"],["77822.54000000","0.00411000"]]}}
{"type":"depth","received_at_ms":1788333198446,"data":{"e":"depthUpdate","E":1788333198614,"s":"BTCUSDT","U":99556332196,"u":99556332211,"b":[["69951.60000000","0.00432000"],["62179.20000000","0.00000000"],["62179.00000000","0.00800000"]],"a":[["77724.70000000","0.13942000"],["77725.37000000","0.00000000"],["77729.46000000","0.10092000"],["77743.42000000","0.00000000"],["77818.17000000","0.00200000"]]}}
{"type":"depth","received_at_ms":1788333198547,"data":{"e":"depthUpdate","E":1788333198714,"s":"BTCUSDT","U":99556332212,"u":99556332260,"b":[["77723.99000000","2.22550000"],["77723.98000000","0.00027000"],["77720.08000000","0.02909000"],["77719.88000000","0.11191000"],["77710.50000000","0.00000000"],["77528.64000000","0.00000000"],["77526.01000000","0.00811000"],["69951.60000000","0.00416000"]],"a":[["77724.00000000","0.79080000"],["77724.69000000","0.00000000"],["77724.70000000","0.00014000"],["77727.99000000","0.00014000"],["77729.45000000","0.00007000"],["77757.97000000","0.00000000"],["77758.35000000","0.00000000"],["77791.44000000","0.00411000"],["77822.54000000","0.00000000"]]}}
{"type":"depth","received_at_ms":1788333198647,"data":{"e":"depthUpdate","E":1788333198814,"s":"BTCUSDT","U":99556332261,"u":99556332278,"b":[["71506.07000000","0.00014000"],["69951.60000000","0.00432000"]],"a":[["77724.00000000","0.79080000"],["77724.01000000","0.00090000"],["77724.70000000","0.00000000"],["77729.59000000","0.00014000"]]}}
{"type":"depth","received_at_ms":1788333198748,"data":{"e":"depthUpdate","E":1788333198914,"s":"BTCUSDT","U":99556332279,"u":99556332297,"b":[["77700.52000000","0.04525000"],["77700.49000000","0.00000000"],["76558.13000000","0.00030000"],["69951.60000000","0.00416000"],["69951.00000000","0.00068000"]],"a":[["77729.46000000","0.10092000"],["77729.59000000","0.00000000"],["77730.00000000","0.03064000"],["78889.86000000","0.00030000"]]}}
{"type":"trade","received_at_ms":1788333198816,"data":{"e":"trade","E":1788333198983,"s":"BTCUSDT","t":6646666038,"p":"77724.00000000","q":"0.00008000","T":1788333198983,"m":false,"M":true}}
{"type":"depth","received_at_ms":1788333198847,"data":{"e":"depthUpdate","E":1788333199014,"s":"BTCUSDT","U":99556332298,"u":99556332309,"b":[["77653.39000000","1.61347000"],["77650.02000000","0.70020000"],["77648.21000000","0.00000000"],["75557.14000000","0.00000000"],["69951.60000000","0.00416000"],["69951.59000000","0.00000000"],["69951.58000000","0.00009000"],["62179.20000000","0.00032000"],["62179.00000000","0.00800000"]],"a":[["77724.00000000","0.79072000"],["77758.11000000","0.00000000"],["81001.14000000","0.00000000"]]}}
{"type":"trade","received_at_ms":1788333198893,"data":{"e":"trade","E":1788333199059,"s":"BTCUSDT","t":6646666039,"p":"77724.00000000","q":"0.00115000","T":1788333199059,"m":false,"M":true}}
{"type":"depth","received_at_ms":1788333198947,"data":{"e":"depthUpdate","E":1788333199114,"s":"BTCUSDT","U":99556332310,"u":99556332342,"b":[["77723.99000000","2.22550000"],["77723.98000000","0.00027000"],["77705.37000000","0.00000000"],["77528.01000000","0.00811000"],["77526.01000000","0.00000000"],["69951.60000000","0.00416000"],["62179.19000000","0.00000000"]],"a":[["77724.00000000","0.78971000"],["77724.01000000","0.00097000"],["77725.76000000","0.00014000"],["77725.77000000","0.11239000"],["77729.45000000","0.00000000"],["77729.59000000","0.14295000"],["77736.26000000","0.73984000"],["77736.47000000","0.00000000"],["77822.53000000","0.00411000"]]}}
{"type":"depth","received_at_ms":1788333199047,"data":{"e":"depthUpdate","E":1788333199214,"s":"BTCUSDT","U":99556332343,"u":99556332385,"b":[["77723.99000000","2.22620000"],["77723.98000000","0.00076000"],["77705.37000000","0.00007000"],["69951.60000000","0.00416000"],["62179.20000000","0.00000000"]],"a":[["77724.00000000","0.79135000"],["77724.97000000","0.00014000"],["77724.98000000","0.12033000"],["77725.76000000","0.00000000"],["77725.77000000","0.00014000"],["77729.46000000","0.10078000"],["77730.00000000","0.03050000"],["77736.47000000","0.00007000"],["77747.78000000","0.00000000"],["77749.95000000","0.64360000"],["77751.07000000","0.00000000"],["77756.93000000","0.00000000"]]}}
{"type":"trade","received_at_ms":1788333199102,"data":{"e":"trade","E":1788333199270,"s":"BTCUSDT","t":6646666040,"p":"77724.00000000","q":"0.00176000","T":1788333199270,"m":false,"M":true}}
{"type":"depth","received_at_ms":1788333199148,"data":{"e":"depthUpdate","E":1788333199314,"s":"BTCUSDT","U":99556332386,"u":99556332419,"b":[["77723.99000000","2.22592000"],["77723.98000000","0.00062000"],["77710.50000000","0.00411000"],["77148.49000000","0.00000000"],["69951.60000000","0.00432000"],["69951.58000000","0.00000000"]],"a":[["77724.00000000","0.78823000"],["77724.01000000","0.00097000"],["77725.77000000","0.00000000"],["77756.88000000","0.00000000"],["77757.09000000","0.00000000"],["77791.44000000","0.00000000"],["77822.53000000","0.00000000"]]}}
{"type":"depth","received_at_ms":1788333199247,"data":{"e":"depthUpdate","E":1788333199414,"s":"BTCUSDT","U":99556332420,"u":99556332432,"b":[["77719.88000000","0.00000000"],["77719.44000000","0.00000000"],["77538.65000000","0.02015000"],["77528.01000000","0.00000000"],["77526.01000000","0.00811000"],["77510.73000000","0.00000000"],["76680.97000000","0.00000000"],["71506.07000000","0.00000000"],["69951.60000000","0.00416000"]],"a":[["77724.00000000","0.91859000"],["77725.37000000","0.11191000"]]}}
{"type":"depth","received_at_ms":1788333199348,"data":{"e":"depthUpdate","E":1788333199514,"s":"BTCUSDT","U":99556332433,"u":99556332496,"b":[["77723.99000000","2.22592000"],["77723.98000000","0.00062000"],["77723.15000000","0.00000000"],["77722.77000000","0.00000000"],["77722.16000000","0.00257000"],["77721.85000000","0.00400000"],["77720.08000000","0.02902000"],["77694.51000000","0.00000000"],["77663.27000000","1.27534000"],["77658.64000000","0.00321000"],["77580.24000000","0.00128000"],["69951.60000000","0.00432000"],["62179.20000000","0.00032000"],["62179.19000000","0.00000000"],["62179.00000000","0.01000000"]],"a":[["77724.00000000","0.78987000"],["77724.01000000","0.00097000"],["77724.97000000","0.00000000"],["77724.98000000","0.00000000"],["77725.36000000","0.00014000"],["77727.99000000","0.00007000"],["77732.34000000","0.00000000"],["77733.12000000","0.00643000"],["77734.53000000","0.00000000"],["77758.12000000","0.09616000"],["77791.43000000","0.00411000"]]}}
{"type":"trade","received_at_ms":1788333199419,"data":{"e":"trade","E":1788333199585,"s":"BTCUSDT","t":6646666041,"p":"77724.00000000","q":"0.00283000","T":1788333199585,"m":false,"M":true}}
{"type":"trade","received_at_ms":1788333199419,"data":{"e":"trade","E":1788333199586,"s":"BTCUSDT","t":6646666042,"p":"77724.00000000","q":"0.00334000","T":1788333199585,"m":false,"M":true}}
{"type":"depth","received_at_ms":1788333199448,"data":{"e":"depthUpdate","E":1788333199614,"s":"BTCUSDT","U":99556332497,"u":99556332511,"b":[["77723.99000000","2.22592000"],["77723.98000000","0.00062000"],["77723.07000000","0.00257000"],["77722.16000000","0.00000000"],["77538.65000000","0.00000000"],["69951.60000000","0.00425000"],["62179.20000000","0.00000000"]],"a":[["77724.00000000","0.78370000"]]}}
{"type":"depth","received_at_ms":1788333199548,"data":{"e":"depthUpdate","E":1788333199714,"s":"BTCUSDT","U":99556332512,"u":99556332523,"b":[["77723.99000000","2.22599000"],["77723.98000000","0.00069000"],["77511.73000000","0.02015000"],["69951.60000000","0.00441000"]],"a":[["77724.00000000","0.68599000"],["77743.17000000","0.00257000"],["77757.26000000","0.00000000"],["77757.27000000","0.00000000"]]}}
{"type":"depth","received_at_ms":1788333199647,"data":{"e":"depthUpdate","E":1788333199814,"s":"BTCUSDT","U":99556332524,"u":99556332549,"b":[["77723.99000000","3.73899000"],["77723.07000000","0.00000000"],["77722.65000000","0.14548000"],["77722.00000000","0.00014000"],["77721.85000000","0.00000000"],["77720.08000000","0.02902000"],["77719.84000000","0.00000000"],["69951.60000000","0.00425000"]],"a":[["77724.00000000","0.68599000"],["77733.12000000","0.00000000"],["77734.07000000","0.00000000"],["77734.21000000","0.00000000"],["77735.12000000","0.00400000"],["77735.79000000","0.00643000"],["77736.24000000","0.11191000"],["77743.13000000","0.00257000"],["77743.17000000","0.00000000"],["77746.22000000","0.09822000"],["77755.89000000","0.00000000"],["77757.97000000","0.00200000"],["77821.72000000","2.15325000"],["77824.31000000","1.93226000"]]}}
{"type":"trade","received_at_ms":1788333199717,"data":{"e":"trade","E":1788333199884,"s":"BTCUSDT","t":6646666043,"p":"77723.99000000","q":"0.00007000","T":1788333199884,"m":true,"M":true}}
{"type":"depth","received_at_ms":1788333199747,"data":{"e":"depthUpdate","E":1788333199914,"s":"BTCUSDT","U":99556332550,"u":99556332599,"b":[["77723.99000000","3.74091000"],["77723.98000000","0.00062000"],["77722.64000000","0.37352000"],["77722.00000000","0.00000000"],["77720.87000000","0.04105000"],["77710.50000000","0.00000000"],["76558.13000000","0.00030000"],["76183.39000000","0.00134000"],["76031.02000000","0.00153000"],["75878.95000000","0.00175000"],["69951.60000000","0.00416000"],["69951.59000000","0.00009000"]],"a":[["77724.00000000","0.68571000"],["77725.37000000","0.11205000"],["77729.46000000","0.10092000"],["77734.27000000","0.08411000"],["77743.13000000","0.00000000"],["77743.56000000","0.00257000"],["77757.16000000","0.00000000"],["77791.43000000","0.00000000"],["77822.53000000","0.00411000"],["78889.86000000","0.00030000"]]}}
{"type":"depth","received_at_ms":1788333199848,"data":{"e":"depthUpdate","E":1788333200014,"s":"BTCUSDT","U":99556332600,"u":99556332615,"b":[["77723.99000000","3.74091000"],["77723.98000000","0.00062000"],["75556.96000000","0.00010000"],["69951.60000000","0.00416000"],["69951.00000000","0.00068000"],["62179.20000000","0.00032000"]],"a":[["77725.20000000","0.00014000"],["77725.21000000","0.11389000"],["77727.99000000","0.00000000"],["77743.55000000","0.00257000"],["77743.56000000","0.00000000"]]}}
{"type":"trade","received_at_ms":1788333199860,"data":{"e":"trade","E":1788333200026,"s":"BTCUSDT","t":6646666044,"p":"77724.00000000","q":"0.01750000","T":1788333200026,"m":false,"M":true}}
{"type":"depth","received_at_ms":1788333199947,"data":{"e":"depthUpdate","E":1788333200114,"s":"BTCUSDT","U":99556332616,"u":99556332643,"b":[["77723.99000000","3.74105000"],["77723.98000000","0.00076000"],["75727.19000000","0.00201000"],["69951.60000000","0.00432000"],["69951.00000000","0.00068000"],["62179.19000000","0.00000000"]],"a":[["77724.00000000","0.66228000"],["77724.01000000","0.00104000"],["77725.21000000","0.11403000"],["77725.99000000","0.00614000"],["77729.46000000","0.10078000"],["77743.53000000","0.00257000"],["77743.55000000","0.00000000"]]}}
{"type":"depth","received_at_ms":1788333200047,"data":{"e":"depthUpdate","E":1788333200214,"s":"BTCUSDT","U":99556332644,"u":99556332707,"b":[["77723.99000000","3.74084000"],["77723.98000000","0.00055000"],["77721.16000000","0.00200000"],["77719.43000000","0.62746000"],["77705.37000000","0.00007000"],["69951.60000000","0.00400000"],["62179.20000000","0.00000000"]],"a":[["77724.00000000","0.66078000"],["77724.01000000","0.00104000"],["77725.36000000","0.00000000"],["77725.37000000","0.00014000"],["77725.99000000","0.00628000"],["77727.99000000","0.00007000"],["77728.42000000","0.01267000"],["77734.27000000","0.00000000"],["77735.12000000","0.00000000"],["77735.32000000","0.00400000"],["77735.98000000","0.00000000"],["77736.19000000","0.00000000"],["77736.23000000","0.00600000"],["77736.25000000","1.31871000"],["77736.47000000","0.00007000"],["77737.36000000","0.00643000"],["77743.53000000","0.00000000"],["77745.48000000","0.00257000"],["77757.88000000","0.00000000"],["81001.33000000","0.00010000"]]}}
{"type":"depth","received_at_ms":1788333200151,"data":{"e":"depthUpdate","E":1788333200314,"s":"BTCUSDT","U":99556332708,"u":99556332735,"b":[["77723.99000000","3.74484000"],["69951.60000000","0.00416000"],["62179.00000000","0.01000000"]],"a":[["77724.00000000","0.66071000"],["77724.01000000","0.00097000"],["77725.20000000","0.00000000"],["77725.21000000","0.00014000"],["77725.37000000","0.00000000"],["77727.99000000","0.00014000"],["77728.42000000","0.01281000"],["77729.45000000","0.00007000"],["77735.18000000","0.00400000"],["77745.47000000","0.00257000"],["77745.48000000","0.00000000"],["77757.96000000","0.00000000"]]}}
{"type":"depth","received_at_ms":1788333200247,"data":{"e":"depthUpdate","E":1788333200414,"s":"BTCUSDT","U":99556332736,"u":99556332749,"b":[["77720.08000000","0.02909000"],["77719.44000000","0.00800000"],["69951.60000000","0.00416000"]],"a":[["77724.00000000","0.66085000"],["77725.21000000","0.00000000"],["77736.22000000","0.09622000"],["77736.23000000","0.01400000"],["77745.46000000","0.00257000"],["77745.47000000","0.00000000"],["77746.22000000","0.00200000"]]}}
{"type":"depth","received_at_ms":1788333200347,"data":{"e":"depthUpdate","E":1788333200514,"s":"BTCUSDT","U":99556332750,"u":99556332774,"b":[["77723.99000000","3.74449000"],["77723.98000000","0.00027000"],["77721.16000000","0.00000000"],["77720.44000000","0.00214000"],["77710.49000000","0.00411000"],["77549.56000000","0.00000000"],["77528.01000000","0.00811000"],["77526.01000000","0.00000000"],["69951.60000000","0.00416000"],["69951.00000000","0.00078000"],["62179.20000000","0.00032000"],["62179.19000000","0.00000000"]],"a":[["77757.95000000","0.00000000"],["77758.48000000","0.12871000"]]}}
{"type":"trade","received_at_ms":1788333200421,"data":{"e":"trade","E":1788333200587,"s":"BTCUSDT","t":6646666045,"p":"77724.00000000","q":"0.01500000","T":1788333200587,"m":false,"M":true}}
{"type":"depth","received_at_ms":1788333200447,"data":{"e":"depthUpdate","E":1788333200614,"s":"BTCUSDT","U":99556332775,"u":99556332818,"b":[["77723.99000000","3.74491000"],["77723.98000000","0.00062000"],["69951.59000000","0.00000000"],["69951.00000000","0.00068000"],["62179.20000000","0.00000000"],["62179.00000000","0.01000000"]],"a":[["77724.00000000","0.64749000"],["77724.01000000","0.00111000"],["77725.36000000","0.00014000"],["77725.37000000","0.11191000"],["77725.63000000","0.00014000"],["77725.64000000","0.14928000"],["77727.99000000","0.00000000"],["77729.45000000","0.00000000"],["77736.22000000","0.00000000"],["77746.22000000","0.09822000"],["77757.97000000","0.00200000"],["77758.48000000","0.00000000"],["77758.53000000","0.00000000"]]}}
{"type":"depth","received_at_ms":1788333200547,"data":{"e":"depthUpdate","E":1788333200714,"s":"BTCUSDT","U":99556332819,"u":99556332831,"b":[["77710.49000000","0.00000000"],["69951.60000000","0.00416000"]],"a":[["77724.00000000","0.64763000"],["77728.42000000","0.01267000"],["77745.45000000","0.00257000"],["77745.46000000","0.00000000"],["77791.42000000","0.00411000"],["77822.53000000","0.00000000"]]}}
{"type":"trade","received_at_ms":1788333200594,"data":{"e":"trade","E":1788333200759,"s":"BTCUSDT","t":6646666046,"p":"77724.00000000","q":"0.00733000","T":1788333200759,"m":false,"M":true}}
{"type":"trade","received_at_ms":1788333200594,"data":{"e":"trade","E":1788333200759,"s":"BTCUSDT","t":6646666047,"p":"77724.00000000","q":"0.00007000","T":1788333200759,"m":false,"M":true}}
{"type":"trade","received_at_ms":1788333200594,"data":{"e":"trade","E":1788333200759,"s":"BTCUSDT","t":6646666048,"p":"77724.00000000","q":"0.00007000","T":1788333200759,"m":false,"M":true}}
{"type":"trade","received_at_ms":1788333200594,"data":{"e":"trade","E":1788333200759,"s":"BTCUSDT","t":6646666049,"p":"77724.00000000","q":"0.00007000","T":1788333200759,"m":false,"M":true}}
{"type":"trade","received_at_ms":1788333200594,"data":{"e":"trade","E":1788333200759,"s":"BTCUSDT","t":6646666050,"p":"77724.00000000","q":"0.00007000","T":1788333200759,"m":false,"M":true}}
{"type":"trade","received_at_ms":1788333200594,"data":{"e":"trade","E":1788333200759,"s":"BTCUSDT","t":6646666051,"p":"77724.00000000","q":"0.00013000","T":1788333200759,"m":false,"M":true}}
{"type":"trade","received_at_ms":1788333200594,"data":{"e":"trade","E":1788333200759,"s":"BTCUSDT","t":6646666052,"p":"77724.00000000","q":"0.00007000","T":1788333200759,"m":false,"M":true}}
{"type":"trade","received_at_ms":1788333200594,"data":{"e":"trade","E":1788333200759,"s":"BTCUSDT","t":6646666053,"p":"77724.00000000","q":"0.00007000","T":1788333200759,"m":false,"M":true}}
{"type":"trade","received_at_ms":1788333200594,"data":{"e":"trade","E":1788333200759,"s":"BTCUSDT","t":6646666054,"p":"77724.00000000","q":"0.00007000","T":1788333200759,"m":false,"M":true}}
{"type":"trade","received_at_ms":1788333200594,"data":{"e":"trade","E":1788333200759,"s":"BTCUSDT","t":6646666055,"p":"77724.00000000","q":"0.00007000","T":1788333200759,"m":false,"M":true}}
{"type":"trade","received_at_ms":1788333200594,"data":{"e":"trade","E":1788333200759,"s":"BTCUSDT","t":6646666056,"p":"77724.00000000","q":"0.00007000","T":1788333200759,"m":false,"M":true}}
{"type":"trade","received_at_ms":1788333200594,"data":{"e":"trade","E":1788333200759,"s":"BTCUSDT","t":6646666057,"p":"77724.00000000","q":"0.00009000","T":1788333200759,"m":false,"M":true}}
{"type":"trade","received_at_ms":1788333200594,"data":{"e":"trade","E":1788333200759,"s":"BTCUSDT","t":6646666058,"p":"77724.00000000","q":"0.00007000","T":1788333200759,"m":false,"M":true}}
{"type":"trade","received_at_ms":1788333200595,"data":{"e":"trade","E":1788333200759,"s":"BTCUSDT","t":6646666059,"p":"77724.00000000","q":"0.00007000","T":1788333200759,"m":false,"M":true}}
{"type":"trade","received_at_ms":1788333200595,"data":{"e":"trade","E":1788333200759,"s":"BTCUSDT","t":6646666060,"p":"77724.00000000","q":"0.00008000","T":1788333200759,"m":false,"M":true}}
{"type":"trade","received_at_ms":1788333200595,"data":{"e":"trade","E":1788333200759,"s":"BTCUSDT","t":6646666061,"p":"77724.00000000","q":"0.00007000","T":1788333200759,"m":false,"M":true}}
{"type":"trade","received_at_ms":1788333200595,"data":{"e":"trade","E":1788333200759,"s":"BTCUSDT","t":6646666062,"p":"77724.00000000","q":"0.00008000","T":1788333200759,"m":false,"M":true}}
{"type":"trade","received_at_ms":1788333200595,"data":{"e":"trade","E":1788333200759,"s":"BTCUSDT","t":6646666063,"p":"77724.00000000","q":"0.00047000","T":1788333200759,"m":false,"M":true}}
{"type":"trade","received_at_ms":1788333200595,"data":{"e":"trade","E":1788333200759,"s":"BTCUSDT","t":6646666064,"p":"77724.00000000","q":"0.00065000","T":1788333200759,"m":false,"M":true}}
{"type":"trade","received_at_ms":1788333200595,"data":{"e":"trade","E":1788333200759,"s":"BTCUSDT","t":6646666065,"p":"77724.00000000","q":"0.00007000","T":1788333200759,"m":false,"M":true}}
{"type":"trade","received_at_ms":1788333200595,"data":{"e":"trade","E":1788333200759,"s":"BTCUSDT","t":6646666066,"p":"77724.00000000","q":"0.00007000","T":1788333200759,"m":false,"M":true}}
{"type":"trade","received_at_ms":1788333200595,"data":{"e":"trade","E":1788333200759,"s":"BTCUSDT","t":6646666067,"p":"77724.00000000","q":"0.00010000","T":1788333200759,"m":false,"M":true}}
{"type":"trade","received_at_ms":1788333200595,"data":{"e":"trade","E":1788333200759,"s":"BTCUSDT","t":6646666068,"p":"77724.00000000","q":"0.01583000","T":1788333200759,"m":false,"M":true}}
{"type":"depth","received_at_ms":1788333200647,"data":{"e":"depthUpdate","E":1788333200814,"s":"BTCUSDT","U":99556332832,"u":99556332857,"b":[["77723.99000000","3.74491000"],["77717.46000000","0.03861000"],["77698.04000000","0.00000000"],["77549.59000000","4.57147000"],["69951.60000000","0.00432000"]],"a":[["77724.00000000","0.62416000"]]}}
{"type":"trade","received_at_ms":1788333200670,"data":{"e":"trade","E":1788333200837,"s":"BTCUSDT","t":6646666069,"p":"77724.00000000","q":"0.00200000","T":1788333200836,"m":false,"M":true}}
{"type":"trade","received_at_ms":1788333200670,"data":{"e":"trade","E":1788333200837,"s":"BTCUSDT","t":6646666070,"p":"77724.00000000","q":"0.00200000","T":1788333200836,"m":false,"M":true}}
{"type":"trade","received_at_ms":1788333200670,"data":{"e":"trade","E":1788333200837,"s":"BTCUSDT","t":6646666071,"p":"77724.00000000","q":"0.00200000","T":1788333200836,"m":false,"M":true}}
{"type":"trade","received_at_ms":1788333200670,"data":{"e":"trade","E":1788333200837,"s":"BTCUSDT","t":6646666072,"p":"77724.00000000","q":"0.00200000","T":1788333200837,"m":false,"M":true}}
{"type":"trade","received_at_ms":1788333200670,"data":{"e":"trade","E":1788333200837,"s":"BTCUSDT","t":6646666073,"p":"77724.00000000","q":"0.00200000","T":1788333200837,"m":false,"M":true}}
{"type":"trade","received_at_ms":1788333200670,"data":{"e":"trade","E":1788333200837,"s":"BTCUSDT","t":6646666074,"p":"77724.00000000","q":"0.00200000","T":1788333200837,"m":false,"M":true}}
{"type":"trade","received_at_ms":1788333200670,"data":{"e":"trade","E":1788333200837,"s":"BTCUSDT","t":6646666075,"p":"77724.00000000","q":"0.00200000","T":1788333200837,"m":false,"M":true}}
{"type":"trade","received_at_ms":1788333200670,"data":{"e":"trade","E":1788333200837,"s":"BTCUSDT","t":6646666076,"p":"77724.00000000","q":"0.00200000","T":1788333200837,"m":false,"M":true}}
{"type":"trade","received_at_ms":1788333200670,"data":{"e":"trade","E":1788333200838,"s":"BTCUSDT","t":6646666077,"p":"77724.00000000","q":"0.00200000","T":1788333200837,"m":false,"M":true}}
{"type":"trade","received_at_ms":1788333200670,"data":{"e":"trade","E":1788333200838,"s":"BTCUSDT","t":6646666078,"p":"77724.00000000","q":"0.00200000","T":1788333200837,"m":false,"M":true}}
{"type":"trade","received_at_ms":1788333200670,"data":{"e":"trade","E":1788333200838,"s":"BTCUSDT","t":6646666079,"p":"77724.00000000","q":"0.00200000","T":1788333200837,"m":false,"M":true}}
{"type":"trade","received_at_ms":1788333200672,"data":{"e":"trade","E":1788333200838,"s":"BTCUSDT","t":6646666080,"p":"77724.00000000","q":"0.00200000","T":1788333200837,"m":false,"M":true}}
{"type":"trade","received_at_ms":1788333200672,"data":{"e":"trade","E":1788333200838,"s":"BTCUSDT","t":6646666081,"p":"77724.00000000","q":"0.00200000","T":1788333200838,"m":false,"M":true}}
{"type":"trade","received_at_ms":1788333200672,"data":{"e":"trade","E":1788333200838,"s":"BTCUSDT","t":6646666082,"p":"77724.00000000","q":"0.00200000","T":1788333200838,"m":false,"M":true}}
{"type":"trade","received_at_ms":1788333200674,"data":{"e":"trade","E":1788333200839,"s":"BTCUSDT","t":6646666083,"p":"77724.00000000","q":"0.00200000","T":1788333200839,"m":false,"M":true}}
{"type":"trade","received_at_ms":1788333200674,"data":{"e":"trade","E":1788333200839,"s":"BTCUSDT","t":6646666084,"p":"77724.00000000","q":"0.00200000","T":1788333200839,"m":false,"M":true}}
{"type":"trade","received_at_ms":1788333200674,"data":{"e":"trade","E":1788333200839,"s":"BTCUSDT","t":6646666085,"p":"77724.00000000","q":"0.00200000","T":1788333200839,"m":false,"M":true}}
{"type":"trade","received_at_ms":1788333200676,"data":{"e":"trade","E":1788333200842,"s":"BTCUSDT","t":6646666086,"p":"77724.00000000","q":"0.00200000","T":1788333200841,"m":false,"M":true}}
{"type":"trade","received_at_ms":1788333200714,"data":{"e":"trade","E":1788333200880,"s":"BTCUSDT","t":6646666087,"p":"77723.99000000","q":"0.00773000","T":1788333200880,"m":true,"M":true}}
{"type":"depth","received_at_ms":1788333200747,"data":{"e":"depthUpdate","E":1788333200914,"s":"BTCUSDT","U":99556332858,"u":99556332916,"b":[["77723.99000000","3.73711000"],["77723.98000000","0.00055000"],["76558.13000000","0.00030000"],["75575.73000000","0.00232000"],["69951.60000000","0.00441000"],["69951.00000000","0.00078000"]],"a":[["77724.00000000","0.58788000"],["77725.37000000","0.11205000"],["77725.64000000","0.14942000"],["77735.32000000","0.00000000"],["77736.24000000","0.11591000"],["77822.54000000","0.00411000"],["78889.86000000","0.00030000"]]}}
{"type":"depth","received_at_ms":1788333200847,"data":{"e":"depthUpdate","E":1788333201014,"s":"BTCUSDT","U":99556332917,"u":99556332924,"b":[["69951.60000000","0.00457000"],["69951.00000000","0.00078000"],["62179.20000000","0.00032000"]],"a":[["77756.81000000","0.00000000"]]}}
{"type":"trade","received_at_ms":1788333200856,"data":{"e":"trade","E":1788333201022,"s":"BTCUSDT","t":6646666088,"p":"77724.00000000","q":"0.00774000","T":1788333201022,"m":false,"M":true}}
{"type":"trade","received_at_ms":1788333200876,"data":{"e":"trade","E":1788333201042,"s":"BTCUSDT","t":6646666089,"p":"77724.00000000","q":"0.00025000","T":1788333201042,"m":false,"M":true}}
{"type":"depth","received_at_ms":1788333200947,"data":{"e":"depthUpdate","E":1788333201114,"s":"BTCUSDT","U":99556332925,"u":99556332999,"b":[["77723.99000000","3.73711000"],["77723.98000000","0.00055000"],["77719.44000000","0.00800000"],["77710.51000000","0.00411000"],["69951.60000000","0.00457000"],["69951.00000000","0.00068000"],["62179.19000000","0.00000000"]],"a":[["77724.00000000","0.60028000"],["77725.99000000","0.01228000"],["77726.49000000","0.00074000"],["77745.45000000","0.00000000"],["77745.46000000","0.00257000"],["77791.42000000","0.00000000"],["77822.54000000","0.00000000"]]}}
{"type":"depth","received_at_ms":1788333201047,"data":{"e":"depthUpdate","E":1788333201214,"s":"BTCUSDT","U":99556333000,"u":99556333018,"b":[["77705.37000000","0.00007000"],["77024.47000000","0.00000000"],["69951.60000000","0.00473000"],["62179.20000000","0.00000000"]],"a":[["77724.00000000","0.60028000"],["77724.01000000","0.00104000"],["77726.00000000","0.03014000"],["77726.49000000","0.00060000"],["77728.42000000","0.01281000"],["77736.47000000","0.00007000"],["77757.06000000","0.00000000"]]}}
{"type":"depth","received_at_ms":1788333201147,"data":{"e":"depthUpdate","E":1788333201314,"s":"BTCUSDT","U":99556333019,"u":99556333044,"b":[["77723.99000000","3.73339000"],["77723.98000000","0.00083000"],["77723.42000000","0.00400000"],["77719.44000000","0.00800000"],["69951.60000000","0.00457000"],["69951.00000000","0.00068000"]],"a":[["77724.00000000","0.60178000"],["77730.90000000","0.00400000"],["77745.46000000","0.00000000"],["77745.48000000","0.00257000"],["77762.10000000","0.00000000"]]}}
{"type":"depth","received_at_ms":1788333201246,"data":{"e":"depthUpdate","E":1788333201414,"s":"BTCUSDT","U":99556333045,"u":99556333052,"b":[["77705.56000000","0.00000000"],["77683.85000000","0.49720000"],["77682.25000000","0.00000000"],["69951.60000000","0.00473000"]],"a":[["77745.48000000","0.00000000"],["77745.50000000","0.00264000"]]}}
{"type":"depth","received_at_ms":1788333201346,"data":{"e":"depthUpdate","E":1788333201514,"s":"BTCUSDT","U":99556333053,"u":99556333066,"b":[["77723.99000000","3.73318000"],["77723.98000000","0.00062000"],["77674.61000000","0.00000000"],["77665.97000000","0.25737000"],["69951.60000000","0.00441000"],["62179.20000000","0.00032000"],["62179.19000000","0.00000000"]],"a":[["77822.53000000","0.00411000"]]}}
{"type":"trade","received_at_ms":1788333201445,"data":{"e":"trade","E":1788333201612,"s":"BTCUSDT","t":6646666090,"p":"77723.99000000","q":"0.01500000","T":1788333201611,"m":true,"M":true}}
{"type":"depth","received_at_ms":1788333201447,"data":{"e":"depthUpdate","E":1788333201614,"s":"BTCUSDT","U":99556333067,"u":99556333077,"b":[["77723.99000000","3.71818000"],["69951.60000000","0.00464000"],["69951.59000000","0.00009000"],["62179.20000000","0.00000000"],["62179.00000000","0.01000000"]],"a":[["77745.50000000","0.00007000"],["77745.52000000","0.00257000"],["77756.87000000","0.00000000"]]}}
{"type":"trade","received_at_ms":1788333201452,"data":{"e":"trade","E":1788333201616,"s":"BTCUSDT","t":6646666091,"p":"77724.00000000","q":"0.02333000","T":1788333201616,"m":false,"M":true}}
{"type":"trade","received_at_ms":1788333201452,"data":{"e":"trade","E":1788333201616,"s":"BTCUSDT","t":6646666092,"p":"77724.00000000","q":"0.00240000","T":1788333201616,"m":false,"M":true}}
{"type":"depth","received_at_ms":1788333201547,"data":{"e":"depthUpdate","E":1788333201714,"s":"BTCUSDT","U":99556333078,"u":99556333088,"b":[["77710.51000000","0.00000000"],["77528.01000000","0.00000000"],["77526.01000000","0.00811000"],["69951.60000000","0.00448000"]],"a":[["77724.00000000","0.57605000"],["77745.52000000","0.00000000"],["77745.53000000","0.00257000"],["77791.43000000","0.00411000"],["77822.53000000","0.00000000"]]}}
{"type":"depth","received_at_ms":1788333201647,"data":{"e":"depthUpdate","E":1788333201814,"s":"BTCUSDT","U":99556333089,"u":99556333096,"b":[["77705.05000000","0.49359000"],["77683.85000000","0.72457000"],["77681.74000000","0.97467000"],["69951.60000000","0.00432000"]],"a":[["77745.53000000","0.00000000"],["77745.54000000","0.00257000"]]}}
{"type":"depth","received_at_ms":1788333201747,"data":{"e":"depthUpdate","E":1788333201914,"s":"BTCUSDT","U":99556333097,"u":99556333104,"b":[["77710.51000000","0.00411000"],["77695.64000000","0.00007000"],["76558.13000000","0.00030000"],["69951.60000000","0.00448000"]],"a":[["77745.54000000","0.00000000"],["78889.86000000","0.00030000"]]}}
{"type":"depth","received_at_ms":1788333201849,"data":{"e":"depthUpdate","E":1788333202015,"s":"BTCUSDT","U":99556333105,"u":99556333122,"b":[["69951.60000000","0.00448000"],["62179.20000000","0.00032000"],["62179.00000000","0.01000000"]],"a":[["77724.00000000","0.57605000"],["77745.55000000","0.00000000"],["77745.56000000","0.00257000"],["77756.82000000","0.00000000"]]}}
{"type":"depth","received_at_ms":1788333201946,"data":{"e":"depthUpdate","E":1788333202114,"s":"BTCUSDT","U":99556333123,"u":99556333128,"b":[["69951.60000000","0.00448000"],["62179.19000000","0.00000000"]],"a":[["77745.56000000","0.00000000"],["77745.57000000","0.00257000"]]}}
{"type":"depth","received_at_ms":1788333202046,"data":{"e":"depthUpdate","E":1788333202214,"s":"BTCUSDT","U":99556333129,"u":99556333143,"b":[["77723.99000000","3.71811000"],["77723.98000000","0.00055000"],["77705.37000000","0.00007000"],["77024.47000000","0.00010000"],["69951.60000000","0.00448000"],["62179.20000000","0.00000000"]],"a":[["77736.47000000","0.00007000"],["77757.07000000","0.00000000"],["77757.08000000","0.00000000"],["77757.43000000","0.00000000"]]}}
{"type":"trade","received_at_ms":1788333202122,"data":{"e":"trade","E":1788333202287,"s":"BTCUSDT","t":6646666093,"p":"77723.99000000","q":"0.00011000","T":1788333202287,"m":true,"M":true}}
{"type":"depth","received_at_ms":1788333202147,"data":{"e":"depthUpdate","E":1788333202314,"s":"BTCUSDT","U":99556333144,"u":99556333153,"b":[["77723.99000000","3.71800000"],["69951.60000000","0.00464000"],["69951.59000000","0.00000000"],["62179.00000000","0.01000000"]],"a":[["77745.57000000","0.00000000"]]}}
{"type":"trade","received_at_ms":1788333202188,"data":{"e":"trade","E":1788333202354,"s":"BTCUSDT","t":6646666094,"p":"77724.00000000","q":"0.01709000","T":1788333202354,"m":false,"M":true}}
{"type":"trade","received_at_ms":1788333202188,"data":{"e":"trade","E":1788333202354,"s":"BTCUSDT","t":6646666095,"p":"77724.00000000","q":"0.00007000","T":1788333202354,"m":false,"M":true}}
{"type":"trade","received_at_ms":1788333202188,"data":{"e":"trade","E":1788333202354,"s":"BTCUSDT","t":6646666096,"p":"77724.00000000","q":"0.00858000","T":1788333202354,"m":false,"M":true}}
{"type":"trade","received_at_ms":1788333202204,"data":{"e":"trade","E":1788333202371,"s":"BTCUSDT","t":6646666097,"p":"77723.99000000","q":"0.00199000","T":1788333202371,"m":true,"M":true}}
{"type":"depth","received_at_ms":1788333202247,"data":{"e":"depthUpdate","E":1788333202414,"s":"BTCUSDT","U":99556333154,"u":99556333164,"b":[["77723.99000000","3.71601000"],["77653.39000000","0.00000000"],["77650.02000000","1.41557000"],["77648.21000000","1.61347000"],["69951.60000000","0.00448000"],["69951.00000000","0.00068000"]],"a":[["77724.00000000","0.55041000"]]}}
{"type":"trade","received_at_ms":1788333202254,"data":{"e":"trade","E":1788333202420,"s":"BTCUSDT","t":6646666098,"p":"77724.00000000","q":"0.00012000","T":1788333202420,"m":false,"M":true}}
{"type":"trade","received_at_ms":1788333202342,"data":{"e":"trade","E":1788333202507,"s":"BTCUSDT","t":6646666099,"p":"77724.00000000","q":"0.00794000","T":1788333202507,"m":false,"M":true}}
{"type":"depth","received_at_ms":1788333202347,"data":{"e":"depthUpdate","E":1788333202514,"s":"BTCUSDT","U":99556333165,"u":99556333177,"b":[["77723.99000000","3.71608000"],["77723.98000000","0.00062000"],["77710.51000000","0.00000000"],["69951.60000000","0.00464000"],["62179.20000000","0.00032000"],["62179.19000000","0.00000000"],["62179.00000000","0.01000000"]],"a":[["77724.00000000","0.54235000"],["77791.43000000","0.00000000"],["77822.54000000","0.00411000"]]}}
{"type":"depth","received_at_ms":1788333202448,"data":{"e":"depthUpdate","E":1788333202614,"s":"BTCUSDT","U":99556333178,"u":99556333181,"b":[["69951.60000000","0.00448000"],["62179.20000000","0.00000000"]],"a":[]}}
{"type":"depth","received_at_ms":1788333202548,"data":{"e":"depthUpdate","E":1788333202714,"s":"BTCUSDT","U":99556333182,"u":99556333186,"b":[["69951.60000000","0.00464000"]],"a":[["77757.08000000","0.00000000"]]}}
{"type":"depth","received_at_ms":1788333202661,"data":{"e":"depthUpdate","E":1788333202814,"s":"BTCUSDT","U":99556333187,"u":99556333193,"b":[["77528.01000000","0.00811000"],["77526.01000000","0.00000000"],["77494.67000000","0.00000000"],["69951.60000000","0.00448000"],["69951.59000000","0.00027000"]],"a":[["77756.80000000","0.00000000"],["77757.53000000","0.12871000"]]}}
{"type":"depth","received_at_ms":1788333202748,"data":{"e":"depthUpdate","E":1788333202915,"s":"BTCUSDT","U":99556333194,"u":99556333217,"b":[["77723.99000000","2.20965000"],["77723.90000000","0.05021000"],["77722.76000000","0.00643000"],["77720.44000000","0.00014000"],["77719.44000000","0.01000000"],["77650.80000000","1.61347000"],["77648.21000000","0.00000000"],["76558.13000000","0.00030000"],["69951.60000000","0.00464000"]],"a":[["77724.00000000","0.54085000"],["77734.41000000","0.08411000"],["77736.22000000","0.09622000"],["77739.54000000","0.00000000"],["77739.76000000","0.04900000"],["77746.22000000","0.00200000"],["77756.76000000","0.00000000"],["77760.41000000","0.00000000"],["77791.44000000","0.00411000"],["78889.86000000","0.00030000"]]}}
{"type":"trade","received_at_ms":1788333202839,"data":{"e":"trade","E":1788333202999,"s":"BTCUSDT","t":6646666100,"p":"77724.00000000","q":"0.02172000","T":1788333202999,"m":false,"M":true}}
{"type":"trade","received_at_ms":1788333202839,"data":{"e":"trade","E":1788333202999,"s":"BTCUSDT","t":6646666101,"p":"77724.00000000","q":"0.00402000","T":1788333202999,"m":false,"M":true}}
{"type":"depth","received_at_ms":1788333202847,"data":{"e":"depthUpdate","E":1788333203014,"s":"BTCUSDT","U":99556333218,"u":99556333236,"b":[["77723.99000000","2.20958000"],["77723.98000000","0.00055000"],["77723.90000000","0.05021000"],["77722.76000000","0.00657000"],["77720.87000000","0.04091000"],["77650.02000000","0.70020000"],["69951.60000000","0.00457000"],["62179.20000000","0.00032000"]],"a":[["77724.00000000","0.51661000"]]}}
{"type":"trade","received_at_ms":1788333202939,"data":{"e":"trade","E":1788333203105,"s":"BTCUSDT","t":6646666102,"p":"77724.00000000","q":"0.00092000","T":1788333203105,"m":false,"M":true}}
{"type":"depth","received_at_ms":1788333202947,"data":{"e":"depthUpdate","E":1788333203114,"s":"BTCUSDT","U":99556333237,"u":99556333259,"b":[["77723.99000000","2.20666000"],["77723.98000000","0.00027000"],["77723.55000000","0.00257000"],["77710.51000000","0.00411000"],["69951.60000000","0.00457000"]],"a":[["77724.00000000","0.51419000"],["77791.44000000","0.00000000"],["77822.54000000","0.00000000"]]}}
{"type":"trade","received_at_ms":1788333202956,"data":{"e":"trade","E":1788333203123,"s":"BTCUSDT","t":6646666103,"p":"77724.00000000","q":"0.02100000","T":1788333203122,"m":false,"M":true}}
{"type":"trade","received_at_ms":1788333202959,"data":{"e":"trade","E":1788333203123,"s":"BTCUSDT","t":6646666104,"p":"77724.00000000","q":"0.02100000","T":1788333203123,"m":false,"M":true}}
{"type":"trade","received_at_ms":1788333202959,"data":{"e":"trade","E":1788333203123,"s":"BTCUSDT","t":6646666105,"p":"77724.00000000","q":"0.02100000","T":1788333203123,"m":false,"M":true}}
{"type":"trade","received_at_ms":1788333202959,"data":{"e":"trade","E":1788333203124,"s":"BTCUSDT","t":6646666106,"p":"77724.00000000","q":"0.02100000","T":1788333203123,"m":false,"M":true}}
{"type":"trade","received_at_ms":1788333202959,"data":{"e":"trade","E":1788333203125,"s":"BTCUSDT","t":6646666107,"p":"77724.00000000","q":"0.02100000","T":1788333203124,"m":false,"M":true}}
{"type":"trade","received_at_ms":1788333202997,"data":{"e":"trade","E":1788333203164,"s":"BTCUSDT","t":6646666108,"p":"77723.99000000","q":"0.00009000","T":1788333203164,"m":true,"M":true}}
{"type":"trade","received_at_ms":1788333203007,"data":{"e":"trade","E":1788333203173,"s":"BTCUSDT","t":6646666109,"p":"77724.00000000","q":"0.00500000","T":1788333203173,"m":false,"M":true}}
{"type":"trade","received_at_ms":1788333203017,"data":{"e":"trade","E":1788333203184,"s":"BTCUSDT","t":6646666110,"p":"77724.00000000","q":"0.02100000","T":1788333203184,"m":false,"M":true}}
{"type":"trade","received_at_ms":1788333203019,"data":{"e":"trade","E":1788333203186,"s":"BTCUSDT","t":6646666111,"p":"77724.00000000","q":"0.01750000","T":1788333203185,"m":false,"M":true}}
{"type":"trade","received_at_ms":1788333203019,"data":{"e":"trade","E":1788333203186,"s":"BTCUSDT","t":6646666112,"p":"77724.00000000","q":"0.00322000","T":1788333203185,"m":false,"M":true}}
{"type":"trade","received_at_ms":1788333203019,"data":{"e":"trade","E":1788333203186,"s":"BTCUSDT","t":6646666113,"p":"77724.00000000","q":"0.00028000","T":1788333203185,"m":false,"M":true}}
{"type":"depth","received_at_ms":1788333203048,"data":{"e":"depthUpdate","E":1788333203214,"s":"BTCUSDT","U":99556333260,"u":99556333296,"b":[["77723.99000000","2.20914000"],["77723.98000000","0.00027000"],["77723.55000000","0.00000000"],["77720.08000000","0.02916000"],["77719.45000000","0.11191000"],["77528.01000000","0.00000000"],["77526.01000000","0.00811000"],["69951.60000000","0.00457000"],["62179.20000000","0.00000000"],["62179.19000000","0.00000000"],["62179.00000000","0.01000000"]],"a":[["77724.00000000","0.36819000"],["77725.24000000","0.00600000"],["77725.99000000","0.00028000"],["77736.21000000","0.00000000"],["77736.22000000","0.00000000"],["77746.21000000","0.09622000"],["77746.22000000","0.00200000"]]}}
{"type":"trade","received_at_ms":1788333203123,"data":{"e":"trade","E":1788333203287,"s":"BTCUSDT","t":6646666114,"p":"77724.00000000","q":"0.00200000","T":1788333203286,"m":false,"M":true}}
{"type":"trade","received_at_ms":1788333203124,"data":{"e":"trade","E":1788333203287,"s":"BTCUSDT","t":6646666115,"p":"77724.00000000","q":"0.00200000","T":1788333203287,"m":false,"M":true}}
{"type":"trade","received_at_ms":1788333203124,"data":{"e":"trade","E":1788333203287,"s":"BTCUSDT","t":6646666116,"p":"77724.00000000","q":"0.00200000","T":1788333203287,"m":false,"M":true}}
{"type":"trade","received_at_ms":1788333203124,"data":{"e":"trade","E":1788333203287,"s":"BTCUSDT","t":6646666117,"p":"77724.00000000","q":"0.00200000","T":1788333203287,"m":false,"M":true}}
{"type":"trade","received_at_ms":1788333203124,"data":{"e":"trade","E":1788333203287,"s":"BTCUSDT","t":6646666118,"p":"77724.00000000","q":"0.00200000","T":1788333203287,"m":false,"M":true}}
{"type":"trade","received_at_ms":1788333203124,"data":{"e":"trade","E":1788333203288,"s":"BTCUSDT","t":6646666119,"p":"77724.00000000","q":"0.00200000","T":1788333203287,"m":false,"M":true}}
{"type":"trade","received_at_ms":1788333203124,"data":{"e":"trade","E":1788333203288,"s":"BTCUSDT","t":6646666120,"p":"77724.00000000","q":"0.00200000","T":1788333203287,"m":false,"M":true}}
{"type":"trade","received_at_ms":1788333203124,"data":{"e":"trade","E":1788333203288,"s":"BTCUSDT","t":6646666121,"p":"77724.00000000","q":"0.00200000","T":1788333203287,"m":false,"M":true}}
{"type":"trade","received_at_ms":1788333203124,"data":{"e":"trade","E":1788333203288,"s":"BTCUSDT","t":6646666122,"p":"77724.00000000","q":"0.00200000","T":1788333203288,"m":false,"M":true}}
{"type":"trade","received_at_ms":1788333203124,"data":{"e":"trade","E":1788333203288,"s":"BTCUSDT","t":6646666123,"p":"77724.00000000","q":"0.00200000","T":1788333203288,"m":false,"M":true}}
{"type":"trade","received_at_ms":1788333203124,"data":{"e":"trade","E":1788333203288,"s":"BTCUSDT","t":6646666124,"p":"77724.00000000","q":"0.00200000","T":1788333203288,"m":false,"M":true}}
{"type":"trade","received_at_ms":1788333203124,"data":{"e":"trade","E":1788333203288,"s":"BTCUSDT","t":6646666125,"p":"77724.00000000","q":"0.00200000","T":1788333203288,"m":false,"M":true}}
{"type":"trade","received_at_ms":1788333203124,"data":{"e":"trade","E":1788333203288,"s":"BTCUSDT","t":6646666126,"p":"77724.00000000","q":"0.00200000","T":1788333203288,"m":false,"M":true}}
{"type":"trade","received_at_ms":1788333203124,"data":{"e":"trade","E":1788333203289,"s":"BTCUSDT","t":6646666127,"p":"77724.00000000","q":"0.00200000","T":1788333203288,"m":false,"M":true}}
{"type":"trade","received_at_ms":1788333203124,"data":{"e":"trade","E":1788333203289,"s":"BTCUSDT","t":6646666128,"p":"77724.00000000","q":"0.00200000","T":1788333203289,"m":false,"M":true}}
{"type":"trade","received_at_ms":1788333203124,"data":{"e":"trade","E":1788333203290,"s":"BTCUSDT","t":6646666129,"p":"77724.00000000","q":"0.00200000","T":1788333203289,"m":false,"M":true}}
{"type":"trade","received_at_ms":1788333203124,"data":{"e":"trade","E":1788333203290,"s":"BTCUSDT","t":6646666130,"p":"77724.00000000","q":"0.00200000","T":1788333203289,"m":false,"M":true}}
{"type":"trade","received_at_ms":1788333203124,"data":{"e":"trade","E":1788333203290,"s":"BTCUSDT","t":6646666131,"p":"77724.00000000","q":"0.00200000","T":1788333203290,"m":false,"M":true}}
{"type":"trade","received_at_ms":1788333203124,"data":{"e":"trade","E":1788333203291,"s":"BTCUSDT","t":6646666132,"p":"77724.00000000","q":"0.02100000","T":1788333203290,"m":false,"M":true}}
{"type":"trade","received_at_ms":1788333203124,"data":{"e":"trade","E":1788333203291,"s":"BTCUSDT","t":6646666133,"p":"77724.00000000","q":"0.02000000","T":1788333203290,"m":false,"M":true}}
{"type":"trade","received_at_ms":1788333203125,"data":{"e":"trade","E":1788333203292,"s":"BTCUSDT","t":6646666134,"p":"77724.00000000","q":"0.02100000","T":1788333203292,"m":false,"M":true}}
{"type":"trade","received_at_ms":1788333203128,"data":{"e":"trade","E":1788333203294,"s":"BTCUSDT","t":6646666135,"p":"77724.00000000","q":"0.00200000","T":1788333203294,"m":false,"M":true}}
{"type":"trade","received_at_ms":1788333203128,"data":{"e":"trade","E":1788333203294,"s":"BTCUSDT","t":6646666136,"p":"77724.00000000","q":"0.00200000","T":1788333203294,"m":false,"M":true}}
{"type":"trade","received_at_ms":1788333203128,"data":{"e":"trade","E":1788333203294,"s":"BTCUSDT","t":6646666137,"p":"77724.00000000","q":"0.00200000","T":1788333203294,"m":false,"M":true}}
{"type":"trade","received_at_ms":1788333203128,"data":{"e":"trade","E":1788333203294,"s":"BTCUSDT","t":6646666138,"p":"77724.00000000","q":"0.00200000","T":1788333203294,"m":false,"M":true}}
{"type":"trade","received_at_ms":1788333203128,"data":{"e":"trade","E":1788333203294,"s":"BTCUSDT","t":6646666139,"p":"77724.00000000","q":"0.00200000","T":1788333203294,"m":false,"M":true}}
{"type":"trade","received_at_ms":1788333203128,"data":{"e":"trade","E":1788333203295,"s":"BTCUSDT","t":6646666140,"p":"77724.00000000","q":"0.00200000","T":1788333203294,"m":false,"M":true}}
{"type":"trade","received_at_ms":1788333203129,"data":{"e":"trade","E":1788333203295,"s":"BTCUSDT","t":6646666141,"p":"77724.00000000","q":"0.00200000","T":1788333203295,"m":false,"M":true}}
{"type":"trade","received_at_ms":1788333203129,"data":{"e":"trade","E":1788333203295,"s":"BTCUSDT","t":6646666142,"p":"77724.00000000","q":"0.00200000","T":1788333203295,"m":false,"M":true}}
{"type":"trade","received_at_ms":1788333203129,"data":{"e":"trade","E":1788333203295,"s":"BTCUSDT","t":6646666143,"p":"77724.00000000","q":"0.00200000","T":1788333203295,"m":false,"M":true}}
{"type":"trade","received_at_ms":1788333203129,"data":{"e":"trade","E":1788333203295,"s":"BTCUSDT","t":6646666144,"p":"77724.00000000","q":"0.00200000","T":1788333203295,"m":false,"M":true}}
{"type":"trade","received_at_ms":1788333203129,"data":{"e":"trade","E":1788333203295,"s":"BTCUSDT","t":6646666145,"p":"77724.00000000","q":"0.00200000","T":1788333203295,"m":false,"M":true}}
{"type":"trade","received_at_ms":1788333203129,"data":{"e":"trade","E":1788333203295,"s":"BTCUSDT","t":6646666146,"p":"77724.00000000","q":"0.00200000","T":1788333203295,"m":false,"M":true}}
{"type":"trade","received_at_ms":1788333203129,"data":{"e":"trade","E":1788333203296,"s":"BTCUSDT","t":6646666147,"p":"77724.00000000","q":"0.00200000","T":1788333203295,"m":false,"M":true}}
{"type":"trade","received_at_ms":1788333203129,"data":{"e":"trade","E":1788333203296,"s":"BTCUSDT","t":6646666148,"p":"77724.00000000","q":"0.00200000","T":1788333203295,"m":false,"M":true}}
{"type":"trade","received_at_ms":1788333203130,"data":{"e":"trade","E":1788333203296,"s":"BTCUSDT","t":6646666149,"p":"77724.00000000","q":"0.00200000","T":1788333203296,"m":false,"M":true}}
{"type":"trade","received_at_ms":1788333203130,"data":{"e":"trade","E":1788333203297,"s":"BTCUSDT","t":6646666150,"p":"77724.00000000","q":"0.00200000","T":1788333203296,"m":false,"M":true}}
{"type":"trade","received_at_ms":1788333203131,"data":{"e":"trade","E":1788333203297,"s":"BTCUSDT","t":6646666151,"p":"77724.00000000","q":"0.00200000","T":1788333203297,"m":false,"M":true}}
{"type":"trade","received_at_ms":1788333203131,"data":{"e":"trade","E":1788333203298,"s":"BTCUSDT","t":6646666152,"p":"77724.00000000","q":"0.00115000","T":1788333203298,"m":false,"M":true}}
{"type":"trade","received_at_ms":1788333203132,"data":{"e":"trade","E":1788333203298,"s":"BTCUSDT","t":6646666153,"p":"77724.00000000","q":"0.00085000","T":1788333203298,"m":false,"M":true}}
{"type":"depth","received_at_ms":1788333203147,"data":{"e":"depthUpdate","E":1788333203314,"s":"BTCUSDT","U":99556333297,"u":99556333406,"b":[["77723.99000000","2.43482000"],["77722.76000000","0.00014000"],["77722.67000000","0.00014000"],["77722.66000000","0.48543000"],["77722.65000000","0.13898000"],["77722.64000000","0.00014000"],["77721.32000000","0.01342000"],["77721.25000000","0.00000000"],["77720.08000000","0.02923000"],["77719.88000000","0.11191000"],["77705.37000000","0.00007000"],["69951.60000000","0.00448000"],["69951.59000000","0.00036000"]],"a":[["77724.00000000","0.37278000"],["77724.01000000","0.00104000"],["77725.24000000","0.00614000"],["77725.36000000","0.00000000"],["77725.37000000","0.00014000"],["77725.64000000","0.14928000"],["77725.99000000","0.00014000"],["77726.74000000","0.00014000"],["77727.65000000","0.00014000"],["77727.99000000","0.00007000"],["77728.67000000","0.00000000"],["77729.59000000","0.00000000"],["77734.41000000","0.08205000"],["77736.21000000","0.15440000"],["77736.22000000","0.00000000"],["77736.25000000","0.00400000"],["77736.26000000","0.00000000"],["77736.27000000","0.00000000"],["77736.47000000","0.00007000"],["77739.75000000","0.10416000"],["77740.67000000","0.19711000"],["77744.66000000","0.00257000"],["77746.21000000","0.00000000"],["77757.01000000","0.01998000"],["77758.12000000","0.00000000"],["77760.66000000","0.05378000"],["77791.44000000","0.00411000"]]}}
{"type":"trade","received_at_ms":1788333203174,"data":{"e":"trade","E":1788333203340,"s":"BTCUSDT","t":6646666154,"p":"77724.00000000","q":"0.00500000","T":1788333203339,"m":false,"M":true}}
{"type":"depth","received_at_ms":1788333203250,"data":{"e":"depthUpdate","E":1788333203414,"s":"BTCUSDT","U":99556333407,"u":99556333514,"b":[["77723.99000000","2.20557000"],["77723.90000000","0.05014000"],["77722.76000000","0.00000000"],["77722.74000000","0.01807000"],["77722.68000000","0.00014000"],["77722.67000000","0.17049000"],["77722.66000000","0.37352000"],["77722.65000000","0.00014000"],["77722.64000000","0.00000000"],["77722.00000000","0.00643000"],["77721.32000000","0.01335000"],["77653.39000000","1.61347000"],["77650.80000000","0.00000000"],["69951.60000000","0.00432000"],["69951.00000000","0.00088000"]],"a":[["77724.00000000","0.36778000"],["77724.01000000","0.00083000"],["77725.24000000","0.00614000"],["77725.37000000","0.00000000"],["77725.64000000","0.14942000"],["77726.00000000","0.03014000"],["77726.73000000","0.00000000"],["77726.74000000","0.00000000"],["77727.64000000","0.00000000"],["77727.65000000","0.00000000"],["77727.99000000","0.00014000"],["77728.10000000","0.00014000"],["77728.11000000","0.11191000"],["77728.48000000","0.00027000"],["77729.44000000","0.00007000"],["77729.45000000","0.17442000"],["77729.46000000","0.10092000"],["77729.99000000","0.00000000"],["77730.00000000","0.03064000"],["77730.22000000","0.02908000"],["77734.17000000","0.00000000"],["77736.21000000","0.17202000"],["77736.23000000","0.00000000"],["77736.25000000","0.00000000"],["77737.70000000","0.11191000"],["77739.07000000","0.11191000"],["77740.64000000","0.01600000"],["77740.66000000","0.00200000"],["77743.46000000","0.02400000"],["77744.66000000","0.00000000"]]}}
{"type":"depth","received_at_ms":1788333203348,"data":{"e":"depthUpdate","E":1788333203514,"s":"BTCUSDT","U":99556333515,"u":99556333551,"b":[["77722.74000000","0.01800000"],["77722.67000000","0.17063000"],["77722.66000000","0.37359000"],["77722.65000000","0.00000000"],["69951.60000000","0.00448000"],["69951.00000000","0.00068000"],["62179.20000000","0.00032000"],["62179.19000000","0.00000000"]],"a":[["77728.00000000","0.03021000"],["77728.11000000","0.11205000"],["77728.42000000","0.01281000"],["77729.45000000","0.17456000"],["77730.00000000","0.03050000"],["77730.22000000","0.02894000"]]}}
{"type":"depth","received_at_ms":1788333203446,"data":{"e":"depthUpdate","E":1788333203614,"s":"BTCUSDT","U":99556333552,"u":99556333567,"b":[["77723.99000000","2.21557000"],["69951.60000000","0.00448000"],["62179.20000000","0.00000000"],["62179.00000000","0.01000000"]],"a":[]}}
{"type":"trade","received_at_ms":1788333203524,"data":{"e":"trade","E":1788333203690,"s":"BTCUSDT","t":6646666155,"p":"77724.00000000","q":"0.00008000","T":1788333203689,"m":false,"M":true}}
{"type":"depth","received_at_ms":1788333203547,"data":{"e":"depthUpdate","E":1788333203715,"s":"BTCUSDT","U":99556333568,"u":99556333577,"b":[["77710.51000000","0.00000000"],["69951.60000000","0.00432000"],["69951.59000000","0.00027000"]],"a":[["77724.00000000","0.36770000"],["77733.73000000","0.00206000"],["77791.44000000","0.00000000"],["77822.54000000","0.00411000"]]}}
{"type":"trade","received_at_ms":1788333203642,"data":{"e":"trade","E":1788333203807,"s":"BTCUSDT","t":6646666156,"p":"77724.00000000","q":"0.02574000","T":1788333203807,"m":false,"M":true}}
{"type":"depth","received_at_ms":1788333203650,"data":{"e":"depthUpdate","E":1788333203814,"s":"BTCUSDT","U":99556333578,"u":99556333581,"b":[["69951.60000000","0.00464000"]],"a":[["77724.00000000","0.34196000"],["77758.32000000","0.09479000"]]}}
{"type":"depth","received_at_ms":1788333203747,"data":{"e":"depthUpdate","E":1788333203914,"s":"BTCUSDT","U":99556333582,"u":99556333593,"b":[["76558.13000000","0.00030000"],["69951.60000000","0.00448000"],["69951.59000000","0.00000000"]],"a":[["77733.68000000","0.00254000"],["77733.73000000","0.00000000"],["78889.86000000","0.00030000"]]}}
{"type":"depth","received_at_ms":1788333203846,"data":{"e":"depthUpdate","E":1788333204014,"s":"BTCUSDT","U":99556333594,"u":99556333599,"b":[["69951.60000000","0.00464000"],["62179.20000000","0.00032000"]],"a":[["77724.00000000","0.34325000"]]}}
{"type":"trade","received_at_ms":1788333203879,"data":{"e":"trade","E":1788333204046,"s":"BTCUSDT","t":6646666157,"p":"77724.00000000","q":"0.04100000","T":1788333204046,"m":false,"M":true}}
{"type":"depth","received_at_ms":1788333203946,"data":{"e":"depthUpdate","E":1788333204114,"s":"BTCUSDT","U":99556333600,"u":99556333604,"b":[["69951.60000000","0.00457000"]],"a":[["77724.00000000","0.30225000"],["77733.68000000","0.00048000"]]}}
{"type":"trade","received_at_ms":1788333204007,"data":{"e":"trade","E":1788333204175,"s":"BTCUSDT","t":6646666158,"p":"77724.00000000","q":"0.01500000","T":1788333204174,"m":false,"M":true}}
{"type":"trade","received_at_ms":1788333204038,"data":{"e":"trade","E":1788333204201,"s":"BTCUSDT","t":6646666159,"p":"77724.00000000","q":"0.00007000","T":1788333204201,"m":false,"M":true}}
{"type":"depth","received_at_ms":1788333204046,"data":{"e":"depthUpdate","E":1788333204214,"s":"BTCUSDT","U":99556333605,"u":99556333614,"b":[["69951.60000000","0.00473000"],["62179.20000000","0.00000000"],["62179.19000000","0.00000000"]],"a":[["77724.00000000","0.28118000"],["77725.24000000","0.00014000"],["77726.00000000","0.04214000"]]}}
{"type":"depth","received_at_ms":1788333204146,"data":{"e":"depthUpdate","E":1788333204314,"s":"BTCUSDT","U":99556333615,"u":99556333634,"b":[["77705.37000000","0.00007000"],["77528.01000000","0.00811000"],["77526.01000000","0.00000000"],["69951.60000000","0.00457000"],["62179.00000000","0.01000000"]],"a":[["77724.00000000","0.37888000"],["77724.01000000","0.00076000"],["77725.24000000","0.00000000"],["77736.47000000","0.00007000"],["77791.44000000","0.00411000"]]}}
{"type":"trade","received_at_ms":1788333204180,"data":{"e":"trade","E":1788333204346,"s":"BTCUSDT","t":6646666160,"p":"77724.00000000","q":"0.00200000","T":1788333204346,"m":false,"M":true}}
{"type":"trade","received_at_ms":1788333204180,"data":{"e":"trade","E":1788333204347,"s":"BTCUSDT","t":6646666161,"p":"77724.00000000","q":"0.00200000","T":1788333204346,"m":false,"M":true}}
{"type":"trade","received_at_ms":1788333204180,"data":{"e":"trade","E":1788333204347,"s":"BTCUSDT","t":6646666162,"p":"77724.00000000","q":"0.00200000","T":1788333204346,"m":false,"M":true}}
{"type":"trade","received_at_ms":1788333204180,"data":{"e":"trade","E":1788333204347,"s":"BTCUSDT","t":6646666163,"p":"77724.00000000","q":"0.00200000","T":1788333204346,"m":false,"M":true}}
{"type":"trade","received_at_ms":1788333204181,"data":{"e":"trade","E":1788333204348,"s":"BTCUSDT","t":6646666164,"p":"77724.00000000","q":"0.00200000","T":1788333204348,"m":false,"M":true}}
{"type":"trade","received_at_ms":1788333204184,"data":{"e":"trade","E":1788333204350,"s":"BTCUSDT","t":6646666165,"p":"77724.00000000","q":"0.02000000","T":1788333204350,"m":false,"M":true}}
{"type":"trade","received_at_ms":1788333204184,"data":{"e":"trade","E":1788333204350,"s":"BTCUSDT","t":6646666166,"p":"77724.00000000","q":"0.02100000","T":1788333204350,"m":false,"M":true}}
{"type":"trade","received_at_ms":1788333204184,"data":{"e":"trade","E":1788333204350,"s":"BTCUSDT","t":6646666167,"p":"77724.00000000","q":"0.02100000","T":1788333204350,"m":false,"M":true}}
{"type":"trade","received_at_ms":1788333204186,"data":{"e":"trade","E":1788333204351,"s":"BTCUSDT","t":6646666168,"p":"77724.00000000","q":"0.02100000","T":1788333204351,"m":false,"M":true}}
{"type":"trade","received_at_ms":1788333204186,"data":{"e":"trade","E":1788333204351,"s":"BTCUSDT","t":6646666169,"p":"77724.00000000","q":"0.02100000","T":1788333204351,"m":false,"M":true}}
{"type":"trade","received_at_ms":1788333204186,"data":{"e":"trade","E":1788333204351,"s":"BTCUSDT","t":6646666170,"p":"77724.00000000","q":"0.00226000","T":1788333204351,"m":false,"M":true}}
{"type":"trade","received_at_ms":1788333204186,"data":{"e":"trade","E":1788333204351,"s":"BTCUSDT","t":6646666171,"p":"77724.00000000","q":"0.00007000","T":1788333204351,"m":false,"M":true}}
{"type":"trade","received_at_ms":1788333204187,"data":{"e":"trade","E":1788333204351,"s":"BTCUSDT","t":6646666172,"p":"77724.00000000","q":"0.00007000","T":1788333204351,"m":false,"M":true}}
{"type":"trade","received_at_ms":1788333204187,"data":{"e":"trade","E":1788333204351,"s":"BTCUSDT","t":6646666173,"p":"77724.00000000","q":"0.00007000","T":1788333204351,"m":false,"M":true}}
{"type":"trade","received_at_ms":1788333204187,"data":{"e":"trade","E":1788333204351,"s":"BTCUSDT","t":6646666174,"p":"77724.00000000","q":"0.00007000","T":1788333204351,"m":false,"M":true}}
{"type":"trade","received_at_ms":1788333204187,"data":{"e":"trade","E":1788333204351,"s":"BTCUSDT","t":6646666175,"p":"77724.00000000","q":"0.00007000","T":1788333204351,"m":false,"M":true}}
{"type":"trade","received_at_ms":1788333204187,"data":{"e":"trade","E":1788333204351,"s":"BTCUSDT","t":6646666176,"p":"77724.00000000","q":"0.00007000","T":1788333204351,"m":false,"M":true}}
{"type":"trade","received_at_ms":1788333204187,"data":{"e":"trade","E":1788333204351,"s":"BTCUSDT","t":6646666177,"p":"77724.00000000","q":"0.00007000","T":1788333204351,"m":false,"M":true}}
{"type":"trade","received_at_ms":1788333204187,"data":{"e":"trade","E":1788333204351,"s":"BTCUSDT","t":6646666178,"p":"77724.00000000","q":"0.00007000","T":1788333204351,"m":false,"M":true}}
{"type":"trade","received_at_ms":1788333204187,"data":{"e":"trade","E":1788333204351,"s":"BTCUSDT","t":6646666179,"p":"77724.00000000","q":"0.00007000","T":1788333204351,"m":false,"M":true}}
{"type":"trade","received_at_ms":1788333204187,"data":{"e":"trade","E":1788333204351,"s":"BTCUSDT","t":6646666180,"p":"77724.00000000","q":"0.00007000","T":1788333204351,"m":false,"M":true}}
{"type":"trade","received_at_ms":1788333204187,"data":{"e":"trade","E":1788333204351,"s":"BTCUSDT","t":6646666181,"p":"77724.00000000","q":"0.00007000","T":1788333204351,"m":false,"M":true}}
{"type":"trade","received_at_ms":1788333204187,"data":{"e":"trade","E":1788333204351,"s":"BTCUSDT","t":6646666182,"p":"77724.00000000","q":"0.00013000","T":1788333204351,"m":false,"M":true}}
{"type":"trade","received_at_ms":1788333204187,"data":{"e":"trade","E":1788333204351,"s":"BTCUSDT","t":6646666183,"p":"77724.00000000","q":"0.00007000","T":1788333204351,"m":false,"M":true}}
{"type":"trade","received_at_ms":1788333204187,"data":{"e":"trade","E":1788333204351,"s":"BTCUSDT","t":6646666184,"p":"77724.00000000","q":"0.00007000","T":1788333204351,"m":false,"M":true}}
{"type":"trade","received_at_ms":1788333204187,"data":{"e":"trade","E":1788333204351,"s":"BTCUSDT","t":6646666185,"p":"77724.00000000","q":"0.00008000","T":1788333204351,"m":false,"M":true}}
{"type":"trade","received_at_ms":1788333204187,"data":{"e":"trade","E":1788333204351,"s":"BTCUSDT","t":6646666186,"p":"77724.00000000","q":"0.00007000","T":1788333204351,"m":false,"M":true}}
{"type":"trade","received_at_ms":1788333204187,"data":{"e":"trade","E":1788333204351,"s":"BTCUSDT","t":6646666187,"p":"77724.00000000","q":"0.00007000","T":1788333204351,"m":false,"M":true}}
{"type":"trade","received_at_ms":1788333204187,"data":{"e":"trade","E":1788333204351,"s":"BTCUSDT","t":6646666188,"p":"77724.00000000","q":"0.01748000","T":1788333204351,"m":false,"M":true}}
{"type":"trade","received_at_ms":1788333204187,"data":{"e":"trade","E":1788333204351,"s":"BTCUSDT","t":6646666189,"p":"77724.00000000","q":"0.00441000","T":1788333204351,"m":false,"M":true}}
{"type":"trade","received_at_ms":1788333204187,"data":{"e":"trade","E":1788333204351,"s":"BTCUSDT","t":6646666190,"p":"77724.00000000","q":"0.00007000","T":1788333204351,"m":false,"M":true}}
{"type":"trade","received_at_ms":1788333204187,"data":{"e":"trade","E":1788333204351,"s":"BTCUSDT","t":6646666191,"p":"77724.00000000","q":"0.00010000","T":1788333204351,"m":false,"M":true}}
{"type":"trade","received_at_ms":1788333204187,"data":{"e":"trade","E":1788333204351,"s":"BTCUSDT","t":6646666192,"p":"77724.00000000","q":"0.00007000","T":1788333204351,"m":false,"M":true}}
{"type":"trade","received_at_ms":1788333204187,"data":{"e":"trade","E":1788333204351,"s":"BTCUSDT","t":6646666193,"p":"77724.00000000","q":"0.00007000","T":1788333204351,"m":false,"M":true}}
{"type":"trade","received_at_ms":1788333204187,"data":{"e":"trade","E":1788333204351,"s":"BTCUSDT","t":6646666194,"p":"77724.00000000","q":"0.01628000","T":1788333204351,"m":false,"M":true}}
{"type":"trade","received_at_ms":1788333204187,"data":{"e":"trade","E":1788333204351,"s":"BTCUSDT","t":6646666195,"p":"77724.00000000","q":"0.02100000","T":1788333204351,"m":false,"M":true}}
{"type":"trade","received_at_ms":1788333204187,"data":{"e":"trade","E":1788333204352,"s":"BTCUSDT","t":6646666196,"p":"77724.00000000","q":"0.02100000","T":1788333204351,"m":false,"M":true}}
{"type":"trade","received_at_ms":1788333204187,"data":{"e":"trade","E":1788333204352,"s":"BTCUSDT","t":6646666197,"p":"77724.00000000","q":"0.02100000","T":1788333204352,"m":false,"M":true}}
{"type":"trade","received_at_ms":1788333204226,"data":{"e":"trade","E":1788333204394,"s":"BTCUSDT","t":6646666198,"p":"77724.00000000","q":"0.00500000","T":1788333204394,"m":false,"M":true}}
{"type":"depth","received_at_ms":1788333204247,"data":{"e":"depthUpdate","E":1788333204414,"s":"BTCUSDT","U":99556333635,"u":99556333724,"b":[["77723.99000000","2.42123000"],["77723.90000000","0.05021000"],["77722.76000000","0.00014000"],["77722.75000000","0.14446000"],["77722.74000000","0.01814000"],["77722.70000000","0.00007000"],["77722.69000000","0.11191000"],["77722.68000000","0.37338000"],["77722.67000000","0.00014000"],["77722.66000000","0.00021000"],["77722.00000000","0.00014000"],["71506.07000000","0.00014000"],["69951.60000000","0.00464000"],["69951.59000000","0.00009000"],["62179.00000000","0.01000000"]],"a":[["77724.00000000","0.15465000"],["77724.01000000","0.00076000"],["77725.63000000","0.00000000"],["77725.64000000","0.00014000"],["77728.48000000","0.00000000"],["77729.44000000","0.00000000"],["77729.45000000","0.00028000"],["77729.99000000","0.00007000"],["77730.00000000","0.03064000"],["77734.41000000","0.00000000"],["77736.15000000","0.00206000"],["77757.01000000","0.00000000"],["77758.32000000","0.00000000"],["77760.66000000","0.00000000"]]}}
{"type":"trade","received_at_ms":1788333204331,"data":{"e":"trade","E":1788333204496,"s":"BTCUSDT","t":6646666199,"p":"77724.00000000","q":"0.00200000","T":1788333204496,"m":false,"M":true}}
{"type":"trade","received_at_ms":1788333204331,"data":{"e":"trade","E":1788333204496,"s":"BTCUSDT","t":6646666200,"p":"77724.00000000","q":"0.00200000","T":1788333204496,"m":false,"M":true}}
{"type":"trade","received_at_ms":1788333204331,"data":{"e":"trade","E":1788333204496,"s":"BTCUSDT","t":6646666201,"p":"77724.00000000","q":"0.00200000","T":1788333204496,"m":false,"M":true}}
{"type":"trade","received_at_ms":1788333204331,"data":{"e":"trade","E":1788333204496,"s":"BTCUSDT","t":6646666202,"p":"77724.00000000","q":"0.00200000","T":1788333204496,"m":false,"M":true}}
{"type":"trade","received_at_ms":1788333204331,"data":{"e":"trade","E":1788333204496,"s":"BTCUSDT","t":6646666203,"p":"77724.00000000","q":"0.00200000","T":1788333204496,"m":false,"M":true}}
{"type":"trade","received_at_ms":1788333204331,"data":{"e":"trade","E":1788333204496,"s":"BTCUSDT","t":6646666204,"p":"77724.00000000","q":"0.00200000","T":1788333204496,"m":false,"M":true}}
{"type":"trade","received_at_ms":1788333204331,"data":{"e":"trade","E":1788333204496,"s":"BTCUSDT","t":6646666205,"p":"77724.00000000","q":"0.00200000","T":1788333204496,"m":false,"M":true}}
{"type":"trade","received_at_ms":1788333204331,"data":{"e":"trade","E":1788333204497,"s":"BTCUSDT","t":6646666206,"p":"77724.00000000","q":"0.00200000","T":1788333204496,"m":false,"M":true}}
{"type":"trade","received_at_ms":1788333204331,"data":{"e":"trade","E":1788333204497,"s":"BTCUSDT","t":6646666207,"p":"77724.00000000","q":"0.00200000","T":1788333204496,"m":false,"M":true}}
{"type":"trade","received_at_ms":1788333204331,"data":{"e":"trade","E":1788333204497,"s":"BTCUSDT","t":6646666208,"p":"77724.00000000","q":"0.00200000","T":1788333204497,"m":false,"M":true}}
{"type":"trade","received_at_ms":1788333204332,"data":{"e":"trade","E":1788333204498,"s":"BTCUSDT","t":6646666209,"p":"77724.00000000","q":"0.00200000","T":1788333204498,"m":false,"M":true}}
{"type":"trade","received_at_ms":1788333204332,"data":{"e":"trade","E":1788333204498,"s":"BTCUSDT","t":6646666210,"p":"77724.00000000","q":"0.00200000","T":1788333204498,"m":false,"M":true}}
{"type":"trade","received_at_ms":1788333204332,"data":{"e":"trade","E":1788333204499,"s":"BTCUSDT","t":6646666211,"p":"77724.00000000","q":"0.00200000","T":1788333204499,"m":false,"M":true}}
{"type":"depth","received_at_ms":1788333204348,"data":{"e":"depthUpdate","E":1788333204514,"s":"BTCUSDT","U":99556333725,"u":99556333789,"b":[["77723.99000000","2.42523000"],["77723.90000000","0.05021000"],["77722.75000000","0.14460000"],["77722.74000000","0.01800000"],["77722.69000000","0.11205000"],["77722.67000000","0.00000000"],["77722.66000000","0.00000000"],["77722.00000000","0.00000000"],["77705.05000000","0.00133000"],["77683.85000000","0.49720000"],["77681.74000000","0.00000000"],["69951.60000000","0.00432000"],["62179.20000000","0.00032000"],["62179.19000000","0.00000000"]],"a":[["77724.00000000","0.12879000"],["77725.64000000","0.00000000"],["77728.42000000","0.01281000"],["77728.49000000","0.00027000"],["77729.45000000","0.00014000"],["77730.22000000","0.02908000"],["77730.28000000","0.00814000"],["77757.07000000","0.02047000"],["77758.39000000","0.09837000"]]}}
{"type":"trade","received_at_ms":1788333204357,"data":{"e":"trade","E":1788333204518,"s":"BTCUSDT","t":6646666212,"p":"77724.00000000","q":"0.00129000","T":1788333204517,"m":false,"M":true}}
{"type":"trade","received_at_ms":1788333204357,"data":{"e":"trade","E":1788333204519,"s":"BTCUSDT","t":6646666213,"p":"77724.00000000","q":"0.00129000","T":1788333204519,"m":false,"M":true}}
{"type":"trade","received_at_ms":1788333204357,"data":{"e":"trade","E":1788333204519,"s":"BTCUSDT","t":6646666214,"p":"77724.00000000","q":"0.00012000","T":1788333204519,"m":false,"M":true}}
{"type":"trade","received_at_ms":1788333204370,"data":{"e":"trade","E":1788333204536,"s":"BTCUSDT","t":6646666215,"p":"77724.00000000","q":"0.00016000","T":1788333204536,"m":false,"M":true}}
{"type":"trade","received_at_ms":1788333204404,"data":{"e":"trade","E":1788333204567,"s":"BTCUSDT","t":6646666216,"p":"77724.00000000","q":"0.00007000","T":1788333204567,"m":false,"M":true}}
{"type":"depth","received_at_ms":1788333204448,"data":{"e":"depthUpdate","E":1788333204614,"s":"BTCUSDT","U":99556333790,"u":99556333816,"b":[["69951.60000000","0.00448000"],["69951.00000000","0.00068000"],["62179.20000000","0.00000000"],["62179.00000000","0.01000000"]],"a":[["77724.00000000","0.12593000"],["77724.01000000","0.00083000"],["77726.73000000","0.00014000"],["77726.74000000","0.10398000"],["77727.04000000","0.00014000"],["77727.05000000","0.13091000"],["77729.45000000","0.00000000"],["77729.99000000","0.00000000"],["77744.33000000","0.00257000"],["77757.53000000","0.00000000"],["77944.71000000","0.00058000"]]}}
{"type":"trade","received_at_ms":1788333204450,"data":{"e":"trade","E":1788333204617,"s":"BTCUSDT","t":6646666217,"p":"77724.00000000","q":"0.02573000","T":1788333204616,"m":false,"M":true}}
{"type":"depth","received_at_ms":1788333204547,"data":{"e":"depthUpdate","E":1788333204714,"s":"BTCUSDT","U":99556333817,"u":99556333841,"b":[["77710.52000000","0.00411000"],["69951.60000000","0.00432000"],["69951.59000000","0.00000000"]],"a":[["77724.00000000","0.10156000"],["77724.01000000","0.00090000"],["77726.00000000","0.04214000"],["77726.74000000","0.10412000"],["77727.05000000","0.13105000"],["77730.22000000","0.02894000"],["77730.28000000","0.00800000"],["77744.30000000","0.00257000"],["77744.33000000","0.00000000"],["77791.44000000","0.00000000"],["77822.54000000","0.00000000"],["77947.10000000","0.00000000"]]}}
{"type":"depth","received_at_ms":1788333204649,"data":{"e":"depthUpdate","E":1788333204814,"s":"BTCUSDT","U":99556333842,"u":99556333853,"b":[["77706.03000000","0.00210000"],["77705.89000000","0.50502000"],["77682.58000000","1.03960000"],["69951.60000000","0.00432000"]],"a":[["77744.27000000","0.00000000"],["77744.30000000","0.00000000"],["77756.00000000","0.03000000"]]}}
{"type":"depth","received_at_ms":1788333204749,"data":{"e":"depthUpdate","E":1788333204915,"s":"BTCUSDT","U":99556333854,"u":99556333889,"b":[["77723.99000000","2.22200000"],["77722.70000000","0.00000000"],["77722.69000000","0.00021000"],["77683.85000000","0.74395000"],["76558.13000000","0.00030000"],["69951.60000000","0.00432000"]],"a":[["77724.00000000","0.10155000"],["77724.01000000","0.00097000"],["77725.36000000","0.00014000"],["77725.37000000","0.11191000"],["77726.20000000","0.00014000"],["77726.21000000","0.11512000"],["77727.04000000","0.00000000"],["77727.05000000","0.00014000"],["77728.10000000","0.00000000"],["77744.25000000","0.00027000"],["77755.97000000","0.00000000"],["77760.72000000","0.05275000"],["78889.86000000","0.00030000"]]}}
{"type":"depth","received_at_ms":1788333204850,"data":{"e":"depthUpdate","E":1788333205014,"s":"BTCUSDT","U":99556333890,"u":99556333926,"b":[["77722.74000000","0.01800000"],["77722.69000000","0.00007000"],["75556.96000000","0.00000000"],["71506.07000000","0.00000000"],["69951.60000000","0.00416000"],["69951.00000000","0.00068000"],["62179.20000000","0.00032000"],["62179.00000000","0.01000000"]],"a":[["77724.00000000","0.10177000"],["77725.37000000","0.11205000"],["77726.00000000","0.04214000"],["77726.21000000","0.11526000"],["77726.74000000","0.10412000"],["77727.05000000","0.00000000"],["77730.00000000","0.03050000"],["77755.71000000","0.00000000"],["81001.33000000","0.00000000"]]}}
{"type":"depth","received_at_ms":1788333204949,"data":{"e":"depthUpdate","E":1788333205114,"s":"BTCUSDT","U":99556333927,"u":99556333930,"b":[["77722.76000000","0.10622000"],["69951.60000000","0.00432000"],["69951.00000000","0.00078000"]],"a":[["77822.57000000","0.00411000"]]}}
{"type":"trade","received_at_ms":1788333205040,"data":{"e":"trade","E":1788333205202,"s":"BTCUSDT","t":6646666218,"p":"77723.99000000","q":"0.01500000","T":1788333205202,"m":true,"M":true}}
{"type":"depth","received_at_ms":1788333205047,"data":{"e":"depthUpdate","E":1788333205214,"s":"BTCUSDT","U":99556333931,"u":99556333961,"b":[["77723.99000000","2.20700000"],["77723.90000000","0.05028000"],["77722.77000000","0.00014000"],["77722.76000000","0.10636000"],["77722.75000000","0.14446000"],["77722.68000000","0.37352000"],["77024.47000000","0.00000000"],["69951.60000000","0.00432000"],["69951.59000000","0.00009000"],["69951.00000000","0.00068000"],["62179.20000000","0.00000000"],["62179.19000000","0.00000000"]],"a":[["77724.00000000","0.10156000"],["77724.01000000","0.00104000"],["77726.00000000","0.03614000"],["77726.02000000","0.00619000"]]}}
{"type":"depth","received_at_ms":1788333205147,"data":{"e":"depthUpdate","E":1788333205314,"s":"BTCUSDT","U":99556333962,"u":99556333974,"b":[["77705.37000000","0.00007000"],["69951.60000000","0.00432000"]],"a":[["77726.00000000","0.03614000"],["77726.02000000","0.00633000"],["77729.46000000","0.10078000"],["77736.47000000","0.00007000"]]}}
{"type":"trade","received_at_ms":1788333205212,"data":{"e":"trade","E":1788333205379,"s":"BTCUSDT","t":6646666219,"p":"77724.00000000","q":"0.00080000","T":1788333205378,"m":false,"M":true}}
{"type":"trade","received_at_ms":1788333205212,"data":{"e":"trade","E":1788333205379,"s":"BTCUSDT","t":6646666220,"p":"77724.00000000","q":"0.00007000","T":1788333205378,"m":false,"M":true}}
{"type":"trade","received_at_ms":1788333205212,"data":{"e":"trade","E":1788333205379,"s":"BTCUSDT","t":6646666221,"p":"77724.00000000","q":"0.00007000","T":1788333205378,"m":false,"M":true}}
{"type":"trade","received_at_ms":1788333205212,"data":{"e":"trade","E":1788333205379,"s":"BTCUSDT","t":6646666222,"p":"77724.00000000","q":"0.00007000","T":1788333205378,"m":false,"M":true}}
{"type":"trade","received_at_ms":1788333205212,"data":{"e":"trade","E":1788333205379,"s":"BTCUSDT","t":6646666223,"p":"77724.00000000","q":"0.02473000","T":1788333205378,"m":false,"M":true}}
{"type":"depth","received_at_ms":1788333205247,"data":{"e":"depthUpdate","E":1788333205414,"s":"BTCUSDT","U":99556333975,"u":99556333983,"b":[["77714.32000000","0.00000000"],["77530.01000000","0.00811000"],["77528.01000000","0.00000000"],["69951.60000000","0.00432000"]],"a":[["77724.00000000","0.20693000"],["77734.99000000","0.08205000"]]}}
{"type":"depth","received_at_ms":1788333205346,"data":{"e":"depthUpdate","E":1788333205514,"s":"BTCUSDT","U":99556333984,"u":99556333991,"b":[["69951.60000000","0.00448000"],["69951.00000000","0.00078000"],["62179.20000000","0.00032000"],["62179.00000000","0.01200000"]],"a":[]}}
{"type":"depth","received_at_ms":1788333205446,"data":{"e":"depthUpdate","E":1788333205614,"s":"BTCUSDT","U":99556333992,"u":99556334004,"b":[["77716.20000000","0.02000000"],["77696.70000000","0.00000000"],["77669.13000000","0.00000000"],["69951.60000000","0.00432000"],["69951.00000000","0.00068000"],["62179.20000000","0.00000000"],["62179.19000000","0.00000000"]],"a":[["77738.62000000","0.00000000"],["77758.08000000","0.00000000"],["77777.54000000","0.00000000"]]}}
{"type":"depth","received_at_ms":1788333205548,"data":{"e":"depthUpdate","E":1788333205714,"s":"BTCUSDT","U":99556334005,"u":99556334012,"b":[["77715.95000000","0.02000000"],["77677.04000000","0.02000000"],["69951.60000000","0.00448000"],["69951.00000000","0.00088000"]],"a":[["77736.15000000","0.00000000"],["77742.34000000","0.03000000"],["77761.79000000","0.03000000"]]}}
{"type":"trade","received_at_ms":1788333205626,"data":{"e":"trade","E":1788333205792,"s":"BTCUSDT","t":6646666224,"p":"77723.99000000","q":"0.00206000","T":1788333205792,"m":true,"M":true}}
{"type":"depth","received_at_ms":1788333205652,"data":{"e":"depthUpdate","E":1788333205819,"s":"BTCUSDT","U":99556334013,"u":99556334020,"b":[["77723.99000000","2.20494000"],["77717.76000000","0.01986000"],["76994.94000000","0.00000000"],["69951.60000000","0.00432000"],["69951.59000000","0.00000000"],["69951.58000000","0.00009000"],["69951.00000000","0.00068000"]],"a":[]}}
{"type":"depth","received_at_ms":1788333205747,"data":{"e":"depthUpdate","E":1788333205914,"s":"BTCUSDT","U":99556334021,"u":99556334033,"b":[["76558.13000000","0.00030000"],["75557.14000000","0.00010000"],["69951.60000000","0.00448000"],["69951.00000000","0.00078000"]],"a":[["77734.95000000","0.00206000"],["77744.08000000","0.00014000"],["78889.86000000","0.00030000"]]}}
{"type":"trade","received_at_ms":1788333205844,"data":{"e":"trade","E":1788333206011,"s":"BTCUSDT","t":6646666225,"p":"77724.00000000","q":"0.02574000","T":1788333206010,"m":false,"M":true}}
{"type":"depth","received_at_ms":1788333205846,"data":{"e":"depthUpdate","E":1788333206014,"s":"BTCUSDT","U":99556334034,"u":99556334042,"b":[["76527.60000000","0.00000000"],["69951.60000000","0.00432000"],["69951.00000000","0.00068000"],["64000.00000000","54.50052000"],["62179.20000000","0.00032000"]],"a":[["77724.00000000","0.18119000"],["77744.07000000","0.00257000"]]}}
{"type":"trade","received_at_ms":1788333205898,"data":{"e":"trade","E":1788333206064,"s":"BTCUSDT","t":6646666226,"p":"77724.00000000","q":"0.02543000","T":1788333206064,"m":false,"M":true}}
{"type":"depth","received_at_ms":1788333205947,"data":{"e":"depthUpdate","E":1788333206114,"s":"BTCUSDT","U":99556334043,"u":99556334057,"b":[["77717.98000000","0.15277000"],["76527.77000000","0.00000000"],["69951.60000000","0.00448000"],["69951.58000000","0.00000000"]],"a":[["77724.00000000","0.15584000"],["77744.05000000","0.00000000"],["77744.07000000","0.00000000"],["77751.09000000","0.00000000"],["77791.47000000","0.00411000"],["77821.72000000","0.00000000"],["77824.31000000","4.08551000"]]}}
{"type":"depth","received_at_ms":1788333206047,"data":{"e":"depthUpdate","E":1788333206214,"s":"BTCUSDT","U":99556334058,"u":99556334087,"b":[["77723.99000000","2.50486000"],["77708.28000000","0.12875000"],["77699.19000000","0.00000000"],["77651.99000000","0.00024000"],["77024.47000000","0.00010000"],["76556.37000000","0.00000000"],["69951.60000000","0.00432000"],["62179.20000000","0.00000000"],["62179.19000000","0.00000000"]],"a":[["77724.00000000","0.02472000"],["77724.01000000","0.00097000"],["77726.00000000","0.03014000"],["77726.02000000","0.01233000"],["77726.20000000","0.00000000"],["77726.21000000","0.00014000"],["77728.10000000","0.00007000"],["77731.78000000","0.00000000"],["77736.24000000","0.11191000"],["77737.03000000","0.00400000"],["77737.36000000","0.00000000"],["77738.67000000","0.00643000"],["77744.03000000","0.00257000"],["77757.39000000","0.00000000"],["81001.15000000","0.00338000"]]}}
{"type":"depth","received_at_ms":1788333206147,"data":{"e":"depthUpdate","E":1788333206314,"s":"BTCUSDT","U":99556334088,"u":99556334112,"b":[["77712.77000000","0.32943000"],["77705.37000000","0.00000000"],["77703.92000000","0.00000000"],["69951.60000000","0.00432000"],["62179.00000000","0.01200000"]],"a":[["77726.02000000","0.01233000"],["77726.21000000","0.00000000"],["77729.46000000","0.10092000"],["77731.78000000","0.16870000"],["77736.47000000","0.00000000"],["77744.02000000","0.00266000"],["77744.03000000","0.00000000"],["77752.75000000","0.00411000"],["77756.17000000","0.00000000"],["77757.80000000","0.00000000"]]}}
{"type":"trade","received_at_ms":1788333206180,"data":{"e":"trade","E":1788333206347,"s":"BTCUSDT","t":6646666227,"p":"77723.99000000","q":"0.01299000","T":1788333206346,"m":true,"M":true}}
{"type":"depth","received_at_ms":1788333206247,"data":{"e":"depthUpdate","E":1788333206414,"s":"BTCUSDT","U":99556334113,"u":99556334136,"b":[["77723.99000000","2.49195000"],["77708.28000000","0.00007000"],["77705.37000000","0.00007000"],["77652.48000000","0.00321000"],["77652.46000000","0.00000000"],["69951.60000000","0.00432000"],["69951.59000000","0.00009000"]],"a":[["77724.00000000","0.02489000"],["77727.75000000","0.00014000"],["77727.76000000","0.13895000"],["77728.10000000","0.00000000"],["77736.47000000","0.00007000"],["77744.01000000","0.00257000"],["77744.02000000","0.00009000"],["77752.75000000","0.00000000"],["77791.47000000","0.00000000"],["77859.38000000","0.00388000"],["77860.05000000","0.00000000"]]}}
{"type":"depth","received_at_ms":1788333206347,"data":{"e":"depthUpdate","E":1788333206514,"s":"BTCUSDT","U":99556334137,"u":99556334157,"b":[["77716.13000000","0.00000000"],["77696.62000000","0.00000000"],["77669.05000000","0.00007000"],["77530.01000000","0.00000000"],["77528.64000000","0.00811000"],["69951.60000000","0.00432000"],["62179.20000000","0.00032000"]],"a":[["77726.74000000","0.10412000"],["77727.76000000","0.13909000"],["77729.46000000","0.10078000"],["77734.95000000","0.00000000"],["77734.99000000","0.00000000"],["77738.68000000","0.00000000"],["77744.01000000","0.00000000"],["77745.84000000","0.00257000"],["77758.13000000","0.00000000"],["77777.59000000","0.00000000"],["77791.65000000","0.00411000"]]}}
{"type":"depth","received_at_ms":1788333206447,"data":{"e":"depthUpdate","E":1788333206614,"s":"BTCUSDT","U":99556334158,"u":99556334171,"b":[["69951.60000000","0.00416000"],["62179.20000000","0.00000000"],["62179.19000000","0.00000000"],["62179.00000000","0.01200000"]],"a":[["77735.18000000","0.00000000"],["77735.84000000","0.00400000"],["77745.82000000","0.00257000"],["77745.84000000","0.00000000"],["77821.72000000","2.15325000"],["77824.31000000","1.93226000"]]}}
{"type":"trade","received_at_ms":1788333206476,"data":{"e":"trade","E":1788333206640,"s":"BTCUSDT","t":6646666228,"p":"77724.00000000","q":"0.02181000","T":1788333206640,"m":false,"M":true}}
{"type":"trade","received_at_ms":1788333206476,"data":{"e":"trade","E":1788333206640,"s":"BTCUSDT","t":6646666229,"p":"77724.00000000","q":"0.00007000","T":1788333206640,"m":false,"M":true}}
{"type":"trade","received_at_ms":1788333206476,"data":{"e":"trade","E":1788333206640,"s":"BTCUSDT","t":6646666230,"p":"77724.00000000","q":"0.00008000","T":1788333206640,"m":false,"M":true}}
{"type":"trade","received_at_ms":1788333206476,"data":{"e":"trade","E":1788333206640,"s":"BTCUSDT","t":6646666231,"p":"77724.00000000","q":"0.00007000","T":1788333206640,"m":false,"M":true}}
{"type":"trade","received_at_ms":1788333206476,"data":{"e":"trade","E":1788333206640,"s":"BTCUSDT","t":6646666232,"p":"77724.00000000","q":"0.00007000","T":1788333206640,"m":false,"M":true}}
{"type":"trade","received_at_ms":1788333206476,"data":{"e":"trade","E":1788333206640,"s":"BTCUSDT","t":6646666233,"p":"77724.00000000","q":"0.00007000","T":1788333206640,"m":false,"M":true}}
{"type":"trade","received_at_ms":1788333206476,"data":{"e":"trade","E":1788333206640,"s":"BTCUSDT","t":6646666234,"p":"77724.00000000","q":"0.00013000","T":1788333206640,"m":false,"M":true}}
{"type":"trade","received_at_ms":1788333206476,"data":{"e":"trade","E":1788333206640,"s":"BTCUSDT","t":6646666235,"p":"77724.00000000","q":"0.00007000","T":1788333206640,"m":false,"M":true}}
{"type":"trade","received_at_ms":1788333206476,"data":{"e":"trade","E":1788333206640,"s":"BTCUSDT","t":6646666236,"p":"77724.00000000","q":"0.00007000","T":1788333206640,"m":false,"M":true}}
{"type":"trade","received_at_ms":1788333206476,"data":{"e":"trade","E":1788333206640,"s":"BTCUSDT","t":6646666237,"p":"77724.00000000","q":"0.00007000","T":1788333206640,"m":false,"M":true}}
{"type":"trade","received_at_ms":1788333206476,"data":{"e":"trade","E":1788333206640,"s":"BTCUSDT","t":6646666238,"p":"77724.00000000","q":"0.00007000","T":1788333206640,"m":false,"M":true}}
{"type":"trade","received_at_ms":1788333206476,"data":{"e":"trade","E":1788333206640,"s":"BTCUSDT","t":6646666239,"p":"77724.00000000","q":"0.00007000","T":1788333206640,"m":false,"M":true}}
{"type":"trade","received_at_ms":1788333206476,"data":{"e":"trade","E":1788333206640,"s":"BTCUSDT","t":6646666240,"p":"77724.00000000","q":"0.00007000","T":1788333206640,"m":false,"M":true}}
{"type":"trade","received_at_ms":1788333206476,"data":{"e":"trade","E":1788333206640,"s":"BTCUSDT","t":6646666241,"p":"77724.00000000","q":"0.00007000","T":1788333206640,"m":false,"M":true}}
{"type":"trade","received_at_ms":1788333206476,"data":{"e":"trade","E":1788333206640,"s":"BTCUSDT","t":6646666242,"p":"77724.00000000","q":"0.00007000","T":1788333206640,"m":false,"M":true}}
{"type":"trade","received_at_ms":1788333206476,"data":{"e":"trade","E":1788333206640,"s":"BTCUSDT","t":6646666243,"p":"77724.00000000","q":"0.00007000","T":1788333206640,"m":false,"M":true}}
{"type":"trade","received_at_ms":1788333206476,"data":{"e":"trade","E":1788333206640,"s":"BTCUSDT","t":6646666244,"p":"77724.00000000","q":"0.00065000","T":1788333206640,"m":false,"M":true}}
{"type":"trade","received_at_ms":1788333206476,"data":{"e":"trade","E":1788333206640,"s":"BTCUSDT","t":6646666245,"p":"77724.00000000","q":"0.00064000","T":1788333206640,"m":false,"M":true}}
{"type":"trade","received_at_ms":1788333206476,"data":{"e":"trade","E":1788333206640,"s":"BTCUSDT","t":6646666246,"p":"77724.00000000","q":"0.00007000","T":1788333206640,"m":false,"M":true}}
{"type":"trade","received_at_ms":1788333206476,"data":{"e":"trade","E":1788333206640,"s":"BTCUSDT","t":6646666247,"p":"77724.00000000","q":"0.00007000","T":1788333206640,"m":false,"M":true}}
{"type":"trade","received_at_ms":1788333206476,"data":{"e":"trade","E":1788333206640,"s":"BTCUSDT","t":6646666248,"p":"77724.00000000","q":"0.00007000","T":1788333206640,"m":false,"M":true}}
{"type":"trade","received_at_ms":1788333206477,"data":{"e":"trade","E":1788333206640,"s":"BTCUSDT","t":6646666249,"p":"77724.00000000","q":"0.00007000","T":1788333206640,"m":false,"M":true}}
{"type":"trade","received_at_ms":1788333206477,"data":{"e":"trade","E":1788333206640,"s":"BTCUSDT","t":6646666250,"p":"77724.00000000","q":"0.00007000","T":1788333206640,"m":false,"M":true}}
{"type":"trade","received_at_ms":1788333206477,"data":{"e":"trade","E":1788333206640,"s":"BTCUSDT","t":6646666251,"p":"77724.00000000","q":"0.00007000","T":1788333206640,"m":false,"M":true}}
{"type":"trade","received_at_ms":1788333206477,"data":{"e":"trade","E":1788333206640,"s":"BTCUSDT","t":6646666252,"p":"77724.00000000","q":"0.00010000","T":1788333206640,"m":false,"M":true}}
{"type":"trade","received_at_ms":1788333206477,"data":{"e":"trade","E":1788333206640,"s":"BTCUSDT","t":6646666253,"p":"77724.00000000","q":"0.00008000","T":1788333206640,"m":false,"M":true}}
{"type":"trade","received_at_ms":1788333206477,"data":{"e":"trade","E":1788333206640,"s":"BTCUSDT","t":6646666254,"p":"77724.00000000","q":"0.00007000","T":1788333206640,"m":false,"M":true}}
{"type":"trade","received_at_ms":1788333206477,"data":{"e":"trade","E":1788333206640,"s":"BTCUSDT","t":6646666255,"p":"77724.01000000","q":"0.00007000","T":1788333206640,"m":false,"M":true}}
{"type":"trade","received_at_ms":1788333206477,"data":{"e":"trade","E":1788333206640,"s":"BTCUSDT","t":6646666256,"p":"77724.01000000","q":"0.00007000","T":1788333206640,"m":false,"M":true}}
{"type":"trade","received_at_ms":1788333206477,"data":{"e":"trade","E":1788333206640,"s":"BTCUSDT","t":6646666257,"p":"77724.01000000","q":"0.00013000","T":1788333206640,"m":false,"M":true}}
{"type":"trade","received_at_ms":1788333206477,"data":{"e":"trade","E":1788333206640,"s":"BTCUSDT","t":6646666258,"p":"77724.01000000","q":"0.00007000","T":1788333206640,"m":false,"M":true}}
{"type":"trade","received_at_ms":1788333206477,"data":{"e":"trade","E":1788333206640,"s":"BTCUSDT","t":6646666259,"p":"77724.01000000","q":"0.00007000","T":1788333206640,"m":false,"M":true}}
{"type":"trade","received_at_ms":1788333206477,"data":{"e":"trade","E":1788333206640,"s":"BTCUSDT","t":6646666260,"p":"77724.01000000","q":"0.00007000","T":1788333206640,"m":false,"M":true}}
{"type":"trade","received_at_ms":1788333206477,"data":{"e":"trade","E":1788333206640,"s":"BTCUSDT","t":6646666261,"p":"77724.01000000","q":"0.00007000","T":1788333206640,"m":false,"M":true}}
{"type":"trade","received_at_ms":1788333206477,"data":{"e":"trade","E":1788333206640,"s":"BTCUSDT","t":6646666262,"p":"77724.01000000","q":"0.00007000","T":1788333206640,"m":false,"M":true}}
{"type":"trade","received_at_ms":1788333206477,"data":{"e":"trade","E":1788333206640,"s":"BTCUSDT","t":6646666263,"p":"77724.01000000","q":"0.00007000","T":1788333206640,"m":false,"M":true}}
{"type":"trade","received_at_ms":1788333206477,"data":{"e":"trade","E":1788333206640,"s":"BTCUSDT","t":6646666264,"p":"77724.01000000","q":"0.00007000","T":1788333206640,"m":false,"M":true}}
{"type":"trade","received_at_ms":1788333206477,"data":{"e":"trade","E":1788333206640,"s":"BTCUSDT","t":6646666265,"p":"77724.01000000","q":"0.00007000","T":1788333206640,"m":false,"M":true}}
{"type":"trade","received_at_ms":1788333206477,"data":{"e":"trade","E":1788333206640,"s":"BTCUSDT","t":6646666266,"p":"77724.01000000","q":"0.00001000","T":1788333206640,"m":false,"M":true}}
{"type":"trade","received_at_ms":1788333206477,"data":{"e":"trade","E":1788333206642,"s":"BTCUSDT","t":6646666267,"p":"77724.01000000","q":"0.00006000","T":1788333206641,"m":false,"M":true}}
{"type":"trade","received_at_ms":1788333206477,"data":{"e":"trade","E":1788333206642,"s":"BTCUSDT","t":6646666268,"p":"77724.01000000","q":"0.00007000","T":1788333206641,"m":false,"M":true}}
{"type":"trade","received_at_ms":1788333206477,"data":{"e":"trade","E":1788333206642,"s":"BTCUSDT","t":6646666269,"p":"77724.01000000","q":"0.00007000","T":1788333206641,"m":false,"M":true}}
{"type":"trade","received_at_ms":1788333206477,"data":{"e":"trade","E":1788333206642,"s":"BTCUSDT","t":6646666270,"p":"77724.01000000","q":"0.00007000","T":1788333206641,"m":false,"M":true}}
{"type":"trade","received_at_ms":1788333206477,"data":{"e":"trade","E":1788333206642,"s":"BTCUSDT","t":6646666271,"p":"77724.02000000","q":"0.00006000","T":1788333206641,"m":false,"M":true}}
{"type":"trade","received_at_ms":1788333206484,"data":{"e":"trade","E":1788333206651,"s":"BTCUSDT","t":6646666272,"p":"77724.00000000","q":"0.03195000","T":1788333206650,"m":true,"M":true}}
{"type":"trade","received_at_ms":1788333206484,"data":{"e":"trade","E":1788333206651,"s":"BTCUSDT","t":6646666273,"p":"77724.00000000","q":"0.05123000","T":1788333206650,"m":true,"M":true}}
{"type":"depth","received_at_ms":1788333206550,"data":{"e":"depthUpdate","E":1788333206714,"s":"BTCUSDT","U":99556334172,"u":99556334440,"b":[["77724.00000000","7.24997000"],["77723.99000000","0.59823000"],["77723.98000000","0.00013000"],["77723.97000000","0.00000000"],["77723.96000000","0.00014000"],["77723.91000000","0.00000000"],["77723.90000000","0.00028000"],["77723.74000000","0.00400000"],["77723.42000000","0.00000000"],["77722.98000000","0.00400000"],["77722.77000000","0.00000000"],["77722.76000000","0.00028000"],["77722.69000000","0.00014000"],["77721.32000000","0.01321000"],["77720.08000000","0.02902000"],["77720.00000000","0.00007000"],["77719.88000000","0.00000000"],["77719.45000000","0.00000000"],["77719.43000000","0.00000000"],["77717.99000000","0.08298000"],["77715.81000000","0.02000000"],["77712.83000000","0.62746000"],["77712.06000000","0.00007000"],["77712.05000000","0.00000000"],["77676.90000000","0.02000000"],["77657.59000000","0.02000000"],["77648.00000000","0.03000000"],["77634.01000000","0.10680000"],["77631.80000000","0.00000000"],["77079.40000000","0.00000000"],["76558.13000000","0.00000000"],["69951.60000000","0.00000000"],["69951.59000000","0.00000000"],["69951.58000000","0.00009000"]],"a":[["77724.00000000","0.00000000"],["77724.01000000","0.00242000"],["77724.02000000","0.00084000"],["77724.03000000","0.00000000"],["77725.36000000","0.00000000"],["77725.37000000","0.00014000"],["77726.01000000","0.00014000"],["77728.00000000","0.03014000"],["77728.42000000","0.01281000"],["77731.78000000","0.00000000"],["77731.79000000","0.16870000"],["77733.87000000","0.32176000"],["77734.64000000","0.00000000"],["77735.51000000","0.00400000"],["77735.84000000","0.00000000"],["77736.77000000","0.00400000"],["77736.86000000","0.08205000"],["77736.90000000","0.00206000"],["77737.03000000","0.00000000"],["77742.36000000","0.02400000"],["77752.00000000","0.03007000"],["77752.77000000","0.00411000"],["77758.39000000","0.00007000"],["77761.82000000","0.02517000"],["77781.25000000","0.03000000"],["77781.27000000","0.02400000"],["77897.68000000","0.00000000"],["78889.86000000","0.00000000"]]}}
{"type":"depth","received_at_ms":1788333206654,"data":{"e":"depthUpdate","E":1788333206814,"s":"BTCUSDT","U":99556334441,"u":99556334482,"b":[["77723.99000000","0.56823000"],["77723.95000000","0.05021000"],["77723.90000000","0.00014000"],["77722.76000000","0.00014000"],["77721.32000000","0.01335000"],["77720.87000000","0.04105000"],["69951.60000000","0.00032000"],["69951.00000000","0.00068000"]],"a":[["77724.01000000","0.00249000"],["77724.02000000","0.00077000"],["77724.37000000","0.00014000"],["77725.37000000","0.00000000"],["77726.01000000","0.00000000"],["77726.02000000","0.00633000"],["77726.10000000","0.00690000"],["77728.10000000","0.00007000"],["77729.46000000","0.10092000"],["77730.00000000","0.03064000"],["77736.86000000","0.00000000"],["77736.87000000","0.07206000"],["77736.90000000","0.00000000"],["77743.78000000","0.00257000"],["77745.82000000","0.00000000"],["77752.77000000","0.00000000"],["77791.65000000","0.00000000"]]}}
{"type":"trade","received_at_ms":1788333206694,"data":{"e":"trade","E":1788333206859,"s":"BTCUSDT","t":6646666274,"p":"77724.01000000","q":"0.00007000","T":1788333206859,"m":false,"M":true}}
{"type":"trade","received_at_ms":1788333206695,"data":{"e":"trade","E":1788333206859,"s":"BTCUSDT","t":6646666275,"p":"77724.01000000","q":"0.00007000","T":1788333206859,"m":false,"M":true}}
{"type":"trade","received_at_ms":1788333206695,"data":{"e":"trade","E":1788333206859,"s":"BTCUSDT","t":6646666276,"p":"77724.01000000","q":"0.00007000","T":1788333206859,"m":false,"M":true}}
{"type":"trade","received_at_ms":1788333206695,"data":{"e":"trade","E":1788333206859,"s":"BTCUSDT","t":6646666277,"p":"77724.01000000","q":"0.00007000","T":1788333206859,"m":false,"M":true}}
{"type":"trade","received_at_ms":1788333206695,"data":{"e":"trade","E":1788333206859,"s":"BTCUSDT","t":6646666278,"p":"77724.01000000","q":"0.00007000","T":1788333206859,"m":false,"M":true}}
{"type":"trade","received_at_ms":1788333206695,"data":{"e":"trade","E":1788333206859,"s":"BTCUSDT","t":6646666279,"p":"77724.01000000","q":"0.00007000","T":1788333206859,"m":false,"M":true}}
{"type":"trade","received_at_ms":1788333206695,"data":{"e":"trade","E":1788333206859,"s":"BTCUSDT","t":6646666280,"p":"77724.01000000","q":"0.00007000","T":1788333206859,"m":false,"M":true}}
{"type":"trade","received_at_ms":1788333206695,"data":{"e":"trade","E":1788333206859,"s":"BTCUSDT","t":6646666281,"p":"77724.01000000","q":"0.00007000","T":1788333206859,"m":false,"M":true}}
{"type":"trade","received_at_ms":1788333206695,"data":{"e":"trade","E":1788333206859,"s":"BTCUSDT","t":6646666282,"p":"77724.01000000","q":"0.00007000","T":1788333206859,"m":false,"M":true}}
{"type":"trade","received_at_ms":1788333206695,"data":{"e":"trade","E":1788333206859,"s":"BTCUSDT","t":6646666283,"p":"77724.01000000","q":"0.00007000","T":1788333206859,"m":false,"M":true}}
{"type":"trade","received_at_ms":1788333206695,"data":{"e":"trade","E":1788333206859,"s":"BTCUSDT","t":6646666284,"p":"77724.01000000","q":"0.00007000","T":1788333206859,"m":false,"M":true}}
{"type":"trade","received_at_ms":1788333206695,"data":{"e":"trade","E":1788333206859,"s":"BTCUSDT","t":6646666285,"p":"77724.01000000","q":"0.00064000","T":1788333206859,"m":false,"M":true}}
{"type":"trade","received_at_ms":1788333206695,"data":{"e":"trade","E":1788333206859,"s":"BTCUSDT","t":6646666286,"p":"77724.01000000","q":"0.00007000","T":1788333206859,"m":false,"M":true}}
{"type":"trade","received_at_ms":1788333206695,"data":{"e":"trade","E":1788333206859,"s":"BTCUSDT","t":6646666287,"p":"77724.01000000","q":"0.00065000","T":1788333206859,"m":false,"M":true}}
{"type":"trade","received_at_ms":1788333206695,"data":{"e":"trade","E":1788333206859,"s":"BTCUSDT","t":6646666288,"p":"77724.01000000","q":"0.00007000","T":1788333206859,"m":false,"M":true}}
{"type":"trade","received_at_ms":1788333206695,"data":{"e":"trade","E":1788333206859,"s":"BTCUSDT","t":6646666289,"p":"77724.01000000","q":"0.00007000","T":1788333206859,"m":false,"M":true}}
{"type":"trade","received_at_ms":1788333206695,"data":{"e":"trade","E":1788333206859,"s":"BTCUSDT","t":6646666290,"p":"77724.01000000","q":"0.00008000","T":1788333206859,"m":false,"M":true}}
{"type":"trade","received_at_ms":1788333206695,"data":{"e":"trade","E":1788333206859,"s":"BTCUSDT","t":6646666291,"p":"77724.01000000","q":"0.00007000","T":1788333206859,"m":false,"M":true}}
{"type":"trade","received_at_ms":1788333206695,"data":{"e":"trade","E":1788333206859,"s":"BTCUSDT","t":6646666292,"p":"77724.01000000","q":"0.00007000","T":1788333206859,"m":false,"M":true}}
{"type":"trade","received_at_ms":1788333206695,"data":{"e":"trade","E":1788333206859,"s":"BTCUSDT","t":6646666293,"p":"77724.02000000","q":"0.00007000","T":1788333206859,"m":false,"M":true}}
{"type":"trade","received_at_ms":1788333206695,"data":{"e":"trade","E":1788333206859,"s":"BTCUSDT","t":6646666294,"p":"77724.02000000","q":"0.00007000","T":1788333206859,"m":false,"M":true}}
{"type":"trade","received_at_ms":1788333206695,"data":{"e":"trade","E":1788333206859,"s":"BTCUSDT","t":6646666295,"p":"77724.02000000","q":"0.00007000","T":1788333206859,"m":false,"M":true}}
{"type":"trade","received_at_ms":1788333206695,"data":{"e":"trade","E":1788333206859,"s":"BTCUSDT","t":6646666296,"p":"77724.02000000","q":"0.00007000","T":1788333206859,"m":false,"M":true}}
{"type":"trade","received_at_ms":1788333206695,"data":{"e":"trade","E":1788333206859,"s":"BTCUSDT","t":6646666297,"p":"77724.02000000","q":"0.00007000","T":1788333206859,"m":false,"M":true}}
{"type":"trade","received_at_ms":1788333206695,"data":{"e":"trade","E":1788333206859,"s":"BTCUSDT","t":6646666298,"p":"77724.02000000","q":"0.00007000","T":1788333206859,"m":false,"M":true}}
{"type":"trade","received_at_ms":1788333206695,"data":{"e":"trade","E":1788333206859,"s":"BTCUSDT","t":6646666299,"p":"77724.02000000","q":"0.00007000","T":1788333206859,"m":false,"M":true}}
{"type":"trade","received_at_ms":1788333206695,"data":{"e":"trade","E":1788333206859,"s":"BTCUSDT","t":6646666300,"p":"77724.02000000","q":"0.00007000","T":1788333206859,"m":false,"M":true}}
{"type":"trade","received_at_ms":1788333206695,"data":{"e":"trade","E":1788333206859,"s":"BTCUSDT","t":6646666301,"p":"77724.02000000","q":"0.00007000","T":1788333206859,"m":false,"M":true}}
{"type":"trade","received_at_ms":1788333206695,"data":{"e":"trade","E":1788333206859,"s":"BTCUSDT","t":6646666302,"p":"77724.02000000","q":"0.00007000","T":1788333206859,"m":false,"M":true}}
{"type":"trade","received_at_ms":1788333206695,"data":{"e":"trade","E":1788333206859,"s":"BTCUSDT","t":6646666303,"p":"77724.02000000","q":"0.00007000","T":1788333206859,"m":false,"M":true}}
{"type":"trade","received_at_ms":1788333206695,"data":{"e":"trade","E":1788333206859,"s":"BTCUSDT","t":6646666304,"p":"77724.37000000","q":"0.00014000","T":1788333206859,"m":false,"M":true}}
{"type":"trade","received_at_ms":1788333206695,"data":{"e":"trade","E":1788333206859,"s":"BTCUSDT","t":6646666305,"p":"77724.38000000","q":"0.00007000","T":1788333206859,"m":false,"M":true}}
{"type":"trade","received_at_ms":1788333206695,"data":{"e":"trade","E":1788333206859,"s":"BTCUSDT","t":6646666306,"p":"77725.00000000","q":"0.00024000","T":1788333206859,"m":false,"M":true}}
{"type":"trade","received_at_ms":1788333206695,"data":{"e":"trade","E":1788333206859,"s":"BTCUSDT","t":6646666307,"p":"77725.00000000","q":"0.00221000","T":1788333206859,"m":false,"M":true}}
{"type":"trade","received_at_ms":1788333206695,"data":{"e":"trade","E":1788333206859,"s":"BTCUSDT","t":6646666308,"p":"77725.99000000","q":"0.00007000","T":1788333206859,"m":false,"M":true}}
{"type":"trade","received_at_ms":1788333206695,"data":{"e":"trade","E":1788333206859,"s":"BTCUSDT","t":6646666309,"p":"77725.99000000","q":"0.00007000","T":1788333206859,"m":false,"M":true}}
{"type":"trade","received_at_ms":1788333206695,"data":{"e":"trade","E":1788333206859,"s":"BTCUSDT","t":6646666310,"p":"77725.99000000","q":"0.00007000","T":1788333206859,"m":false,"M":true}}
{"type":"trade","received_at_ms":1788333206695,"data":{"e":"trade","E":1788333206859,"s":"BTCUSDT","t":6646666311,"p":"77726.00000000","q":"0.01000000","T":1788333206859,"m":false,"M":true}}
{"type":"trade","received_at_ms":1788333206695,"data":{"e":"trade","E":1788333206859,"s":"BTCUSDT","t":6646666312,"p":"77726.00000000","q":"0.00322000","T":1788333206859,"m":false,"M":true}}
{"type":"depth","received_at_ms":1788333206748,"data":{"e":"depthUpdate","E":1788333206914,"s":"BTCUSDT","U":99556334483,"u":99556334843,"b":[["77725.99000000","4.36445000"],["77725.98000000","0.00027000"],["77725.97000000","0.00013000"],["77725.81000000","0.00014000"],["77725.80000000","0.05007000"],["77725.76000000","0.00007000"],["77725.75000000","0.05000000"],["77725.00000000","0.00014000"],["77724.99000000","0.30007000"],["77724.61000000","0.00000000"],["77724.38000000","0.00014000"],["77724.02000000","0.00014000"],["77724.01000000","3.21795000"],["77724.00000000","5.20643000"],["77723.99000000","0.45508000"],["77723.98000000","0.00000000"],["77723.96000000","0.00000000"],["77723.95000000","0.00021000"],["77723.90000000","0.00007000"],["77723.74000000","0.00000000"],["77723.32000000","0.01308000"],["77722.98000000","0.00000000"],["77722.76000000","0.00000000"],["77722.75000000","0.00014000"],["77722.74000000","0.01793000"],["77722.69000000","0.00000000"],["77721.32000000","0.00014000"],["77720.87000000","0.00007000"],["77720.32000000","0.00007000"],["77720.17000000","0.00013000"],["77719.99000000","0.00000000"],["77719.20000000","0.00400000"],["77718.22000000","0.00008000"],["77718.21000000","0.00060000"],["77718.20000000","0.00000000"],["77718.17000000","0.00000000"],["77717.85000000","0.00007000"],["77717.58000000","0.00010000"],["77717.19000000","0.09831000"],["77716.29000000","0.00007000"],["77715.77000000","0.00000000"],["77714.05000000","0.00007000"],["77712.83000000","0.00000000"],["77712.06000000","0.00000000"],["77710.44000000","0.00008000"],["77708.52000000","0.00000000"],["77706.56000000","0.00008000"],["77706.45000000","0.00000000"],["77703.35000000","0.00007000"],["77702.67000000","0.00008000"],["77702.56000000","0.00000000"],["77698.79000000","0.00008000"],["77698.67000000","0.00000000"],["77698.47000000","0.00257000"],["77694.90000000","1.93234000"],["77694.79000000","0.00000000"],["77691.01000000","0.00008000"],["77690.90000000","0.00000000"],["77687.80000000","0.00007000"],["77687.13000000","0.00008000"],["77687.02000000","0.00000000"],["77683.13000000","0.00000000"],["77672.25000000","0.00007000"],["77660.95000000","0.00000000"],["77656.70000000","0.00007000"],["77654.01000000","0.00318000"],["77652.47000000","0.00000000"],["77641.15000000","0.00007000"],["77639.10000000","0.00000000"],["77637.05000000","1.88929000"],["77625.60000000","0.00007000"],["77618.94000000","0.00000000"],["77610.05000000","0.00007000"],["77606.76000000","0.00000000"],["77603.41000000","0.00000000"],["77600.00000000","0.03823000"],["77594.50000000","0.00007000"],["77591.22000000","0.00000000"],["77587.88000000","0.00000000"],["77584.48000000","0.00008000"],["77578.95000000","0.00007000"],["77577.51000000","0.00128000"],["77575.68000000","0.00000000"],["77575.46000000","0.00000000"],["77572.35000000","0.00000000"],["77563.40000000","0.00007000"],["77563.18000000","0.00000000"],["77560.14000000","0.00000000"],["77556.67000000","0.00000000"],["77547.85000000","0.00007000"],["77544.60000000","0.00000000"],["77532.30000000","0.00007000"],["77529.06000000","0.00000000"],["77516.75000000","0.00007000"],["77513.52000000","0.00010000"],["77501.20000000","0.00007000"],["77500.00000000","1.61296000"],["77497.98000000","0.00000000"],["77485.65000000","0.00007000"],["77482.44000000","0.00000000"],["76701.10000000","0.00000000"],["76560.10000000","0.00030000"],["69951.60000000","0.00000000"],["62179.00000000","0.01200000"]],"a":[["77724.01000000","0.00000000"],["77724.02000000","0.00000000"],["77724.37000000","0.00000000"],["77724.38000000","0.00000000"],["77725.00000000","0.00000000"],["77725.99000000","0.00000000"],["77726.00000000","0.30179000"],["77726.01000000","0.00063000"],["77726.02000000","0.00033000"],["77726.10000000","0.00704000"],["77726.42000000","0.00611000"],["77726.73000000","0.00000000"],["77726.74000000","0.00014000"],["77728.10000000","0.00014000"],["77729.38000000","0.00000000"],["77729.45000000","0.00014000"],["77729.54000000","0.00000000"],["77729.82000000","0.00000000"],["77729.99000000","0.00007000"],["77730.00000000","0.03050000"],["77731.77000000","0.00000000"],["77731.82000000","0.00013000"],["77733.77000000","0.00008000"],["77734.54000000","0.00000000"],["77734.68000000","0.08205000"],["77734.69000000","0.00000000"],["77735.51000000","0.00000000"],["77736.77000000","0.00000000"],["77736.87000000","0.07000000"],["77737.06000000","0.00400000"],["77737.42000000","0.00000000"],["77737.99000000","0.00400000"],["77741.31000000","0.00000000"],["77741.38000000","0.00000000"],["77741.55000000","0.00016000"],["77742.52000000","0.00152000"],["77743.75000000","0.00000000"],["77743.78000000","0.00000000"],["77744.86000000","0.00257000"],["77745.20000000","0.00000000"],["77745.43000000","0.00008000"],["77749.08000000","0.00000000"],["77749.32000000","0.00008000"],["77751.34000000","0.12861000"],["77752.97000000","0.00000000"],["77753.20000000","0.00008000"],["77756.85000000","0.00000000"],["77757.07000000","0.00000000"],["77757.09000000","0.00008000"],["77758.73000000","0.09625000"],["77760.72000000","0.00000000"],["77760.74000000","0.00000000"],["77760.98000000","0.00008000"],["77763.00000000","0.00000000"],["77763.78000000","0.00014000"],["77764.86000000","0.00008000"],["77765.00000000","0.01000000"],["77766.72000000","0.00000000"],["77766.75000000","0.00000000"],["77780.91000000","0.00000000"],["77783.33000000","0.00320000"],["77839.86000000","0.00000000"],["77855.40000000","0.00000000"],["77859.38000000","0.00260000"],["77861.97000000","0.00128000"],["77870.94000000","0.00000000"],["77886.48000000","0.00000000"],["77902.02000000","0.00000000"],["77917.56000000","0.00000000"],["77933.10000000","0.00000000"],["77948.64000000","0.00000000"],["78021.53000000","0.00007000"],["78891.89000000","0.00037000"]]}}
{"type":"depth","received_at_ms":1788333206850,"data":{"e":"depthUpdate","E":1788333207014,"s":"BTCUSDT","U":99556334844,"u":99556334966,"b":[["77725.99000000","4.36244000"],["77725.81000000","0.00000000"],["77725.80000000","0.00021000"],["77725.76000000","0.00000000"],["77725.75000000","0.00014000"],["77725.71000000","0.00014000"],["77725.70000000","0.05007000"],["77725.67000000","0.00643000"],["77725.66000000","0.00007000"],["77725.65000000","0.05000000"],["77725.01000000","0.00643000"],["77724.99000000","0.30028000"],["77724.02000000","0.01414000"],["77724.01000000","2.88849000"],["77724.00000000","4.84040000"],["77723.99000000","0.45450000"],["77723.95000000","0.00000000"],["77723.90000000","0.00000000"],["77723.39000000","0.00058000"],["77722.75000000","0.00000000"],["77722.74000000","0.00021000"],["77722.68000000","0.37338000"],["77722.46000000","0.00000000"],["77721.99000000","0.00186000"],["77721.50000000","0.00000000"],["77720.86000000","0.00000000"],["77720.43000000","0.00000000"],["77720.25000000","0.00021000"],["77720.08000000","0.02895000"],["77719.44000000","0.00000000"],["77719.41000000","1.93226000"],["77718.21000000","0.00090000"],["77717.98000000","0.15263000"],["77716.21000000","0.00000000"],["77708.44000000","0.00000000"],["77700.67000000","0.00000000"],["77692.90000000","0.00000000"],["77687.00000000","0.01000000"],["77685.00000000","0.00000000"],["77672.92000000","0.00435000"],["77607.76000000","0.00000000"],["77509.94000000","0.00000000"],["69953.40000000","0.00032000"],["62180.80000000","0.00032000"]],"a":[["77726.00000000","0.30207000"],["77726.02000000","0.00019000"],["77726.10000000","0.00704000"],["77726.42000000","0.00625000"],["77726.74000000","0.00000000"],["77729.03000000","0.00000000"],["77730.00000000","0.03064000"],["77730.28000000","0.00000000"],["77731.52000000","0.00000000"],["77732.77000000","0.00000000"],["77735.79000000","0.00000000"],["77736.68000000","0.00643000"],["77738.67000000","0.00000000"],["77739.26000000","0.00643000"],["77744.84000000","0.00257000"],["77744.86000000","0.00000000"],["77750.00000000","0.05104000"],["77765.55000000","0.00007000"],["77775.76000000","0.00435000"],["77775.84000000","0.00426000"],["77781.10000000","0.00007000"],["77796.65000000","0.00007000"],["77812.20000000","0.00007000"],["77821.72000000","0.00000000"],["77824.31000000","4.08551000"],["77827.75000000","0.00007000"],["77843.30000000","0.00007000"],["77858.85000000","0.00007000"],["77874.40000000","0.00019000"],["77889.95000000","0.00007000"],["77905.50000000","0.00007000"],["77921.05000000","0.00007000"]]}}
{"type":"trade","received_at_ms":1788333206872,"data":{"e":"trade","E":1788333207035,"s":"BTCUSDT","t":6646666313,"p":"77726.00000000","q":"0.00178000","T":1788333207035,"m":false,"M":true}}
{"type":"trade","received_at_ms":1788333206872,"data":{"e":"trade","E":1788333207035,"s":"BTCUSDT","t":6646666314,"p":"77726.00000000","q":"0.00500000","T":1788333207035,"m":false,"M":true}}
{"type":"trade","received_at_ms":1788333206872,"data":{"e":"trade","E":1788333207035,"s":"BTCUSDT","t":6646666315,"p":"77726.00000000","q":"0.01000000","T":1788333207035,"m":false,"M":true}}
{"type":"trade","received_at_ms":1788333206872,"data":{"e":"trade","E":1788333207035,"s":"BTCUSDT","t":6646666316,"p":"77726.00000000","q":"0.00007000","T":1788333207035,"m":false,"M":true}}
{"type":"trade","received_at_ms":1788333206872,"data":{"e":"trade","E":1788333207035,"s":"BTCUSDT","t":6646666317,"p":"77726.00000000","q":"0.00007000","T":1788333207035,"m":false,"M":true}}
{"type":"trade","received_at_ms":1788333206872,"data":{"e":"trade","E":1788333207035,"s":"BTCUSDT","t":6646666318,"p":"77726.00000000","q":"0.00007000","T":1788333207035,"m":false,"M":true}}
{"type":"trade","received_at_ms":1788333206872,"data":{"e":"trade","E":1788333207035,"s":"BTCUSDT","t":6646666319,"p":"77726.00000000","q":"0.00007000","T":1788333207035,"m":false,"M":true}}
{"type":"trade","received_at_ms":1788333206872,"data":{"e":"trade","E":1788333207035,"s":"BTCUSDT","t":6646666320,"p":"77726.00000000","q":"0.00007000","T":1788333207035,"m":false,"M":true}}
{"type":"trade","received_at_ms":1788333206872,"data":{"e":"trade","E":1788333207035,"s":"BTCUSDT","t":6646666321,"p":"77726.00000000","q":"0.00007000","T":1788333207035,"m":false,"M":true}}
{"type":"trade","received_at_ms":1788333206872,"data":{"e":"trade","E":1788333207035,"s":"BTCUSDT","t":6646666322,"p":"77726.00000000","q":"0.00007000","T":1788333207035,"m":false,"M":true}}
{"type":"trade","received_at_ms":1788333206872,"data":{"e":"trade","E":1788333207035,"s":"BTCUSDT","t":6646666323,"p":"77726.00000000","q":"0.00007000","T":1788333207035,"m":false,"M":true}}
{"type":"trade","received_at_ms":1788333206872,"data":{"e":"trade","E":1788333207035,"s":"BTCUSDT","t":6646666324,"p":"77726.00000000","q":"0.00007000","T":1788333207035,"m":false,"M":true}}
{"type":"trade","received_at_ms":1788333206872,"data":{"e":"trade","E":1788333207035,"s":"BTCUSDT","t":6646666325,"p":"77726.00000000","q":"0.00007000","T":1788333207035,"m":false,"M":true}}
{"type":"trade","received_at_ms":1788333206872,"data":{"e":"trade","E":1788333207035,"s":"BTCUSDT","t":6646666326,"p":"77726.00000000","q":"0.00007000","T":1788333207035,"m":false,"M":true}}
{"type":"trade","received_at_ms":1788333206872,"data":{"e":"trade","E":1788333207035,"s":"BTCUSDT","t":6646666327,"p":"77726.00000000","q":"0.00007000","T":1788333207035,"m":false,"M":true}}
{"type":"trade","received_at_ms":1788333206872,"data":{"e":"trade","E":1788333207035,"s":"BTCUSDT","t":6646666328,"p":"77726.00000000","q":"0.00007000","T":1788333207035,"m":false,"M":true}}
{"type":"trade","received_at_ms":1788333206872,"data":{"e":"trade","E":1788333207035,"s":"BTCUSDT","t":6646666329,"p":"77726.00000000","q":"0.00007000","T":1788333207035,"m":false,"M":true}}
{"type":"trade","received_at_ms":1788333206872,"data":{"e":"trade","E":1788333207035,"s":"BTCUSDT","t":6646666330,"p":"77726.00000000","q":"0.00065000","T":1788333207035,"m":false,"M":true}}
{"type":"trade","received_at_ms":1788333206872,"data":{"e":"trade","E":1788333207035,"s":"BTCUSDT","t":6646666331,"p":"77726.00000000","q":"0.00064000","T":1788333207035,"m":false,"M":true}}
{"type":"trade","received_at_ms":1788333206872,"data":{"e":"trade","E":1788333207035,"s":"BTCUSDT","t":6646666332,"p":"77726.00000000","q":"0.00007000","T":1788333207035,"m":false,"M":true}}
{"type":"trade","received_at_ms":1788333206872,"data":{"e":"trade","E":1788333207035,"s":"BTCUSDT","t":6646666333,"p":"77726.00000000","q":"0.00007000","T":1788333207035,"m":false,"M":true}}
{"type":"trade","received_at_ms":1788333206872,"data":{"e":"trade","E":1788333207035,"s":"BTCUSDT","t":6646666334,"p":"77726.00000000","q":"0.00007000","T":1788333207035,"m":false,"M":true}}
{"type":"trade","received_at_ms":1788333206872,"data":{"e":"trade","E":1788333207035,"s":"BTCUSDT","t":6646666335,"p":"77726.00000000","q":"0.00008000","T":1788333207035,"m":false,"M":true}}
{"type":"trade","received_at_ms":1788333206872,"data":{"e":"trade","E":1788333207035,"s":"BTCUSDT","t":6646666336,"p":"77726.00000000","q":"0.00014000","T":1788333207035,"m":false,"M":true}}
{"type":"trade","received_at_ms":1788333206872,"data":{"e":"trade","E":1788333207035,"s":"BTCUSDT","t":6646666337,"p":"77726.00000000","q":"0.00007000","T":1788333207035,"m":false,"M":true}}
{"type":"trade","received_at_ms":1788333206872,"data":{"e":"trade","E":1788333207035,"s":"BTCUSDT","t":6646666338,"p":"77726.00000000","q":"0.00007000","T":1788333207035,"m":false,"M":true}}
{"type":"trade","received_at_ms":1788333206872,"data":{"e":"trade","E":1788333207035,"s":"BTCUSDT","t":6646666339,"p":"77726.00000000","q":"0.00007000","T":1788333207035,"m":false,"M":true}}
{"type":"trade","received_at_ms":1788333206872,"data":{"e":"trade","E":1788333207035,"s":"BTCUSDT","t":6646666340,"p":"77726.00000000","q":"0.13391000","T":1788333207035,"m":false,"M":true}}
{"type":"trade","received_at_ms":1788333206872,"data":{"e":"trade","E":1788333207035,"s":"BTCUSDT","t":6646666341,"p":"77726.01000000","q":"0.00007000","T":1788333207035,"m":false,"M":true}}
{"type":"trade","received_at_ms":1788333206872,"data":{"e":"trade","E":1788333207035,"s":"BTCUSDT","t":6646666342,"p":"77726.01000000","q":"0.00007000","T":1788333207035,"m":false,"M":true}}
{"type":"trade","received_at_ms":1788333206872,"data":{"e":"trade","E":1788333207035,"s":"BTCUSDT","t":6646666343,"p":"77726.01000000","q":"0.00007000","T":1788333207035,"m":false,"M":true}}
{"type":"trade","received_at_ms":1788333206872,"data":{"e":"trade","E":1788333207035,"s":"BTCUSDT","t":6646666344,"p":"77726.01000000","q":"0.00007000","T":1788333207035,"m":false,"M":true}}
{"type":"trade","received_at_ms":1788333206872,"data":{"e":"trade","E":1788333207035,"s":"BTCUSDT","t":6646666345,"p":"77726.01000000","q":"0.00007000","T":1788333207035,"m":false,"M":true}}
{"type":"trade","received_at_ms":1788333206872,"data":{"e":"trade","E":1788333207035,"s":"BTCUSDT","t":6646666346,"p":"77726.01000000","q":"0.00007000","T":1788333207035,"m":false,"M":true}}
{"type":"trade","received_at_ms":1788333206872,"data":{"e":"trade","E":1788333207035,"s":"BTCUSDT","t":6646666347,"p":"77726.01000000","q":"0.00007000","T":1788333207035,"m":false,"M":true}}
{"type":"trade","received_at_ms":1788333206872,"data":{"e":"trade","E":1788333207035,"s":"BTCUSDT","t":6646666348,"p":"77726.01000000","q":"0.00007000","T":1788333207035,"m":false,"M":true}}
{"type":"trade","received_at_ms":1788333206872,"data":{"e":"trade","E":1788333207035,"s":"BTCUSDT","t":6646666349,"p":"77726.01000000","q":"0.00007000","T":1788333207035,"m":false,"M":true}}
{"type":"trade","received_at_ms":1788333206872,"data":{"e":"trade","E":1788333207035,"s":"BTCUSDT","t":6646666350,"p":"77726.02000000","q":"0.00008000","T":1788333207035,"m":false,"M":true}}
{"type":"trade","received_at_ms":1788333206872,"data":{"e":"trade","E":1788333207035,"s":"BTCUSDT","t":6646666351,"p":"77726.02000000","q":"0.00011000","T":1788333207035,"m":false,"M":true}}
{"type":"trade","received_at_ms":1788333206872,"data":{"e":"trade","E":1788333207035,"s":"BTCUSDT","t":6646666352,"p":"77726.10000000","q":"0.00090000","T":1788333207035,"m":false,"M":true}}
{"type":"trade","received_at_ms":1788333206872,"data":{"e":"trade","E":1788333207035,"s":"BTCUSDT","t":6646666353,"p":"77726.10000000","q":"0.00600000","T":1788333207035,"m":false,"M":true}}
{"type":"trade","received_at_ms":1788333206872,"data":{"e":"trade","E":1788333207035,"s":"BTCUSDT","t":6646666354,"p":"77726.10000000","q":"0.00007000","T":1788333207035,"m":false,"M":true}}
{"type":"trade","received_at_ms":1788333206872,"data":{"e":"trade","E":1788333207035,"s":"BTCUSDT","t":6646666355,"p":"77726.10000000","q":"0.00007000","T":1788333207035,"m":false,"M":true}}
{"type":"trade","received_at_ms":1788333206872,"data":{"e":"trade","E":1788333207035,"s":"BTCUSDT","t":6646666356,"p":"77726.42000000","q":"0.00011000","T":1788333207035,"m":false,"M":true}}
{"type":"trade","received_at_ms":1788333206872,"data":{"e":"trade","E":1788333207035,"s":"BTCUSDT","t":6646666357,"p":"77726.42000000","q":"0.00600000","T":1788333207035,"m":false,"M":true}}
{"type":"trade","received_at_ms":1788333206872,"data":{"e":"trade","E":1788333207035,"s":"BTCUSDT","t":6646666358,"p":"77726.42000000","q":"0.00007000","T":1788333207035,"m":false,"M":true}}
{"type":"trade","received_at_ms":1788333206872,"data":{"e":"trade","E":1788333207035,"s":"BTCUSDT","t":6646666359,"p":"77726.42000000","q":"0.00007000","T":1788333207035,"m":false,"M":true}}
{"type":"trade","received_at_ms":1788333206872,"data":{"e":"trade","E":1788333207035,"s":"BTCUSDT","t":6646666360,"p":"77726.49000000","q":"0.00060000","T":1788333207035,"m":false,"M":true}}
{"type":"trade","received_at_ms":1788333206872,"data":{"e":"trade","E":1788333207035,"s":"BTCUSDT","t":6646666361,"p":"77726.98000000","q":"0.00128000","T":1788333207035,"m":false,"M":true}}
{"type":"trade","received_at_ms":1788333206872,"data":{"e":"trade","E":1788333207035,"s":"BTCUSDT","t":6646666362,"p":"77727.24000000","q":"0.00010000","T":1788333207035,"m":false,"M":true}}
{"type":"trade","received_at_ms":1788333206872,"data":{"e":"trade","E":1788333207035,"s":"BTCUSDT","t":6646666363,"p":"77727.27000000","q":"0.00055000","T":1788333207035,"m":false,"M":true}}
{"type":"trade","received_at_ms":1788333206872,"data":{"e":"trade","E":1788333207035,"s":"BTCUSDT","t":6646666364,"p":"77727.27000000","q":"0.00034000","T":1788333207035,"m":false,"M":true}}
{"type":"trade","received_at_ms":1788333206872,"data":{"e":"trade","E":1788333207035,"s":"BTCUSDT","t":6646666365,"p":"77727.27000000","q":"0.00068000","T":1788333207035,"m":false,"M":true}}
{"type":"trade","received_at_ms":1788333206872,"data":{"e":"trade","E":1788333207035,"s":"BTCUSDT","t":6646666366,"p":"77727.30000000","q":"0.00321000","T":1788333207035,"m":false,"M":true}}
{"type":"trade","received_at_ms":1788333206873,"data":{"e":"trade","E":1788333207035,"s":"BTCUSDT","t":6646666367,"p":"77727.60000000","q":"0.00007000","T":1788333207035,"m":false,"M":true}}
{"type":"trade","received_at_ms":1788333206873,"data":{"e":"trade","E":1788333207035,"s":"BTCUSDT","t":6646666368,"p":"77727.75000000","q":"0.00007000","T":1788333207035,"m":false,"M":true}}
{"type":"trade","received_at_ms":1788333206873,"data":{"e":"trade","E":1788333207035,"s":"BTCUSDT","t":6646666369,"p":"77727.75000000","q":"0.00007000","T":1788333207035,"m":false,"M":true}}
{"type":"trade","received_at_ms":1788333206873,"data":{"e":"trade","E":1788333207035,"s":"BTCUSDT","t":6646666370,"p":"77727.75000000","q":"0.00007000","T":1788333207035,"m":false,"M":true}}
{"type":"depth","received_at_ms":1788333206947,"data":{"e":"depthUpdate","E":1788333207114,"s":"BTCUSDT","U":99556334967,"u":99556335355,"b":[["77727.75000000","4.13623000"],["77727.74000000","0.00027000"],["77727.73000000","0.00013000"],["77727.29000000","0.00000000"],["77727.26000000","0.00000000"],["77726.66000000","0.00014000"],["77726.65000000","0.05007000"],["77726.61000000","0.00007000"],["77726.60000000","0.05000000"],["77726.41000000","0.00000000"],["77726.35000000","0.00000000"],["77726.09000000","0.00000000"],["77726.01000000","0.00014000"],["77726.00000000","0.20582000"],["77725.99000000","0.69032000"],["77725.98000000","0.00000000"],["77725.97000000","0.00000000"],["77725.80000000","0.00000000"],["77725.75000000","0.00000000"],["77725.71000000","0.00000000"],["77725.70000000","0.00028000"],["77725.67000000","0.00014000"],["77725.66000000","0.00000000"],["77725.65000000","0.00028000"],["77725.08000000","0.01315000"],["77725.05000000","0.00400000"],["77725.03000000","0.00643000"],["77725.02000000","0.00000000"],["77725.01000000","0.00014000"],["77725.00000000","0.00007000"],["77724.99000000","0.30035000"],["77724.74000000","0.01701000"],["77724.02000000","0.01407000"],["77724.01000000","1.75122000"],["77724.00000000","4.16190000"],["77723.99000000","0.45450000"],["77723.50000000","0.02041000"],["77723.32000000","0.00000000"],["77722.74000000","0.00007000"],["77722.68000000","0.37345000"],["77722.25000000","0.02041000"],["77720.25000000","0.00014000"],["77719.43000000","0.00120000"],["77719.34000000","0.05386000"],["77718.21000000","0.16900000"],["77715.81000000","0.02007000"],["77714.87000000","0.95590000"],["77714.86000000","0.62746000"],["77714.83000000","0.00000000"],["77714.05000000","0.00000000"],["77710.45000000","0.41270000"],["77710.44000000","0.00038000"],["77706.57000000","0.00000000"],["77702.67000000","0.00038000"],["77702.42000000","0.00257000"],["77698.47000000","0.00000000"],["77698.44000000","0.00000000"],["77694.89000000","0.37368000"],["77693.85000000","0.00042000"],["77688.00000000","0.04000000"],["77687.00000000","0.00000000"],["77662.31000000","0.00321000"],["77658.64000000","0.00000000"],["77639.23000000","0.00000000"],["77630.93000000","0.00000000"],["77594.01000000","0.00000000"],["77568.18000000","0.00055000"],["77564.45000000","0.00000000"],["77561.64000000","0.00008000"],["77552.78000000","0.00012000"],["77545.53000000","0.03379000"],["77500.00000000","1.61398000"],["77499.97000000","0.00010000"],["77481.14000000","0.00090000"],["77475.59000000","0.00007000"],["69954.98000000","0.00016000"],["69953.40000000","0.00000000"],["69951.58000000","0.00000000"]],"a":[["77726.00000000","0.00000000"],["77726.01000000","0.00000000"],["77726.02000000","0.00000000"],["77726.10000000","0.00000000"],["77726.42000000","0.00000000"],["77726.49000000","0.00000000"],["77726.98000000","0.00000000"],["77727.24000000","0.00000000"],["77727.27000000","0.00000000"],["77727.30000000","0.00000000"],["77727.60000000","0.00000000"],["77727.75000000","0.00000000"],["77727.76000000","0.28853000"],["77727.77000000","0.00063000"],["77728.10000000","0.00000000"],["77728.11000000","0.00014000"],["77728.42000000","0.00014000"],["77728.49000000","0.00000000"],["77728.71000000","0.00000000"],["77729.99000000","0.00014000"],["77730.21000000","0.00014000"],["77730.22000000","0.02908000"],["77730.39000000","0.00522000"],["77730.52000000","0.01266000"],["77730.83000000","0.00007000"],["77730.84000000","0.11205000"],["77730.99000000","0.00000000"],["77731.08000000","0.00000000"],["77731.56000000","0.00000000"],["77731.64000000","0.00871000"],["77731.73000000","0.00321000"],["77731.76000000","0.11205000"],["77731.79000000","0.00000000"],["77731.94000000","0.00000000"],["77732.88000000","0.01045000"],["77733.07000000","0.00000000"],["77733.36000000","0.11415000"],["77733.69000000","0.00000000"],["77734.13000000","0.01045000"],["77735.92000000","0.12864000"],["77736.04000000","0.00000000"],["77736.68000000","0.00000000"],["77736.82000000","0.00000000"],["77737.06000000","0.00000000"],["77737.36000000","0.00000000"],["77737.50000000","0.00400000"],["77737.95000000","0.00643000"],["77737.99000000","0.00000000"],["77739.26000000","0.00000000"],["77739.68000000","0.00008000"],["77740.13000000","0.00643000"],["77740.67000000","0.10089000"],["77740.89000000","0.00007000"],["77743.18000000","0.00000000"],["77744.82000000","0.00257000"],["77744.84000000","0.00000000"],["77746.62000000","0.00000000"],["77747.33000000","0.00000000"],["77749.83000000","0.09622000"],["77749.95000000","0.43111000"],["77751.08000000","0.00000000"],["77752.13000000","0.64357000"],["77753.26000000","0.25742000"],["77757.60000000","0.01993000"],["77758.73000000","0.00000000"],["77761.25000000","0.05524000"],["77765.00000000","0.00000000"],["77767.00000000","0.01000000"],["77778.76000000","0.01278000"],["78264.04000000","0.00000000"],["78271.85000000","0.00008000"],["78891.89000000","0.00007000"]]}}
{"type":"depth","received_at_ms":1788333207046,"data":{"e":"depthUpdate","E":1788333207214,"s":"BTCUSDT","U":99556335356,"u":99556335445,"b":[["77727.75000000","4.13637000"],["77726.65000000","0.05021000"],["77726.60000000","0.05014000"],["77726.43000000","0.00007000"],["77726.00000000","0.17212000"],["77725.99000000","0.51142000"],["77725.70000000","0.00007000"],["77725.67000000","0.00000000"],["77725.65000000","0.00007000"],["77725.08000000","0.01329000"],["77725.03000000","0.00657000"],["77725.01000000","0.00000000"],["77724.99000000","0.30014000"],["77724.74000000","0.00000000"],["77724.01000000","1.75108000"],["77723.99000000","0.45443000"],["77723.50000000","0.00000000"],["77722.68000000","0.37338000"],["77722.56000000","0.00000000"],["77722.25000000","0.00000000"],["77721.79000000","0.00000000"],["77720.25000000","0.00007000"],["77718.46000000","0.12866000"],["77598.54000000","0.00011000"],["77024.47000000","0.00000000"],["69954.98000000","0.00048000"],["62182.20000000","0.00000000"],["62180.80000000","0.00000000"]],"a":[["77727.76000000","0.28859000"],["77728.00000000","0.03014000"],["77728.11000000","0.00000000"],["77728.42000000","0.00000000"],["77730.22000000","0.02908000"],["77730.39000000","0.00014000"],["77730.52000000","0.01280000"],["77730.84000000","0.11205000"],["77731.64000000","0.00014000"],["77731.76000000","0.11191000"],["77732.88000000","0.00000000"],["77734.13000000","0.00000000"],["77739.15000000","0.00007000"],["77806.52000000","0.74726000"],["77936.60000000","0.00007000"],["77952.15000000","0.00007000"],["77967.70000000","0.00007000"]]}}
{"type":"depth","received_at_ms":1788333207147,"data":{"e":"depthUpdate","E":1788333207314,"s":"BTCUSDT","U":99556335446,"u":99556335488,"b":[["77727.75000000","4.14664000"],["77726.66000000","0.00000000"],["77726.65000000","0.00021000"],["77726.61000000","0.00000000"],["77726.60000000","0.00014000"],["77726.51000000","0.00014000"],["77726.50000000","0.01701000"],["77725.99000000","0.51149000"],["77725.26000000","0.02041000"],["77725.00000000","0.00014000"],["77724.01000000","1.77149000"]],"a":[["77727.76000000","0.29294000"],["77727.77000000","0.00070000"],["77729.15000000","0.00007000"],["77729.16000000","0.11434000"],["77730.22000000","0.02908000"],["77730.39000000","0.00000000"],["77730.83000000","0.00000000"],["77730.84000000","0.11205000"],["77731.64000000","0.00000000"],["77731.76000000","0.11205000"],["77731.99000000","0.19262000"],["77732.15000000","0.00522000"],["77733.40000000","0.00871000"],["77734.64000000","0.01045000"],["77735.89000000","0.01045000"],["77752.78000000","0.00411000"],["77757.41000000","0.00000000"]]}}
{"type":"trade","received_at_ms":1788333207228,"data":{"e":"trade","E":1788333207394,"s":"BTCUSDT","t":6646666371,"p":"77727.76000000","q":"0.00447000","T":1788333207394,"m":false,"M":true}}
{"type":"trade","received_at_ms":1788333207228,"data":{"e":"trade","E":1788333207395,"s":"BTCUSDT","t":6646666372,"p":"77727.76000000","q":"0.02127000","T":1788333207394,"m":false,"M":true}}
{"type":"trade","received_at_ms":1788333207247,"data":{"e":"trade","E":1788333207414,"s":"BTCUSDT","t":6646666373,"p":"77727.75000000","q":"0.00007000","T":1788333207413,"m":true,"M":true}}
{"type":"depth","received_at_ms":1788333207247,"data":{"e":"depthUpdate","E":1788333207414,"s":"BTCUSDT","U":99556335489,"u":99556335542,"b":[["77727.75000000","4.16636000"],["77726.65000000","0.00000000"],["77726.60000000","0.00000000"],["77726.50000000","0.01715000"],["77726.00000000","0.31851000"],["77725.99000000","0.51115000"],["77725.26000000","0.02055000"],["77724.99000000","0.30028000"],["77724.00000000","3.96190000"],["77723.99000000","0.43443000"],["77710.44000000","0.00008000"],["77709.13000000","0.00014000"],["77705.37000000","0.00000000"],["77694.89000000","0.37338000"],["77599.63000000","0.00000000"],["69954.98000000","0.00089000"]],"a":[["77727.76000000","0.26720000"],["77728.00000000","0.03014000"],["77729.16000000","0.11448000"],["77731.99000000","0.19248000"],["77736.47000000","0.00000000"],["77740.23000000","0.00007000"],["77744.81000000","0.00257000"],["77744.82000000","0.00000000"],["77757.75000000","0.00000000"],["77757.88000000","0.00000000"]]}}
{"type":"depth","received_at_ms":1788333207349,"data":{"e":"depthUpdate","E":1788333207515,"s":"BTCUSDT","U":99556335543,"u":99556335560,"b":[["77727.75000000","4.16876000"],["77719.97000000","0.00030000"],["77718.21000000","0.16870000"],["77716.11000000","0.00000000"],["77712.20000000","0.00030000"],["77704.43000000","0.00030000"],["77702.67000000","0.00008000"],["77696.65000000","0.00030000"],["77696.60000000","0.00000000"],["77668.98000000","0.00000000"],["69954.98000000","0.00105000"],["62182.20000000","0.00032000"]],"a":[["77738.58000000","0.00000000"],["77743.87000000","0.00257000"],["77744.81000000","0.00000000"],["77757.46000000","0.00000000"],["77757.66000000","0.00000000"],["77758.03000000","0.00000000"],["77777.49000000","0.00000000"]]}}
{"type":"trade","received_at_ms":1788333207363,"data":{"e":"trade","E":1788333207529,"s":"BTCUSDT","t":6646666374,"p":"77727.76000000","q":"0.00200000","T":1788333207529,"m":false,"M":true}}
{"type":"trade","received_at_ms":1788333207363,"data":{"e":"trade","E":1788333207529,"s":"BTCUSDT","t":6646666375,"p":"77727.76000000","q":"0.00200000","T":1788333207529,"m":false,"M":true}}
{"type":"trade","received_at_ms":1788333207363,"data":{"e":"trade","E":1788333207529,"s":"BTCUSDT","t":6646666376,"p":"77727.76000000","q":"0.00200000","T":1788333207529,"m":false,"M":true}}
{"type":"trade","received_at_ms":1788333207363,"data":{"e":"trade","E":1788333207529,"s":"BTCUSDT","t":6646666377,"p":"77727.76000000","q":"0.00200000","T":1788333207529,"m":false,"M":true}}
{"type":"trade","received_at_ms":1788333207363,"data":{"e":"trade","E":1788333207529,"s":"BTCUSDT","t":6646666378,"p":"77727.76000000","q":"0.00200000","T":1788333207529,"m":false,"M":true}}
{"type":"trade","received_at_ms":1788333207363,"data":{"e":"trade","E":1788333207530,"s":"BTCUSDT","t":6646666379,"p":"77727.76000000","q":"0.00200000","T":1788333207529,"m":false,"M":true}}
{"type":"trade","received_at_ms":1788333207363,"data":{"e":"trade","E":1788333207530,"s":"BTCUSDT","t":6646666380,"p":"77727.76000000","q":"0.00200000","T":1788333207529,"m":false,"M":true}}
{"type":"trade","received_at_ms":1788333207363,"data":{"e":"trade","E":1788333207530,"s":"BTCUSDT","t":6646666381,"p":"77727.76000000","q":"0.00200000","T":1788333207529,"m":false,"M":true}}
{"type":"trade","received_at_ms":1788333207363,"data":{"e":"trade","E":1788333207530,"s":"BTCUSDT","t":6646666382,"p":"77727.76000000","q":"0.00200000","T":1788333207529,"m":false,"M":true}}
{"type":"trade","received_at_ms":1788333207365,"data":{"e":"trade","E":1788333207530,"s":"BTCUSDT","t":6646666383,"p":"77727.76000000","q":"0.00200000","T":1788333207530,"m":false,"M":true}}
{"type":"trade","received_at_ms":1788333207365,"data":{"e":"trade","E":1788333207531,"s":"BTCUSDT","t":6646666384,"p":"77727.76000000","q":"0.00200000","T":1788333207531,"m":false,"M":true}}
{"type":"trade","received_at_ms":1788333207365,"data":{"e":"trade","E":1788333207531,"s":"BTCUSDT","t":6646666385,"p":"77727.76000000","q":"0.00200000","T":1788333207531,"m":false,"M":true}}
{"type":"trade","received_at_ms":1788333207367,"data":{"e":"trade","E":1788333207533,"s":"BTCUSDT","t":6646666386,"p":"77727.76000000","q":"0.02100000","T":1788333207533,"m":false,"M":true}}
{"type":"trade","received_at_ms":1788333207367,"data":{"e":"trade","E":1788333207534,"s":"BTCUSDT","t":6646666387,"p":"77727.76000000","q":"0.02100000","T":1788333207534,"m":false,"M":true}}
{"type":"trade","received_at_ms":1788333207368,"data":{"e":"trade","E":1788333207535,"s":"BTCUSDT","t":6646666388,"p":"77727.76000000","q":"0.00200000","T":1788333207534,"m":false,"M":true}}
{"type":"trade","received_at_ms":1788333207410,"data":{"e":"trade","E":1788333207575,"s":"BTCUSDT","t":6646666389,"p":"77727.76000000","q":"0.00500000","T":1788333207575,"m":false,"M":true}}
{"type":"depth","received_at_ms":1788333207447,"data":{"e":"depthUpdate","E":1788333207614,"s":"BTCUSDT","U":99556335561,"u":99556335594,"b":[["77727.75000000","4.22227000"],["77723.99000000","0.41443000"],["77699.39000000","0.00000000"],["77560.83000000","0.00000000"],["77530.01000000","0.00811000"],["77528.64000000","0.00000000"],["69954.98000000","0.00121000"],["62182.20000000","0.00000000"],["62182.00000000","0.00000000"]],"a":[["77727.76000000","0.19430000"],["77738.71000000","0.00400000"],["77759.02000000","0.09637000"]]}}
{"type":"trade","received_at_ms":1788333207459,"data":{"e":"trade","E":1788333207626,"s":"BTCUSDT","t":6646666390,"p":"77727.75000000","q":"0.01329000","T":1788333207626,"m":true,"M":true}}
{"type":"depth","received_at_ms":1788333207548,"data":{"e":"depthUpdate","E":1788333207714,"s":"BTCUSDT","U":99556335595,"u":99556335616,"b":[["77727.75000000","4.23177000"],["77727.70000000","0.05000000"],["77724.02000000","0.01400000"],["77715.68000000","0.02000000"],["77676.77000000","0.02000000"],["77657.45000000","0.02000000"],["76560.10000000","0.00000000"],["69954.98000000","0.00137000"]],"a":[["77727.76000000","0.19430000"],["77729.15000000","0.00014000"],["77742.44000000","0.03200000"],["77743.86000000","0.00257000"],["77743.87000000","0.00000000"],["77761.90000000","0.03200000"],["77781.35000000","0.03200000"],["78893.68000000","0.00030000"]]}}
{"type":"trade","received_at_ms":1788333207620,"data":{"e":"trade","E":1788333207785,"s":"BTCUSDT","t":6646666391,"p":"77727.76000000","q":"0.01500000","T":1788333207785,"m":false,"M":true}}
