{"type":"depth","received_at_ms":1788331827775,"data":{"e":"depthUpdate","E":1788331827914,"s":"BTCUSDT","U":99555808024,"u":99555808030,"b":[["77592.06000000","0.01200000"],["77581.29000000","0.00200000"],["77540.52000000","0.00000000"],["77526.50000000","0.00000000"],["69837.36000000","0.00464000"]],"a":[["77615.01000000","0.00412000"],["77684.87000000","0.00000000"]]}}
{"type":"depth","received_at_ms":1788331827875,"data":{"e":"depthUpdate","E":1788331828014,"s":"BTCUSDT","U":99555808031,"u":99555808038,"b":[["69837.36000000","0.00448000"],["62078.00000000","0.00600000"],["62077.65000000","0.00032000"]],"a":[]}}
{"type":"depth","received_at_ms":1788331827975,"data":{"e":"depthUpdate","E":1788331828114,"s":"BTCUSDT","U":99555808039,"u":99555808043,"b":[["69837.36000000","0.00464000"],["62077.65000000","0.00032000"]],"a":[]}}
{"type":"depth","received_at_ms":1788331828074,"data":{"e":"depthUpdate","E":1788331828214,"s":"BTCUSDT","U":99555808044,"u":99555808048,"b":[["73717.21000000","0.00020000"],["69837.36000000","0.00448000"],["62077.65000000","0.00000000"]],"a":[["78761.03000000","0.00030000"]]}}
{"type":"depth","received_at_ms":1788331828174,"data":{"e":"depthUpdate","E":1788331828314,"s":"BTCUSDT","U":99555808049,"u":99555808057,"b":[["73717.21000000","0.00000000"],["69837.36000000","0.00464000"],["62078.00000000","0.00600000"]],"a":[["77684.85000000","0.00412000"]]}}
{"type":"depth","received_at_ms":1788331828274,"data":{"e":"depthUpdate","E":1788331828414,"s":"BTCUSDT","U":99555808058,"u":99555808063,"b":[["77540.55000000","0.12892000"],["76433.10000000","0.00030000"],["69837.36000000","0.00448000"]],"a":[]}}
{"type":"depth","received_at_ms":1788331828374,"data":{"e":"depthUpdate","E":1788331828514,"s":"BTCUSDT","U":99555808064,"u":99555808078,"b":[["77583.90000000","0.02000000"],["77579.15000000","0.02000000"],["77545.08000000","0.02000000"],["77540.55000000","0.00000000"],["77540.33000000","0.00000000"],["77525.57000000","0.02000000"],["77520.93000000","0.00000000"],["69837.36000000","0.00448000"],["62078.00000000","0.00600000"],["62077.65000000","0.00032000"]],"a":[["77604.72000000","0.00000000"],["77605.80000000","0.03000000"],["77624.13000000","0.00000000"],["77625.20000000","0.03000000"],["77643.53000000","0.00000000"],["77644.57000000","0.05000000"],["77644.61000000","0.03000000"],["77659.42000000","0.00000000"]]}}
{"type":"depth","received_at_ms":1788331828475,"data":{"e":"depthUpdate","E":1788331828614,"s":"BTCUSDT","U":99555808079,"u":99555808085,"b":[["77580.01000000","0.45361000"],["77464.67000000","0.02019000"],["77460.01000000","0.00000000"],["77459.70000000","0.00000000"],["69837.36000000","0.00448000"],["62077.65000000","0.00000000"]],"a":[]}}
{"type":"depth","received_at_ms":1788331828574,"data":{"e":"depthUpdate","E":1788331828714,"s":"BTCUSDT","U":99555808086,"u":99555808097,"b":[["69837.36000000","0.00448000"],["62078.00000000","0.00600000"],["62077.65000000","0.00000000"]],"a":[]}}
{"type":"depth","received_at_ms":1788331828678,"data":{"e":"depthUpdate","E":1788331828815,"s":"BTCUSDT","U":99555808098,"u":99555808108,"b":[["77590.22000000","0.00000000"],["77577.78000000","0.00007000"],["77540.51000000","0.00000000"],["77540.48000000","0.12892000"],["69837.36000000","0.00448000"],["69837.00000000","0.00000000"]],"a":[["77608.82000000","0.00007000"]]}}
{"type":"depth","received_at_ms":1788331828775,"data":{"e":"depthUpdate","E":1788331828914,"s":"BTCUSDT","U":99555808109,"u":99555808128,"b":[["77597.06000000","0.70339000"],["77592.07000000","0.00000000"],["77581.29000000","0.00200000"],["77565.19000000","0.00000000"],["77526.38000000","0.00000000"],["77495.39000000","0.00000000"],["75557.06000000","0.00000000"],["69837.36000000","0.00448000"],["69837.35000000","0.00000000"]],"a":[["77597.07000000","4.76157000"],["77615.01000000","0.00000000"],["77653.83000000","0.00000000"],["77684.85000000","0.00000000"],["81001.05000000","0.00000000"]]}}
{"type":"depth","received_at_ms":1788331828874,"data":{"e":"depthUpdate","E":1788331829014,"s":"BTCUSDT","U":99555808129,"u":99555808133,"b":[["75900.00000000","6.79094000"],["69837.36000000","0.00464000"],["62077.65000000","0.00032000"]],"a":[]}}
{"type":"depth","received_at_ms":1788331828974,"data":{"e":"depthUpdate","E":1788331829114,"s":"BTCUSDT","U":99555808134,"u":99555808140,"b":[["77590.21000000","0.00000000"],["77588.65000000","0.00000000"],["71389.30000000","0.00015000"],["69837.36000000","0.00432000"],["62077.65000000","0.00032000"]],"a":[]}}
{"type":"depth","received_at_ms":1788331829076,"data":{"e":"depthUpdate","E":1788331829215,"s":"BTCUSDT","U":99555808141,"u":99555808145,"b":[["69837.36000000","0.00464000"],["62077.65000000","0.00000000"]],"a":[["78761.03000000","0.00030000"]]}}
{"type":"depth","received_at_ms":1788331829174,"data":{"e":"depthUpdate","E":1788331829314,"s":"BTCUSDT","U":99555808146,"u":99555808150,"b":[["77589.96000000","0.00341000"],["69837.36000000","0.00448000"]],"a":[["77615.03000000","0.00412000"]]}}
{"type":"depth","received_at_ms":1788331829274,"data":{"e":"depthUpdate","E":1788331829414,"s":"BTCUSDT","U":99555808151,"u":99555808155,"b":[["76433.10000000","0.00030000"],["69837.36000000","0.00464000"]],"a":[]}}
{"type":"depth","received_at_ms":1788331829374,"data":{"e":"depthUpdate","E":1788331829514,"s":"BTCUSDT","U":99555808156,"u":99555808170,"b":[["77592.05000000","0.00200000"],["77584.74000000","0.02000000"],["77581.29000000","0.00000000"],["77545.93000000","0.02000000"],["77525.67000000","0.02000000"],["77501.91000000","0.00000000"],["69837.36000000","0.00448000"],["62077.65000000","0.00032000"]],"a":[["77605.04000000","0.02600000"],["77624.45000000","0.02600000"],["77643.82000000","0.02000000"],["77643.86000000","0.02600000"],["77653.84000000","0.00734000"],["77658.64000000","0.00000000"],["77734.78000000","0.00000000"]]}}
{"type":"trade","received_at_ms":1788331829393,"data":{"e":"trade","E":1788331829528,"s":"BTCUSDT","t":6646633339,"p":"77597.07000000","q":"0.00582000","T":1788331829528,"m":false,"M":true}}
{"type":"depth","received_at_ms":1788331829475,"data":{"e":"depthUpdate","E":1788331829614,"s":"BTCUSDT","U":99555808171,"u":99555808204,"b":[["77597.06000000","0.70346000"],["77592.69000000","0.11363000"],["77592.07000000","0.01200000"],["77592.06000000","0.00000000"],["77592.05000000","0.00200000"],["77581.29000000","0.00000000"],["77490.86000000","0.04883000"],["71389.30000000","0.00000000"],["69837.36000000","0.00473000"],["62078.00000000","0.00600000"],["62077.65000000","0.00000000"]],"a":[["77597.07000000","4.75575000"],["77723.69000000","0.00971000"]]}}
{"type":"trade","received_at_ms":1788331829475,"data":{"e":"trade","E":1788331829614,"s":"BTCUSDT","t":6646633340,"p":"77597.07000000","q":"0.00100000","T":1788331829614,"m":false,"M":true}}
{"type":"depth","received_at_ms":1788331829576,"data":{"e":"depthUpdate","E":1788331829714,"s":"BTCUSDT","U":99555808205,"u":99555808227,"b":[["77597.06000000","0.70339000"],["77592.69000000","0.11363000"],["77592.08000000","0.01400000"],["77592.07000000","0.00000000"],["77592.05000000","0.00000000"],["77581.29000000","0.00000000"],["77565.21000000","0.00624000"],["69837.36000000","0.00457000"],["62077.65000000","0.00020000"]],"a":[["77597.07000000","4.75475000"]]}}
{"type":"depth","received_at_ms":1788331829674,"data":{"e":"depthUpdate","E":1788331829814,"s":"BTCUSDT","U":99555808228,"u":99555808235,"b":[["77592.69000000","0.11363000"],["77577.78000000","0.00000000"],["77540.48000000","0.00000000"],["75556.87000000","0.00010000"],["69837.36000000","0.00473000"],["69837.00000000","0.00020000"],["62077.65000000","0.00000000"]],"a":[["77608.82000000","0.00000000"]]}}
{"type":"depth","received_at_ms":1788331829774,"data":{"e":"depthUpdate","E":1788331829914,"s":"BTCUSDT","U":99555808236,"u":99555808243,"b":[["77577.78000000","0.00007000"],["77526.42000000","0.00412000"],["69837.36000000","0.00457000"],["69837.00000000","0.00000000"]],"a":[["77608.82000000","0.00007000"],["77663.29000000","0.00000000"]]}}
{"type":"depth","received_at_ms":1788331829875,"data":{"e":"depthUpdate","E":1788331830014,"s":"BTCUSDT","U":99555808244,"u":99555808265,"b":[["77597.06000000","0.53476000"],["77592.69000000","0.11370000"],["77592.08000000","0.00200000"],["77592.05000000","0.01200000"],["77580.86000000","0.00128000"],["77579.00000000","0.00012000"],["77540.39000000","0.00000000"],["69837.36000000","0.00457000"],["62077.65000000","0.00032000"]],"a":[["77690.19000000","0.00000000"],["77692.82000000","0.00087000"],["81001.24000000","0.00010000"],["86422.88000000","0.20801000"]]}}
{"type":"depth","received_at_ms":1788331829974,"data":{"e":"depthUpdate","E":1788331830114,"s":"BTCUSDT","U":99555808266,"u":99555808286,"b":[["77597.06000000","0.53469000"],["77594.36000000","0.01332000"],["77592.69000000","0.11356000"],["77592.08000000","0.00000000"],["77592.06000000","0.01200000"],["77592.05000000","0.00000000"],["77581.29000000","0.00200000"],["69837.36000000","0.00441000"],["62077.65000000","0.00032000"]],"a":[["77684.89000000","0.00412000"],["86422.88000000","0.22692000"]]}}
{"type":"depth","received_at_ms":1788331830075,"data":{"e":"depthUpdate","E":1788331830214,"s":"BTCUSDT","U":99555808287,"u":99555808313,"b":[["77597.06000000","0.53469000"],["77592.69000000","0.11363000"],["77592.07000000","0.00000000"],["77592.06000000","0.00000000"],["77592.05000000","0.01200000"],["77589.88000000","0.00334000"],["69837.36000000","0.00441000"],["62077.65000000","0.00000000"]],"a":[["78761.03000000","0.00030000"]]}}
{"type":"depth","received_at_ms":1788331830176,"data":{"e":"depthUpdate","E":1788331830314,"s":"BTCUSDT","U":99555808314,"u":99555808352,"b":[["77597.06000000","0.53469000"],["77592.69000000","0.11363000"],["77592.06000000","0.01200000"],["77592.05000000","0.00000000"],["77581.29000000","0.00200000"],["69837.36000000","0.00457000"],["62078.00000000","0.00600000"]],"a":[["77689.33000000","0.95522000"],["77692.22000000","2.15391000"],["77693.99000000","0.63755000"],["77694.81000000","0.00000000"],["84202.54000000","0.01768000"]]}}
{"type":"depth","received_at_ms":1788331830275,"data":{"e":"depthUpdate","E":1788331830414,"s":"BTCUSDT","U":99555808353,"u":99555808379,"b":[["77597.06000000","0.53462000"],["77592.69000000","0.11356000"],["77592.06000000","0.00000000"],["77592.05000000","0.00000000"],["77581.29000000","0.01400000"],["76433.10000000","0.00030000"],["69837.36000000","0.00425000"],["62078.00000000","0.00600000"]],"a":[["77597.07000000","4.75575000"]]}}
{"type":"trade","received_at_ms":1788331830333,"data":{"e":"trade","E":1788331830471,"s":"BTCUSDT","t":6646633341,"p":"77597.06000000","q":"0.00257000","T":1788331830471,"m":true,"M":true}}
{"type":"depth","received_at_ms":1788331830375,"data":{"e":"depthUpdate","E":1788331830514,"s":"BTCUSDT","U":99555808380,"u":99555808418,"b":[["77597.06000000","0.53205000"],["77592.69000000","0.11356000"],["77592.05000000","0.00000000"],["77581.29000000","0.01400000"],["77526.52000000","0.02000000"],["69837.36000000","0.00448000"],["69837.35000000","0.00009000"],["62077.65000000","0.00032000"]],"a":[["77647.72000000","0.02400000"],["77648.50000000","0.02200000"],["77662.52000000","0.00000000"]]}}
{"type":"depth","received_at_ms":1788331830474,"data":{"e":"depthUpdate","E":1788331830614,"s":"BTCUSDT","U":99555808419,"u":99555808433,"b":[["77597.06000000","0.53212000"],["77592.69000000","0.11363000"],["77592.05000000","0.01200000"],["77581.29000000","0.00200000"],["77540.43000000","0.12892000"],["69837.36000000","0.00432000"],["62078.00000000","0.00600000"],["62077.65000000","0.00000000"]],"a":[]}}
{"type":"trade","received_at_ms":1788331830510,"data":{"e":"trade","E":1788331830648,"s":"BTCUSDT","t":6646633342,"p":"77597.06000000","q":"0.00100000","T":1788331830648,"m":true,"M":true}}
{"type":"depth","received_at_ms":1788331830574,"data":{"e":"depthUpdate","E":1788331830714,"s":"BTCUSDT","U":99555808434,"u":99555808455,"b":[["77597.06000000","0.53112000"],["77592.69000000","0.11363000"],["77592.06000000","0.01200000"],["77592.05000000","0.00000000"],["77570.13000000","0.00000000"],["77549.24000000","0.30971000"],["77546.86000000","0.00000000"],["77540.43000000","0.00000000"],["69837.36000000","0.00432000"]],"a":[["77689.33000000","0.34873000"],["77692.22000000","0.00000000"],["77694.81000000","2.15391000"]]}}
{"type":"depth","received_at_ms":1788331830674,"data":{"e":"depthUpdate","E":1788331830814,"s":"BTCUSDT","U":99555808456,"u":99555808499,"b":[["77597.06000000","0.53105000"],["77592.69000000","0.11356000"],["77592.07000000","0.00000000"],["77592.06000000","0.00000000"],["77592.05000000","0.01200000"],["77581.29000000","0.00200000"],["69837.36000000","0.00432000"],["62077.65000000","0.00000000"]],"a":[["77597.07000000","4.75582000"],["77598.92000000","0.00340000"],["77605.59000000","0.00008000"],["77661.74000000","0.00000000"]]}}
{"type":"trade","received_at_ms":1788331830699,"data":{"e":"trade","E":1788331830839,"s":"BTCUSDT","t":6646633343,"p":"77597.06000000","q":"0.00225000","T":1788331830839,"m":true,"M":true}}
{"type":"depth","received_at_ms":1788331830774,"data":{"e":"depthUpdate","E":1788331830914,"s":"BTCUSDT","U":99555808500,"u":99555808529,"b":[["77597.06000000","0.52887000"],["77592.69000000","0.11363000"],["77592.05000000","0.01200000"],["77581.29000000","0.00200000"],["77577.78000000","0.00007000"],["77539.97000000","0.12892000"],["69837.36000000","0.00448000"],["69837.35000000","0.00000000"],["69837.00000000","0.00020000"]],"a":[["77608.82000000","0.00007000"]]}}
{"type":"trade","received_at_ms":1788331830784,"data":{"e":"trade","E":1788331830924,"s":"BTCUSDT","t":6646633344,"p":"77597.06000000","q":"0.09038000","T":1788331830923,"m":true,"M":true}}
{"type":"trade","received_at_ms":1788331830784,"data":{"e":"trade","E":1788331830924,"s":"BTCUSDT","t":6646633345,"p":"77597.06000000","q":"0.00007000","T":1788331830923,"m":true,"M":true}}
{"type":"trade","received_at_ms":1788331830784,"data":{"e":"trade","E":1788331830924,"s":"BTCUSDT","t":6646633346,"p":"77597.06000000","q":"0.00971000","T":1788331830923,"m":true,"M":true}}
{"type":"depth","received_at_ms":1788331830874,"data":{"e":"depthUpdate","E":1788331831014,"s":"BTCUSDT","U":99555808530,"u":99555808782,"b":[["77597.06000000","0.18233000"],["77597.05000000","0.00090000"],["77596.95000000","0.00000000"],["77596.94000000","0.00021000"],["77596.76000000","0.00000000"],["77596.75000000","0.00014000"],["77594.37000000","0.00014000"],["77594.36000000","0.01325000"],["77594.18000000","0.00000000"],["77594.15000000","0.00000000"],["77594.14000000","0.00014000"],["77594.01000000","0.00014000"],["77593.51000000","0.00208000"],["77592.70000000","0.00014000"],["77592.69000000","0.11356000"],["77592.06000000","0.00007000"],["77592.05000000","0.09929000"],["77592.04000000","0.11335000"],["77592.03000000","0.07775000"],["77592.01000000","0.00000000"],["77589.96000000","0.00000000"],["77589.88000000","0.00000000"],["77589.76000000","0.11335000"],["77589.08000000","0.00000000"],["77589.03000000","0.00000000"],["77588.53000000","0.00000000"],["77588.32000000","0.11335000"],["77587.78000000","0.11335000"],["77587.19000000","0.00000000"],["77586.97000000","0.00000000"],["77586.84000000","0.00000000"],["77586.79000000","0.00000000"],["77586.58000000","0.00000000"],["77586.53000000","0.00000000"],["77586.27000000","0.00000000"],["77585.86000000","0.00137000"],["77585.85000000","0.00000000"],["77585.34000000","0.00000000"],["77585.02000000","0.00000000"],["77584.95000000","0.02000000"],["77584.90000000","0.00000000"],["77584.85000000","0.00257000"],["77584.84000000","0.00000000"],["77584.75000000","0.00644000"],["77584.72000000","0.00000000"],["77584.56000000","0.00000000"],["77584.55000000","0.00400000"],["77584.53000000","0.00000000"],["77584.48000000","0.00015000"],["77584.47000000","0.00000000"],["77584.44000000","0.00000000"],["77584.43000000","0.00000000"],["77584.32000000","0.00161000"],["77583.97000000","0.00000000"],["77583.96000000","0.00000000"],["77583.94000000","0.00000000"],["77583.81000000","0.00000000"],["77582.35000000","0.00000000"],["77581.66000000","0.00000000"],["77581.29000000","0.00000000"],["77581.21000000","0.00000000"],["77581.19000000","0.00000000"],["77581.16000000","0.00000000"],["77581.13000000","0.00000000"],["77580.89000000","0.00000000"],["77580.86000000","0.00128000"],["77580.74000000","0.00000000"],["77580.69000000","0.00000000"],["77580.59000000","0.00000000"],["77580.58000000","0.00000000"],["77580.56000000","0.00007000"],["77580.27000000","0.00400000"],["77580.02000000","0.00000000"],["77578.85000000","0.00400000"],["77578.81000000","0.00000000"],["77578.63000000","0.00644000"],["77578.39000000","0.00000000"],["77577.77000000","0.00000000"],["77577.67000000","0.00200000"],["77572.96000000","0.10000000"],["77571.83000000","0.50259000"],["77569.40000000","0.44225000"],["77568.17000000","0.00000000"],["77565.81000000","0.00000000"],["77565.21000000","0.00412000"],["77565.01000000","1.04341000"],["77563.35000000","0.00000000"],["77562.50000000","0.00200000"],["77562.00000000","0.03000000"],["77559.26000000","0.00400000"],["77554.96000000","0.00007000"],["77549.24000000","0.59235000"],["77548.56000000","1.01017000"],["77544.83000000","0.34834000"],["77539.97000000","0.00000000"],["77518.83000000","1.27768000"],["77518.29000000","0.70976000"],["77516.12000000","0.00000000"],["77501.91000000","0.03997000"],["77490.86000000","0.00000000"],["77204.19000000","0.00007000"],["69837.36000000","0.00432000"],["69837.00000000","0.00000000"],["62078.00000000","0.00600000"],["62077.65000000","0.00032000"]],"a":[["77597.07000000","5.06945000"],["77597.08000000","0.01062000"],["77597.15000000","0.00000000"],["77597.76000000","0.00014000"],["77597.81000000","0.00014000"],["77597.82000000","0.36253000"],["77598.85000000","0.00007000"],["77599.56000000","0.02285000"],["77599.79000000","0.01302000"],["77600.23000000","0.00000000"],["77601.03000000","0.00400000"],["77601.49000000","0.00400000"],["77601.97000000","0.00400000"],["77602.70000000","0.00000000"],["77602.98000000","0.38675000"],["77603.97000000","0.00000000"],["77604.39000000","0.00000000"],["77604.92000000","0.00000000"],["77605.37000000","0.00000000"],["77606.02000000","0.00000000"],["77610.93000000","1.02026000"],["77611.58000000","0.45221000"],["77615.83000000","0.00000000"],["77616.00000000","0.00265000"],["77626.77000000","0.00000000"],["77629.10000000","0.00400000"],["77631.04000000","0.00023000"],["77651.42000000","0.10853000"],["77653.48000000","0.00000000"],["77723.69000000","0.00000000"],["77734.78000000","0.00971000"],["77795.43000000","0.02019000"],["77805.16000000","0.00000000"],["77824.77000000","0.00000000"]]}}
{"type":"depth","received_at_ms":1788331830974,"data":{"e":"depthUpdate","E":1788331831114,"s":"BTCUSDT","U":99555808783,"u":99555808855,"b":[["77597.06000000","0.18247000"],["77597.05000000","0.00090000"],["77596.94000000","0.00000000"],["77596.75000000","0.00000000"],["77596.00000000","0.03028000"],["77594.38000000","0.00014000"],["77594.37000000","0.05077000"],["77594.36000000","0.01318000"],["77594.14000000","0.00000000"],["77592.69000000","0.11370000"],["77592.27000000","0.08226000"],["77592.06000000","0.00000000"],["77592.05000000","0.12017000"],["77592.04000000","0.11342000"],["77587.79000000","0.00600000"],["77586.97000000","0.00140000"],["77585.86000000","0.00000000"],["77584.85000000","0.00000000"],["77584.21000000","0.00257000"],["77578.85000000","0.00000000"],["77577.67000000","0.00000000"],["77576.00000000","0.03007000"],["77565.21000000","0.00000000"],["77548.19000000","0.00212000"],["77526.42000000","0.00000000"],["77495.40000000","0.00412000"],["69837.36000000","0.00448000"],["62077.65000000","0.00032000"]],"a":[["77597.11000000","0.03234000"],["77597.76000000","0.00000000"],["77597.78000000","0.20487000"],["77597.79000000","0.26044000"],["77598.06000000","0.00400000"],["77599.52000000","0.00027000"],["77599.56000000","0.02299000"],["77600.24000000","0.92927000"],["77601.05000000","0.14273000"],["77601.28000000","0.00000000"],["77602.97000000","1.93226000"],["77603.07000000","0.00000000"],["77615.03000000","0.00000000"],["77629.10000000","0.00000000"],["77653.84000000","0.00322000"],["77684.89000000","0.00000000"]]}}
{"type":"depth","received_at_ms":1788331831074,"data":{"e":"depthUpdate","E":1788331831214,"s":"BTCUSDT","U":99555808856,"u":99555808891,"b":[["77597.06000000","0.18240000"],["77596.00000000","0.03028000"],["77594.37000000","0.05091000"],["77592.69000000","0.11363000"],["77592.24000000","0.00008000"],["77592.04000000","0.11335000"],["77587.80000000","0.00400000"],["77587.79000000","0.00200000"],["77585.75000000","0.00164000"],["77585.53000000","0.00000000"],["77585.52000000","0.00400000"],["77584.55000000","0.00000000"],["77584.32000000","0.00000000"],["77580.44000000","0.00400000"],["77580.27000000","0.00000000"],["77563.14000000","0.00400000"],["77539.23000000","0.12892000"],["77514.01000000","0.50189000"],["77513.53000000","1.61611000"],["69837.36000000","0.00432000"],["62077.65000000","0.00000000"]],"a":[["77600.23000000","1.31471000"],["77601.03000000","0.00000000"],["77602.19000000","0.00200000"],["78761.03000000","0.00030000"]]}}
{"type":"depth","received_at_ms":1788331831174,"data":{"e":"depthUpdate","E":1788331831314,"s":"BTCUSDT","U":99555808892,"u":99555808925,"b":[["77597.06000000","0.18247000"],["77597.05000000","0.00097000"],["77594.38000000","0.00000000"],["77594.37000000","0.00028000"],["77594.36000000","0.01332000"],["77594.15000000","0.00014000"],["77594.14000000","0.11027000"],["77594.02000000","0.00014000"],["77594.01000000","0.07011000"],["77592.70000000","0.00000000"],["77592.28000000","0.00000000"],["77590.19000000","0.00021000"],["77584.21000000","0.00000000"],["77584.20000000","1.05904000"],["77565.23000000","0.00412000"],["77539.23000000","0.00000000"],["69837.36000000","0.00432000"]],"a":[["77600.22000000","0.00200000"],["77602.19000000","0.00000000"]]}}
{"type":"depth","received_at_ms":1788331831274,"data":{"e":"depthUpdate","E":1788331831414,"s":"BTCUSDT","U":99555808926,"u":99555808951,"b":[["77596.64000000","0.00007000"],["77596.00000000","0.03028000"],["77594.37000000","0.00014000"],["77594.36000000","0.01332000"],["77594.14000000","0.11041000"],["77594.01000000","0.07025000"],["77592.05000000","0.12003000"],["77584.20000000","1.05647000"],["77538.82000000","0.00000000"],["76433.10000000","0.00030000"],["62078.00000000","0.00600000"]],"a":[["77687.56000000","0.00602000"],["77692.82000000","0.00000000"]]}}
{"type":"depth","received_at_ms":1788331831375,"data":{"e":"depthUpdate","E":1788331831514,"s":"BTCUSDT","U":99555808952,"u":99555808981,"b":[["77587.80000000","0.00000000"],["77587.79000000","0.00600000"],["77585.55000000","0.00000000"],["77585.52000000","0.00000000"],["77584.95000000","0.00000000"],["77584.19000000","0.00257000"],["77580.68000000","0.00000000"],["77580.44000000","0.00000000"],["77579.45000000","0.02000000"],["77501.91000000","0.00000000"],["69837.36000000","0.00432000"],["62078.00000000","0.00600000"],["62077.65000000","0.00032000"]],"a":[["77597.07000000","5.10500000"],["77597.82000000","0.32253000"],["77601.49000000","0.00000000"],["77602.96000000","0.00400000"],["77646.96000000","0.02800000"],["77684.91000000","0.00412000"],["77693.99000000","1.19898000"],["77734.78000000","0.00000000"]]}}
{"type":"depth","received_at_ms":1788331831475,"data":{"e":"depthUpdate","E":1788331831614,"s":"BTCUSDT","U":99555808982,"u":99555808993,"b":[["77587.79000000","0.00600000"],["77585.55000000","0.00400000"],["77584.19000000","0.00000000"],["77584.18000000","0.00257000"],["77580.69000000","0.00400000"],["77489.56000000","0.04883000"],["69837.36000000","0.00432000"],["62077.65000000","0.00000000"]],"a":[["77599.52000000","0.00000000"],["77722.38000000","0.00971000"]]}}
{"type":"depth","received_at_ms":1788331831573,"data":{"e":"depthUpdate","E":1788331831714,"s":"BTCUSDT","U":99555808994,"u":99555809003,"b":[["77584.18000000","0.00000000"],["77584.17000000","0.00257000"],["77539.60000000","0.00000000"],["77539.48000000","0.00000000"],["77539.26000000","0.12892000"],["77526.44000000","0.00412000"],["69837.36000000","0.00432000"]],"a":[]}}
{"type":"depth","received_at_ms":1788331831675,"data":{"e":"depthUpdate","E":1788331831814,"s":"BTCUSDT","U":99555809004,"u":99555809015,"b":[["77584.17000000","0.00000000"],["77584.16000000","0.00257000"],["77539.26000000","0.00000000"],["69837.36000000","0.00448000"],["62077.65000000","0.00000000"]],"a":[["77597.07000000","5.10270000"],["77663.28000000","0.00000000"]]}}
{"type":"depth","received_at_ms":1788331831774,"data":{"e":"depthUpdate","E":1788331831915,"s":"BTCUSDT","U":99555809016,"u":99555809033,"b":[["77590.42000000","0.00091000"],["77590.30000000","0.00000000"],["77584.16000000","0.00000000"],["77582.53000000","0.00257000"],["77577.78000000","0.00007000"],["77555.38000000","0.00400000"],["77539.55000000","0.00000000"],["77539.27000000","0.00000000"],["69837.36000000","0.00432000"]],"a":[["77598.04000000","0.00257000"],["77599.56000000","0.02042000"],["77608.82000000","0.00007000"],["77653.86000000","0.00412000"]]}}
{"type":"depth","received_at_ms":1788331831883,"data":{"e":"depthUpdate","E":1788331832014,"s":"BTCUSDT","U":99555809034,"u":99555809060,"b":[["77597.06000000","0.18240000"],["77597.05000000","0.00090000"],["77593.51000000","0.00000000"],["77514.01000000","0.02058000"],["77513.53000000","0.00000000"],["69837.36000000","0.00432000"],["62077.65000000","0.00032000"]],"a":[["77597.08000000","0.01069000"],["77597.09000000","0.00027000"],["77597.10000000","0.05014000"],["77597.11000000","0.03241000"],["77597.14000000","0.00014000"],["77597.15000000","0.05000000"],["77597.78000000","0.21130000"],["77597.79000000","0.25428000"],["77597.81000000","0.00000000"],["77689.63000000","2.15391000"],["77693.99000000","0.63755000"],["77694.81000000","0.00000000"]]}}
{"type":"depth","received_at_ms":1788331831974,"data":{"e":"depthUpdate","E":1788331832114,"s":"BTCUSDT","U":99555809061,"u":99555809082,"b":[["69837.36000000","0.00432000"],["69837.00000000","0.00000000"],["62077.65000000","0.00032000"]],"a":[["77597.08000000","0.01069000"],["77597.10000000","0.05028000"],["77597.11000000","0.03241000"],["77597.15000000","0.05014000"],["77599.17000000","0.04145000"],["77599.56000000","0.02028000"]]}}
{"type":"depth","received_at_ms":1788331832076,"data":{"e":"depthUpdate","E":1788331832214,"s":"BTCUSDT","U":99555809083,"u":99555809094,"b":[["77539.42000000","0.00000000"],["77500.51000000","0.03997000"],["77489.56000000","0.00000000"],["69837.36000000","0.00448000"],["62077.65000000","0.00000000"]],"a":[["77722.38000000","0.00000000"],["77733.38000000","0.00971000"],["78761.03000000","0.00030000"]]}}
{"type":"depth","received_at_ms":1788331832174,"data":{"e":"depthUpdate","E":1788331832314,"s":"BTCUSDT","U":99555809095,"u":99555809109,"b":[["77565.23000000","0.00000000"],["77538.95000000","0.00000000"],["77526.44000000","0.00000000"],["77495.40000000","0.00000000"],["77455.88000000","0.00000000"],["77419.79000000","0.01547000"],["69837.36000000","0.00416000"],["62078.00000000","0.00600000"]],"a":[["77615.05000000","0.00412000"],["77653.86000000","0.00000000"],["77684.91000000","0.00000000"]]}}
{"type":"depth","received_at_ms":1788331832275,"data":{"e":"depthUpdate","E":1788331832414,"s":"BTCUSDT","U":99555809110,"u":99555809116,"b":[["77538.97000000","0.00000000"],["76433.10000000","0.00030000"],["69837.36000000","0.00448000"]],"a":[["80200.00000000","4.27407000"]]}}
{"type":"depth","received_at_ms":1788331832374,"data":{"e":"depthUpdate","E":1788331832514,"s":"BTCUSDT","U":99555809117,"u":99555809127,"b":[["77580.86000000","0.00000000"],["77579.00000000","0.00140000"],["77539.19000000","0.00000000"],["77526.32000000","0.00412000"],["69837.36000000","0.00432000"],["62077.65000000","0.00032000"]],"a":[["77648.54000000","0.02400000"],["77689.33000000","0.95496000"]]}}
{"type":"depth","received_at_ms":1788331832475,"data":{"e":"depthUpdate","E":1788331832614,"s":"BTCUSDT","U":99555809128,"u":99555809134,"b":[["69837.36000000","0.00432000"],["62078.00000000","0.00600000"],["62077.65000000","0.00000000"]],"a":[]}}
{"type":"trade","received_at_ms":1788331832554,"data":{"e":"trade","E":1788331832690,"s":"BTCUSDT","t":6646633347,"p":"77597.06000000","q":"0.00029000","T":1788331832689,"m":true,"M":true}}
{"type":"trade","received_at_ms":1788331832554,"data":{"e":"trade","E":1788331832690,"s":"BTCUSDT","t":6646633348,"p":"77597.06000000","q":"0.00007000","T":1788331832689,"m":true,"M":true}}
{"type":"trade","received_at_ms":1788331832554,"data":{"e":"trade","E":1788331832690,"s":"BTCUSDT","t":6646633349,"p":"77597.06000000","q":"0.00007000","T":1788331832689,"m":true,"M":true}}
{"type":"trade","received_at_ms":1788331832554,"data":{"e":"trade","E":1788331832690,"s":"BTCUSDT","t":6646633350,"p":"77597.06000000","q":"0.00007000","T":1788331832689,"m":true,"M":true}}
{"type":"trade","received_at_ms":1788331832554,"data":{"e":"trade","E":1788331832690,"s":"BTCUSDT","t":6646633351,"p":"77597.06000000","q":"0.00007000","T":1788331832689,"m":true,"M":true}}
{"type":"trade","received_at_ms":1788331832554,"data":{"e":"trade","E":1788331832690,"s":"BTCUSDT","t":6646633352,"p":"77597.06000000","q":"0.00007000","T":1788331832689,"m":true,"M":true}}
{"type":"trade","received_at_ms":1788331832554,"data":{"e":"trade","E":1788331832690,"s":"BTCUSDT","t":6646633353,"p":"77597.06000000","q":"0.00019000","T":1788331832689,"m":true,"M":true}}
{"type":"trade","received_at_ms":1788331832554,"data":{"e":"trade","E":1788331832690,"s":"BTCUSDT","t":6646633354,"p":"77597.06000000","q":"0.00045000","T":1788331832689,"m":true,"M":true}}
{"type":"trade","received_at_ms":1788331832554,"data":{"e":"trade","E":1788331832690,"s":"BTCUSDT","t":6646633355,"p":"77597.06000000","q":"0.00065000","T":1788331832689,"m":true,"M":true}}
{"type":"trade","received_at_ms":1788331832554,"data":{"e":"trade","E":1788331832690,"s":"BTCUSDT","t":6646633356,"p":"77597.06000000","q":"0.00008000","T":1788331832689,"m":true,"M":true}}
{"type":"trade","received_at_ms":1788331832554,"data":{"e":"trade","E":1788331832690,"s":"BTCUSDT","t":6646633357,"p":"77597.06000000","q":"0.00013000","T":1788331832689,"m":true,"M":true}}
{"type":"trade","received_at_ms":1788331832554,"data":{"e":"trade","E":1788331832690,"s":"BTCUSDT","t":6646633358,"p":"77597.06000000","q":"0.00007000","T":1788331832689,"m":true,"M":true}}
{"type":"trade","received_at_ms":1788331832554,"data":{"e":"trade","E":1788331832690,"s":"BTCUSDT","t":6646633359,"p":"77597.06000000","q":"0.00007000","T":1788331832689,"m":true,"M":true}}
{"type":"trade","received_at_ms":1788331832554,"data":{"e":"trade","E":1788331832690,"s":"BTCUSDT","t":6646633360,"p":"77597.06000000","q":"0.00007000","T":1788331832689,"m":true,"M":true}}
{"type":"trade","received_at_ms":1788331832554,"data":{"e":"trade","E":1788331832690,"s":"BTCUSDT","t":6646633361,"p":"77597.06000000","q":"0.00200000","T":1788331832689,"m":true,"M":true}}
{"type":"trade","received_at_ms":1788331832554,"data":{"e":"trade","E":1788331832690,"s":"BTCUSDT","t":6646633362,"p":"77597.06000000","q":"0.00007000","T":1788331832689,"m":true,"M":true}}
{"type":"trade","received_at_ms":1788331832555,"data":{"e":"trade","E":1788331832690,"s":"BTCUSDT","t":6646633363,"p":"77597.06000000","q":"0.00007000","T":1788331832689,"m":true,"M":true}}
{"type":"trade","received_at_ms":1788331832555,"data":{"e":"trade","E":1788331832690,"s":"BTCUSDT","t":6646633364,"p":"77597.06000000","q":"0.00007000","T":1788331832689,"m":true,"M":true}}
{"type":"trade","received_at_ms":1788331832555,"data":{"e":"trade","E":1788331832690,"s":"BTCUSDT","t":6646633365,"p":"77597.06000000","q":"0.00200000","T":1788331832689,"m":true,"M":true}}
{"type":"trade","received_at_ms":1788331832555,"data":{"e":"trade","E":1788331832690,"s":"BTCUSDT","t":6646633366,"p":"77597.06000000","q":"0.00200000","T":1788331832689,"m":true,"M":true}}
{"type":"trade","received_at_ms":1788331832555,"data":{"e":"trade","E":1788331832690,"s":"BTCUSDT","t":6646633367,"p":"77597.06000000","q":"0.00200000","T":1788331832689,"m":true,"M":true}}
{"type":"trade","received_at_ms":1788331832555,"data":{"e":"trade","E":1788331832690,"s":"BTCUSDT","t":6646633368,"p":"77597.06000000","q":"0.00027000","T":1788331832689,"m":true,"M":true}}
{"type":"depth","received_at_ms":1788331832574,"data":{"e":"depthUpdate","E":1788331832714,"s":"BTCUSDT","U":99555809135,"u":99555809174,"b":[["77597.06000000","0.17957000"],["77597.05000000","0.00090000"],["77594.02000000","0.00000000"],["77594.01000000","0.00028000"],["77592.70000000","0.00007000"],["77565.11000000","0.00412000"],["69837.36000000","0.00432000"],["69837.35000000","0.00009000"]],"a":[["77597.07000000","5.10399000"],["77597.78000000","0.20473000"],["77604.43000000","0.00000000"],["77612.50000000","0.00000000"]]}}
{"type":"trade","received_at_ms":1788331832581,"data":{"e":"trade","E":1788331832721,"s":"BTCUSDT","t":6646633369,"p":"77597.06000000","q":"0.00092000","T":1788331832721,"m":true,"M":true}}
{"type":"trade","received_at_ms":1788331832644,"data":{"e":"trade","E":1788331832783,"s":"BTCUSDT","t":6646633370,"p":"77597.06000000","q":"0.00081000","T":1788331832782,"m":true,"M":true}}
{"type":"trade","received_at_ms":1788331832644,"data":{"e":"trade","E":1788331832783,"s":"BTCUSDT","t":6646633371,"p":"77597.06000000","q":"0.00007000","T":1788331832782,"m":true,"M":true}}
{"type":"trade","received_at_ms":1788331832644,"data":{"e":"trade","E":1788331832783,"s":"BTCUSDT","t":6646633372,"p":"77597.06000000","q":"0.00234000","T":1788331832782,"m":true,"M":true}}
{"type":"depth","received_at_ms":1788331832674,"data":{"e":"depthUpdate","E":1788331832814,"s":"BTCUSDT","U":99555809175,"u":99555809196,"b":[["77597.06000000","0.18742000"],["77594.14000000","0.11041000"],["77594.01000000","0.00014000"],["77592.69000000","0.11370000"],["77592.27000000","0.08233000"],["77539.75000000","0.00000000"],["69837.36000000","0.00432000"],["62077.65000000","0.00000000"]],"a":[]}}
{"type":"trade","received_at_ms":1788331832712,"data":{"e":"trade","E":1788331832851,"s":"BTCUSDT","t":6646633373,"p":"77597.06000000","q":"0.00111000","T":1788331832851,"m":true,"M":true}}
{"type":"depth","received_at_ms":1788331832778,"data":{"e":"depthUpdate","E":1788331832914,"s":"BTCUSDT","U":99555809197,"u":99555809210,"b":[["77597.06000000","0.18638000"],["77591.95000000","0.00208000"],["77577.78000000","0.00000000"],["77539.74000000","0.00000000"],["77536.01000000","0.12892000"],["77514.01000000","0.50189000"],["77510.94000000","1.61611000"],["69837.36000000","0.00432000"]],"a":[["77608.82000000","0.00000000"],["77653.74000000","0.00412000"]]}}
{"type":"depth","received_at_ms":1788331832875,"data":{"e":"depthUpdate","E":1788331833014,"s":"BTCUSDT","U":99555809211,"u":99555809215,"b":[["77577.78000000","0.00007000"],["69837.36000000","0.00432000"],["62077.65000000","0.00032000"]],"a":[["77608.82000000","0.00007000"]]}}
{"type":"depth","received_at_ms":1788331832975,"data":{"e":"depthUpdate","E":1788331833114,"s":"BTCUSDT","U":99555809216,"u":99555809228,"b":[["77587.79000000","0.00200000"],["77585.55000000","0.00000000"],["77585.17000000","0.00400000"],["77585.16000000","0.00000000"],["77580.69000000","0.00000000"],["77551.02000000","0.00007000"],["69837.36000000","0.00432000"],["69837.00000000","0.00000000"]],"a":[]}}
{"type":"depth","received_at_ms":1788331833074,"data":{"e":"depthUpdate","E":1788331833214,"s":"BTCUSDT","U":99555809229,"u":99555809239,"b":[["77587.79000000","0.00600000"],["77581.04000000","0.00400000"],["69837.36000000","0.00432000"],["62077.65000000","0.00000000"]],"a":[["78761.03000000","0.00030000"]]}}
{"type":"trade","received_at_ms":1788331833098,"data":{"e":"trade","E":1788331833237,"s":"BTCUSDT","t":6646633374,"p":"77597.07000000","q":"0.00100000","T":1788331833237,"m":false,"M":true}}
{"type":"trade","received_at_ms":1788331833168,"data":{"e":"trade","E":1788331833308,"s":"BTCUSDT","t":6646633375,"p":"77597.06000000","q":"0.00257000","T":1788331833307,"m":true,"M":true}}
{"type":"depth","received_at_ms":1788331833174,"data":{"e":"depthUpdate","E":1788331833314,"s":"BTCUSDT","U":99555809240,"u":99555809253,"b":[["77597.06000000","0.18367000"],["77592.27000000","0.00021000"],["77592.05000000","0.12010000"],["77591.95000000","0.00000000"],["77582.53000000","0.00000000"],["69837.36000000","0.00448000"],["69837.35000000","0.00000000"],["69837.34000000","0.00009000"]],"a":[["77597.07000000","5.10299000"],["77598.04000000","0.00000000"],["77684.79000000","0.00412000"]]}}
{"type":"depth","received_at_ms":1788331833274,"data":{"e":"depthUpdate","E":1788331833414,"s":"BTCUSDT","U":99555809254,"u":99555809281,"b":[["77597.06000000","0.18375000"],["77597.05000000","0.00090000"],["77592.69000000","0.11370000"],["77592.27000000","0.00007000"],["77592.05000000","0.12017000"],["77592.04000000","0.11342000"],["77591.55000000","0.00904000"],["77590.19000000","0.00000000"],["77582.10000000","0.00000000"],["76433.10000000","0.00030000"],["69837.36000000","0.00432000"]],"a":[["77597.07000000","5.10556000"],["77687.04000000","2.15391000"],["77689.33000000","0.34873000"],["77689.63000000","0.00000000"]]}}
{"type":"trade","received_at_ms":1788331833293,"data":{"e":"trade","E":1788331833432,"s":"BTCUSDT","t":6646633376,"p":"77597.06000000","q":"0.01295000","T":1788331833431,"m":true,"M":true}}
{"type":"depth","received_at_ms":1788331833534,"data":{"e":"depthUpdate","E":1788331833515,"s":"BTCUSDT","U":99555809282,"u":99555809290,"b":[["77597.06000000","0.17080000"],["77582.14000000","0.00257000"],["69837.36000000","0.00448000"],["62077.65000000","0.00032000"]],"a":[["77687.03000000","1.52028000"]]}}
{"type":"depth","received_at_ms":1788331833536,"data":{"e":"depthUpdate","E":1788331833614,"s":"BTCUSDT","U":99555809291,"u":99555809295,"b":[["77582.18000000","0.00257000"],["77582.14000000","0.00000000"],["69837.36000000","0.00432000"],["62078.00000000","0.00800000"],["62077.65000000","0.00000000"]],"a":[]}}
{"type":"depth","received_at_ms":1788331833574,"data":{"e":"depthUpdate","E":1788331833714,"s":"BTCUSDT","U":99555809296,"u":99555809304,"b":[["77551.02000000","0.00000000"],["77403.93000000","0.02019000"],["77377.21000000","0.00000000"],["69837.36000000","0.00448000"],["62078.00000000","0.00600000"]],"a":[["77597.07000000","5.10707000"]]}}
{"type":"trade","received_at_ms":1788331833663,"data":{"e":"trade","E":1788331833803,"s":"BTCUSDT","t":6646633377,"p":"77597.07000000","q":"0.00276000","T":1788331833803,"m":false,"M":true}}
{"type":"depth","received_at_ms":1788331833674,"data":{"e":"depthUpdate","E":1788331833814,"s":"BTCUSDT","U":99555809305,"u":99555809317,"b":[["77568.74000000","0.00000000"],["77565.64000000","0.04718000"],["77561.20000000","0.00408000"],["77555.38000000","0.00000000"],["69837.36000000","0.00432000"],["69837.34000000","0.00000000"],["62077.65000000","0.00000000"]],"a":[["77597.07000000","5.10431000"],["77597.77000000","0.00668000"],["77604.48000000","0.12885000"]]}}
{"type":"depth","received_at_ms":1788331833774,"data":{"e":"depthUpdate","E":1788331833914,"s":"BTCUSDT","U":99555809318,"u":99555809332,"b":[["69837.36000000","0.00432000"]],"a":[["77597.07000000","5.10174000"],["77597.15000000","0.05021000"],["77597.77000000","0.00682000"],["77598.32000000","0.01697000"],["77687.03000000","0.00000000"],["77687.04000000","0.00000000"],["77689.63000000","2.15391000"]]}}
{"type":"depth","received_at_ms":1788331833874,"data":{"e":"depthUpdate","E":1788331834014,"s":"BTCUSDT","U":99555809333,"u":99555809344,"b":[["77577.78000000","0.00007000"],["69837.36000000","0.00432000"],["62078.00000000","0.00600000"],["62077.65000000","0.00032000"]],"a":[["77597.09000000","0.00027000"],["77608.82000000","0.00007000"]]}}
{"type":"depth","received_at_ms":1788331833975,"data":{"e":"depthUpdate","E":1788331834114,"s":"BTCUSDT","U":99555809345,"u":99555809349,"b":[["69837.36000000","0.00448000"]],"a":[["77597.12000000","0.00000000"]]}}
{"type":"trade","received_at_ms":1788331834051,"data":{"e":"trade","E":1788331834190,"s":"BTCUSDT","t":6646633378,"p":"77597.06000000","q":"0.00388000","T":1788331834190,"m":true,"M":true}}
{"type":"depth","received_at_ms":1788331834081,"data":{"e":"depthUpdate","E":1788331834214,"s":"BTCUSDT","U":99555809350,"u":99555809362,"b":[["77597.06000000","0.16692000"],["75800.00000000","25.87769000"],["69837.36000000","0.00416000"],["69837.35000000","0.00009000"],["69837.00000000","0.00000000"],["62077.65000000","0.00000000"]],"a":[["77597.15000000","0.05278000"],["78761.03000000","0.00030000"]]}}
{"type":"trade","received_at_ms":1788331834128,"data":{"e":"trade","E":1788331834268,"s":"BTCUSDT","t":6646633379,"p":"77597.06000000","q":"0.00100000","T":1788331834268,"m":true,"M":true}}
{"type":"depth","received_at_ms":1788331834176,"data":{"e":"depthUpdate","E":1788331834315,"s":"BTCUSDT","U":99555809363,"u":99555809374,"b":[["77597.06000000","0.16592000"],["69837.36000000","0.00432000"],["62078.00000000","0.00600000"]],"a":[["77597.15000000","0.05021000"],["77597.19000000","0.00257000"],["77597.53000000","0.01011000"],["77597.77000000","0.00028000"]]}}
{"type":"depth","received_at_ms":1788331834274,"data":{"e":"depthUpdate","E":1788331834414,"s":"BTCUSDT","U":99555809375,"u":99555809389,"b":[["76433.10000000","0.00030000"],["69837.36000000","0.00432000"]],"a":[["77597.15000000","0.05028000"],["77597.19000000","0.00000000"],["77597.23000000","0.00257000"],["77597.53000000","0.01025000"],["77597.77000000","0.00014000"]]}}
{"type":"depth","received_at_ms":1788331834375,"data":{"e":"depthUpdate","E":1788331834515,"s":"BTCUSDT","U":99555809390,"u":99555809400,"b":[["69837.36000000","0.00432000"],["62078.00000000","0.00800000"],["62077.65000000","0.00032000"]],"a":[["77597.23000000","0.00000000"],["77597.26000000","0.00257000"],["77688.30000000","0.95913000"]]}}
{"type":"trade","received_at_ms":1788331834451,"data":{"e":"trade","E":1788331834590,"s":"BTCUSDT","t":6646633380,"p":"77597.07000000","q":"0.00257000","T":1788331834590,"m":false,"M":true}}
{"type":"depth","received_at_ms":1788331834474,"data":{"e":"depthUpdate","E":1788331834614,"s":"BTCUSDT","U":99555809401,"u":99555809406,"b":[["77586.03000000","0.11335000"],["69837.35000000","0.00000000"],["69837.34000000","0.00009000"],["62077.65000000","0.00000000"]],"a":[["77597.07000000","5.09917000"],["77597.26000000","0.00000000"],["77597.30000000","0.00257000"]]}}
{"type":"depth","received_at_ms":1788331834574,"data":{"e":"depthUpdate","E":1788331834714,"s":"BTCUSDT","U":99555809407,"u":99555809415,"b":[["71389.30000000","0.00015000"],["69837.36000000","0.00432000"]],"a":[["77597.30000000","0.00000000"],["77597.33000000","0.00257000"],["77597.53000000","0.00414000"],["77597.77000000","0.00644000"]]}}
{"type":"depth","received_at_ms":1788331834675,"data":{"e":"depthUpdate","E":1788331834814,"s":"BTCUSDT","U":99555809416,"u":99555809439,"b":[["77596.00000000","0.03035000"],["77595.61000000","0.00014000"],["77595.60000000","0.11335000"],["77594.37000000","0.00000000"],["76800.00000000","17.55753000"],["75556.87000000","0.00000000"],["69837.36000000","0.00448000"],["62077.65000000","0.00000000"]],"a":[["77597.15000000","0.05028000"],["77597.33000000","0.00000000"],["77597.37000000","0.00000000"],["77597.53000000","0.00400000"],["77597.77000000","0.00658000"],["81001.24000000","0.00000000"]]}}
{"type":"depth","received_at_ms":1788331834774,"data":{"e":"depthUpdate","E":1788331834914,"s":"BTCUSDT","U":99555809440,"u":99555809449,"b":[["77596.00000000","0.03028000"],["77595.60000000","0.11342000"],["77592.04000000","0.11335000"],["69837.36000000","0.00432000"]],"a":[["77597.40000000","0.00000000"]]}}
{"type":"depth","received_at_ms":1788331834875,"data":{"e":"depthUpdate","E":1788331835014,"s":"BTCUSDT","U":99555809450,"u":99555809467,"b":[["77597.06000000","0.16613000"],["77597.05000000","0.00097000"],["77593.84000000","0.00027000"],["77592.96000000","0.00020000"],["77591.80000000","0.08219000"],["77591.78000000","0.00215000"],["77591.55000000","0.00886000"],["77585.17000000","0.00000000"],["77577.78000000","0.00007000"],["69837.36000000","0.00448000"],["62077.65000000","0.00032000"]],"a":[["77608.82000000","0.00007000"]]}}
{"type":"depth","received_at_ms":1788331834975,"data":{"e":"depthUpdate","E":1788331835114,"s":"BTCUSDT","U":99555809468,"u":99555809479,"b":[["77594.86000000","0.00020000"],["77592.96000000","0.00000000"],["77565.11000000","0.00000000"],["77526.32000000","0.00000000"],["77495.30000000","0.00412000"],["69837.36000000","0.00448000"]],"a":[["77615.05000000","0.00000000"],["77653.74000000","0.00000000"],["77684.79000000","0.00000000"]]}}
{"type":"depth","received_at_ms":1788331835085,"data":{"e":"depthUpdate","E":1788331835214,"s":"BTCUSDT","U":99555809480,"u":99555809490,"b":[["71389.30000000","0.00000000"],["69837.36000000","0.00464000"],["69837.00000000","0.00000000"],["62078.00000000","0.00800000"],["62077.65000000","0.00000000"]],"a":[["78761.03000000","0.00030000"]]}}
{"type":"trade","received_at_ms":1788331835110,"data":{"e":"trade","E":1788331835249,"s":"BTCUSDT","t":6646633381,"p":"77597.06000000","q":"0.00680000","T":1788331835249,"m":true,"M":true}}
{"type":"depth","received_at_ms":1788331835174,"data":{"e":"depthUpdate","E":1788331835314,"s":"BTCUSDT","U":99555809491,"u":99555809496,"b":[["77597.06000000","0.15933000"],["77465.06000000","0.00000000"],["69837.36000000","0.00448000"],["69837.34000000","0.00000000"]],"a":[]}}
{"type":"depth","received_at_ms":1788331835275,"data":{"e":"depthUpdate","E":1788331835414,"s":"BTCUSDT","U":99555809497,"u":99555809510,"b":[["77594.86000000","0.00000000"],["77592.69000000","0.11363000"],["77592.27000000","0.00000000"],["77592.00000000","0.03036000"],["77388.75000000","0.00007000"],["77384.88000000","0.00007000"],["76433.10000000","0.00030000"],["69837.36000000","0.00464000"]],"a":[["77597.07000000","5.10240000"]]}}
{"type":"depth","received_at_ms":1788331835374,"data":{"e":"depthUpdate","E":1788331835514,"s":"BTCUSDT","U":99555809511,"u":99555809515,"b":[["77384.88000000","0.00000000"],["69837.36000000","0.00432000"],["62077.65000000","0.00032000"]],"a":[["77653.76000000","0.02152000"]]}}
{"type":"depth","received_at_ms":1788331835474,"data":{"e":"depthUpdate","E":1788331835614,"s":"BTCUSDT","U":99555809516,"u":99555809530,"b":[["75557.06000000","0.00010000"],["69837.36000000","0.00464000"],["62078.00000000","0.00800000"],["62077.65000000","0.00000000"]],"a":[["77597.07000000","5.10557000"],["77597.77000000","0.00028000"],["77689.33000000","0.95496000"]]}}
{"type":"depth","received_at_ms":1788331835574,"data":{"e":"depthUpdate","E":1788331835714,"s":"BTCUSDT","U":99555809531,"u":99555809546,"b":[["77592.29000000","0.00021000"],["77586.67000000","0.00000000"],["77526.34000000","0.00412000"],["69837.36000000","0.00448000"]],"a":[["77597.07000000","5.10902000"],["77597.15000000","0.05028000"],["77597.77000000","0.00014000"],["77598.32000000","0.01711000"]]}}
{"type":"depth","received_at_ms":1788331835674,"data":{"e":"depthUpdate","E":1788331835814,"s":"BTCUSDT","U":99555809547,"u":99555809554,"b":[["77590.42000000","0.00098000"],["77582.18000000","0.00000000"],["69837.36000000","0.00432000"],["62077.65000000","0.00000000"]],"a":[["81001.06000000","0.00010000"]]}}
{"type":"depth","received_at_ms":1788331835775,"data":{"e":"depthUpdate","E":1788331835915,"s":"BTCUSDT","U":99555809555,"u":99555809557,"b":[["77582.98000000","0.00257000"],["77418.74000000","0.00012000"],["69837.36000000","0.00448000"]],"a":[]}}
{"type":"depth","received_at_ms":1788331835875,"data":{"e":"depthUpdate","E":1788331836014,"s":"BTCUSDT","U":99555809558,"u":99555809563,"b":[["77577.78000000","0.00000000"],["69837.36000000","0.00448000"],["62077.65000000","0.00032000"]],"a":[["77608.82000000","0.00000000"]]}}
{"type":"depth","received_at_ms":1788331835974,"data":{"e":"depthUpdate","E":1788331836114,"s":"BTCUSDT","U":99555809564,"u":99555809569,"b":[["77577.78000000","0.00007000"],["69837.36000000","0.00448000"]],"a":[["77597.77000000","0.00014000"],["77608.82000000","0.00007000"]]}}
{"type":"depth","received_at_ms":1788331836074,"data":{"e":"depthUpdate","E":1788331836214,"s":"BTCUSDT","U":99555809570,"u":99555809582,"b":[["77413.01000000","4.50134000"],["77381.66000000","0.00000000"],["77378.67000000","0.00813000"],["76502.27000000","0.00000000"],["69837.36000000","0.00448000"],["69837.00000000","0.00000000"],["62077.65000000","0.00000000"]],"a":[["77597.79000000","0.25685000"],["78761.03000000","0.00030000"]]}}
{"type":"depth","received_at_ms":1788331836175,"data":{"e":"depthUpdate","E":1788331836314,"s":"BTCUSDT","U":99555809583,"u":99555809591,"b":[["69837.36000000","0.00464000"],["62078.00000000","0.00800000"]],"a":[["77597.79000000","0.25428000"],["77597.82000000","0.32510000"]]}}
{"type":"depth","received_at_ms":1788331836275,"data":{"e":"depthUpdate","E":1788331836414,"s":"BTCUSDT","U":99555809592,"u":99555809600,"b":[["76433.10000000","0.00030000"],["69837.36000000","0.00448000"],["62078.00000000","0.00800000"]],"a":[["77597.82000000","0.32253000"],["77597.84000000","0.00257000"]]}}
{"type":"trade","received_at_ms":1788331836341,"data":{"e":"trade","E":1788331836473,"s":"BTCUSDT","t":6646633382,"p":"77597.06000000","q":"0.00009000","T":1788331836473,"m":true,"M":true}}
{"type":"trade","received_at_ms":1788331836341,"data":{"e":"trade","E":1788331836473,"s":"BTCUSDT","t":6646633383,"p":"77597.06000000","q":"0.09811000","T":1788331836473,"m":true,"M":true}}
{"type":"trade","received_at_ms":1788331836341,"data":{"e":"trade","E":1788331836473,"s":"BTCUSDT","t":6646633384,"p":"77597.06000000","q":"0.02000000","T":1788331836473,"m":true,"M":true}}
{"type":"trade","received_at_ms":1788331836341,"data":{"e":"trade","E":1788331836473,"s":"BTCUSDT","t":6646633385,"p":"77597.06000000","q":"0.02000000","T":1788331836473,"m":true,"M":true}}
{"type":"trade","received_at_ms":1788331836341,"data":{"e":"trade","E":1788331836473,"s":"BTCUSDT","t":6646633386,"p":"77597.06000000","q":"0.00007000","T":1788331836473,"m":true,"M":true}}
{"type":"trade","received_at_ms":1788331836341,"data":{"e":"trade","E":1788331836473,"s":"BTCUSDT","t":6646633387,"p":"77597.06000000","q":"0.00007000","T":1788331836473,"m":true,"M":true}}
{"type":"trade","received_at_ms":1788331836341,"data":{"e":"trade","E":1788331836473,"s":"BTCUSDT","t":6646633388,"p":"77597.06000000","q":"0.00007000","T":1788331836473,"m":true,"M":true}}
{"type":"trade","received_at_ms":1788331836341,"data":{"e":"trade","E":1788331836473,"s":"BTCUSDT","t":6646633389,"p":"77597.06000000","q":"0.00007000","T":1788331836473,"m":true,"M":true}}
{"type":"trade","received_at_ms":1788331836341,"data":{"e":"trade","E":1788331836473,"s":"BTCUSDT","t":6646633390,"p":"77597.06000000","q":"0.00007000","T":1788331836473,"m":true,"M":true}}
{"type":"trade","received_at_ms":1788331836341,"data":{"e":"trade","E":1788331836473,"s":"BTCUSDT","t":6646633391,"p":"77597.06000000","q":"0.00007000","T":1788331836473,"m":true,"M":true}}
{"type":"trade","received_at_ms":1788331836341,"data":{"e":"trade","E":1788331836473,"s":"BTCUSDT","t":6646633392,"p":"77597.06000000","q":"0.00007000","T":1788331836473,"m":true,"M":true}}
{"type":"trade","received_at_ms":1788331836341,"data":{"e":"trade","E":1788331836473,"s":"BTCUSDT","t":6646633393,"p":"77597.06000000","q":"0.00007000","T":1788331836473,"m":true,"M":true}}
{"type":"trade","received_at_ms":1788331836341,"data":{"e":"trade","E":1788331836473,"s":"BTCUSDT","t":6646633394,"p":"77597.06000000","q":"0.00001000","T":1788331836473,"m":true,"M":true}}
{"type":"trade","received_at_ms":1788331836341,"data":{"e":"trade","E":1788331836473,"s":"BTCUSDT","t":6646633395,"p":"77597.06000000","q":"0.00008000","T":1788331836473,"m":true,"M":true}}
{"type":"trade","received_at_ms":1788331836341,"data":{"e":"trade","E":1788331836473,"s":"BTCUSDT","t":6646633396,"p":"77597.06000000","q":"0.00065000","T":1788331836473,"m":true,"M":true}}
{"type":"trade","received_at_ms":1788331836341,"data":{"e":"trade","E":1788331836473,"s":"BTCUSDT","t":6646633397,"p":"77597.06000000","q":"0.00045000","T":1788331836473,"m":true,"M":true}}
{"type":"trade","received_at_ms":1788331836341,"data":{"e":"trade","E":1788331836473,"s":"BTCUSDT","t":6646633398,"p":"77597.06000000","q":"0.00019000","T":1788331836473,"m":true,"M":true}}
{"type":"trade","received_at_ms":1788331836341,"data":{"e":"trade","E":1788331836473,"s":"BTCUSDT","t":6646633399,"p":"77597.06000000","q":"0.00007000","T":1788331836473,"m":true,"M":true}}
{"type":"trade","received_at_ms":1788331836341,"data":{"e":"trade","E":1788331836473,"s":"BTCUSDT","t":6646633400,"p":"77597.06000000","q":"0.00007000","T":1788331836473,"m":true,"M":true}}
{"type":"trade","received_at_ms":1788331836341,"data":{"e":"trade","E":1788331836473,"s":"BTCUSDT","t":6646633401,"p":"77597.06000000","q":"0.00013000","T":1788331836473,"m":true,"M":true}}
{"type":"trade","received_at_ms":1788331836341,"data":{"e":"trade","E":1788331836473,"s":"BTCUSDT","t":6646633402,"p":"77597.06000000","q":"0.00007000","T":1788331836473,"m":true,"M":true}}
{"type":"trade","received_at_ms":1788331836341,"data":{"e":"trade","E":1788331836473,"s":"BTCUSDT","t":6646633403,"p":"77597.06000000","q":"0.00007000","T":1788331836473,"m":true,"M":true}}
{"type":"trade","received_at_ms":1788331836341,"data":{"e":"trade","E":1788331836473,"s":"BTCUSDT","t":6646633404,"p":"77597.06000000","q":"0.00007000","T":1788331836473,"m":true,"M":true}}
{"type":"trade","received_at_ms":1788331836341,"data":{"e":"trade","E":1788331836473,"s":"BTCUSDT","t":6646633405,"p":"77597.06000000","q":"0.00007000","T":1788331836473,"m":true,"M":true}}
{"type":"trade","received_at_ms":1788331836341,"data":{"e":"trade","E":1788331836473,"s":"BTCUSDT","t":6646633406,"p":"77597.06000000","q":"0.00007000","T":1788331836473,"m":true,"M":true}}
{"type":"trade","received_at_ms":1788331836341,"data":{"e":"trade","E":1788331836473,"s":"BTCUSDT","t":6646633407,"p":"77597.06000000","q":"0.00007000","T":1788331836473,"m":true,"M":true}}
{"type":"trade","received_at_ms":1788331836341,"data":{"e":"trade","E":1788331836473,"s":"BTCUSDT","t":6646633408,"p":"77597.06000000","q":"0.00129000","T":1788331836473,"m":true,"M":true}}
{"type":"trade","received_at_ms":1788331836341,"data":{"e":"trade","E":1788331836473,"s":"BTCUSDT","t":6646633409,"p":"77597.06000000","q":"0.00071000","T":1788331836473,"m":true,"M":true}}
{"type":"trade","received_at_ms":1788331836341,"data":{"e":"trade","E":1788331836473,"s":"BTCUSDT","t":6646633410,"p":"77597.06000000","q":"0.00200000","T":1788331836473,"m":true,"M":true}}
{"type":"trade","received_at_ms":1788331836341,"data":{"e":"trade","E":1788331836473,"s":"BTCUSDT","t":6646633411,"p":"77597.06000000","q":"0.00200000","T":1788331836473,"m":true,"M":true}}
{"type":"trade","received_at_ms":1788331836341,"data":{"e":"trade","E":1788331836473,"s":"BTCUSDT","t":6646633412,"p":"77597.06000000","q":"0.00007000","T":1788331836473,"m":true,"M":true}}
{"type":"trade","received_at_ms":1788331836342,"data":{"e":"trade","E":1788331836473,"s":"BTCUSDT","t":6646633413,"p":"77597.06000000","q":"0.00200000","T":1788331836473,"m":true,"M":true}}
{"type":"trade","received_at_ms":1788331836342,"data":{"e":"trade","E":1788331836473,"s":"BTCUSDT","t":6646633414,"p":"77597.06000000","q":"0.01000000","T":1788331836473,"m":true,"M":true}}
{"type":"trade","received_at_ms":1788331836342,"data":{"e":"trade","E":1788331836473,"s":"BTCUSDT","t":6646633415,"p":"77597.06000000","q":"0.00007000","T":1788331836473,"m":true,"M":true}}
{"type":"trade","received_at_ms":1788331836342,"data":{"e":"trade","E":1788331836473,"s":"BTCUSDT","t":6646633416,"p":"77597.06000000","q":"0.00007000","T":1788331836473,"m":true,"M":true}}
{"type":"trade","received_at_ms":1788331836342,"data":{"e":"trade","E":1788331836473,"s":"BTCUSDT","t":6646633417,"p":"77597.06000000","q":"0.00008000","T":1788331836473,"m":true,"M":true}}
{"type":"trade","received_at_ms":1788331836342,"data":{"e":"trade","E":1788331836473,"s":"BTCUSDT","t":6646633418,"p":"77597.06000000","q":"0.00007000","T":1788331836473,"m":true,"M":true}}
{"type":"trade","received_at_ms":1788331836342,"data":{"e":"trade","E":1788331836473,"s":"BTCUSDT","t":6646633419,"p":"77597.06000000","q":"0.00007000","T":1788331836473,"m":true,"M":true}}
{"type":"trade","received_at_ms":1788331836342,"data":{"e":"trade","E":1788331836473,"s":"BTCUSDT","t":6646633420,"p":"77597.06000000","q":"0.00007000","T":1788331836473,"m":true,"M":true}}
{"type":"trade","received_at_ms":1788331836342,"data":{"e":"trade","E":1788331836473,"s":"BTCUSDT","t":6646633421,"p":"77597.06000000","q":"0.00007000","T":1788331836473,"m":true,"M":true}}
{"type":"trade","received_at_ms":1788331836342,"data":{"e":"trade","E":1788331836473,"s":"BTCUSDT","t":6646633422,"p":"77597.05000000","q":"0.00007000","T":1788331836473,"m":true,"M":true}}
{"type":"trade","received_at_ms":1788331836342,"data":{"e":"trade","E":1788331836473,"s":"BTCUSDT","t":6646633423,"p":"77597.05000000","q":"0.00007000","T":1788331836473,"m":true,"M":true}}
{"type":"trade","received_at_ms":1788331836342,"data":{"e":"trade","E":1788331836473,"s":"BTCUSDT","t":6646633424,"p":"77597.05000000","q":"0.00007000","T":1788331836473,"m":true,"M":true}}
{"type":"trade","received_at_ms":1788331836342,"data":{"e":"trade","E":1788331836473,"s":"BTCUSDT","t":6646633425,"p":"77597.05000000","q":"0.00007000","T":1788331836473,"m":true,"M":true}}
{"type":"trade","received_at_ms":1788331836342,"data":{"e":"trade","E":1788331836473,"s":"BTCUSDT","t":6646633426,"p":"77597.05000000","q":"0.00007000","T":1788331836473,"m":true,"M":true}}
{"type":"trade","received_at_ms":1788331836342,"data":{"e":"trade","E":1788331836473,"s":"BTCUSDT","t":6646633427,"p":"77597.05000000","q":"0.00007000","T":1788331836473,"m":true,"M":true}}
{"type":"trade","received_at_ms":1788331836342,"data":{"e":"trade","E":1788331836473,"s":"BTCUSDT","t":6646633428,"p":"77597.05000000","q":"0.00007000","T":1788331836473,"m":true,"M":true}}
{"type":"trade","received_at_ms":1788331836342,"data":{"e":"trade","E":1788331836473,"s":"BTCUSDT","t":6646633429,"p":"77597.05000000","q":"0.00007000","T":1788331836473,"m":true,"M":true}}
{"type":"trade","received_at_ms":1788331836342,"data":{"e":"trade","E":1788331836473,"s":"BTCUSDT","t":6646633430,"p":"77597.05000000","q":"0.00013000","T":1788331836473,"m":true,"M":true}}
{"type":"trade","received_at_ms":1788331836342,"data":{"e":"trade","E":1788331836473,"s":"BTCUSDT","t":6646633431,"p":"77597.05000000","q":"0.00007000","T":1788331836473,"m":true,"M":true}}
{"type":"trade","received_at_ms":1788331836342,"data":{"e":"trade","E":1788331836473,"s":"BTCUSDT","t":6646633432,"p":"77597.05000000","q":"0.00007000","T":1788331836473,"m":true,"M":true}}
{"type":"trade","received_at_ms":1788331836342,"data":{"e":"trade","E":1788331836473,"s":"BTCUSDT","t":6646633433,"p":"77597.05000000","q":"0.00007000","T":1788331836473,"m":true,"M":true}}
{"type":"trade","received_at_ms":1788331836342,"data":{"e":"trade","E":1788331836473,"s":"BTCUSDT","t":6646633434,"p":"77597.05000000","q":"0.00007000","T":1788331836473,"m":true,"M":true}}
{"type":"trade","received_at_ms":1788331836342,"data":{"e":"trade","E":1788331836473,"s":"BTCUSDT","t":6646633435,"p":"77597.04000000","q":"0.00013000","T":1788331836473,"m":true,"M":true}}
{"type":"trade","received_at_ms":1788331836342,"data":{"e":"trade","E":1788331836473,"s":"BTCUSDT","t":6646633436,"p":"77596.88000000","q":"0.00008000","T":1788331836473,"m":true,"M":true}}
{"type":"trade","received_at_ms":1788331836342,"data":{"e":"trade","E":1788331836473,"s":"BTCUSDT","t":6646633437,"p":"77596.80000000","q":"0.00007000","T":1788331836473,"m":true,"M":true}}
{"type":"trade","received_at_ms":1788331836342,"data":{"e":"trade","E":1788331836473,"s":"BTCUSDT","t":6646633438,"p":"77596.80000000","q":"0.00007000","T":1788331836473,"m":true,"M":true}}
{"type":"trade","received_at_ms":1788331836342,"data":{"e":"trade","E":1788331836473,"s":"BTCUSDT","t":6646633439,"p":"77596.80000000","q":"0.00007000","T":1788331836473,"m":true,"M":true}}
{"type":"trade","received_at_ms":1788331836342,"data":{"e":"trade","E":1788331836473,"s":"BTCUSDT","t":6646633440,"p":"77596.80000000","q":"0.00007000","T":1788331836473,"m":true,"M":true}}
{"type":"trade","received_at_ms":1788331836342,"data":{"e":"trade","E":1788331836473,"s":"BTCUSDT","t":6646633441,"p":"77596.80000000","q":"0.00007000","T":1788331836473,"m":true,"M":true}}
{"type":"trade","received_at_ms":1788331836342,"data":{"e":"trade","E":1788331836473,"s":"BTCUSDT","t":6646633442,"p":"77596.64000000","q":"0.00007000","T":1788331836473,"m":true,"M":true}}
{"type":"trade","received_at_ms":1788331836342,"data":{"e":"trade","E":1788331836473,"s":"BTCUSDT","t":6646633443,"p":"77596.11000000","q":"0.00007000","T":1788331836473,"m":true,"M":true}}
{"type":"trade","received_at_ms":1788331836342,"data":{"e":"trade","E":1788331836473,"s":"BTCUSDT","t":6646633444,"p":"77596.11000000","q":"0.00007000","T":1788331836473,"m":true,"M":true}}
{"type":"trade","received_at_ms":1788331836342,"data":{"e":"trade","E":1788331836473,"s":"BTCUSDT","t":6646633445,"p":"77596.01000000","q":"0.00007000","T":1788331836473,"m":true,"M":true}}
{"type":"trade","received_at_ms":1788331836342,"data":{"e":"trade","E":1788331836473,"s":"BTCUSDT","t":6646633446,"p":"77596.01000000","q":"0.00007000","T":1788331836473,"m":true,"M":true}}
{"type":"trade","received_at_ms":1788331836342,"data":{"e":"trade","E":1788331836473,"s":"BTCUSDT","t":6646633447,"p":"77596.01000000","q":"0.00007000","T":1788331836473,"m":true,"M":true}}
{"type":"trade","received_at_ms":1788331836342,"data":{"e":"trade","E":1788331836473,"s":"BTCUSDT","t":6646633448,"p":"77596.00000000","q":"0.00077000","T":1788331836473,"m":true,"M":true}}
{"type":"trade","received_at_ms":1788331836342,"data":{"e":"trade","E":1788331836473,"s":"BTCUSDT","t":6646633449,"p":"77596.00000000","q":"0.00923000","T":1788331836473,"m":true,"M":true}}
{"type":"trade","received_at_ms":1788331836342,"data":{"e":"trade","E":1788331836473,"s":"BTCUSDT","t":6646633450,"p":"77596.00000000","q":"0.00500000","T":1788331836473,"m":true,"M":true}}
{"type":"trade","received_at_ms":1788331836343,"data":{"e":"trade","E":1788331836473,"s":"BTCUSDT","t":6646633451,"p":"77596.00000000","q":"0.00500000","T":1788331836473,"m":true,"M":true}}
{"type":"trade","received_at_ms":1788331836343,"data":{"e":"trade","E":1788331836473,"s":"BTCUSDT","t":6646633452,"p":"77596.00000000","q":"0.00077000","T":1788331836473,"m":true,"M":true}}
{"type":"trade","received_at_ms":1788331836343,"data":{"e":"trade","E":1788331836473,"s":"BTCUSDT","t":6646633453,"p":"77596.00000000","q":"0.00923000","T":1788331836473,"m":true,"M":true}}
{"type":"trade","received_at_ms":1788331836343,"data":{"e":"trade","E":1788331836473,"s":"BTCUSDT","t":6646633454,"p":"77596.00000000","q":"0.00007000","T":1788331836473,"m":true,"M":true}}
{"type":"trade","received_at_ms":1788331836343,"data":{"e":"trade","E":1788331836473,"s":"BTCUSDT","t":6646633455,"p":"77596.00000000","q":"0.00007000","T":1788331836473,"m":true,"M":true}}
{"type":"trade","received_at_ms":1788331836343,"data":{"e":"trade","E":1788331836473,"s":"BTCUSDT","t":6646633456,"p":"77596.00000000","q":"0.00007000","T":1788331836473,"m":true,"M":true}}
{"type":"trade","received_at_ms":1788331836343,"data":{"e":"trade","E":1788331836473,"s":"BTCUSDT","t":6646633457,"p":"77596.00000000","q":"0.00007000","T":1788331836473,"m":true,"M":true}}
{"type":"trade","received_at_ms":1788331836343,"data":{"e":"trade","E":1788331836473,"s":"BTCUSDT","t":6646633458,"p":"77596.00000000","q":"0.00007000","T":1788331836473,"m":true,"M":true}}
{"type":"trade","received_at_ms":1788331836343,"data":{"e":"trade","E":1788331836473,"s":"BTCUSDT","t":6646633459,"p":"77596.00000000","q":"0.00007000","T":1788331836473,"m":true,"M":true}}
{"type":"trade","received_at_ms":1788331836343,"data":{"e":"trade","E":1788331836473,"s":"BTCUSDT","t":6646633460,"p":"77595.87000000","q":"0.00007000","T":1788331836473,"m":true,"M":true}}
{"type":"trade","received_at_ms":1788331836343,"data":{"e":"trade","E":1788331836473,"s":"BTCUSDT","t":6646633461,"p":"77595.82000000","q":"0.00007000","T":1788331836473,"m":true,"M":true}}
{"type":"trade","received_at_ms":1788331836343,"data":{"e":"trade","E":1788331836473,"s":"BTCUSDT","t":6646633462,"p":"77595.82000000","q":"0.00007000","T":1788331836473,"m":true,"M":true}}
{"type":"trade","received_at_ms":1788331836343,"data":{"e":"trade","E":1788331836473,"s":"BTCUSDT","t":6646633463,"p":"77595.61000000","q":"0.00007000","T":1788331836473,"m":true,"M":true}}
{"type":"trade","received_at_ms":1788331836343,"data":{"e":"trade","E":1788331836473,"s":"BTCUSDT","t":6646633464,"p":"77595.61000000","q":"0.00007000","T":1788331836473,"m":true,"M":true}}
{"type":"trade","received_at_ms":1788331836343,"data":{"e":"trade","E":1788331836474,"s":"BTCUSDT","t":6646633465,"p":"77595.61000000","q":"0.00007000","T":1788331836474,"m":true,"M":true}}
{"type":"trade","received_at_ms":1788331836343,"data":{"e":"trade","E":1788331836474,"s":"BTCUSDT","t":6646633466,"p":"77595.60000000","q":"0.00007000","T":1788331836474,"m":true,"M":true}}
{"type":"trade","received_at_ms":1788331836343,"data":{"e":"trade","E":1788331836476,"s":"BTCUSDT","t":6646633467,"p":"77595.19000000","q":"0.00007000","T":1788331836475,"m":true,"M":true}}
{"type":"trade","received_at_ms":1788331836343,"data":{"e":"trade","E":1788331836476,"s":"BTCUSDT","t":6646633468,"p":"77595.19000000","q":"0.00007000","T":1788331836475,"m":true,"M":true}}
{"type":"trade","received_at_ms":1788331836343,"data":{"e":"trade","E":1788331836476,"s":"BTCUSDT","t":6646633469,"p":"77595.19000000","q":"0.00007000","T":1788331836475,"m":true,"M":true}}
{"type":"trade","received_at_ms":1788331836343,"data":{"e":"trade","E":1788331836476,"s":"BTCUSDT","t":6646633470,"p":"77595.19000000","q":"0.00007000","T":1788331836475,"m":true,"M":true}}
{"type":"trade","received_at_ms":1788331836343,"data":{"e":"trade","E":1788331836476,"s":"BTCUSDT","t":6646633471,"p":"77594.37000000","q":"0.00007000","T":1788331836475,"m":true,"M":true}}
{"type":"trade","received_at_ms":1788331836506,"data":{"e":"trade","E":1788331836478,"s":"BTCUSDT","t":6646633472,"p":"77594.36000000","q":"0.00007000","T":1788331836477,"m":true,"M":true}}
{"type":"trade","received_at_ms":1788331836506,"data":{"e":"trade","E":1788331836478,"s":"BTCUSDT","t":6646633473,"p":"77594.36000000","q":"0.00007000","T":1788331836477,"m":true,"M":true}}
{"type":"trade","received_at_ms":1788331836506,"data":{"e":"trade","E":1788331836478,"s":"BTCUSDT","t":6646633474,"p":"77594.36000000","q":"0.00007000","T":1788331836477,"m":true,"M":true}}
{"type":"trade","received_at_ms":1788331836506,"data":{"e":"trade","E":1788331836478,"s":"BTCUSDT","t":6646633475,"p":"77594.36000000","q":"0.00007000","T":1788331836477,"m":true,"M":true}}
{"type":"trade","received_at_ms":1788331836506,"data":{"e":"trade","E":1788331836478,"s":"BTCUSDT","t":6646633476,"p":"77594.36000000","q":"0.00007000","T":1788331836477,"m":true,"M":true}}
{"type":"trade","received_at_ms":1788331836506,"data":{"e":"trade","E":1788331836478,"s":"BTCUSDT","t":6646633477,"p":"77594.36000000","q":"0.00007000","T":1788331836477,"m":true,"M":true}}
{"type":"trade","received_at_ms":1788331836506,"data":{"e":"trade","E":1788331836478,"s":"BTCUSDT","t":6646633478,"p":"77594.36000000","q":"0.00007000","T":1788331836477,"m":true,"M":true}}
{"type":"trade","received_at_ms":1788331836506,"data":{"e":"trade","E":1788331836478,"s":"BTCUSDT","t":6646633479,"p":"77594.36000000","q":"0.00007000","T":1788331836477,"m":true,"M":true}}
{"type":"trade","received_at_ms":1788331836506,"data":{"e":"trade","E":1788331836478,"s":"BTCUSDT","t":6646633480,"p":"77594.14000000","q":"0.00007000","T":1788331836477,"m":true,"M":true}}
{"type":"trade","received_at_ms":1788331836506,"data":{"e":"trade","E":1788331836478,"s":"BTCUSDT","t":6646633481,"p":"77594.14000000","q":"0.00007000","T":1788331836477,"m":true,"M":true}}
{"type":"trade","received_at_ms":1788331836506,"data":{"e":"trade","E":1788331836478,"s":"BTCUSDT","t":6646633482,"p":"77594.01000000","q":"0.00007000","T":1788331836477,"m":true,"M":true}}
{"type":"trade","received_at_ms":1788331836506,"data":{"e":"trade","E":1788331836478,"s":"BTCUSDT","t":6646633483,"p":"77594.01000000","q":"0.00007000","T":1788331836477,"m":true,"M":true}}
{"type":"trade","received_at_ms":1788331836506,"data":{"e":"trade","E":1788331836478,"s":"BTCUSDT","t":6646633484,"p":"77594.01000000","q":"0.00007000","T":1788331836477,"m":true,"M":true}}
{"type":"trade","received_at_ms":1788331836506,"data":{"e":"trade","E":1788331836478,"s":"BTCUSDT","t":6646633485,"p":"77594.00000000","q":"0.01000000","T":1788331836477,"m":true,"M":true}}
{"type":"trade","received_at_ms":1788331836506,"data":{"e":"trade","E":1788331836478,"s":"BTCUSDT","t":6646633486,"p":"77594.00000000","q":"0.00500000","T":1788331836477,"m":true,"M":true}}
{"type":"trade","received_at_ms":1788331836506,"data":{"e":"trade","E":1788331836478,"s":"BTCUSDT","t":6646633487,"p":"77594.00000000","q":"0.00500000","T":1788331836477,"m":true,"M":true}}
{"type":"trade","received_at_ms":1788331836506,"data":{"e":"trade","E":1788331836478,"s":"BTCUSDT","t":6646633488,"p":"77594.00000000","q":"0.01000000","T":1788331836477,"m":true,"M":true}}
{"type":"trade","received_at_ms":1788331836506,"data":{"e":"trade","E":1788331836478,"s":"BTCUSDT","t":6646633489,"p":"77594.00000000","q":"0.00007000","T":1788331836477,"m":true,"M":true}}
{"type":"trade","received_at_ms":1788331836506,"data":{"e":"trade","E":1788331836478,"s":"BTCUSDT","t":6646633490,"p":"77594.00000000","q":"0.00007000","T":1788331836477,"m":true,"M":true}}
{"type":"trade","received_at_ms":1788331836506,"data":{"e":"trade","E":1788331836478,"s":"BTCUSDT","t":6646633491,"p":"77594.00000000","q":"0.00007000","T":1788331836477,"m":true,"M":true}}
{"type":"trade","received_at_ms":1788331836506,"data":{"e":"trade","E":1788331836478,"s":"BTCUSDT","t":6646633492,"p":"77594.00000000","q":"0.00007000","T":1788331836477,"m":true,"M":true}}
{"type":"trade","received_at_ms":1788331836507,"data":{"e":"trade","E":1788331836478,"s":"BTCUSDT","t":6646633493,"p":"77594.00000000","q":"0.00007000","T":1788331836477,"m":true,"M":true}}
{"type":"trade","received_at_ms":1788331836507,"data":{"e":"trade","E":1788331836478,"s":"BTCUSDT","t":6646633494,"p":"77594.00000000","q":"0.00007000","T":1788331836477,"m":true,"M":true}}
{"type":"trade","received_at_ms":1788331836507,"data":{"e":"trade","E":1788331836478,"s":"BTCUSDT","t":6646633495,"p":"77593.97000000","q":"0.00007000","T":1788331836477,"m":true,"M":true}}
{"type":"trade","received_at_ms":1788331836507,"data":{"e":"trade","E":1788331836478,"s":"BTCUSDT","t":6646633496,"p":"77593.97000000","q":"0.00007000","T":1788331836477,"m":true,"M":true}}
{"type":"trade","received_at_ms":1788331836507,"data":{"e":"trade","E":1788331836478,"s":"BTCUSDT","t":6646633497,"p":"77593.55000000","q":"0.00007000","T":1788331836477,"m":true,"M":true}}
{"type":"trade","received_at_ms":1788331836507,"data":{"e":"trade","E":1788331836478,"s":"BTCUSDT","t":6646633498,"p":"77593.28000000","q":"0.00007000","T":1788331836477,"m":true,"M":true}}
{"type":"trade","received_at_ms":1788331836507,"data":{"e":"trade","E":1788331836478,"s":"BTCUSDT","t":6646633499,"p":"77593.28000000","q":"0.00007000","T":1788331836477,"m":true,"M":true}}
{"type":"trade","received_at_ms":1788331836507,"data":{"e":"trade","E":1788331836478,"s":"BTCUSDT","t":6646633500,"p":"77592.95000000","q":"0.00007000","T":1788331836477,"m":true,"M":true}}
{"type":"trade","received_at_ms":1788331836507,"data":{"e":"trade","E":1788331836478,"s":"BTCUSDT","t":6646633501,"p":"77592.95000000","q":"0.00007000","T":1788331836477,"m":true,"M":true}}
{"type":"trade","received_at_ms":1788331836507,"data":{"e":"trade","E":1788331836478,"s":"BTCUSDT","t":6646633502,"p":"77592.80000000","q":"0.00531000","T":1788331836477,"m":true,"M":true}}
{"type":"trade","received_at_ms":1788331836507,"data":{"e":"trade","E":1788331836478,"s":"BTCUSDT","t":6646633503,"p":"77592.80000000","q":"0.00007000","T":1788331836477,"m":true,"M":true}}
{"type":"trade","received_at_ms":1788331836507,"data":{"e":"trade","E":1788331836478,"s":"BTCUSDT","t":6646633504,"p":"77592.80000000","q":"0.00007000","T":1788331836477,"m":true,"M":true}}
{"type":"trade","received_at_ms":1788331836507,"data":{"e":"trade","E":1788331836478,"s":"BTCUSDT","t":6646633505,"p":"77592.80000000","q":"0.00007000","T":1788331836477,"m":true,"M":true}}
{"type":"trade","received_at_ms":1788331836507,"data":{"e":"trade","E":1788331836478,"s":"BTCUSDT","t":6646633506,"p":"77592.80000000","q":"0.00007000","T":1788331836477,"m":true,"M":true}}
{"type":"trade","received_at_ms":1788331836507,"data":{"e":"trade","E":1788331836478,"s":"BTCUSDT","t":6646633507,"p":"77592.73000000","q":"0.00007000","T":1788331836477,"m":true,"M":true}}
{"type":"trade","received_at_ms":1788331836507,"data":{"e":"trade","E":1788331836478,"s":"BTCUSDT","t":6646633508,"p":"77592.73000000","q":"0.00007000","T":1788331836477,"m":true,"M":true}}
{"type":"trade","received_at_ms":1788331836507,"data":{"e":"trade","E":1788331836478,"s":"BTCUSDT","t":6646633509,"p":"77592.70000000","q":"0.00007000","T":1788331836477,"m":true,"M":true}}
{"type":"trade","received_at_ms":1788331836507,"data":{"e":"trade","E":1788331836478,"s":"BTCUSDT","t":6646633510,"p":"77592.70000000","q":"0.00007000","T":1788331836477,"m":true,"M":true}}
{"type":"trade","received_at_ms":1788331836507,"data":{"e":"trade","E":1788331836478,"s":"BTCUSDT","t":6646633511,"p":"77592.70000000","q":"0.00007000","T":1788331836477,"m":true,"M":true}}
{"type":"trade","received_at_ms":1788331836507,"data":{"e":"trade","E":1788331836478,"s":"BTCUSDT","t":6646633512,"p":"77592.69000000","q":"0.00007000","T":1788331836477,"m":true,"M":true}}
{"type":"trade","received_at_ms":1788331836507,"data":{"e":"trade","E":1788331836478,"s":"BTCUSDT","t":6646633513,"p":"77592.69000000","q":"0.00007000","T":1788331836477,"m":true,"M":true}}
{"type":"trade","received_at_ms":1788331836507,"data":{"e":"trade","E":1788331836478,"s":"BTCUSDT","t":6646633514,"p":"77592.69000000","q":"0.00007000","T":1788331836477,"m":true,"M":true}}
{"type":"trade","received_at_ms":1788331836507,"data":{"e":"trade","E":1788331836478,"s":"BTCUSDT","t":6646633515,"p":"77592.69000000","q":"0.00007000","T":1788331836477,"m":true,"M":true}}
{"type":"trade","received_at_ms":1788331836507,"data":{"e":"trade","E":1788331836478,"s":"BTCUSDT","t":6646633516,"p":"77592.54000000","q":"0.00007000","T":1788331836477,"m":true,"M":true}}
{"type":"trade","received_at_ms":1788331836507,"data":{"e":"trade","E":1788331836478,"s":"BTCUSDT","t":6646633517,"p":"77592.54000000","q":"0.00007000","T":1788331836477,"m":true,"M":true}}
{"type":"trade","received_at_ms":1788331836507,"data":{"e":"trade","E":1788331836478,"s":"BTCUSDT","t":6646633518,"p":"77592.06000000","q":"0.00007000","T":1788331836477,"m":true,"M":true}}
{"type":"trade","received_at_ms":1788331836507,"data":{"e":"trade","E":1788331836478,"s":"BTCUSDT","t":6646633519,"p":"77592.06000000","q":"0.00007000","T":1788331836477,"m":true,"M":true}}
{"type":"trade","received_at_ms":1788331836507,"data":{"e":"trade","E":1788331836478,"s":"BTCUSDT","t":6646633520,"p":"77592.06000000","q":"0.00007000","T":1788331836477,"m":true,"M":true}}
{"type":"trade","received_at_ms":1788331836507,"data":{"e":"trade","E":1788331836478,"s":"BTCUSDT","t":6646633521,"p":"77592.05000000","q":"0.00007000","T":1788331836477,"m":true,"M":true}}
{"type":"trade","received_at_ms":1788331836507,"data":{"e":"trade","E":1788331836478,"s":"BTCUSDT","t":6646633522,"p":"77592.05000000","q":"0.00007000","T":1788331836477,"m":true,"M":true}}
{"type":"trade","received_at_ms":1788331836507,"data":{"e":"trade","E":1788331836478,"s":"BTCUSDT","t":6646633523,"p":"77592.04000000","q":"0.00007000","T":1788331836477,"m":true,"M":true}}
{"type":"trade","received_at_ms":1788331836507,"data":{"e":"trade","E":1788331836478,"s":"BTCUSDT","t":6646633524,"p":"77592.01000000","q":"0.00007000","T":1788331836477,"m":true,"M":true}}
{"type":"trade","received_at_ms":1788331836507,"data":{"e":"trade","E":1788331836478,"s":"BTCUSDT","t":6646633525,"p":"77592.01000000","q":"0.00007000","T":1788331836477,"m":true,"M":true}}
{"type":"trade","received_at_ms":1788331836507,"data":{"e":"trade","E":1788331836478,"s":"BTCUSDT","t":6646633526,"p":"77592.01000000","q":"0.00007000","T":1788331836477,"m":true,"M":true}}
{"type":"trade","received_at_ms":1788331836507,"data":{"e":"trade","E":1788331836478,"s":"BTCUSDT","t":6646633527,"p":"77592.00000000","q":"0.00008000","T":1788331836477,"m":true,"M":true}}
{"type":"trade","received_at_ms":1788331836507,"data":{"e":"trade","E":1788331836478,"s":"BTCUSDT","t":6646633528,"p":"77592.00000000","q":"0.01000000","T":1788331836477,"m":true,"M":true}}
{"type":"trade","received_at_ms":1788331836507,"data":{"e":"trade","E":1788331836478,"s":"BTCUSDT","t":6646633529,"p":"77592.00000000","q":"0.00500000","T":1788331836477,"m":true,"M":true}}
{"type":"trade","received_at_ms":1788331836507,"data":{"e":"trade","E":1788331836478,"s":"BTCUSDT","t":6646633530,"p":"77592.00000000","q":"0.00500000","T":1788331836477,"m":true,"M":true}}
{"type":"trade","received_at_ms":1788331836507,"data":{"e":"trade","E":1788331836478,"s":"BTCUSDT","t":6646633531,"p":"77592.00000000","q":"0.01000000","T":1788331836477,"m":true,"M":true}}
{"type":"trade","received_at_ms":1788331836507,"data":{"e":"trade","E":1788331836478,"s":"BTCUSDT","t":6646633532,"p":"77592.00000000","q":"0.00007000","T":1788331836477,"m":true,"M":true}}
{"type":"trade","received_at_ms":1788331836507,"data":{"e":"trade","E":1788331836478,"s":"BTCUSDT","t":6646633533,"p":"77592.00000000","q":"0.00007000","T":1788331836477,"m":true,"M":true}}
{"type":"trade","received_at_ms":1788331836507,"data":{"e":"trade","E":1788331836478,"s":"BTCUSDT","t":6646633534,"p":"77592.00000000","q":"0.00007000","T":1788331836477,"m":true,"M":true}}
{"type":"trade","received_at_ms":1788331836507,"data":{"e":"trade","E":1788331836478,"s":"BTCUSDT","t":6646633535,"p":"77592.00000000","q":"0.00007000","T":1788331836477,"m":true,"M":true}}
{"type":"trade","received_at_ms":1788331836507,"data":{"e":"trade","E":1788331836478,"s":"BTCUSDT","t":6646633536,"p":"77592.00000000","q":"0.00007000","T":1788331836477,"m":true,"M":true}}
{"type":"trade","received_at_ms":1788331836507,"data":{"e":"trade","E":1788331836478,"s":"BTCUSDT","t":6646633537,"p":"77592.00000000","q":"0.00007000","T":1788331836477,"m":true,"M":true}}
{"type":"trade","received_at_ms":1788331836507,"data":{"e":"trade","E":1788331836478,"s":"BTCUSDT","t":6646633538,"p":"77591.81000000","q":"0.00012000","T":1788331836477,"m":true,"M":true}}
{"type":"trade","received_at_ms":1788331836507,"data":{"e":"trade","E":1788331836478,"s":"BTCUSDT","t":6646633539,"p":"77591.81000000","q":"0.00007000","T":1788331836477,"m":true,"M":true}}
{"type":"trade","received_at_ms":1788331836507,"data":{"e":"trade","E":1788331836478,"s":"BTCUSDT","t":6646633540,"p":"77591.79000000","q":"0.00077000","T":1788331836477,"m":true,"M":true}}
{"type":"trade","received_at_ms":1788331836507,"data":{"e":"trade","E":1788331836478,"s":"BTCUSDT","t":6646633541,"p":"77591.78000000","q":"0.00007000","T":1788331836477,"m":true,"M":true}}
{"type":"trade","received_at_ms":1788331836507,"data":{"e":"trade","E":1788331836478,"s":"BTCUSDT","t":6646633542,"p":"77591.78000000","q":"0.00007000","T":1788331836477,"m":true,"M":true}}
{"type":"trade","received_at_ms":1788331836507,"data":{"e":"trade","E":1788331836478,"s":"BTCUSDT","t":6646633543,"p":"77591.55000000","q":"0.00886000","T":1788331836477,"m":true,"M":true}}
{"type":"trade","received_at_ms":1788331836507,"data":{"e":"trade","E":1788331836478,"s":"BTCUSDT","t":6646633544,"p":"77591.55000000","q":"0.00007000","T":1788331836477,"m":true,"M":true}}
{"type":"trade","received_at_ms":1788331836507,"data":{"e":"trade","E":1788331836478,"s":"BTCUSDT","t":6646633545,"p":"77591.55000000","q":"0.00007000","T":1788331836477,"m":true,"M":true}}
{"type":"trade","received_at_ms":1788331836507,"data":{"e":"trade","E":1788331836478,"s":"BTCUSDT","t":6646633546,"p":"77590.77000000","q":"0.02899000","T":1788331836477,"m":true,"M":true}}
{"type":"trade","received_at_ms":1788331836507,"data":{"e":"trade","E":1788331836478,"s":"BTCUSDT","t":6646633547,"p":"77590.77000000","q":"0.00007000","T":1788331836477,"m":true,"M":true}}
{"type":"trade","received_at_ms":1788331836507,"data":{"e":"trade","E":1788331836478,"s":"BTCUSDT","t":6646633548,"p":"77590.77000000","q":"0.00007000","T":1788331836477,"m":true,"M":true}}
{"type":"trade","received_at_ms":1788331836507,"data":{"e":"trade","E":1788331836478,"s":"BTCUSDT","t":6646633549,"p":"77590.42000000","q":"0.00007000","T":1788331836477,"m":true,"M":true}}
{"type":"trade","received_at_ms":1788331836507,"data":{"e":"trade","E":1788331836478,"s":"BTCUSDT","t":6646633550,"p":"77590.42000000","q":"0.00084000","T":1788331836477,"m":true,"M":true}}
{"type":"trade","received_at_ms":1788331836507,"data":{"e":"trade","E":1788331836478,"s":"BTCUSDT","t":6646633551,"p":"77590.31000000","q":"0.00007000","T":1788331836477,"m":true,"M":true}}
{"type":"trade","received_at_ms":1788331836507,"data":{"e":"trade","E":1788331836478,"s":"BTCUSDT","t":6646633552,"p":"77590.31000000","q":"0.01063000","T":1788331836477,"m":true,"M":true}}
{"type":"trade","received_at_ms":1788331836507,"data":{"e":"trade","E":1788331836478,"s":"BTCUSDT","t":6646633553,"p":"77590.31000000","q":"0.00007000","T":1788331836477,"m":true,"M":true}}
{"type":"trade","received_at_ms":1788331836507,"data":{"e":"trade","E":1788331836478,"s":"BTCUSDT","t":6646633554,"p":"77590.31000000","q":"0.00007000","T":1788331836477,"m":true,"M":true}}
{"type":"trade","received_at_ms":1788331836507,"data":{"e":"trade","E":1788331836478,"s":"BTCUSDT","t":6646633555,"p":"77590.28000000","q":"0.00322000","T":1788331836477,"m":true,"M":true}}
{"type":"trade","received_at_ms":1788331836507,"data":{"e":"trade","E":1788331836478,"s":"BTCUSDT","t":6646633556,"p":"77590.00000000","q":"0.00534000","T":1788331836477,"m":true,"M":true}}
{"type":"depth","received_at_ms":1788331836507,"data":{"e":"depthUpdate","E":1788331836514,"s":"BTCUSDT","U":99555809601,"u":99555811013,"b":[["77597.06000000","0.00000000"],["77597.05000000","0.00000000"],["77597.04000000","0.00000000"],["77596.88000000","0.00000000"],["77596.80000000","0.00000000"],["77596.64000000","0.00000000"],["77596.11000000","0.00000000"],["77596.01000000","0.00000000"],["77596.00000000","0.00000000"],["77595.87000000","0.00000000"],["77595.82000000","0.00000000"],["77595.61000000","0.00000000"],["77595.60000000","0.00000000"],["77595.19000000","0.00000000"],["77594.52000000","0.00000000"],["77594.37000000","0.00000000"],["77594.36000000","0.00000000"],["77594.15000000","0.00000000"],["77594.14000000","0.00000000"],["77594.01000000","0.00000000"],["77594.00000000","0.00000000"],["77593.97000000","0.00000000"],["77593.84000000","0.00000000"],["77593.55000000","0.00000000"],["77593.28000000","0.00000000"],["77592.95000000","0.00000000"],["77592.80000000","0.00000000"],["77592.73000000","0.00000000"],["77592.70000000","0.00000000"],["77592.69000000","0.00000000"],["77592.54000000","0.00000000"],["77592.29000000","0.00000000"],["77592.24000000","0.00000000"],["77592.06000000","0.00000000"],["77592.05000000","0.00000000"],["77592.04000000","0.00000000"],["77592.03000000","0.00000000"],["77592.01000000","0.00000000"],["77592.00000000","0.00000000"],["77591.97000000","0.00000000"],["77591.94000000","0.00000000"],["77591.81000000","0.00000000"],["77591.80000000","0.00000000"],["77591.79000000","0.00000000"],["77591.78000000","0.00000000"],["77591.73000000","0.00000000"],["77591.55000000","0.00000000"],["77590.77000000","0.00000000"],["77590.42000000","0.00000000"],["77590.31000000","0.00000000"],["77590.28000000","0.00000000"],["77590.02000000","0.00000000"],["77590.00000000","0.16686000"],["77589.99000000","0.00049000"],["77589.77000000","0.00000000"],["77589.76000000","0.00007000"],["77589.45000000","0.00000000"],["77589.08000000","0.00014000"],["77589.07000000","0.01070000"],["77588.94000000","0.00000000"],["77588.92000000","0.00000000"],["77588.84000000","0.00000000"],["77588.52000000","0.00000000"],["77588.38000000","0.00000000"],["77588.36000000","0.00000000"],["77588.33000000","0.00014000"],["77588.32000000","0.04359000"],["77588.31000000","0.03873000"],["77588.18000000","0.00000000"],["77588.07000000","0.00000000"],["77588.01000000","0.00014000"],["77588.00000000","0.03014000"],["77587.84000000","0.00000000"],["77587.80000000","0.00000000"],["77587.79000000","0.00000000"],["77587.78000000","0.00007000"],["77587.77000000","0.00000000"],["77587.65000000","0.00000000"],["77587.31000000","0.00000000"],["77587.30000000","0.01297000"],["77586.97000000","0.00000000"],["77586.96000000","0.00007000"],["77586.60000000","0.00000000"],["77586.48000000","0.00007000"],["77586.35000000","0.00000000"],["77586.26000000","0.00000000"],["77586.19000000","0.00322000"],["77586.14000000","0.00000000"],["77586.04000000","0.00000000"],["77586.03000000","0.00000000"],["77586.02000000","0.00007000"],["77586.01000000","0.00007000"],["77586.00000000","0.03007000"],["77585.75000000","0.00000000"],["77585.74000000","0.00000000"],["77585.46000000","0.00000000"],["77585.33000000","0.00000000"],["77585.30000000","0.00000000"],["77585.13000000","0.00000000"],["77584.75000000","0.00007000"],["77584.74000000","0.02007000"],["77584.71000000","0.00000000"],["77584.32000000","0.00000000"],["77584.31000000","0.00000000"],["77584.22000000","0.00000000"],["77584.21000000","0.11336000"],["77584.20000000","0.65922000"],["77584.19000000","0.00013000"],["77584.07000000","0.00000000"],["77584.05000000","0.00000000"],["77584.00000000","0.03014000"],["77583.92000000","0.00000000"],["77583.90000000","0.02007000"],["77583.77000000","0.00000000"],["77583.56000000","0.00000000"],["77582.99000000","0.00128000"],["77582.98000000","0.00000000"],["77582.80000000","0.00000000"],["77582.64000000","0.00007000"],["77582.54000000","0.00007000"],["77582.35000000","0.00000000"],["77582.24000000","0.16886000"],["77582.06000000","0.00000000"],["77581.93000000","0.02900000"],["77581.54000000","0.00000000"],["77581.29000000","0.07926000"],["77581.28000000","0.00000000"],["77581.27000000","0.00000000"],["77581.26000000","1.31471000"],["77581.25000000","0.00000000"],["77581.04000000","0.00000000"],["77580.76000000","0.00000000"],["77580.54000000","0.00000000"],["77579.86000000","0.03000000"],["77579.56000000","0.04000000"],["77579.54000000","0.00007000"],["77579.45000000","0.00000000"],["77578.92000000","0.00343000"],["77578.63000000","0.00000000"],["77578.60000000","0.00007000"],["77578.36000000","0.08000000"],["77578.01000000","0.00644000"],["77577.66000000","0.00000000"],["77577.58000000","0.00000000"],["77577.35000000","1.31471000"],["77577.34000000","0.00000000"],["77577.30000000","0.00000000"],["77576.89000000","0.00000000"],["77576.44000000","0.00007000"],["77575.58000000","0.02000000"],["77575.45000000","0.00000000"],["77575.04000000","0.00331000"],["77574.66000000","0.00007000"],["77574.61000000","0.00000000"],["77574.60000000","0.00000000"],["77574.53000000","0.00000000"],["77574.52000000","0.00000000"],["77574.48000000","0.00008000"],["77574.12000000","0.00166000"],["77573.78000000","0.00128000"],["77573.71000000","0.00000000"],["77572.87000000","0.34778000"],["77571.88000000","0.00000000"],["77571.83000000","0.00000000"],["77571.71000000","0.00000000"],["77571.17000000","0.00644000"],["77571.16000000","0.00344000"],["77570.72000000","0.00007000"],["77570.60000000","0.00008000"],["77569.90000000","0.00000000"],["77569.79000000","0.62860000"],["77569.40000000","0.00000000"],["77569.22000000","0.00000000"],["77569.00000000","0.00000000"],["77568.07000000","0.00000000"],["77568.06000000","0.00000000"],["77568.00000000","0.03007000"],["77567.28000000","0.00343000"],["77567.07000000","0.00000000"],["77566.87000000","0.02034000"],["77566.72000000","0.00008000"],["77566.57000000","0.00000000"],["77566.24000000","0.00000000"],["77566.02000000","0.00000000"],["77565.64000000","0.00000000"],["77565.63000000","0.00000000"],["77565.32000000","0.44228000"],["77565.31000000","0.00000000"],["77565.02000000","0.07775000"],["77564.31000000","0.00000000"],["77564.28000000","0.00000000"],["77562.90000000","0.00000000"],["77562.84000000","0.00022000"],["77562.57000000","0.00000000"],["77562.50000000","0.00000000"],["77562.14000000","0.00000000"],["77561.40000000","0.00000000"],["77560.61000000","0.00000000"],["77560.02000000","0.07775000"],["77560.00000000","1.96484000"],["77559.72000000","0.00000000"],["77559.23000000","0.04691000"],["77558.96000000","0.00008000"],["77558.73000000","0.00000000"],["77558.66000000","0.00119000"],["77558.26000000","0.00000000"],["77558.00000000","0.03000000"],["77556.59000000","0.00000000"],["77556.00000000","0.03000000"],["77555.38000000","0.00400000"],["77555.08000000","0.00008000"],["77554.96000000","0.00014000"],["77553.85000000","0.07775000"],["77553.25000000","1.09889000"],["77553.24000000","0.00000000"],["77553.10000000","0.00000000"],["77551.50000000","0.00400000"],["77551.21000000","0.00008000"],["77551.02000000","0.00007000"],["77551.00000000","0.01000000"],["77550.64000000","0.07775000"],["77549.24000000","0.30971000"],["77548.56000000","0.00000000"],["77548.08000000","0.00008000"],["77547.08000000","0.00007000"],["77543.87000000","0.34834000"],["77543.14000000","0.00007000"],["77541.26000000","0.64511000"],["77540.22000000","0.00000000"],["77537.71000000","0.00000000"],["77536.62000000","0.00000000"],["77532.05000000","0.00000000"],["77526.01000000","0.00000000"],["77525.79000000","0.00000000"],["77525.03000000","0.00321000"],["77523.89000000","0.00000000"],["77523.02000000","0.00321000"],["77520.00000000","0.03014000"],["77514.01000000","0.02058000"],["77514.00000000","0.03000000"],["77512.41000000","0.00008000"],["77510.94000000","0.00000000"],["77510.03000000","0.00000000"],["77509.25000000","0.12782000"],["77508.77000000","2.26024000"],["77508.74000000","0.00000000"],["77508.35000000","0.00000000"],["77454.55000000","0.00000000"],["77448.17000000","0.00000000"],["77446.29000000","0.00000000"],["77444.81000000","0.00128000"],["77434.82000000","0.00008000"],["77434.20000000","0.10506000"],["77386.34000000","0.16870000"],["77368.69000000","0.00000000"],["77357.23000000","0.00008000"],["77291.08000000","0.00000000"],["77279.64000000","0.00008000"],["77278.17000000","0.00000000"],["77213.48000000","0.00000000"],["77202.05000000","0.00008000"],["77135.88000000","0.00000000"],["77124.46000000","0.00008000"],["77077.55000000","0.00000000"],["77058.28000000","0.00000000"],["77046.87000000","0.00008000"],["76980.68000000","0.00000000"],["76969.28000000","0.00008000"],["76433.10000000","0.00000000"],["69837.36000000","0.00000000"],["69837.35000000","0.00009000"],["69831.00000000","0.00016000"],["62072.00000000","0.14789000"]],"a":[["77590.01000000","3.66875000"],["77590.02000000","0.00027000"],["77590.03000000","0.00013000"],["77590.13000000","0.07485000"],["77590.14000000","0.24814000"],["77590.27000000","0.00000000"],["77590.29000000","0.00000000"],["77590.30000000","0.00400000"],["77590.32000000","0.00000000"],["77590.42000000","0.00014000"],["77590.49000000","0.00000000"],["77590.77000000","0.00007000"],["77590.78000000","0.00000000"],["77591.47000000","0.00000000"],["77591.55000000","1.31471000"],["77591.56000000","0.00000000"],["77591.79000000","0.00000000"],["77591.80000000","0.00000000"],["77591.81000000","0.00000000"],["77591.98000000","0.00130000"],["77592.01000000","0.00000000"],["77592.04000000","0.00000000"],["77592.05000000","0.00000000"],["77592.06000000","0.24828000"],["77592.07000000","0.00126000"],["77592.24000000","0.00400000"],["77592.25000000","0.00000000"],["77592.30000000","0.00000000"],["77592.55000000","0.00014000"],["77592.70000000","0.00014000"],["77592.71000000","0.00000000"],["77592.73000000","0.01289000"],["77592.74000000","0.00014000"],["77592.81000000","0.00014000"],["77592.92000000","0.00000000"],["77592.96000000","0.00000000"],["77593.29000000","0.28008000"],["77593.56000000","0.00000000"],["77593.85000000","0.00000000"],["77593.98000000","0.00000000"],["77594.01000000","0.00014000"],["77594.02000000","0.00014000"],["77594.14000000","0.07507000"],["77594.15000000","0.00014000"],["77594.16000000","0.00000000"],["77594.18000000","0.00400000"],["77594.36000000","1.21812000"],["77594.37000000","1.48284000"],["77594.38000000","0.14483000"],["77594.39000000","0.00000000"],["77594.51000000","0.00120000"],["77594.70000000","0.00000000"],["77595.08000000","0.38686000"],["77595.19000000","0.00000000"],["77595.20000000","0.68563000"],["77595.34000000","0.00000000"],["77595.35000000","0.00007000"],["77595.57000000","0.00000000"],["77595.59000000","0.00000000"],["77595.60000000","0.00000000"],["77595.61000000","0.00000000"],["77595.62000000","1.44429000"],["77595.71000000","0.03000000"],["77595.82000000","0.44413000"],["77595.83000000","0.21569000"],["77595.85000000","0.05007000"],["77595.87000000","0.03227000"],["77595.88000000","0.00000000"],["77595.90000000","0.05007000"],["77596.00000000","0.00000000"],["77596.01000000","0.30000000"],["77596.12000000","0.14619000"],["77596.65000000","0.00000000"],["77596.81000000","0.00000000"],["77596.89000000","0.00000000"],["77596.99000000","0.00000000"],["77597.00000000","0.00000000"],["77597.01000000","0.00007000"],["77597.05000000","0.00000000"],["77597.06000000","1.23370000"],["77597.07000000","1.58607000"],["77597.08000000","0.01021000"],["77597.09000000","0.00000000"],["77597.10000000","0.00000000"],["77597.11000000","0.00007000"],["77597.14000000","0.00000000"],["77597.15000000","0.00007000"],["77597.31000000","0.00007000"],["77597.53000000","0.00000000"],["77597.77000000","1.93234000"],["77597.78000000","0.00000000"],["77597.79000000","0.25353000"],["77597.82000000","0.00007000"],["77597.84000000","0.00000000"],["77598.14000000","0.00007000"],["77598.32000000","0.01690000"],["77598.59000000","0.00000000"],["77598.80000000","0.00000000"],["77598.85000000","0.00000000"],["77598.90000000","0.00000000"],["77599.17000000","0.04138000"],["77599.59000000","0.00027000"],["77599.79000000","0.00000000"],["77600.00000000","0.00015000"],["77600.10000000","0.00007000"],["77600.22000000","1.47075000"],["77600.24000000","0.00000000"],["77600.28000000","0.16870000"],["77600.31000000","0.00000000"],["77600.46000000","0.12886000"],["77600.65000000","0.00007000"],["77600.72000000","0.00000000"],["77600.73000000","0.14079000"],["77601.04000000","0.14282000"],["77601.05000000","0.14266000"],["77601.08000000","0.00000000"],["77601.11000000","0.34809000"],["77601.18000000","0.00000000"],["77601.24000000","0.00007000"],["77601.50000000","0.00333000"],["77601.79000000","0.00010000"],["77601.97000000","0.00000000"],["77601.98000000","0.00000000"],["77602.76000000","0.10424000"],["77602.96000000","0.00000000"],["77603.28000000","0.03210000"],["77603.51000000","0.12000000"],["77603.59000000","0.00000000"],["77603.60000000","0.00000000"],["77604.34000000","0.00007000"],["77604.47000000","1.00246000"],["77604.48000000","0.00000000"],["77604.70000000","0.10424000"],["77605.01000000","0.00000000"],["77605.53000000","0.00008000"],["77605.56000000","0.00000000"],["77605.59000000","0.00000000"],["77605.84000000","0.00000000"],["77605.99000000","0.00000000"],["77606.01000000","0.01278000"],["77606.47000000","0.00000000"],["77606.64000000","0.00008000"],["77607.44000000","0.00000000"],["77607.71000000","0.00000000"],["77607.72000000","0.25789000"],["77607.81000000","0.00000000"],["77609.31000000","0.34805000"],["77609.41000000","0.00008000"],["77609.64000000","0.00000000"],["77610.54000000","0.00000000"],["77610.93000000","0.00000000"],["77611.58000000","0.34804000"],["77612.59000000","0.00017000"],["77613.24000000","0.00200000"],["77613.29000000","0.00136000"],["77613.64000000","0.00000000"],["77615.55000000","0.00000000"],["77615.84000000","0.00000000"],["77616.47000000","0.00000000"],["77617.17000000","0.00008000"],["77617.76000000","0.00007000"],["77618.75000000","0.00000000"],["77619.32000000","0.00000000"],["77619.40000000","0.00400000"],["77619.51000000","0.23936000"],["77619.61000000","0.00000000"],["77619.66000000","0.00007000"],["77619.75000000","0.00000000"],["77620.35000000","0.00009000"],["77621.05000000","0.00008000"],["77621.34000000","0.00000000"],["77621.59000000","0.00000000"],["77621.70000000","0.00000000"],["77622.00000000","0.04344000"],["77623.23000000","0.79623000"],["77623.26000000","0.00800000"],["77623.28000000","0.00008000"],["77623.65000000","0.00000000"],["77624.00000000","0.03000000"],["77624.03000000","0.00000000"],["77624.23000000","0.00000000"],["77624.93000000","0.00008000"],["77625.22000000","0.00000000"],["77625.60000000","0.00000000"],["77626.67000000","0.00000000"],["77627.16000000","0.00000000"],["77628.11000000","0.00009000"],["77628.81000000","0.00008000"],["77629.30000000","0.00000000"],["77629.34000000","0.00000000"],["77629.82000000","0.00000000"],["77631.99000000","0.00000000"],["77633.76000000","0.00000000"],["77633.97000000","0.00000000"],["77635.87000000","0.00000000"],["77636.42000000","0.79616000"],["77637.64000000","0.03866000"],["77645.73000000","0.00000000"],["77649.61000000","0.00000000"],["77653.75000000","0.00321000"],["77655.44000000","0.00000000"],["77656.43000000","0.00000000"],["77656.78000000","0.00000000"],["77667.60000000","0.13715000"],["77673.61000000","2.39495000"],["77679.10000000","0.00000000"],["77681.15000000","0.00000000"],["77681.49000000","0.00000000"],["77681.85000000","1.07442000"],["77683.87000000","0.00000000"],["77701.55000000","0.00000000"],["77703.95000000","0.00000000"],["77731.31000000","0.00128000"],["77733.99000000","0.00000000"],["77963.64000000","0.00000000"],["77977.96000000","0.00008000"],["77985.78000000","0.00000000"],["78055.55000000","0.00025000"],["78063.42000000","0.00000000"],["78133.14000000","0.00008000"],["78141.01000000","0.00000000"],["78210.73000000","0.00032000"],["78218.61000000","0.00000000"],["78761.03000000","0.00000000"]]}}
{"type":"trade","received_at_ms":1788331836507,"data":{"e":"trade","E":1788331836578,"s":"BTCUSDT","t":6646633557,"p":"77590.00000000","q":"0.00466000","T":1788331836578,"m":true,"M":true}}
{"type":"trade","received_at_ms":1788331836507,"data":{"e":"trade","E":1788331836578,"s":"BTCUSDT","t":6646633558,"p":"77590.00000000","q":"0.00500000","T":1788331836578,"m":true,"M":true}}
{"type":"trade","received_at_ms":1788331836507,"data":{"e":"trade","E":1788331836578,"s":"BTCUSDT","t":6646633559,"p":"77590.00000000","q":"0.00500000","T":1788331836578,"m":true,"M":true}}
{"type":"trade","received_at_ms":1788331836507,"data":{"e":"trade","E":1788331836578,"s":"BTCUSDT","t":6646633560,"p":"77590.00000000","q":"0.01000000","T":1788331836578,"m":true,"M":true}}
{"type":"trade","received_at_ms":1788331836507,"data":{"e":"trade","E":1788331836578,"s":"BTCUSDT","t":6646633561,"p":"77590.00000000","q":"0.00007000","T":1788331836578,"m":true,"M":true}}
{"type":"trade","received_at_ms":1788331836507,"data":{"e":"trade","E":1788331836578,"s":"BTCUSDT","t":6646633562,"p":"77590.00000000","q":"0.00007000","T":1788331836578,"m":true,"M":true}}
{"type":"trade","received_at_ms":1788331836507,"data":{"e":"trade","E":1788331836578,"s":"BTCUSDT","t":6646633563,"p":"77590.00000000","q":"0.00007000","T":1788331836578,"m":true,"M":true}}
{"type":"trade","received_at_ms":1788331836507,"data":{"e":"trade","E":1788331836578,"s":"BTCUSDT","t":6646633564,"p":"77590.00000000","q":"0.00007000","T":1788331836578,"m":true,"M":true}}
{"type":"trade","received_at_ms":1788331836507,"data":{"e":"trade","E":1788331836578,"s":"BTCUSDT","t":6646633565,"p":"77590.00000000","q":"0.00007000","T":1788331836578,"m":true,"M":true}}
{"type":"trade","received_at_ms":1788331836507,"data":{"e":"trade","E":1788331836578,"s":"BTCUSDT","t":6646633566,"p":"77590.00000000","q":"0.00007000","T":1788331836578,"m":true,"M":true}}
{"type":"trade","received_at_ms":1788331836507,"data":{"e":"trade","E":1788331836578,"s":"BTCUSDT","t":6646633567,"p":"77590.00000000","q":"0.00008000","T":1788331836578,"m":true,"M":true}}
{"type":"trade","received_at_ms":1788331836507,"data":{"e":"trade","E":1788331836578,"s":"BTCUSDT","t":6646633568,"p":"77590.00000000","q":"0.00007000","T":1788331836578,"m":true,"M":true}}
{"type":"trade","received_at_ms":1788331836507,"data":{"e":"trade","E":1788331836578,"s":"BTCUSDT","t":6646633569,"p":"77590.00000000","q":"0.00007000","T":1788331836578,"m":true,"M":true}}
{"type":"trade","received_at_ms":1788331836507,"data":{"e":"trade","E":1788331836578,"s":"BTCUSDT","t":6646633570,"p":"77590.00000000","q":"0.00007000","T":1788331836578,"m":true,"M":true}}
{"type":"trade","received_at_ms":1788331836507,"data":{"e":"trade","E":1788331836578,"s":"BTCUSDT","t":6646633571,"p":"77590.00000000","q":"0.12886000","T":1788331836578,"m":true,"M":true}}
{"type":"trade","received_at_ms":1788331836507,"data":{"e":"trade","E":1788331836578,"s":"BTCUSDT","t":6646633572,"p":"77590.00000000","q":"0.00007000","T":1788331836578,"m":true,"M":true}}
{"type":"trade","received_at_ms":1788331836507,"data":{"e":"trade","E":1788331836578,"s":"BTCUSDT","t":6646633573,"p":"77590.00000000","q":"0.00007000","T":1788331836578,"m":true,"M":true}}
{"type":"trade","received_at_ms":1788331836507,"data":{"e":"trade","E":1788331836578,"s":"BTCUSDT","t":6646633574,"p":"77590.00000000","q":"0.00007000","T":1788331836578,"m":true,"M":true}}
{"type":"trade","received_at_ms":1788331836507,"data":{"e":"trade","E":1788331836578,"s":"BTCUSDT","t":6646633575,"p":"77590.00000000","q":"0.00007000","T":1788331836578,"m":true,"M":true}}
{"type":"trade","received_at_ms":1788331836508,"data":{"e":"trade","E":1788331836578,"s":"BTCUSDT","t":6646633576,"p":"77590.00000000","q":"0.00007000","T":1788331836578,"m":true,"M":true}}
{"type":"trade","received_at_ms":1788331836508,"data":{"e":"trade","E":1788331836578,"s":"BTCUSDT","t":6646633577,"p":"77590.00000000","q":"0.00007000","T":1788331836578,"m":true,"M":true}}
{"type":"trade","received_at_ms":1788331836508,"data":{"e":"trade","E":1788331836578,"s":"BTCUSDT","t":6646633578,"p":"77590.00000000","q":"0.00349000","T":1788331836578,"m":true,"M":true}}
{"type":"trade","received_at_ms":1788331836508,"data":{"e":"trade","E":1788331836580,"s":"BTCUSDT","t":6646633579,"p":"77590.00000000","q":"0.01651000","T":1788331836579,"m":true,"M":true}}
{"type":"trade","received_at_ms":1788331836508,"data":{"e":"trade","E":1788331836580,"s":"BTCUSDT","t":6646633580,"p":"77590.00000000","q":"0.00007000","T":1788331836579,"m":true,"M":true}}
{"type":"trade","received_at_ms":1788331836508,"data":{"e":"trade","E":1788331836580,"s":"BTCUSDT","t":6646633581,"p":"77590.00000000","q":"0.00007000","T":1788331836579,"m":true,"M":true}}
{"type":"trade","received_at_ms":1788331836508,"data":{"e":"trade","E":1788331836580,"s":"BTCUSDT","t":6646633582,"p":"77590.00000000","q":"0.00007000","T":1788331836579,"m":true,"M":true}}
{"type":"trade","received_at_ms":1788331836508,"data":{"e":"trade","E":1788331836580,"s":"BTCUSDT","t":6646633583,"p":"77590.00000000","q":"0.00007000","T":1788331836579,"m":true,"M":true}}
{"type":"trade","received_at_ms":1788331836508,"data":{"e":"trade","E":1788331836580,"s":"BTCUSDT","t":6646633584,"p":"77590.00000000","q":"0.00007000","T":1788331836579,"m":true,"M":true}}
{"type":"trade","received_at_ms":1788331836508,"data":{"e":"trade","E":1788331836580,"s":"BTCUSDT","t":6646633585,"p":"77590.00000000","q":"0.00007000","T":1788331836579,"m":true,"M":true}}
{"type":"trade","received_at_ms":1788331836508,"data":{"e":"trade","E":1788331836580,"s":"BTCUSDT","t":6646633586,"p":"77590.00000000","q":"0.00007000","T":1788331836579,"m":true,"M":true}}
{"type":"trade","received_at_ms":1788331836508,"data":{"e":"trade","E":1788331836580,"s":"BTCUSDT","t":6646633587,"p":"77590.00000000","q":"0.00200000","T":1788331836579,"m":true,"M":true}}
{"type":"trade","received_at_ms":1788331836508,"data":{"e":"trade","E":1788331836580,"s":"BTCUSDT","t":6646633588,"p":"77590.00000000","q":"0.00007000","T":1788331836579,"m":true,"M":true}}
{"type":"trade","received_at_ms":1788331836508,"data":{"e":"trade","E":1788331836580,"s":"BTCUSDT","t":6646633589,"p":"77590.00000000","q":"0.00007000","T":1788331836579,"m":true,"M":true}}
{"type":"trade","received_at_ms":1788331836508,"data":{"e":"trade","E":1788331836580,"s":"BTCUSDT","t":6646633590,"p":"77590.00000000","q":"0.00008000","T":1788331836579,"m":true,"M":true}}
{"type":"trade","received_at_ms":1788331836508,"data":{"e":"trade","E":1788331836580,"s":"BTCUSDT","t":6646633591,"p":"77590.00000000","q":"0.00007000","T":1788331836579,"m":true,"M":true}}
{"type":"trade","received_at_ms":1788331836508,"data":{"e":"trade","E":1788331836580,"s":"BTCUSDT","t":6646633592,"p":"77589.99000000","q":"0.00007000","T":1788331836579,"m":true,"M":true}}
{"type":"trade","received_at_ms":1788331836508,"data":{"e":"trade","E":1788331836580,"s":"BTCUSDT","t":6646633593,"p":"77589.99000000","q":"0.00007000","T":1788331836579,"m":true,"M":true}}
{"type":"trade","received_at_ms":1788331836508,"data":{"e":"trade","E":1788331836580,"s":"BTCUSDT","t":6646633594,"p":"77589.99000000","q":"0.00007000","T":1788331836579,"m":true,"M":true}}
{"type":"trade","received_at_ms":1788331836508,"data":{"e":"trade","E":1788331836580,"s":"BTCUSDT","t":6646633595,"p":"77589.99000000","q":"0.00007000","T":1788331836579,"m":true,"M":true}}
{"type":"trade","received_at_ms":1788331836508,"data":{"e":"trade","E":1788331836580,"s":"BTCUSDT","t":6646633596,"p":"77589.99000000","q":"0.00007000","T":1788331836579,"m":true,"M":true}}
{"type":"trade","received_at_ms":1788331836508,"data":{"e":"trade","E":1788331836580,"s":"BTCUSDT","t":6646633597,"p":"77589.99000000","q":"0.00007000","T":1788331836579,"m":true,"M":true}}
{"type":"trade","received_at_ms":1788331836508,"data":{"e":"trade","E":1788331836580,"s":"BTCUSDT","t":6646633598,"p":"77589.99000000","q":"0.00007000","T":1788331836579,"m":true,"M":true}}
{"type":"trade","received_at_ms":1788331836508,"data":{"e":"trade","E":1788331836580,"s":"BTCUSDT","t":6646633599,"p":"77589.99000000","q":"0.00007000","T":1788331836579,"m":true,"M":true}}
{"type":"trade","received_at_ms":1788331836508,"data":{"e":"trade","E":1788331836580,"s":"BTCUSDT","t":6646633600,"p":"77589.99000000","q":"0.00007000","T":1788331836579,"m":true,"M":true}}
{"type":"trade","received_at_ms":1788331836508,"data":{"e":"trade","E":1788331836580,"s":"BTCUSDT","t":6646633601,"p":"77589.99000000","q":"0.00007000","T":1788331836579,"m":true,"M":true}}
{"type":"trade","received_at_ms":1788331836508,"data":{"e":"trade","E":1788331836580,"s":"BTCUSDT","t":6646633602,"p":"77589.76000000","q":"0.00007000","T":1788331836579,"m":true,"M":true}}
{"type":"trade","received_at_ms":1788331836508,"data":{"e":"trade","E":1788331836580,"s":"BTCUSDT","t":6646633603,"p":"77589.76000000","q":"0.00007000","T":1788331836579,"m":true,"M":true}}
{"type":"trade","received_at_ms":1788331836508,"data":{"e":"trade","E":1788331836580,"s":"BTCUSDT","t":6646633604,"p":"77589.07000000","q":"0.00007000","T":1788331836579,"m":true,"M":true}}
{"type":"trade","received_at_ms":1788331836508,"data":{"e":"trade","E":1788331836580,"s":"BTCUSDT","t":6646633605,"p":"77589.07000000","q":"0.00007000","T":1788331836579,"m":true,"M":true}}
{"type":"trade","received_at_ms":1788331836508,"data":{"e":"trade","E":1788331836580,"s":"BTCUSDT","t":6646633606,"p":"77589.07000000","q":"0.00007000","T":1788331836579,"m":true,"M":true}}
{"type":"trade","received_at_ms":1788331836508,"data":{"e":"trade","E":1788331836580,"s":"BTCUSDT","t":6646633607,"p":"77589.07000000","q":"0.00007000","T":1788331836579,"m":true,"M":true}}
{"type":"trade","received_at_ms":1788331836508,"data":{"e":"trade","E":1788331836580,"s":"BTCUSDT","t":6646633608,"p":"77588.55000000","q":"0.00007000","T":1788331836579,"m":true,"M":true}}
{"type":"trade","received_at_ms":1788331836508,"data":{"e":"trade","E":1788331836580,"s":"BTCUSDT","t":6646633609,"p":"77588.55000000","q":"0.00007000","T":1788331836579,"m":true,"M":true}}
{"type":"trade","received_at_ms":1788331836508,"data":{"e":"trade","E":1788331836580,"s":"BTCUSDT","t":6646633610,"p":"77588.55000000","q":"0.00007000","T":1788331836579,"m":true,"M":true}}
{"type":"trade","received_at_ms":1788331836508,"data":{"e":"trade","E":1788331836580,"s":"BTCUSDT","t":6646633611,"p":"77588.33000000","q":"0.00007000","T":1788331836579,"m":true,"M":true}}
{"type":"trade","received_at_ms":1788331836508,"data":{"e":"trade","E":1788331836580,"s":"BTCUSDT","t":6646633612,"p":"77588.33000000","q":"0.00007000","T":1788331836579,"m":true,"M":true}}
{"type":"trade","received_at_ms":1788331836508,"data":{"e":"trade","E":1788331836580,"s":"BTCUSDT","t":6646633613,"p":"77588.33000000","q":"0.00007000","T":1788331836579,"m":true,"M":true}}
{"type":"trade","received_at_ms":1788331836508,"data":{"e":"trade","E":1788331836580,"s":"BTCUSDT","t":6646633614,"p":"77588.32000000","q":"0.00007000","T":1788331836579,"m":true,"M":true}}
{"type":"trade","received_at_ms":1788331836508,"data":{"e":"trade","E":1788331836580,"s":"BTCUSDT","t":6646633615,"p":"77588.32000000","q":"0.00007000","T":1788331836579,"m":true,"M":true}}
{"type":"trade","received_at_ms":1788331836508,"data":{"e":"trade","E":1788331836580,"s":"BTCUSDT","t":6646633616,"p":"77588.32000000","q":"0.00007000","T":1788331836579,"m":true,"M":true}}
{"type":"trade","received_at_ms":1788331836508,"data":{"e":"trade","E":1788331836580,"s":"BTCUSDT","t":6646633617,"p":"77588.32000000","q":"0.00007000","T":1788331836579,"m":true,"M":true}}
{"type":"trade","received_at_ms":1788331836508,"data":{"e":"trade","E":1788331836580,"s":"BTCUSDT","t":6646633618,"p":"77588.32000000","q":"0.00007000","T":1788331836579,"m":true,"M":true}}
{"type":"trade","received_at_ms":1788331836508,"data":{"e":"trade","E":1788331836580,"s":"BTCUSDT","t":6646633619,"p":"77588.32000000","q":"0.00007000","T":1788331836579,"m":true,"M":true}}
{"type":"trade","received_at_ms":1788331836508,"data":{"e":"trade","E":1788331836580,"s":"BTCUSDT","t":6646633620,"p":"77588.32000000","q":"0.00007000","T":1788331836579,"m":true,"M":true}}
{"type":"trade","received_at_ms":1788331836508,"data":{"e":"trade","E":1788331836580,"s":"BTCUSDT","t":6646633621,"p":"77588.31000000","q":"0.01930000","T":1788331836579,"m":true,"M":true}}
{"type":"trade","received_at_ms":1788331836508,"data":{"e":"trade","E":1788331836580,"s":"BTCUSDT","t":6646633622,"p":"77588.31000000","q":"0.01936000","T":1788331836579,"m":true,"M":true}}
{"type":"trade","received_at_ms":1788331836508,"data":{"e":"trade","E":1788331836580,"s":"BTCUSDT","t":6646633623,"p":"77588.31000000","q":"0.00007000","T":1788331836579,"m":true,"M":true}}
{"type":"trade","received_at_ms":1788331836508,"data":{"e":"trade","E":1788331836580,"s":"BTCUSDT","t":6646633624,"p":"77588.31000000","q":"0.00007000","T":1788331836579,"m":true,"M":true}}
{"type":"trade","received_at_ms":1788331836508,"data":{"e":"trade","E":1788331836580,"s":"BTCUSDT","t":6646633625,"p":"77588.31000000","q":"0.00007000","T":1788331836579,"m":true,"M":true}}
{"type":"trade","received_at_ms":1788331836508,"data":{"e":"trade","E":1788331836580,"s":"BTCUSDT","t":6646633626,"p":"77588.31000000","q":"0.00007000","T":1788331836579,"m":true,"M":true}}
{"type":"trade","received_at_ms":1788331836508,"data":{"e":"trade","E":1788331836580,"s":"BTCUSDT","t":6646633627,"p":"77588.01000000","q":"0.00007000","T":1788331836579,"m":true,"M":true}}
{"type":"trade","received_at_ms":1788331836508,"data":{"e":"trade","E":1788331836580,"s":"BTCUSDT","t":6646633628,"p":"77588.01000000","q":"0.00007000","T":1788331836579,"m":true,"M":true}}
{"type":"trade","received_at_ms":1788331836508,"data":{"e":"trade","E":1788331836580,"s":"BTCUSDT","t":6646633629,"p":"77588.01000000","q":"0.00007000","T":1788331836579,"m":true,"M":true}}
{"type":"trade","received_at_ms":1788331836508,"data":{"e":"trade","E":1788331836580,"s":"BTCUSDT","t":6646633630,"p":"77588.00000000","q":"0.00500000","T":1788331836579,"m":true,"M":true}}
{"type":"trade","received_at_ms":1788331836508,"data":{"e":"trade","E":1788331836580,"s":"BTCUSDT","t":6646633631,"p":"77588.00000000","q":"0.00500000","T":1788331836579,"m":true,"M":true}}
{"type":"trade","received_at_ms":1788331836508,"data":{"e":"trade","E":1788331836580,"s":"BTCUSDT","t":6646633632,"p":"77588.00000000","q":"0.01000000","T":1788331836579,"m":true,"M":true}}
{"type":"trade","received_at_ms":1788331836508,"data":{"e":"trade","E":1788331836580,"s":"BTCUSDT","t":6646633633,"p":"77588.00000000","q":"0.00321000","T":1788331836579,"m":true,"M":true}}
{"type":"trade","received_at_ms":1788331836508,"data":{"e":"trade","E":1788331836580,"s":"BTCUSDT","t":6646633634,"p":"77588.00000000","q":"0.00679000","T":1788331836579,"m":true,"M":true}}
{"type":"trade","received_at_ms":1788331836508,"data":{"e":"trade","E":1788331836580,"s":"BTCUSDT","t":6646633635,"p":"77588.00000000","q":"0.00007000","T":1788331836579,"m":true,"M":true}}
{"type":"trade","received_at_ms":1788331836508,"data":{"e":"trade","E":1788331836580,"s":"BTCUSDT","t":6646633636,"p":"77588.00000000","q":"0.00007000","T":1788331836579,"m":true,"M":true}}
{"type":"trade","received_at_ms":1788331836508,"data":{"e":"trade","E":1788331836580,"s":"BTCUSDT","t":6646633637,"p":"77588.00000000","q":"0.00007000","T":1788331836579,"m":true,"M":true}}
{"type":"trade","received_at_ms":1788331836508,"data":{"e":"trade","E":1788331836580,"s":"BTCUSDT","t":6646633638,"p":"77588.00000000","q":"0.00007000","T":1788331836579,"m":true,"M":true}}
{"type":"trade","received_at_ms":1788331836508,"data":{"e":"trade","E":1788331836580,"s":"BTCUSDT","t":6646633639,"p":"77588.00000000","q":"0.00007000","T":1788331836579,"m":true,"M":true}}
{"type":"trade","received_at_ms":1788331836508,"data":{"e":"trade","E":1788331836580,"s":"BTCUSDT","t":6646633640,"p":"77588.00000000","q":"0.00007000","T":1788331836579,"m":true,"M":true}}
{"type":"trade","received_at_ms":1788331836508,"data":{"e":"trade","E":1788331836580,"s":"BTCUSDT","t":6646633641,"p":"77588.00000000","q":"0.00007000","T":1788331836579,"m":true,"M":true}}
{"type":"trade","received_at_ms":1788331836508,"data":{"e":"trade","E":1788331836580,"s":"BTCUSDT","t":6646633642,"p":"77588.00000000","q":"0.00007000","T":1788331836579,"m":true,"M":true}}
{"type":"trade","received_at_ms":1788331836508,"data":{"e":"trade","E":1788331836580,"s":"BTCUSDT","t":6646633643,"p":"77588.00000000","q":"0.00007000","T":1788331836579,"m":true,"M":true}}
{"type":"trade","received_at_ms":1788331836508,"data":{"e":"trade","E":1788331836580,"s":"BTCUSDT","t":6646633644,"p":"77588.00000000","q":"0.00007000","T":1788331836579,"m":true,"M":true}}
{"type":"trade","received_at_ms":1788331836508,"data":{"e":"trade","E":1788331836580,"s":"BTCUSDT","t":6646633645,"p":"77587.78000000","q":"0.00007000","T":1788331836579,"m":true,"M":true}}
{"type":"trade","received_at_ms":1788331836508,"data":{"e":"trade","E":1788331836580,"s":"BTCUSDT","t":6646633646,"p":"77587.78000000","q":"0.00007000","T":1788331836579,"m":true,"M":true}}
{"type":"trade","received_at_ms":1788331836508,"data":{"e":"trade","E":1788331836581,"s":"BTCUSDT","t":6646633647,"p":"77587.30000000","q":"0.00007000","T":1788331836580,"m":true,"M":true}}
{"type":"trade","received_at_ms":1788331836508,"data":{"e":"trade","E":1788331836581,"s":"BTCUSDT","t":6646633648,"p":"77587.30000000","q":"0.00007000","T":1788331836580,"m":true,"M":true}}
{"type":"trade","received_at_ms":1788331836508,"data":{"e":"trade","E":1788331836581,"s":"BTCUSDT","t":6646633649,"p":"77587.12000000","q":"0.00008000","T":1788331836580,"m":true,"M":true}}
{"type":"trade","received_at_ms":1788331836508,"data":{"e":"trade","E":1788331836581,"s":"BTCUSDT","t":6646633650,"p":"77587.09000000","q":"0.00007000","T":1788331836580,"m":true,"M":true}}
{"type":"trade","received_at_ms":1788331836508,"data":{"e":"trade","E":1788331836581,"s":"BTCUSDT","t":6646633651,"p":"77587.09000000","q":"0.00007000","T":1788331836580,"m":true,"M":true}}
{"type":"trade","received_at_ms":1788331836508,"data":{"e":"trade","E":1788331836581,"s":"BTCUSDT","t":6646633652,"p":"77587.09000000","q":"0.00007000","T":1788331836580,"m":true,"M":true}}
{"type":"trade","received_at_ms":1788331836508,"data":{"e":"trade","E":1788331836582,"s":"BTCUSDT","t":6646633653,"p":"77586.96000000","q":"0.00007000","T":1788331836581,"m":true,"M":true}}
{"type":"trade","received_at_ms":1788331836508,"data":{"e":"trade","E":1788331836582,"s":"BTCUSDT","t":6646633654,"p":"77586.96000000","q":"0.00007000","T":1788331836581,"m":true,"M":true}}
{"type":"trade","received_at_ms":1788331836508,"data":{"e":"trade","E":1788331836582,"s":"BTCUSDT","t":6646633655,"p":"77586.48000000","q":"0.00007000","T":1788331836581,"m":true,"M":true}}
{"type":"trade","received_at_ms":1788331836508,"data":{"e":"trade","E":1788331836582,"s":"BTCUSDT","t":6646633656,"p":"77586.34000000","q":"0.00010000","T":1788331836581,"m":true,"M":true}}
{"type":"trade","received_at_ms":1788331836508,"data":{"e":"trade","E":1788331836582,"s":"BTCUSDT","t":6646633657,"p":"77586.32000000","q":"0.01297000","T":1788331836581,"m":true,"M":true}}
{"type":"trade","received_at_ms":1788331836508,"data":{"e":"trade","E":1788331836584,"s":"BTCUSDT","t":6646633658,"p":"77586.19000000","q":"0.00322000","T":1788331836582,"m":true,"M":true}}
{"type":"trade","received_at_ms":1788331836508,"data":{"e":"trade","E":1788331836584,"s":"BTCUSDT","t":6646633659,"p":"77586.02000000","q":"0.00007000","T":1788331836582,"m":true,"M":true}}
{"type":"trade","received_at_ms":1788331836508,"data":{"e":"trade","E":1788331836584,"s":"BTCUSDT","t":6646633660,"p":"77586.02000000","q":"0.00007000","T":1788331836582,"m":true,"M":true}}
{"type":"trade","received_at_ms":1788331836508,"data":{"e":"trade","E":1788331836584,"s":"BTCUSDT","t":6646633661,"p":"77586.01000000","q":"0.00007000","T":1788331836582,"m":true,"M":true}}
{"type":"trade","received_at_ms":1788331836508,"data":{"e":"trade","E":1788331836584,"s":"BTCUSDT","t":6646633662,"p":"77586.01000000","q":"0.00007000","T":1788331836582,"m":true,"M":true}}
{"type":"trade","received_at_ms":1788331836508,"data":{"e":"trade","E":1788331836584,"s":"BTCUSDT","t":6646633663,"p":"77586.01000000","q":"0.00007000","T":1788331836582,"m":true,"M":true}}
{"type":"trade","received_at_ms":1788331836508,"data":{"e":"trade","E":1788331836584,"s":"BTCUSDT","t":6646633664,"p":"77586.00000000","q":"0.00500000","T":1788331836582,"m":true,"M":true}}
{"type":"trade","received_at_ms":1788331836508,"data":{"e":"trade","E":1788331836584,"s":"BTCUSDT","t":6646633665,"p":"77586.00000000","q":"0.00500000","T":1788331836582,"m":true,"M":true}}
{"type":"trade","received_at_ms":1788331836508,"data":{"e":"trade","E":1788331836584,"s":"BTCUSDT","t":6646633666,"p":"77586.00000000","q":"0.01000000","T":1788331836582,"m":true,"M":true}}
{"type":"trade","received_at_ms":1788331836508,"data":{"e":"trade","E":1788331836584,"s":"BTCUSDT","t":6646633667,"p":"77586.00000000","q":"0.01000000","T":1788331836582,"m":true,"M":true}}
{"type":"trade","received_at_ms":1788331836508,"data":{"e":"trade","E":1788331836584,"s":"BTCUSDT","t":6646633668,"p":"77586.00000000","q":"0.00007000","T":1788331836582,"m":true,"M":true}}
{"type":"trade","received_at_ms":1788331836508,"data":{"e":"trade","E":1788331836584,"s":"BTCUSDT","t":6646633669,"p":"77586.00000000","q":"0.00007000","T":1788331836582,"m":true,"M":true}}
{"type":"trade","received_at_ms":1788331836508,"data":{"e":"trade","E":1788331836584,"s":"BTCUSDT","t":6646633670,"p":"77586.00000000","q":"0.00007000","T":1788331836582,"m":true,"M":true}}
{"type":"trade","received_at_ms":1788331836508,"data":{"e":"trade","E":1788331836584,"s":"BTCUSDT","t":6646633671,"p":"77586.00000000","q":"0.00007000","T":1788331836582,"m":true,"M":true}}
{"type":"trade","received_at_ms":1788331836508,"data":{"e":"trade","E":1788331836584,"s":"BTCUSDT","t":6646633672,"p":"77586.00000000","q":"0.00007000","T":1788331836582,"m":true,"M":true}}
{"type":"trade","received_at_ms":1788331836508,"data":{"e":"trade","E":1788331836584,"s":"BTCUSDT","t":6646633673,"p":"77586.00000000","q":"0.00007000","T":1788331836582,"m":true,"M":true}}
{"type":"trade","received_at_ms":1788331836508,"data":{"e":"trade","E":1788331836584,"s":"BTCUSDT","t":6646633674,"p":"77585.63000000","q":"0.00007000","T":1788331836582,"m":true,"M":true}}
{"type":"trade","received_at_ms":1788331836508,"data":{"e":"trade","E":1788331836584,"s":"BTCUSDT","t":6646633675,"p":"77585.63000000","q":"0.00007000","T":1788331836582,"m":true,"M":true}}
{"type":"trade","received_at_ms":1788331836508,"data":{"e":"trade","E":1788331836584,"s":"BTCUSDT","t":6646633676,"p":"77585.63000000","q":"0.00007000","T":1788331836582,"m":true,"M":true}}
{"type":"trade","received_at_ms":1788331836508,"data":{"e":"trade","E":1788331836584,"s":"BTCUSDT","t":6646633677,"p":"77585.62000000","q":"0.00007000","T":1788331836582,"m":true,"M":true}}
{"type":"trade","received_at_ms":1788331836508,"data":{"e":"trade","E":1788331836584,"s":"BTCUSDT","t":6646633678,"p":"77585.62000000","q":"0.00007000","T":1788331836582,"m":true,"M":true}}
{"type":"trade","received_at_ms":1788331836508,"data":{"e":"trade","E":1788331836584,"s":"BTCUSDT","t":6646633679,"p":"77585.05000000","q":"0.00007000","T":1788331836582,"m":true,"M":true}}
{"type":"trade","received_at_ms":1788331836508,"data":{"e":"trade","E":1788331836584,"s":"BTCUSDT","t":6646633680,"p":"77585.05000000","q":"0.00007000","T":1788331836582,"m":true,"M":true}}
{"type":"trade","received_at_ms":1788331836508,"data":{"e":"trade","E":1788331836584,"s":"BTCUSDT","t":6646633681,"p":"77585.05000000","q":"0.00007000","T":1788331836582,"m":true,"M":true}}
{"type":"trade","received_at_ms":1788331836508,"data":{"e":"trade","E":1788331836584,"s":"BTCUSDT","t":6646633682,"p":"77584.75000000","q":"0.00007000","T":1788331836582,"m":true,"M":true}}
{"type":"trade","received_at_ms":1788331836509,"data":{"e":"trade","E":1788331836584,"s":"BTCUSDT","t":6646633683,"p":"77584.75000000","q":"0.00007000","T":1788331836582,"m":true,"M":true}}
{"type":"trade","received_at_ms":1788331836509,"data":{"e":"trade","E":1788331836584,"s":"BTCUSDT","t":6646633684,"p":"77584.74000000","q":"0.00007000","T":1788331836582,"m":true,"M":true}}
{"type":"trade","received_at_ms":1788331836509,"data":{"e":"trade","E":1788331836584,"s":"BTCUSDT","t":6646633685,"p":"77584.74000000","q":"0.00007000","T":1788331836582,"m":true,"M":true}}
{"type":"trade","received_at_ms":1788331836509,"data":{"e":"trade","E":1788331836584,"s":"BTCUSDT","t":6646633686,"p":"77584.74000000","q":"0.00007000","T":1788331836582,"m":true,"M":true}}
{"type":"trade","received_at_ms":1788331836509,"data":{"e":"trade","E":1788331836584,"s":"BTCUSDT","t":6646633687,"p":"77584.74000000","q":"0.00007000","T":1788331836582,"m":true,"M":true}}
{"type":"trade","received_at_ms":1788331836509,"data":{"e":"trade","E":1788331836584,"s":"BTCUSDT","t":6646633688,"p":"77584.74000000","q":"0.00007000","T":1788331836582,"m":true,"M":true}}
{"type":"trade","received_at_ms":1788331836509,"data":{"e":"trade","E":1788331836584,"s":"BTCUSDT","t":6646633689,"p":"77584.74000000","q":"0.00007000","T":1788331836582,"m":true,"M":true}}
{"type":"trade","received_at_ms":1788331836509,"data":{"e":"trade","E":1788331836584,"s":"BTCUSDT","t":6646633690,"p":"77584.21000000","q":"0.00007000","T":1788331836582,"m":true,"M":true}}
{"type":"trade","received_at_ms":1788331836509,"data":{"e":"trade","E":1788331836584,"s":"BTCUSDT","t":6646633691,"p":"77584.21000000","q":"0.00007000","T":1788331836582,"m":true,"M":true}}
{"type":"trade","received_at_ms":1788331836509,"data":{"e":"trade","E":1788331836584,"s":"BTCUSDT","t":6646633692,"p":"77584.21000000","q":"0.00007000","T":1788331836582,"m":true,"M":true}}
{"type":"trade","received_at_ms":1788331836509,"data":{"e":"trade","E":1788331836584,"s":"BTCUSDT","t":6646633693,"p":"77584.21000000","q":"0.00007000","T":1788331836582,"m":true,"M":true}}
{"type":"trade","received_at_ms":1788331836509,"data":{"e":"trade","E":1788331836584,"s":"BTCUSDT","t":6646633694,"p":"77584.19000000","q":"0.00013000","T":1788331836582,"m":true,"M":true}}
{"type":"trade","received_at_ms":1788331836509,"data":{"e":"trade","E":1788331836584,"s":"BTCUSDT","t":6646633695,"p":"77584.00000000","q":"0.00007000","T":1788331836582,"m":true,"M":true}}
{"type":"trade","received_at_ms":1788331836509,"data":{"e":"trade","E":1788331836584,"s":"BTCUSDT","t":6646633696,"p":"77584.00000000","q":"0.01000000","T":1788331836582,"m":true,"M":true}}
{"type":"trade","received_at_ms":1788331836509,"data":{"e":"trade","E":1788331836584,"s":"BTCUSDT","t":6646633697,"p":"77584.00000000","q":"0.00500000","T":1788331836582,"m":true,"M":true}}
{"type":"trade","received_at_ms":1788331836509,"data":{"e":"trade","E":1788331836584,"s":"BTCUSDT","t":6646633698,"p":"77584.00000000","q":"0.00500000","T":1788331836582,"m":true,"M":true}}
{"type":"trade","received_at_ms":1788331836509,"data":{"e":"trade","E":1788331836584,"s":"BTCUSDT","t":6646633699,"p":"77584.00000000","q":"0.01000000","T":1788331836582,"m":true,"M":true}}
{"type":"trade","received_at_ms":1788331836509,"data":{"e":"trade","E":1788331836584,"s":"BTCUSDT","t":6646633700,"p":"77584.00000000","q":"0.00007000","T":1788331836582,"m":true,"M":true}}
{"type":"trade","received_at_ms":1788331836509,"data":{"e":"trade","E":1788331836584,"s":"BTCUSDT","t":6646633701,"p":"77584.00000000","q":"0.00007000","T":1788331836582,"m":true,"M":true}}
{"type":"trade","received_at_ms":1788331836509,"data":{"e":"trade","E":1788331836584,"s":"BTCUSDT","t":6646633702,"p":"77584.00000000","q":"0.00007000","T":1788331836582,"m":true,"M":true}}
{"type":"trade","received_at_ms":1788331836509,"data":{"e":"trade","E":1788331836584,"s":"BTCUSDT","t":6646633703,"p":"77584.00000000","q":"0.00007000","T":1788331836582,"m":true,"M":true}}
{"type":"trade","received_at_ms":1788331836509,"data":{"e":"trade","E":1788331836584,"s":"BTCUSDT","t":6646633704,"p":"77583.90000000","q":"0.00007000","T":1788331836582,"m":true,"M":true}}
{"type":"trade","received_at_ms":1788331836509,"data":{"e":"trade","E":1788331836584,"s":"BTCUSDT","t":6646633705,"p":"77583.90000000","q":"0.00007000","T":1788331836582,"m":true,"M":true}}
{"type":"trade","received_at_ms":1788331836509,"data":{"e":"trade","E":1788331836584,"s":"BTCUSDT","t":6646633706,"p":"77583.80000000","q":"0.00007000","T":1788331836582,"m":true,"M":true}}
{"type":"trade","received_at_ms":1788331836509,"data":{"e":"trade","E":1788331836584,"s":"BTCUSDT","t":6646633707,"p":"77583.80000000","q":"0.00007000","T":1788331836582,"m":true,"M":true}}
{"type":"trade","received_at_ms":1788331836509,"data":{"e":"trade","E":1788331836584,"s":"BTCUSDT","t":6646633708,"p":"77583.50000000","q":"0.00007000","T":1788331836582,"m":true,"M":true}}
{"type":"trade","received_at_ms":1788331836509,"data":{"e":"trade","E":1788331836584,"s":"BTCUSDT","t":6646633709,"p":"77583.35000000","q":"0.00007000","T":1788331836582,"m":true,"M":true}}
{"type":"trade","received_at_ms":1788331836509,"data":{"e":"trade","E":1788331836584,"s":"BTCUSDT","t":6646633710,"p":"77582.71000000","q":"0.00007000","T":1788331836582,"m":true,"M":true}}
{"type":"trade","received_at_ms":1788331836509,"data":{"e":"trade","E":1788331836584,"s":"BTCUSDT","t":6646633711,"p":"77582.71000000","q":"0.00007000","T":1788331836582,"m":true,"M":true}}
{"type":"trade","received_at_ms":1788331836509,"data":{"e":"trade","E":1788331836584,"s":"BTCUSDT","t":6646633712,"p":"77582.64000000","q":"0.00007000","T":1788331836582,"m":true,"M":true}}
{"type":"trade","received_at_ms":1788331836509,"data":{"e":"trade","E":1788331836584,"s":"BTCUSDT","t":6646633713,"p":"77582.54000000","q":"0.00007000","T":1788331836582,"m":true,"M":true}}
{"type":"trade","received_at_ms":1788331836509,"data":{"e":"trade","E":1788331836584,"s":"BTCUSDT","t":6646633714,"p":"77582.26000000","q":"0.00008000","T":1788331836582,"m":true,"M":true}}
{"type":"trade","received_at_ms":1788331836509,"data":{"e":"trade","E":1788331836584,"s":"BTCUSDT","t":6646633715,"p":"77582.24000000","q":"0.00008000","T":1788331836582,"m":true,"M":true}}
{"type":"trade","received_at_ms":1788331836509,"data":{"e":"trade","E":1788331836584,"s":"BTCUSDT","t":6646633716,"p":"77582.24000000","q":"0.00008000","T":1788331836582,"m":true,"M":true}}
{"type":"trade","received_at_ms":1788331836509,"data":{"e":"trade","E":1788331836584,"s":"BTCUSDT","t":6646633717,"p":"77582.24000000","q":"0.00007000","T":1788331836582,"m":true,"M":true}}
{"type":"trade","received_at_ms":1788331836509,"data":{"e":"trade","E":1788331836584,"s":"BTCUSDT","t":6646633718,"p":"77582.24000000","q":"0.00007000","T":1788331836582,"m":true,"M":true}}
{"type":"trade","received_at_ms":1788331836509,"data":{"e":"trade","E":1788331836584,"s":"BTCUSDT","t":6646633719,"p":"77582.00000000","q":"0.01000000","T":1788331836582,"m":true,"M":true}}
{"type":"trade","received_at_ms":1788331836509,"data":{"e":"trade","E":1788331836584,"s":"BTCUSDT","t":6646633720,"p":"77582.00000000","q":"0.00500000","T":1788331836582,"m":true,"M":true}}
{"type":"trade","received_at_ms":1788331836509,"data":{"e":"trade","E":1788331836584,"s":"BTCUSDT","t":6646633721,"p":"77582.00000000","q":"0.00500000","T":1788331836582,"m":true,"M":true}}
{"type":"trade","received_at_ms":1788331836509,"data":{"e":"trade","E":1788331836584,"s":"BTCUSDT","t":6646633722,"p":"77582.00000000","q":"0.01000000","T":1788331836582,"m":true,"M":true}}
{"type":"trade","received_at_ms":1788331836509,"data":{"e":"trade","E":1788331836584,"s":"BTCUSDT","t":6646633723,"p":"77582.00000000","q":"0.00007000","T":1788331836582,"m":true,"M":true}}
{"type":"trade","received_at_ms":1788331836509,"data":{"e":"trade","E":1788331836584,"s":"BTCUSDT","t":6646633724,"p":"77582.00000000","q":"0.00007000","T":1788331836582,"m":true,"M":true}}
{"type":"trade","received_at_ms":1788331836509,"data":{"e":"trade","E":1788331836584,"s":"BTCUSDT","t":6646633725,"p":"77581.96000000","q":"0.00007000","T":1788331836582,"m":true,"M":true}}
{"type":"trade","received_at_ms":1788331836509,"data":{"e":"trade","E":1788331836584,"s":"BTCUSDT","t":6646633726,"p":"77581.93000000","q":"0.02900000","T":1788331836582,"m":true,"M":true}}
{"type":"trade","received_at_ms":1788331836509,"data":{"e":"trade","E":1788331836584,"s":"BTCUSDT","t":6646633727,"p":"77581.93000000","q":"0.00007000","T":1788331836582,"m":true,"M":true}}
{"type":"trade","received_at_ms":1788331836509,"data":{"e":"trade","E":1788331836584,"s":"BTCUSDT","t":6646633728,"p":"77581.93000000","q":"0.00007000","T":1788331836582,"m":true,"M":true}}
{"type":"trade","received_at_ms":1788331836509,"data":{"e":"trade","E":1788331836584,"s":"BTCUSDT","t":6646633729,"p":"77581.80000000","q":"0.00104000","T":1788331836582,"m":true,"M":true}}
{"type":"trade","received_at_ms":1788331836509,"data":{"e":"trade","E":1788331836584,"s":"BTCUSDT","t":6646633730,"p":"77581.75000000","q":"0.00056000","T":1788331836582,"m":true,"M":true}}
{"type":"trade","received_at_ms":1788331836509,"data":{"e":"trade","E":1788331836584,"s":"BTCUSDT","t":6646633731,"p":"77581.23000000","q":"0.00096000","T":1788331836582,"m":true,"M":true}}
{"type":"trade","received_at_ms":1788331836509,"data":{"e":"trade","E":1788331836592,"s":"BTCUSDT","t":6646633732,"p":"77581.23000000","q":"0.01904000","T":1788331836588,"m":true,"M":true}}
{"type":"trade","received_at_ms":1788331836509,"data":{"e":"trade","E":1788331836592,"s":"BTCUSDT","t":6646633733,"p":"77581.23000000","q":"0.00007000","T":1788331836588,"m":true,"M":true}}
{"type":"trade","received_at_ms":1788331836509,"data":{"e":"trade","E":1788331836592,"s":"BTCUSDT","t":6646633734,"p":"77581.23000000","q":"0.00007000","T":1788331836588,"m":true,"M":true}}
{"type":"trade","received_at_ms":1788331836509,"data":{"e":"trade","E":1788331836592,"s":"BTCUSDT","t":6646633735,"p":"77581.23000000","q":"0.00007000","T":1788331836588,"m":true,"M":true}}
{"type":"trade","received_at_ms":1788331836509,"data":{"e":"trade","E":1788331836592,"s":"BTCUSDT","t":6646633736,"p":"77581.23000000","q":"0.00007000","T":1788331836588,"m":true,"M":true}}
{"type":"trade","received_at_ms":1788331836509,"data":{"e":"trade","E":1788331836592,"s":"BTCUSDT","t":6646633737,"p":"77581.23000000","q":"0.00007000","T":1788331836588,"m":true,"M":true}}
{"type":"trade","received_at_ms":1788331836509,"data":{"e":"trade","E":1788331836592,"s":"BTCUSDT","t":6646633738,"p":"77581.23000000","q":"0.00007000","T":1788331836588,"m":true,"M":true}}
{"type":"trade","received_at_ms":1788331836509,"data":{"e":"trade","E":1788331836592,"s":"BTCUSDT","t":6646633739,"p":"77581.23000000","q":"0.00007000","T":1788331836588,"m":true,"M":true}}
{"type":"trade","received_at_ms":1788331836509,"data":{"e":"trade","E":1788331836592,"s":"BTCUSDT","t":6646633740,"p":"77581.14000000","q":"0.00047000","T":1788331836588,"m":true,"M":true}}
{"type":"trade","received_at_ms":1788331836509,"data":{"e":"trade","E":1788331836598,"s":"BTCUSDT","t":6646633741,"p":"77581.14000000","q":"0.00008000","T":1788331836594,"m":true,"M":true}}
{"type":"depth","received_at_ms":1788331836509,"data":{"e":"depthUpdate","E":1788331836614,"s":"BTCUSDT","U":99555811014,"u":99555812721,"b":[["77590.00000000","0.00000000"],["77589.99000000","0.00000000"],["77589.76000000","0.00000000"],["77589.08000000","0.00000000"],["77589.07000000","0.00000000"],["77588.55000000","0.00000000"],["77588.54000000","0.00000000"],["77588.33000000","0.00000000"],["77588.32000000","0.00000000"],["77588.31000000","0.00000000"],["77588.01000000","0.00000000"],["77588.00000000","0.00000000"],["77587.78000000","0.00000000"],["77587.50000000","0.00000000"],["77587.31000000","0.00000000"],["77587.30000000","0.00000000"],["77587.12000000","0.00000000"],["77587.09000000","0.00000000"],["77587.08000000","0.00000000"],["77586.96000000","0.00000000"],["77586.48000000","0.00000000"],["77586.34000000","0.00000000"],["77586.33000000","0.00000000"],["77586.32000000","0.00000000"],["77586.19000000","0.00000000"],["77586.02000000","0.00000000"],["77586.01000000","0.00000000"],["77586.00000000","0.00000000"],["77585.80000000","0.00000000"],["77585.63000000","0.00000000"],["77585.62000000","0.00000000"],["77585.05000000","0.00000000"],["77585.04000000","0.00000000"],["77584.75000000","0.00000000"],["77584.74000000","0.00000000"],["77584.65000000","0.00000000"],["77584.48000000","0.00000000"],["77584.21000000","0.00000000"],["77584.20000000","0.00000000"],["77584.19000000","0.00000000"],["77584.00000000","0.00000000"],["77583.90000000","0.00000000"],["77583.80000000","0.00000000"],["77583.50000000","0.00000000"],["77583.35000000","0.00000000"],["77582.99000000","0.00000000"],["77582.92000000","0.00000000"],["77582.71000000","0.00000000"],["77582.70000000","0.00000000"],["77582.64000000","0.00000000"],["77582.54000000","0.00000000"],["77582.26000000","0.00000000"],["77582.25000000","0.00000000"],["77582.24000000","0.00000000"],["77582.04000000","0.00000000"],["77582.00000000","0.00000000"],["77581.96000000","0.00000000"],["77581.93000000","0.00000000"],["77581.84000000","0.00000000"],["77581.80000000","0.00000000"],["77581.75000000","0.00000000"],["77581.29000000","0.00000000"],["77581.26000000","0.00000000"],["77581.23000000","0.00000000"],["77581.14000000","0.16179000"],["77581.13000000","0.00249000"],["77580.75000000","0.00000000"],["77580.60000000","0.00000000"],["77580.56000000","0.00000000"],["77580.09000000","0.00000000"],["77580.03000000","0.00000000"],["77580.02000000","0.00000000"],["77580.01000000","0.00021000"],["77580.00000000","0.03007000"],["77579.90000000","0.00000000"],["77579.86000000","0.00007000"],["77579.66000000","0.00007000"],["77579.56000000","0.00000000"],["77579.54000000","0.00000000"],["77579.20000000","0.00000000"],["77579.16000000","0.04513000"],["77579.15000000","0.02007000"],["77579.00000000","0.00012000"],["77578.92000000","0.00000000"],["77578.85000000","0.00000000"],["77578.84000000","0.00000000"],["77578.80000000","0.00000000"],["77578.60000000","0.00007000"],["77578.39000000","0.00014000"],["77578.38000000","0.02007000"],["77578.37000000","0.00000000"],["77578.36000000","0.00007000"],["77578.07000000","0.00014000"],["77578.06000000","0.00007000"],["77578.01000000","0.00014000"],["77578.00000000","0.03007000"],["77577.85000000","0.00000000"],["77577.78000000","0.00000000"],["77577.76000000","0.00000000"],["77577.41000000","0.00007000"],["77577.40000000","0.00000000"],["77577.36000000","0.00015000"],["77577.35000000","0.00000000"],["77577.16000000","0.00000000"],["77576.88000000","0.00000000"],["77576.71000000","0.00000000"],["77576.61000000","0.00000000"],["77576.54000000","0.30885000"],["77576.04000000","0.02007000"],["77576.00000000","0.03014000"],["77575.80000000","0.00322000"],["77575.58000000","0.00000000"],["77575.49000000","0.00000000"],["77575.28000000","0.00000000"],["77575.04000000","0.00000000"],["77574.66000000","0.00007000"],["77574.52000000","0.00000000"],["77574.51000000","0.00000000"],["77574.48000000","0.00000000"],["77574.46000000","0.00000000"],["77574.12000000","0.00000000"],["77573.78000000","0.00000000"],["77573.66000000","0.01000000"],["77573.47000000","0.00008000"],["77573.43000000","0.00000000"],["77573.34000000","0.00007000"],["77572.98000000","0.00000000"],["77572.97000000","0.00000000"],["77572.96000000","0.00000000"],["77572.88000000","0.00000000"],["77572.87000000","0.00000000"],["77572.86000000","0.00000000"],["77572.64000000","0.00000000"],["77572.38000000","0.00000000"],["77572.07000000","0.00000000"],["77572.01000000","0.03454000"],["77571.40000000","0.02900000"],["77571.17000000","0.00000000"],["77570.72000000","0.00007000"],["77570.24000000","0.00007000"],["77570.03000000","0.00145000"],["77569.79000000","0.00000000"],["77569.78000000","0.00000000"],["77569.41000000","0.00128000"],["77569.06000000","0.14000000"],["77568.98000000","0.00000000"],["77568.97000000","0.00159000"],["77568.04000000","0.12891000"],["77567.29000000","0.00000000"],["77567.26000000","0.00000000"],["77567.20000000","0.00000000"],["77566.87000000","0.02000000"],["77566.78000000","0.00007000"],["77566.72000000","0.00000000"],["77566.52000000","0.00644000"],["77565.85000000","0.00000000"],["77565.71000000","0.00008000"],["77565.67000000","0.00000000"],["77565.63000000","0.34778000"],["77565.54000000","0.00000000"],["77565.40000000","0.00000000"],["77565.32000000","0.00000000"],["77565.30000000","0.00000000"],["77565.15000000","0.00400000"],["77565.00000000","0.00000000"],["77564.73000000","0.00000000"],["77564.30000000","0.00166000"],["77563.50000000","0.00644000"],["77563.17000000","0.00000000"],["77562.84000000","0.00014000"],["77562.21000000","0.00027000"],["77562.03000000","0.00000000"],["77561.89000000","0.00000000"],["77561.86000000","0.00007000"],["77561.83000000","0.00008000"],["77561.75000000","0.00360000"],["77561.66000000","0.00000000"],["77561.50000000","0.00000000"],["77561.36000000","0.00000000"],["77561.18000000","0.00200000"],["77561.16000000","0.00000000"],["77561.08000000","0.00000000"],["77560.24000000","0.00000000"],["77560.15000000","0.44231000"],["77560.07000000","0.00000000"],["77560.03000000","0.62865000"],["77560.00000000","1.96233000"],["77559.87000000","0.00000000"],["77559.23000000","0.00000000"],["77559.00000000","0.00117000"],["77558.80000000","0.00000000"],["77558.70000000","0.00000000"],["77558.16000000","0.00000000"],["77557.96000000","0.00008000"],["77557.87000000","0.00128000"],["77557.75000000","0.00000000"],["77557.32000000","0.00400000"],["77557.13000000","0.10000000"],["77556.63000000","0.10431000"],["77556.22000000","0.00007000"],["77556.07000000","0.00000000"],["77555.96000000","0.00000000"],["77555.08000000","0.00000000"],["77554.69000000","0.10431000"],["77554.08000000","0.00008000"],["77554.07000000","0.00000000"],["77553.96000000","0.00000000"],["77553.44000000","0.00015000"],["77551.82000000","0.00000000"],["77551.60000000","0.00000000"],["77551.21000000","0.00000000"],["77551.02000000","0.00014000"],["77551.00000000","0.00000000"],["77550.20000000","0.00008000"],["77549.24000000","0.14097000"],["77548.74000000","0.00000000"],["77548.19000000","0.00000000"],["77547.62000000","0.00400000"],["77547.08000000","0.00014000"],["77546.32000000","0.00015000"],["77545.68000000","0.00408000"],["77545.44000000","0.07775000"],["77544.83000000","0.00000000"],["77543.74000000","0.00400000"],["77543.14000000","0.00014000"],["77542.61000000","0.00000000"],["77542.44000000","0.00008000"],["77542.00000000","0.04000000"],["77541.91000000","0.00000000"],["77541.63000000","0.60628000"],["77540.06000000","0.00000000"],["77538.31000000","0.79710000"],["77537.76000000","0.04592000"],["77537.72000000","0.00000000"],["77536.11000000","1.01412000"],["77536.01000000","0.00000000"],["77535.85000000","0.33888000"],["77535.48000000","0.00000000"],["77535.44000000","0.00000000"],["77535.26000000","0.00007000"],["77532.30000000","0.00010000"],["77532.17000000","0.12901000"],["77530.60000000","0.00212000"],["77527.75000000","0.34842000"],["77525.04000000","0.00000000"],["77525.03000000","0.00000000"],["77523.87000000","0.00000000"],["77522.10000000","1.16053000"],["77521.77000000","0.00000000"],["77521.76000000","0.00000000"],["77518.39000000","0.06281000"],["77512.79000000","0.00321000"],["77511.93000000","0.79737000"],["77508.97000000","1.64225000"],["77508.56000000","1.27785000"],["77503.65000000","0.00008000"],["77500.51000000","0.00000000"],["77448.50000000","0.18716000"],["77447.33000000","0.00000000"],["77447.32000000","0.00000000"],["77447.29000000","0.00000000"],["77447.27000000","0.00000000"],["77434.82000000","0.00000000"],["77430.78000000","0.35924000"],["77430.77000000","0.00000000"],["77428.59000000","0.06953000"],["77426.07000000","0.00008000"],["77422.59000000","1.15763000"],["77419.40000000","0.64663000"],["77419.39000000","2.15602000"],["77410.56000000","1.20000000"],["77386.82000000","0.00007000"],["77382.95000000","0.00007000"],["77379.08000000","0.00007000"],["77375.21000000","0.00007000"],["77357.23000000","0.00000000"],["77355.08000000","0.00000000"],["77348.49000000","0.00008000"],["77286.24000000","0.00000000"],["77270.91000000","0.00008000"],["77269.80000000","0.02388000"],["77266.22000000","0.00032000"],["77252.57000000","1.79315000"],["77202.05000000","0.00000000"],["77193.32000000","0.00008000"],["77124.46000000","0.00000000"],["77115.74000000","0.00008000"],["77046.87000000","0.00000000"],["77038.16000000","0.00008000"],["76969.28000000","0.00000000"],["76960.58000000","0.00008000"],["69831.00000000","0.00000000"],["62078.00000000","0.01000000"],["62072.00000000","0.14757000"]],"a":[["77581.15000000","4.45193000"],["77581.16000000","0.00027000"],["77581.17000000","0.00013000"],["77581.21000000","0.04000000"],["77581.23000000","1.90936000"],["77581.24000000","0.46584000"],["77581.25000000","0.00000000"],["77581.28000000","0.00000000"],["77581.29000000","0.00000000"],["77581.30000000","0.12823000"],["77581.70000000","0.05000000"],["77581.75000000","0.05000000"],["77581.84000000","0.00000000"],["77581.85000000","0.00021000"],["77581.94000000","0.00021000"],["77582.01000000","0.00021000"],["77582.13000000","0.24807000"],["77582.24000000","0.00007000"],["77582.25000000","0.00021000"],["77582.26000000","0.00000000"],["77582.45000000","0.24807000"],["77582.54000000","0.00014000"],["77582.70000000","0.00000000"],["77582.72000000","0.00021000"],["77582.92000000","0.00000000"],["77583.36000000","0.00000000"],["77583.51000000","0.24814000"],["77583.76000000","0.00000000"],["77583.81000000","0.00000000"],["77583.86000000","0.02900000"],["77583.91000000","0.00021000"],["77584.01000000","0.00007000"],["77584.16000000","0.00000000"],["77584.21000000","0.00000000"],["77584.22000000","0.00007000"],["77584.48000000","0.00400000"],["77584.75000000","0.00007000"],["77584.76000000","0.00000000"],["77585.05000000","0.00000000"],["77585.41000000","0.00007000"],["77585.63000000","0.00000000"],["77585.81000000","0.00000000"],["77586.01000000","0.00007000"],["77586.02000000","0.00000000"],["77586.03000000","0.00000000"],["77586.19000000","1.35701000"],["77586.20000000","1.31471000"],["77586.32000000","0.00007000"],["77586.33000000","0.63165000"],["77586.34000000","0.00000000"],["77586.35000000","0.00000000"],["77586.42000000","0.00400000"],["77586.48000000","0.00014000"],["77586.49000000","0.00007000"],["77586.54000000","0.12895000"],["77586.97000000","0.12965000"],["77587.08000000","0.00000000"],["77587.09000000","0.00007000"],["77587.10000000","0.00000000"],["77587.13000000","0.00124000"],["77587.30000000","0.00000000"],["77587.31000000","0.26280000"],["77587.51000000","0.00000000"],["77587.77000000","0.00000000"],["77587.79000000","0.00000000"],["77587.85000000","0.38683000"],["77587.99000000","0.00000000"],["77588.00000000","0.00000000"],["77588.01000000","0.00000000"],["77588.02000000","0.00000000"],["77588.31000000","0.00000000"],["77588.32000000","0.00327000"],["77588.33000000","0.41269000"],["77588.34000000","0.13051000"],["77588.36000000","0.00400000"],["77588.53000000","0.00000000"],["77588.54000000","0.30000000"],["77588.55000000","0.00000000"],["77588.89000000","0.00000000"],["77588.99000000","0.00159000"],["77589.00000000","0.00008000"],["77589.08000000","0.00000000"],["77589.09000000","0.00000000"],["77589.69000000","0.01284000"],["77589.77000000","0.00000000"],["77590.00000000","2.15490000"],["77590.01000000","0.61649000"],["77590.02000000","0.00000000"],["77590.03000000","0.00000000"],["77590.05000000","0.00000000"],["77590.10000000","0.00000000"],["77590.12000000","0.00000000"],["77590.13000000","0.00000000"],["77590.14000000","0.00007000"],["77590.61000000","0.00000000"],["77590.77000000","0.00000000"],["77591.54000000","0.40649000"],["77591.55000000","1.31471000"],["77591.78000000","0.00007000"],["77591.79000000","0.00027000"],["77591.85000000","0.00000000"],["77591.87000000","0.00000000"],["77591.93000000","0.00000000"],["77591.94000000","0.00007000"],["77591.97000000","0.04139000"],["77591.98000000","0.00000000"],["77592.00000000","0.00007000"],["77592.05000000","0.00000000"],["77592.06000000","0.00000000"],["77592.24000000","0.00408000"],["77592.38000000","0.34813000"],["77592.54000000","0.03210000"],["77592.55000000","0.00000000"],["77592.70000000","0.00000000"],["77592.73000000","0.00000000"],["77592.74000000","0.00000000"],["77592.81000000","0.00000000"],["77592.90000000","0.00007000"],["77593.28000000","0.00000000"],["77593.29000000","0.14186000"],["77594.01000000","0.00000000"],["77594.02000000","0.00000000"],["77594.07000000","0.00010000"],["77594.14000000","0.07500000"],["77594.15000000","0.00000000"],["77594.31000000","0.10426000"],["77594.33000000","0.00000000"],["77594.35000000","0.00000000"],["77594.36000000","1.14312000"],["77594.37000000","0.58469000"],["77594.38000000","0.00000000"],["77594.85000000","0.00000000"],["77595.04000000","0.00007000"],["77595.08000000","0.38679000"],["77595.20000000","0.16870000"],["77595.35000000","0.00330000"],["77595.82000000","0.34778000"],["77595.83000000","0.21555000"],["77595.85000000","0.00000000"],["77595.87000000","0.03220000"],["77595.90000000","0.00000000"],["77596.01000000","0.00000000"],["77596.12000000","0.00400000"],["77596.25000000","0.10425000"],["77596.82000000","0.00008000"],["77597.01000000","0.00000000"],["77597.05000000","0.90269000"],["77597.06000000","1.15870000"],["77597.07000000","1.13887000"],["77597.08000000","0.00000000"],["77597.11000000","0.00000000"],["77597.15000000","0.00000000"],["77597.76000000","0.28728000"],["77597.77000000","1.93226000"],["77597.79000000","0.00000000"],["77597.82000000","0.00000000"],["77598.32000000","0.00000000"],["77598.96000000","0.00000000"],["77599.17000000","0.00000000"],["77599.56000000","0.00000000"],["77599.69000000","0.00007000"],["77599.79000000","0.01278000"],["77600.00000000","0.00022000"],["77600.65000000","0.00000000"],["77600.73000000","0.00000000"],["77600.80000000","0.00000000"],["77601.04000000","0.00000000"],["77601.05000000","0.00000000"],["77601.24000000","0.00000000"],["77601.38000000","0.34809000"],["77602.65000000","0.00000000"],["77602.76000000","0.00000000"],["77603.55000000","0.00007000"],["77604.34000000","0.00000000"],["77604.47000000","0.00000000"],["77604.57000000","0.00008000"],["77604.70000000","0.00000000"],["77605.53000000","0.00000000"],["77606.63000000","0.00000000"],["77607.72000000","0.00000000"],["77608.00000000","0.00265000"],["77608.39000000","0.00000000"],["77608.45000000","0.00008000"],["77608.82000000","0.00000000"],["77610.25000000","0.00000000"],["77610.76000000","0.00400000"],["77611.58000000","0.00000000"],["77612.27000000","0.00000000"],["77613.29000000","0.00128000"],["77613.58000000","0.00400000"],["77613.90000000","0.00000000"],["77614.21000000","0.00000000"],["77614.79000000","0.79631000"],["77615.49000000","0.02003000"],["77615.52000000","0.00015000"],["77615.85000000","0.00000000"],["77616.00000000","0.00007000"],["77616.21000000","0.00008000"],["77616.65000000","0.00000000"],["77617.17000000","0.00000000"],["77617.46000000","0.00000000"],["77617.49000000","0.48962000"],["77617.80000000","0.00000000"],["77618.59000000","0.00000000"],["77619.40000000","0.00000000"],["77619.51000000","0.51409000"],["77619.86000000","0.05273000"],["77620.09000000","0.00008000"],["77621.38000000","0.00000000"],["77621.94000000","0.00000000"],["77623.23000000","0.00000000"],["77623.25000000","0.00000000"],["77623.26000000","0.00000000"],["77623.40000000","2.03114000"],["77624.17000000","0.00616000"],["77624.21000000","0.12782000"],["77624.56000000","0.35942000"],["77624.93000000","0.00000000"],["77625.88000000","0.00000000"],["77626.04000000","0.00000000"],["77628.81000000","0.00000000"],["77628.87000000","0.00431000"],["77629.00000000","0.01000000"],["77629.74000000","0.00432000"],["77631.38000000","0.00000000"],["77635.00000000","0.00000000"],["77635.27000000","0.00000000"],["77636.00000000","0.03000000"],["77637.65000000","0.00000000"],["77638.63000000","0.00000000"],["77638.99000000","0.47234000"],["77639.54000000","0.00000000"],["77641.16000000","0.79604000"],["77641.42000000","0.00000000"],["77643.43000000","0.00000000"],["77648.45000000","0.00000000"],["77651.42000000","0.00000000"],["77651.43000000","0.00000000"],["77651.99000000","0.05219000"],["77652.89000000","0.00000000"],["77656.54000000","0.00000000"],["77656.93000000","0.00000000"],["77667.35000000","0.00000000"],["77671.41000000","1.65482000"],["77674.42000000","0.00000000"],["77674.81000000","1.47420000"],["77675.42000000","0.00000000"],["77689.33000000","0.63152000"],["77689.34000000","0.00000000"],["77697.60000000","0.14566000"],["77700.03000000","0.00000000"],["77700.68000000","0.04524000"],["77701.99000000","0.03897000"],["77729.70000000","0.00000000"],["77733.38000000","0.00000000"],["77743.50000000","0.00008000"],["77745.22000000","2.62173000"],["77752.26000000","0.00000000"],["77767.02000000","0.00000000"],["77821.08000000","0.00008000"],["77826.39000000","0.00000000"],["77827.82000000","0.00000000"],["77828.41000000","0.00000000"],["77829.86000000","0.00000000"],["77842.64000000","0.00033000"],["77856.99000000","0.00000000"],["77876.10000000","1.20006000"],["77896.43000000","0.00000000"],["77898.67000000","0.00008000"],["77907.46000000","0.00000000"],["77910.45000000","0.00000000"],["77955.87000000","0.00000000"],["77969.21000000","0.00008000"],["77972.88000000","0.00000000"],["77977.96000000","0.00000000"],["78046.79000000","0.00008000"],["78055.55000000","0.00017000"],["78144.00000000","0.00073000"],["78201.95000000","0.00008000"],["78210.73000000","0.00024000"],["78347.75000000","0.00000000"]]}}
{"type":"trade","received_at_ms":1788331836558,"data":{"e":"trade","E":1788331836697,"s":"BTCUSDT","t":6646633742,"p":"77581.14000000","q":"0.00039000","T":1788331836697,"m":true,"M":true}}
{"type":"trade","received_at_ms":1788331836558,"data":{"e":"trade","E":1788331836697,"s":"BTCUSDT","t":6646633743,"p":"77581.14000000","q":"0.01000000","T":1788331836697,"m":true,"M":true}}
{"type":"trade","received_at_ms":1788331836558,"data":{"e":"trade","E":1788331836697,"s":"BTCUSDT","t":6646633744,"p":"77581.14000000","q":"0.00007000","T":1788331836697,"m":true,"M":true}}
{"type":"trade","received_at_ms":1788331836558,"data":{"e":"trade","E":1788331836697,"s":"BTCUSDT","t":6646633745,"p":"77581.14000000","q":"0.00007000","T":1788331836697,"m":true,"M":true}}
{"type":"trade","received_at_ms":1788331836558,"data":{"e":"trade","E":1788331836697,"s":"BTCUSDT","t":6646633746,"p":"77581.14000000","q":"0.00007000","T":1788331836697,"m":true,"M":true}}
{"type":"trade","received_at_ms":1788331836558,"data":{"e":"trade","E":1788331836697,"s":"BTCUSDT","t":6646633747,"p":"77581.14000000","q":"0.00007000","T":1788331836697,"m":true,"M":true}}
{"type":"trade","received_at_ms":1788331836558,"data":{"e":"trade","E":1788331836697,"s":"BTCUSDT","t":6646633748,"p":"77581.14000000","q":"0.00007000","T":1788331836697,"m":true,"M":true}}
{"type":"trade","received_at_ms":1788331836558,"data":{"e":"trade","E":1788331836697,"s":"BTCUSDT","t":6646633749,"p":"77581.14000000","q":"0.00007000","T":1788331836697,"m":true,"M":true}}
{"type":"trade","received_at_ms":1788331836558,"data":{"e":"trade","E":1788331836697,"s":"BTCUSDT","t":6646633750,"p":"77581.14000000","q":"0.02000000","T":1788331836697,"m":true,"M":true}}
{"type":"trade","received_at_ms":1788331836558,"data":{"e":"trade","E":1788331836697,"s":"BTCUSDT","t":6646633751,"p":"77581.14000000","q":"0.00007000","T":1788331836697,"m":true,"M":true}}
{"type":"trade","received_at_ms":1788331836558,"data":{"e":"trade","E":1788331836697,"s":"BTCUSDT","t":6646633752,"p":"77581.14000000","q":"0.00007000","T":1788331836697,"m":true,"M":true}}
{"type":"trade","received_at_ms":1788331836558,"data":{"e":"trade","E":1788331836697,"s":"BTCUSDT","t":6646633753,"p":"77581.14000000","q":"0.00007000","T":1788331836697,"m":true,"M":true}}
{"type":"trade","received_at_ms":1788331836558,"data":{"e":"trade","E":1788331836697,"s":"BTCUSDT","t":6646633754,"p":"77581.14000000","q":"0.00007000","T":1788331836697,"m":true,"M":true}}
{"type":"trade","received_at_ms":1788331836558,"data":{"e":"trade","E":1788331836697,"s":"BTCUSDT","t":6646633755,"p":"77581.14000000","q":"0.00113000","T":1788331836697,"m":true,"M":true}}
{"type":"trade","received_at_ms":1788331836558,"data":{"e":"trade","E":1788331836697,"s":"BTCUSDT","t":6646633756,"p":"77581.14000000","q":"0.01000000","T":1788331836697,"m":true,"M":true}}
{"type":"trade","received_at_ms":1788331836558,"data":{"e":"trade","E":1788331836697,"s":"BTCUSDT","t":6646633757,"p":"77581.14000000","q":"0.02000000","T":1788331836697,"m":true,"M":true}}
{"type":"depth","received_at_ms":1788331836574,"data":{"e":"depthUpdate","E":1788331836714,"s":"BTCUSDT","U":99555812722,"u":99555813223,"b":[["77581.14000000","0.10530000"],["77581.13000000","0.00063000"],["77580.80000000","0.00000000"],["77580.02000000","0.00000000"],["77580.01000000","0.00021000"],["77580.00000000","0.03028000"],["77579.17000000","0.00000000"],["77579.16000000","0.00014000"],["77579.15000000","0.00021000"],["77579.00000000","0.00000000"],["77578.47000000","0.00000000"],["77578.39000000","0.00000000"],["77578.38000000","0.00021000"],["77578.07000000","0.00000000"],["77578.01000000","0.00021000"],["77578.00000000","0.03035000"],["77576.85000000","0.00000000"],["77576.75000000","0.00014000"],["77576.74000000","0.11447000"],["77576.73000000","0.00000000"],["77576.55000000","0.00014000"],["77576.54000000","0.12414000"],["77576.04000000","0.00021000"],["77576.01000000","0.00007000"],["77576.00000000","0.03035000"],["77575.39000000","0.00432000"],["77575.29000000","0.11447000"],["77575.28000000","0.00000000"],["77575.27000000","0.00007000"],["77574.90000000","0.00000000"],["77574.86000000","0.00007000"],["77574.68000000","0.00007000"],["77574.66000000","0.00014000"],["77574.50000000","0.02007000"],["77574.47000000","0.02007000"],["77574.18000000","0.11405000"],["77574.17000000","0.00000000"],["77574.14000000","0.00721000"],["77573.66000000","0.00000000"],["77572.90000000","0.00865000"],["77572.89000000","0.11447000"],["77572.88000000","0.00000000"],["77572.46000000","0.00000000"],["77572.32000000","0.00000000"],["77572.01000000","0.15741000"],["77571.66000000","0.00913000"],["77570.85000000","0.11447000"],["77570.72000000","0.00014000"],["77570.60000000","0.00000000"],["77569.80000000","0.07775000"],["77569.41000000","0.00000000"],["77569.38000000","0.11447000"],["77569.07000000","0.11647000"],["77569.06000000","0.06000000"],["77568.96000000","0.01015000"],["77568.69000000","0.00069000"],["77568.64000000","0.00048000"],["77568.50000000","0.00188000"],["77568.25000000","0.00048000"],["77567.76000000","0.08000000"],["77566.91000000","0.00257000"],["77566.78000000","0.00014000"],["77566.52000000","0.00000000"],["77565.63000000","0.34786000"],["77565.13000000","0.00412000"],["77564.69000000","0.00000000"],["77564.45000000","0.00000000"],["77563.60000000","0.00000000"],["77563.49000000","0.00000000"],["77561.18000000","0.00000000"],["77560.96000000","0.00400000"],["77560.03000000","0.63265000"],["77560.01000000","1.61057000"],["77559.46000000","0.00000000"],["77559.42000000","0.00012000"],["77558.96000000","0.00000000"],["77558.78000000","0.00000000"],["77557.84000000","0.00008000"],["77557.54000000","0.00000000"],["77557.42000000","0.00000000"],["77556.27000000","0.00257000"],["77555.22000000","0.00000000"],["77555.13000000","0.00000000"],["77554.19000000","0.00000000"],["77553.89000000","0.00000000"],["77553.78000000","0.00000000"],["77552.82000000","0.00000000"],["77552.75000000","0.03867000"],["77552.72000000","0.00000000"],["77551.62000000","0.00118000"],["77551.46000000","0.00000000"],["77551.28000000","0.00118000"],["77551.03000000","0.00059000"],["77550.57000000","0.00189000"],["77550.53000000","0.00012000"],["77546.69000000","0.00200000"],["77545.43000000","1.10033000"],["77541.80000000","0.00400000"],["77541.63000000","0.88246000"],["77539.86000000","0.00400000"],["77537.96000000","0.00000000"],["77537.55000000","0.00000000"],["77535.26000000","0.00000000"],["77532.31000000","0.00000000"],["77532.18000000","0.20365000"],["77532.17000000","0.00007000"],["77530.60000000","0.00000000"],["77530.59000000","0.00000000"],["77529.41000000","0.00000000"],["77528.27000000","0.00000000"],["77528.10000000","0.00000000"],["77519.87000000","0.00620000"],["77518.91000000","0.00435000"],["77518.57000000","0.00424000"],["77517.00000000","0.00433000"],["77516.01000000","0.00321000"],["77514.59000000","0.00212000"],["77514.01000000","0.61945000"],["77512.41000000","0.00000000"],["77511.47000000","1.31471000"],["77494.14000000","0.00000000"],["77493.63000000","0.00000000"],["77491.05000000","0.04497000"],["77471.84000000","0.01289000"],["77471.83000000","0.04525000"],["77453.95000000","0.00000000"],["77438.27000000","0.00128000"],["77437.72000000","0.00671000"],["77432.96000000","0.05206000"],["77430.78000000","0.00000000"],["77378.58000000","0.16870000"],["77372.69000000","0.00007000"],["77368.82000000","0.00007000"],["77366.36000000","0.00007000"],["77362.49000000","0.00007000"],["77279.64000000","0.00000000"],["77266.22000000","0.00000000"],["77257.95000000","0.00028000"],["69823.03000000","0.00032000"],["62078.00000000","0.00800000"]],"a":[["77581.15000000","4.68711000"],["77581.19000000","0.78979000"],["77581.20000000","1.31471000"],["77581.21000000","0.04021000"],["77581.22000000","0.00014000"],["77581.23000000","0.00028000"],["77581.29000000","0.00014000"],["77581.30000000","0.12822000"],["77581.69000000","0.00000000"],["77581.70000000","0.00021000"],["77581.75000000","0.00021000"],["77581.85000000","0.00007000"],["77581.94000000","0.00007000"],["77582.01000000","0.00007000"],["77582.12000000","0.00007000"],["77582.13000000","0.24835000"],["77582.25000000","0.00007000"],["77582.40000000","0.01856000"],["77582.45000000","0.24821000"],["77582.54000000","0.00414000"],["77582.72000000","0.00007000"],["77583.51000000","0.24828000"],["77583.62000000","0.00000000"],["77583.64000000","0.02227000"],["77583.86000000","0.02907000"],["77583.91000000","0.00007000"],["77584.27000000","0.00007000"],["77584.62000000","0.04152000"],["77584.74000000","0.00400000"],["77584.88000000","0.02227000"],["77586.18000000","0.34978000"],["77586.19000000","0.93512000"],["77586.33000000","0.63158000"],["77587.09000000","0.00000000"],["77587.31000000","0.26273000"],["77587.50000000","0.15000000"],["77587.73000000","0.00322000"],["77588.33000000","0.41262000"],["77590.01000000","0.60279000"],["77590.14000000","0.00000000"],["77590.83000000","0.00007000"],["77594.36000000","0.78635000"],["77594.69000000","0.00007000"],["77595.71000000","0.00000000"],["77595.83000000","0.00947000"],["77597.07000000","1.00023000"],["77600.28000000","0.00000000"],["77600.70000000","0.00008000"],["77601.27000000","0.00200000"],["77603.05000000","0.00190000"],["77603.07000000","0.00012000"],["77603.16000000","0.00060000"],["77603.26000000","0.00000000"],["77603.51000000","0.00000000"],["77608.59000000","0.48962000"],["77609.41000000","0.00000000"],["77610.76000000","0.00000000"],["77611.64000000","0.00400000"],["77611.95000000","0.00000000"],["77612.33000000","0.00008000"],["77613.24000000","0.00000000"],["77613.58000000","0.00000000"],["77614.31000000","0.00433000"],["77614.38000000","0.25000000"],["77614.60000000","0.09489000"],["77614.67000000","0.00626000"],["77616.16000000","0.00000000"],["77616.29000000","0.00027000"],["77617.15000000","0.00000000"],["77619.44000000","0.00429000"],["77619.48000000","0.00433000"],["77619.51000000","0.23936000"],["77619.79000000","0.02523000"],["77620.00000000","0.04200000"],["77621.05000000","0.00000000"],["77621.28000000","0.00678000"],["77623.40000000","1.93226000"],["77623.68000000","0.01153000"],["77624.17000000","0.00000000"],["77627.48000000","0.00000000"],["77628.00000000","0.03000000"],["77628.22000000","0.00000000"],["77628.87000000","0.00000000"],["77629.00000000","0.00000000"],["77629.74000000","0.00000000"],["77639.55000000","0.00110000"],["77640.26000000","0.01739000"],["77640.70000000","0.00541000"],["77650.84000000","0.09305000"],["77651.86000000","0.00386000"],["77653.76000000","0.00412000"],["77653.85000000","0.00000000"],["77653.99000000","0.00000000"],["77654.69000000","0.00000000"],["77658.88000000","0.00008000"],["77667.60000000","0.13707000"],["77669.06000000","0.04560000"],["77673.55000000","0.00000000"],["77681.85000000","0.75095000"],["77682.61000000","0.00000000"],["77691.32000000","0.00000000"],["77723.89000000","0.00971000"],["77791.09000000","0.30085000"],["77867.48000000","0.00000000"],["78124.37000000","0.00008000"],["78133.14000000","0.00000000"]]}}
{"type":"depth","received_at_ms":1788331836688,"data":{"e":"depthUpdate","E":1788331836814,"s":"BTCUSDT","U":99555813224,"u":99555813429,"b":[["77581.14000000","0.12137000"],["77581.13000000","0.00091000"],["77580.00000000","0.03028000"],["77579.16000000","0.00000000"],["77579.15000000","0.00007000"],["77578.38000000","0.00007000"],["77578.22000000","0.00014000"],["77578.21000000","0.07453000"],["77578.20000000","0.10353000"],["77578.00000000","0.03035000"],["77577.80000000","0.01294000"],["77576.74000000","0.11461000"],["77576.55000000","0.00000000"],["77576.54000000","0.54862000"],["77576.08000000","0.08219000"],["77576.04000000","0.00215000"],["77576.01000000","0.00000000"],["77576.00000000","0.03035000"],["77575.29000000","0.11461000"],["77574.50000000","0.00021000"],["77574.47000000","0.00021000"],["77572.95000000","0.00000000"],["77572.92000000","0.11447000"],["77572.91000000","1.39246000"],["77572.89000000","0.00000000"],["77572.01000000","0.08047000"],["77570.85000000","0.00000000"],["77569.38000000","0.00000000"],["77569.07000000","0.00200000"],["77568.47000000","0.00257000"],["77566.91000000","0.00000000"],["77563.74000000","0.02000000"],["77556.21000000","0.00000000"],["77556.09000000","0.00000000"],["77555.44000000","0.02053000"],["77552.57000000","0.00000000"],["77552.46000000","0.00000000"],["77552.44000000","0.00000000"],["77552.31000000","0.25000000"],["77551.79000000","0.05339000"],["77539.20000000","0.00007000"],["77538.32000000","0.00008000"],["77537.92000000","0.00415000"],["77532.38000000","0.55290000"],["77532.37000000","1.30011000"],["77532.18000000","0.00000000"],["77523.02000000","0.00000000"],["77510.01000000","0.00322000"],["77503.43000000","0.02000000"],["77493.60000000","0.97080000"],["77493.59000000","3.25189000"],["77471.84000000","0.01584000"],["77464.67000000","0.00000000"],["77456.27000000","0.06680000"],["77454.15000000","0.02019000"],["77444.81000000","0.00000000"],["77437.72000000","0.00000000"],["77431.01000000","0.00128000"],["77430.33000000","0.00671000"],["77423.91000000","0.09224000"],["77362.49000000","0.00000000"]],"a":[["77581.15000000","4.68877000"],["77581.18000000","0.00014000"],["77581.19000000","0.78993000"],["77581.20000000","1.31485000"],["77581.21000000","0.04021000"],["77581.22000000","0.00000000"],["77581.23000000","0.00014000"],["77581.24000000","0.63454000"],["77581.29000000","0.00000000"],["77581.30000000","0.12822000"],["77581.70000000","0.00007000"],["77581.75000000","0.00007000"],["77582.12000000","0.00014000"],["77582.13000000","0.24835000"],["77582.40000000","0.01870000"],["77582.44000000","0.00007000"],["77582.72000000","0.00014000"],["77583.20000000","0.00257000"],["77583.87000000","0.01285000"],["77584.69000000","0.00127000"],["77584.74000000","0.00000000"],["77586.17000000","0.00400000"],["77586.97000000","0.12958000"],["77588.32000000","0.00655000"],["77588.99000000","0.00000000"],["77589.69000000","0.00000000"],["77590.01000000","0.58990000"],["77592.20000000","0.00328000"],["77594.37000000","0.41599000"],["77595.20000000","0.00000000"],["77595.83000000","0.00644000"],["77597.07000000","0.99923000"],["77598.95000000","0.00000000"],["77601.76000000","0.00008000"],["77605.62000000","0.04608000"],["77608.41000000","1.29883000"],["77612.82000000","0.03867000"],["77617.49000000","0.00000000"],["77620.89000000","0.00000000"],["77634.39000000","0.00012000"],["77637.64000000","0.00000000"],["77638.99000000","0.65670000"],["77640.69000000","0.00321000"],["77647.15000000","2.10736000"],["77647.20000000","3.24545000"],["77653.75000000","0.00000000"],["77717.99000000","0.00128000"],["77731.31000000","0.00000000"],["77820.48000000","0.00000000"],["77820.88000000","0.11555000"],["77822.52000000","0.00000000"]]}}
{"type":"trade","received_at_ms":1788331836688,"data":{"e":"trade","E":1788331836819,"s":"BTCUSDT","t":6646633758,"p":"77581.15000000","q":"0.03223000","T":1788331836818,"m":false,"M":true}}
{"type":"trade","received_at_ms":1788331836718,"data":{"e":"trade","E":1788331836857,"s":"BTCUSDT","t":6646633759,"p":"77581.15000000","q":"0.00100000","T":1788331836857,"m":false,"M":true}}
{"type":"depth","received_at_ms":1788331836782,"data":{"e":"depthUpdate","E":1788331836914,"s":"BTCUSDT","U":99555813430,"u":99555813493,"b":[["77581.14000000","0.12144000"],["77581.13000000","0.00098000"],["77580.00000000","0.03035000"],["77578.84000000","0.00018000"],["77578.21000000","0.07467000"],["77578.20000000","0.10367000"],["77578.00000000","0.03035000"],["77577.80000000","0.01308000"],["77576.54000000","0.54862000"],["77576.08000000","0.08233000"],["77576.00000000","0.03021000"],["77575.29000000","0.11447000"],["77574.50000000","0.00007000"],["77574.47000000","0.00007000"],["77569.07000000","0.00000000"],["77565.03000000","0.00200000"],["77563.36000000","0.02000000"],["77557.15000000","0.49849000"],["77533.32000000","0.85678000"],["77533.31000000","1.01796000"],["77532.38000000","0.00000000"],["77512.79000000","0.00000000"],["77510.03000000","0.00320000"],["77505.61000000","0.02000000"],["77454.15000000","0.00000000"],["77448.68000000","0.00000000"],["77432.97000000","0.00128000"],["77381.31000000","0.02019000"],["69837.35000000","0.00000000"],["69837.34000000","0.00009000"],["69823.03000000","0.00064000"],["62064.91000000","0.00000000"]],"a":[["77581.15000000","4.70130000"],["77586.33000000","0.63094000"],["77586.54000000","0.12888000"],["77587.31000000","0.09403000"],["77596.66000000","0.00008000"],["77597.44000000","0.02800000"],["77612.59000000","0.00009000"],["77637.99000000","0.00322000"],["77650.83000000","0.06766000"],["77651.99000000","0.00000000"],["77653.84000000","0.00000000"],["77715.88000000","0.00128000"],["77731.98000000","0.00000000"],["77738.78000000","0.01543000"],["77761.05000000","0.00000000"]]}}
{"type":"trade","received_at_ms":1788331836862,"data":{"e":"trade","E":1788331837002,"s":"BTCUSDT","t":6646633760,"p":"77581.14000000","q":"0.00257000","T":1788331837002,"m":true,"M":true}}
{"type":"depth","received_at_ms":1788331836874,"data":{"e":"depthUpdate","E":1788331837014,"s":"BTCUSDT","U":99555813494,"u":99555813536,"b":[["77581.14000000","0.11894000"],["77581.13000000","0.00105000"],["77578.22000000","0.00000000"],["77578.21000000","0.07864000"],["77576.56000000","0.00007000"],["77576.55000000","0.07775000"],["77572.19000000","0.00153000"],["77570.03000000","0.00000000"],["77569.81000000","0.00644000"],["77553.44000000","0.00415000"],["77547.13000000","0.00335000"],["77538.26000000","0.00212000"],["77537.92000000","0.00015000"],["77514.59000000","0.00000000"],["77473.46000000","0.00000000"],["77469.81000000","0.00000000"],["77457.38000000","0.00012000"],["69823.03000000","0.00080000"],["62065.00000000","0.00000000"],["62064.92000000","0.00032000"]],"a":[["77581.15000000","4.70142000"],["77588.91000000","0.00009000"],["77589.98000000","0.09622000"],["77589.99000000","1.22809000"],["77591.54000000","0.00000000"],["77592.53000000","0.27692000"],["77596.67000000","0.00009000"],["77597.07000000","0.99911000"],["77597.76000000","0.00000000"],["77602.88000000","0.00038000"],["77604.43000000","0.00009000"],["77604.83000000","0.00000000"],["77612.19000000","0.00009000"],["77612.59000000","0.00000000"],["77617.75000000","0.00000000"],["77620.35000000","0.00000000"],["77628.11000000","0.00000000"],["77714.95000000","0.00000000"],["77717.31000000","0.00000000"],["77722.06000000","0.00000000"]]}}
{"type":"depth","received_at_ms":1788331836986,"data":{"e":"depthUpdate","E":1788331837114,"s":"BTCUSDT","U":99555813537,"u":99555813565,"b":[["77578.84000000","0.00000000"],["77578.22000000","0.00014000"],["77578.21000000","0.00028000"],["77577.85000000","0.00027000"],["77576.74000000","0.11461000"],["77576.56000000","0.00000000"],["77576.55000000","0.07789000"],["77576.08000000","0.08219000"],["77560.15000000","0.00000000"],["77554.97000000","0.44234000"],["77524.54000000","0.00000000"],["77503.43000000","0.00000000"],["77453.91000000","0.00011000"],["77411.24000000","0.02019000"],["77403.93000000","0.00000000"],["77381.31000000","0.00000000"],["77357.27000000","0.02019000"],["69823.03000000","0.00096000"]],"a":[["77581.15000000","4.70455000"],["77609.32000000","0.00000000"],["77695.34000000","0.00012000"],["77697.70000000","0.00019000"]]}}
{"type":"trade","received_at_ms":1788331837034,"data":{"e":"trade","E":1788331837174,"s":"BTCUSDT","t":6646633761,"p":"77581.15000000","q":"0.00128000","T":1788331837174,"m":false,"M":true}}
{"type":"depth","received_at_ms":1788331837074,"data":{"e":"depthUpdate","E":1788331837214,"s":"BTCUSDT","U":99555813566,"u":99555813591,"b":[["77580.00000000","0.03035000"],["77578.22000000","0.00000000"],["77578.21000000","0.00014000"],["77578.10000000","0.00007000"],["77577.71000000","0.00000000"],["77576.56000000","0.00007000"],["77576.08000000","0.08233000"],["77550.06000000","0.09481000"],["76898.69000000","0.00000000"],["69837.34000000","0.00000000"],["69823.03000000","0.00112000"],["62064.92000000","0.00000000"],["62064.91000000","0.00000000"]],"a":[["77581.15000000","4.70327000"],["77592.00000000","0.00015000"],["77612.47000000","0.00000000"],["77702.45000000","0.00032000"],["77748.16000000","0.00000000"],["78744.87000000","0.00030000"]]}}
{"type":"depth","received_at_ms":1788331837174,"data":{"e":"depthUpdate","E":1788331837314,"s":"BTCUSDT","U":99555813592,"u":99555813602,"b":[["77570.73000000","0.00169000"],["77568.97000000","0.00000000"],["77563.37000000","0.02000000"],["77552.00000000","0.03265000"],["77505.61000000","0.04000000"],["77378.67000000","0.00000000"],["77358.32000000","0.00813000"],["69823.03000000","0.00144000"]],"a":[["77597.45000000","0.03000000"],["77609.30000000","0.00000000"],["77697.86000000","0.02019000"],["77715.89000000","0.00000000"]]}}
{"type":"depth","received_at_ms":1788331837274,"data":{"e":"depthUpdate","E":1788331837414,"s":"BTCUSDT","U":99555813603,"u":99555813615,"b":[["77581.14000000","0.11887000"],["77581.13000000","0.00098000"],["77578.18000000","0.00018000"],["77547.13000000","0.00000000"],["77543.00000000","0.70000000"],["77536.93000000","0.64514000"],["77505.61000000","0.00000000"],["77500.83000000","1.27798000"],["77472.90000000","0.00000000"],["69823.03000000","0.00128000"]],"a":[["77581.24000000","0.46584000"],["77597.07000000","0.99901000"]]}}
{"type":"depth","received_at_ms":1788331837374,"data":{"e":"depthUpdate","E":1788331837514,"s":"BTCUSDT","U":99555813616,"u":99555813668,"b":[["77579.68000000","0.00014000"],["77579.67000000","0.11447000"],["77579.00000000","0.00017000"],["77578.18000000","0.00000000"],["77576.56000000","0.00000000"],["77568.05000000","0.02000000"],["77567.30000000","0.02000000"],["77567.28000000","0.02343000"],["77567.27000000","0.02000000"],["77564.97000000","0.02000000"],["77563.43000000","0.02000000"],["77563.42000000","0.02000000"],["77561.47000000","0.12892000"],["77553.71000000","0.12894000"],["77522.14000000","0.02000000"],["77521.28000000","0.02000000"],["77517.97000000","0.02000000"],["77508.67000000","0.02000000"],["77507.12000000","0.02000000"],["77506.27000000","0.02000000"],["77506.17000000","0.02000000"],["77503.60000000","0.02000000"],["77502.54000000","0.02000000"],["77501.00000000","0.02000000"],["69823.03000000","0.00160000"],["69823.00000000","0.00000000"],["62065.00000000","0.00000000"],["62064.92000000","0.00032000"]],"a":[["77581.20000000","1.36485000"],["77588.93000000","0.00007000"],["77591.72000000","0.00007000"],["77592.77000000","0.02000000"],["77592.82000000","0.02600000"],["77593.54000000","0.05600000"],["77593.58000000","0.02400000"],["77593.61000000","0.03000000"],["77595.88000000","0.02800000"],["77596.10000000","0.12887000"],["77596.65000000","0.02400000"],["77596.88000000","0.00008000"],["77597.43000000","0.04600000"],["77600.00000000","0.00280000"],["77605.04000000","0.00000000"],["77608.51000000","0.02600000"],["77644.57000000","0.02400000"],["77645.68000000","0.00000000"],["77684.81000000","0.00412000"]]}}
{"type":"depth","received_at_ms":1788331837473,"data":{"e":"depthUpdate","E":1788331837614,"s":"BTCUSDT","U":99555813669,"u":99555813734,"b":[["77581.14000000","0.11902000"],["77581.13000000","0.00105000"],["77580.00000000","0.03042000"],["77579.67000000","0.11461000"],["77578.00000000","0.03042000"],["77576.08000000","0.08219000"],["77566.43000000","0.00400000"],["77564.21000000","0.02000000"],["77561.86000000","0.00000000"],["77559.53000000","0.00128000"],["77549.56000000","0.00400000"],["77541.07000000","0.34836000"],["77539.86000000","0.00000000"],["77506.27000000","0.00000000"],["77503.60000000","0.00000000"],["77501.60000000","0.02000000"],["76417.42000000","0.00030000"],["69823.03000000","0.00160000"],["62064.92000000","0.00000000"]],"a":[["77581.15000000","4.71304000"],["77581.24000000","0.46584000"],["77581.28000000","0.00014000"],["77581.29000000","0.32238000"],["77581.30000000","0.12822000"],["77582.44000000","0.00000000"],["77586.32000000","0.00000000"],["77586.49000000","0.00000000"],["77591.97000000","0.00000000"],["77592.90000000","0.00000000"],["77596.66000000","0.02608000"],["77604.00000000","0.00500000"],["77604.02000000","0.00000000"],["77604.63000000","0.00000000"],["77605.38000000","0.42909000"],["77605.40000000","0.00000000"],["77605.76000000","0.00000000"],["77606.00000000","0.00500000"],["77607.73000000","0.00000000"],["77609.29000000","0.02400000"],["77644.49000000","0.00000000"],["77644.61000000","0.00000000"],["77697.86000000","0.00000000"],["77710.32000000","0.02019000"]]}}
{"type":"trade","received_at_ms":1788331837500,"data":{"e":"trade","E":1788331837640,"s":"BTCUSDT","t":6646633762,"p":"77581.14000000","q":"0.00668000","T":1788331837640,"m":true,"M":true}}
{"type":"depth","received_at_ms":1788331837575,"data":{"e":"depthUpdate","E":1788331837714,"s":"BTCUSDT","U":99555813735,"u":99555813773,"b":[["77581.14000000","0.11227000"],["77581.13000000","0.00098000"],["77579.67000000","0.11545000"],["77578.21000000","0.00074000"],["77576.74000000","0.11468000"],["77576.08000000","0.00000000"],["77561.86000000","0.00007000"],["77547.17000000","0.00335000"],["77501.60000000","0.00000000"],["77501.00000000","0.00000000"],["69823.03000000","0.00160000"],["69823.02000000","0.00009000"]],"a":[["77581.24000000","0.46584000"],["77581.29000000","0.32252000"],["77582.45000000","0.24807000"],["77583.20000000","0.00000000"],["77583.66000000","0.00257000"],["77586.19000000","0.93505000"],["77592.90000000","0.00007000"],["77605.67000000","0.00000000"],["77605.80000000","0.00000000"],["77608.00000000","0.00765000"],["77609.29000000","0.00000000"],["77610.00000000","0.00900000"],["77611.87000000","0.00000000"],["77612.00000000","0.00500000"],["77612.75000000","1.57752000"],["77614.00000000","0.00500000"],["77616.00000000","0.00507000"],["77618.00000000","0.00514000"],["77648.54000000","0.00000000"],["77656.49000000","0.00000000"]]}}
{"type":"depth","received_at_ms":1788331837676,"data":{"e":"depthUpdate","E":1788331837814,"s":"BTCUSDT","U":99555813774,"u":99555813790,"b":[["77581.14000000","0.11220000"],["77581.13000000","0.00091000"],["77578.10000000","0.00000000"],["77576.54000000","0.54862000"],["77576.04000000","0.00007000"],["77508.67000000","0.00000000"],["77507.12000000","0.00000000"],["77506.17000000","0.00000000"],["69823.03000000","0.00192000"]],"a":[["77581.15000000","4.71854000"],["77597.08000000","0.02000000"],["77608.51000000","0.00000000"]]}}
{"type":"trade","received_at_ms":1788331837765,"data":{"e":"trade","E":1788331837905,"s":"BTCUSDT","t":6646633763,"p":"77581.14000000","q":"0.00100000","T":1788331837905,"m":true,"M":true}}
{"type":"depth","received_at_ms":1788331837776,"data":{"e":"depthUpdate","E":1788331837914,"s":"BTCUSDT","U":99555813791,"u":99555813809,"b":[["77581.14000000","0.11120000"],["77580.41000000","0.00007000"],["77566.43000000","0.00000000"],["77565.80000000","0.00400000"],["77565.13000000","0.00000000"],["77526.34000000","0.00000000"],["77524.04000000","0.00000000"],["77495.30000000","0.00000000"],["69823.03000000","0.00192000"],["69823.02000000","0.00000000"],["69823.01000000","0.00009000"],["62064.91000000","0.00000000"]],"a":[["77614.95000000","0.00000000"],["77616.86000000","0.02807000"],["77653.76000000","0.00000000"],["77684.81000000","0.00000000"]]}}
{"type":"depth","received_at_ms":1788331837873,"data":{"e":"depthUpdate","E":1788331838014,"s":"BTCUSDT","U":99555813810,"u":99555813821,"b":[["77581.14000000","0.11133000"],["77581.13000000","0.00104000"],["77581.12000000","0.00013000"],["77502.54000000","0.00000000"],["69823.03000000","0.00208000"],["62064.92000000","0.00032000"]],"a":[["77597.06000000","0.83821000"],["77597.07000000","0.72701000"],["77608.94000000","0.00000000"]]}}
{"type":"depth","received_at_ms":1788331837974,"data":{"e":"depthUpdate","E":1788331838114,"s":"BTCUSDT","U":99555813822,"u":99555813837,"b":[["77581.14000000","0.11147000"],["77581.13000000","0.00118000"],["77577.54000000","0.00208000"],["77577.21000000","0.00007000"],["77577.20000000","0.08219000"],["77576.75000000","0.00007000"],["77549.79000000","0.00412000"],["77498.72000000","0.52368000"],["77497.99000000","1.61644000"]],"a":[["77586.33000000","0.63438000"],["77677.34000000","0.00025000"],["77693.28000000","0.00000000"]]}}
{"type":"depth","received_at_ms":1788331838074,"data":{"e":"depthUpdate","E":1788331838214,"s":"BTCUSDT","U":99555813838,"u":99555813856,"b":[["77577.80000000","0.01308000"],["77577.20000000","0.08233000"],["77576.54000000","0.54848000"],["77550.00000000","0.73007000"],["76882.91000000","0.00010000"],["69823.03000000","0.00224000"],["62064.92000000","0.00000000"],["62064.91000000","0.00000000"]],"a":[["77613.28000000","0.00000000"],["78744.87000000","0.00030000"]]}}
{"type":"depth","received_at_ms":1788331838174,"data":{"e":"depthUpdate","E":1788331838314,"s":"BTCUSDT","U":99555813857,"u":99555813864,"b":[["69823.03000000","0.00224000"],["62078.00000000","0.00800000"],["62065.00000000","0.00000000"]],"a":[["77599.60000000","0.00412000"],["77616.87000000","0.03000000"]]}}
{"type":"depth","received_at_ms":1788331838273,"data":{"e":"depthUpdate","E":1788331838414,"s":"BTCUSDT","U":99555813865,"u":99555813870,"b":[["77581.14000000","0.11162000"],["69823.03000000","0.00240000"]],"a":[["77581.15000000","4.71864000"],["77583.21000000","0.00341000"],["77661.54000000","0.00000000"],["77673.50000000","0.00000000"]]}}
{"type":"depth","received_at_ms":1788331838373,"data":{"e":"depthUpdate","E":1788331838514,"s":"BTCUSDT","U":99555813871,"u":99555813888,"b":[["77581.14000000","0.11147000"],["77580.41000000","0.00000000"],["77575.33000000","0.00013000"],["77524.01000000","0.00000000"],["77523.99000000","0.00000000"],["77479.99000000","0.00412000"],["69823.03000000","0.00240000"],["62064.92000000","0.00032000"]],"a":[["77586.13000000","0.00007000"],["77586.96000000","0.00013000"],["77594.51000000","0.00127000"],["77644.25000000","0.02600000"],["77644.48000000","0.03000000"],["77644.61000000","0.03000000"],["77648.14000000","0.02400000"]]}}
{"type":"depth","received_at_ms":1788331838474,"data":{"e":"depthUpdate","E":1788331838614,"s":"BTCUSDT","U":99555813889,"u":99555813920,"b":[["77536.18000000","0.34838000"],["77451.69000000","0.00000000"],["77450.91000000","0.00391000"],["77434.16000000","0.00000000"],["76417.42000000","0.00030000"],["69823.03000000","0.00256000"],["69823.00000000","0.00020000"],["62065.00000000","0.00000000"],["62064.92000000","0.00000000"]],"a":[["77581.15000000","5.19449000"],["77581.17000000","0.00027000"],["77581.18000000","0.03139000"],["77582.12000000","0.00000000"],["77595.83000000","0.00000000"],["77595.87000000","0.00000000"],["77647.36000000","0.02600000"],["77678.43000000","0.00000000"],["77686.19000000","0.00000000"],["77693.94000000","0.00000000"],["77717.20000000","0.00000000"],["77721.22000000","0.00000000"],["77760.08000000","0.00000000"]]}}
{"type":"depth","received_at_ms":1788331838574,"data":{"e":"depthUpdate","E":1788331838714,"s":"BTCUSDT","U":99555813921,"u":99555813939,"b":[["77581.14000000","0.11147000"],["77561.86000000","0.00007000"],["77534.14000000","0.54647000"],["69823.00000000","0.00000000"]],"a":[["77581.15000000","5.19464000"],["77581.18000000","0.03153000"],["77582.40000000","0.01856000"],["77592.90000000","0.00007000"],["77619.51000000","0.37186000"],["77623.25000000","0.52181000"],["77669.44000000","0.00412000"]]}}
{"type":"depth","received_at_ms":1788331838674,"data":{"e":"depthUpdate","E":1788331838814,"s":"BTCUSDT","U":99555813940,"u":99555813961,"b":[["77581.14000000","0.11163000"],["77571.92000000","0.00007000"],["77550.06000000","0.00000000"],["77548.50000000","0.09751000"],["77491.05000000","0.00000000"],["77476.16000000","0.04884000"],["69823.03000000","0.00272000"]],"a":[["77581.15000000","5.19463000"],["77588.91000000","0.00010000"],["77596.67000000","0.00010000"],["77604.43000000","0.00010000"],["77612.19000000","0.00010000"],["77616.51000000","0.02000000"],["77708.94000000","0.00971000"],["77723.89000000","0.00000000"]]}}
{"type":"depth","received_at_ms":1788331838773,"data":{"e":"depthUpdate","E":1788331838914,"s":"BTCUSDT","U":99555813962,"u":99555813977,"b":[["77524.19000000","0.11163000"],["69823.03000000","0.00272000"],["62064.91000000","0.00000000"]],"a":[["77604.00000000","0.01500000"],["77606.00000000","0.01500000"],["77608.00000000","0.01765000"],["77610.00000000","0.01900000"],["77612.00000000","0.01500000"],["77614.00000000","0.01500000"],["77614.60000000","0.00000000"],["77616.00000000","0.01507000"],["77618.00000000","0.01514000"],["77624.00000000","0.12450000"],["77638.40000000","0.00412000"]]}}
{"type":"depth","received_at_ms":1788331838877,"data":{"e":"depthUpdate","E":1788331839014,"s":"BTCUSDT","U":99555813978,"u":99555813981,"b":[["77524.19000000","0.00000000"],["69823.03000000","0.00272000"],["62064.92000000","0.00032000"]],"a":[]}}
{"type":"trade","received_at_ms":1788331838930,"data":{"e":"trade","E":1788331839068,"s":"BTCUSDT","t":6646633764,"p":"77581.15000000","q":"0.00007000","T":1788331839067,"m":false,"M":true}}
{"type":"depth","received_at_ms":1788331838973,"data":{"e":"depthUpdate","E":1788331839114,"s":"BTCUSDT","U":99555813982,"u":99555813997,"b":[["77543.00000000","0.00000000"],["69823.03000000","0.00304000"],["69823.01000000","0.00000000"]],"a":[["77581.15000000","5.19563000"],["77597.07000000","0.72594000"],["77604.00000000","0.02500000"],["77606.00000000","0.02500000"],["77608.00000000","0.02765000"],["77610.00000000","0.02900000"],["77612.00000000","0.02500000"],["77614.00000000","0.02500000"],["77616.00000000","0.02507000"],["77618.00000000","0.02514000"],["77673.11000000","0.00000000"]]}}
{"type":"depth","received_at_ms":1788331839075,"data":{"e":"depthUpdate","E":1788331839214,"s":"BTCUSDT","U":99555813998,"u":99555814010,"b":[["77541.23000000","0.00000000"],["77527.24000000","0.00015000"],["77524.32000000","0.00000000"],["77524.02000000","0.11163000"],["69823.03000000","0.00304000"],["62064.92000000","0.00000000"]],"a":[["77647.77000000","0.00000000"],["77702.14000000","0.00108000"],["77724.42000000","0.00000000"],["78744.87000000","0.00030000"]]}}
{"type":"depth","received_at_ms":1788331839174,"data":{"e":"depthUpdate","E":1788331839314,"s":"BTCUSDT","U":99555814011,"u":99555814016,"b":[["69823.03000000","0.00304000"],["62064.91000000","0.00000000"]],"a":[["77604.00000000","0.03000000"],["77633.76000000","0.00644000"]]}}
{"type":"depth","received_at_ms":1788331839277,"data":{"e":"depthUpdate","E":1788331839416,"s":"BTCUSDT","U":99555814017,"u":99555814029,"b":[["77581.14000000","0.11292000"],["69823.03000000","0.00320000"]],"a":[["77601.50000000","0.00000000"],["77606.00000000","0.03000000"],["77608.00000000","0.03265000"],["77610.00000000","0.03400000"],["77612.00000000","0.03000000"],["77614.00000000","0.03000000"],["77616.00000000","0.03007000"],["77618.00000000","0.03014000"]]}}
{"type":"depth","received_at_ms":1788331839372,"data":{"e":"depthUpdate","E":1788331839514,"s":"BTCUSDT","U":99555814030,"u":99555814034,"b":[["77524.02000000","0.00000000"],["69823.03000000","0.00336000"],["62064.92000000","0.00032000"]],"a":[]}}
{"type":"depth","received_at_ms":1788331839484,"data":{"e":"depthUpdate","E":1788331839615,"s":"BTCUSDT","U":99555814035,"u":99555814045,"b":[["77531.07000000","0.34840000"],["77524.29000000","0.00000000"],["77505.19000000","0.00007000"],["77499.61000000","0.00007000"],["76417.42000000","0.00030000"],["69823.03000000","0.00336000"],["62065.00000000","0.00200000"],["62064.92000000","0.00000000"]],"a":[]}}
{"type":"depth","received_at_ms":1788331839579,"data":{"e":"depthUpdate","E":1788331839714,"s":"BTCUSDT","U":99555814046,"u":99555814082,"b":[["77581.14000000","0.11299000"],["77580.69000000","0.00021000"],["77579.00000000","0.00000000"],["77576.54000000","1.05336000"],["77575.96000000","0.00326000"],["77574.47000000","0.00000000"],["77574.41000000","0.00329000"],["77572.93000000","1.93226000"],["77572.92000000","0.00000000"],["77561.86000000","0.00007000"],["77549.79000000","0.00000000"],["77524.43000000","0.00000000"],["77524.18000000","0.11292000"],["77511.01000000","0.00412000"],["77479.99000000","0.00000000"],["77457.01000000","0.00032000"],["69823.03000000","0.00352000"],["62065.00000000","0.00000000"]],"a":[["77581.83000000","0.00339000"],["77592.90000000","0.00007000"],["77599.60000000","0.00000000"],["77604.40000000","0.00000000"],["77614.50000000","0.00000000"],["77638.40000000","0.00000000"],["77658.75000000","2.91362000"],["77658.76000000","3.86481000"],["77660.00000000","0.03000000"],["77669.44000000","0.00000000"],["77674.09000000","2.15391000"],["77689.33000000","0.01935000"],["77689.63000000","0.00000000"]]}}
{"type":"depth","received_at_ms":1788331839684,"data":{"e":"depthUpdate","E":1788331839814,"s":"BTCUSDT","U":99555814083,"u":99555814095,"b":[["77524.54000000","0.00000000"],["77524.18000000","0.00000000"],["77498.72000000","0.51079000"],["77487.68000000","0.03997000"],["77476.16000000","0.00000000"],["69823.03000000","0.00352000"],["69823.00000000","0.00000000"]],"a":[["77588.32000000","0.00866000"],["77708.94000000","0.00000000"],["77720.50000000","0.00971000"]]}}
{"type":"depth","received_at_ms":1788331839773,"data":{"e":"depthUpdate","E":1788331839914,"s":"BTCUSDT","U":99555814096,"u":99555814101,"b":[["69823.03000000","0.00368000"],["62064.91000000","0.00000000"]],"a":[["77599.60000000","0.00412000"]]}}
{"type":"depth","received_at_ms":1788331839873,"data":{"e":"depthUpdate","E":1788331840014,"s":"BTCUSDT","U":99555814102,"u":99555814118,"b":[["77580.00000000","0.03049000"],["77579.69000000","0.00014000"],["77579.68000000","0.13861000"],["77577.21000000","0.00000000"],["77576.75000000","0.00000000"],["77576.54000000","1.04047000"],["77574.50000000","0.00000000"],["77524.39000000","0.00000000"],["77418.28000000","0.00055000"],["62065.00000000","0.00000000"],["62064.92000000","0.00032000"]],"a":[]}}
{"type":"depth","received_at_ms":1788331839974,"data":{"e":"depthUpdate","E":1788331840114,"s":"BTCUSDT","U":99555814119,"u":99555814137,"b":[["77581.14000000","0.11306000"],["77581.13000000","0.00125000"],["77580.00000000","0.03049000"],["77579.68000000","0.13875000"],["77577.80000000","0.01315000"],["77576.55000000","0.07775000"],["77575.27000000","0.00000000"],["77574.86000000","0.00000000"],["77574.68000000","0.00000000"],["69823.03000000","0.00384000"]],"a":[["77581.15000000","5.19570000"],["77581.24000000","0.46591000"]]}}
{"type":"depth","received_at_ms":1788331840075,"data":{"e":"depthUpdate","E":1788331840216,"s":"BTCUSDT","U":99555814138,"u":99555814144,"b":[["77538.26000000","0.00000000"],["71389.30000000","0.00015000"],["69823.03000000","0.00384000"],["62064.92000000","0.00000000"]],"a":[["78744.87000000","0.00030000"]]}}
{"type":"depth","received_at_ms":1788331840174,"data":{"e":"depthUpdate","E":1788331840314,"s":"BTCUSDT","U":99555814145,"u":99555814161,"b":[["77576.00000000","0.03014000"],["77570.02000000","0.00427000"],["77565.03000000","0.00600000"],["77525.78000000","0.60582000"],["77525.13000000","0.79723000"],["69823.03000000","0.00400000"],["62065.00000000","0.00000000"],["62064.91000000","0.00000000"]],"a":[["77581.15000000","5.19970000"],["77583.86000000","0.02914000"],["77586.17000000","0.00800000"],["77669.44000000","0.00412000"],["77705.27000000","0.00127000"]]}}
{"type":"depth","received_at_ms":1788331840274,"data":{"e":"depthUpdate","E":1788331840414,"s":"BTCUSDT","U":99555814162,"u":99555814166,"b":[["77565.03000000","0.01000000"],["69823.03000000","0.00400000"]],"a":[["77581.15000000","5.20070000"],["77586.17000000","0.01200000"]]}}
{"type":"trade","received_at_ms":1788331840345,"data":{"e":"trade","E":1788331840485,"s":"BTCUSDT","t":6646633765,"p":"77581.15000000","q":"0.00100000","T":1788331840484,"m":false,"M":true}}
{"type":"depth","received_at_ms":1788331840374,"data":{"e":"depthUpdate","E":1788331840514,"s":"BTCUSDT","U":99555814167,"u":99555814176,"b":[["75557.06000000","0.00000000"],["69823.03000000","0.00425000"],["62065.00000000","0.00000000"],["62064.92000000","0.00032000"]],"a":[["77581.15000000","5.19970000"],["77744.12000000","0.00127000"],["81001.06000000","0.00000000"]]}}
{"type":"depth","received_at_ms":1788331840474,"data":{"e":"depthUpdate","E":1788331840615,"s":"BTCUSDT","U":99555814177,"u":99555814185,"b":[["77524.16000000","0.11306000"],["77496.82000000","0.00007000"],["76417.42000000","0.00030000"],["69823.03000000","0.00425000"],["62064.92000000","0.00000000"]],"a":[["77674.09000000","0.00000000"],["77676.68000000","2.15391000"]]}}
{"type":"depth","received_at_ms":1788331840573,"data":{"e":"depthUpdate","E":1788331840714,"s":"BTCUSDT","U":99555814186,"u":99555814196,"b":[["77565.03000000","0.01400000"],["77561.86000000","0.00000000"],["77524.16000000","0.00000000"],["69823.03000000","0.00441000"],["62065.00000000","0.00000000"]],"a":[["77586.17000000","0.01600000"],["77592.90000000","0.00000000"]]}}
{"type":"depth","received_at_ms":1788331840674,"data":{"e":"depthUpdate","E":1788331840814,"s":"BTCUSDT","U":99555814197,"u":99555814202,"b":[["77561.86000000","0.00007000"],["71389.30000000","0.00000000"],["69823.03000000","0.00457000"]],"a":[["77592.90000000","0.00007000"]]}}
{"type":"depth","received_at_ms":1788331840773,"data":{"e":"depthUpdate","E":1788331840914,"s":"BTCUSDT","U":99555814203,"u":99555814213,"b":[["77581.14000000","0.11290000"],["77522.51000000","0.11306000"],["76400.00000000","4.71477000"],["69823.03000000","0.00425000"],["62064.91000000","0.00000000"]],"a":[["77659.40000000","0.01680000"],["77667.15000000","0.01799000"],["77674.90000000","0.01360000"],["77698.16000000","0.01360000"]]}}
{"type":"depth","received_at_ms":1788331840876,"data":{"e":"depthUpdate","E":1788331841014,"s":"BTCUSDT","U":99555814214,"u":99555814225,"b":[["77581.14000000","0.13297000"],["69823.03000000","0.00457000"],["69823.00000000","0.00020000"],["62084.00000000","0.00000000"],["62078.00000000","0.00200000"],["62064.92000000","0.00032000"]],"a":[]}}
{"type":"depth","received_at_ms":1788331840974,"data":{"e":"depthUpdate","E":1788331841114,"s":"BTCUSDT","U":99555814226,"u":99555814233,"b":[["69823.03000000","0.00441000"],["69823.00000000","0.00000000"]],"a":[["77674.09000000","2.15391000"],["77676.68000000","0.00000000"],["77778.38000000","0.02019000"],["77795.43000000","0.00000000"]]}}
{"type":"depth","received_at_ms":1788331841074,"data":{"e":"depthUpdate","E":1788331841214,"s":"BTCUSDT","U":99555814234,"u":99555814240,"b":[["77581.14000000","0.13282000"],["69823.03000000","0.00457000"],["62064.92000000","0.00000000"]],"a":[["78744.87000000","0.00030000"]]}}
{"type":"depth","received_at_ms":1788331841173,"data":{"e":"depthUpdate","E":1788331841314,"s":"BTCUSDT","U":99555814241,"u":99555814245,"b":[["77581.14000000","0.13308000"],["69823.03000000","0.00441000"],["62064.91000000","0.00000000"]],"a":[]}}
{"type":"depth","received_at_ms":1788331841275,"data":{"e":"depthUpdate","E":1788331841414,"s":"BTCUSDT","U":99555814246,"u":99555814251,"b":[["77568.47000000","0.00000000"],["75557.06000000","0.00010000"],["69823.03000000","0.00457000"]],"a":[["77624.00000000","0.03000000"]]}}
{"type":"depth","received_at_ms":1788331841374,"data":{"e":"depthUpdate","E":1788331841514,"s":"BTCUSDT","U":99555814252,"u":99555814258,"b":[["77581.14000000","0.13290000"],["77568.21000000","0.00257000"],["77479.99000000","0.00412000"],["69823.03000000","0.00441000"],["62064.92000000","0.00032000"]],"a":[]}}
{"type":"trade","received_at_ms":1788331841375,"data":{"e":"trade","E":1788331841515,"s":"BTCUSDT","t":6646633766,"p":"77581.14000000","q":"0.00100000","T":1788331841515,"m":true,"M":true}}
{"type":"depth","received_at_ms":1788331841474,"data":{"e":"depthUpdate","E":1788331841614,"s":"BTCUSDT","U":99555814259,"u":99555814279,"b":[["77581.14000000","0.13205000"],["77568.21000000","0.00000000"],["77568.16000000","0.00257000"],["76417.42000000","0.00030000"],["69823.03000000","0.00448000"],["69823.02000000","0.00009000"],["62065.00000000","0.00000000"],["62064.92000000","0.00000000"]],"a":[["77581.15000000","5.19420000"],["77674.09000000","0.00000000"],["77676.68000000","2.15391000"],["81001.06000000","0.00010000"]]}}
{"type":"depth","received_at_ms":1788331841573,"data":{"e":"depthUpdate","E":1788331841714,"s":"BTCUSDT","U":99555814280,"u":99555814289,"b":[["77581.14000000","0.13206000"],["77568.16000000","0.00000000"],["77567.36000000","0.00257000"],["69823.03000000","0.00432000"]],"a":[["77581.15000000","5.19806000"],["77582.87000000","0.00257000"],["77583.66000000","0.00000000"]]}}
{"type":"depth","received_at_ms":1788331841673,"data":{"e":"depthUpdate","E":1788331841814,"s":"BTCUSDT","U":99555814290,"u":99555814299,"b":[["77561.86000000","0.00007000"],["69823.03000000","0.00432000"]],"a":[["77581.15000000","4.89706000"],["77581.24000000","0.16591000"],["77592.90000000","0.00007000"]]}}
{"type":"depth","received_at_ms":1788331841781,"data":{"e":"depthUpdate","E":1788331841914,"s":"BTCUSDT","U":99555814300,"u":99555814303,"b":[["62064.91000000","0.00000000"]],"a":[["77615.73000000","0.09789000"],["77638.40000000","0.00412000"]]}}
{"type":"depth","received_at_ms":1788331841874,"data":{"e":"depthUpdate","E":1788331842014,"s":"BTCUSDT","U":99555814304,"u":99555814311,"b":[["77581.14000000","0.13190000"],["69823.03000000","0.00432000"],["62064.92000000","0.00032000"]],"a":[["77674.09000000","2.15391000"],["77676.68000000","0.00000000"]]}}
{"type":"depth","received_at_ms":1788331841973,"data":{"e":"depthUpdate","E":1788331842114,"s":"BTCUSDT","U":99555814312,"u":99555814316,"b":[["77581.14000000","0.15182000"],["69823.03000000","0.00448000"]],"a":[]}}
{"type":"depth","received_at_ms":1788331842073,"data":{"e":"depthUpdate","E":1788331842214,"s":"BTCUSDT","U":99555814317,"u":99555814328,"b":[["77530.09000000","1.10166000"],["77530.08000000","1.27757000"],["77529.08000000","0.00000000"],["77500.83000000","0.00000000"],["69823.03000000","0.00432000"],["69823.00000000","0.00000000"],["62064.92000000","0.00000000"]],"a":[["77581.83000000","0.00000000"],["77582.85000000","0.00330000"],["78744.87000000","0.00030000"]]}}
{"type":"depth","received_at_ms":1788331842174,"data":{"e":"depthUpdate","E":1788331842314,"s":"BTCUSDT","U":99555814329,"u":99555814343,"b":[["77581.14000000","0.15208000"],["69823.03000000","0.00448000"],["62065.00000000","0.00000000"],["62064.91000000","0.00000000"]],"a":[["77582.85000000","0.00000000"],["77583.53000000","0.00000000"],["77583.62000000","0.00332000"]]}}
