{"type":"snapshot","received_at_ms":1788407302810,"data":{"lastUpdateId":99603289106,"bids":[["77666.88000000","13.71583000"],["77666.87000000","0.03392000"],["77666.85000000","0.00257000"],["77666.55000000","0.00400000"],["77666.05000000","0.00007000"],["77666.03000000","0.00007000"],["77666.02000000","0.01814000"],["77666.01000000","0.00014000"],["77666.00000000","2.02583000"],["77665.99000000","5.01143000"],["77665.98000000","0.07678000"],["77665.97000000","0.12613000"],["77665.90000000","0.22461000"],["77665.13000000","0.00400000"],["77665.11000000","0.12862000"],["77665.10000000","0.00007000"],["77665.09000000","0.00007000"],["77664.73000000","0.01654000"],["77664.60000000","0.00400000"],["77664.51000000","0.00007000"],["77664.25000000","0.41276000"],["77664.21000000","0.03259000"],["77663.49000000","0.01977000"],["77663.23000000","0.00007000"],["77663.20000000","0.00014000"],["77663.18000000","0.00014000"],["77663.17000000","1.28637000"],["77663.16000000","0.15584000"],["77662.88000000","0.00007000"],["77662.87000000","0.12461000"],["77662.65000000","0.00400000"],["77662.40000000","0.00539000"],["77662.25000000","0.01977000"],["77662.08000000","0.00008000"],["77661.91000000","0.00014000"],["77661.59000000","0.00007000"],["77661.05000000","0.02000000"],["77660.88000000","0.45296000"],["77660.87000000","0.07960000"],["77660.74000000","0.12876000"],["77660.70000000","0.00400000"],["77660.37000000","0.12517000"],["77660.17000000","0.00013000"],["77659.34000000","0.00014000"],["77658.80000000","0.00007000"],["77658.75000000","0.00400000"],["77658.40000000","0.31266000"],["77658.39000000","1.13026000"],["77658.21000000","0.16870000"],["77657.62000000","0.70030000"],["77657.60000000","0.04235000"],["77657.33000000","0.00008000"],["77657.21000000","0.00027000"],["77656.95000000","0.02000000"],["77656.92000000","0.00007000"],["77656.91000000","0.02000000"],["77656.80000000","0.00400000"],["77656.74000000","0.00008000"],["77656.64000000","0.10477000"],["77656.63000000","0.42946000"],["77656.53000000","0.30000000"],["77656.52000000","0.30539000"],["77656.30000000","0.35838000"],["77656.29000000","0.42877000"],["77656.20000000","0.00007000"],["77656.15000000","0.02200000"],["77656.14000000","0.02000000"],["77656.13000000","0.02000000"],["77656.00000000","0.00014000"],["77655.70000000","0.00007000"],["77655.59000000","0.14163000"],["77655.48000000","0.00014000"],["77654.86000000","0.08644000"],["77654.85000000","0.00400000"],["77654.32000000","0.00008000"],["77653.88000000","1.97531000"],["77653.86000000","1.54962000"],["77653.81000000","0.00007000"],["77653.55000000","0.18625000"],["77653.46000000","0.00007000"],["77653.39000000","0.02400000"],["77653.20000000","0.00007000"],["77653.07000000","0.02200000"],["77652.91000000","0.00183000"],["77652.90000000","0.00923000"],["77652.68000000","0.00824000"],["77652.67000000","4.63540000"],["77652.57000000","0.00007000"],["77652.37000000","0.03863000"],["77652.29000000","0.02000000"],["77652.06000000","0.02897000"],["77651.91000000","0.00008000"],["77651.78000000","0.10536000"],["77651.64000000","0.00321000"],["77651.62000000","0.00014000"],["77651.05000000","0.02000000"],["77650.95000000","0.00400000"],["77650.70000000","0.00007000"],["77650.67000000","0.00007000"],["77650.41000000","0.00007000"],["77650.00000000","0.00007000"],["77649.87000000","0.02000000"],["77649.83000000","0.10696000"],["77649.68000000","0.02000000"],["77649.57000000","0.00008000"],["77649.50000000","0.04200000"],["77649.49000000","0.02000000"],["77649.42000000","0.32976000"],["77649.37000000","0.00027000"],["77649.08000000","0.75799000"],["77649.07000000","0.42444000"],["77649.00000000","0.00400000"],["77648.86000000","0.16870000"],["77648.74000000","0.00010000"],["77648.23000000","0.13612000"],["77648.00000000","0.00265000"],["77647.76000000","0.00014000"],["77647.63000000","0.30866000"],["77647.61000000","0.00007000"],["77647.08000000","0.00008000"],["77647.07000000","0.69936000"],["77647.05000000","0.00400000"],["77646.94000000","0.00007000"],["77646.74000000","0.25524000"],["77646.73000000","0.12841000"],["77646.72000000","1.13026000"],["77646.56000000","0.00008000"],["77646.32000000","1.50989000"],["77646.31000000","0.12878000"],["77646.03000000","4.63601000"],["77645.87000000","0.64620000"],["77645.74000000","0.07000000"],["77645.68000000","0.00008000"],["77645.10000000","0.00400000"],["77644.84000000","0.00008000"],["77644.83000000","0.04659000"],["77644.82000000","0.00007000"],["77644.59000000","0.00660000"],["77644.53000000","0.51725000"],["77644.00000000","0.03000000"],["77643.90000000","0.00014000"],["77643.67000000","0.00335000"],["77643.20000000","0.00007000"],["77643.15000000","0.00400000"],["77642.39000000","1.11669000"],["77642.38000000","0.54103000"],["77642.37000000","1.13026000"],["77642.34000000","0.08000000"],["77642.25000000","0.00008000"],["77642.09000000","0.91216000"],["77642.08000000","0.01000000"],["77642.02000000","0.00007000"],["77642.01000000","0.00096000"],["77642.00000000","0.03000000"],["77641.85000000","0.00012000"],["77641.83000000","0.00138000"],["77641.80000000","0.00008000"],["77641.55000000","0.00093000"],["77641.43000000","0.00027000"],["77641.20000000","0.00400000"],["77640.96000000","0.00010000"],["77640.74000000","0.00260000"],["77640.68000000","0.00007000"],["77640.67000000","0.01371000"],["77640.47000000","0.00677000"],["77640.46000000","0.16870000"],["77640.24000000","0.00087000"],["77640.04000000","0.00014000"],["77640.01000000","0.00067000"],["77640.00000000","0.03195000"],["77639.78000000","0.00007000"],["77639.63000000","0.00058000"],["77639.57000000","0.00030000"],["77639.36000000","0.09629000"],["77639.26000000","0.30866000"],["77639.25000000","0.00400000"],["77639.23000000","0.00007000"],["77639.16000000","0.00010000"],["77639.10000000","0.00007000"],["77638.80000000","0.00008000"],["77638.75000000","0.00030000"],["77638.53000000","0.00007000"],["77638.46000000","0.00189000"],["77638.00000000","0.03000000"],["77637.97000000","2.05462000"],["77637.96000000","4.63829000"],["77637.94000000","1.13026000"],["77637.92000000","0.00008000"],["77637.42000000","0.00008000"],["77637.30000000","0.00400000"],["77637.28000000","0.00176000"],["77637.21000000","0.00019000"],["77637.17000000","0.00059000"],["77636.84000000","0.00043000"],["77636.52000000","0.64428000"],["77636.36000000","0.00025000"],["77636.33000000","0.00007000"],["77636.24000000","0.00035000"],["77636.18000000","0.00014000"],["77636.00000000","0.03000000"],["77635.33000000","0.34791000"],["77635.29000000","0.00031000"],["77635.00000000","0.70000000"],["77634.86000000","0.00093000"],["77634.48000000","0.84289000"],["77634.47000000","0.00007000"],["77634.38000000","0.00007000"],["77634.17000000","0.34792000"],["77634.03000000","0.00008000"],["77634.00000000","0.03000000"],["77633.99000000","0.00043000"],["77633.82000000","0.00008000"],["77633.64000000","0.00007000"],["77633.40000000","0.00027000"],["77633.31000000","0.00051000"],["77633.18000000","0.00010000"],["77632.82000000","0.02000000"],["77632.75000000","0.00017000"],["77632.59000000","0.00008000"],["77632.44000000","0.00007000"],["77632.32000000","0.00014000"],["77632.18000000","0.00016000"],["77632.00000000","0.03007000"],["77631.69000000","0.02486000"],["77631.27000000","0.00007000"],["77631.23000000","1.29845000"],["77631.19000000","0.30866000"],["77631.14000000","1.13026000"],["77631.04000000","0.00008000"],["77630.87000000","0.00515000"],["77630.84000000","0.00007000"],["77630.80000000","1.90981000"],["77630.79000000","4.63666000"],["77630.71000000","0.00007000"],["77630.65000000","0.16870000"],["77630.61000000","0.81988000"],["77630.54000000","0.00012000"],["77630.49000000","0.00007000"],["77630.24000000","0.03210000"],["77630.15000000","0.00008000"],["77630.00000000","0.03050000"],["77628.57000000","0.00027000"],["77628.55000000","0.00007000"],["77628.46000000","0.00023000"],["77628.05000000","0.00007000"],["77628.00000000","0.04000000"],["77627.76000000","0.00008000"],["77627.18000000","1.13026000"],["77627.07000000","1.39098000"],["77627.06000000","0.64435000"],["77627.02000000","0.08611000"],["77626.60000000","0.00007000"],["77626.43000000","0.00020000"],["77626.32000000","0.00059000"],["77626.27000000","0.00008000"],["77626.00000000","0.73000000"],["77625.61000000","0.00027000"],["77625.52000000","1.27585000"],["77625.47000000","0.34796000"],["77625.44000000","0.00010000"],["77625.40000000","0.00010000"],["77625.26000000","0.00007000"],["77625.00000000","0.00052000"],["77624.97000000","0.00007000"],["77624.20000000","0.00007000"],["77624.17000000","0.00018000"],["77624.00000000","0.03000000"],["77623.94000000","0.34796000"],["77623.61000000","0.37749000"],["77623.36000000","0.00017000"],["77623.28000000","0.00008000"],["77623.22000000","0.30866000"],["77623.19000000","1.87648000"],["77623.18000000","5.76692000"],["77622.93000000","0.00008000"],["77622.86000000","0.16870000"],["77622.30000000","0.00007000"],["77622.24000000","0.00007000"],["77622.20000000","0.00013000"],["77622.00000000","0.03391000"],["77621.51000000","0.00007000"],["77620.61000000","1.05687000"],["77620.31000000","0.00007000"],["77620.11000000","0.57263000"],["77620.00000000","0.03061000"],["77619.91000000","0.00200000"],["77619.67000000","0.00007000"],["77619.43000000","0.00007000"],["77619.05000000","0.85895000"],["77619.04000000","1.13051000"],["77618.94000000","0.00007000"],["77618.65000000","0.00018000"],["77618.59000000","0.00009000"],["77618.48000000","0.00021000"],["77618.10000000","0.00008000"],["77618.06000000","0.02000000"],["77618.00000000","0.03028000"],["77617.99000000","0.12871000"],["77617.96000000","0.00011000"],["77617.91000000","0.00007000"],["77617.84000000","0.00027000"],["77617.62000000","0.00010000"],["77617.57000000","0.64443000"],["77617.41000000","0.85207000"],["77617.29000000","0.04000000"],["77617.20000000","0.00007000"],["77616.81000000","0.00007000"],["77616.00000000","0.03007000"],["77615.99000000","0.00008000"],["77615.52000000","0.00008000"],["77615.50000000","0.34800000"],["77615.38000000","0.00035000"],["77615.13000000","1.13026000"],["77615.12000000","1.69784000"],["77615.07000000","0.16870000"],["77614.55000000","0.02200000"],["77614.10000000","0.00008000"],["77614.08000000","0.00007000"],["77614.00000000","0.03000000"],["77613.95000000","0.25000000"],["77613.94000000","0.00007000"],["77613.42000000","0.00007000"],["77613.32000000","0.02000000"],["77613.27000000","0.00008000"],["77613.20000000","0.00007000"],["77612.72000000","0.01135000"],["77612.70000000","4.63523000"],["77612.62000000","0.00491000"],["77612.59000000","0.30866000"],["77612.53000000","0.00053000"],["77612.51000000","0.02400000"],["77612.46000000","0.00033000"],["77612.15000000","0.00027000"],["77612.00000000","0.03007000"],["77611.93000000","0.00012000"],["77611.68000000","0.00926000"],["77611.65000000","0.06268000"],["77611.42000000","0.00012000"],["77611.28000000","0.00007000"],["77611.25000000","0.00008000"],["77611.23000000","0.02000000"],["77611.01000000","0.00022000"],["77610.97000000","0.00008000"],["77610.92000000","0.01148000"],["77610.85000000","0.00007000"],["77610.81000000","0.00386000"],["77610.80000000","0.02000000"],["77610.59000000","0.00253000"],["77610.43000000","0.02015000"],["77610.42000000","0.02000000"],["77610.27000000","0.00013000"],["77610.21000000","0.02000000"],["77610.05000000","0.00007000"],["77610.00000000","0.03050000"],["77609.84000000","0.00010000"],["77609.66000000","0.00007000"],["77609.44000000","0.02200000"],["77609.43000000","0.00432000"],["77609.29000000","0.40535000"],["77609.28000000","1.27612000"],["77609.27000000","0.00627000"],["77609.25000000","0.00187000"],["77608.65000000","0.02200000"],["77608.57000000","0.02000000"],["77608.44000000","0.00008000"],["77608.10000000","0.00033000"],["77608.05000000","0.00007000"],["77608.00000000","0.03087000"],["77607.97000000","0.00027000"],["77607.76000000","0.00008000"],["77607.28000000","0.16870000"],["77607.14000000","0.02556000"],["77606.88000000","0.12782000"],["77606.76000000","0.00007000"],["77606.74000000","0.00007000"],["77606.10000000","0.00014000"],["77606.00000000","0.03000000"],["77605.88000000","0.00015000"],["77605.78000000","0.00023000"],["77605.70000000","0.00007000"],["77605.68000000","0.00038000"],["77605.65000000","0.00380000"],["77605.01000000","1.11606000"],["77604.99000000","0.00007000"],["77604.90000000","0.00024000"],["77604.35000000","0.00904000"],["77604.32000000","0.00039000"],["77604.23000000","0.00014000"],["77604.00000000","0.03000000"],["77603.84000000","0.00007000"],["77603.78000000","0.00007000"],["77603.74000000","0.12887000"],["77603.41000000","0.00007000"],["77602.95000000","0.00434000"],["77602.77000000","0.30866000"],["77602.44000000","0.00011000"],["77602.08000000","0.00009000"],["77602.06000000","0.00010000"],["77602.00000000","0.03200000"],["77601.89000000","0.00007000"],["77601.80000000","0.00010000"],["77601.12000000","0.00009000"],["77600.72000000","0.03453000"],["77600.59000000","0.00848000"],["77600.36000000","0.03210000"],["77600.19000000","0.00009000"],["77600.11000000","0.00007000"],["77600.00000000","0.36475000"],["77599.95000000","0.00007000"],["77599.77000000","0.00100000"],["77599.49000000","0.16870000"],["77599.41000000","0.00007000"],["77599.19000000","0.34270000"],["77598.78000000","0.00008000"],["77598.67000000","0.00018000"],["77598.64000000","0.02000000"],["77598.57000000","0.00027000"],["77598.37000000","0.00009000"],["77598.33000000","1.11606000"],["77598.13000000","0.00008000"],["77598.05000000","0.00019000"],["77598.00000000","0.03021000"],["77597.87000000","0.02000000"],["77597.32000000","0.00007000"],["77597.06000000","0.00319000"],["77597.05000000","0.00053000"],["77596.72000000","0.00007000"],["77596.62000000","0.00025000"],["77596.06000000","0.00007000"],["77596.00000000","0.03000000"],["77595.68000000","0.03210000"],["77594.66000000","0.02200000"],["77594.60000000","0.02000000"],["77594.30000000","0.00059000"],["77594.28000000","0.00010000"],["77594.00000000","0.03128000"],["77593.90000000","0.02000000"],["77593.79000000","0.00111000"],["77593.75000000","0.00007000"],["77593.46000000","0.00050000"],["77593.42000000","0.00015000"],["77593.33000000","0.00007000"],["77593.11000000","0.00013000"],["77593.09000000","0.02400000"],["77593.08000000","0.00022000"],["77592.93000000","0.85234000"],["77592.66000000","0.00321000"],["77592.65000000","0.01332000"],["77592.43000000","0.00007000"],["77592.42000000","1.30262000"],["77592.41000000","3.24775000"],["77592.32000000","1.11597000"],["77592.25000000","0.00007000"],["77592.24000000","0.00008000"],["77592.18000000","0.00038000"],["77592.00000000","0.03000000"],["77591.95000000","1.04052000"],["77591.94000000","2.51774000"],["77591.81000000","0.29298000"],["77591.80000000","0.02000000"],["77591.74000000","0.00021000"],["77591.73000000","0.00007000"],["77591.70000000","0.16870000"],["77591.38000000","0.02000000"],["77591.22000000","0.00007000"],["77591.03000000","0.00049000"],["77590.99000000","0.02000000"],["77590.76000000","0.00027000"],["77590.31000000","0.00007000"],["77590.16000000","0.00009000"],["77590.02000000","0.02200000"],["77590.00000000","0.03050000"],["77589.99000000","0.00009000"],["77589.89000000","0.03210000"],["77589.67000000","0.02556000"],["77589.66000000","0.00007000"],["77589.41000000","0.00007000"],["77589.28000000","0.00028000"],["77589.23000000","0.02200000"],["77589.12000000","0.00008000"],["77588.79000000","0.00321000"],["77588.78000000","0.30866000"],["77588.52000000","0.00015000"],["77588.39000000","0.00030000"],["77588.36000000","0.00007000"],["77588.24000000","0.35842000"],["77588.23000000","1.11617000"],["77588.20000000","0.01710000"],["77588.00000000","0.03000000"],["77587.88000000","0.00007000"],["77587.76000000","0.00007000"],["77587.55000000","0.00011000"],["77587.43000000","0.00008000"],["77587.31000000","0.00541000"],["77586.89000000","0.00025000"],["77586.78000000","0.00022000"],["77586.55000000","0.00010000"],["77586.50000000","0.00010000"],["77586.42000000","0.00007000"],["77586.15000000","0.00021000"],["77586.14000000","0.00007000"],["77586.00000000","0.03000000"],["77585.48000000","0.00019000"],["77585.20000000","0.00035000"],["77584.74000000","0.00009000"],["77584.48000000","0.00008000"],["77584.47000000","0.00026000"],["77584.19000000","0.65542000"],["77584.18000000","1.81329000"],["77584.00000000","0.03071000"],["77583.96000000","0.00200000"],["77583.95000000","0.02000000"],["77583.91000000","0.16870000"],["77583.76000000","0.72124000"],["77583.58000000","0.00007000"],["77583.35000000","0.00007000"],["77583.33000000","0.00007000"],["77583.08000000","0.00014000"],["77582.93000000","0.00029000"],["77582.63000000","0.00027000"],["77582.60000000","0.00007000"],["77582.48000000","0.02000000"],["77582.41000000","0.00031000"],["77582.11000000","0.00007000"],["77582.00000000","0.03000000"],["77581.81000000","0.00010000"],["77581.52000000","0.00013000"],["77581.39000000","0.00094000"],["77581.14000000","0.00008000"],["77581.06000000","0.00009000"],["77580.98000000","0.01091000"],["77580.95000000","0.00015000"],["77580.94000000","0.00264000"],["77580.64000000","0.00105000"],["77580.56000000","0.00007000"],["77580.37000000","0.00032000"],["77580.21000000","0.25764000"],["77580.17000000","0.00007000"],["77580.00000000","0.05765000"],["77579.77000000","0.00051000"],["77579.68000000","0.00772000"],["77579.55000000","0.47930000"],["77579.46000000","0.12849000"],["77578.72000000","0.00010000"],["77578.22000000","0.00007000"],["77578.13000000","1.11636000"],["77578.00000000","0.03000000"],["77577.28000000","0.00010000"],["77577.09000000","0.00076000"],["77577.00000000","0.20059000"],["77576.92000000","0.00007000"],["77576.72000000","0.00008000"],["77576.47000000","0.00030000"],["77576.33000000","0.00026000"],["77576.29000000","0.01278000"],["77576.12000000","0.16870000"],["77576.00000000","0.03000000"],["77575.87000000","0.74732000"],["77575.86000000","1.27667000"],["77575.78000000","0.00022000"],["77575.75000000","0.00010000"],["77575.68000000","0.00007000"],["77575.51000000","0.00046000"],["77575.42000000","0.00334000"],["77575.05000000","0.00007000"],["77575.02000000","0.00007000"],["77575.00000000","0.00007000"],["77574.97000000","0.00007000"],["77574.64000000","0.00027000"],["77574.59000000","0.00009000"],["77574.07000000","0.00018000"],["77574.00000000","0.03000000"],["77573.64000000","1.12745000"],["77572.79000000","0.00014000"],["77572.54000000","0.00045000"],["77572.35000000","0.00007000"],["77572.09000000","0.00007000"],["77572.00000000","0.03000000"],["77571.85000000","0.00007000"],["77571.65000000","0.00011000"],["77571.42000000","0.00168000"],["77571.41000000","0.00026000"],["77571.34000000","1.22686000"],["77571.22000000","0.00007000"],["77571.14000000","0.00007000"],["77571.04000000","0.00034000"],["77570.94000000","0.00010000"],["77570.69000000","0.00007000"],["77570.43000000","0.00011000"],["77570.04000000","0.00245000"],["77570.00000000","0.03050000"],["77569.87000000","0.00014000"],["77569.86000000","0.00018000"],["77569.80000000","0.00008000"],["77569.64000000","0.30866000"],["77569.44000000","3.74456000"],["77569.36000000","0.00007000"],["77569.12000000","0.00018000"],["77568.96000000","0.00008000"],["77568.71000000","0.00100000"],["77568.57000000","0.00013000"],["77568.49000000","0.00015000"],["77568.39000000","0.44136000"],["77568.38000000","1.11606000"],["77568.34000000","0.16870000"],["77568.18000000","0.00055000"],["77568.00000000","0.03007000"],["77567.82000000","0.11557000"],["77567.56000000","0.00289000"],["77567.49000000","0.00014000"],["77567.41000000","0.00007000"],["77567.27000000","0.00104000"],["77567.26000000","0.00319000"],["77566.99000000","0.00050000"],["77566.86000000","0.00027000"],["77566.66000000","0.00272000"],["77566.63000000","0.00147000"],["77566.54000000","0.00008000"],["77566.00000000","0.03000000"],["77565.92000000","0.00200000"],["77565.18000000","0.00007000"],["77564.88000000","0.00012000"],["77564.59000000","0.00022000"],["77564.06000000","0.00023000"],["77564.03000000","0.04351000"],["77564.02000000","0.03993000"],["77564.00000000","0.03000000"],["77563.82000000","0.00007000"],["77563.80000000","0.00007000"],["77563.16000000","0.00010000"],["77562.92000000","0.00007000"],["77562.50000000","0.00007000"],["77562.32000000","0.00011000"],["77562.00000000","0.03000000"],["77561.64000000","0.00008000"],["77561.57000000","0.04520000"],["77561.50000000","0.00007000"],["77561.00000000","0.00515000"],["77560.70000000","0.00013000"],["77560.69000000","0.00007000"],["77560.56000000","0.16870000"],["77560.14000000","0.00015000"],["77560.00000000","0.03124000"],["77559.85000000","0.04591000"],["77559.74000000","0.00007000"],["77559.68000000","0.00007000"],["77559.34000000","0.00016000"],["77558.82000000","0.01027000"],["77558.29000000","0.34653000"],["77558.28000000","1.13026000"],["77558.22000000","0.00007000"],["77558.04000000","0.00108000"],["77558.00000000","0.03027000"],["77557.92000000","0.00029000"],["77557.18000000","0.00438000"],["77557.10000000","0.00010000"],["77556.91000000","0.00007000"],["77556.82000000","0.00007000"],["77556.80000000","0.00010000"],["77556.79000000","0.00007000"],["77556.62000000","0.01377000"],["77556.44000000","0.00007000"],["77556.19000000","0.14815000"],["77556.18000000","0.11557000"],["77556.00000000","0.03000000"],["77555.68000000","0.00160000"],["77555.65000000","0.30866000"],["77555.55000000","0.00031000"],["77555.00000000","0.00021000"],["77554.71000000","0.00436000"],["77554.47000000","0.00017000"],["77554.28000000","0.00007000"],["77554.00000000","0.03000000"],["77553.95000000","0.00010000"],["77553.60000000","0.00013000"],["77553.59000000","0.00008000"],["77553.51000000","0.00012000"],["77553.45000000","0.00484000"],["77553.44000000","0.00008000"],["77553.43000000","0.00010000"],["77553.17000000","0.07495000"],["77552.78000000","0.16882000"],["77552.45000000","0.00009000"],["77552.19000000","0.00007000"],["77552.08000000","0.00007000"],["77552.00000000","0.03000000"],["77551.22000000","0.00128000"],["77551.21000000","0.00014000"],["77550.79000000","0.00052000"],["77550.66000000","0.00007000"],["77550.61000000","0.01578000"],["77550.48000000","0.00008000"],["77550.30000000","0.00007000"],["77550.27000000","0.00007000"],["77550.02000000","0.00027000"],["77550.00000000","0.03375000"],["77549.52000000","0.00009000"],["77549.35000000","0.00019000"],["77549.28000000","0.00007000"],["77548.93000000","0.00049000"],["77548.31000000","0.00007000"],["77548.16000000","0.00014000"],["77548.00000000","0.03020000"],["77547.88000000","0.00200000"],["77547.87000000","0.00019000"],["77547.79000000","0.00014000"],["77547.74000000","0.00017000"],["77547.66000000","0.00010000"],["77547.56000000","0.00007000"],["77547.31000000","0.00007000"],["77547.10000000","0.00029000"],["77546.66000000","0.00019000"],["77546.55000000","0.00010000"],["77546.36000000","0.00008000"],["77546.19000000","0.80000000"],["77546.07000000","0.00007000"],["77546.00000000","0.03000000"],["77545.84000000","0.00041000"],["77545.50000000","0.00057000"],["77545.45000000","0.00007000"],["77545.15000000","0.00018000"],["77545.01000000","0.13856000"],["77545.00000000","0.16870000"],["77544.87000000","0.00013000"],["77544.60000000","0.00007000"],["77544.54000000","0.11557000"],["77544.25000000","0.00058000"],["77544.13000000","0.00007000"],["77544.00000000","0.03007000"],["77543.72000000","0.00021000"],["77543.47000000","0.00026000"],["77543.46000000","0.00019000"],["77543.41000000","0.00025000"],["77543.38000000","0.01457000"],["77543.18000000","0.00100000"],["77542.85000000","0.00048000"],["77542.61000000","0.00008000"],["77542.56000000","0.00009000"],["77542.40000000","0.10000000"],["77542.26000000","0.00012000"],["77542.00000000","0.03000000"],["77541.86000000","0.00174000"],["77541.67000000","0.14253000"],["77541.66000000","0.30866000"],["77541.42000000","0.00009000"],["77541.33000000","0.00027000"],["77541.29000000","0.00014000"],["77541.01000000","0.00007000"],["77540.82000000","0.00008000"],["77540.25000000","0.00007000"],["77540.00000000","0.03159000"],["77539.98000000","0.00032000"],["77539.21000000","0.00007000"],["77539.16000000","0.00016000"],["77538.46000000","0.00101000"],["77538.31000000","0.00128000"],["77538.00000000","0.03000000"],["77537.98000000","0.05958000"],["77537.92000000","0.00008000"],["77537.67000000","0.00035000"],["77537.52000000","0.00007000"],["77537.32000000","1.60403000"],["77537.30000000","3.87063000"],["77537.22000000","0.16870000"],["77537.09000000","0.00011000"],["77536.00000000","0.03019000"],["77535.91000000","0.00007000"],["77535.81000000","0.00010000"],["77535.78000000","0.00027000"],["77535.47000000","0.00007000"],["77535.29000000","0.00010000"],["77535.22000000","0.00020000"],["77534.95000000","0.00069000"],["77534.73000000","0.00029000"],["77534.02000000","0.01572000"],["77534.00000000","0.03000000"],["77533.84000000","0.00037000"],["77533.51000000","0.00067000"],["77533.33000000","0.00099000"],["77533.20000000","0.00007000"],["77533.12000000","0.00010000"],["77533.10000000","0.00027000"],["77533.06000000","0.01288000"],["77532.95000000","0.16947000"],["77532.94000000","0.30866000"],["77532.90000000","0.11566000"],["77532.83000000","0.00009000"],["77532.77000000","0.00007000"],["77532.60000000","0.00065000"],["77532.37000000","0.00183000"],["77532.00000000","0.03000000"],["77531.95000000","0.00015000"],["77531.65000000","0.00009000"],["77531.48000000","0.00011000"],["77531.16000000","0.00008000"],["77530.75000000","0.00012000"],["77530.54000000","0.00007000"],["77530.45000000","0.00008000"],["77530.22000000","0.00012000"],["77530.12000000","0.00013000"],["77530.11000000","0.00007000"],["77530.00000000","0.03057000"],["77529.74000000","0.00039000"],["77529.45000000","0.08255000"],["77529.44000000","0.16878000"],["77529.41000000","0.00736000"],["77529.06000000","0.00007000"],["77528.88000000","0.00022000"],["77528.76000000","0.00007000"],["77528.72000000","0.00177000"],["77528.26000000","0.00049000"],["77528.01000000","0.00007000"],["77528.00000000","0.03000000"],["77527.94000000","0.00048000"],["77527.87000000","0.00010000"],["77527.78000000","0.00028000"],["77527.77000000","0.00019000"],["77527.15000000","0.00153000"],["77527.10000000","0.00015000"],["77527.03000000","0.00111000"],["77527.00000000","0.00007000"],["77526.88000000","0.00007000"],["77526.53000000","0.00010000"],["77526.38000000","0.00017000"],["77526.31000000","0.00007000"],["77526.14000000","0.00007000"],["77526.06000000","0.00016000"],["77526.00000000","0.03000000"],["77525.77000000","0.00010000"],["77525.76000000","0.00007000"],["77525.68000000","0.00456000"],["77525.33000000","0.00008000"],["77525.31000000","0.00009000"],["77525.13000000","0.00027000"],["77525.09000000","0.00007000"],["77525.03000000","0.00016000"],["77525.00000000","0.00059000"],["77524.96000000","0.00007000"],["77524.24000000","0.00035000"],["77524.18000000","0.00057000"],["77524.00000000","0.03000000"],["77523.77000000","0.00021000"],["77523.67000000","0.00017000"],["77523.58000000","0.00256000"],["77522.75000000","1.54374000"],["77522.66000000","0.00081000"],["77522.43000000","0.00007000"],["77522.00000000","0.03000000"],["77521.66000000","0.16870000"],["77521.50000000","0.00008000"],["77521.27000000","0.11557000"],["77521.15000000","0.00378000"],["77520.49000000","0.00099000"],["77520.42000000","0.00007000"],["77520.36000000","0.00121000"],["77520.13000000","0.00128000"],["77520.12000000","0.00038000"],["77520.00000000","0.03295000"],["77519.91000000","0.02017000"],["77519.75000000","0.00178000"],["77519.64000000","0.00038000"],["77519.43000000","0.00008000"],["77519.38000000","0.00020000"],["77519.28000000","0.00007000"],["77519.23000000","0.00046000"],["77519.18000000","0.00037000"],["77519.09000000","0.00007000"],["77518.97000000","0.05113000"],["77518.95000000","0.30866000"],["77518.75000000","0.00013000"],["77518.37000000","0.00007000"],["77518.18000000","0.00091000"],["77518.00000000","0.03011000"],["77517.94000000","3.87159000"],["77517.57000000","0.00025000"],["77517.22000000","0.00010000"],["77517.12000000","0.00181000"],["77516.74000000","0.00045000"],["77516.63000000","0.00027000"],["77516.35000000","0.00007000"],["77516.23000000","0.00007000"],["77516.00000000","0.03000000"],["77515.93000000","0.00041000"],["77515.78000000","0.00007000"],["77515.29000000","0.00012000"],["77515.07000000","0.00144000"],["77515.00000000","0.00008000"],["77514.59000000","0.00042000"],["77514.50000000","0.00043000"],["77514.37000000","0.00007000"],["77514.28000000","0.00007000"],["77514.26000000","0.00007000"],["77514.00000000","0.03000000"],["77513.89000000","0.16870000"],["77513.52000000","0.00010000"],["77513.33000000","0.00016000"],["77513.24000000","0.00064000"],["77512.78000000","0.02087000"],["77512.67000000","0.00011000"],["77512.08000000","0.00022000"],["77512.04000000","0.00007000"],["77512.00000000","0.03000000"],["77511.84000000","0.00008000"],["77511.61000000","0.00010000"],["77511.38000000","0.00007000"],["77511.20000000","0.00035000"],["77511.11000000","0.00007000"],["77510.89000000","0.00011000"],["77510.64000000","0.00128000"],["77510.63000000","0.00023000"],["77510.56000000","0.00017000"],["77510.23000000","0.00007000"],["77510.09000000","0.00284000"],["77510.00000000","0.03050000"],["77509.82000000","0.00012000"],["77509.77000000","0.00008000"],["77509.64000000","0.11565000"],["77509.37000000","0.00007000"],["77509.29000000","0.00007000"],["77509.01000000","0.00007000"],["77508.82000000","0.00027000"],["77508.77000000","0.00010000"],["77508.55000000","0.00010000"],["77508.12000000","0.00008000"],["77508.03000000","0.00024000"],["77508.01000000","0.00128000"],["77508.00000000","0.03000000"],["77507.99000000","0.00032000"],["77507.72000000","0.00011000"],["77507.46000000","0.00016000"],["77507.36000000","0.00025000"],["77507.23000000","0.00007000"],["77507.18000000","0.00102000"],["77507.17000000","0.00085000"],["77506.89000000","0.00020000"],["77506.88000000","0.00008000"],["77506.87000000","0.00017000"],["77506.12000000","0.16908000"],["77506.00000000","0.03000000"],["77505.88000000","0.00012000"],["77505.34000000","0.00011000"],["77505.17000000","0.00039000"],["77504.98000000","0.00007000"],["77504.96000000","0.30866000"],["77504.91000000","0.00022000"],["77504.66000000","0.00007000"],["77504.42000000","0.00008000"],["77504.12000000","0.00024000"],["77504.09000000","2.62014000"],["77504.00000000","0.03007000"],["77503.89000000","0.00007000"],["77503.86000000","0.00220000"],["77503.09000000","0.00008000"],["77503.06000000","0.04000000"],["77503.00000000","0.03733000"],["77502.62000000","0.00007000"],["77502.05000000","0.00008000"],["77502.00000000","0.03000000"],["77501.75000000","0.00118000"],["77501.44000000","0.00054000"],["77501.06000000","0.00086000"],["77500.75000000","0.00009000"],["77500.65000000","0.00135000"],["77500.64000000","0.00381000"],["77500.49000000","0.00035000"],["77500.32000000","0.00011000"],["77500.06000000","0.00007000"],["77500.01000000","0.00008000"],["77500.00000000","0.47691000"],["77499.97000000","0.00010000"],["77499.86000000","0.00007000"],["77499.70000000","0.00163000"],["77499.31000000","0.00027000"],["77498.85000000","0.00029000"],["77498.69000000","0.00007000"],["77498.56000000","0.00248000"],["77498.36000000","0.00050000"],["77498.35000000","0.16870000"],["77498.28000000","0.00237000"],["77498.01000000","0.11557000"],["77497.93000000","0.00007000"],["77497.77000000","0.00008000"],["77497.58000000","0.00007000"],["77497.50000000","0.00672000"],["77497.47000000","0.00044000"],["77496.77000000","0.00007000"],["77496.65000000","0.00008000"],["77496.58000000","0.00100000"],["77496.55000000","0.00013000"],["77496.51000000","0.00191000"],["77495.69000000","0.00013000"],["77495.57000000","0.00023000"],["77495.29000000","0.00011000"],["77495.25000000","0.00022000"],["77494.81000000","0.00007000"],["77494.70000000","0.00007000"],["77494.57000000","0.00024000"],["77494.41000000","0.00034000"],["77494.39000000","0.00387000"],["77494.34000000","0.00806000"]],"asks":[["77666.89000000","0.21315000"],["77666.90000000","0.00063000"],["77667.06000000","0.00007000"],["77667.16000000","0.00014000"],["77667.41000000","0.00007000"],["77667.97000000","0.00321000"],["77667.99000000","0.00014000"],["77668.00000000","0.03035000"],["77668.28000000","0.00014000"],["77668.29000000","0.09966000"],["77668.36000000","0.00007000"],["77668.81000000","0.00014000"],["77668.82000000","0.10037000"],["77669.32000000","0.00007000"],["77669.53000000","0.00014000"],["77669.54000000","0.32221000"],["77669.87000000","0.00577000"],["77669.97000000","0.00007000"],["77669.99000000","0.00007000"],["77670.00000000","0.03021000"],["77670.53000000","0.00664000"],["77670.54000000","0.10254000"],["77670.68000000","0.00007000"],["77670.91000000","0.00631000"],["77670.92000000","0.00007000"],["77671.09000000","0.09952000"],["77671.12000000","0.00927000"],["77671.23000000","0.00008000"],["77671.55000000","0.09184000"],["77671.59000000","0.03180000"],["77671.82000000","0.00013000"],["77672.00000000","0.03007000"],["77672.09000000","0.00010000"],["77672.36000000","0.01112000"],["77672.47000000","0.00007000"],["77672.77000000","0.00007000"],["77672.91000000","0.10000000"],["77672.94000000","0.00008000"],["77673.52000000","0.00208000"],["77673.60000000","0.01112000"],["77673.79000000","0.19208000"],["77673.84000000","0.09989000"],["77674.00000000","0.03000000"],["77674.07000000","0.00200000"],["77674.38000000","0.00832000"],["77674.48000000","0.00007000"],["77674.72000000","0.00070000"],["77674.78000000","0.00014000"],["77674.87000000","0.00048000"],["77675.06000000","0.00048000"],["77675.29000000","0.09952000"],["77675.30000000","0.00047000"],["77675.35000000","0.10023000"],["77675.56000000","0.00007000"],["77675.58000000","0.00007000"],["77675.65000000","0.00027000"],["77675.91000000","0.00008000"],["77676.00000000","0.03000000"],["77676.06000000","0.00008000"],["77676.73000000","0.00525000"],["77676.76000000","0.10023000"],["77677.07000000","0.10023000"],["77677.08000000","0.30866000"],["77677.10000000","0.00400000"],["77677.33000000","0.00007000"],["77677.60000000","0.00008000"],["77677.76000000","0.00668000"],["77678.00000000","0.03000000"],["77678.13000000","0.00007000"],["77678.14000000","0.66214000"],["77678.25000000","0.00400000"],["77678.31000000","0.16870000"],["77678.36000000","0.00007000"],["77678.63000000","0.12873000"],["77678.64000000","0.00014000"],["77678.69000000","0.00007000"],["77678.70000000","0.00008000"],["77678.74000000","0.00400000"],["77679.30000000","0.02896000"],["77679.31000000","0.00538000"],["77679.58000000","0.10023000"],["77679.87000000","0.00010000"],["77680.00000000","0.03007000"],["77680.20000000","0.00400000"],["77680.24000000","0.15000000"],["77680.34000000","0.00007000"],["77680.61000000","0.02200000"],["77680.62000000","0.02000000"],["77680.80000000","0.00400000"],["77680.89000000","0.00008000"],["77680.92000000","0.00007000"],["77680.99000000","0.10023000"],["77681.06000000","0.00007000"],["77681.15000000","0.00007000"],["77681.37000000","0.10023000"],["77681.38000000","0.01800000"],["77681.40000000","1.14660000"],["77681.43000000","0.02000000"],["77682.00000000","0.03000000"],["77682.07000000","0.02400000"],["77682.15000000","0.00400000"],["77682.23000000","2.32216000"],["77682.37000000","0.00257000"],["77682.49000000","0.02600000"],["77682.50000000","0.00014000"],["77682.59000000","0.00008000"],["77682.76000000","0.02000000"],["77683.20000000","0.00533000"],["77683.22000000","4.63523000"],["77683.37000000","0.00007000"],["77683.49000000","0.00027000"],["77683.64000000","0.00007000"],["77683.76000000","0.02000000"],["77683.95000000","0.00007000"],["77684.00000000","0.03000000"],["77684.10000000","0.00400000"],["77684.14000000","0.00643000"],["77684.39000000","0.12872000"],["77684.43000000","0.00100000"],["77684.49000000","0.02000000"],["77684.80000000","0.02000000"],["77684.88000000","0.02000000"],["77685.31000000","0.04000000"],["77685.32000000","3.33676000"],["77685.36000000","1.49294000"],["77685.37000000","0.02000000"],["77685.39000000","0.02000000"],["77685.46000000","0.00157000"],["77685.53000000","0.00655000"],["77685.72000000","0.00008000"],["77686.00000000","0.03000000"],["77686.05000000","0.00400000"],["77686.14000000","0.00007000"],["77686.30000000","0.00007000"],["77686.36000000","0.00014000"],["77686.47000000","0.00008000"],["77686.75000000","0.00007000"],["77686.95000000","0.00012000"],["77687.09000000","0.00525000"],["77687.25000000","0.00128000"],["77687.65000000","0.00010000"],["77687.96000000","0.30866000"],["77687.98000000","4.63496000"],["77688.00000000","0.03607000"],["77688.01000000","0.01184000"],["77688.37000000","0.00007000"],["77689.21000000","0.00128000"],["77689.35000000","0.00059000"],["77689.54000000","0.66324000"],["77689.55000000","1.11250000"],["77689.95000000","0.00400000"],["77690.00000000","0.03000000"],["77690.22000000","0.00014000"],["77690.35000000","0.00008000"],["77690.55000000","0.00008000"],["77690.76000000","0.00189000"],["77691.14000000","0.33824000"],["77691.15000000","0.38629000"],["77691.29000000","0.00027000"],["77691.80000000","0.00643000"],["77691.90000000","0.00400000"],["77692.00000000","0.03200000"],["77692.01000000","0.00007000"],["77692.15000000","0.17669000"],["77692.34000000","0.00007000"],["77692.40000000","0.12871000"],["77693.11000000","0.00013000"],["77693.12000000","0.00008000"],["77693.30000000","0.00647000"],["77693.39000000","1.02321000"],["77693.40000000","0.52276000"],["77693.53000000","0.50513000"],["77693.85000000","0.00400000"],["77694.00000000","0.03000000"],["77694.08000000","0.00014000"],["77694.10000000","0.03210000"],["77694.13000000","0.00012000"],["77694.24000000","0.00008000"],["77694.78000000","0.64401000"],["77694.85000000","0.64379000"],["77695.14000000","0.00007000"],["77695.31000000","0.00007000"],["77695.38000000","0.00008000"],["77695.43000000","0.00010000"],["77695.80000000","0.00400000"],["77695.99000000","0.25759000"],["77696.00000000","0.73265000"],["77696.35000000","1.42116000"],["77696.59000000","0.00057000"],["77696.90000000","0.07214000"],["77697.29000000","1.47837000"],["77697.30000000","4.63666000"],["77697.53000000","0.01278000"],["77697.71000000","0.00007000"],["77697.75000000","0.00400000"],["77697.94000000","0.00021000"],["77698.00000000","0.03000000"],["77698.12000000","0.00008000"],["77698.24000000","0.00101000"],["77698.87000000","0.00370000"],["77699.70000000","0.00407000"],["77699.77000000","0.02200000"],["77699.96000000","0.00027000"],["77700.00000000","0.21777000"],["77700.21000000","0.00008000"],["77700.26000000","0.00100000"],["77700.68000000","0.34762000"],["77700.73000000","0.00007000"],["77700.88000000","0.00008000"],["77700.98000000","0.02000000"],["77701.01000000","0.00078000"],["77701.07000000","0.00671000"],["77701.65000000","0.00400000"],["77701.71000000","0.00007000"],["77701.80000000","0.00014000"],["77701.84000000","0.04532000"],["77702.00000000","0.03008000"],["77702.36000000","0.97307000"],["77702.37000000","1.19201000"],["77702.82000000","0.64373000"],["77702.89000000","0.34761000"],["77703.13000000","0.02000000"],["77703.21000000","0.00010000"],["77703.23000000","0.00010000"],["77703.53000000","0.00007000"],["77703.55000000","0.16870000"],["77703.60000000","0.00400000"],["77703.65000000","0.02000000"],["77703.74000000","0.00007000"],["77704.00000000","0.03000000"],["77704.27000000","0.81910000"],["77704.51000000","0.01278000"],["77704.73000000","0.00165000"],["77705.04000000","0.00008000"],["77705.19000000","0.32977000"],["77705.55000000","0.00400000"],["77705.61000000","0.00224000"],["77705.66000000","0.00014000"],["77705.71000000","0.00007000"],["77706.00000000","0.04000000"],["77706.28000000","0.37104000"],["77706.33000000","0.00007000"],["77706.50000000","1.49426000"],["77706.62000000","4.63666000"],["77707.37000000","1.29718000"],["77707.50000000","0.00400000"],["77707.68000000","0.00618000"],["77707.71000000","0.00007000"],["77708.00000000","0.03000000"],["77708.27000000","0.11557000"],["77708.36000000","0.00431000"],["77708.40000000","0.10000000"],["77708.61000000","0.00432000"],["77708.64000000","0.00008000"],["77708.69000000","0.00838000"],["77708.88000000","0.08173000"],["77709.10000000","0.75368000"],["77709.11000000","0.30866000"],["77709.12000000","0.00007000"],["77709.16000000","1.19201000"],["77709.52000000","0.00007000"],["77709.59000000","0.34758000"],["77709.61000000","0.00434000"],["77709.64000000","0.85106000"],["77709.87000000","0.00008000"],["77710.00000000","0.03200000"],["77710.01000000","0.00007000"],["77710.99000000","0.00010000"],["77711.65000000","0.01133000"],["77711.92000000","0.00007000"],["77712.00000000","0.03007000"],["77712.12000000","0.00007000"],["77712.13000000","0.00007000"],["77712.43000000","0.02000000"],["77712.92000000","0.03863000"],["77713.24000000","0.02000000"],["77713.26000000","0.02000000"],["77713.27000000","0.02000000"],["77713.36000000","0.57068000"],["77714.00000000","0.03000000"],["77714.43000000","0.00007000"],["77714.66000000","0.00027000"],["77714.70000000","0.00008000"],["77714.72000000","0.00007000"],["77714.74000000","1.27439000"],["77715.18000000","2.00936000"],["77715.19000000","4.63666000"],["77715.29000000","0.34755000"],["77715.54000000","0.00007000"],["77715.69000000","1.19201000"],["77715.76000000","0.02000000"],["77716.00000000","0.03000000"],["77716.40000000","0.00008000"],["77716.49000000","0.02400000"],["77716.99000000","0.02600000"],["77717.29000000","0.14782000"],["77717.31000000","0.02000000"],["77717.32000000","0.02000000"],["77717.41000000","0.00007000"],["77717.46000000","0.95563000"],["77717.47000000","1.01634000"],["77717.52000000","0.00007000"],["77718.00000000","0.03000000"],["77718.31000000","0.34754000"],["77718.39000000","1.27433000"],["77718.77000000","0.00010000"],["77719.19000000","0.02200000"],["77719.35000000","0.00007000"],["77719.73000000","0.00320000"],["77719.74000000","0.00043000"],["77719.91000000","0.30866000"],["77720.00000000","0.03000000"],["77720.13000000","0.16870000"],["77720.31000000","0.00007000"],["77720.40000000","0.02000000"],["77720.78000000","0.42485000"],["77720.80000000","0.03210000"],["77720.93000000","0.25000000"],["77721.93000000","0.00007000"],["77721.99000000","0.00320000"],["77722.00000000","0.03000000"],["77722.05000000","0.00007000"],["77722.34000000","0.01278000"],["77722.40000000","1.19201000"],["77722.78000000","0.00027000"],["77723.07000000","0.02000000"],["77723.11000000","0.00007000"],["77724.00000000","0.03000000"],["77724.16000000","0.00008000"],["77724.21000000","1.59627000"],["77724.22000000","4.63666000"],["77724.33000000","0.06379000"],["77724.36000000","0.00008000"],["77724.48000000","0.00672000"],["77725.91000000","0.00007000"],["77725.93000000","0.00007000"],["77726.00000000","0.03000000"],["77726.55000000","0.00010000"],["77726.93000000","0.00535000"],["77727.65000000","0.00007000"],["77728.00000000","0.03007000"],["77728.01000000","0.58139000"],["77728.05000000","0.01703000"],["77728.19000000","0.52118000"],["77728.71000000","0.00007000"],["77728.90000000","1.19201000"],["77729.52000000","0.41262000"],["77729.60000000","0.00386000"],["77730.00000000","0.03000000"],["77730.30000000","0.00163000"],["77730.56000000","0.00027000"],["77730.67000000","0.85083000"],["77730.99000000","0.00007000"],["77731.08000000","0.00007000"],["77731.36000000","0.00007000"],["77731.57000000","0.00112000"],["77731.63000000","0.00007000"],["77731.74000000","0.03210000"],["77731.85000000","0.02000000"],["77731.92000000","0.00008000"],["77732.00000000","0.03000000"],["77732.66000000","0.02000000"],["77732.68000000","0.02000000"],["77732.69000000","0.02000000"],["77732.77000000","1.27409000"],["77732.78000000","1.85643000"],["77732.79000000","4.63664000"],["77732.81000000","1.19201000"],["77732.99000000","0.02000000"],["77733.86000000","0.30866000"],["77733.94000000","0.00007000"],["77734.00000000","0.03000000"],["77734.02000000","0.00008000"],["77734.31000000","0.00007000"],["77734.33000000","0.00010000"],["77734.62000000","0.05149000"],["77734.85000000","0.01135000"],["77735.18000000","0.02000000"],["77735.91000000","0.02400000"],["77736.00000000","0.03137000"],["77736.41000000","0.02600000"],["77736.58000000","1.27403000"],["77736.72000000","0.02000000"],["77736.73000000","0.02000000"],["77736.75000000","0.02000000"],["77737.07000000","1.12953000"],["77737.08000000","1.13039000"],["77737.10000000","0.00007000"],["77737.37000000","0.00386000"],["77737.66000000","2.45020000"],["77737.77000000","0.00007000"],["77737.80000000","0.16870000"],["77737.81000000","0.00020000"],["77738.00000000","0.03000000"],["77738.06000000","0.00007000"],["77739.06000000","0.00027000"],["77739.68000000","0.00008000"],["77739.72000000","0.00007000"],["77740.00000000","0.03000000"],["77741.29000000","2.99961000"],["77741.30000000","4.63658000"],["77741.32000000","3.77496000"],["77741.71000000","0.00007000"],["77742.00000000","0.03000000"],["77742.06000000","0.00007000"],["77742.11000000","0.00010000"],["77742.12000000","0.00010000"],["77742.23000000","0.25762000"],["77742.28000000","0.00100000"],["77742.58000000","0.00128000"],["77742.70000000","0.00007000"],["77742.77000000","0.00008000"],["77742.91000000","1.19201000"],["77743.18000000","0.00007000"],["77743.55000000","0.41262000"],["77743.68000000","0.00008000"],["77743.73000000","0.00007000"],["77744.00000000","0.03000000"],["77744.38000000","1.18580000"],["77745.48000000","0.00280000"],["77745.50000000","0.00007000"],["77745.71000000","0.00007000"],["77745.93000000","0.80000000"],["77746.00000000","0.03000000"],["77746.21000000","3.24132000"],["77746.36000000","0.00200000"],["77746.62000000","0.00007000"],["77746.84000000","0.00027000"],["77747.11000000","0.00311000"],["77747.44000000","0.00008000"],["77747.71000000","0.00007000"],["77747.83000000","1.48983000"],["77747.84000000","0.30866000"],["77748.00000000","0.03000000"],["77748.10000000","0.00515000"],["77748.30000000","0.00007000"],["77748.72000000","0.03210000"],["77749.71000000","0.00007000"],["77749.89000000","0.00010000"],["77750.00000000","0.03015000"],["77750.62000000","4.63601000"],["77751.10000000","0.00007000"],["77751.71000000","0.00007000"],["77752.00000000","0.03000000"],["77752.21000000","0.00007000"],["77752.31000000","0.08857000"],["77752.32000000","0.06500000"],["77753.34000000","0.00008000"],["77753.71000000","0.00007000"],["77753.73000000","0.03210000"],["77754.00000000","0.03000000"],["77755.10000000","0.00027000"],["77755.13000000","0.00042000"],["77755.14000000","0.16870000"],["77755.20000000","0.00008000"],["77755.67000000","0.00007000"],["77755.73000000","0.11170000"],["77756.00000000","0.03000000"],["77756.19000000","0.30866000"],["77756.70000000","0.00007000"],["77757.54000000","0.00514000"],["77757.67000000","0.00010000"],["77757.71000000","0.00007000"],["77757.96000000","0.04625000"],["77758.00000000","0.03000000"],["77758.56000000","0.01278000"],["77758.71000000","0.00007000"],["77759.50000000","0.00007000"],["77759.66000000","1.51539000"],["77759.77000000","0.00007000"],["77759.94000000","4.63601000"],["77760.00000000","0.03014000"],["77760.54000000","0.00007000"],["77762.00000000","0.03000000"],["77762.06000000","0.03210000"],["77762.14000000","0.00007000"],["77762.16000000","0.00007000"],["77762.30000000","0.00025000"],["77762.79000000","0.41262000"],["77763.00000000","0.00008000"],["77763.22000000","0.00027000"],["77763.32000000","1.18836000"],["77763.33000000","3.85938000"],["77763.83000000","0.00089000"],["77764.00000000","0.03000000"],["77764.20000000","0.01320000"],["77764.83000000","0.00007000"],["77765.45000000","0.00010000"],["77765.55000000","0.00007000"],["77766.00000000","0.03000000"],["77766.99000000","1.58540000"],["77767.00000000","0.30866000"],["77767.02000000","0.00007000"],["77768.00000000","0.03000000"],["77768.25000000","0.41262000"],["77769.26000000","4.63540000"],["77769.75000000","0.00007000"],["77770.00000000","0.03000000"],["77770.69000000","0.00007000"],["77770.72000000","0.00008000"],["77770.77000000","0.00007000"],["77771.29000000","0.00027000"],["77771.99000000","0.01846000"],["77772.00000000","0.03000000"],["77772.45000000","0.00012000"],["77772.66000000","0.00130000"],["77773.23000000","0.00010000"],["77773.36000000","0.00007000"],["77773.49000000","0.00007000"],["77774.00000000","0.03000000"],["77774.24000000","0.00007000"],["77775.10000000","0.11974000"],["77775.11000000","0.30866000"],["77775.56000000","0.04562000"],["77776.00000000","0.03000000"],["77776.16000000","0.03210000"],["77776.38000000","0.00108000"],["77776.57000000","0.00019000"],["77776.72000000","0.00007000"],["77777.70000000","0.00007000"],["77778.00000000","0.03000000"],["77778.93000000","0.00007000"],["77779.79000000","0.00027000"],["77779.85000000","0.01568000"],["77780.00000000","0.03000000"],["77780.35000000","0.06874000"],["77780.36000000","0.16870000"],["77780.63000000","0.00032000"],["77780.68000000","0.00007000"],["77781.00000000","0.01568000"],["77781.01000000","0.00020000"],["77781.12000000","0.00007000"],["77781.18000000","0.01421000"],["77782.00000000","0.03000000"],["77782.01000000","0.00128000"],["77782.32000000","0.00008000"],["77782.57000000","0.03463000"],["77782.58000000","0.03210000"],["77783.69000000","0.00007000"],["77784.00000000","0.03000000"],["77784.28000000","0.01615000"],["77784.72000000","0.00100000"],["77786.00000000","0.03000000"],["77786.01000000","0.00643000"],["77786.24000000","0.00008000"],["77787.47000000","0.00007000"],["77787.59000000","0.00007000"],["77788.00000000","0.03200000"],["77788.06000000","0.00027000"],["77788.46000000","0.00136000"],["77788.79000000","0.00010000"],["77788.96000000","0.05933000"],["77788.97000000","0.16870000"],["77789.77000000","0.00007000"],["77790.00000000","0.03000000"],["77790.23000000","0.00007000"],["77790.25000000","0.30866000"],["77790.29000000","0.00007000"],["77791.98000000","0.00008000"],["77791.99000000","0.40920000"],["77792.00000000","0.03007000"],["77792.09000000","0.00400000"],["77792.46000000","0.00007000"],["77793.23000000","0.03210000"],["77793.80000000","0.00023000"],["77793.89000000","1.27310000"],["77794.00000000","0.03000000"],["77794.41000000","0.00007000"],["77795.89000000","0.00007000"],["77796.00000000","0.03000000"],["77796.48000000","0.00027000"],["77796.57000000","0.00010000"],["77796.94000000","0.00007000"],["77797.06000000","0.00128000"],["77797.07000000","0.00971000"],["77798.00000000","0.03000000"],["77798.07000000","0.15857000"],["77798.08000000","0.30866000"],["77799.08000000","0.00007000"],["77799.15000000","0.00007000"],["77800.00000000","0.06362000"],["77800.29000000","0.16870000"],["77801.64000000","0.00008000"],["77801.76000000","0.00008000"],["77801.95000000","0.00007000"],["77804.28000000","0.00128000"],["77804.29000000","0.00027000"],["77804.30000000","0.00007000"],["77804.35000000","0.00010000"],["77805.30000000","0.00007000"],["77805.58000000","0.05818000"],["77805.72000000","0.14253000"],["77805.83000000","0.00007000"],["77807.27000000","0.01567000"],["77807.98000000","0.00007000"],["77808.16000000","0.16870000"],["77808.33000000","0.30866000"],["77809.90000000","0.00007000"],["77809.91000000","0.00007000"],["77810.00000000","0.00011000"],["77810.08000000","0.00007000"],["77811.30000000","0.00008000"],["77811.35000000","0.03210000"],["77811.54000000","0.00122000"],["77812.16000000","0.00007000"],["77813.10000000","0.00027000"],["77813.31000000","0.00889000"],["77814.60000000","0.00007000"],["77815.20000000","0.00385000"],["77816.63000000","0.03210000"],["77816.80000000","0.00007000"],["77817.28000000","0.00008000"],["77817.86000000","0.30866000"],["77817.89000000","1.54374000"],["77818.30000000","0.00007000"],["77818.65000000","0.02000000"],["77819.30000000","0.00007000"],["77819.90000000","0.00010000"],["77820.01000000","0.16877000"],["77820.42000000","0.00039000"],["77820.43000000","0.00008000"],["77820.51000000","0.00109000"],["77820.83000000","0.00007000"],["77820.88000000","0.00128000"],["77821.68000000","0.00027000"],["77822.98000000","0.00385000"],["77823.29000000","0.00007000"],["77823.52000000","0.00179000"],["77823.80000000","0.00100000"],["77823.91000000","0.00007000"],["77824.00000000","0.00007000"],["77824.52000000","0.03210000"],["77824.97000000","0.00256000"],["77825.39000000","0.00007000"],["77825.88000000","4.46398000"],["77826.59000000","0.00010000"],["77827.19000000","0.30866000"],["77827.51000000","0.00007000"],["77827.58000000","0.00514000"],["77827.79000000","0.16870000"],["77828.28000000","0.00169000"],["77829.49000000","0.00007000"],["77829.50000000","0.00027000"],["77829.64000000","3.85613000"],["77830.29000000","1.24162000"],["77831.60000000","0.00007000"],["77831.80000000","0.00010000"],["77832.80000000","0.00008000"],["77833.02000000","0.00140000"],["77833.10000000","0.00010000"],["77833.33000000","0.01613000"],["77833.54000000","0.00007000"],["77835.49000000","0.00007000"],["77836.36000000","0.00007000"],["77837.06000000","3.85572000"],["77837.16000000","0.00007000"],["77837.34000000","0.00027000"],["77837.53000000","0.00131000"],["77837.76000000","0.00007000"],["77838.24000000","0.00011000"],["77838.30000000","0.00228000"],["77838.58000000","0.00007000"],["77838.60000000","0.00385000"],["77838.70000000","0.00400000"],["77839.00000000","0.00020000"],["77839.57000000","0.00102000"],["77840.00000000","0.00057000"],["77840.28000000","0.00008000"],["77840.33000000","0.00010000"],["77840.53000000","0.03210000"],["77840.72000000","0.00007000"],["77840.83000000","0.00007000"],["77840.90000000","0.00014000"],["77841.19000000","0.30866000"],["77843.17000000","0.16870000"],["77843.24000000","0.00007000"],["77843.66000000","0.00181000"],["77844.77000000","0.03210000"],["77845.10000000","0.05605000"],["77845.18000000","0.00027000"],["77845.29000000","0.00007000"],["77845.42000000","0.02017000"],["77846.62000000","0.03221000"],["77847.55000000","0.00007000"],["77848.32000000","0.00008000"],["77848.88000000","0.00022000"],["77849.05000000","0.00007000"],["77849.12000000","0.00007000"],["77849.50000000","3.85511000"],["77850.00000000","0.31413000"],["77850.26000000","0.00007000"],["77850.98000000","0.00013000"],["77851.06000000","0.00023000"],["77851.78000000","0.16870000"],["77851.89000000","0.00007000"],["77852.21000000","0.00007000"],["77852.30000000","0.00007000"],["77852.94000000","0.00078000"],["77854.02000000","0.00027000"],["77854.73000000","0.00007000"],["77854.91000000","0.00100000"],["77855.17000000","0.30866000"],["77855.80000000","0.00026000"],["77855.93000000","0.00097000"],["77856.00000000","0.00014000"],["77857.14000000","0.00014000"],["77857.15000000","0.03210000"],["77857.92000000","0.00007000"],["77857.96000000","0.00007000"],["77858.79000000","0.00010000"],["77859.18000000","0.00011000"],["77859.56000000","0.00128000"],["77859.57000000","0.16870000"],["77860.00000000","0.00066000"],["77860.30000000","0.00011000"],["77860.48000000","0.00007000"],["77861.56000000","0.00190000"],["77862.28000000","0.00027000"],["77862.93000000","0.00007000"],["77863.84000000","0.00008000"],["77864.16000000","0.00047000"],["77864.66000000","0.02395000"],["77865.13000000","0.00008000"],["77865.49000000","0.00007000"],["77865.71000000","0.00011000"],["77866.13000000","0.00017000"],["77866.66000000","0.00007000"],["77866.81000000","0.00007000"],["77867.36000000","0.16870000"],["77867.42000000","0.00007000"],["77869.26000000","0.00008000"],["77870.00000000","0.00050000"],["77870.16000000","0.00027000"],["77871.53000000","0.03210000"],["77872.58000000","0.00007000"],["77873.42000000","0.11561000"],["77874.25000000","0.02017000"],["77875.00000000","0.00026000"],["77875.99000000","0.16870000"],["77876.00000000","0.00391000"],["77876.10000000","0.00008000"],["77876.37000000","0.00007000"],["77876.72000000","0.00013000"],["77879.29000000","0.01278000"],["77879.36000000","0.00008000"],["77879.67000000","0.00007000"],["77879.79000000","0.00045000"],["77880.00000000","0.00136000"],["77880.49000000","0.00514000"],["77880.98000000","2.44590000"],["77882.35000000","0.00287000"],["77882.69000000","0.00007000"],["77882.95000000","0.00007000"],["77883.38000000","0.00263000"],["77884.01000000","0.00027000"],["77884.83000000","0.03210000"],["77885.04000000","0.00575000"],["77885.11000000","0.00011000"],["77885.31000000","0.00290000"],["77885.64000000","0.00016000"],["77885.71000000","0.00007000"],["77886.00000000","0.01000000"],["77886.36000000","0.00055000"],["77886.57000000","0.00010000"],["77886.75000000","0.00007000"],["77887.79000000","0.16870000"],["77887.95000000","0.00042000"],["77888.00000000","4.76847000"],["77888.19000000","0.00007000"],["77888.88000000","0.00008000"],["77888.90000000","3.44811000"],["77888.99000000","2.58567000"],["77889.50000000","0.01084000"],["77889.55000000","0.00007000"],["77890.00000000","0.28400000"],["77890.05000000","3.85310000"],["77890.41000000","0.00008000"],["77891.29000000","0.00010000"],["77891.30000000","0.00026000"],["77891.53000000","0.00008000"],["77891.56000000","0.00013000"],["77891.77000000","0.00044000"],["77891.89000000","0.00159000"],["77892.09000000","0.00027000"],["77892.52000000","0.00289000"],["77893.00000000","0.00257000"],["77893.78000000","0.01911000"],["77893.84000000","0.00007000"],["77894.11000000","0.00018000"],["77894.40000000","0.00334000"],["77894.52000000","0.03210000"],["77894.88000000","0.00008000"],["77895.79000000","0.16870000"],["77896.37000000","0.00019000"],["77896.54000000","0.00007000"],["77896.93000000","0.00007000"],["77897.31000000","0.00147000"],["77897.58000000","0.00010000"],["77897.68000000","0.00010000"],["77897.69000000","0.00513000"],["77898.10000000","0.00008000"],["77898.14000000","0.00009000"],["77898.18000000","0.00007000"],["77898.24000000","0.00008000"],["77898.33000000","0.00035000"],["77898.34000000","0.00402000"],["77898.45000000","0.00128000"],["77898.48000000","0.00007000"],["77898.95000000","0.00007000"],["77899.00000000","0.00854000"],["77899.65000000","0.00011000"],["77899.72000000","0.00012000"],["77899.80000000","0.00062000"],["77899.95000000","0.00012000"],["77900.00000000","8.16402000"],["77900.17000000","0.00034000"],["77900.56000000","0.00009000"],["77900.58000000","0.02577000"],["77900.60000000","0.00017000"],["77900.86000000","0.01409000"],["77900.87000000","0.00008000"],["77900.89000000","0.00385000"],["77900.93000000","0.00007000"],["77900.97000000","0.00007000"],["77901.06000000","0.00351000"],["77901.09000000","0.00007000"],["77901.54000000","0.00007000"],["77901.76000000","0.00015000"],["77901.94000000","0.00039000"],["77902.11000000","0.00027000"],["77902.46000000","0.00030000"],["77902.47000000","0.00020000"],["77902.73000000","0.00082000"],["77902.84000000","0.00053000"],["77903.15000000","0.00048000"],["77903.22000000","0.00199000"],["77903.30000000","0.00007000"],["77903.52000000","0.00281000"],["77903.63000000","0.00131000"],["77903.91000000","0.00032000"],["77904.15000000","0.00118000"],["77904.19000000","0.00048000"],["77904.22000000","0.00557000"],["77904.26000000","0.00010000"],["77904.33000000","0.00013000"],["77904.45000000","0.00037000"],["77904.64000000","0.00064000"],["77904.73000000","0.00263000"],["77904.76000000","0.00007000"],["77905.00000000","0.00007000"],["77905.13000000","0.00023000"],["77905.15000000","0.00007000"],["77905.17000000","0.00007000"],["77905.27000000","0.00049000"],["77905.40000000","0.00380000"],["77905.52000000","0.00222000"],["77905.59000000","0.00641000"],["77905.65000000","0.00578000"],["77906.12000000","0.00007000"],["77906.37000000","0.00059000"],["77906.53000000","0.00009000"],["77906.63000000","0.00007000"],["77906.68000000","0.00024000"],["77907.09000000","0.00020000"],["77907.27000000","0.00007000"],["77907.40000000","0.00008000"],["77907.50000000","0.00016000"],["77907.65000000","0.00023000"],["77907.79000000","0.16870000"],["77907.90000000","0.00018000"],["77908.01000000","0.00021000"],["77908.02000000","0.00007000"],["77908.07000000","0.00007000"],["77908.28000000","0.00053000"],["77908.33000000","0.00010000"],["77908.61000000","0.00007000"],["77908.66000000","0.00064000"],["77908.68000000","0.00385000"],["77908.97000000","0.11615000"],["77909.09000000","0.00168000"],["77909.35000000","0.02786000"],["77909.52000000","0.00007000"],["77910.00000000","0.01457000"],["77910.06000000","0.00027000"],["77910.17000000","0.00012000"],["77910.26000000","0.00018000"],["77910.40000000","0.00008000"],["77910.71000000","0.00028000"],["77910.74000000","0.00011000"],["77910.96000000","0.00008000"],["77911.00000000","0.00940000"],["77911.01000000","0.00019000"],["77911.57000000","0.00055000"],["77911.61000000","0.00010000"],["77911.74000000","0.00012000"],["77911.76000000","0.00069000"],["77911.82000000","0.00018000"],["77912.00000000","0.00034000"],["77912.58000000","0.00010000"],["77912.59000000","0.00515000"],["77913.03000000","0.00030000"],["77913.35000000","0.00015000"],["77913.41000000","0.00035000"],["77913.88000000","0.00366000"],["77913.99000000","0.00010000"],["77914.10000000","0.00007000"],["77914.18000000","0.00030000"],["77914.28000000","0.00276000"],["77914.35000000","0.00016000"],["77914.59000000","0.00009000"],["77914.70000000","0.00032000"],["77914.80000000","0.00028000"],["77914.81000000","0.00026000"],["77914.91000000","0.00023000"],["77914.98000000","0.00007000"],["77914.99000000","0.00253000"],["77915.05000000","0.00007000"],["77915.11000000","0.00007000"],["77915.32000000","0.00020000"],["77915.52000000","0.00013000"],["77915.84000000","0.01926000"],["77915.91000000","0.11464000"],["77916.00000000","0.00076000"],["77916.02000000","0.00028000"],["77916.07000000","0.00021000"],["77916.28000000","0.00026000"],["77916.30000000","0.00008000"],["77916.36000000","0.00008000"],["77916.39000000","0.00011000"],["77916.45000000","0.01294000"],["77916.47000000","0.00017000"],["77916.57000000","0.00012000"],["77916.65000000","0.00014000"],["77916.66000000","0.00652000"],["77917.01000000","0.16908000"],["77917.05000000","0.00077000"],["77917.41000000","0.00027000"],["77917.70000000","0.00010000"],["77917.85000000","0.00027000"],["77918.17000000","0.01919000"],["77918.20000000","0.00081000"],["77918.38000000","0.00049000"],["77919.29000000","0.00008000"],["77919.39000000","0.00055000"],["77919.62000000","0.07720000"],["77919.69000000","0.00022000"],["77919.72000000","0.00008000"],["77920.00000000","0.53273000"],["77920.09000000","0.00010000"],["77920.23000000","0.00020000"],["77920.24000000","0.00075000"],["77920.44000000","0.00012000"],["77920.86000000","0.00024000"],["77920.97000000","0.00056000"],["77921.06000000","0.00648000"],["77921.18000000","0.00011000"],["77921.27000000","0.00007000"],["77921.60000000","0.00265000"],["77921.70000000","0.00019000"],["77921.80000000","0.00035000"],["77921.84000000","0.00008000"],["77922.20000000","0.00007000"],["77922.36000000","0.00200000"],["77922.40000000","0.00062000"],["77922.73000000","0.00008000"],["77922.79000000","0.00024000"],["77922.81000000","0.00010000"],["77922.98000000","0.00023000"],["77923.03000000","0.00026000"],["77923.07000000","0.00136000"],["77923.37000000","0.00039000"],["77923.40000000","0.00046000"],["77923.41000000","0.00007000"],["77923.96000000","0.00018000"],["77924.12000000","0.03210000"],["77924.18000000","0.00042000"],["77924.41000000","0.00012000"],["77924.78000000","0.16870000"],["77925.00000000","0.00337000"],["77925.04000000","0.00013000"],["77925.12000000","0.00021000"],["77925.25000000","0.00101000"],["77925.37000000","0.00007000"],["77925.43000000","0.00007000"],["77925.60000000","0.00007000"],["77925.62000000","0.00025000"],["77925.92000000","0.00008000"],["77925.95000000","0.04228000"],["77926.08000000","0.00014000"],["77926.20000000","0.00007000"],["77926.28000000","0.00014000"],["77926.39000000","0.00009000"],["77926.75000000","0.00092000"],["77926.96000000","0.00108000"],["77927.15000000","0.00010000"],["77927.22000000","0.00008000"],["77927.26000000","0.00007000"],["77927.30000000","0.00007000"],["77927.62000000","0.00027000"],["77927.90000000","0.00007000"]]}}
{"type":"depth","received_at_ms":1788407302810,"data":{"e":"depthUpdate","E":1788407303014,"s":"BTCUSDT","U":99603289107,"u":99603289123,"b":[["77666.88000000","13.71848000"],["77666.85000000","0.00000000"],["77659.65000000","0.02000000"],["76501.87000000","0.00030000"],["69900.20000000","0.00233000"],["62133.51000000","0.00032000"]],"a":[["77666.89000000","0.21329000"],["77667.16000000","0.00000000"],["77682.37000000","0.00000000"],["77724.27000000","0.00000000"],["78831.90000000","0.00030000"]]}}
{"type":"depth","received_at_ms":1788407302911,"data":{"e":"depthUpdate","E":1788407303114,"s":"BTCUSDT","U":99603289124,"u":99603289139,"b":[["77652.57000000","0.00007000"],["77591.80000000","0.00000000"],["69900.20000000","0.00224000"],["69900.19000000","0.00009000"],["62133.50000000","0.00000000"],["62133.00000000","0.01809000"]],"a":[["77666.89000000","0.20948000"],["77683.64000000","0.00007000"],["77762.30000000","0.00000000"],["77763.19000000","0.00025000"]]}}
{"type":"depth","received_at_ms":1788407303112,"data":{"e":"depthUpdate","E":1788407303214,"s":"BTCUSDT","U":99603289140,"u":99603289150,"b":[["77659.23000000","0.02000000"],["77652.91000000","0.00192000"],["77649.68000000","0.00000000"],["69900.20000000","0.00240000"],["62133.51000000","0.00000000"],["62133.00000000","0.01609000"]],"a":[["77669.14000000","0.00007000"],["77769.89000000","2.60723000"],["77895.29000000","0.01287000"]]}}
{"type":"depth","received_at_ms":1788407303112,"data":{"e":"depthUpdate","E":1788407303314,"s":"BTCUSDT","U":99603289151,"u":99603289156,"b":[["77658.84000000","0.02000000"],["77649.87000000","0.00000000"],["77591.38000000","0.00000000"],["69900.20000000","0.00224000"],["62134.00000000","0.00000000"]],"a":[]}}
{"type":"depth","received_at_ms":1788407303260,"data":{"e":"depthUpdate","E":1788407303414,"s":"BTCUSDT","U":99603289157,"u":99603289803,"b":[["77669.86000000","14.62258000"],["77669.54000000","0.07514000"],["77669.53000000","6.21870000"],["77669.52000000","0.00000000"],["77669.31000000","0.00000000"],["77669.13000000","0.00000000"],["77668.81000000","0.00000000"],["77668.80000000","0.00000000"],["77668.50000000","0.00400000"],["77668.48000000","0.30873000"],["77668.28000000","0.00000000"],["77668.12000000","0.00000000"],["77667.99000000","0.00000000"],["77667.98000000","0.00000000"],["77667.96000000","0.00000000"],["77667.40000000","0.00000000"],["77667.15000000","0.00000000"],["77667.06000000","0.00014000"],["77667.05000000","0.00000000"],["77666.89000000","0.08320000"],["77666.88000000","0.55084000"],["77666.87000000","0.00021000"],["77666.85000000","0.03259000"],["77666.03000000","0.00000000"],["77666.01000000","0.00000000"],["77666.00000000","0.07514000"],["77665.99000000","0.26942000"],["77665.90000000","0.19034000"],["77665.79000000","0.00027000"],["77665.13000000","0.00000000"],["77665.11000000","0.12848000"],["77664.39000000","0.00007000"],["77664.26000000","0.59045000"],["77664.25000000","0.41269000"],["77664.21000000","0.00000000"],["77664.00000000","0.00007000"],["77663.71000000","0.00013000"],["77663.18000000","0.00000000"],["77663.17000000","1.21137000"],["77662.73000000","0.02400000"],["77661.76000000","0.00008000"],["77660.88000000","1.89171000"],["77660.87000000","0.00007000"],["77660.39000000","0.02000000"],["77660.37000000","0.02534000"],["77660.17000000","0.00000000"],["77660.16000000","0.00007000"],["77660.03000000","0.00007000"],["77659.24000000","0.08643000"],["77659.04000000","4.63518000"],["77658.85000000","0.02200000"],["77658.84000000","0.04000000"],["77657.60000000","0.00000000"],["77657.33000000","0.00000000"],["77656.29000000","0.12877000"],["77655.70000000","0.00000000"],["77654.86000000","0.00000000"],["77654.00000000","0.00008000"],["77652.68000000","0.00000000"],["77650.70000000","0.00000000"],["77650.11000000","0.00008000"],["77649.84000000","0.00200000"],["77649.57000000","0.00000000"],["77649.50000000","0.02200000"],["77646.23000000","0.00008000"],["77645.87000000","0.64420000"],["77645.68000000","0.00000000"],["77642.35000000","0.00008000"],["77641.80000000","0.00000000"],["77640.00000000","0.03188000"],["77638.46000000","0.00197000"],["77637.92000000","0.00000000"],["77637.30000000","0.00000000"],["77634.58000000","0.00008000"],["77634.03000000","0.00000000"],["77630.70000000","0.00008000"],["77630.15000000","0.00000000"],["77628.46000000","0.00009000"],["77626.27000000","0.00000000"],["77615.12000000","0.00000000"],["77613.95000000","0.00000000"],["77612.71000000","0.00000000"],["77612.70000000","0.00000000"],["77606.89000000","0.39362000"],["77604.01000000","0.00321000"],["77600.59000000","0.00000000"],["77598.53000000","3.81873000"],["77597.06000000","0.00000000"],["77590.99000000","0.00000000"],["77582.60000000","0.00000000"],["77569.44000000","0.00000000"],["77560.57000000","0.08605000"],["77558.29000000","0.00000000"],["77558.28000000","0.00000000"],["77463.93000000","0.00000000"],["76501.87000000","0.00000000"],["69900.20000000","0.00000000"],["69900.19000000","0.00000000"]],"a":[["77666.89000000","0.00000000"],["77666.90000000","0.00000000"],["77667.06000000","0.00000000"],["77667.41000000","0.00000000"],["77667.97000000","0.00000000"],["77667.99000000","0.00000000"],["77668.00000000","0.00000000"],["77668.28000000","0.00000000"],["77668.29000000","0.00000000"],["77668.36000000","0.00000000"],["77668.81000000","0.00000000"],["77668.82000000","0.00000000"],["77669.14000000","0.00000000"],["77669.32000000","0.00000000"],["77669.53000000","0.00000000"],["77669.54000000","0.00000000"],["77669.55000000","0.00000000"],["77669.87000000","0.02821000"],["77669.88000000","0.00063000"],["77669.97000000","0.00000000"],["77669.99000000","0.00014000"],["77670.29000000","0.00000000"],["77670.53000000","0.00678000"],["77670.54000000","0.10275000"],["77670.91000000","0.00021000"],["77671.09000000","0.00014000"],["77671.12000000","0.00948000"],["77671.55000000","0.00014000"],["77671.58000000","0.00000000"],["77671.59000000","0.00021000"],["77671.82000000","0.00000000"],["77671.99000000","0.00014000"],["77672.00000000","0.03000000"],["77672.28000000","0.00014000"],["77672.29000000","0.00000000"],["77672.47000000","0.00000000"],["77672.77000000","0.00000000"],["77672.90000000","0.00000000"],["77672.91000000","0.00000000"],["77672.94000000","0.00000000"],["77673.52000000","0.00000000"],["77673.79000000","0.00000000"],["77673.84000000","0.00000000"],["77673.99000000","0.00007000"],["77674.38000000","0.00000000"],["77674.51000000","0.03179000"],["77674.72000000","0.00000000"],["77674.78000000","0.00007000"],["77674.91000000","0.00615000"],["77675.29000000","0.00000000"],["77675.35000000","0.00000000"],["77675.36000000","0.00013000"],["77675.51000000","0.10022000"],["77675.63000000","0.00000000"],["77676.20000000","0.00321000"],["77676.73000000","0.00000000"],["77677.01000000","0.00000000"],["77677.07000000","0.00000000"],["77677.08000000","0.00000000"],["77677.10000000","0.00000000"],["77677.31000000","0.00008000"],["77677.36000000","0.00810000"],["77677.76000000","0.00000000"],["77678.13000000","0.10029000"],["77678.31000000","0.00675000"],["77678.70000000","0.00000000"],["77678.74000000","0.00000000"],["77679.31000000","0.00000000"],["77679.39000000","0.00400000"],["77679.68000000","0.00535000"],["77680.80000000","0.00000000"],["77681.36000000","0.00400000"],["77681.37000000","0.10022000"],["77681.80000000","0.00007000"],["77682.03000000","0.00400000"],["77682.23000000","1.25190000"],["77682.59000000","0.00000000"],["77682.76000000","0.00000000"],["77683.22000000","0.00000000"],["77684.14000000","0.00000000"],["77684.39000000","0.00000000"],["77684.59000000","0.02000000"],["77685.07000000","0.00008000"],["77685.08000000","0.16870000"],["77686.47000000","0.00000000"],["77686.94000000","0.00643000"],["77687.25000000","0.00000000"],["77688.96000000","0.00008000"],["77690.35000000","0.00000000"],["77691.96000000","0.00128000"],["77692.84000000","0.00008000"],["77694.24000000","0.00000000"],["77694.85000000","0.00000000"],["77696.72000000","0.00008000"],["77698.12000000","0.00000000"],["77699.34000000","0.20000000"],["77700.61000000","0.00008000"],["77700.68000000","0.00000000"],["77702.00000000","0.03000000"],["77704.49000000","0.00008000"],["77706.00000000","0.03000000"],["77707.32000000","0.64369000"],["77708.37000000","0.00008000"],["77708.69000000","0.00000000"],["77709.00000000","0.01000000"],["77709.08000000","0.00000000"],["77709.15000000","0.00000000"],["77709.41000000","0.00000000"],["77709.49000000","0.00832000"],["77713.38000000","0.00007000"],["77719.73000000","0.00000000"],["77720.07000000","0.34753000"],["77720.93000000","0.00000000"],["77721.99000000","0.00000000"],["77726.92000000","0.00319000"],["77727.99000000","0.00320000"],["77744.00000000","0.03007000"],["77763.83000000","0.00000000"],["77769.89000000","0.00000000"],["77778.59000000","4.63518000"],["78183.00000000","0.00000000"],["78831.90000000","0.00000000"]]}}
{"type":"depth","received_at_ms":1788407303322,"data":{"e":"depthUpdate","E":1788407303514,"s":"BTCUSDT","U":99603289804,"u":99603290020,"b":[["77669.86000000","14.63704000"],["77669.85000000","0.00014000"],["77669.55000000","0.00400000"],["77669.54000000","0.07514000"],["77669.53000000","6.22406000"],["77669.50000000","0.00000000"],["77668.48000000","0.00021000"],["77666.89000000","0.08334000"],["77666.88000000","0.54924000"],["77666.87000000","0.00007000"],["77666.85000000","0.03266000"],["77666.02000000","0.00014000"],["77665.99000000","0.26928000"],["77665.98000000","0.07664000"],["77665.97000000","0.11611000"],["77665.79000000","0.00000000"],["77665.11000000","0.12855000"],["77665.02000000","0.00000000"],["77664.73000000","0.00007000"],["77664.40000000","0.00800000"],["77664.27000000","0.00000000"],["77664.25000000","0.41269000"],["77663.49000000","0.00000000"],["77663.18000000","0.01000000"],["77662.87000000","0.12454000"],["77662.40000000","0.00532000"],["77662.25000000","0.00000000"],["77660.87000000","0.00000000"],["77656.00000000","0.00272000"],["77655.60000000","0.29199000"],["77655.45000000","0.10536000"],["77653.51000000","0.10696000"],["77651.78000000","0.00000000"],["77651.05000000","0.00000000"],["77649.84000000","0.00000000"],["77649.83000000","0.00000000"],["77649.50000000","0.00000000"],["77649.49000000","0.00000000"],["77649.07000000","0.41911000"],["77647.54000000","0.00200000"],["77646.74000000","0.00000000"],["77640.47000000","0.00000000"],["77635.91000000","0.00840000"],["77631.00000000","0.01000000"],["77630.00000000","0.03050000"],["77628.00000000","0.03000000"],["77620.81000000","0.00618000"],["77617.91000000","0.25007000"],["77609.27000000","0.00000000"],["77607.88000000","0.85218000"],["77592.93000000","0.00000000"],["77571.34000000","0.00000000"],["77564.03000000","0.00000000"],["77564.02000000","0.00000000"],["77469.62000000","0.00000000"],["69902.88000000","0.00032000"],["62135.89000000","0.00032000"],["40864.30000000","0.00037000"]],"a":[["77669.87000000","0.02244000"],["77669.88000000","0.00070000"],["77670.54000000","0.10275000"],["77670.68000000","0.00000000"],["77670.91000000","0.00007000"],["77671.09000000","0.00000000"],["77671.12000000","0.00021000"],["77671.55000000","0.00000000"],["77671.59000000","0.00007000"],["77672.00000000","0.03014000"],["77672.23000000","0.00007000"],["77672.28000000","0.00000000"],["77672.36000000","0.00014000"],["77673.60000000","0.00014000"],["77673.99000000","0.00014000"],["77674.00000000","0.03014000"],["77674.09000000","0.00007000"],["77674.10000000","0.10022000"],["77674.50000000","0.00007000"],["77674.78000000","0.00007000"],["77678.25000000","0.00000000"],["77678.31000000","0.00000000"],["77678.82000000","0.00674000"],["77679.39000000","0.00000000"],["77679.68000000","0.00000000"],["77679.73000000","0.00000000"],["77679.97000000","0.00069000"],["77679.99000000","0.00527000"],["77680.20000000","0.00000000"],["77680.24000000","0.03000000"],["77682.03000000","0.00000000"],["77684.24000000","0.12000000"],["77685.46000000","0.00000000"],["77688.33000000","0.12871000"],["77691.14000000","0.00000000"],["77691.24000000","0.10531000"],["77693.18000000","0.10690000"],["77693.99000000","0.28231000"],["77705.19000000","0.00000000"],["77705.61000000","0.00000000"],["77709.45000000","0.00400000"],["77709.49000000","0.00000000"],["77709.64000000","0.00000000"],["77709.65000000","0.00000000"],["77709.72000000","0.00000000"],["77710.03000000","0.00000000"],["77712.92000000","0.00000000"],["77713.35000000","0.00400000"],["77713.38000000","0.00007000"],["77713.62000000","0.00224000"],["77724.89000000","0.25000000"],["77797.07000000","0.00000000"],["77825.88000000","0.00000000"],["77874.25000000","0.00000000"],["77879.49000000","0.02017000"]]}}
{"type":"depth","received_at_ms":1788407303411,"data":{"e":"depthUpdate","E":1788407303614,"s":"BTCUSDT","U":99603290021,"u":99603290112,"b":[["77669.86000000","14.70026000"],["77669.55000000","0.00414000"],["77669.54000000","0.07542000"],["77669.53000000","5.75536000"],["77668.61000000","0.01684000"],["77668.48000000","0.00007000"],["77667.71000000","0.02896000"],["77667.37000000","0.02021000"],["77666.89000000","0.08348000"],["77666.88000000","0.49966000"],["77666.87000000","0.00000000"],["77666.85000000","0.03280000"],["77666.13000000","0.02021000"],["77666.02000000","0.00000000"],["77665.99000000","0.26942000"],["77653.39000000","0.00000000"],["77652.06000000","0.00000000"],["77614.71000000","0.00429000"],["77602.95000000","0.00000000"],["77574.94000000","0.03992000"],["62136.00000000","0.00015000"],["62135.89000000","0.00000000"]],"a":[["77669.87000000","0.20605000"],["77669.88000000","0.00077000"],["77670.54000000","0.10275000"],["77671.12000000","0.00007000"],["77672.00000000","0.03014000"],["77672.23000000","0.12116000"],["77672.36000000","0.00000000"],["77672.69000000","0.10022000"],["77673.60000000","0.00000000"],["77674.00000000","0.03014000"],["77674.09000000","0.00541000"],["77674.10000000","0.10036000"],["77674.48000000","0.00000000"],["77674.51000000","0.03193000"],["77674.91000000","0.00629000"],["77675.34000000","0.00890000"],["77676.58000000","0.01068000"],["77676.94000000","0.32197000"],["77677.82000000","0.01068000"],["77681.21000000","0.00400000"],["77684.79000000","0.00400000"],["77693.31000000","0.00157000"],["77707.68000000","0.00000000"],["77708.36000000","0.00000000"],["77708.61000000","0.00000000"],["77711.69000000","0.32973000"],["77716.70000000","0.00624000"],["77717.34000000","0.03863000"],["77717.55000000","0.00431000"],["77717.95000000","0.00427000"],["77808.02000000","0.00971000"]]}}
{"type":"depth","received_at_ms":1788407303511,"data":{"e":"depthUpdate","E":1788407303714,"s":"BTCUSDT","U":99603290113,"u":99603290199,"b":[["77669.86000000","14.73245000"],["77669.53000000","5.75536000"],["77668.61000000","0.01698000"],["77667.71000000","0.02910000"],["77667.37000000","0.02035000"],["77666.85000000","0.03266000"],["77666.00000000","0.07500000"],["77665.99000000","0.26928000"],["77665.07000000","0.00027000"],["77661.91000000","0.00007000"],["77653.55000000","0.00000000"],["77495.80000000","4.42427000"],["77464.81000000","0.00812000"],["77454.89000000","0.00306000"],["69902.88000000","0.00064000"]],"a":[["77669.87000000","0.20619000"],["77669.88000000","0.00091000"],["77669.99000000","0.01203000"],["77671.16000000","0.00014000"],["77671.17000000","0.12517000"],["77672.00000000","0.03014000"],["77672.22000000","0.00000000"],["77672.23000000","0.00021000"],["77672.68000000","0.00007000"],["77672.69000000","0.10036000"],["77673.99000000","0.00007000"],["77674.00000000","0.03014000"],["77674.09000000","0.00548000"],["77674.10000000","0.10022000"],["77674.50000000","0.00000000"],["77674.51000000","0.03179000"],["77674.78000000","0.00014000"],["77674.91000000","0.00615000"],["77675.34000000","0.01098000"],["77675.61000000","0.09989000"],["77681.36000000","0.00600000"],["77681.38000000","0.00000000"],["77683.40000000","0.00400000"],["77684.79000000","0.00000000"],["77685.07000000","0.09862000"],["77685.30000000","0.01600000"],["77710.45000000","0.00849000"],["77713.38000000","0.00000000"],["77776.57000000","0.00000000"],["77853.85000000","4.39757000"],["77869.68000000","0.00007000"],["77873.56000000","0.00000000"]]}}
{"type":"depth","received_at_ms":1788407303611,"data":{"e":"depthUpdate","E":1788407303814,"s":"BTCUSDT","U":99603290200,"u":99603290244,"b":[["77669.86000000","14.72945000"],["77668.37000000","0.00007000"],["77667.71000000","0.02917000"],["77666.05000000","0.00000000"],["77664.51000000","0.00000000"],["77537.44000000","0.00012000"],["77530.75000000","0.00000000"],["69902.88000000","0.00080000"],["69902.87000000","0.00009000"]],"a":[["77669.87000000","0.20783000"],["77669.88000000","0.00098000"],["77669.99000000","0.01217000"],["77670.54000000","0.10275000"],["77671.17000000","0.12531000"],["77672.00000000","0.03014000"],["77672.23000000","0.00007000"],["77674.09000000","0.00534000"],["77674.90000000","0.20695000"],["77681.36000000","0.00400000"],["77685.06000000","0.00200000"],["77772.45000000","0.00000000"],["77779.16000000","0.00012000"],["77780.63000000","0.00000000"]]}}
{"type":"depth","received_at_ms":1788407303711,"data":{"e":"depthUpdate","E":1788407303915,"s":"BTCUSDT","U":99603290245,"u":99603290251,"b":[["77646.00000000","0.00500000"],["77639.78000000","0.00000000"],["69902.88000000","0.00112000"]],"a":[["77669.87000000","0.20633000"],["77783.28000000","0.00019000"],["77787.34000000","0.00032000"]]}}
{"type":"depth","received_at_ms":1788407303812,"data":{"e":"depthUpdate","E":1788407304014,"s":"BTCUSDT","U":99603290252,"u":99603290266,"b":[["77669.86000000","14.69734000"],["77591.80000000","0.02000000"],["76504.81000000","0.00030000"],["62135.89000000","0.00032000"]],"a":[["77669.87000000","0.20548000"],["77678.82000000","0.00000000"],["77678.87000000","0.00664000"],["77685.07000000","0.00008000"],["77711.40000000","0.00400000"],["77713.35000000","0.00000000"],["78834.92000000","0.00030000"]]}}
{"type":"depth","received_at_ms":1788407303911,"data":{"e":"depthUpdate","E":1788407304114,"s":"BTCUSDT","U":99603290267,"u":99603290283,"b":[["77655.55000000","0.00007000"],["77652.57000000","0.00000000"],["77636.00000000","0.73000000"],["77635.00000000","0.00000000"],["69902.88000000","0.00144000"],["62135.89000000","0.00032000"]],"a":[["77669.87000000","0.20548000"],["77672.23000000","0.00000000"],["77683.09000000","0.00257000"],["77683.64000000","0.00000000"],["77686.62000000","0.00007000"],["77723.63000000","0.00000000"]]}}
{"type":"depth","received_at_ms":1788407304011,"data":{"e":"depthUpdate","E":1788407304214,"s":"BTCUSDT","U":99603290284,"u":99603290287,"b":[["77591.38000000","0.02000000"],["69902.88000000","0.00144000"],["62135.89000000","0.00000000"]],"a":[]}}
{"type":"depth","received_at_ms":1788407304111,"data":{"e":"depthUpdate","E":1788407304314,"s":"BTCUSDT","U":99603290288,"u":99603290298,"b":[["77669.86000000","14.72953000"],["77667.60000000","0.00007000"],["77658.24000000","0.03582000"],["77590.99000000","0.02000000"],["69902.88000000","0.00160000"],["62136.00000000","0.00015000"]],"a":[["77669.87000000","0.20198000"],["77675.34000000","0.00890000"],["77675.61000000","0.00000000"]]}}
{"type":"depth","received_at_ms":1788407304250,"data":{"e":"depthUpdate","E":1788407304414,"s":"BTCUSDT","U":99603290299,"u":99603290314,"b":[["77615.14000000","0.54562000"],["77524.18000000","0.00000000"],["76967.88000000","0.00000000"],["69902.88000000","0.00160000"],["40864.30000000","0.00000000"]],"a":[["77669.87000000","0.20191000"],["77669.88000000","0.00091000"],["77671.16000000","0.00000000"],["77671.17000000","0.00014000"],["77672.68000000","0.00014000"],["77722.81000000","0.00000000"],["77778.58000000","1.46612000"],["77780.35000000","0.00000000"]]}}
{"type":"depth","received_at_ms":1788407304315,"data":{"e":"depthUpdate","E":1788407304514,"s":"BTCUSDT","U":99603290315,"u":99603290335,"b":[["77669.54000000","2.16666000"],["77667.61000000","0.00257000"],["77666.89000000","0.08334000"],["77666.85000000","0.03273000"],["77665.11000000","0.12862000"],["77662.87000000","0.12447000"],["77661.91000000","0.00000000"],["69902.88000000","0.00176000"],["62135.89000000","0.00032000"]],"a":[["77670.54000000","0.10275000"],["77671.17000000","0.00000000"],["77674.09000000","0.00548000"],["77703.31000000","0.09508000"]]}}
{"type":"depth","received_at_ms":1788407304426,"data":{"e":"depthUpdate","E":1788407304614,"s":"BTCUSDT","U":99603290336,"u":99603290353,"b":[["77669.86000000","14.72992000"],["77669.56000000","0.00014000"],["77669.55000000","0.02014000"],["77665.11000000","0.12855000"],["77664.40000000","0.00000000"],["77663.18000000","0.00200000"],["77646.00000000","0.01500000"],["77485.41000000","0.00000000"],["62135.89000000","0.00000000"]],"a":[["77722.80000000","0.00000000"]]}}
{"type":"depth","received_at_ms":1788407304518,"data":{"e":"depthUpdate","E":1788407304714,"s":"BTCUSDT","U":99603290354,"u":99603290395,"b":[["77669.86000000","14.72953000"],["77669.56000000","0.30866000"],["77669.55000000","0.00414000"],["77664.27000000","0.01600000"],["69902.88000000","0.00192000"],["69902.87000000","0.00000000"],["69902.86000000","0.00009000"],["62136.00000000","0.00015000"]],"a":[["77669.87000000","0.02201000"],["77672.23000000","0.00007000"],["77673.73000000","0.13751000"],["77674.78000000","0.00007000"],["77674.90000000","0.00000000"],["77678.64000000","0.00007000"],["77678.87000000","0.00000000"],["77679.99000000","0.00000000"],["77681.36000000","0.00000000"],["77681.40000000","0.02000000"],["77683.09000000","0.00000000"],["77683.40000000","0.00000000"],["77684.09000000","0.00400000"],["77685.29000000","0.00000000"],["77685.30000000","0.01200000"],["77687.98000000","0.00000000"],["77772.44000000","2.60723000"]]}}
{"type":"depth","received_at_ms":1788407304610,"data":{"e":"depthUpdate","E":1788407304814,"s":"BTCUSDT","U":99603290396,"u":99603290451,"b":[["77669.58000000","0.00014000"],["77669.57000000","0.01614000"],["77664.27000000","0.00000000"],["75561.55000000","0.00009000"],["69902.88000000","0.00192000"]],"a":[["77669.87000000","0.02208000"],["77669.88000000","0.00098000"],["77672.09000000","0.00000000"],["77672.69000000","0.10036000"],["77673.72000000","0.00007000"],["77673.73000000","0.00014000"],["77674.09000000","0.00534000"],["77674.74000000","0.00208000"],["77674.78000000","0.00014000"],["77677.36000000","0.00000000"],["77677.37000000","0.00714000"],["77678.14000000","0.00000000"],["77678.62000000","0.18081000"],["77678.64000000","0.00014000"],["77679.06000000","0.00000000"],["77680.15000000","0.00000000"],["77682.50000000","0.00014000"],["77682.74000000","0.00257000"],["77683.97000000","0.10022000"],["77685.07000000","0.10011000"],["77685.29000000","0.00800000"],["77685.36000000","0.17311000"],["77703.31000000","0.00000000"],["77710.45000000","0.00000000"],["77772.66000000","0.00008000"],["81006.25000000","0.00000000"]]}}
{"type":"depth","received_at_ms":1788407304727,"data":{"e":"depthUpdate","E":1788407304915,"s":"BTCUSDT","U":99603290452,"u":99603290479,"b":[["77669.86000000","14.72708000"],["77666.88000000","0.49952000"],["77642.10000000","0.00025000"],["69902.88000000","0.00208000"],["69902.86000000","0.00000000"]],"a":[["77669.87000000","0.08986000"],["77669.88000000","0.00091000"],["77669.91000000","0.00007000"],["77672.69000000","0.10036000"],["77673.72000000","0.00000000"],["77673.73000000","0.00000000"],["77674.09000000","0.00548000"],["77680.49000000","0.00653000"],["77682.74000000","0.00000000"]]}}
{"type":"depth","received_at_ms":1788407304813,"data":{"e":"depthUpdate","E":1788407305014,"s":"BTCUSDT","U":99603290480,"u":99603290534,"b":[["77669.86000000","14.32308000"],["77669.58000000","0.00000000"],["77669.57000000","0.00000000"],["77669.56000000","0.00000000"],["77669.54000000","2.09166000"],["77669.53000000","5.71545000"],["77669.27000000","0.00400000"],["77664.25000000","0.41276000"],["77663.21000000","0.00800000"],["77663.18000000","0.00814000"],["77661.60000000","0.00200000"],["76504.81000000","0.00030000"],["69902.88000000","0.00224000"],["62135.89000000","0.00032000"]],"a":[["77669.87000000","0.51424000"],["77669.88000000","0.00098000"],["77671.27000000","0.00014000"],["77671.28000000","0.10022000"],["77673.99000000","0.00000000"],["77674.50000000","0.18652000"],["77682.26000000","0.00400000"],["77682.78000000","0.00257000"],["77684.09000000","0.00000000"],["77689.54000000","1.89285000"],["77692.61000000","4.63500000"],["77800.67000000","0.02017000"],["77845.42000000","0.00000000"],["78834.92000000","0.00030000"]]}}
{"type":"depth","received_at_ms":1788407304916,"data":{"e":"depthUpdate","E":1788407305114,"s":"BTCUSDT","U":99603290535,"u":99603290556,"b":[["77655.55000000","0.00000000"],["69902.88000000","0.00224000"],["62135.89000000","0.00032000"]],"a":[["77669.87000000","0.51574000"],["77670.54000000","0.10275000"],["77671.28000000","0.10036000"],["77674.09000000","0.00534000"],["77682.78000000","0.00000000"],["77682.81000000","0.00257000"],["77686.62000000","0.00000000"],["77722.96000000","0.12880000"],["77763.19000000","0.00000000"],["77766.17000000","0.00025000"],["77811.54000000","0.00000000"]]}}
{"type":"depth","received_at_ms":1788407305020,"data":{"e":"depthUpdate","E":1788407305214,"s":"BTCUSDT","U":99603290557,"u":99603290562,"b":[["77655.55000000","0.00007000"],["69902.88000000","0.00224000"],["62135.89000000","0.00000000"]],"a":[["77686.62000000","0.00007000"],["77722.96000000","0.00000000"]]}}
{"type":"depth","received_at_ms":1788407305114,"data":{"e":"depthUpdate","E":1788407305314,"s":"BTCUSDT","U":99603290563,"u":99603290576,"b":[["77669.86000000","14.32288000"],["77647.54000000","0.00000000"],["77646.16000000","0.00200000"],["77646.00000000","0.02000000"],["69902.88000000","0.00240000"],["69902.87000000","0.00009000"],["62134.00000000","0.00000000"]],"a":[["77669.87000000","0.64535000"],["77671.44000000","0.13903000"],["77679.76000000","0.00400000"],["77681.21000000","0.00000000"],["77710.46000000","0.00855000"]]}}
{"type":"depth","received_at_ms":1788407305211,"data":{"e":"depthUpdate","E":1788407305414,"s":"BTCUSDT","U":99603290577,"u":99603290601,"b":[["77599.19000000","1.45072000"],["77569.65000000","0.09223000"],["76970.83000000","0.00010000"],["71430.73000000","0.00014000"],["69902.88000000","0.00256000"]],"a":[["77669.91000000","0.00000000"],["77670.68000000","0.00007000"],["77671.28000000","0.10036000"],["77671.43000000","0.00014000"],["77671.44000000","0.13917000"],["77672.68000000","0.00000000"],["77674.00000000","0.03000000"],["77681.19000000","0.00529000"],["77698.06000000","0.00853000"],["77703.36000000","0.09596000"],["77771.99000000","0.79392000"]]}}
{"type":"depth","received_at_ms":1788407305311,"data":{"e":"depthUpdate","E":1788407305514,"s":"BTCUSDT","U":99603290602,"u":99603290604,"b":[["69902.88000000","0.00240000"],["62135.89000000","0.00032000"]],"a":[["77669.87000000","0.64545000"]]}}
{"type":"depth","received_at_ms":1788407305410,"data":{"e":"depthUpdate","E":1788407305614,"s":"BTCUSDT","U":99603290605,"u":99603290623,"b":[["77669.86000000","14.14319000"],["77656.15000000","0.00000000"],["77646.00000000","0.03000000"],["77614.55000000","0.00000000"],["77594.66000000","0.00000000"],["69902.88000000","0.00272000"],["62135.89000000","0.00000000"]],"a":[["77669.87000000","0.65840000"],["77670.46000000","0.11727000"],["77671.44000000","0.00014000"],["77684.80000000","0.00000000"],["77713.26000000","0.00000000"],["77732.68000000","0.00000000"]]}}
{"type":"depth","received_at_ms":1788407305512,"data":{"e":"depthUpdate","E":1788407305714,"s":"BTCUSDT","U":99603290624,"u":99603290648,"b":[["77588.86000000","0.72120000"],["77583.76000000","0.00000000"],["75561.73000000","0.00010000"],["69902.88000000","0.00272000"]],"a":[["77669.87000000","0.65847000"],["77669.88000000","0.00105000"],["77670.00000000","0.03021000"],["77670.45000000","0.00014000"],["77670.46000000","0.11741000"],["77671.28000000","0.10036000"],["77671.43000000","0.00000000"],["77671.44000000","0.00000000"],["77679.76000000","0.00000000"],["77680.28000000","0.00400000"]]}}
{"type":"depth","received_at_ms":1788407305623,"data":{"e":"depthUpdate","E":1788407305814,"s":"BTCUSDT","U":99603290649,"u":99603290663,"b":[["77669.86000000","14.14448000"],["77666.88000000","0.49823000"],["77663.18000000","0.00800000"],["69902.88000000","0.00288000"],["62136.00000000","0.00015000"]],"a":[["77669.87000000","0.51576000"],["77681.19000000","0.00000000"],["81006.07000000","0.00010000"]]}}
{"type":"depth","received_at_ms":1788407305711,"data":{"e":"depthUpdate","E":1788407305914,"s":"BTCUSDT","U":99603290664,"u":99603290669,"b":[],"a":[["77669.87000000","0.51426000"],["77680.28000000","0.00000000"],["77680.77000000","0.00400000"],["77722.17000000","0.00000000"],["77903.57000000","0.00386000"]]}}
{"type":"depth","received_at_ms":1788407305810,"data":{"e":"depthUpdate","E":1788407306014,"s":"BTCUSDT","U":99603290670,"u":99603290688,"b":[["76504.81000000","0.00030000"],["71430.73000000","0.00000000"],["69902.88000000","0.00304000"],["62135.89000000","0.00032000"]],"a":[["77669.87000000","0.51441000"],["77670.68000000","0.00000000"],["77671.45000000","0.00007000"],["77721.69000000","0.00000000"],["77721.76000000","0.12880000"],["77722.25000000","0.00000000"],["78834.92000000","0.00030000"]]}}
{"type":"depth","received_at_ms":1788407305912,"data":{"e":"depthUpdate","E":1788407306114,"s":"BTCUSDT","U":99603290689,"u":99603290706,"b":[["77669.86000000","14.14440000"],["77663.18000000","0.00814000"],["69902.88000000","0.00304000"],["69902.87000000","0.00000000"],["69902.86000000","0.00009000"],["62136.00000000","0.00215000"],["62135.89000000","0.00032000"]],"a":[["77669.87000000","0.64807000"],["77721.72000000","0.00000000"],["77721.76000000","0.00000000"],["77722.06000000","0.00000000"]]}}
{"type":"depth","received_at_ms":1788407306011,"data":{"e":"depthUpdate","E":1788407306214,"s":"BTCUSDT","U":99603290707,"u":99603290729,"b":[["77663.08000000","0.02200000"],["77655.55000000","0.00007000"],["77624.24000000","0.02200000"],["69902.88000000","0.00320000"],["62136.00000000","0.00015000"],["62135.89000000","0.00080000"]],"a":[["77685.87000000","0.02000000"],["77686.62000000","0.00007000"],["77705.29000000","0.02000000"],["77721.33000000","0.00000000"],["77722.05000000","0.00007000"],["77724.72000000","0.02000000"]]}}
{"type":"depth","received_at_ms":1788407306111,"data":{"e":"depthUpdate","E":1788407306314,"s":"BTCUSDT","U":99603290730,"u":99603290750,"b":[["69902.88000000","0.00320000"],["62136.00000000","0.00015000"],["62135.89000000","0.00000000"]],"a":[["77669.87000000","0.66072000"],["77672.23000000","0.00000000"],["77721.41000000","0.12880000"],["77721.61000000","0.00000000"],["77722.04000000","0.00000000"]]}}
{"type":"depth","received_at_ms":1788407306211,"data":{"e":"depthUpdate","E":1788407306415,"s":"BTCUSDT","U":99603290751,"u":99603290761,"b":[["77602.78000000","0.23067000"],["77564.01000000","0.03159000"],["69902.88000000","0.00336000"],["62136.00000000","0.00015000"]],"a":[["77721.41000000","0.00000000"],["77722.00000000","0.03000000"],["77722.18000000","0.12880000"]]}}
{"type":"depth","received_at_ms":1788407306314,"data":{"e":"depthUpdate","E":1788407306514,"s":"BTCUSDT","U":99603290762,"u":99603290773,"b":[["77656.14000000","0.00000000"],["77617.29000000","0.02000000"],["77594.60000000","0.00000000"],["69902.88000000","0.00352000"],["62135.89000000","0.00032000"]],"a":[["77669.87000000","0.64785000"],["77670.91000000","0.00611000"],["77674.91000000","0.00000000"],["77684.88000000","0.00000000"],["77713.27000000","0.00000000"],["77722.16000000","0.00000000"],["77722.18000000","0.00000000"],["77722.25000000","0.12880000"],["77732.69000000","0.00000000"]]}}
{"type":"depth","received_at_ms":1788407306410,"data":{"e":"depthUpdate","E":1788407306614,"s":"BTCUSDT","U":99603290774,"u":99603290797,"b":[["69902.88000000","0.00352000"],["62136.00000000","0.00015000"],["62135.89000000","0.00000000"]],"a":[["77669.87000000","0.64792000"],["77669.88000000","0.00112000"],["77670.54000000","0.10275000"],["77670.91000000","0.00625000"],["77672.69000000","0.10022000"],["77722.25000000","0.00000000"],["77722.31000000","0.00000000"]]}}
{"type":"depth","received_at_ms":1788407306510,"data":{"e":"depthUpdate","E":1788407306714,"s":"BTCUSDT","U":99603290798,"u":99603290851,"b":[["77669.86000000","7.82687000"],["77669.85000000","0.00042000"],["77669.53000000","0.66765000"],["77669.27000000","0.00000000"],["77668.47000000","0.00400000"],["77666.89000000","0.00014000"],["77663.21000000","0.00000000"],["77663.18000000","0.00014000"],["77659.51000000","0.00818000"],["77646.16000000","0.00000000"],["77644.78000000","0.00200000"],["77612.69000000","4.63500000"],["77602.20000000","4.63500000"],["69902.88000000","0.00368000"]],"a":[["77669.87000000","1.00417000"],["77670.45000000","0.13881000"],["77682.22000000","0.00200000"],["77682.26000000","0.00000000"],["77685.06000000","0.00000000"],["77685.29000000","4.64300000"],["77693.12000000","0.64389000"],["77721.40000000","0.00000000"],["77721.87000000","0.00000000"],["77721.91000000","0.00000000"],["77736.58000000","0.00000000"],["77778.59000000","0.00000000"]]}}
{"type":"depth","received_at_ms":1788407306612,"data":{"e":"depthUpdate","E":1788407306814,"s":"BTCUSDT","U":99603290852,"u":99603291030,"b":[["77669.86000000","7.76987000"],["77669.85000000","0.00049000"],["77669.56000000","0.00000000"],["77669.55000000","0.00014000"],["77669.54000000","0.38896000"],["77669.53000000","0.53395000"],["77668.64000000","0.00000000"],["77668.47000000","0.00000000"],["77668.38000000","0.00000000"],["77667.72000000","0.00713000"],["77667.61000000","0.00000000"],["77667.38000000","0.00000000"],["77667.37000000","0.02035000"],["77666.89000000","0.00014000"],["77666.81000000","0.00400000"],["77666.71000000","0.00400000"],["77666.56000000","0.00088000"],["77666.00000000","0.00014000"],["77665.99000000","0.12932000"],["77665.98000000","0.00007000"],["77665.97000000","0.00007000"],["77665.91000000","0.00007000"],["77665.33000000","0.00000000"],["77665.17000000","0.00000000"],["77665.07000000","0.00000000"],["77664.74000000","0.00643000"],["77664.41000000","0.00257000"],["77664.27000000","0.00000000"],["77664.25000000","0.41262000"],["77663.18000000","0.00000000"],["77662.87000000","0.12440000"],["77662.09000000","0.00000000"],["77661.60000000","0.00800000"],["77660.89000000","0.01600000"],["77659.05000000","0.00200000"],["77658.40000000","0.30866000"],["77656.00000000","0.00014000"],["77655.60000000","0.00000000"],["77652.91000000","0.00009000"],["77649.43000000","0.25675000"],["77645.87000000","0.00000000"],["77644.78000000","0.00000000"],["77642.09000000","0.91058000"],["77642.08000000","0.01000000"],["77640.68000000","0.00207000"],["77627.71000000","0.00183000"],["77588.86000000","0.00000000"],["77586.31000000","0.72120000"],["77579.07000000","3.86855000"],["77574.94000000","0.00000000"],["69902.88000000","0.00352000"]],"a":[["77669.87000000","1.01644000"],["77669.88000000","0.00119000"],["77670.00000000","0.03021000"],["77670.44000000","0.00014000"],["77670.45000000","0.13895000"],["77670.69000000","0.00208000"],["77670.91000000","0.00021000"],["77670.92000000","0.00014000"],["77671.43000000","0.09989000"],["77671.99000000","0.00000000"],["77672.00000000","0.03000000"],["77674.35000000","0.00000000"],["77674.56000000","0.00533000"],["77674.74000000","0.00000000"],["77674.87000000","0.00000000"],["77675.06000000","0.00000000"],["77675.30000000","0.00000000"],["77675.72000000","0.00660000"],["77676.59000000","0.00517000"],["77677.46000000","0.00400000"],["77677.98000000","0.00400000"],["77678.25000000","0.00400000"],["77678.61000000","0.00200000"],["77678.62000000","0.25649000"],["77679.91000000","0.00257000"],["77679.94000000","0.00000000"],["77679.97000000","0.00000000"],["77680.02000000","0.30866000"],["77680.20000000","0.00400000"],["77680.74000000","0.00515000"],["77680.77000000","0.00000000"],["77682.22000000","0.01600000"],["77682.23000000","2.42207000"],["77682.81000000","0.00000000"],["77683.92000000","0.38633000"],["77683.97000000","0.00000000"],["77685.07000000","0.00008000"],["77685.11000000","0.00157000"],["77685.29000000","4.63900000"],["77685.30000000","0.00000000"],["77693.12000000","0.00008000"],["77693.31000000","0.00000000"],["77709.45000000","0.00000000"],["77709.52000000","0.00000000"],["77711.40000000","0.00000000"],["77722.19000000","0.12880000"],["77778.58000000","0.08251000"],["77808.02000000","0.00000000"]]}}
{"type":"depth","received_at_ms":1788407306711,"data":{"e":"depthUpdate","E":1788407306914,"s":"BTCUSDT","U":99603291031,"u":99603291085,"b":[["77669.86000000","7.76980000"],["77669.85000000","0.00042000"],["77669.53000000","0.53388000"],["77668.61000000","0.01705000"],["77665.11000000","0.12882000"],["77664.41000000","0.00000000"],["77663.52000000","0.00257000"],["77663.00000000","0.02000000"],["77636.00000000","0.03000000"],["77627.07000000","0.88917000"],["77626.00000000","0.03000000"],["77624.15000000","0.02000000"],["77572.18000000","0.03993000"],["77545.59000000","0.00066000"],["69902.88000000","0.00384000"]],"a":[["77669.87000000","1.03741000"],["77670.54000000","0.10275000"],["77670.91000000","0.00007000"],["77671.28000000","0.10036000"],["77671.43000000","0.10003000"],["77674.56000000","0.00000000"],["77675.72000000","0.00000000"],["77676.59000000","0.00000000"],["77677.98000000","0.00000000"],["77678.23000000","0.00533000"],["77678.61000000","0.00000000"],["77679.04000000","0.00257000"],["77679.91000000","0.00000000"],["77680.98000000","0.00200000"],["77685.85000000","0.02000000"],["77705.27000000","0.02000000"],["77722.19000000","0.00000000"],["77722.66000000","0.12880000"],["77724.70000000","0.02000000"],["77805.26000000","0.00971000"]]}}
{"type":"depth","received_at_ms":1788407306811,"data":{"e":"depthUpdate","E":1788407307014,"s":"BTCUSDT","U":99603291086,"u":99603291142,"b":[["77669.86000000","7.80924000"],["77669.85000000","0.00056000"],["77668.62000000","0.00086000"],["77668.56000000","0.00400000"],["77667.90000000","0.00514000"],["77667.72000000","0.00643000"],["77666.81000000","0.00000000"],["77666.56000000","0.00000000"],["77665.76000000","0.00257000"],["77663.52000000","0.00000000"],["77663.18000000","0.00800000"],["77660.89000000","0.00800000"],["77643.95000000","0.00200000"],["77640.68000000","0.00007000"],["77579.08000000","0.30866000"],["77464.81000000","0.00000000"],["77454.89000000","0.01118000"],["76504.81000000","0.00030000"],["69902.88000000","0.00384000"],["62136.00000000","0.00015000"],["62135.89000000","0.00032000"]],"a":[["77669.87000000","0.89456000"],["77669.88000000","0.00112000"],["77670.69000000","0.00000000"],["77670.92000000","0.00007000"],["77671.43000000","0.00014000"],["77674.99000000","0.00027000"],["77675.65000000","0.00000000"],["77677.46000000","0.00000000"],["77678.23000000","0.00000000"],["77678.41000000","0.00000000"],["77678.45000000","0.00530000"],["77678.50000000","0.00000000"],["77678.91000000","0.00400000"],["77679.04000000","0.00000000"],["77679.35000000","0.00400000"],["77680.98000000","0.00000000"],["77681.29000000","0.00257000"],["77682.06000000","0.00200000"],["77709.52000000","0.00007000"],["78834.92000000","0.00030000"]]}}
{"type":"depth","received_at_ms":1788407306914,"data":{"e":"depthUpdate","E":1788407307114,"s":"BTCUSDT","U":99603291143,"u":99603291171,"b":[["77668.61000000","0.01712000"],["77665.76000000","0.00000000"],["77665.11000000","0.12889000"],["77664.44000000","0.00257000"],["77663.16000000","0.15577000"],["77662.88000000","0.00000000"],["77658.24000000","0.00000000"],["77531.54000000","0.02017000"],["77519.91000000","0.00000000"],["77506.81000000","0.00066000"],["69902.88000000","0.00384000"]],"a":[["77669.87000000","0.89408000"],["77670.92000000","0.00014000"],["77671.28000000","0.10036000"],["77671.43000000","0.00000000"],["77672.00000000","0.03014000"],["77679.96000000","0.00257000"],["77681.29000000","0.00000000"],["77709.52000000","0.00000000"]]}}
{"type":"depth","received_at_ms":1788407307020,"data":{"e":"depthUpdate","E":1788407307214,"s":"BTCUSDT","U":99603291172,"u":99603291195,"b":[["77668.56000000","0.00000000"],["77668.13000000","0.00400000"],["77667.76000000","0.00400000"],["77666.71000000","0.00000000"],["77663.18000000","0.00000000"],["77661.60000000","0.01600000"],["77655.55000000","0.00007000"],["77652.91000000","0.00000000"],["77604.81000000","0.02200000"],["69902.88000000","0.00400000"],["62135.89000000","0.00000000"]],"a":[["77669.87000000","0.89456000"],["77670.54000000","0.10942000"],["77678.52000000","0.00000000"],["77686.62000000","0.00007000"],["78058.22000000","0.00007000"]]}}
{"type":"depth","received_at_ms":1788407307114,"data":{"e":"depthUpdate","E":1788407307314,"s":"BTCUSDT","U":99603291196,"u":99603291212,"b":[["77669.86000000","7.80917000"],["77669.85000000","0.00049000"],["77668.61000000","0.01705000"],["77667.90000000","0.00000000"],["69902.88000000","0.00416000"],["62136.00000000","0.00015000"]],"a":[["77669.87000000","0.89441000"],["77670.00000000","0.03028000"]]}}
{"type":"depth","received_at_ms":1788407307210,"data":{"e":"depthUpdate","E":1788407307414,"s":"BTCUSDT","U":99603291213,"u":99603291234,"b":[["77669.86000000","7.80709000"],["77668.61000000","0.01705000"],["77654.52000000","0.05643000"],["77615.14000000","1.85284000"],["77586.31000000","0.00000000"],["77583.76000000","0.72120000"],["77579.55000000","1.62639000"],["69902.88000000","0.00416000"],["62136.00000000","0.00015000"]],"a":[["77670.45000000","0.13907000"],["77670.54000000","0.10275000"],["77670.92000000","0.00007000"],["77676.41000000","0.00677000"],["77794.13000000","0.00113000"]]}}
{"type":"depth","received_at_ms":1788407307310,"data":{"e":"depthUpdate","E":1788407307514,"s":"BTCUSDT","U":99603291235,"u":99603291258,"b":[["77669.86000000","7.81591000"],["77669.34000000","0.00539000"],["77666.37000000","0.00000000"],["77664.44000000","0.00000000"],["77656.13000000","0.00000000"],["77617.36000000","0.25758000"],["77617.29000000","0.00000000"],["77597.87000000","0.00000000"],["77580.21000000","0.00000000"],["69902.88000000","0.00432000"],["62135.89000000","0.00032000"]],"a":[["77669.87000000","0.89456000"],["77670.92000000","0.00014000"],["77674.22000000","0.00027000"],["77674.78000000","0.00014000"],["77674.99000000","0.00000000"],["77676.41000000","0.00000000"],["77679.96000000","0.00000000"],["77681.40000000","0.00000000"],["77691.00000000","0.70000000"],["77696.00000000","0.03265000"],["77709.52000000","0.00000000"],["77713.24000000","0.00000000"],["77732.66000000","0.00000000"]]}}
{"type":"depth","received_at_ms":1788407307410,"data":{"e":"depthUpdate","E":1788407307614,"s":"BTCUSDT","U":99603291259,"u":99603291272,"b":[["77669.86000000","7.81598000"],["77669.85000000","0.00056000"],["77669.53000000","0.53388000"],["77664.75000000","0.00257000"],["77631.00000000","0.71000000"],["69902.88000000","0.00432000"],["62135.89000000","0.00000000"]],"a":[["77669.87000000","1.02701000"],["77833.02000000","0.00253000"]]}}
{"type":"depth","received_at_ms":1788407307513,"data":{"e":"depthUpdate","E":1788407307714,"s":"BTCUSDT","U":99603291273,"u":99603291317,"b":[["77669.86000000","7.81025000"],["77669.34000000","0.00014000"],["77667.72000000","0.00657000"],["77633.14000000","0.00000000"],["77632.24000000","0.12880000"],["77603.74000000","0.00000000"],["69902.88000000","0.00432000"],["69902.86000000","0.00000000"]],"a":[["77669.87000000","1.02287000"],["77669.99000000","0.01224000"]]}}
{"type":"depth","received_at_ms":1788407307610,"data":{"e":"depthUpdate","E":1788407307814,"s":"BTCUSDT","U":99603291318,"u":99603291341,"b":[["77669.86000000","7.81018000"],["77669.85000000","0.00049000"],["77669.53000000","0.53388000"],["77669.34000000","0.00000000"],["77667.76000000","0.00000000"],["77667.02000000","0.00400000"],["77666.88000000","0.49837000"],["77662.91000000","0.02000000"],["77643.95000000","0.00000000"],["77641.75000000","0.00200000"],["77632.83000000","0.00000000"],["77632.40000000","0.00000000"],["77632.24000000","0.00000000"],["77624.06000000","0.02000000"]],"a":[["77685.77000000","0.02000000"],["77705.20000000","0.02000000"],["77724.62000000","0.02000000"]]}}
{"type":"depth","received_at_ms":1788407307711,"data":{"e":"depthUpdate","E":1788407307914,"s":"BTCUSDT","U":99603291342,"u":99603291353,"b":[["77669.86000000","7.81018000"],["77669.56000000","0.00000000"],["77668.62000000","0.00000000"],["77668.14000000","0.00087000"],["77632.25000000","0.12880000"],["77604.73000000","0.02000000"],["77495.80000000","0.00000000"],["69902.88000000","0.00432000"],["69902.87000000","0.00027000"]],"a":[["77669.87000000","1.02272000"]]}}
{"type":"depth","received_at_ms":1788407307811,"data":{"e":"depthUpdate","E":1788407308014,"s":"BTCUSDT","U":99603291354,"u":99603291376,"b":[["77669.86000000","7.80965000"],["77669.85000000","0.00063000"],["77669.56000000","0.00068000"],["77632.92000000","0.12880000"],["77632.30000000","0.00000000"],["77632.25000000","0.00000000"],["76504.81000000","0.00030000"],["69902.88000000","0.00457000"],["62135.89000000","0.00032000"]],"a":[["77669.87000000","1.02028000"],["77853.85000000","0.00000000"],["78834.92000000","0.00030000"]]}}
{"type":"depth","received_at_ms":1788407307910,"data":{"e":"depthUpdate","E":1788407308114,"s":"BTCUSDT","U":99603291377,"u":99603291389,"b":[["77668.13000000","0.00000000"],["77667.63000000","0.00400000"],["77632.92000000","0.00000000"],["77632.57000000","0.00000000"],["77632.24000000","0.00000000"],["69902.88000000","0.00441000"]],"a":[["77677.84000000","0.00400000"],["77679.35000000","0.00000000"],["77679.57000000","0.00200000"],["77682.06000000","0.00000000"],["79020.00000000","0.02852000"]]}}
{"type":"depth","received_at_ms":1788407308011,"data":{"e":"depthUpdate","E":1788407308214,"s":"BTCUSDT","U":99603291390,"u":99603291409,"b":[["77669.86000000","7.81034000"],["77669.56000000","0.00000000"],["77668.62000000","0.00000000"],["77655.55000000","0.00000000"],["77632.24000000","0.00000000"],["77489.59000000","4.55523000"],["69902.88000000","0.00457000"],["62135.89000000","0.00000000"]],"a":[["77677.84000000","0.00000000"],["77678.60000000","0.00400000"],["77679.57000000","0.00000000"],["77681.36000000","0.00200000"],["77686.62000000","0.00000000"],["77848.25000000","4.54862000"],["78058.22000000","0.00000000"]]}}
{"type":"depth","received_at_ms":1788407308110,"data":{"e":"depthUpdate","E":1788407308314,"s":"BTCUSDT","U":99603291410,"u":99603291421,"b":[["77669.86000000","7.81027000"],["77669.85000000","0.00056000"],["77655.55000000","0.00007000"],["69902.88000000","0.00441000"],["62136.00000000","0.00015000"]],"a":[["77686.62000000","0.00007000"],["77769.89000000","2.60723000"],["77771.99000000","0.01846000"],["77772.44000000","0.00000000"]]}}
{"type":"depth","received_at_ms":1788407308210,"data":{"e":"depthUpdate","E":1788407308414,"s":"BTCUSDT","U":99603291422,"u":99603291438,"b":[["77669.86000000","7.81034000"],["77669.85000000","0.00063000"],["77669.51000000","0.00530000"],["77602.78000000","1.58473000"],["69902.88000000","0.00441000"]],"a":[["77669.87000000","1.03015000"],["77766.99000000","2.19253000"]]}}
{"type":"depth","received_at_ms":1788407308311,"data":{"e":"depthUpdate","E":1788407308514,"s":"BTCUSDT","U":99603291439,"u":99603291448,"b":[["77669.53000000","0.53388000"],["77669.51000000","0.00000000"],["77656.91000000","0.00000000"],["77618.06000000","0.00000000"],["77598.64000000","0.00000000"],["69902.88000000","0.00441000"],["62135.89000000","0.00032000"]],"a":[["77679.50000000","0.00257000"],["77680.62000000","0.00000000"],["77712.43000000","0.00000000"],["77731.85000000","0.00000000"]]}}
{"type":"depth","received_at_ms":1788407308410,"data":{"e":"depthUpdate","E":1788407308614,"s":"BTCUSDT","U":99603291449,"u":99603291457,"b":[["77669.53000000","0.53388000"],["69902.88000000","0.00457000"],["62135.89000000","0.00000000"]],"a":[["77676.15000000","0.00538000"]]}}
{"type":"depth","received_at_ms":1788407308510,"data":{"e":"depthUpdate","E":1788407308714,"s":"BTCUSDT","U":99603291458,"u":99603291466,"b":[["77669.86000000","7.81027000"],["77669.85000000","0.00056000"],["77631.67000000","0.12880000"],["69902.88000000","0.00416000"],["69902.87000000","0.00036000"]],"a":[["77669.87000000","1.02997000"],["77676.33000000","0.00670000"],["77710.46000000","0.00000000"]]}}
{"type":"depth","received_at_ms":1788407308611,"data":{"e":"depthUpdate","E":1788407308815,"s":"BTCUSDT","U":99603291467,"u":99603291477,"b":[["77663.60000000","0.02000000"],["77631.67000000","0.00000000"],["77624.75000000","0.02000000"],["77604.64000000","0.02000000"],["69902.88000000","0.00448000"],["62136.00000000","0.00015000"]],"a":[["77684.91000000","0.02000000"],["77704.33000000","0.02000000"],["77723.76000000","0.02000000"]]}}
{"type":"depth","received_at_ms":1788407308711,"data":{"e":"depthUpdate","E":1788407308914,"s":"BTCUSDT","U":99603291478,"u":99603291492,"b":[["77669.86000000","7.81041000"],["77669.85000000","0.00063000"],["69902.88000000","0.00432000"]],"a":[["77678.91000000","0.00000000"],["77678.99000000","0.00400000"],["77710.54000000","0.00836000"]]}}
{"type":"depth","received_at_ms":1788407308811,"data":{"e":"depthUpdate","E":1788407309014,"s":"BTCUSDT","U":99603291493,"u":99603291506,"b":[["77669.86000000","7.81048000"],["77644.53000000","0.00000000"],["77620.61000000","0.00000000"],["76504.81000000","0.00030000"],["69902.88000000","0.00416000"],["69902.87000000","0.00009000"],["62135.89000000","0.00032000"]],"a":[["77693.53000000","0.00000000"],["77717.47000000","0.00000000"],["78834.92000000","0.00030000"]]}}
{"type":"depth","received_at_ms":1788407308911,"data":{"e":"depthUpdate","E":1788407309114,"s":"BTCUSDT","U":99603291507,"u":99603291519,"b":[["77669.86000000","7.80986000"],["77668.62000000","0.00068000"],["77667.63000000","0.00000000"],["77667.12000000","0.00400000"],["77654.52000000","0.00000000"],["77631.54000000","0.12880000"],["69902.88000000","0.00432000"],["62136.00000000","0.00015000"]],"a":[["77669.87000000","1.03253000"],["77679.50000000","0.00000000"],["77679.51000000","0.00257000"]]}}
{"type":"depth","received_at_ms":1788407309011,"data":{"e":"depthUpdate","E":1788407309214,"s":"BTCUSDT","U":99603291520,"u":99603291588,"b":[["77669.86000000","7.72218000"],["77669.85000000","0.00063000"],["77668.14000000","0.00000000"],["77667.98000000","0.00521000"],["77667.61000000","0.00000000"],["77667.12000000","0.00000000"],["77667.07000000","0.00101000"],["77667.02000000","0.00000000"],["77666.85000000","0.03266000"],["77666.44000000","0.00400000"],["77666.00000000","0.00000000"],["77665.99000000","0.00007000"],["77665.91000000","0.00014000"],["77665.57000000","0.00400000"],["77665.12000000","0.00007000"],["77664.75000000","0.00000000"],["77664.49000000","0.00257000"],["77641.75000000","0.00000000"],["77641.04000000","0.00200000"],["69902.88000000","0.00432000"],["62135.89000000","0.00000000"]],"a":[["77669.87000000","2.14070000"],["77669.88000000","0.00112000"],["77670.36000000","0.00208000"],["77670.45000000","0.13914000"],["77670.56000000","0.00007000"],["77670.57000000","0.09989000"],["77671.27000000","0.00000000"],["77671.28000000","0.00014000"],["77676.30000000","0.00400000"],["77676.89000000","0.00400000"],["77677.52000000","0.00400000"],["77678.60000000","0.00000000"],["77678.61000000","0.00200000"],["77678.99000000","0.00000000"],["77681.36000000","0.00000000"],["77707.50000000","0.00000000"]]}}
{"type":"depth","received_at_ms":1788407309111,"data":{"e":"depthUpdate","E":1788407309314,"s":"BTCUSDT","U":99603291589,"u":99603291621,"b":[["77669.86000000","7.72215000"],["77669.85000000","0.00070000"],["77668.61000000","0.01705000"],["77655.55000000","0.00007000"],["77654.52000000","0.04466000"],["77641.99000000","0.50970000"],["77621.56000000","0.02556000"],["77618.07000000","1.03675000"],["69902.88000000","0.00432000"],["69902.87000000","0.00000000"],["62136.00000000","0.00015000"]],"a":[["77670.54000000","0.10275000"],["77670.57000000","0.10003000"],["77671.28000000","0.00000000"],["77676.89000000","0.00000000"],["77677.55000000","0.00400000"],["77678.61000000","0.00000000"],["77679.99000000","0.00200000"],["77686.62000000","0.00007000"],["77693.60000000","0.51412000"],["77717.55000000","1.01797000"]]}}
{"type":"depth","received_at_ms":1788407309210,"data":{"e":"depthUpdate","E":1788407309414,"s":"BTCUSDT","U":99603291622,"u":99603291625,"b":[["77669.86000000","7.72167000"],["77661.08000000","0.00048000"],["69902.88000000","0.00432000"]],"a":[]}}
{"type":"depth","received_at_ms":1788407309310,"data":{"e":"depthUpdate","E":1788407309514,"s":"BTCUSDT","U":99603291626,"u":99603291638,"b":[["77669.86000000","7.72222000"],["77661.08000000","0.00000000"],["77619.05000000","1.19221000"],["69902.88000000","0.00448000"],["62136.00000000","0.00015000"],["62135.89000000","0.00032000"]],"a":[["77669.87000000","1.97149000"]]}}
{"type":"depth","received_at_ms":1788407309411,"data":{"e":"depthUpdate","E":1788407309614,"s":"BTCUSDT","U":99603291639,"u":99603291647,"b":[["69902.88000000","0.00432000"],["62136.00000000","0.00015000"],["62135.89000000","0.00000000"]],"a":[["85436.85000000","0.00383000"]]}}
{"type":"depth","received_at_ms":1788407309511,"data":{"e":"depthUpdate","E":1788407309714,"s":"BTCUSDT","U":99603291648,"u":99603291652,"b":[["77669.86000000","7.77562000"],["69902.88000000","0.00448000"],["69902.87000000","0.00009000"]],"a":[["85436.85000000","0.00000000"]]}}
{"type":"depth","received_at_ms":1788407309611,"data":{"e":"depthUpdate","E":1788407309814,"s":"BTCUSDT","U":99603291653,"u":99603291658,"b":[["77605.32000000","0.02000000"],["77583.76000000","0.00000000"],["77581.21000000","0.72120000"],["69902.88000000","0.00432000"]],"a":[]}}
{"type":"depth","received_at_ms":1788407309712,"data":{"e":"depthUpdate","E":1788407309914,"s":"BTCUSDT","U":99603291659,"u":99603291666,"b":[["77669.86000000","7.77508000"],["77667.98000000","0.00000000"],["69902.88000000","0.00448000"],["62136.00000000","0.00015000"]],"a":[["77685.28000000","0.36386000"]]}}
{"type":"depth","received_at_ms":1788407309811,"data":{"e":"depthUpdate","E":1788407310014,"s":"BTCUSDT","U":99603291667,"u":99603291681,"b":[["77669.86000000","7.77501000"],["77669.85000000","0.00063000"],["77668.61000000","0.01705000"],["76504.81000000","0.00030000"],["69902.88000000","0.00432000"],["62136.00000000","0.00015000"],["62135.89000000","0.00032000"]],"a":[["78834.92000000","0.00030000"],["86422.88000000","0.22692000"]]}}
{"type":"depth","received_at_ms":1788407309911,"data":{"e":"depthUpdate","E":1788407310115,"s":"BTCUSDT","U":99603291682,"u":99603291689,"b":[["77669.86000000","7.77508000"],["77658.68000000","0.00007000"],["69902.88000000","0.00448000"]],"a":[["77698.80000000","0.04549000"],["77701.84000000","0.00000000"],["86422.88000000","0.24583000"]]}}
{"type":"depth","received_at_ms":1788407310011,"data":{"e":"depthUpdate","E":1788407310214,"s":"BTCUSDT","U":99603291690,"u":99603291706,"b":[["77669.86000000","7.67183000"],["69902.88000000","0.00432000"],["69902.87000000","0.00000000"],["69902.86000000","0.00009000"],["62135.89000000","0.00000000"]],"a":[["77669.87000000","2.37350000"],["77763.83000000","0.00089000"],["77837.53000000","0.00093000"]]}}
{"type":"depth","received_at_ms":1788407310111,"data":{"e":"depthUpdate","E":1788407310314,"s":"BTCUSDT","U":99603291707,"u":99603291741,"b":[["77669.86000000","7.66121000"],["77669.85000000","0.00063000"],["77668.62000000","0.00000000"],["77668.38000000","0.00070000"],["77667.72000000","0.00014000"],["77666.44000000","0.00000000"],["77665.24000000","0.00400000"],["77665.13000000","0.00643000"],["77661.60000000","0.00000000"],["77661.19000000","0.00048000"],["77659.24000000","0.00000000"],["77659.05000000","0.01800000"],["77655.55000000","0.00007000"],["77653.89000000","0.08644000"],["77641.04000000","0.00000000"],["77639.45000000","0.00200000"],["69902.88000000","0.00432000"],["62136.00000000","0.00015000"]],"a":[["77677.54000000","0.00000000"],["77679.29000000","0.00200000"],["77679.99000000","0.00000000"],["77686.62000000","0.00007000"],["84202.54000000","0.01768000"]]}}
{"type":"depth","received_at_ms":1788407310211,"data":{"e":"depthUpdate","E":1788407310414,"s":"BTCUSDT","U":99603291742,"u":99603291758,"b":[["77669.86000000","7.66123000"],["77668.61000000","0.01698000"],["77667.72000000","0.00000000"],["77666.85000000","0.03280000"],["77665.90000000","0.19041000"],["77661.19000000","0.00000000"],["69902.88000000","0.00432000"]],"a":[["77669.87000000","2.37365000"]]}}
{"type":"depth","received_at_ms":1788407310311,"data":{"e":"depthUpdate","E":1788407310514,"s":"BTCUSDT","U":99603291759,"u":99603291766,"b":[["77669.86000000","7.66075000"],["77669.36000000","0.04989000"],["77609.29000000","0.60603000"],["69902.88000000","0.00432000"],["62135.89000000","0.00032000"]],"a":[]}}
{"type":"depth","received_at_ms":1788407310412,"data":{"e":"depthUpdate","E":1788407310615,"s":"BTCUSDT","U":99603291767,"u":99603291785,"b":[["77669.86000000","7.66130000"],["77669.85000000","0.00070000"],["77669.53000000","0.53388000"],["77669.37000000","0.00014000"],["77665.12000000","0.00000000"],["69902.88000000","0.00416000"],["69902.86000000","0.00000000"],["62136.00000000","0.00215000"],["62135.89000000","0.00000000"]],"a":[["77669.87000000","2.37331000"],["77679.29000000","0.00000000"],["77680.48000000","0.00200000"]]}}
{"type":"depth","received_at_ms":1788407310510,"data":{"e":"depthUpdate","E":1788407310714,"s":"BTCUSDT","U":99603291786,"u":99603291801,"b":[["77669.86000000","7.66034000"],["77664.49000000","0.00000000"],["77663.03000000","0.00257000"],["77661.10000000","0.00096000"],["75561.73000000","0.00000000"],["69902.88000000","0.00432000"],["62136.00000000","0.00015000"]],"a":[["77679.51000000","0.00000000"],["81006.07000000","0.00000000"]]}}
{"type":"depth","received_at_ms":1788407310612,"data":{"e":"depthUpdate","E":1788407310814,"s":"BTCUSDT","U":99603291802,"u":99603291805,"b":[["77669.86000000","7.56214000"],["69902.88000000","0.00432000"]],"a":[["77703.36000000","0.00000000"]]}}
{"type":"depth","received_at_ms":1788407310712,"data":{"e":"depthUpdate","E":1788407310914,"s":"BTCUSDT","U":99603291806,"u":99603291815,"b":[["77669.86000000","7.56206000"],["69902.88000000","0.00432000"]],"a":[["77669.87000000","2.37324000"],["77669.88000000","0.00105000"],["77672.69000000","0.00000000"]]}}
{"type":"depth","received_at_ms":1788407310811,"data":{"e":"depthUpdate","E":1788407311014,"s":"BTCUSDT","U":99603291816,"u":99603291838,"b":[["77669.86000000","7.56221000"],["77669.14000000","0.00158000"],["77642.96000000","0.00200000"],["77640.16000000","0.02000000"],["77639.45000000","0.00000000"],["76504.81000000","0.00030000"],["69902.88000000","0.00464000"],["62135.89000000","0.00032000"]],"a":[["77669.87000000","2.37331000"],["77672.00000000","0.03014000"],["77708.37000000","0.02577000"],["78834.92000000","0.00030000"]]}}
{"type":"depth","received_at_ms":1788407310911,"data":{"e":"depthUpdate","E":1788407311114,"s":"BTCUSDT","U":99603291839,"u":99603291852,"b":[["77669.86000000","7.56221000"],["77669.85000000","0.00070000"],["77669.37000000","0.00000000"],["77669.36000000","0.00000000"],["77665.12000000","0.00007000"],["77663.17000000","1.13026000"],["77591.80000000","0.00000000"],["71456.28000000","0.00014000"],["69902.88000000","0.00448000"]],"a":[]}}
{"type":"depth","received_at_ms":1788407311010,"data":{"e":"depthUpdate","E":1788407311214,"s":"BTCUSDT","U":99603291853,"u":99603291863,"b":[["77669.53000000","0.53388000"],["77639.74000000","0.02000000"],["77583.76000000","0.72120000"],["77581.21000000","0.00000000"],["69902.88000000","0.00464000"],["62135.89000000","0.00000000"]],"a":[]}}
{"type":"depth","received_at_ms":1788407311111,"data":{"e":"depthUpdate","E":1788407311314,"s":"BTCUSDT","U":99603291864,"u":99603291873,"b":[["77660.00000000","0.02576000"],["77655.55000000","0.00000000"],["77591.38000000","0.00000000"],["69902.88000000","0.00448000"],["62136.00000000","0.00015000"],["62135.89000000","0.00000000"]],"a":[["77686.62000000","0.00000000"]]}}
{"type":"depth","received_at_ms":1788407311211,"data":{"e":"depthUpdate","E":1788407311414,"s":"BTCUSDT","U":99603291874,"u":99603291887,"b":[["77655.55000000","0.00007000"],["77643.25000000","0.02400000"],["77640.89000000","0.02000000"],["77639.37000000","0.02000000"],["77639.36000000","0.13829000"],["77631.54000000","0.00000000"],["77590.99000000","0.00000000"],["69902.88000000","0.00464000"],["62136.00000000","0.00015000"]],"a":[["77686.62000000","0.00007000"]]}}
{"type":"depth","received_at_ms":1788407311311,"data":{"e":"depthUpdate","E":1788407311514,"s":"BTCUSDT","U":99603291888,"u":99603291897,"b":[["77642.96000000","0.00000000"],["77641.44000000","0.00200000"],["77631.74000000","0.00000000"],["77631.15000000","0.12880000"],["69902.88000000","0.00448000"],["62135.89000000","0.00032000"]],"a":[["77719.74000000","0.00079000"]]}}
{"type":"depth","received_at_ms":1788407311411,"data":{"e":"depthUpdate","E":1788407311614,"s":"BTCUSDT","U":99603291898,"u":99603291904,"b":[["77661.10000000","0.00048000"],["77631.15000000","0.00000000"],["77583.95000000","0.00000000"],["77582.48000000","0.00000000"],["71456.28000000","0.00000000"],["69902.88000000","0.00464000"],["62135.89000000","0.00000000"]],"a":[]}}
{"type":"depth","received_at_ms":1788407311510,"data":{"e":"depthUpdate","E":1788407311714,"s":"BTCUSDT","U":99603291905,"u":99603291918,"b":[["77669.86000000","7.56214000"],["77669.51000000","0.00014000"],["77669.50000000","0.05322000"],["77665.12000000","0.00000000"],["77661.19000000","0.00048000"],["77589.23000000","0.00000000"],["77583.76000000","0.00000000"],["77581.21000000","0.72120000"],["69902.88000000","0.00448000"]],"a":[["77678.01000000","0.00257000"],["77691.00000000","0.00000000"]]}}
{"type":"depth","received_at_ms":1788407311610,"data":{"e":"depthUpdate","E":1788407311814,"s":"BTCUSDT","U":99603291919,"u":99603291937,"b":[["77669.86000000","7.56269000"],["77669.85000000","0.00077000"],["77669.53000000","0.53388000"],["77664.04000000","0.00257000"],["77663.03000000","0.00000000"],["77661.19000000","0.00000000"],["77632.17000000","0.00000000"],["77593.09000000","0.00000000"],["69902.88000000","0.00464000"],["62136.00000000","0.00015000"]],"a":[["77678.01000000","0.00000000"]]}}
{"type":"depth","received_at_ms":1788407311712,"data":{"e":"depthUpdate","E":1788407311915,"s":"BTCUSDT","U":99603291938,"u":99603291942,"b":[["77631.97000000","0.00000000"],["75561.73000000","0.00010000"],["69902.88000000","0.00432000"]],"a":[]}}
{"type":"depth","received_at_ms":1788407311811,"data":{"e":"depthUpdate","E":1788407312014,"s":"BTCUSDT","U":99603291943,"u":99603291952,"b":[["77631.56000000","0.00000000"],["76504.81000000","0.00030000"],["69902.88000000","0.00448000"],["62135.89000000","0.00032000"]],"a":[["78834.92000000","0.00030000"]]}}
{"type":"depth","received_at_ms":1788407311910,"data":{"e":"depthUpdate","E":1788407312114,"s":"BTCUSDT","U":99603291953,"u":99603291959,"b":[["77583.76000000","0.72120000"],["77581.21000000","0.00000000"],["77454.88000000","0.00000000"],["69902.88000000","0.00448000"],["62136.00000000","0.00215000"]],"a":[["81006.07000000","0.00010000"]]}}
{"type":"depth","received_at_ms":1788407312010,"data":{"e":"depthUpdate","E":1788407312214,"s":"BTCUSDT","U":99603291960,"u":99603291970,"b":[["77666.00000000","0.00129000"],["77654.52000000","0.00000000"],["77480.01000000","0.02017000"],["69902.88000000","0.00441000"],["62136.00000000","0.00015000"],["62135.89000000","0.00000000"]],"a":[["77669.87000000","2.23022000"],["77685.28000000","0.00000000"]]}}
{"type":"depth","received_at_ms":1788407312111,"data":{"e":"depthUpdate","E":1788407312314,"s":"BTCUSDT","U":99603291971,"u":99603291987,"b":[["77669.86000000","7.56262000"],["77666.87000000","0.00400000"],["77665.24000000","0.00000000"],["77661.10000000","0.00000000"],["77480.01000000","0.00000000"],["69902.88000000","0.00457000"],["62136.00000000","0.00015000"],["62135.89000000","0.00000000"]],"a":[["77676.15000000","0.00000000"],["77776.38000000","0.00000000"],["77798.08000000","0.30974000"]]}}
{"type":"depth","received_at_ms":1788407312212,"data":{"e":"depthUpdate","E":1788407312414,"s":"BTCUSDT","U":99603291988,"u":99603292006,"b":[["77669.86000000","7.56309000"],["77666.87000000","0.00000000"],["77666.38000000","0.00400000"],["77655.55000000","0.00007000"],["77631.84000000","0.00000000"],["77454.89000000","0.00306000"],["77453.93000000","0.00812000"],["77452.89000000","0.02017000"],["69902.88000000","0.00457000"],["62136.00000000","0.00015000"]],"a":[["77686.62000000","0.00007000"],["77696.00000000","0.73265000"]]}}
{"type":"depth","received_at_ms":1788407312311,"data":{"e":"depthUpdate","E":1788407312514,"s":"BTCUSDT","U":99603292007,"u":99603292017,"b":[["77669.86000000","7.56291000"],["77668.89000000","0.00532000"],["77631.71000000","0.00000000"],["69902.88000000","0.00473000"],["62135.89000000","0.00032000"]],"a":[["77684.79000000","0.35245000"],["77721.95000000","0.85093000"]]}}
{"type":"depth","received_at_ms":1788407312412,"data":{"e":"depthUpdate","E":1788407312614,"s":"BTCUSDT","U":99603292018,"u":99603292034,"b":[["77669.86000000","7.56298000"],["77669.85000000","0.00084000"],["77669.50000000","0.05336000"],["77666.85000000","0.03266000"],["69902.88000000","0.00457000"],["62136.00000000","0.00015000"],["62135.89000000","0.00000000"]],"a":[["77720.78000000","0.63736000"]]}}
{"type":"depth","received_at_ms":1788407312512,"data":{"e":"depthUpdate","E":1788407312715,"s":"BTCUSDT","U":99603292035,"u":99603292037,"b":[["69902.88000000","0.00473000"]],"a":[]}}
{"type":"depth","received_at_ms":1788407312611,"data":{"e":"depthUpdate","E":1788407312814,"s":"BTCUSDT","U":99603292038,"u":99603292048,"b":[["77669.86000000","7.16298000"],["77669.51000000","0.00000000"],["77669.50000000","0.00014000"],["77668.89000000","0.00000000"],["77665.12000000","0.00007000"],["69902.88000000","0.00448000"],["69902.87000000","0.00009000"]],"a":[["77678.90000000","0.00257000"]]}}
{"type":"depth","received_at_ms":1788407312710,"data":{"e":"depthUpdate","E":1788407312914,"s":"BTCUSDT","U":99603292049,"u":99603292065,"b":[["77669.86000000","7.16298000"],["77669.53000000","0.53388000"],["77669.50000000","0.00000000"],["77666.85000000","0.03280000"],["77632.00000000","0.73007000"],["77631.00000000","0.01000000"],["69902.88000000","0.00464000"],["62136.00000000","0.00015000"]],"a":[["77675.11000000","0.00532000"],["78058.22000000","0.00034000"]]}}
{"type":"depth","received_at_ms":1788407312811,"data":{"e":"depthUpdate","E":1788407313014,"s":"BTCUSDT","U":99603292066,"u":99603292083,"b":[["77669.86000000","7.16298000"],["77669.85000000","0.00070000"],["77631.25000000","0.12880000"],["76863.05000000","0.00007000"],["76504.81000000","0.00030000"],["69902.88000000","0.00448000"],["62136.00000000","0.00015000"],["62135.89000000","0.00032000"]],"a":[["78834.92000000","0.00030000"]]}}
{"type":"depth","received_at_ms":1788407312911,"data":{"e":"depthUpdate","E":1788407313114,"s":"BTCUSDT","U":99603292084,"u":99603292094,"b":[["77669.81000000","0.00014000"],["77669.80000000","0.05496000"],["77665.12000000","0.00000000"],["77647.48000000","0.04643000"],["77644.83000000","0.00000000"],["77631.25000000","0.00000000"],["69902.88000000","0.00464000"]],"a":[["77669.87000000","2.23088000"]]}}
{"type":"depth","received_at_ms":1788407313011,"data":{"e":"depthUpdate","E":1788407313214,"s":"BTCUSDT","U":99603292095,"u":99603292105,"b":[["77669.86000000","7.16298000"],["69902.88000000","0.00448000"],["69902.87000000","0.00016000"],["62135.89000000","0.00000000"]],"a":[["77669.87000000","2.23049000"],["77678.90000000","0.00000000"],["77678.91000000","0.00257000"]]}}
{"type":"depth","received_at_ms":1788407313111,"data":{"e":"depthUpdate","E":1788407313314,"s":"BTCUSDT","U":99603292106,"u":99603292118,"b":[["77669.86000000","7.16305000"],["77669.85000000","0.00077000"],["69902.88000000","0.00464000"],["62136.00000000","0.00015000"],["62135.89000000","0.00000000"]],"a":[["77678.91000000","0.00000000"],["77678.92000000","0.00257000"]]}}
{"type":"depth","received_at_ms":1788407313210,"data":{"e":"depthUpdate","E":1788407313414,"s":"BTCUSDT","U":99603292119,"u":99603292129,"b":[["77655.55000000","0.00007000"],["69902.88000000","0.00448000"],["69902.87000000","0.00032000"],["62136.00000000","0.00015000"]],"a":[["77686.62000000","0.00007000"]]}}
{"type":"depth","received_at_ms":1788407313311,"data":{"e":"depthUpdate","E":1788407313514,"s":"BTCUSDT","U":99603292130,"u":99603292132,"b":[["69902.88000000","0.00448000"],["62135.89000000","0.00032000"]],"a":[]}}
{"type":"depth","received_at_ms":1788407313412,"data":{"e":"depthUpdate","E":1788407313614,"s":"BTCUSDT","U":99603292133,"u":99603292138,"b":[["69902.88000000","0.00457000"],["62135.89000000","0.00000000"]],"a":[["77669.87000000","2.21195000"],["77678.92000000","0.00000000"]]}}
{"type":"depth","received_at_ms":1788407313511,"data":{"e":"depthUpdate","E":1788407313714,"s":"BTCUSDT","U":99603292139,"u":99603292144,"b":[["77669.86000000","7.16298000"],["69902.88000000","0.00457000"]],"a":[["77678.93000000","0.00257000"]]}}
{"type":"depth","received_at_ms":1788407313611,"data":{"e":"depthUpdate","E":1788407313814,"s":"BTCUSDT","U":99603292145,"u":99603292146,"b":[["76716.45000000","0.00000000"],["76250.56000000","0.00000000"],["75784.67000000","0.00000000"],["75318.78000000","0.00000000"],["74852.89000000","0.00000000"],["74387.00000000","0.00069000"],["73921.11000000","0.00000000"],["73455.23000000","0.00000000"],["72989.34000000","0.00000000"],["72523.45000000","0.00000000"],["69902.88000000","0.00441000"]],"a":[]}}
{"type":"depth","received_at_ms":1788407313711,"data":{"e":"depthUpdate","E":1788407313914,"s":"BTCUSDT","U":99603292147,"u":99603292155,"b":[["77632.00000000","0.03007000"],["77355.08000000","0.00000000"],["77275.66000000","0.00000000"],["77196.24000000","0.00000000"],["69902.88000000","0.00457000"]],"a":[["77678.93000000","0.00000000"],["77722.66000000","0.00000000"]]}}
{"type":"depth","received_at_ms":1788407313811,"data":{"e":"depthUpdate","E":1788407314014,"s":"BTCUSDT","U":99603292156,"u":99603292162,"b":[["69902.88000000","0.00464000"],["69902.87000000","0.00041000"],["62135.89000000","0.00032000"]],"a":[["77669.87000000","2.20936000"],["77675.11000000","0.00000000"]]}}
{"type":"depth","received_at_ms":1788407313911,"data":{"e":"depthUpdate","E":1788407314114,"s":"BTCUSDT","U":99603292163,"u":99603292172,"b":[["77633.44000000","0.00000000"],["76504.81000000","0.00030000"],["69902.88000000","0.00432000"]],"a":[["77722.71000000","0.00000000"],["78834.92000000","0.00030000"]]}}
{"type":"depth","received_at_ms":1788407314011,"data":{"e":"depthUpdate","E":1788407314214,"s":"BTCUSDT","U":99603292173,"u":99603292177,"b":[["77666.38000000","0.00000000"],["77665.75000000","0.00400000"],["69902.88000000","0.00464000"],["62135.89000000","0.00000000"]],"a":[]}}
{"type":"depth","received_at_ms":1788407314110,"data":{"e":"depthUpdate","E":1788407314314,"s":"BTCUSDT","U":99603292178,"u":99603292191,"b":[["77669.86000000","7.16291000"],["69902.88000000","0.00432000"],["62136.00000000","0.00015000"],["62135.89000000","0.00000000"]],"a":[["77669.87000000","2.19904000"],["86000.00000000","16.31144000"]]}}
{"type":"depth","received_at_ms":1788407314212,"data":{"e":"depthUpdate","E":1788407314415,"s":"BTCUSDT","U":99603292192,"u":99603292199,"b":[["77655.55000000","0.00000000"],["77631.00000000","0.71000000"],["77355.08000000","2.50000000"],["69902.88000000","0.00448000"]],"a":[["77686.62000000","0.00000000"],["77695.00000000","0.70000000"],["77696.00000000","0.03265000"]]}}
{"type":"depth","received_at_ms":1788407314311,"data":{"e":"depthUpdate","E":1788407314514,"s":"BTCUSDT","U":99603292200,"u":99603292204,"b":[["77655.55000000","0.00007000"],["69902.88000000","0.00432000"],["62135.89000000","0.00032000"]],"a":[["77676.40000000","0.00531000"],["77686.62000000","0.00007000"]]}}
{"type":"depth","received_at_ms":1788407314410,"data":{"e":"depthUpdate","E":1788407314614,"s":"BTCUSDT","U":99603292205,"u":99603292208,"b":[["69902.88000000","0.00448000"],["62135.89000000","0.00000000"]],"a":[]}}
{"type":"depth","received_at_ms":1788407314511,"data":{"e":"depthUpdate","E":1788407314714,"s":"BTCUSDT","U":99603292209,"u":99603292214,"b":[["77648.24000000","0.00012000"],["77633.13000000","0.12880000"],["69902.88000000","0.00432000"]],"a":[["77722.74000000","0.12880000"]]}}
{"type":"depth","received_at_ms":1788407314611,"data":{"e":"depthUpdate","E":1788407314814,"s":"BTCUSDT","U":99603292215,"u":99603292220,"b":[["77668.70000000","0.00530000"],["69902.88000000","0.00448000"],["69902.87000000","0.00057000"],["62136.00000000","0.00015000"]],"a":[["77703.39000000","0.09493000"]]}}
{"type":"depth","received_at_ms":1788407314711,"data":{"e":"depthUpdate","E":1788407314914,"s":"BTCUSDT","U":99603292221,"u":99603292237,"b":[["77669.86000000","7.16290000"],["77669.85000000","0.00084000"],["77669.80000000","0.05510000"],["77669.53000000","0.53388000"],["77666.85000000","0.03266000"],["77275.66000000","2.50000000"],["69902.88000000","0.00432000"]],"a":[]}}
{"type":"depth","received_at_ms":1788407314813,"data":{"e":"depthUpdate","E":1788407315014,"s":"BTCUSDT","U":99603292238,"u":99603292245,"b":[["77480.59000000","0.00000000"],["69902.88000000","0.00432000"],["69902.87000000","0.00073000"],["62135.89000000","0.00032000"]],"a":[["77722.74000000","0.00000000"]]}}
{"type":"depth","received_at_ms":1788407314911,"data":{"e":"depthUpdate","E":1788407315114,"s":"BTCUSDT","U":99603292246,"u":99603292262,"b":[["77669.86000000","7.16082000"],["76504.81000000","0.00030000"],["62136.00000000","0.00215000"]],"a":[["77670.36000000","0.00000000"],["77670.45000000","0.07728000"],["77670.56000000","0.00000000"],["77670.57000000","0.00014000"],["77670.92000000","0.00007000"],["77671.99000000","0.00007000"],["77676.40000000","0.00000000"],["77678.97000000","0.00257000"],["77722.57000000","0.00000000"],["78834.92000000","0.00030000"]]}}
{"type":"depth","received_at_ms":1788407315012,"data":{"e":"depthUpdate","E":1788407315216,"s":"BTCUSDT","U":99603292263,"u":99603292288,"b":[["76737.82000000","0.00043000"],["69902.88000000","0.00432000"],["62136.00000000","0.00015000"],["62135.89000000","0.00000000"]],"a":[["77669.87000000","2.19897000"],["77669.88000000","0.00098000"],["77670.54000000","0.10275000"],["77670.57000000","0.00000000"],["77674.00000000","0.03014000"],["77676.46000000","0.00534000"],["77678.97000000","0.00000000"],["77678.98000000","0.00257000"],["77722.41000000","0.00000000"],["77722.45000000","0.00000000"]]}}
{"type":"depth","received_at_ms":1788407315111,"data":{"e":"depthUpdate","E":1788407315314,"s":"BTCUSDT","U":99603292289,"u":99603292300,"b":[["77633.13000000","0.00000000"],["77484.55000000","0.00135000"],["69902.88000000","0.00448000"],["62136.00000000","0.00015000"],["62135.89000000","0.00000000"]],"a":[["77670.92000000","0.00014000"]]}}
{"type":"depth","received_at_ms":1788407315211,"data":{"e":"depthUpdate","E":1788407315415,"s":"BTCUSDT","U":99603292301,"u":99603292310,"b":[["77669.86000000","7.16089000"],["77669.15000000","0.00047000"],["77668.38000000","0.00000000"],["77667.26000000","0.00400000"],["77665.75000000","0.00000000"],["77196.24000000","2.50000000"],["69902.88000000","0.00416000"]],"a":[["77676.46000000","0.00000000"],["77680.48000000","0.00000000"],["77682.06000000","0.00200000"]]}}
{"type":"depth","received_at_ms":1788407315310,"data":{"e":"depthUpdate","E":1788407315514,"s":"BTCUSDT","U":99603292311,"u":99603292322,"b":[["77669.86000000","7.16096000"],["77667.26000000","0.00000000"],["77666.78000000","0.00400000"],["77655.55000000","0.00007000"],["76271.80000000","0.00043000"],["69902.88000000","0.00448000"],["62135.89000000","0.00032000"]],"a":[["77678.98000000","0.00000000"],["77678.99000000","0.00257000"],["77686.62000000","0.00007000"]]}}
{"type":"depth","received_at_ms":1788407315411,"data":{"e":"depthUpdate","E":1788407315614,"s":"BTCUSDT","U":99603292323,"u":99603292333,"b":[["77669.86000000","7.16089000"],["69902.88000000","0.00432000"],["69902.87000000","0.00064000"],["62136.00000000","0.00015000"],["62135.89000000","0.00000000"]],"a":[["77669.87000000","2.19622000"]]}}
{"type":"depth","received_at_ms":1788407315510,"data":{"e":"depthUpdate","E":1788407315714,"s":"BTCUSDT","U":99603292334,"u":99603292339,"b":[["77669.86000000","7.16089000"],["77666.78000000","0.00000000"],["77666.29000000","0.00400000"],["69902.88000000","0.00432000"]],"a":[]}}
{"type":"depth","received_at_ms":1788407315610,"data":{"e":"depthUpdate","E":1788407315814,"s":"BTCUSDT","U":99603292340,"u":99603292343,"b":[["77669.86000000","7.16081000"],["75805.78000000","0.00043000"],["69902.88000000","0.00432000"]],"a":[]}}
{"type":"depth","received_at_ms":1788407315710,"data":{"e":"depthUpdate","E":1788407315914,"s":"BTCUSDT","U":99603292344,"u":99603292357,"b":[["77669.86000000","7.16297000"],["69902.88000000","0.00448000"]],"a":[["77669.87000000","2.19636000"],["77669.88000000","0.00105000"],["77671.31000000","0.00007000"],["77671.32000000","0.09989000"],["77671.40000000","0.00208000"],["77722.02000000","0.12880000"]]}}
{"type":"depth","received_at_ms":1788407315811,"data":{"e":"depthUpdate","E":1788407316014,"s":"BTCUSDT","U":99603292358,"u":99603292390,"b":[["77669.86000000","7.15990000"],["77669.85000000","0.00077000"],["77669.15000000","0.00000000"],["77668.70000000","0.00000000"],["77668.51000000","0.00038000"],["77666.14000000","0.00643000"],["77665.13000000","0.00000000"],["77664.74000000","0.00000000"],["77664.61000000","0.00643000"],["77632.12000000","0.12880000"],["77599.20000000","0.00321000"],["77594.31000000","0.00318000"],["77592.66000000","0.00000000"],["77588.79000000","0.00000000"],["77521.67000000","0.00128000"],["77517.58000000","0.00128000"],["77508.01000000","0.00000000"],["77500.65000000","0.00007000"],["69902.88000000","0.00432000"],["69902.87000000","0.00073000"],["62136.00000000","0.00015000"],["62135.89000000","0.00032000"]],"a":[["77670.54000000","0.10275000"],["77671.32000000","0.10003000"],["77674.00000000","0.03000000"],["77676.48000000","0.00540000"],["77678.62000000","0.26292000"],["77678.99000000","0.00000000"],["77686.94000000","0.00000000"],["77722.02000000","0.00000000"],["77797.06000000","0.00000000"],["77804.27000000","0.00128000"],["77804.28000000","0.00000000"],["77805.57000000","0.00128000"]]}}
{"type":"depth","received_at_ms":1788407315911,"data":{"e":"depthUpdate","E":1788407316114,"s":"BTCUSDT","U":99603292391,"u":99603292411,"b":[["77669.86000000","7.16004000"],["77669.53000000","0.53388000"],["77666.85000000","0.03273000"],["77665.90000000","0.19034000"],["77665.11000000","0.12882000"],["77632.44000000","0.00007000"],["77632.12000000","0.00000000"],["76504.81000000","0.00030000"],["75339.76000000","0.00044000"],["69902.88000000","0.00448000"]],"a":[["77721.77000000","0.00000000"],["77722.02000000","0.12880000"],["78834.92000000","0.00030000"]]}}
{"type":"depth","received_at_ms":1788407316010,"data":{"e":"depthUpdate","E":1788407316214,"s":"BTCUSDT","U":99603292412,"u":99603292418,"b":[["77632.81000000","0.00000000"],["69902.88000000","0.00432000"],["62135.89000000","0.00000000"]],"a":[["77678.62000000","0.25649000"],["77679.29000000","0.00643000"]]}}
{"type":"depth","received_at_ms":1788407316110,"data":{"e":"depthUpdate","E":1788407316314,"s":"BTCUSDT","U":99603292419,"u":99603292429,"b":[["77669.86000000","7.15706000"],["77665.29000000","0.00257000"],["77664.04000000","0.00000000"],["77632.19000000","0.12880000"],["69902.88000000","0.00448000"],["69902.87000000","0.00064000"],["69902.86000000","0.00009000"],["62136.00000000","0.00015000"]],"a":[]}}
{"type":"depth","received_at_ms":1788407316210,"data":{"e":"depthUpdate","E":1788407316414,"s":"BTCUSDT","U":99603292430,"u":99603292442,"b":[["77632.69000000","0.00000000"],["77632.19000000","0.00000000"],["77632.18000000","0.12896000"],["69902.88000000","0.00432000"],["62135.89000000","0.00000000"]],"a":[["77669.87000000","2.18350000"],["77670.54000000","0.10927000"]]}}
{"type":"depth","received_at_ms":1788407316311,"data":{"e":"depthUpdate","E":1788407316514,"s":"BTCUSDT","U":99603292443,"u":99603292456,"b":[["77655.55000000","0.00007000"],["77632.18000000","0.00016000"],["77632.12000000","0.00000000"],["74873.74000000","0.00044000"],["69902.88000000","0.00432000"],["62135.89000000","0.00032000"]],"a":[["77679.99000000","0.00200000"],["77682.06000000","0.00000000"],["77686.62000000","0.00007000"]]}}
{"type":"depth","received_at_ms":1788407316410,"data":{"e":"depthUpdate","E":1788407316614,"s":"BTCUSDT","U":99603292457,"u":99603292465,"b":[["77632.29000000","0.00000000"],["77631.89000000","0.12880000"],["77489.59000000","0.00000000"],["71456.28000000","0.00014000"],["69902.88000000","0.00432000"],["62135.89000000","0.00000000"]],"a":[["77848.25000000","0.00000000"]]}}
{"type":"depth","received_at_ms":1788407316510,"data":{"e":"depthUpdate","E":1788407316714,"s":"BTCUSDT","U":99603292466,"u":99603292470,"b":[["77631.89000000","0.00000000"],["69902.88000000","0.00432000"],["62136.00000000","0.00015000"]],"a":[]}}
{"type":"depth","received_at_ms":1788407316611,"data":{"e":"depthUpdate","E":1788407316814,"s":"BTCUSDT","U":99603292471,"u":99603292477,"b":[["77631.49000000","0.12880000"],["77489.34000000","4.52649000"],["74407.73000000","0.00044000"],["69902.88000000","0.00448000"]],"a":[["77846.11000000","4.49665000"]]}}
{"type":"depth","received_at_ms":1788407316710,"data":{"e":"depthUpdate","E":1788407316914,"s":"BTCUSDT","U":99603292478,"u":99603292485,"b":[["77669.86000000","7.15698000"],["77668.94000000","0.00534000"],["75561.73000000","0.00000000"],["69902.88000000","0.00432000"]],"a":[["81006.07000000","0.00000000"]]}}
{"type":"depth","received_at_ms":1788407316811,"data":{"e":"depthUpdate","E":1788407317014,"s":"BTCUSDT","U":99603292486,"u":99603292495,"b":[["77669.86000000","7.15706000"],["77669.53000000","0.53388000"],["69902.88000000","0.00432000"],["62135.89000000","0.00032000"]],"a":[["77669.87000000","2.25135000"]]}}
{"type":"depth","received_at_ms":1788407316910,"data":{"e":"depthUpdate","E":1788407317114,"s":"BTCUSDT","U":99603292496,"u":99603292508,"b":[["77669.86000000","7.15713000"],["77669.85000000","0.00084000"],["77658.32000000","0.32967000"],["77649.42000000","0.00000000"],["77531.54000000","0.00000000"],["76504.81000000","0.00030000"],["73941.71000000","0.00045000"],["69902.88000000","0.00432000"]],"a":[["77680.06000000","0.00257000"],["78834.92000000","0.00030000"]]}}
{"type":"depth","received_at_ms":1788407317011,"data":{"e":"depthUpdate","E":1788407317214,"s":"BTCUSDT","U":99603292509,"u":99603292514,"b":[["77537.72000000","0.02017000"],["71456.28000000","0.00000000"],["69902.88000000","0.00448000"],["62135.89000000","0.00000000"]],"a":[]}}
{"type":"depth","received_at_ms":1788407317110,"data":{"e":"depthUpdate","E":1788407317314,"s":"BTCUSDT","U":99603292515,"u":99603292531,"b":[["77669.86000000","7.12494000"],["77669.53000000","0.53395000"],["77666.85000000","0.03266000"],["77666.56000000","0.00643000"],["77666.14000000","0.00000000"],["77281.51000000","0.00007000"],["69902.88000000","0.00416000"],["69902.86000000","0.00000000"],["62136.00000000","0.00015000"]],"a":[["77669.87000000","2.24435000"],["77679.99000000","0.00000000"],["77680.06000000","0.00000000"],["77680.07000000","0.00257000"],["77681.36000000","0.00200000"]]}}
{"type":"depth","received_at_ms":1788407317210,"data":{"e":"depthUpdate","E":1788407317414,"s":"BTCUSDT","U":99603292532,"u":99603292541,"b":[["77669.86000000","7.15713000"],["77587.64000000","0.00484000"],["77553.45000000","0.00000000"],["69902.88000000","0.00448000"],["62135.89000000","0.00000000"]],"a":[["77669.87000000","2.24450000"]]}}
{"type":"depth","received_at_ms":1788407317310,"data":{"e":"depthUpdate","E":1788407317514,"s":"BTCUSDT","U":99603292542,"u":99603292549,"b":[["77655.55000000","0.00007000"],["73475.69000000","0.00045000"],["69902.88000000","0.00432000"],["62135.89000000","0.00032000"]],"a":[["77686.62000000","0.00007000"]]}}
{"type":"depth","received_at_ms":1788407317410,"data":{"e":"depthUpdate","E":1788407317614,"s":"BTCUSDT","U":99603292550,"u":99603292554,"b":[["77669.15000000","0.00037000"],["77668.51000000","0.00000000"],["69902.88000000","0.00448000"],["62135.89000000","0.00000000"]],"a":[]}}
{"type":"depth","received_at_ms":1788407317511,"data":{"e":"depthUpdate","E":1788407317714,"s":"BTCUSDT","U":99603292555,"u":99603292562,"b":[["77669.86000000","7.16364000"],["77665.30000000","0.00643000"],["77664.61000000","0.00000000"],["69902.88000000","0.00432000"]],"a":[["77679.29000000","0.00000000"],["77679.57000000","0.00643000"],["77680.07000000","0.00000000"],["77680.08000000","0.00257000"],["77701.17000000","0.34762000"],["77720.07000000","0.00000000"]]}}
{"type":"depth","received_at_ms":1788407317611,"data":{"e":"depthUpdate","E":1788407317814,"s":"BTCUSDT","U":99603292563,"u":99603292577,"b":[["77669.86000000","7.16371000"],["77667.08000000","0.00400000"],["77665.57000000","0.00000000"],["77654.73000000","0.07308000"],["75561.73000000","0.00010000"],["73009.67000000","0.00045000"],["69902.88000000","0.00457000"],["62136.00000000","0.00015000"]],"a":[["77669.87000000","2.24437000"],["77677.55000000","0.00000000"],["77678.03000000","0.00400000"]]}}
{"type":"depth","received_at_ms":1788407317711,"data":{"e":"depthUpdate","E":1788407317914,"s":"BTCUSDT","U":99603292578,"u":99603292580,"b":[["69902.88000000","0.00441000"]],"a":[]}}
{"type":"depth","received_at_ms":1788407317813,"data":{"e":"depthUpdate","E":1788407318015,"s":"BTCUSDT","U":99603292581,"u":99603292586,"b":[["69902.88000000","0.00441000"],["62135.89000000","0.00032000"]],"a":[["77680.08000000","0.00000000"],["77680.09000000","0.00257000"],["81006.07000000","0.00010000"]]}}
{"type":"depth","received_at_ms":1788407317910,"data":{"e":"depthUpdate","E":1788407318114,"s":"BTCUSDT","U":99603292587,"u":99603292596,"b":[["77669.86000000","7.16364000"],["77669.15000000","0.00000000"],["77668.62000000","0.00037000"],["77666.56000000","0.00000000"],["77666.30000000","0.00643000"],["76504.81000000","0.00030000"],["69902.88000000","0.00441000"],["62136.00000000","0.00215000"]],"a":[["78834.92000000","0.00030000"]]}}
{"type":"depth","received_at_ms":1788407318012,"data":{"e":"depthUpdate","E":1788407318214,"s":"BTCUSDT","U":99603292597,"u":99603292793,"b":[["77669.86000000","4.40760000"],["77669.85000000","0.00063000"],["77669.81000000","0.00000000"],["77669.80000000","0.00014000"],["77669.55000000","0.00014000"],["77669.54000000","0.34546000"],["77669.53000000","0.53388000"],["77668.94000000","0.00000000"],["77668.62000000","0.00000000"],["77668.50000000","0.00000000"],["77667.76000000","0.00027000"],["77667.72000000","0.00000000"],["77667.61000000","0.00041000"],["77667.08000000","0.00000000"],["77667.07000000","0.00000000"],["77667.06000000","0.00007000"],["77667.03000000","0.00400000"],["77666.55000000","0.00000000"],["77666.52000000","0.00400000"],["77666.30000000","0.00000000"],["77666.29000000","0.00000000"],["77666.01000000","0.00000000"],["77665.37000000","0.00644000"],["77665.36000000","0.00160000"],["77665.30000000","0.00000000"],["77665.29000000","0.00000000"],["77665.19000000","0.00000000"],["77665.11000000","0.00014000"],["77664.40000000","0.00000000"],["77664.27000000","0.00007000"],["77664.25000000","0.41269000"],["77663.60000000","0.02007000"],["77663.24000000","0.00078000"],["77663.20000000","0.00007000"],["77662.41000000","0.00644000"],["77662.09000000","0.00000000"],["77660.89000000","0.00000000"],["77659.34000000","0.00014000"],["77659.06000000","0.01200000"],["77659.05000000","0.01400000"],["77658.69000000","0.03210000"],["77658.40000000","0.00000000"],["77656.31000000","0.30866000"],["77656.30000000","0.30000000"],["77649.09000000","0.28370000"],["77648.49000000","0.30866000"],["77648.00000000","0.00265000"],["77647.63000000","0.00000000"],["77647.48000000","0.00000000"],["77647.07000000","0.25760000"],["77641.59000000","0.00200000"],["77641.44000000","0.00000000"],["77640.49000000","0.30866000"],["77640.00000000","0.03446000"],["77639.26000000","0.00000000"],["77638.81000000","0.44181000"],["77637.71000000","0.00000000"],["77635.91000000","0.00000000"],["77635.75000000","0.00858000"],["77635.35000000","0.00400000"],["77635.33000000","0.00000000"],["77633.40000000","0.00427000"],["77631.45000000","0.00000000"],["77631.00000000","0.01000000"],["77624.78000000","0.04765000"],["77616.74000000","0.34800000"],["77587.64000000","0.00000000"],["77583.76000000","0.00000000"],["77581.21000000","0.72120000"],["72543.65000000","0.00045000"],["69902.88000000","0.00441000"],["62136.00000000","0.00015000"],["62135.89000000","0.00000000"]],"a":[["77669.87000000","2.24437000"],["77669.88000000","0.00091000"],["77670.92000000","0.00007000"],["77671.31000000","0.00000000"],["77671.32000000","0.00014000"],["77671.40000000","0.00000000"],["77672.18000000","0.00000000"],["77672.40000000","0.00400000"],["77672.62000000","0.03180000"],["77673.68000000","0.00000000"],["77674.22000000","0.00000000"],["77674.35000000","0.00400000"],["77674.50000000","0.50247000"],["77674.51000000","0.00000000"],["77675.95000000","0.00400000"],["77676.05000000","0.00000000"],["77676.52000000","0.00000000"],["77676.93000000","1.15151000"],["77677.08000000","0.00400000"],["77677.30000000","0.00000000"],["77677.52000000","0.00000000"],["77677.59000000","0.00000000"],["77678.03000000","0.00000000"],["77678.13000000","0.00007000"],["77678.24000000","0.00000000"],["77678.44000000","0.00000000"],["77678.62000000","1.96118000"],["77679.29000000","0.00644000"],["77679.56000000","0.00000000"],["77679.57000000","0.00000000"],["77679.58000000","0.00000000"],["77679.86000000","0.00200000"],["77679.98000000","0.00257000"],["77679.99000000","4.63500000"],["77680.09000000","0.00000000"],["77680.98000000","1.15151000"],["77680.99000000","0.00000000"],["77681.36000000","0.00400000"],["77681.37000000","0.00000000"],["77682.21000000","0.01200000"],["77682.22000000","0.00000000"],["77703.60000000","0.00000000"],["77705.55000000","0.00000000"],["77766.99000000","0.93394000"],["77769.26000000","0.00000000"]]}}
{"type":"depth","received_at_ms":1788407318111,"data":{"e":"depthUpdate","E":1788407318314,"s":"BTCUSDT","U":99603292794,"u":99603292917,"b":[["77669.86000000","4.51026000"],["77669.85000000","0.00077000"],["77669.80000000","0.00000000"],["77669.53000000","0.53388000"],["77668.61000000","0.01705000"],["77667.91000000","0.00516000"],["77667.06000000","0.00014000"],["77666.91000000","0.00000000"],["77666.85000000","0.03280000"],["77666.55000000","0.00400000"],["77666.53000000","0.00643000"],["77666.52000000","0.00000000"],["77666.34000000","0.00400000"],["77665.88000000","0.00257000"],["77665.66000000","0.00000000"],["77665.56000000","0.03210000"],["77663.20000000","0.00014000"],["77662.41000000","0.00000000"],["77660.72000000","0.00000000"],["77660.49000000","0.00000000"],["77659.06000000","0.01400000"],["77659.05000000","0.01200000"],["77656.31000000","0.60866000"],["77643.54000000","0.00200000"],["77641.59000000","0.00000000"],["77637.30000000","0.00400000"],["77635.35000000","0.00000000"],["77633.40000000","0.00027000"],["77572.18000000","0.00000000"],["77281.51000000","0.00000000"],["69902.88000000","0.00457000"],["62136.00000000","0.00015000"]],"a":[["77669.87000000","2.11551000"],["77670.45000000","0.11051000"],["77670.54000000","0.10927000"],["77671.32000000","0.00000000"],["77672.00000000","0.03014000"],["77672.62000000","0.03194000"],["77672.71000000","0.09989000"],["77673.52000000","0.00000000"],["77674.50000000","0.18652000"],["77675.95000000","0.00000000"],["77676.78000000","0.00000000"],["77676.92000000","0.02200000"],["77676.93000000","0.00000000"],["77677.08000000","0.00000000"],["77677.19000000","0.00000000"],["77677.57000000","0.00400000"],["77677.59000000","0.00000000"],["77678.33000000","0.10022000"],["77678.61000000","0.09224000"],["77678.62000000","0.52420000"],["77679.29000000","0.00000000"],["77679.86000000","0.00000000"],["77679.98000000","0.00000000"],["77679.99000000","0.00000000"],["77680.23000000","0.00643000"],["77681.36000000","0.00000000"],["77682.21000000","0.00000000"],["77685.29000000","4.63500000"],["77709.52000000","0.00007000"],["77805.26000000","0.00000000"]]}}
{"type":"depth","received_at_ms":1788407318211,"data":{"e":"depthUpdate","E":1788407318414,"s":"BTCUSDT","U":99603292918,"u":99603292971,"b":[["77669.86000000","4.55219000"],["77668.61000000","0.01705000"],["77667.91000000","0.00530000"],["77666.85000000","0.03273000"],["77665.90000000","0.19034000"],["77665.56000000","0.03217000"],["77665.10000000","0.00000000"],["77665.09000000","0.00000000"],["77663.23000000","0.00000000"],["77660.89000000","0.00000000"],["77659.06000000","0.01200000"],["77659.05000000","0.01400000"],["77654.73000000","0.00000000"],["77566.49000000","0.03993000"],["69902.88000000","0.00441000"],["62136.00000000","0.00015000"],["62135.89000000","0.00000000"]],"a":[["77669.87000000","2.11544000"],["77672.40000000","0.00000000"],["77672.62000000","0.03194000"],["77675.64000000","0.00027000"],["77676.92000000","0.00400000"],["77680.97000000","0.01800000"],["77684.79000000","0.00000000"],["77707.50000000","0.00400000"],["77799.55000000","0.00971000"]]}}
{"type":"depth","received_at_ms":1788407318311,"data":{"e":"depthUpdate","E":1788407318514,"s":"BTCUSDT","U":99603292972,"u":99603292982,"b":[["77665.88000000","0.00000000"],["77660.89000000","0.00200000"],["77659.05000000","0.01200000"],["69902.88000000","0.00457000"],["62135.89000000","0.00032000"]],"a":[["77673.37000000","0.00208000"],["77678.62000000","0.52020000"],["77679.01000000","0.00400000"]]}}
{"type":"depth","received_at_ms":1788407318410,"data":{"e":"depthUpdate","E":1788407318614,"s":"BTCUSDT","U":99603292983,"u":99603293002,"b":[["77669.86000000","4.55226000"],["77669.85000000","0.00084000"],["77667.58000000","0.00257000"],["77660.89000000","0.00000000"],["77659.24000000","0.00200000"],["77655.55000000","0.00007000"],["69902.88000000","0.00441000"],["62136.00000000","0.00015000"],["62135.89000000","0.00000000"]],"a":[["77669.87000000","2.11551000"],["77672.00000000","0.03021000"],["77686.62000000","0.00007000"]]}}
{"type":"depth","received_at_ms":1788407318512,"data":{"e":"depthUpdate","E":1788407318715,"s":"BTCUSDT","U":99603293003,"u":99603293007,"b":[["77500.00000000","0.48017000"],["69902.88000000","0.00457000"]],"a":[["77684.88000000","0.34844000"]]}}
{"type":"depth","received_at_ms":1788407318611,"data":{"e":"depthUpdate","E":1788407318814,"s":"BTCUSDT","U":99603293008,"u":99603293015,"b":[["77667.76000000","0.00000000"],["77666.10000000","0.00027000"],["77631.00000000","0.71000000"],["69902.88000000","0.00441000"]],"a":[["77669.87000000","2.13559000"]]}}
{"type":"depth","received_at_ms":1788407318710,"data":{"e":"depthUpdate","E":1788407318914,"s":"BTCUSDT","U":99603293016,"u":99603293022,"b":[["77669.86000000","4.55226000"],["69902.88000000","0.00441000"]],"a":[["77669.87000000","2.13583000"]]}}
{"type":"depth","received_at_ms":1788407318811,"data":{"e":"depthUpdate","E":1788407319014,"s":"BTCUSDT","U":99603293023,"u":99603293029,"b":[["77666.56000000","0.00067000"],["77666.53000000","0.00000000"],["77666.01000000","0.00643000"],["77663.24000000","0.00000000"],["69902.88000000","0.00441000"],["62136.00000000","0.00015000"],["62135.89000000","0.00032000"]],"a":[]}}
{"type":"depth","received_at_ms":1788407318910,"data":{"e":"depthUpdate","E":1788407319115,"s":"BTCUSDT","U":99603293030,"u":99603293041,"b":[["77669.86000000","4.55219000"],["77666.85000000","0.03266000"],["77666.13000000","0.02028000"],["77663.60000000","0.02000000"],["76504.81000000","0.00030000"],["69902.88000000","0.00457000"]],"a":[["77672.62000000","0.03201000"],["78834.92000000","0.00030000"]]}}
{"type":"depth","received_at_ms":1788407319011,"data":{"e":"depthUpdate","E":1788407319214,"s":"BTCUSDT","U":99603293042,"u":99603293044,"b":[["69902.88000000","0.00425000"],["62135.89000000","0.00000000"]],"a":[]}}
{"type":"depth","received_at_ms":1788407319111,"data":{"e":"depthUpdate","E":1788407319314,"s":"BTCUSDT","U":99603293045,"u":99603293053,"b":[["77669.86000000","4.55212000"],["77666.34000000","0.00000000"],["77665.61000000","0.00400000"],["77643.54000000","0.00000000"],["69902.88000000","0.00457000"],["62136.00000000","0.00015000"]],"a":[["77682.08000000","0.00257000"]]}}
{"type":"depth","received_at_ms":1788407319210,"data":{"e":"depthUpdate","E":1788407319414,"s":"BTCUSDT","U":99603293054,"u":99603293072,"b":[["77666.13000000","0.02021000"],["77666.01000000","0.00000000"],["77665.56000000","0.03224000"],["77665.38000000","0.00643000"],["77642.17000000","0.00200000"],["69902.88000000","0.00457000"],["62136.00000000","0.00015000"],["62135.89000000","0.00000000"]],"a":[["77705.55000000","0.00400000"],["77707.50000000","0.00000000"],["77708.88000000","0.00000000"]]}}
{"type":"depth","received_at_ms":1788407319310,"data":{"e":"depthUpdate","E":1788407319514,"s":"BTCUSDT","U":99603293073,"u":99603293077,"b":[["69902.88000000","0.00457000"],["62135.89000000","0.00032000"]],"a":[]}}
{"type":"depth","received_at_ms":1788407319411,"data":{"e":"depthUpdate","E":1788407319614,"s":"BTCUSDT","U":99603293078,"u":99603293081,"b":[["77655.55000000","0.00007000"],["62135.89000000","0.00000000"]],"a":[["77686.62000000","0.00007000"]]}}
{"type":"depth","received_at_ms":1788407319510,"data":{"e":"depthUpdate","E":1788407319714,"s":"BTCUSDT","U":99603293082,"u":99603293085,"b":[["69902.88000000","0.00457000"]],"a":[]}}
{"type":"depth","received_at_ms":1788407319611,"data":{"e":"depthUpdate","E":1788407319814,"s":"BTCUSDT","U":99603293086,"u":99603293093,"b":[["77669.86000000","4.55865000"],["77588.24000000","0.52788000"],["77586.31000000","0.72120000"],["77581.21000000","0.00000000"],["69902.88000000","0.00473000"]],"a":[]}}
{"type":"depth","received_at_ms":1788407319710,"data":{"e":"depthUpdate","E":1788407319914,"s":"BTCUSDT","U":99603293094,"u":99603293096,"b":[["77632.00000000","0.73007000"],["77631.00000000","0.01000000"],["69902.88000000","0.00457000"]],"a":[]}}
{"type":"depth","received_at_ms":1788407319811,"data":{"e":"depthUpdate","E":1788407320014,"s":"BTCUSDT","U":99603293097,"u":99603293100,"b":[["69902.88000000","0.00473000"],["62135.89000000","0.00032000"]],"a":[]}}
{"type":"depth","received_at_ms":1788407319911,"data":{"e":"depthUpdate","E":1788407320114,"s":"BTCUSDT","U":99603293101,"u":99603293107,"b":[["76504.81000000","0.00030000"],["69902.88000000","0.00457000"]],"a":[["78834.92000000","0.00030000"]]}}
{"type":"depth","received_at_ms":1788407320010,"data":{"e":"depthUpdate","E":1788407320214,"s":"BTCUSDT","U":99603293108,"u":99603293109,"b":[["69902.88000000","0.00473000"],["62135.89000000","0.00000000"]],"a":[]}}
{"type":"depth","received_at_ms":1788407320117,"data":{"e":"depthUpdate","E":1788407320314,"s":"BTCUSDT","U":99603293110,"u":99603293114,"b":[["69902.88000000","0.00457000"],["62136.00000000","0.00015000"]],"a":[]}}
{"type":"depth","received_at_ms":1788407320210,"data":{"e":"depthUpdate","E":1788407320414,"s":"BTCUSDT","U":99603293115,"u":99603293120,"b":[["69902.88000000","0.00473000"],["62135.89000000","0.00020000"]],"a":[]}}
{"type":"depth","received_at_ms":1788407320311,"data":{"e":"depthUpdate","E":1788407320514,"s":"BTCUSDT","U":99603293121,"u":99603293126,"b":[["69902.88000000","0.00432000"],["69902.87000000","0.00073000"],["62135.89000000","0.00032000"]],"a":[["77669.87000000","2.12933000"]]}}
{"type":"depth","received_at_ms":1788407320414,"data":{"e":"depthUpdate","E":1788407320614,"s":"BTCUSDT","U":99603293127,"u":99603293160,"b":[["77669.86000000","9.19157000"],["77669.49000000","0.00400000"],["77669.15000000","0.00038000"],["77667.92000000","0.00643000"],["77667.61000000","0.00000000"],["77667.03000000","0.00000000"],["77666.99000000","0.00400000"],["77666.90000000","0.00643000"],["77665.61000000","0.00000000"],["77665.38000000","0.00000000"],["77665.37000000","0.00000000"],["77655.55000000","0.00000000"],["77612.70000000","4.63500000"],["77612.69000000","0.00000000"],["77602.20000000","0.00000000"],["69902.88000000","0.00464000"],["62135.89000000","0.00000000"]],"a":[["77669.87000000","2.11581000"],["77670.45000000","0.00035000"],["77672.71000000","0.00000000"],["77673.37000000","0.00000000"],["77674.78000000","0.00007000"],["77676.33000000","0.00000000"],["77676.48000000","0.00000000"],["77676.92000000","0.00000000"],["77680.23000000","0.00000000"],["77680.96000000","0.00400000"],["77686.62000000","0.00000000"],["77769.27000000","4.63500000"]]}}
{"type":"depth","received_at_ms":1788407320510,"data":{"e":"depthUpdate","E":1788407320714,"s":"BTCUSDT","U":99603293161,"u":99603293235,"b":[["77669.86000000","9.18532000"],["77669.85000000","0.00752000"],["77669.49000000","0.00000000"],["77668.95000000","0.00400000"],["77668.61000000","0.01712000"],["77667.92000000","0.00657000"],["77667.58000000","0.00000000"],["77667.37000000","0.02042000"],["77666.88000000","0.49823000"],["77665.56000000","0.03210000"],["77655.55000000","0.00007000"],["77602.78000000","0.23067000"],["69902.88000000","0.00448000"]],"a":[["77669.87000000","2.11322000"],["77669.88000000","0.00105000"],["77670.00000000","0.03028000"],["77670.44000000","0.00014000"],["77670.45000000","0.08862000"],["77670.54000000","0.10275000"],["77670.91000000","0.00620000"],["77671.99000000","0.00014000"],["77672.61000000","0.00000000"],["77672.62000000","0.03201000"],["77674.00000000","0.03014000"],["77674.78000000","0.00014000"],["77679.01000000","0.00000000"],["77681.79000000","0.00643000"],["77686.62000000","0.00007000"],["77766.99000000","2.27570000"]]}}
{"type":"depth","received_at_ms":1788407320611,"data":{"e":"depthUpdate","E":1788407320814,"s":"BTCUSDT","U":99603293236,"u":99603293272,"b":[["77669.86000000","9.18532000"],["77669.85000000","0.00745000"],["77667.55000000","0.00000000"],["77667.53000000","0.00257000"],["69902.88000000","0.00448000"],["62136.00000000","0.00015000"]],"a":[["77669.87000000","2.11274000"],["77670.00000000","0.03028000"],["77670.45000000","0.08876000"],["77670.54000000","0.10275000"],["77670.91000000","0.00634000"],["77672.62000000","0.03187000"],["77674.00000000","0.03000000"],["77678.64000000","0.00061000"],["77679.70000000","0.00400000"]]}}
{"type":"depth","received_at_ms":1788407320710,"data":{"e":"depthUpdate","E":1788407320914,"s":"BTCUSDT","U":99603293273,"u":99603293286,"b":[["77669.86000000","9.18524000"],["77667.53000000","0.00000000"],["77641.99000000","0.00000000"],["77618.07000000","0.00000000"],["69902.88000000","0.00448000"]],"a":[["77693.60000000","0.00000000"],["77717.46000000","0.65397000"],["77717.55000000","0.00431000"]]}}
{"type":"depth","received_at_ms":1788407320811,"data":{"e":"depthUpdate","E":1788407321014,"s":"BTCUSDT","U":99603293287,"u":99603293292,"b":[["77667.50000000","0.00257000"],["69902.88000000","0.00448000"],["62135.89000000","0.00032000"]],"a":[]}}
{"type":"depth","received_at_ms":1788407320911,"data":{"e":"depthUpdate","E":1788407321114,"s":"BTCUSDT","U":99603293293,"u":99603293313,"b":[["77669.86000000","9.18525000"],["77667.50000000","0.00000000"],["77667.48000000","0.00257000"],["76504.81000000","0.00030000"],["69902.88000000","0.00448000"],["62136.00000000","0.00215000"]],"a":[["77669.87000000","2.13874000"],["77669.88000000","0.00098000"],["77670.54000000","0.10865000"],["77670.91000000","0.00021000"],["77678.64000000","0.00014000"],["77697.60000000","0.04756000"],["77698.80000000","0.00000000"],["78834.92000000","0.00030000"]]}}
{"type":"depth","received_at_ms":1788407321011,"data":{"e":"depthUpdate","E":1788407321214,"s":"BTCUSDT","U":99603293314,"u":99603293338,"b":[["77669.86000000","9.18532000"],["77669.85000000","0.00098000"],["77667.91000000","0.00014000"],["77667.48000000","0.00000000"],["77667.46000000","0.00257000"],["77645.23000000","0.49542000"],["77621.94000000","0.97884000"],["69902.88000000","0.00448000"],["69902.87000000","0.00064000"],["62136.00000000","0.00015000"],["62135.89000000","0.00000000"]],"a":[["77669.87000000","2.12874000"],["77670.54000000","0.10865000"],["77670.91000000","0.00007000"],["77672.62000000","0.03201000"],["77693.89000000","0.51466000"],["77717.19000000","1.05406000"]]}}
{"type":"depth","received_at_ms":1788407321112,"data":{"e":"depthUpdate","E":1788407321315,"s":"BTCUSDT","U":99603293339,"u":99603293376,"b":[["77669.86000000","9.18525000"],["77669.85000000","0.00091000"],["77668.61000000","0.01712000"],["77668.46000000","0.00536000"],["77667.92000000","0.00657000"],["77667.91000000","0.00000000"],["77667.46000000","0.00000000"],["77667.43000000","0.00257000"],["77666.90000000","0.00657000"],["77619.62000000","0.00100000"],["77543.18000000","0.00000000"],["69902.88000000","0.00464000"],["62136.00000000","0.00015000"]],"a":[["77675.88000000","0.00665000"],["77677.57000000","0.00000000"],["77678.11000000","0.00400000"],["77682.08000000","0.00000000"],["77682.21000000","0.00257000"],["77700.26000000","0.00000000"],["77720.13000000","0.16970000"],["77854.91000000","0.00000000"],["77898.78000000","0.00100000"]]}}
{"type":"depth","received_at_ms":1788407321210,"data":{"e":"depthUpdate","E":1788407321414,"s":"BTCUSDT","U":99603293377,"u":99603293383,"b":[["77668.61000000","0.01712000"],["69902.88000000","0.00448000"]],"a":[]}}
{"type":"depth","received_at_ms":1788407321310,"data":{"e":"depthUpdate","E":1788407321514,"s":"BTCUSDT","U":99603293384,"u":99603293389,"b":[["69902.88000000","0.00464000"],["62135.89000000","0.00032000"]],"a":[]}}
{"type":"depth","received_at_ms":1788407321410,"data":{"e":"depthUpdate","E":1788407321614,"s":"BTCUSDT","U":99603293390,"u":99603293398,"b":[["69902.88000000","0.00448000"],["62136.00000000","0.00015000"],["62135.89000000","0.00000000"]],"a":[["77669.87000000","2.12808000"]]}}
{"type":"depth","received_at_ms":1788407321511,"data":{"e":"depthUpdate","E":1788407321714,"s":"BTCUSDT","U":99603293399,"u":99603293404,"b":[["77655.55000000","0.00007000"],["69902.88000000","0.00464000"]],"a":[["77686.62000000","0.00007000"]]}}
{"type":"depth","received_at_ms":1788407321612,"data":{"e":"depthUpdate","E":1788407321815,"s":"BTCUSDT","U":99603293405,"u":99603293405,"b":[["69902.88000000","0.00448000"]],"a":[]}}
{"type":"depth","received_at_ms":1788407321711,"data":{"e":"depthUpdate","E":1788407321914,"s":"BTCUSDT","U":99603293406,"u":99603293411,"b":[["69902.88000000","0.00464000"]],"a":[["77673.95000000","0.09989000"],["77707.30000000","0.32967000"],["77711.69000000","0.00000000"]]}}
{"type":"depth","received_at_ms":1788407321811,"data":{"e":"depthUpdate","E":1788407322014,"s":"BTCUSDT","U":99603293412,"u":99603293430,"b":[["77669.86000000","9.18733000"],["69902.88000000","0.00457000"],["62136.00000000","0.00015000"],["62135.89000000","0.00032000"]],"a":[["77669.87000000","2.12513000"],["77672.62000000","0.03201000"],["77673.29000000","0.00208000"]]}}
{"type":"depth","received_at_ms":1788407321910,"data":{"e":"depthUpdate","E":1788407322114,"s":"BTCUSDT","U":99603293431,"u":99603293436,"b":[["76504.81000000","0.00030000"],["69902.88000000","0.00457000"]],"a":[["78834.92000000","0.00030000"]]}}
{"type":"depth","received_at_ms":1788407322011,"data":{"e":"depthUpdate","E":1788407322214,"s":"BTCUSDT","U":99603293437,"u":99603293446,"b":[["77661.60000000","0.01200000"],["77659.05000000","0.00000000"],["71456.28000000","0.00014000"],["69902.88000000","0.00457000"],["62135.89000000","0.00000000"]],"a":[]}}
{"type":"depth","received_at_ms":1788407322110,"data":{"e":"depthUpdate","E":1788407322314,"s":"BTCUSDT","U":99603293447,"u":99603293453,"b":[["69902.88000000","0.00464000"],["69902.87000000","0.00073000"],["62136.00000000","0.00015000"]],"a":[["77669.87000000","2.12507000"]]}}
{"type":"depth","received_at_ms":1788407322211,"data":{"e":"depthUpdate","E":1788407322414,"s":"BTCUSDT","U":99603293454,"u":99603293458,"b":[["77479.21000000","0.02017000"],["77452.89000000","0.00000000"],["69902.88000000","0.00432000"]],"a":[["77669.87000000","2.12514000"]]}}
{"type":"depth","received_at_ms":1788407322310,"data":{"e":"depthUpdate","E":1788407322514,"s":"BTCUSDT","U":99603293459,"u":99603293467,"b":[["69902.88000000","0.00448000"],["62135.89000000","0.00032000"]],"a":[["77669.87000000","2.12475000"]]}}
{"type":"depth","received_at_ms":1788407322411,"data":{"e":"depthUpdate","E":1788407322614,"s":"BTCUSDT","U":99603293468,"u":99603293472,"b":[["77479.21000000","0.00000000"],["77452.89000000","0.02017000"],["69902.88000000","0.00448000"],["62135.89000000","0.00000000"]],"a":[]}}
{"type":"depth","received_at_ms":1788407322511,"data":{"e":"depthUpdate","E":1788407322714,"s":"BTCUSDT","U":99603293473,"u":99603293484,"b":[["77655.55000000","0.00007000"],["69902.88000000","0.00432000"],["62136.00000000","0.00015000"]],"a":[["77686.62000000","0.00007000"]]}}
{"type":"depth","received_at_ms":1788407322610,"data":{"e":"depthUpdate","E":1788407322814,"s":"BTCUSDT","U":99603293485,"u":99603293491,"b":[["77669.14000000","0.00000000"],["77382.00000000","0.00258000"],["75561.73000000","0.00000000"],["71456.28000000","0.00000000"],["69902.88000000","0.00448000"]],"a":[["81006.07000000","0.00000000"]]}}
{"type":"depth","received_at_ms":1788407322711,"data":{"e":"depthUpdate","E":1788407322914,"s":"BTCUSDT","U":99603293492,"u":99603293501,"b":[["77669.86000000","9.18718000"],["77669.85000000","0.00084000"],["69902.88000000","0.00432000"],["69902.87000000","0.00064000"]],"a":[["77669.87000000","2.12466000"]]}}
{"type":"depth","received_at_ms":1788407322812,"data":{"e":"depthUpdate","E":1788407323015,"s":"BTCUSDT","U":99603293502,"u":99603293507,"b":[["69902.88000000","0.00448000"],["62135.89000000","0.00032000"]],"a":[["77679.70000000","0.00000000"],["77680.21000000","0.00400000"]]}}
{"type":"depth","received_at_ms":1788407322910,"data":{"e":"depthUpdate","E":1788407323114,"s":"BTCUSDT","U":99603293508,"u":99603293522,"b":[["77669.86000000","9.18760000"],["77669.15000000","0.00000000"],["77668.49000000","0.00063000"],["77666.56000000","0.00000000"],["76504.81000000","0.00030000"],["69902.88000000","0.00432000"],["62135.90000000","0.00000000"]],"a":[["77669.87000000","2.11436000"],["77678.11000000","0.00000000"],["77678.62000000","0.52420000"],["77717.18000000","1.03652000"],["77717.46000000","0.00000000"],["78834.92000000","0.00030000"]]}}
{"type":"depth","received_at_ms":1788407323011,"data":{"e":"depthUpdate","E":1788407323214,"s":"BTCUSDT","U":99603293523,"u":99603293528,"b":[["69902.88000000","0.00448000"],["62135.89000000","0.00000000"]],"a":[["77680.21000000","0.00000000"],["77680.71000000","0.00400000"]]}}
{"type":"depth","received_at_ms":1788407323110,"data":{"e":"depthUpdate","E":1788407323314,"s":"BTCUSDT","U":99603293529,"u":99603293539,"b":[["77669.86000000","9.18782000"],["69902.88000000","0.00432000"],["69902.87000000","0.00073000"],["62136.00000000","0.00015000"]],"a":[["77669.87000000","2.11437000"],["77675.88000000","0.00000000"]]}}
{"type":"depth","received_at_ms":1788407323217,"data":{"e":"depthUpdate","E":1788407323415,"s":"BTCUSDT","U":99603293540,"u":99603293540,"b":[["69902.88000000","0.00448000"]],"a":[]}}
{"type":"depth","received_at_ms":1788407323313,"data":{"e":"depthUpdate","E":1788407323514,"s":"BTCUSDT","U":99603293541,"u":99603293550,"b":[["69902.88000000","0.00432000"],["62135.89000000","0.00032000"]],"a":[["77669.87000000","2.11363000"]]}}
{"type":"depth","received_at_ms":1788407323419,"data":{"e":"depthUpdate","E":1788407323616,"s":"BTCUSDT","U":99603293551,"u":99603293554,"b":[["69902.88000000","0.00448000"],["62135.89000000","0.00000000"]],"a":[]}}
{"type":"depth","received_at_ms":1788407323511,"data":{"e":"depthUpdate","E":1788407323714,"s":"BTCUSDT","U":99603293555,"u":99603293561,"b":[["77655.55000000","0.00007000"],["75561.73000000","0.00010000"],["69902.88000000","0.00432000"],["69902.87000000","0.00064000"],["69902.86000000","0.00009000"]],"a":[["77669.87000000","2.10103000"],["77686.62000000","0.00007000"]]}}
{"type":"depth","received_at_ms":1788407323610,"data":{"e":"depthUpdate","E":1788407323814,"s":"BTCUSDT","U":99603293562,"u":99603293567,"b":[["69902.88000000","0.00448000"],["62136.00000000","0.00015000"]],"a":[["77669.87000000","2.10141000"]]}}
{"type":"depth","received_at_ms":1788407323710,"data":{"e":"depthUpdate","E":1788407323914,"s":"BTCUSDT","U":99603293568,"u":99603293571,"b":[["69902.88000000","0.00432000"]],"a":[["81006.07000000","0.00010000"]]}}
{"type":"depth","received_at_ms":1788407323810,"data":{"e":"depthUpdate","E":1788407324014,"s":"BTCUSDT","U":99603293572,"u":99603293578,"b":[["77669.86000000","9.18507000"],["73500.00000000","41.32649000"],["69902.88000000","0.00416000"],["69902.86000000","0.00000000"],["62135.89000000","0.00032000"]],"a":[]}}
{"type":"depth","received_at_ms":1788407323911,"data":{"e":"depthUpdate","E":1788407324115,"s":"BTCUSDT","U":99603293579,"u":99603293585,"b":[["76504.81000000","0.00030000"],["69902.88000000","0.00432000"],["62136.00000000","0.00215000"]],"a":[["77669.87000000","2.10169000"],["78834.92000000","0.00030000"]]}}
{"type":"depth","received_at_ms":1788407324011,"data":{"e":"depthUpdate","E":1788407324214,"s":"BTCUSDT","U":99603293586,"u":99603293591,"b":[["69902.88000000","0.00432000"],["62136.00000000","0.00015000"],["62135.89000000","0.00000000"]],"a":[]}}
{"type":"depth","received_at_ms":1788407324110,"data":{"e":"depthUpdate","E":1788407324314,"s":"BTCUSDT","U":99603293592,"u":99603293595,"b":[["69902.88000000","0.00432000"],["62136.00000000","0.00015000"]],"a":[]}}
{"type":"depth","received_at_ms":1788407324210,"data":{"e":"depthUpdate","E":1788407324414,"s":"BTCUSDT","U":99603293596,"u":99603293604,"b":[["77669.86000000","9.18507000"],["77667.43000000","0.00000000"],["77667.42000000","0.00257000"],["77587.64000000","0.00484000"],["69902.88000000","0.00432000"],["62136.00000000","0.00015000"]],"a":[]}}
{"type":"depth","received_at_ms":1788407324310,"data":{"e":"depthUpdate","E":1788407324514,"s":"BTCUSDT","U":99603293605,"u":99603293614,"b":[["77667.42000000","0.00000000"],["77667.40000000","0.00257000"],["69902.88000000","0.00448000"],["62135.89000000","0.00032000"]],"a":[]}}
{"type":"depth","received_at_ms":1788407324412,"data":{"e":"depthUpdate","E":1788407324615,"s":"BTCUSDT","U":99603293615,"u":99603293635,"b":[["77669.86000000","9.18441000"],["77667.40000000","0.00000000"],["77667.39000000","0.00257000"],["77648.23000000","0.12612000"],["69902.88000000","0.00432000"],["69902.87000000","0.00073000"],["62136.00000000","0.00015000"],["62135.89000000","0.00000000"]],"a":[["77703.39000000","0.00000000"],["77703.40000000","0.09739000"]]}}
{"type":"depth","received_at_ms":1788407324510,"data":{"e":"depthUpdate","E":1788407324714,"s":"BTCUSDT","U":99603293636,"u":99603293639,"b":[["77669.86000000","9.18434000"],["77667.39000000","0.00000000"],["77667.37000000","0.02299000"],["69902.88000000","0.00448000"]],"a":[]}}
{"type":"depth","received_at_ms":1788407324611,"data":{"e":"depthUpdate","E":1788407324814,"s":"BTCUSDT","U":99603293640,"u":99603293648,"b":[["77669.86000000","9.18441000"],["77667.37000000","0.02042000"],["77667.35000000","0.00257000"],["77655.55000000","0.00007000"],["69902.88000000","0.00432000"]],"a":[["77686.62000000","0.00007000"]]}}
{"type":"depth","received_at_ms":1788407324712,"data":{"e":"depthUpdate","E":1788407324914,"s":"BTCUSDT","U":99603293649,"u":99603293655,"b":[["77669.86000000","9.18433000"],["77667.35000000","0.00000000"],["69902.88000000","0.00448000"]],"a":[]}}
{"type":"depth","received_at_ms":1788407324819,"data":{"e":"depthUpdate","E":1788407325014,"s":"BTCUSDT","U":99603293656,"u":99603293664,"b":[["77669.86000000","9.18433000"],["77667.33000000","0.00000000"],["77667.31000000","0.00257000"],["69902.88000000","0.00432000"],["62136.00000000","0.00015000"],["62135.89000000","0.00032000"]],"a":[]}}
{"type":"depth","received_at_ms":1788407324912,"data":{"e":"depthUpdate","E":1788407325115,"s":"BTCUSDT","U":99603293665,"u":99603293679,"b":[["77669.86000000","9.18426000"],["77667.64000000","0.00400000"],["77667.31000000","0.00000000"],["77667.29000000","0.00257000"],["77666.99000000","0.00000000"],["76504.81000000","0.00030000"],["76277.83000000","0.00000000"],["69902.88000000","0.00448000"]],"a":[["77681.79000000","0.00000000"],["77683.19000000","0.00643000"],["77698.07000000","0.04602000"],["78834.92000000","0.00030000"]]}}
{"type":"depth","received_at_ms":1788407325011,"data":{"e":"depthUpdate","E":1788407325214,"s":"BTCUSDT","U":99603293680,"u":99603293685,"b":[["77667.29000000","0.00000000"],["77667.27000000","0.00257000"],["69902.88000000","0.00432000"],["62135.89000000","0.00000000"]],"a":[]}}
{"type":"depth","received_at_ms":1788407325111,"data":{"e":"depthUpdate","E":1788407325314,"s":"BTCUSDT","U":99603293686,"u":99603293754,"b":[["77669.86000000","9.18441000"],["77669.85000000","0.00098000"],["77669.08000000","0.00000000"],["77668.96000000","0.00643000"],["77668.50000000","0.00400000"],["77668.49000000","0.00000000"],["77668.38000000","0.00055000"],["77667.64000000","0.00000000"],["77667.27000000","0.00000000"],["77666.90000000","0.00014000"],["77666.10000000","0.00000000"],["77664.52000000","0.00257000"],["77663.18000000","0.00000000"],["77661.60000000","0.01600000"],["77659.24000000","0.00000000"],["77659.06000000","0.00800000"],["77646.25000000","0.00000000"],["77642.17000000","0.00000000"],["77637.30000000","0.00000000"],["69902.88000000","0.00448000"],["62136.00000000","0.00015000"]],"a":[["77669.87000000","2.10107000"],["77669.88000000","0.00091000"],["77670.44000000","0.00014000"],["77670.45000000","0.08924000"],["77670.54000000","0.10275000"],["77670.91000000","0.00691000"],["77670.92000000","0.00014000"],["77672.61000000","0.00000000"],["77673.29000000","0.00000000"],["77673.95000000","0.00000000"],["77674.35000000","0.00000000"],["77680.71000000","0.00000000"],["77680.96000000","0.00800000"],["77680.97000000","0.01400000"],["77681.36000000","0.00400000"],["77682.21000000","0.00000000"],["77709.52000000","0.00000000"],["77711.40000000","0.00400000"],["77766.99000000","1.49744000"],["77769.89000000","0.00000000"],["77772.44000000","2.60865000"]]}}
{"type":"depth","received_at_ms":1788407325210,"data":{"e":"depthUpdate","E":1788407325414,"s":"BTCUSDT","U":99603293755,"u":99603293892,"b":[["77669.86000000","4.44024000"],["77669.85000000","0.00070000"],["77669.53000000","0.53388000"],["77668.96000000","0.00014000"],["77668.95000000","0.00000000"],["77668.46000000","0.00014000"],["77668.38000000","0.00000000"],["77667.93000000","0.00023000"],["77667.92000000","0.00014000"],["77667.39000000","0.00000000"],["77667.37000000","0.02021000"],["77667.36000000","0.00000000"],["77667.06000000","0.00007000"],["77666.94000000","0.00400000"],["77666.90000000","0.00000000"],["77666.14000000","0.00055000"],["77665.49000000","0.00400000"],["77665.37000000","0.01286000"],["77661.61000000","0.00000000"],["77661.60000000","0.00000000"],["77660.89000000","0.00400000"],["77659.52000000","0.00000000"],["77659.35000000","0.00800000"],["77659.24000000","0.01200000"],["77659.06000000","0.00000000"],["77659.05000000","0.08843000"],["77656.65000000","0.30866000"],["77656.31000000","0.30000000"],["77653.89000000","0.00000000"],["77643.75000000","0.00000000"],["77642.71000000","0.00000000"],["77602.78000000","1.58473000"],["77602.21000000","4.63500000"],["69902.88000000","0.00432000"],["62136.00000000","0.00015000"]],"a":[["77669.87000000","2.10162000"],["77669.88000000","0.00105000"],["77670.54000000","0.10275000"],["77670.91000000","0.00705000"],["77672.62000000","0.03194000"],["77672.69000000","0.09808000"],["77676.30000000","0.00000000"],["77676.39000000","0.00675000"],["77678.62000000","0.52020000"],["77678.66000000","0.00000000"],["77680.73000000","0.00200000"],["77680.95000000","0.10022000"],["77680.97000000","0.01200000"],["77681.36000000","0.00000000"],["77707.50000000","0.00400000"],["77709.45000000","0.00400000"],["77711.40000000","0.00000000"]]}}
{"type":"depth","received_at_ms":1788407325310,"data":{"e":"depthUpdate","E":1788407325514,"s":"BTCUSDT","U":99603293893,"u":99603294287,"b":[["77669.86000000","9.20652000"],["77669.85000000","0.00014000"],["77669.53000000","0.53388000"],["77668.96000000","0.00000000"],["77668.61000000","0.01698000"],["77668.46000000","0.00000000"],["77667.93000000","0.00000000"],["77667.92000000","0.00000000"],["77667.37000000","0.02035000"],["77667.06000000","0.00014000"],["77666.94000000","0.00000000"],["77666.88000000","0.49837000"],["77666.85000000","0.03280000"],["77666.49000000","0.00027000"],["77666.14000000","0.00000000"],["77665.91000000","0.00014000"],["77665.56000000","0.03217000"],["77665.50000000","0.00000000"],["77665.49000000","0.00000000"],["77665.37000000","0.00007000"],["77665.36000000","0.00000000"],["77665.14000000","0.00007000"],["77665.13000000","0.12882000"],["77665.12000000","0.00400000"],["77664.52000000","0.00000000"],["77664.27000000","0.00407000"],["77663.18000000","0.00400000"],["77660.89000000","0.00000000"],["77660.74000000","0.00000000"],["77659.35000000","0.00000000"],["77659.24000000","0.00400000"],["77659.05000000","0.08643000"],["77656.92000000","0.03007000"],["77652.13000000","0.00335000"],["77650.53000000","0.12878000"],["77648.70000000","0.04681000"],["77647.40000000","0.00000000"],["77646.31000000","0.00000000"],["77646.07000000","0.64420000"],["77645.74000000","0.04000000"],["77641.60000000","0.00000000"],["77635.14000000","0.34791000"],["77634.75000000","0.02484000"],["77631.69000000","0.00000000"],["77631.23000000","0.00000000"],["77624.78000000","0.00000000"],["77615.50000000","0.00000000"],["77612.71000000","4.63500000"],["77612.70000000","0.00000000"],["77602.78000000","0.26443000"],["77602.21000000","0.00000000"],["77588.24000000","0.49412000"],["77364.30000000","0.00000000"],["77340.24000000","0.00000000"],["69902.88000000","0.00432000"],["69902.87000000","0.00064000"],["69902.86000000","0.00009000"],["62135.89000000","0.00052000"]],"a":[["77669.87000000","0.87022000"],["77669.88000000","0.00084000"],["77670.44000000","0.00000000"],["77670.45000000","0.00021000"],["77670.46000000","0.00014000"],["77670.92000000","0.00007000"],["77672.61000000","0.00014000"],["77672.62000000","0.03187000"],["77672.67000000","0.00007000"],["77672.68000000","0.09190000"],["77672.69000000","0.00000000"],["77673.55000000","0.00000000"],["77674.08000000","0.10022000"],["77674.10000000","0.00000000"],["77674.50000000","0.00000000"],["77674.78000000","0.00007000"],["77675.50000000","0.10022000"],["77675.51000000","0.00000000"],["77675.64000000","0.00000000"],["77676.07000000","0.00000000"],["77676.39000000","0.00000000"],["77676.75000000","0.10022000"],["77676.76000000","0.00000000"],["77677.60000000","0.00000000"],["77677.74000000","0.00000000"],["77678.25000000","0.00000000"],["77678.32000000","0.12096000"],["77678.45000000","0.00000000"],["77678.60000000","0.09939000"],["77678.61000000","0.00000000"],["77678.62000000","0.00000000"],["77678.63000000","0.00000000"],["77678.64000000","0.00007000"],["77680.02000000","0.00000000"],["77680.20000000","0.00000000"],["77680.24000000","0.00000000"],["77680.61000000","0.00000000"],["77680.79000000","0.00048000"],["77680.94000000","0.10822000"],["77680.95000000","0.00000000"],["77680.96000000","0.00000000"],["77680.98000000","0.00000000"],["77681.21000000","0.12873000"],["77681.25000000","0.00048000"],["77681.43000000","0.00000000"],["77681.72000000","0.00069000"],["77682.07000000","0.00000000"],["77682.09000000","0.00048000"],["77682.22000000","0.10022000"],["77682.23000000","0.46350000"],["77682.49000000","0.00000000"],["77682.50000000","0.00007000"],["77683.19000000","0.00000000"],["77683.76000000","0.00000000"],["77683.92000000","0.00000000"],["77683.97000000","0.10022000"],["77684.24000000","0.00000000"],["77684.33000000","0.00643000"],["77684.34000000","0.15000000"],["77684.49000000","0.00000000"],["77684.87000000","4.63500000"],["77684.88000000","0.00000000"],["77685.07000000","0.10030000"],["77685.28000000","1.46017000"],["77685.29000000","0.00000000"],["77685.31000000","0.00000000"],["77685.32000000","0.00000000"],["77685.36000000","0.13343000"],["77685.37000000","0.00000000"],["77685.39000000","0.00000000"],["77686.36000000","0.00014000"],["77686.79000000","0.10022000"],["77687.96000000","0.00000000"],["77688.20000000","0.10022000"],["77688.33000000","0.00000000"],["77688.98000000","0.12871000"],["77689.53000000","0.10022000"],["77689.55000000","0.00000000"],["77692.14000000","0.26635000"],["77692.40000000","0.00000000"],["77692.60000000","5.78651000"],["77692.61000000","0.00000000"],["77693.11000000","0.00000000"],["77693.39000000","0.29117000"],["77693.89000000","0.00000000"],["77693.99000000","0.00000000"],["77694.10000000","0.00000000"],["77694.78000000","0.00000000"],["77695.00000000","0.00000000"],["77695.13000000","0.00013000"],["77695.99000000","0.25758000"],["77696.34000000","0.64397000"],["77696.35000000","0.30866000"],["77697.28000000","1.15151000"],["77697.29000000","0.10815000"],["77697.30000000","0.00000000"],["77697.38000000","0.00000000"],["77697.60000000","0.00000000"],["77702.35000000","1.15151000"],["77702.36000000","0.00000000"],["77702.37000000","0.00000000"],["77703.40000000","0.00000000"],["77703.60000000","0.00400000"],["77706.48000000","2.10005000"],["77706.49000000","5.78651000"],["77706.50000000","0.00000000"],["77706.62000000","0.00000000"],["77707.37000000","0.00000000"],["77709.16000000","0.00000000"],["77709.45000000","0.00400000"],["77709.52000000","0.00007000"],["77709.61000000","0.00000000"],["77710.54000000","0.00000000"],["77711.19000000","4.63500000"],["77711.40000000","0.00400000"],["77713.38000000","0.00007000"],["77713.56000000","0.00000000"],["77715.18000000","0.00000000"],["77715.19000000","0.00000000"],["77715.30000000","0.00000000"],["77715.92000000","0.04762000"],["77717.18000000","0.00000000"],["77717.19000000","0.00000000"],["77722.02000000","0.00000000"],["77724.33000000","0.00000000"],["77737.52000000","1.27401000"],["77745.75000000","0.06414000"],["77753.01000000","1.15151000"],["77759.65000000","1.15151000"],["77763.83000000","0.00000000"],["77769.26000000","1.15151000"],["77772.44000000","0.00000000"],["77778.60000000","4.63500000"],["77779.36000000","1.15151000"],["77787.93000000","0.00000000"],["77797.26000000","0.00000000"],["77805.57000000","0.01865000"],["77883.38000000","0.00007000"],["77909.60000000","0.00256000"],["77921.80000000","0.00000000"],["77933.04000000","0.00026000"]]}}
{"type":"depth","received_at_ms":1788407325411,"data":{"e":"depthUpdate","E":1788407325614,"s":"BTCUSDT","U":99603294288,"u":99603294360,"b":[["77669.86000000","9.24515000"],["77668.73000000","0.00400000"],["77664.27000000","0.00007000"],["77663.18000000","0.01600000"],["77660.89000000","0.00200000"],["77645.53000000","0.00200000"],["77643.67000000","0.00000000"],["77640.00000000","0.03188000"],["77354.79000000","0.00038000"],["75805.56000000","0.00000000"],["69902.88000000","0.00416000"],["62135.89000000","0.00000000"]],"a":[["77669.87000000","0.84949000"],["77670.00000000","0.03021000"],["77670.45000000","0.00000000"],["77670.46000000","0.00000000"],["77670.91000000","0.00021000"],["77672.62000000","0.03208000"],["77672.68000000","0.09204000"],["77674.00000000","0.03007000"],["77674.78000000","0.00014000"],["77675.33000000","0.17408000"],["77675.60000000","0.00208000"],["77675.72000000","0.00027000"],["77675.77000000","0.09989000"],["77678.64000000","0.00014000"],["77680.01000000","0.00400000"],["77680.73000000","0.00000000"],["77680.94000000","0.10422000"],["77680.97000000","0.00000000"],["77682.23000000","1.94165000"],["77682.50000000","0.00014000"],["77683.15000000","0.00400000"],["77683.48000000","0.00200000"],["77684.86000000","0.11622000"],["77685.07000000","0.00008000"],["77685.36000000","0.08502000"],["77686.79000000","0.00000000"],["77688.20000000","0.00000000"],["77689.53000000","0.00000000"],["77693.39000000","0.52309000"],["77694.46000000","0.02000000"],["77713.38000000","0.00000000"],["77718.57000000","0.00433000"],["77756.17000000","0.02000000"]]}}
{"type":"depth","received_at_ms":1788407325510,"data":{"e":"depthUpdate","E":1788407325714,"s":"BTCUSDT","U":99603294361,"u":99603294400,"b":[["77669.86000000","9.25697000"],["77650.98000000","0.00189000"],["77649.61000000","0.00059000"],["77638.46000000","0.00008000"],["77638.32000000","1.29833000"],["77637.17000000","0.00000000"],["69902.88000000","0.00432000"]],"a":[["77669.87000000","0.86841000"],["77669.88000000","0.00084000"],["77670.54000000","0.10275000"],["77670.91000000","0.00007000"],["77674.00000000","0.03021000"],["77674.78000000","0.00007000"],["77682.21000000","0.01600000"],["77684.86000000","0.10022000"],["77702.74000000","0.52334000"],["77713.38000000","0.00007000"],["77714.46000000","1.29706000"],["77726.62000000","1.04083000"]]}}
{"type":"depth","received_at_ms":1788407325611,"data":{"e":"depthUpdate","E":1788407325814,"s":"BTCUSDT","U":99603294401,"u":99603294421,"b":[["77669.86000000","9.28657000"],["77655.55000000","0.00007000"],["77655.19000000","0.21581000"],["77464.81000000","0.00812000"],["77453.93000000","0.00000000"],["69902.88000000","0.00448000"],["69902.86000000","0.00000000"]],"a":[["77669.87000000","0.71779000"],["77670.68000000","0.00007000"],["77674.78000000","0.00014000"],["77686.62000000","0.00007000"],["77689.72000000","0.02200000"],["77693.61000000","0.02000000"],["77713.38000000","0.00000000"],["77738.61000000","0.02200000"],["77742.50000000","0.02000000"]]}}
{"type":"depth","received_at_ms":1788407325710,"data":{"e":"depthUpdate","E":1788407325914,"s":"BTCUSDT","U":99603294422,"u":99603294432,"b":[["69902.88000000","0.00416000"]],"a":[["77669.87000000","0.71786000"],["77669.88000000","0.00091000"],["77670.65000000","0.00014000"],["77670.66000000","0.12806000"],["77672.67000000","0.00000000"],["77703.65000000","0.00000000"],["77738.61000000","0.00000000"],["77742.50000000","0.00000000"]]}}
{"type":"depth","received_at_ms":1788407325811,"data":{"e":"depthUpdate","E":1788407326014,"s":"BTCUSDT","U":99603294433,"u":99603294451,"b":[["77669.86000000","9.27956000"],["77668.74000000","0.00053000"],["77668.62000000","0.00643000"],["69902.88000000","0.00448000"],["62135.89000000","0.00032000"]],"a":[["77670.54000000","0.10275000"],["77670.66000000","0.12820000"],["77674.00000000","0.03007000"],["77699.77000000","0.00000000"],["77711.18000000","1.15151000"],["77713.79000000","0.00852000"],["77722.31000000","0.00000000"],["77756.17000000","0.00000000"]]}}
{"type":"depth","received_at_ms":1788407325912,"data":{"e":"depthUpdate","E":1788407326115,"s":"BTCUSDT","U":99603294452,"u":99603294468,"b":[["77669.53000000","0.53388000"],["76504.81000000","0.00030000"],["69902.88000000","0.00432000"]],"a":[["77693.57000000","0.02400000"],["77722.29000000","0.00000000"],["77722.46000000","0.00000000"],["77755.34000000","0.02400000"],["78834.92000000","0.00030000"]]}}
{"type":"depth","received_at_ms":1788407326010,"data":{"e":"depthUpdate","E":1788407326214,"s":"BTCUSDT","U":99603294469,"u":99603294482,"b":[["77635.00000000","0.70000000"],["77634.48000000","0.54798000"],["77632.00000000","0.03007000"],["69902.88000000","0.00448000"],["62135.89000000","0.00000000"]],"a":[["77669.87000000","0.71793000"],["77673.45000000","0.00597000"],["77693.98000000","0.02600000"],["77723.37000000","0.00000000"],["77755.34000000","0.00000000"],["77755.84000000","0.02600000"]]}}
{"type":"depth","received_at_ms":1788407326110,"data":{"e":"depthUpdate","E":1788407326314,"s":"BTCUSDT","U":99603294483,"u":99603294494,"b":[["69902.88000000","0.00432000"],["62136.00000000","0.00015000"]],"a":[["77670.68000000","0.00000000"],["77672.68000000","0.09204000"],["77700.00000000","0.91777000"],["77722.83000000","0.00000000"],["77755.84000000","0.00000000"]]}}
{"type":"depth","received_at_ms":1788407326211,"data":{"e":"depthUpdate","E":1788407326414,"s":"BTCUSDT","U":99603294495,"u":99603294510,"b":[["76970.83000000","0.00000000"],["69902.88000000","0.00448000"]],"a":[["77684.20000000","0.00257000"],["77690.43000000","0.02000000"],["77692.76000000","0.02000000"],["77694.31000000","0.02000000"],["77694.36000000","0.02000000"],["77723.48000000","0.12879000"],["77739.82000000","0.02000000"],["77752.41000000","0.02000000"],["77754.61000000","0.02000000"],["77756.14000000","0.02000000"],["77756.16000000","0.02000000"],["77774.99000000","2.60865000"]]}}
{"type":"depth","received_at_ms":1788407326311,"data":{"e":"depthUpdate","E":1788407326515,"s":"BTCUSDT","U":99603294511,"u":99603294522,"b":[["77669.46000000","0.00257000"],["77489.34000000","0.00000000"],["69902.88000000","0.00441000"],["62135.89000000","0.00032000"]],"a":[["77669.87000000","0.71771000"],["77703.13000000","0.00000000"],["77723.48000000","0.00000000"],["77756.14000000","0.00000000"],["77846.11000000","0.00000000"]]}}
{"type":"depth","received_at_ms":1788407326410,"data":{"e":"depthUpdate","E":1788407326614,"s":"BTCUSDT","U":99603294523,"u":99603294537,"b":[["69902.88000000","0.00457000"],["62135.89000000","0.00000000"]],"a":[["77669.87000000","0.70609000"],["77695.02000000","0.12870000"],["77722.64000000","0.12879000"],["77722.69000000","0.00000000"],["77754.61000000","0.00000000"],["77756.16000000","0.00000000"]]}}
{"type":"depth","received_at_ms":1788407326510,"data":{"e":"depthUpdate","E":1788407326715,"s":"BTCUSDT","U":99603294538,"u":99603294543,"b":[["77563.95000000","0.00108000"],["77558.04000000","0.00000000"],["69902.88000000","0.00441000"]],"a":[["77722.64000000","0.00000000"]]}}
{"type":"depth","received_at_ms":1788407326612,"data":{"e":"depthUpdate","E":1788407326814,"s":"BTCUSDT","U":99603294544,"u":99603294566,"b":[["77669.46000000","0.00000000"],["77669.39000000","0.00257000"],["77655.55000000","0.00007000"],["77495.59000000","4.42071000"],["69902.88000000","0.00441000"],["62136.00000000","0.00015000"]],"a":[["77669.87000000","0.84730000"],["77670.53000000","0.12382000"],["77670.66000000","0.00014000"],["77686.62000000","0.00007000"],["77722.60000000","0.00000000"],["77738.61000000","0.02200000"],["77742.50000000","0.02000000"],["77852.58000000","4.52683000"]]}}
{"type":"depth","received_at_ms":1788407326735,"data":{"e":"depthUpdate","E":1788407326914,"s":"BTCUSDT","U":99603294567,"u":99603294592,"b":[["77669.86000000","9.27956000"]],"a":[["77669.87000000","0.99452000"],["77669.88000000","0.00084000"],["77670.52000000","0.00014000"],["77670.53000000","0.08560000"],["77670.54000000","0.10275000"],["77670.65000000","0.00000000"],["77670.66000000","0.00000000"],["77670.68000000","0.00007000"],["77673.45000000","0.00611000"],["77723.01000000","0.00000000"]]}}
{"type":"depth","received_at_ms":1788407326810,"data":{"e":"depthUpdate","E":1788407327014,"s":"BTCUSDT","U":99603294593,"u":99603294600,"b":[["77669.86000000","9.28114000"],["69902.88000000","0.00441000"],["62135.89000000","0.00032000"]],"a":[["77670.91000000","0.00598000"],["77673.45000000","0.00014000"]]}}
{"type":"depth","received_at_ms":1788407326910,"data":{"e":"depthUpdate","E":1788407327114,"s":"BTCUSDT","U":99603294601,"u":99603294624,"b":[["76504.81000000","0.00030000"],["69902.88000000","0.00441000"],["62136.00000000","0.00215000"]],"a":[["77669.87000000","0.99452000"],["77669.88000000","0.00091000"],["77670.54000000","0.10275000"],["77670.91000000","0.00612000"],["77672.68000000","0.09204000"],["77673.45000000","0.00000000"],["77722.33000000","0.00000000"],["78834.92000000","0.00030000"]]}}
{"type":"depth","received_at_ms":1788407327010,"data":{"e":"depthUpdate","E":1788407327214,"s":"BTCUSDT","U":99603294625,"u":99603294633,"b":[["77541.03000000","0.02017000"],["77537.72000000","0.00000000"],["69902.88000000","0.00441000"],["62136.00000000","0.00015000"],["62135.89000000","0.00000000"]],"a":[["77702.34000000","1.11127000"],["77752.31000000","0.42694000"],["77778.58000000","1.79924000"]]}}
